Workbook
Name MODEPAID: MODEPAID!$A$1:$A$3
Name MODEPAID: #REF!
Name MODEPAID: #REF!
Name MODEPAID: #REF!
Name MODEPAID: #REF!
Name MODEPAID: #REF!
Name MODEPAID: #REF!
Name MODEPAID: #REF!
Name MODEPAID: #REF!
Name MODEPAID: #REF!
Name MODEPAID: #REF!
Name MODEPAID: #REF!
Name MODEPAID: #REF!
Name MODEPAID: #REF!
Name MODEPAID: #REF!
Name MODEPAID: #REF!
Name MODEPAID: #REF!
Name VALMODEPAID: MODEPAID!$A$1:$A$3

Sheet Feuil1
B1: INTERET VENTE | C1: MISE A PRIX | D1: INTERET MISE EN VENTE | E1: INTERET PETIT LOT | F1: INT CUMUL MISE EN VENTE | G1: INTERET NON REMB | H1: PETIT LOT + INTERET
A2: 42979 | B2: =#REF! -> #REF! | C2: 200000 | D2: =B2-C2 -> #REF! | E2: =#REF! -> #REF! | H2: =#REF! -> #REF! | I2: OK
A3: 43009 | B3: =+#REF! -> #REF! | C3: 200000 | D3: =B3-C3 -> #REF! | E3: =+#REF! -> #REF! | F3: =D2+E2+D3 -> #REF! | H3: =#REF! -> #REF! | I3: OK
A4: 43040 | B4: =+#REF! -> #REF! | C4: 200000 | D4: =B4-C4 -> #REF! | E4: =+#REF! -> #REF! | F4: =F3+D4+E3 -> #REF! | H4: =#REF! -> #REF! | I4: OK
A5: 43070 | B5: =#REF! -> #REF! | C5: 200000 | D5: =B5-C5 -> #REF! | E5: =+#REF! -> #REF! | F5: =F4+D5+E4 -> #REF! | G5: 200000 | H5: =#REF! -> #REF! | I5: NOK
A6: 43101 | B6: =+#REF! -> #REF! | C6: 200000 | D6: =B6-C6 -> #REF! | E6: =+#REF! -> #REF! | F6: =F5+D6+E5 -> #REF! | H6: =#REF! -> #REF!
A7: 43132 | B7: =+#REF! -> #REF! | C7: 200000 | D7: =B7-C7 -> #REF! | E7: =+#REF! -> #REF! | F7: =F6+D7+E6 -> #REF! | G7: 200000 | H7: =#REF! -> #REF!
A8: 43160 | B8: =+#REF! -> #REF! | C8: 200000 | D8: =B8-C8 -> #REF! | E8: =+#REF! -> #REF! | F8: =F7+D8+E7 -> #REF! | H8: =#REF! -> #REF!
A9: 43191 | B9: =+#REF! -> #REF! | C9: 200000 | D9: =B9-C9 -> #REF! | E9: =+#REF! -> #REF! | F9: =F8+D9+E8 -> #REF! | H9: =#REF! -> #REF!
A10: 43221 | B10: =+#REF! -> #REF! | C10: 200000 | D10: =B10-C10 -> #REF! | E10: =+#REF! -> #REF! | F10: =F9+D10+E9 -> #REF! | H10: =#REF! -> #REF!
A11: 43252 | B11: =+#REF! -> #REF! | C11: 200000 | D11: =B11-C11 -> #REF! | E11: =+#REF! -> #REF! | F11: =F10+D11+E10 -> #REF! | H11: =#REF! -> #REF!
A12: 43282 | B12: =+#REF! -> #REF! | C12: 100000 | D12: =B12-C12 -> #REF! | E12: =+#REF! -> #REF! | F12: =F11+D12+E11 -> #REF! | H12: =#REF! -> #REF!
A13: 43313 | B13: 200000 | C13: 200000 | D13: 0 | E13: 0 | F13: =F12+D13+E12 -> #REF! | H13: =#REF! -> #REF!
B14: =SUM(B2:B13) -> #REF! | C14: =SUM(C2:C13) -> 2300000
C15: =+B14-C14 -> #REF! | D15: =SUM(D2:D14) -> #REF! | E15: =SUM(E2:E14) -> #REF! | H15: 1145500 | I15: 2300000
H16: 12000
B17: NGONDIEP | D17: 101000 | H17: =+H15+H16 -> 1157500
B18: NANGUEN | D18: 96000 | H18: 200000
B19: FOTSO THOMAS | D19: 206000 | H19: 269000
H20: =+H17+H18+H19 -> 1626500
H21: =D15+E15-H20 -> #REF!
D22: =SUM(D17:D21) -> 403000

Sheet MODEPAID
A1: BANQUE
A2: ESPECES
A3: ECHEC

Sheet TONTNOV
A1: ASSOCIATION | B1: ASELBY
A2: ANNEE | B2: 2019/2020
A3: TONTINE | B3: 100000
C4: 43793
A5: MATRICULE | B5: NOM ET PRENOM | C5: MONTANT TONTINE | D5: PENALITE | E5: MODE VERSEMENT TONTINE | F5: VENTE PETIT LOT | G5: INTERET PETIT LOT | H5: MODE VERSEMENT VENTE PETIT LOT | I5: NUMERO CHEQUE | J5: REMBOURSEMENT | K5: MODE VERSEMENT REMBOURSEMENT | L5: MODE VERSEMENT TONTINE PRINCIPAL | M5: NUMERO CHEQUE | N5: MONTANT TONTINE LOT PRINCIPAL | O5: INTERET LOT PRINCIPAL | P5: DATE VENTE
A6: AS201608 | B6: =VLOOKUP(A6,[1]LISTADHERENT!A$5:H$60,3,0) -> DJUOMBESSY ANTOINE | C6: =IF(E6="ECHEC",0,IF(E6="",0,100000)) -> 100000 | D6: =IF(E6="ESPECES",0,0) -> 0 | E6: BANQUE | N6: =IF(O6=0,0,($C$38-O6)) -> 0
A7: AS201613 | B7: =VLOOKUP(A7,[1]LISTADHERENT!A$5:H$60,3,0) -> HOTCHO BENJAMIN | C7: =IF(E7="ECHEC",0,IF(E7="",0,100000)) -> 100000 | D7: =IF(E7="ESPECES",0,0) -> 0 | E7: BANQUE | N7: =IF(O7=0,0,($C$38-O7)) -> 0
A8: AS201619 | B8: =VLOOKUP(A8,[1]LISTADHERENT!A$5:H$60,3,0) -> KOUATCHO MESSACK | C8: =IF(E8="ECHEC",0,IF(E8="",0,100000)) -> 100000 | D8: =IF(E8="ESPECES",0,0) -> 0 | E8: BANQUE | F8: =100000+50000 -> 150000 | G8: =2500+1000 -> 3500 | H8: BANQUE | N8: =IF(O8=0,0,($C$38-O8)) -> 0
A9: AS201617 | B9: =VLOOKUP(A9,[1]LISTADHERENT!A$5:H$60,3,0) -> KOUAMOU MOISE | C9: =IF(E9="ECHEC",0,IF(E9="",0,100000)) -> 100000 | D9: =IF(E9="ESPECES",0,0) -> 0 | E9: BANQUE | N9: =IF(O9=0,0,($C$38-O9)) -> 0
A10: AS201649 | B10: =VLOOKUP(A10,[1]LISTADHERENT!A$5:H$60,3,0) -> MBOGNING TUGMA GUY | C10: =IF(E10="ECHEC",0,IF(E10="",0,100000)) -> 100000 | D10: =IF(E10="ESPECES",0,0) -> 0 | E10: BANQUE | F10: =100000+100000 -> 200000 | G10: =2500+5500 -> 8000 | H10: ESPECES | N10: =IF(O10=0,0,($C$38-O10)) -> 0
A11: AS201649 | B11: =VLOOKUP(A11,[1]LISTADHERENT!A$5:H$60,3,0) -> MBOGNING TUGMA GUY | C11: =IF(E11="ECHEC",0,IF(E11="",0,100000)) -> 100000 | D11: =IF(E11="ESPECES",0,0) -> 0 | E11: BANQUE | N11: =IF(O11=0,0,($C$38-O11)) -> 0
A12: AS201639 | B12: =VLOOKUP(A12,[1]LISTADHERENT!A$5:H$60,3,0) -> NANGUEN MARTIN | C12: =IF(E12="ECHEC",0,IF(E12="",0,100000)) -> 100000 | D12: =IF(E12="ESPECES",0,0) -> 0 | E12: BANQUE | N12: =IF(O12=0,0,($C$38-O12)) -> 0
A13: AS201622 | B13: =VLOOKUP(A13,[1]LISTADHERENT!A$5:H$60,3,0) -> NDJOMO ETIENNE | C13: =IF(E13="ECHEC",0,IF(E13="",0,100000)) -> 100000 | D13: =IF(E13="ESPECES",0,0) -> 0 | E13: BANQUE | N13: =IF(O13=0,0,($C$38-O13)) -> 0
A14: AS201624 | B14: =VLOOKUP(A14,[1]LISTADHERENT!A$5:H$60,3,0) -> NGONDIEP CLAUDE | C14: =IF(E14="ECHEC",0,IF(E14="",0,100000)) -> 100000 | D14: =IF(E14="ESPECES",0,0) -> 0 | E14: BANQUE | N14: =IF(O14=0,0,($C$38-O14)) -> 0
A15: AS201614 | B15: =VLOOKUP(A15,[1]LISTADHERENT!A$5:H$60,3,0) -> NKEHE DAVID | C15: =IF(E15="ECHEC",0,IF(E15="",0,100000)) -> 100000 | D15: =IF(E15="ESPECES",0,0) -> 0 | E15: ESPECES | N15: =IF(O15=0,0,($C$38-O15)) -> 1350000 | O15: 150000 | P15: 43793
A16: AS201629 | B16: =VLOOKUP(A16,[1]LISTADHERENT!A$5:H$60,3,0) -> NKEPSEU DIEUDONNE | C16: =IF(E16="ECHEC",0,IF(E16="",0,100000)) -> 100000 | D16: =IF(E16="ESPECES",0,0) -> 0 | E16: BANQUE | N16: =IF(O16=0,0,($C$38-O16)) -> 0
A17: AS201636 | B17: =VLOOKUP(A17,[1]LISTADHERENT!A$5:H$60,3,0) -> SIMO FONGANG ERIC | C17: =IF(E17="ECHEC",0,IF(E17="",0,100000)) -> 100000 | D17: =IF(E17="ESPECES",0,0) -> 0 | E17: BANQUE | N17: =IF(O17=0,0,($C$38-O17)) -> 0
A18: AS201636 | B18: =VLOOKUP(A18,[1]LISTADHERENT!A$5:H$60,3,0) -> SIMO FONGANG ERIC | C18: =IF(E18="ECHEC",0,IF(E18="",0,100000)) -> 100000 | D18: =IF(E18="ESPECES",0,0) -> 0 | E18: BANQUE | N18: =IF(O18=0,0,($C$38-O18)) -> 0
A19: AS201637 | B19: =VLOOKUP(A19,[1]LISTADHERENT!A$5:H$60,3,0) -> SIME MATHIEU | C19: =IF(E19="ECHEC",0,IF(E19="",0,100000)) -> 100000 | D19: =IF(E19="ESPECES",0,0) -> 0 | E19: BANQUE | N19: =IF(O19=0,0,($C$38-O19)) -> 0
A20: AS201637 | B20: =VLOOKUP(A20,[1]LISTADHERENT!A$5:H$60,3,0) -> SIME MATHIEU | C20: =IF(E20="ECHEC",0,IF(E20="",0,100000)) -> 100000 | D20: =IF(E20="ESPECES",0,0) -> 0 | E20: BANQUE | N20: =IF(O20=0,0,($C$38-O20)) -> 0
A21: AS201641 | B21: =VLOOKUP(A21,[1]LISTADHERENT!A$5:H$60,3,0) -> TCHOUAMOU MATHIEU | C21: =IF(E21="ECHEC",0,IF(E21="",0,100000)) -> 100000 | D21: =IF(E21="ESPECES",0,0) -> 0 | E21: BANQUE | N21: =IF(O21=0,0,($C$38-O21)) -> 0
A22: AS201644 | B22: =VLOOKUP(A22,[1]LISTADHERENT!A$5:H$60,3,0) -> TIEYAM ERNEST | C22: =IF(E22="ECHEC",0,IF(E22="",0,100000)) -> 100000 | D22: =IF(E22="ESPECES",0,0) -> 0 | E22: BANQUE | F22: =100000+100000 -> 200000 | G22: =4000+9000 -> 13000 | H22: BANQUE | N22: =IF(O22=0,0,($C$38-O22)) -> 0
A23: AS201647 | B23: =VLOOKUP(A23,[1]LISTADHERENT!A$5:H$60,3,0) -> YOUMBI EMMANUEL | C23: =IF(E23="ECHEC",0,IF(E23="",0,100000)) -> 100000 | D23: =IF(E23="ESPECES",0,0) -> 0 | E23: BANQUE | N23: =IF(O23=0,0,($C$38-O23)) -> 0
A25: TOTAL | C25: =SUM(C6:C24) -> 1800000 | D25: =SUM(D6:D24) -> 0 | F25: =SUM(F6:F24) -> 550000 | G25: =SUM(G6:G24) -> 24500 | J25: =SUM(J6:J24) -> 0 | N25: =SUM(N6:N24) -> 1350000 | O25: =SUM(O6:O24) -> 150000
C27: TONTINE | D27: REMBOURSEMENT PETIT LOT | E27: VENTE PETIT LOT | F27: VENTE LOT PRINCIPAL | G27: SOLDE EN CAISSE | K27: TONTINE + REMB + INTERET VENTE | L27: =C25+D32+O25 -> 1950000
K28: TONTINE | L28: =IF(L27>=3000000,1500000*2,1500000) -> 1500000
B29: ESPECES | C29: =SUMIFS(C6:C23,E6:E23,"ESPECES") -> 100000 | D29: =SUMIFS(J6:J23,K6:K23,"ESPECES") -> 0 | E29: =SUMIFS(F6:F23,H6:H23,"ESPECES") -> 200000 | F29: =SUMIFS(N6:N23,L6:L23,"ESPECES") -> 0 | G29: =C29+D29-E29-F29 -> -100000 | K29: PETIT LOT | L29: =L27-L28 -> 450000
B30: BANQUE | C30: =SUMIFS(C6:C23,E6:E23,"BANQUE") -> 1700000 | D30: =SUMIFS(J6:J23,K6:K23,"BANQUE") -> 0 | E30: =SUMIFS(F6:F23,H6:H23,"BANQUE") -> 350000 | F30: =SUMIFS(N6:N23,L6:L23,"BANQUE") -> 0 | G30: =C30+D30-E30-F30 -> 1350000 | K30: RESTE | L30: =L29-F25 -> -100000 | M30: SURPLUS
B32: TOTAL | C32: =C29+C30 -> 1800000 | D32: =D29+D30 -> 0 | E32: =E29+E30 -> 550000 | F32: =F29+F30 -> 0 | G32: =G29+G30 -> 1250000 | K32: ECHEC TONTINE | L32: 0
K33: ECHEC REMBOURSEMENT | L33: 0
B35: INTERET LOT PRINCIPAL | C35: =O25 -> 150000
B36: INTERET PETIT LOT | C36: =+G25 -> 24500
B38: MONTANT TONTINE | C38: 1500000
B39: MONTANT PETIT LOT A VENDRE | C39: =L29 -> 450000

Sheet TONTDEC
A1: ASSOCIATION | B1: ASELBY
A2: ANNEE | B2: 2019/2020
A3: TONTINE | B3: 100000
C4: 43814
A5: MATRICULE | B5: NOM ET PRENOM | C5: MONTANT TONTINE | D5: PENALITE | E5: MODE VERSEMENT TONTINE | F5: VENTE PETIT LOT | G5: INTERET PETIT LOT | H5: MODE VERSEMENT VENTE PETIT LOT | I5: NUMERO CHEQUE | J5: REMBOURSEMENT | K5: MODE VERSEMENT REMBOURSEMENT | L5: MODE VERSEMENT TONTINE PRINCIPAL | M5: NUMERO CHEQUE | N5: MONTANT TONTINE LOT PRINCIPAL | O5: INTERET LOT PRINCIPAL | P5: DATE VENTE
A6: AS201608 | B6: =VLOOKUP(A6,[1]LISTADHERENT!A$5:H$60,3,0) -> DJUOMBESSY ANTOINE | C6: =IF(E6="ECHEC",0,IF(E6="",0,100000)) -> 100000 | D6: =IF(E6="ESPECES",0,0) -> 0 | E6: BANQUE | J6: =TONTNOV!F6+TONTNOV!G6 -> 0 | N6: =IF(O6=0,0,($C$38-O6)) -> 0
A7: AS201613 | B7: =VLOOKUP(A7,[1]LISTADHERENT!A$5:H$60,3,0) -> HOTCHO BENJAMIN | C7: =IF(E7="ECHEC",0,IF(E7="",0,100000)) -> 100000 | D7: =IF(E7="ESPECES",0,0) -> 0 | E7: BANQUE | J7: =TONTNOV!F7+TONTNOV!G7 -> 0 | N7: =IF(O7=0,0,($C$38-O7)) -> 0
A8: AS201619 | B8: =VLOOKUP(A8,[1]LISTADHERENT!A$5:H$60,3,0) -> KOUATCHO MESSACK | C8: =IF(E8="ECHEC",0,IF(E8="",0,100000)) -> 100000 | D8: =IF(E8="ESPECES",0,0) -> 0 | E8: BANQUE | J8: =TONTNOV!F8+TONTNOV!G8 -> 153500 | K8: BANQUE | N8: =IF(O8=0,0,($C$38-O8)) -> 1250000 | O8: 250000 | P8: 43814
A9: AS201617 | B9: =VLOOKUP(A9,[1]LISTADHERENT!A$5:H$60,3,0) -> KOUAMOU MOISE | C9: =IF(E9="ECHEC",0,IF(E9="",0,100000)) -> 100000 | D9: =IF(E9="ESPECES",0,0) -> 0 | E9: BANQUE | J9: =TONTNOV!F9+TONTNOV!G9 -> 0 | N9: =IF(O9=0,0,($C$38-O9)) -> 0
A10: AS201649 | B10: =VLOOKUP(A10,[1]LISTADHERENT!A$5:H$60,3,0) -> MBOGNING TUGMA GUY | C10: =IF(E10="ECHEC",0,IF(E10="",0,100000)) -> 100000 | D10: =IF(E10="ESPECES",0,0) -> 0 | E10: BANQUE | J10: =TONTNOV!F10+TONTNOV!G10 -> 208000 | K10: BANQUE | N10: =IF(O10=0,0,($C$38-O10)) -> 0
A11: AS201649 | B11: =VLOOKUP(A11,[1]LISTADHERENT!A$5:H$60,3,0) -> MBOGNING TUGMA GUY | C11: =IF(E11="ECHEC",0,IF(E11="",0,100000)) -> 100000 | D11: =IF(E11="ESPECES",0,0) -> 0 | E11: BANQUE | J11: =TONTNOV!F11+TONTNOV!G11 -> 0 | N11: =IF(O11=0,0,($C$38-O11)) -> 0
A12: AS201639 | B12: =VLOOKUP(A12,[1]LISTADHERENT!A$5:H$60,3,0) -> NANGUEN MARTIN | C12: =IF(E12="ECHEC",0,IF(E12="",0,100000)) -> 100000 | D12: =IF(E12="ESPECES",0,0) -> 0 | E12: BANQUE | J12: =TONTNOV!F12+TONTNOV!G12 -> 0 | N12: =IF(O12=0,0,($C$38-O12)) -> 0
A13: AS201622 | B13: =VLOOKUP(A13,[1]LISTADHERENT!A$5:H$60,3,0) -> NDJOMO ETIENNE | C13: =IF(E13="ECHEC",0,IF(E13="",0,100000)) -> 100000 | D13: =IF(E13="ESPECES",0,0) -> 0 | E13: BANQUE | J13: =TONTNOV!F13+TONTNOV!G13 -> 0 | N13: =IF(O13=0,0,($C$38-O13)) -> 0
A14: AS201624 | B14: =VLOOKUP(A14,[1]LISTADHERENT!A$5:H$60,3,0) -> NGONDIEP CLAUDE | C14: =IF(E14="ECHEC",0,IF(E14="",0,100000)) -> 100000 | D14: =IF(E14="ESPECES",0,0) -> 0 | E14: BANQUE | J14: =TONTNOV!F14+TONTNOV!G14 -> 0 | N14: =IF(O14=0,0,($C$38-O14)) -> 0
A15: AS201614 | B15: =VLOOKUP(A15,[1]LISTADHERENT!A$5:H$60,3,0) -> NKEHE DAVID | C15: =IF(E15="ECHEC",0,IF(E15="",0,100000)) -> 100000 | D15: =IF(E15="ESPECES",0,0) -> 0 | E15: BANQUE | J15: =TONTNOV!F15+TONTNOV!G15 -> 0 | N15: =IF(O15=0,0,($C$38-O15)) -> 0
A16: AS201629 | B16: =VLOOKUP(A16,[1]LISTADHERENT!A$5:H$60,3,0) -> NKEPSEU DIEUDONNE | C16: =IF(E16="ECHEC",0,IF(E16="",0,100000)) -> 100000 | D16: =IF(E16="ESPECES",0,0) -> 0 | E16: ESPECES | J16: =TONTNOV!F16+TONTNOV!G16 -> 0 | N16: =IF(O16=0,0,($C$38-O16)) -> 0
A17: AS201636 | B17: =VLOOKUP(A17,[1]LISTADHERENT!A$5:H$60,3,0) -> SIMO FONGANG ERIC | C17: =IF(E17="ECHEC",0,IF(E17="",0,100000)) -> 100000 | D17: =IF(E17="ESPECES",0,0) -> 0 | E17: ESPECES | J17: =TONTNOV!F17+TONTNOV!G17 -> 0 | N17: =IF(O17=0,0,($C$38-O17)) -> 1255000 | O17: 245000 | P17: 43814
A18: AS201636 | B18: =VLOOKUP(A18,[1]LISTADHERENT!A$5:H$60,3,0) -> SIMO FONGANG ERIC | C18: =IF(E18="ECHEC",0,IF(E18="",0,100000)) -> 100000 | D18: =IF(E18="ESPECES",0,0) -> 0 | E18: ESPECES | J18: =TONTNOV!F18+TONTNOV!G18 -> 0 | N18: =IF(O18=0,0,($C$38-O18)) -> 0
A19: AS201637 | B19: =VLOOKUP(A19,[1]LISTADHERENT!A$5:H$60,3,0) -> SIME MATHIEU | C19: =IF(E19="ECHEC",0,IF(E19="",0,100000)) -> 100000 | D19: =IF(E19="ESPECES",0,0) -> 0 | E19: BANQUE | J19: =TONTNOV!F19+TONTNOV!G19 -> 0 | N19: =IF(O19=0,0,($C$38-O19)) -> 0
A20: AS201637 | B20: =VLOOKUP(A20,[1]LISTADHERENT!A$5:H$60,3,0) -> SIME MATHIEU | C20: =IF(E20="ECHEC",0,IF(E20="",0,100000)) -> 100000 | D20: =IF(E20="ESPECES",0,0) -> 0 | E20: BANQUE | J20: =TONTNOV!F20+TONTNOV!G20 -> 0 | N20: =IF(O20=0,0,($C$38-O20)) -> 0
A21: AS201641 | B21: =VLOOKUP(A21,[1]LISTADHERENT!A$5:H$60,3,0) -> TCHOUAMOU MATHIEU | C21: =IF(E21="ECHEC",0,IF(E21="",0,100000)) -> 100000 | D21: =IF(E21="ESPECES",0,0) -> 0 | E21: BANQUE | J21: =TONTNOV!F21+TONTNOV!G21 -> 0 | N21: =IF(O21=0,0,($C$38-O21)) -> 0
A22: AS201644 | B22: =VLOOKUP(A22,[1]LISTADHERENT!A$5:H$60,3,0) -> TIEYAM ERNEST | C22: =IF(E22="ECHEC",0,IF(E22="",0,100000)) -> 100000 | D22: =IF(E22="ESPECES",0,0) -> 0 | E22: BANQUE | J22: =TONTNOV!F22+TONTNOV!G22 -> 213000 | K22: ESPECES | N22: =IF(O22=0,0,($C$38-O22)) -> 0
A23: AS201647 | B23: =VLOOKUP(A23,[1]LISTADHERENT!A$5:H$60,3,0) -> YOUMBI EMMANUEL | C23: =IF(E23="ECHEC",0,IF(E23="",0,100000)) -> 100000 | D23: =IF(E23="ESPECES",0,0) -> 0 | E23: BANQUE | J23: =TONTNOV!F23+TONTNOV!G23 -> 0 | N23: =IF(O23=0,0,($C$38-O23)) -> 0
A25: TOTAL | C25: =SUM(C6:C24) -> 1800000 | D25: =SUM(D6:D24) -> 0 | F25: =SUM(F6:F24) -> 0 | G25: =SUM(G6:G24) -> 0 | J25: =SUM(J6:J24) -> 574500 | N25: =SUM(N6:N24) -> 2505000 | O25: =SUM(O6:O24) -> 495000
C27: TONTINE | D27: REMBOURSEMENT PETIT LOT | E27: VENTE PETIT LOT | F27: VENTE LOT PRINCIPAL | G27: SOLDE EN CAISSE | K27: TONTINE + REMB + INTERET VENTE | L27: =C25+D32+O25+30500+100000 -> 3000000
K28: TONTINE | L28: =IF(L27>=3000000,1500000*2,1500000) -> 3000000
B29: ESPECES | C29: =SUMIFS(C6:C23,E6:E23,"ESPECES") -> 300000 | D29: =SUMIFS(J6:J23,K6:K23,"ESPECES") -> 213000 | E29: =SUMIFS(F6:F23,H6:H23,"ESPECES") -> 0 | F29: =SUMIFS(N6:N23,L6:L23,"ESPECES") -> 0 | G29: =C29+D29-E29-F29 -> 513000 | K29: PETIT LOT | L29: =L27-L28 -> 0
B30: BANQUE | C30: =SUMIFS(C6:C23,E6:E23,"BANQUE") -> 1500000 | D30: =SUMIFS(J6:J23,K6:K23,"BANQUE") -> 361500 | E30: =SUMIFS(F6:F23,H6:H23,"BANQUE") -> 0 | F30: =SUMIFS(N6:N23,L6:L23,"BANQUE") -> 0 | G30: =C30+D30-E30-F30 -> 1861500 | K30: RESTE | L30: 0
B32: TOTAL | C32: =C29+C30 -> 1800000 | D32: =D29+D30 -> 574500 | E32: =E29+E30 -> 0 | F32: =F29+F30 -> 0 | G32: =G29+G30 -> 2374500 | K32: ECHEC TONTINE | L32: 0
K33: ECHEC REMBOURSEMENT | L33: 0
B35: INTERET LOT PRINCIPAL | C35: =O25 -> 495000
B36: INTERET PETIT LOT | C36: =+G25 -> 0
B38: MONTANT TONTINE | C38: 1500000
B39: MONTANT PETIT LOT A VENDRE | C39: =L29 -> 0

Sheet TONTJANV
A1: ASSOCIATION | B1: ASELBY
A2: ANNEE | B2: 2019/2020
A3: TONTINE | B3: 100000
C4: 43848
A5: MATRICULE | B5: NOM ET PRENOM | C5: MONTANT TONTINE | D5: PENALITE | E5: MODE VERSEMENT TONTINE | F5: VENTE PETIT LOT | G5: INTERET PETIT LOT | H5: MODE VERSEMENT VENTE PETIT LOT | I5: NUMERO CHEQUE | J5: REMBOURSEMENT | K5: MODE VERSEMENT REMBOURSEMENT | L5: MODE VERSEMENT TONTINE PRINCIPAL | M5: NUMERO CHEQUE | N5: MONTANT TONTINE LOT PRINCIPAL | O5: INTERET LOT PRINCIPAL | P5: DATE VENTE
A6: AS201608 | B6: =VLOOKUP(A6,[1]LISTADHERENT!A$5:H$60,3,0) -> DJUOMBESSY ANTOINE | C6: =IF(E6="ECHEC",0,IF(E6="",0,100000)) -> 100000 | D6: =IF(E6="ESPECES",0,0) -> 0 | E6: BANQUE | J6: =TONTDEC!F6+TONTDEC!G6 -> 0 | N6: =IF(O6=0,0,($C$38-O6)) -> 0
A7: AS201613 | B7: =VLOOKUP(A7,[1]LISTADHERENT!A$5:H$60,3,0) -> HOTCHO BENJAMIN | C7: =IF(E7="ECHEC",0,IF(E7="",0,100000)) -> 100000 | D7: =IF(E7="ESPECES",0,0) -> 0 | E7: BANQUE | J7: =TONTDEC!F7+TONTDEC!G7 -> 0 | N7: =IF(O7=0,0,($C$38-O7)) -> 0
A8: AS201619 | B8: =VLOOKUP(A8,[1]LISTADHERENT!A$5:H$60,3,0) -> KOUATCHO MESSACK | C8: =IF(E8="ECHEC",0,IF(E8="",0,100000)) -> 100000 | D8: =IF(E8="ESPECES",0,0) -> 0 | E8: BANQUE | F8: 100000 | G8: 4000 | H8: ESPECES | J8: =TONTDEC!F8+TONTDEC!G8 -> 0 | N8: =IF(O8=0,0,($C$38-O8)) -> 0
A9: AS201617 | B9: =VLOOKUP(A9,[1]LISTADHERENT!A$5:H$60,3,0) -> KOUAMOU MOISE | C9: =IF(E9="ECHEC",0,IF(E9="",0,100000)) -> 100000 | D9: =IF(E9="ESPECES",0,0) -> 0 | E9: BANQUE | J9: =TONTDEC!F9+TONTDEC!G9 -> 0 | N9: =IF(O9=0,0,($C$38-O9)) -> 0
A10: AS201649 | B10: =VLOOKUP(A10,[1]LISTADHERENT!A$5:H$60,3,0) -> MBOGNING TUGMA GUY | C10: =IF(E10="ECHEC",0,IF(E10="",0,100000)) -> 100000 | D10: =IF(E10="ESPECES",0,0) -> 0 | E10: BANQUE | J10: =TONTDEC!F10+TONTDEC!G10 -> 0 | N10: =IF(O10=0,0,($C$38-O10)) -> 1270000 | O10: 230000
A11: AS201649 | B11: =VLOOKUP(A11,[1]LISTADHERENT!A$5:H$60,3,0) -> MBOGNING TUGMA GUY | C11: =IF(E11="ECHEC",0,IF(E11="",0,100000)) -> 100000 | D11: =IF(E11="ESPECES",0,0) -> 0 | E11: BANQUE | J11: =TONTDEC!F11+TONTDEC!G11 -> 0 | N11: =IF(O11=0,0,($C$38-O11)) -> 0
A12: AS201639 | B12: =VLOOKUP(A12,[1]LISTADHERENT!A$5:H$60,3,0) -> NANGUEN MARTIN | C12: =IF(E12="ECHEC",0,IF(E12="",0,100000)) -> 100000 | D12: =IF(E12="ESPECES",0,0) -> 0 | E12: BANQUE | J12: =TONTDEC!F12+TONTDEC!G12 -> 0 | N12: =IF(O12=0,0,($C$38-O12)) -> 0
A13: AS201622 | B13: =VLOOKUP(A13,[1]LISTADHERENT!A$5:H$60,3,0) -> NDJOMO ETIENNE | C13: =IF(E13="ECHEC",0,IF(E13="",0,100000)) -> 100000 | D13: =IF(E13="ESPECES",0,0) -> 0 | E13: BANQUE | J13: =TONTDEC!F13+TONTDEC!G13 -> 0 | N13: =IF(O13=0,0,($C$38-O13)) -> 0
A14: AS201624 | B14: =VLOOKUP(A14,[1]LISTADHERENT!A$5:H$60,3,0) -> NGONDIEP CLAUDE | C14: =IF(E14="ECHEC",0,IF(E14="",0,100000)) -> 100000 | D14: =IF(E14="ESPECES",0,0) -> 0 | E14: BANQUE | F14: 99500 | G14: 4000 | H14: ESPECES | J14: =TONTDEC!F14+TONTDEC!G14 -> 0 | N14: =IF(O14=0,0,($C$38-O14)) -> 0
A15: AS201614 | B15: =VLOOKUP(A15,[1]LISTADHERENT!A$5:H$60,3,0) -> NKEHE DAVID | C15: =IF(E15="ECHEC",0,IF(E15="",0,100000)) -> 100000 | D15: =IF(E15="ESPECES",0,0) -> 0 | E15: BANQUE | F15: 100000 | G15: 6000 | H15: ESPECES | J15: =TONTDEC!F15+TONTDEC!G15 -> 0 | N15: =IF(O15=0,0,($C$38-O15)) -> 0
A16: AS201629 | B16: =VLOOKUP(A16,[1]LISTADHERENT!A$5:H$60,3,0) -> NKEPSEU DIEUDONNE | C16: =IF(E16="ECHEC",0,IF(E16="",0,100000)) -> 100000 | D16: =IF(E16="ESPECES",0,0) -> 0 | E16: BANQUE | J16: =TONTDEC!F16+TONTDEC!G16 -> 0 | N16: =IF(O16=0,0,($C$38-O16)) -> 0
A17: AS201636 | B17: =VLOOKUP(A17,[1]LISTADHERENT!A$5:H$60,3,0) -> SIMO FONGANG ERIC | C17: =IF(E17="ECHEC",0,IF(E17="",0,100000)) -> 100000 | D17: =IF(E17="ESPECES",0,0) -> 0 | E17: BANQUE | J17: =TONTDEC!F17+TONTDEC!G17 -> 0 | N17: =IF(O17=0,0,($C$38-O17)) -> 0
A18: AS201636 | B18: =VLOOKUP(A18,[1]LISTADHERENT!A$5:H$60,3,0) -> SIMO FONGANG ERIC | C18: =IF(E18="ECHEC",0,IF(E18="",0,100000)) -> 100000 | D18: =IF(E18="ESPECES",0,0) -> 0 | E18: BANQUE | J18: =TONTDEC!F18+TONTDEC!G18 -> 0 | N18: =IF(O18=0,0,($C$38-O18)) -> 0
A19: AS201637 | B19: =VLOOKUP(A19,[1]LISTADHERENT!A$5:H$60,3,0) -> SIME MATHIEU | C19: =IF(E19="ECHEC",0,IF(E19="",0,100000)) -> 100000 | D19: =IF(E19="ESPECES",0,0) -> 0 | E19: BANQUE | J19: =TONTDEC!F19+TONTDEC!G19 -> 0 | N19: =IF(O19=0,0,($C$38-O19)) -> 0
A20: AS201637 | B20: =VLOOKUP(A20,[1]LISTADHERENT!A$5:H$60,3,0) -> SIME MATHIEU | C20: =IF(E20="ECHEC",0,IF(E20="",0,100000)) -> 100000 | D20: =IF(E20="ESPECES",0,0) -> 0 | E20: BANQUE | J20: =TONTDEC!F20+TONTDEC!G20 -> 0 | N20: =IF(O20=0,0,($C$38-O20)) -> 0
A21: AS201641 | B21: =VLOOKUP(A21,[1]LISTADHERENT!A$5:H$60,3,0) -> TCHOUAMOU MATHIEU | C21: =IF(E21="ECHEC",0,IF(E21="",0,100000)) -> 100000 | D21: =IF(E21="ESPECES",0,0) -> 0 | E21: BANQUE | J21: =TONTDEC!F21+TONTDEC!G21 -> 0 | N21: =IF(O21=0,0,($C$38-O21)) -> 0
A22: AS201644 | B22: =VLOOKUP(A22,[1]LISTADHERENT!A$5:H$60,3,0) -> TIEYAM ERNEST | C22: =IF(E22="ECHEC",0,IF(E22="",0,100000)) -> 100000 | D22: =IF(E22="ESPECES",0,0) -> 0 | E22: BANQUE | F22: 200000 | G22: 10000 | H22: ESPECES | J22: =TONTDEC!F22+TONTDEC!G22 -> 0 | N22: =IF(O22=0,0,($C$38-O22)) -> 0
A23: AS201647 | B23: =VLOOKUP(A23,[1]LISTADHERENT!A$5:H$60,3,0) -> YOUMBI EMMANUEL | C23: =IF(E23="ECHEC",0,IF(E23="",0,100000)) -> 100000 | D23: =IF(E23="ESPECES",0,0) -> 0 | E23: BANQUE | J23: =TONTDEC!F23+TONTDEC!G23 -> 0 | N23: =IF(O23=0,0,($C$38-O23)) -> 0
A25: TOTAL | C25: =SUM(C6:C24) -> 1800000 | D25: =SUM(D6:D24) -> 0 | F25: =SUM(F6:F24) -> 499500 | G25: =SUM(G6:G24) -> 24000 | J25: =SUM(J6:J24) -> 0 | N25: =SUM(N6:N24) -> 1270000 | O25: =SUM(O6:O24) -> 230000
C27: TONTINE | D27: REMBOURSEMENT PETIT LOT | E27: VENTE PETIT LOT | F27: VENTE LOT PRINCIPAL | G27: SOLDE EN CAISSE | K27: TONTINE + REMB + INTERET VENTE | L27: =C25+D32+O25 -> 2030000
K28: TONTINE | L28: =IF(L27>=3000000,1500000*2,1500000) -> 1500000
B29: ESPECES | C29: =SUMIFS(C6:C23,E6:E23,"ESPECES") -> 0 | D29: =SUMIFS(J6:J23,K6:K23,"ESPECES") -> 0 | E29: =SUMIFS(F6:F23,H6:H23,"ESPECES") -> 499500 | F29: =SUMIFS(N6:N23,L6:L23,"ESPECES") -> 0 | G29: =C29+D29-E29-F29 -> -499500 | K29: PETIT LOT | L29: =L27-L28-30500 -> 499500
B30: BANQUE | C30: =SUMIFS(C6:C23,E6:E23,"BANQUE") -> 1800000 | D30: =SUMIFS(J6:J23,K6:K23,"BANQUE") -> 0 | E30: =SUMIFS(F6:F23,H6:H23,"BANQUE") -> 0 | F30: =SUMIFS(N6:N23,L6:L23,"BANQUE") -> 0 | G30: =C30+D30-E30-F30 -> 1800000 | K30: RESTE | L30: =L29-F25 -> 0
B32: TOTAL | C32: =C29+C30 -> 1800000 | D32: =D29+D30 -> 0 | E32: =E29+E30 -> 499500 | F32: =F29+F30 -> 0 | G32: =G29+G30 -> 1300500
K33: ECHEC TONTINE | L33: 0
K34: ECHEC REMBOURSEMENT | L34: 0
B35: INTERET LOT PRINCIPAL | C35: =O25 -> 230000
B36: INTERET PETIT LOT | C36: =+G25 -> 24000
B38: MONTANT TONTINE | C38: 1500000
B39: MONTANT PETIT LOT A VENDRE | C39: =L29 -> 499500

Sheet TONTFEV
A1: ASSOCIATION | B1: ASELBY
A2: ANNEE | B2: 2019/2020
A3: TONTINE | B3: 100000
C4: 43877
A5: MATRICULE | B5: NOM ET PRENOM | C5: MONTANT TONTINE | D5: PENALITE | E5: MODE VERSEMENT TONTINE | F5: VENTE PETIT LOT | G5: INTERET PETIT LOT | H5: MODE VERSEMENT VENTE PETIT LOT | I5: NUMERO CHEQUE | J5: REMBOURSEMENT | K5: MODE VERSEMENT REMBOURSEMENT | L5: MODE VERSEMENT TONTINE PRINCIPAL | M5: NUMERO CHEQUE | N5: MONTANT TONTINE LOT PRINCIPAL | O5: INTERET LOT PRINCIPAL | P5: DATE VENTE
A6: AS201608 | B6: =VLOOKUP(A6,[1]LISTADHERENT!A$5:H$60,3,0) -> DJUOMBESSY ANTOINE | C6: =IF(E6="ECHEC",0,IF(E6="",0,100000)) -> 100000 | D6: =IF(E6="ESPECES",0,0) -> 0 | E6: BANQUE | J6: =TONTJANV!F6+TONTJANV!G6 -> 0 | N6: =IF(O6=0,0,($C$38-O6)) -> 0
A7: AS201613 | B7: =VLOOKUP(A7,[1]LISTADHERENT!A$5:H$60,3,0) -> HOTCHO BENJAMIN | C7: =IF(E7="ECHEC",0,IF(E7="",0,100000)) -> 100000 | D7: =IF(E7="ESPECES",0,0) -> 0 | E7: BANQUE | J7: =TONTJANV!F7+TONTJANV!G7 -> 0 | N7: =IF(O7=0,0,($C$38-O7)) -> 0
A8: AS201619 | B8: =VLOOKUP(A8,[1]LISTADHERENT!A$5:H$60,3,0) -> KOUATCHO MESSACK | C8: =IF(E8="ECHEC",0,IF(E8="",0,100000)) -> 100000 | D8: =IF(E8="ESPECES",0,0) -> 0 | E8: BANQUE | F8: 100000 | G8: 3000 | J8: =TONTJANV!F8+TONTJANV!G8 -> 104000 | K8: ESPECES | N8: =IF(O8=0,0,($C$38-O8)) -> 0
A9: AS201617 | B9: =VLOOKUP(A9,[1]LISTADHERENT!A$5:H$60,3,0) -> KOUAMOU MOISE | C9: =IF(E9="ECHEC",0,IF(E9="",0,100000)) -> 100000 | D9: =IF(E9="ESPECES",0,0) -> 0 | E9: BANQUE | J9: =TONTJANV!F9+TONTJANV!G9 -> 0 | N9: =IF(O9=0,0,($C$38-O9)) -> 0
A10: AS201649 | B10: =VLOOKUP(A10,[1]LISTADHERENT!A$5:H$60,3,0) -> MBOGNING TUGMA GUY | C10: =IF(E10="ECHEC",0,IF(E10="",0,100000)) -> 100000 | D10: =IF(E10="ESPECES",0,0) -> 0 | E10: BANQUE | F10: 200000 | G10: 5000 | J10: =TONTJANV!F10+TONTJANV!G10 -> 0 | N10: =IF(O10=0,0,($C$38-O10)) -> 0
A11: AS201649 | B11: =VLOOKUP(A11,[1]LISTADHERENT!A$5:H$60,3,0) -> MBOGNING TUGMA GUY | C11: =IF(E11="ECHEC",0,IF(E11="",0,100000)) -> 100000 | D11: =IF(E11="ESPECES",0,0) -> 0 | E11: BANQUE | J11: =TONTJANV!F11+TONTJANV!G11 -> 0 | N11: =IF(O11=0,0,($C$38-O11)) -> 0
A12: AS201639 | B12: =VLOOKUP(A12,[1]LISTADHERENT!A$5:H$60,3,0) -> NANGUEN MARTIN | C12: =IF(E12="ECHEC",0,IF(E12="",0,100000)) -> 100000 | D12: =IF(E12="ESPECES",0,0) -> 0 | E12: BANQUE | J12: =TONTJANV!F12+TONTJANV!G12 -> 0 | N12: =IF(O12=0,0,($C$38-O12)) -> 0
A13: AS201622 | B13: =VLOOKUP(A13,[1]LISTADHERENT!A$5:H$60,3,0) -> NDJOMO ETIENNE | C13: =IF(E13="ECHEC",0,IF(E13="",0,100000)) -> 100000 | D13: =IF(E13="ESPECES",0,0) -> 0 | E13: BANQUE | F13: 100000 | G13: 3000 | J13: =TONTJANV!F13+TONTJANV!G13 -> 0 | N13: =IF(O13=0,0,($C$38-O13)) -> 0
A14: AS201624 | B14: =VLOOKUP(A14,[1]LISTADHERENT!A$5:H$60,3,0) -> NGONDIEP CLAUDE | C14: =IF(E14="ECHEC",0,IF(E14="",0,100000)) -> 100000 | D14: =IF(E14="ESPECES",0,0) -> 0 | E14: BANQUE | J14: =TONTJANV!F14+TONTJANV!G14 -> 103500 | K14: ESPECES | N14: =IF(O14=0,0,($C$38-O14)) -> 0
A15: AS201614 | B15: =VLOOKUP(A15,[1]LISTADHERENT!A$5:H$60,3,0) -> NKEHE DAVID | C15: =IF(E15="ECHEC",0,IF(E15="",0,100000)) -> 100000 | D15: =IF(E15="ESPECES",0,0) -> 0 | E15: ESPECES | F15: 213500 | G15: 4000 | J15: =TONTJANV!F15+TONTJANV!G15 -> 106000 | K15: ESPECES | N15: =IF(O15=0,0,($C$38-O15)) -> 0
A16: AS201629 | B16: =VLOOKUP(A16,[1]LISTADHERENT!A$5:H$60,3,0) -> NKEPSEU DIEUDONNE | C16: =IF(E16="ECHEC",0,IF(E16="",0,100000)) -> 100000 | D16: =IF(E16="ESPECES",0,0) -> 0 | E16: BANQUE | F16: 100000 | G16: 2000 | J16: =TONTJANV!F16+TONTJANV!G16 -> 0 | N16: =IF(O16=0,0,($C$38-O16)) -> 1400000 | O16: 100000
A17: AS201636 | B17: =VLOOKUP(A17,[1]LISTADHERENT!A$5:H$60,3,0) -> SIMO FONGANG ERIC | C17: =IF(E17="ECHEC",0,IF(E17="",0,100000)) -> 100000 | D17: =IF(E17="ESPECES",0,0) -> 0 | E17: BANQUE | J17: =TONTJANV!F17+TONTJANV!G17 -> 0 | N17: =IF(O17=0,0,($C$38-O17)) -> 0
A18: AS201636 | B18: =VLOOKUP(A18,[1]LISTADHERENT!A$5:H$60,3,0) -> SIMO FONGANG ERIC | C18: =IF(E18="ECHEC",0,IF(E18="",0,100000)) -> 100000 | D18: =IF(E18="ESPECES",0,0) -> 0 | E18: BANQUE | J18: =TONTJANV!F18+TONTJANV!G18 -> 0 | N18: =IF(O18=0,0,($C$38-O18)) -> 0
A19: AS201637 | B19: =VLOOKUP(A19,[1]LISTADHERENT!A$5:H$60,3,0) -> SIME MATHIEU | C19: =IF(E19="ECHEC",0,IF(E19="",0,100000)) -> 100000 | D19: =IF(E19="ESPECES",0,0) -> 0 | E19: BANQUE | J19: =TONTJANV!F19+TONTJANV!G19 -> 0 | N19: =IF(O19=0,0,($C$38-O19)) -> 0
A20: AS201637 | B20: =VLOOKUP(A20,[1]LISTADHERENT!A$5:H$60,3,0) -> SIME MATHIEU | C20: =IF(E20="ECHEC",0,IF(E20="",0,100000)) -> 100000 | D20: =IF(E20="ESPECES",0,0) -> 0 | E20: BANQUE | J20: =TONTJANV!F20+TONTJANV!G20 -> 0 | N20: =IF(O20=0,0,($C$38-O20)) -> 0
A21: AS201641 | B21: =VLOOKUP(A21,[1]LISTADHERENT!A$5:H$60,3,0) -> TCHOUAMOU MATHIEU | C21: =IF(E21="ECHEC",0,IF(E21="",0,100000)) -> 100000 | D21: =IF(E21="ESPECES",0,0) -> 0 | E21: BANQUE | J21: =TONTJANV!F21+TONTJANV!G21 -> 0 | N21: =IF(O21=0,0,($C$38-O21)) -> 0
A22: AS201644 | B22: =VLOOKUP(A22,[1]LISTADHERENT!A$5:H$60,3,0) -> TIEYAM ERNEST | C22: =IF(E22="ECHEC",0,IF(E22="",0,100000)) -> 100000 | D22: =IF(E22="ESPECES",0,0) -> 0 | E22: BANQUE | F22: 210000 | G22: 20000 | J22: =TONTJANV!F22+TONTJANV!G22 -> 210000 | K22: ECHEC | N22: =IF(O22=0,0,($C$38-O22)) -> 0
A23: AS201647 | B23: =VLOOKUP(A23,[1]LISTADHERENT!A$5:H$60,3,0) -> YOUMBI EMMANUEL | C23: =IF(E23="ECHEC",0,IF(E23="",0,100000)) -> 100000 | D23: =IF(E23="ESPECES",0,0) -> 0 | E23: BANQUE | J23: =TONTJANV!F23+TONTJANV!G23 -> 0 | N23: =IF(O23=0,0,($C$38-O23)) -> 0
A25: TOTAL | C25: =SUM(C6:C24) -> 1800000 | D25: =SUM(D6:D24) -> 0 | F25: =SUM(F6:F24) -> 923500 | G25: =SUM(G6:G24) -> 37000 | J25: =SUM(J6:J24) -> 523500 | N25: =SUM(N6:N24) -> 1400000 | O25: =SUM(O6:O24) -> 100000
C27: TONTINE | D27: REMBOURSEMENT PETIT LOT | E27: VENTE PETIT LOT | F27: VENTE LOT PRINCIPAL | G27: SOLDE EN CAISSE | K27: TONTINE + REMB + INTERET VENTE | L27: =C25+D32+O25 -> 2213500
K28: TONTINE | L28: =IF(L27>=3000000,1500000*2,1500000) -> 1500000
B29: ESPECES | C29: =SUMIFS(C6:C23,E6:E23,"ESPECES") -> 100000 | D29: =SUMIFS(J6:J23,K6:K23,"ESPECES") -> 313500 | E29: =SUMIFS(F6:F23,H6:H23,"ESPECES") -> 0 | F29: =SUMIFS(N6:N23,L6:L23,"ESPECES") -> 0 | G29: =C29+D29-E29-F29 -> 413500 | K29: PETIT LOT | L29: =L27-L28 -> 713500
B30: BANQUE | C30: =SUMIFS(C6:C23,E6:E23,"BANQUE") -> 1700000 | D30: =SUMIFS(J6:J23,K6:K23,"BANQUE") -> 0 | E30: =SUMIFS(F6:F23,H6:H23,"BANQUE") -> 0 | F30: =SUMIFS(N6:N23,L6:L23,"BANQUE") -> 0 | G30: =C30+D30-E30-F30 -> 1700000 | K30: RESTE | L30: =L29-F25 -> -210000
B32: TOTAL | C32: =C29+C30 -> 1800000 | D32: =D29+D30 -> 313500 | E32: =E29+E30 -> 0 | F32: =F29+F30 -> 0 | G32: =G29+G30 -> 2113500 | K32: ECHEC TONTINE | L32: 0
K33: ECHEC REMBOURSEMENT | L33: 210000 | M33: TYAM ERNEST
B35: INTERET LOT PRINCIPAL | C35: =O25 -> 100000
B36: INTERET PETIT LOT | C36: =+G25 -> 37000
B38: MONTANT TONTINE | C38: 1500000
B39: MONTANT PETIT LOT A VENDRE | C39: =L29 -> 713500

Sheet TONTMARS
A1: ASSOCIATION | B1: ASELBY
A2: ANNEE | B2: 2019/2020
A3: TONTINE | B3: 100000
C4: 43905
A5: MATRICULE | B5: NOM ET PRENOM | C5: MONTANT TONTINE | D5: PENALITE | E5: MODE VERSEMENT TONTINE | F5: VENTE PETIT LOT | G5: INTERET PETIT LOT | H5: MODE VERSEMENT VENTE PETIT LOT | I5: NUMERO CHEQUE | J5: REMBOURSEMENT | K5: MODE VERSEMENT REMBOURSEMENT | L5: MODE VERSEMENT TONTINE PRINCIPAL | M5: NUMERO CHEQUE | N5: MONTANT TONTINE LOT PRINCIPAL | O5: INTERET LOT PRINCIPAL | P5: DATE VENTE
A6: AS201608 | B6: =VLOOKUP(A6,[1]LISTADHERENT!A$5:H$60,3,0) -> DJUOMBESSY ANTOINE | C6: =IF(E6="ECHEC",0,IF(E6="",0,100000)) -> 100000 | D6: =IF(E6="ESPECES",0,0) -> 0 | E6: BANQUE | J6: =TONTFEV!F6+TONTFEV!G6 -> 0 | N6: =IF(O6=0,0,($C$38-O6)) -> 0
A7: AS201613 | B7: =VLOOKUP(A7,[1]LISTADHERENT!A$5:H$60,3,0) -> HOTCHO BENJAMIN | C7: =IF(E7="ECHEC",0,IF(E7="",0,100000)) -> 100000 | D7: =IF(E7="ESPECES",0,0) -> 0 | E7: BANQUE | J7: =TONTFEV!F7+TONTFEV!G7 -> 0 | N7: =IF(O7=0,0,($C$38-O7)) -> 0
A8: AS201619 | B8: =VLOOKUP(A8,[1]LISTADHERENT!A$5:H$60,3,0) -> KOUATCHO MESSACK | C8: =IF(E8="ECHEC",0,IF(E8="",0,100000)) -> 100000 | D8: =IF(E8="ESPECES",0,0) -> 0 | E8: BANQUE | F8: 200000 | G8: 2500 | H8: BANQUE | J8: =TONTFEV!F8+TONTFEV!G8 -> 103000 | K8: BANQUE | N8: =IF(O8=0,0,($C$38-O8)) -> 0
A9: AS201617 | B9: =VLOOKUP(A9,[1]LISTADHERENT!A$5:H$60,3,0) -> KOUAMOU MOISE | C9: =IF(E9="ECHEC",0,IF(E9="",0,100000)) -> 100000 | D9: =IF(E9="ESPECES",0,0) -> 0 | E9: BANQUE | J9: =TONTFEV!F9+TONTFEV!G9 -> 0 | N9: =IF(O9=0,0,($C$38-O9)) -> 1365000 | O9: 135000
A10: AS201649 | B10: =VLOOKUP(A10,[1]LISTADHERENT!A$5:H$60,3,0) -> MBOGNING TUGMA GUY | C10: =IF(E10="ECHEC",0,IF(E10="",0,100000)) -> 100000 | D10: =IF(E10="ESPECES",0,0) -> 0 | E10: BANQUE | F10: 100000 | G10: 1000 | H10: BANQUE | J10: =TONTFEV!F10+TONTFEV!G10 -> 205000 | K10: BANQUE | N10: =IF(O10=0,0,($C$38-O10)) -> 0
A11: AS201649 | B11: =VLOOKUP(A11,[1]LISTADHERENT!A$5:H$60,3,0) -> MBOGNING TUGMA GUY | C11: =IF(E11="ECHEC",0,IF(E11="",0,100000)) -> 100000 | D11: =IF(E11="ESPECES",0,0) -> 0 | E11: BANQUE | J11: =TONTFEV!F11+TONTFEV!G11 -> 0 | N11: =IF(O11=0,0,($C$38-O11)) -> 0
A12: AS201639 | B12: =VLOOKUP(A12,[1]LISTADHERENT!A$5:H$60,3,0) -> NANGUEN MARTIN | C12: =IF(E12="ECHEC",0,IF(E12="",0,100000)) -> 100000 | D12: =IF(E12="ESPECES",0,0) -> 0 | E12: BANQUE | J12: =TONTFEV!F12+TONTFEV!G12 -> 0 | N12: =IF(O12=0,0,($C$38-O12)) -> 0
A13: AS201622 | B13: =VLOOKUP(A13,[1]LISTADHERENT!A$5:H$60,3,0) -> NDJOMO ETIENNE | C13: =IF(E13="ECHEC",0,IF(E13="",0,100000)) -> 100000 | D13: =IF(E13="ESPECES",0,0) -> 0 | E13: BANQUE | F13: 100000 | G13: 1500 | H13: BANQUE | J13: =TONTFEV!F13+TONTFEV!G13 -> 103000 | K13: BANQUE | N13: =IF(O13=0,0,($C$38-O13)) -> 0
A14: AS201624 | B14: =VLOOKUP(A14,[1]LISTADHERENT!A$5:H$60,3,0) -> NGONDIEP CLAUDE | C14: =IF(E14="ECHEC",0,IF(E14="",0,100000)) -> 100000 | D14: =IF(E14="ESPECES",0,0) -> 0 | E14: BANQUE | J14: =TONTFEV!F14+TONTFEV!G14 -> 0 | N14: =IF(O14=0,0,($C$38-O14)) -> 0
A15: AS201614 | B15: =VLOOKUP(A15,[1]LISTADHERENT!A$5:H$60,3,0) -> NKEHE DAVID | C15: =IF(E15="ECHEC",0,IF(E15="",0,100000)) -> 100000 | D15: =IF(E15="ESPECES",0,0) -> 0 | E15: BANQUE | F15: 217500 | G15: 8000 | H15: ECHEC | J15: =TONTFEV!F15+TONTFEV!G15 -> 217500 | K15: ECHEC | N15: =IF(O15=0,0,($C$38-O15)) -> 0
A16: AS201629 | B16: =VLOOKUP(A16,[1]LISTADHERENT!A$5:H$60,3,0) -> NKEPSEU DIEUDONNE | C16: =IF(E16="ECHEC",0,IF(E16="",0,100000)) -> 100000 | D16: =IF(E16="ESPECES",0,0) -> 0 | E16: BANQUE | F16: 200000 | G16: 3000 | H16: BANQUE | J16: =TONTFEV!F16+TONTFEV!G16 -> 102000 | K16: BANQUE | N16: =IF(O16=0,0,($C$38-O16)) -> 0
A17: AS201636 | B17: =VLOOKUP(A17,[1]LISTADHERENT!A$5:H$60,3,0) -> SIMO FONGANG ERIC | C17: =IF(E17="ECHEC",0,IF(E17="",0,100000)) -> 100000 | D17: =IF(E17="ESPECES",0,0) -> 0 | E17: ESPECES | F17: 200000 | G17: 2500 | H17: BANQUE | J17: =TONTFEV!F17+TONTFEV!G17 -> 0 | N17: =IF(O17=0,0,($C$38-O17)) -> 0
A18: AS201636 | B18: =VLOOKUP(A18,[1]LISTADHERENT!A$5:H$60,3,0) -> SIMO FONGANG ERIC | C18: =IF(E18="ECHEC",0,IF(E18="",0,100000)) -> 100000 | D18: =IF(E18="ESPECES",0,0) -> 0 | E18: ESPECES | J18: =TONTFEV!F18+TONTFEV!G18 -> 0 | N18: =IF(O18=0,0,($C$38-O18)) -> 0
A19: AS201637 | B19: =VLOOKUP(A19,[1]LISTADHERENT!A$5:H$60,3,0) -> SIME MATHIEU | C19: =IF(E19="ECHEC",0,IF(E19="",0,100000)) -> 100000 | D19: =IF(E19="ESPECES",0,0) -> 0 | E19: BANQUE | J19: =TONTFEV!F19+TONTFEV!G19 -> 0 | N19: =IF(O19=0,0,($C$38-O19)) -> 0
A20: AS201637 | B20: =VLOOKUP(A20,[1]LISTADHERENT!A$5:H$60,3,0) -> SIME MATHIEU | C20: =IF(E20="ECHEC",0,IF(E20="",0,100000)) -> 100000 | D20: =IF(E20="ESPECES",0,0) -> 0 | E20: BANQUE | J20: =TONTFEV!F20+TONTFEV!G20 -> 0 | N20: =IF(O20=0,0,($C$38-O20)) -> 0
A21: AS201641 | B21: =VLOOKUP(A21,[1]LISTADHERENT!A$5:H$60,3,0) -> TCHOUAMOU MATHIEU | C21: =IF(E21="ECHEC",0,IF(E21="",0,100000)) -> 100000 | D21: =IF(E21="ESPECES",0,0) -> 0 | E21: BANQUE | F21: 200000 | G21: 2000 | H21: BANQUE | J21: =TONTFEV!F21+TONTFEV!G21 -> 0 | N21: =IF(O21=0,0,($C$38-O21)) -> 0
A22: AS201644 | B22: =VLOOKUP(A22,[1]LISTADHERENT!A$5:H$60,3,0) -> TIEYAM ERNEST | C22: =IF(E22="ECHEC",0,IF(E22="",0,100000)) -> 100000 | D22: =IF(E22="ESPECES",0,0) -> 0 | E22: BANQUE | F22: 200000 | G22: 2000 | H22: BANQUE | J22: =TONTFEV!F22+TONTFEV!G22 -> 230000 | K22: BANQUE | N22: =IF(O22=0,0,($C$38-O22)) -> 0
A23: AS201647 | B23: =VLOOKUP(A23,[1]LISTADHERENT!A$5:H$60,3,0) -> YOUMBI EMMANUEL | C23: =IF(E23="ECHEC",0,IF(E23="",0,100000)) -> 100000 | D23: =IF(E23="ESPECES",0,0) -> 0 | E23: BANQUE | J23: =TONTFEV!F23+TONTFEV!G23 -> 0 | N23: =IF(O23=0,0,($C$38-O23)) -> 0
A25: TOTAL | C25: =SUM(C6:C24) -> 1800000 | D25: =SUM(D6:D24) -> 0 | F25: =SUM(F6:F24) -> 1417500 | G25: =SUM(G6:G24) -> 22500 | J25: =SUM(J6:J24) -> 960500 | N25: =SUM(N6:N24) -> 1365000 | O25: =SUM(O6:O24) -> 135000
C27: TONTINE | D27: REMBOURSEMENT PETIT LOT | E27: VENTE PETIT LOT | F27: VENTE LOT PRINCIPAL | G27: SOLDE EN CAISSE | K27: TONTINE + REMB + INTERET VENTE | L27: =C25+D32+O25 -> 2678000
K28: TONTINE | L28: =IF(L27>=3000000,1500000*2,1500000) -> 1500000
B29: ESPECES | C29: =SUMIFS(C6:C23,E6:E23,"ESPECES") -> 200000 | D29: =SUMIFS(J6:J23,K6:K23,"ESPECES") -> 0 | E29: =SUMIFS(F6:F23,H6:H23,"ESPECES") -> 0 | F29: =SUMIFS(N6:N23,L6:L23,"ESPECES") -> 0 | G29: =C29+D29-E29-F29 -> 200000 | K29: PETIT LOT | L29: =L27-L28 -> 1178000
B30: BANQUE | C30: =SUMIFS(C6:C23,E6:E23,"BANQUE") -> 1600000 | D30: =SUMIFS(J6:J23,K6:K23,"BANQUE") -> 743000 | E30: =SUMIFS(F6:F23,H6:H23,"BANQUE") -> 1200000 | F30: =SUMIFS(N6:N23,L6:L23,"BANQUE") -> 0 | G30: =C30+D30-E30-F30 -> 1143000 | K30: RESTE | L30: =L29-F25 -> -239500
B32: TOTAL | C32: =C29+C30 -> 1800000 | D32: =D29+D30 -> 743000 | E32: =E29+E30 -> 1200000 | F32: =F29+F30 -> 0 | G32: =G29+G30 -> 1343000 | K32: ECHEC TONTINE | L32: 0
K33: ECHEC REMBOURSEMENT | L33: 217500 | M33: NKEHEP DAVID
B35: INTERET LOT PRINCIPAL | C35: =O25 -> 135000
B36: INTERET PETIT LOT | C36: =+G25 -> 22500
B38: MONTANT TONTINE | C38: 1500000
B39: MONTANT PETIT LOT A VENDRE | C39: =L29 -> 1178000

Sheet TONTAVRIL
A1: ASSOCIATION | B1: ASELBY
A2: ANNEE | B2: 2019/2020
A3: TONTINE | B3: 100000
C4: 43940
A5: MATRICULE | B5: NOM ET PRENOM | C5: MONTANT TONTINE | D5: PENALITE | E5: MODE VERSEMENT TONTINE | F5: VENTE PETIT LOT | G5: INTERET PETIT LOT | H5: MODE VERSEMENT VENTE PETIT LOT | I5: NUMERO CHEQUE | J5: REMBOURSEMENT | K5: MODE VERSEMENT REMBOURSEMENT | L5: MODE VERSEMENT TONTINE PRINCIPAL | M5: NUMERO CHEQUE | N5: MONTANT TONTINE LOT PRINCIPAL | O5: INTERET LOT PRINCIPAL | P5: DATE VENTE
A6: AS201608 | B6: =VLOOKUP(A6,[1]LISTADHERENT!A$5:H$60,3,0) -> DJUOMBESSY ANTOINE | C6: =IF(E6="ECHEC",0,IF(E6="",0,100000)) -> 100000 | D6: =IF(E6="ESPECES",0,0) -> 0 | E6: BANQUE | J6: =TONTMARS!F6+TONTMARS!G6 -> 0 | N6: =IF(O6=0,0,($C$38-O6)) -> 0
A7: AS201613 | B7: =VLOOKUP(A7,[1]LISTADHERENT!A$5:H$60,3,0) -> HOTCHO BENJAMIN | C7: =IF(E7="ECHEC",0,IF(E7="",0,100000)) -> 100000 | D7: =IF(E7="ESPECES",0,0) -> 0 | E7: BANQUE | J7: =TONTMARS!F7+TONTMARS!G7 -> 0 | N7: =IF(O7=0,0,($C$38-O7)) -> 1400000 | O7: 100000
A8: AS201619 | B8: =VLOOKUP(A8,[1]LISTADHERENT!A$5:H$60,3,0) -> KOUATCHO MESSACK | C8: =IF(E8="ECHEC",0,IF(E8="",0,100000)) -> 100000 | D8: =IF(E8="ESPECES",0,0) -> 0 | E8: BANQUE | J8: =TONTMARS!F8+TONTMARS!G8 -> 202500 | K8: BANQUE | N8: =IF(O8=0,0,($C$38-O8)) -> 0
A9: AS201617 | B9: =VLOOKUP(A9,[1]LISTADHERENT!A$5:H$60,3,0) -> KOUAMOU MOISE | C9: =IF(E9="ECHEC",0,IF(E9="",0,100000)) -> 100000 | D9: =IF(E9="ESPECES",0,0) -> 0 | E9: BANQUE | J9: =TONTMARS!F9+TONTMARS!G9 -> 0 | N9: =IF(O9=0,0,($C$38-O9)) -> 0
A10: AS201649 | B10: =VLOOKUP(A10,[1]LISTADHERENT!A$5:H$60,3,0) -> MBOGNING TUGMA GUY | C10: =IF(E10="ECHEC",0,IF(E10="",0,100000)) -> 100000 | D10: =IF(E10="ESPECES",0,0) -> 0 | E10: BANQUE | J10: =TONTMARS!F10+TONTMARS!G10 -> 101000 | K10: BANQUE | N10: =IF(O10=0,0,($C$38-O10)) -> 0
A11: AS201649 | B11: =VLOOKUP(A11,[1]LISTADHERENT!A$5:H$60,3,0) -> MBOGNING TUGMA GUY | C11: =IF(E11="ECHEC",0,IF(E11="",0,100000)) -> 100000 | D11: =IF(E11="ESPECES",0,0) -> 0 | E11: BANQUE | J11: =TONTMARS!F11+TONTMARS!G11 -> 0 | N11: =IF(O11=0,0,($C$38-O11)) -> 0
A12: AS201639 | B12: =VLOOKUP(A12,[1]LISTADHERENT!A$5:H$60,3,0) -> NANGUEN MARTIN | C12: =IF(E12="ECHEC",0,IF(E12="",0,100000)) -> 100000 | D12: =IF(E12="ESPECES",0,0) -> 0 | E12: BANQUE | J12: =TONTMARS!F12+TONTMARS!G12 -> 0 | N12: =IF(O12=0,0,($C$38-O12)) -> 0
A13: AS201622 | B13: =VLOOKUP(A13,[1]LISTADHERENT!A$5:H$60,3,0) -> NDJOMO ETIENNE | C13: =IF(E13="ECHEC",0,IF(E13="",0,100000)) -> 100000 | D13: =IF(E13="ESPECES",0,0) -> 0 | E13: BANQUE | J13: =TONTMARS!F13+TONTMARS!G13 -> 101500 | K13: BANQUE | N13: =IF(O13=0,0,($C$38-O13)) -> 1400000 | O13: 100000
A14: AS201624 | B14: =VLOOKUP(A14,[1]LISTADHERENT!A$5:H$60,3,0) -> NGONDIEP CLAUDE | C14: =IF(E14="ECHEC",0,IF(E14="",0,100000)) -> 100000 | D14: =IF(E14="ESPECES",0,0) -> 0 | E14: BANQUE | J14: =TONTMARS!F14+TONTMARS!G14 -> 0 | N14: =IF(O14=0,0,($C$38-O14)) -> 0
A15: AS201614 | B15: =VLOOKUP(A15,[1]LISTADHERENT!A$5:H$60,3,0) -> NKEHE DAVID | C15: =IF(E15="ECHEC",0,IF(E15="",0,100000)) -> 100000 | D15: =IF(E15="ESPECES",0,0) -> 0 | E15: BANQUE | F15: 225500 | G15: 4000 | J15: =TONTMARS!F15+TONTMARS!G15 -> 225500 | N15: =IF(O15=0,0,($C$38-O15)) -> 0
A16: AS201629 | B16: =VLOOKUP(A16,[1]LISTADHERENT!A$5:H$60,3,0) -> NKEPSEU DIEUDONNE | C16: =IF(E16="ECHEC",0,IF(E16="",0,100000)) -> 100000 | D16: =IF(E16="ESPECES",0,0) -> 0 | E16: BANQUE | J16: =TONTMARS!F16+TONTMARS!G16 -> 203000 | K16: BANQUE | N16: =IF(O16=0,0,($C$38-O16)) -> 0
A17: AS201636 | B17: =VLOOKUP(A17,[1]LISTADHERENT!A$5:H$60,3,0) -> SIMO FONGANG ERIC | C17: =IF(E17="ECHEC",0,IF(E17="",0,100000)) -> 100000 | D17: =IF(E17="ESPECES",0,0) -> 0 | E17: ESPECES | J17: =TONTMARS!F17+TONTMARS!G17-22000 -> 180500 | K17: ESPECES | N17: =IF(O17=0,0,($C$38-O17)) -> 0
A18: AS201636 | B18: =VLOOKUP(A18,[1]LISTADHERENT!A$5:H$60,3,0) -> SIMO FONGANG ERIC | C18: =IF(E18="ECHEC",0,IF(E18="",0,100000)) -> 100000 | D18: =IF(E18="ESPECES",0,0) -> 0 | E18: ESPECES | J18: =TONTMARS!F18+TONTMARS!G18 -> 0 | N18: =IF(O18=0,0,($C$38-O18)) -> 0
A19: AS201637 | B19: =VLOOKUP(A19,[1]LISTADHERENT!A$5:H$60,3,0) -> SIME MATHIEU | C19: =IF(E19="ECHEC",0,IF(E19="",0,100000)) -> 100000 | D19: =IF(E19="ESPECES",0,0) -> 0 | E19: BANQUE | J19: =TONTMARS!F19+TONTMARS!G19 -> 0 | N19: =IF(O19=0,0,($C$38-O19)) -> 0
A20: AS201637 | B20: =VLOOKUP(A20,[1]LISTADHERENT!A$5:H$60,3,0) -> SIME MATHIEU | C20: =IF(E20="ECHEC",0,IF(E20="",0,100000)) -> 100000 | D20: =IF(E20="ESPECES",0,0) -> 0 | E20: BANQUE | J20: =TONTMARS!F20+TONTMARS!G20 -> 0 | N20: =IF(O20=0,0,($C$38-O20)) -> 0
A21: AS201641 | B21: =VLOOKUP(A21,[1]LISTADHERENT!A$5:H$60,3,0) -> TCHOUAMOU MATHIEU | C21: =IF(E21="ECHEC",0,IF(E21="",0,100000)) -> 100000 | D21: =IF(E21="ESPECES",0,0) -> 0 | E21: BANQUE | J21: =TONTMARS!F21+TONTMARS!G21 -> 202000 | K21: BANQUE | N21: =IF(O21=0,0,($C$38-O21)) -> 0
A22: AS201644 | B22: =VLOOKUP(A22,[1]LISTADHERENT!A$5:H$60,3,0) -> TIEYAM ERNEST | C22: =IF(E22="ECHEC",0,IF(E22="",0,100000)) -> 100000 | D22: =IF(E22="ESPECES",0,0) -> 0 | E22: BANQUE | F22: 202000 | G22: 4000 | J22: =TONTMARS!F22+TONTMARS!G22 -> 202000 | N22: =IF(O22=0,0,($C$38-O22)) -> 0
A23: AS201647 | B23: =VLOOKUP(A23,[1]LISTADHERENT!A$5:H$60,3,0) -> YOUMBI EMMANUEL | C23: =IF(E23="ECHEC",0,IF(E23="",0,100000)) -> 100000 | D23: =IF(E23="ESPECES",0,0) -> 0 | E23: BANQUE | J23: =TONTFEV!F23+TONTFEV!G23 -> 0 | N23: =IF(O23=0,0,($C$38-O23)) -> 0
A25: TOTAL | C25: =SUM(C6:C24) -> 1800000 | D25: =SUM(D6:D24) -> 0 | F25: =SUM(F6:F24) -> 427500 | G25: =SUM(G6:G24) -> 8000 | J25: =SUM(J6:J24) -> 1418000 | N25: =SUM(N6:N24) -> 2800000 | O25: =SUM(O6:O24) -> 200000
C27: TONTINE | D27: REMBOURSEMENT PETIT LOT | E27: VENTE PETIT LOT | F27: VENTE LOT PRINCIPAL | G27: SOLDE EN CAISSE | K27: TONTINE + REMB + INTERET VENTE | L27: =C25+D32+O25+9500 -> 3000000
K28: TONTINE | L28: =IF(L27>=3000000,1500000*2,1500000) -> 3000000
B29: ESPECES | C29: =SUMIFS(C6:C23,E6:E23,"ESPECES") -> 200000 | D29: =SUMIFS(J6:J23,K6:K23,"ESPECES") -> 180500 | E29: =SUMIFS(F6:F23,H6:H23,"ESPECES") -> 0 | F29: =SUMIFS(N6:N23,L6:L23,"ESPECES") -> 0 | G29: =C29+D29-E29-F29 -> 380500 | K29: PETIT LOT | L29: =L27-L28 -> 0
B30: BANQUE | C30: =SUMIFS(C6:C23,E6:E23,"BANQUE") -> 1600000 | D30: =SUMIFS(J6:J23,K6:K23,"BANQUE") -> 810000 | E30: =SUMIFS(F6:F23,H6:H23,"BANQUE") -> 0 | F30: =SUMIFS(N6:N23,L6:L23,"BANQUE") -> 0 | G30: =C30+D30-E30-F30 -> 2410000 | K30: RESTE | L30: =L29-F25 -> -427500
B32: TOTAL | C32: =C29+C30 -> 1800000 | D32: =D29+D30 -> 990500 | E32: =E29+E30 -> 0 | F32: =F29+F30 -> 0 | G32: =G29+G30 -> 2790500 | J32: COMPLEMENT TONTINE 9500 | K32: ECHEC TONTINE | L32: 0
K33: ECHEC REMBOURSEMENT | L33: =225500+202000 -> 427500 | M33: KEHEP/TYAM
B35: INTERET LOT PRINCIPAL | C35: =O25 -> 200000
B36: INTERET PETIT LOT | C36: =+G25 -> 8000
B38: MONTANT TONTINE | C38: 1500000
B39: MONTANT PETIT LOT A VENDRE | C39: =L29 -> 0

Sheet TONTMAI
A1: ASSOCIATION | B1: ASELBY
A2: ANNEE | B2: 2019/2020
A3: TONTINE | B3: 100000
C4: 43968
A5: MATRICULE | B5: NOM ET PRENOM | C5: MONTANT TONTINE | D5: PENALITE | E5: MODE VERSEMENT TONTINE | F5: VENTE PETIT LOT | G5: INTERET PETIT LOT | H5: MODE VERSEMENT VENTE PETIT LOT | I5: NUMERO CHEQUE | J5: REMBOURSEMENT | K5: MODE VERSEMENT REMBOURSEMENT | L5: MODE VERSEMENT TONTINE PRINCIPAL | M5: NUMERO CHEQUE | N5: MONTANT TONTINE LOT PRINCIPAL | O5: INTERET LOT PRINCIPAL | P5: DATE VENTE
A6: AS201608 | B6: =VLOOKUP(A6,[1]LISTADHERENT!A$5:H$60,3,0) -> DJUOMBESSY ANTOINE | C6: =IF(E6="ECHEC",0,IF(E6="",0,100000)) -> 100000 | D6: =IF(E6="ESPECES",0,0) -> 0 | E6: BANQUE | J6: =TONTAVRIL!F6+TONTAVRIL!G6 -> 0 | N6: =IF(O6=0,0,($C$38-O6)) -> 0
A7: AS201613 | B7: =VLOOKUP(A7,[1]LISTADHERENT!A$5:H$60,3,0) -> HOTCHO BENJAMIN | C7: =IF(E7="ECHEC",0,IF(E7="",0,100000)) -> 100000 | D7: =IF(E7="ESPECES",0,0) -> 0 | E7: BANQUE | J7: =TONTAVRIL!F7+TONTAVRIL!G7 -> 0 | N7: =IF(O7=0,0,($C$38-O7)) -> 0
A8: AS201619 | B8: =VLOOKUP(A8,[1]LISTADHERENT!A$5:H$60,3,0) -> KOUATCHO MESSACK | C8: =IF(E8="ECHEC",0,IF(E8="",0,100000)) -> 100000 | D8: =IF(E8="ESPECES",0,0) -> 0 | E8: BANQUE | F8: 200000 | G8: 10000 | J8: =TONTAVRIL!F8+TONTAVRIL!G8 -> 0 | N8: =IF(O8=0,0,($C$38-O8)) -> 0
A9: AS201617 | B9: =VLOOKUP(A9,[1]LISTADHERENT!A$5:H$60,3,0) -> KOUAMOU MOISE | C9: =IF(E9="ECHEC",0,IF(E9="",0,100000)) -> 100000 | D9: =IF(E9="ESPECES",0,0) -> 0 | E9: BANQUE | J9: =TONTAVRIL!F9+TONTAVRIL!G9 -> 0 | N9: =IF(O9=0,0,($C$38-O9)) -> 0
A10: AS201649 | B10: =VLOOKUP(A10,[1]LISTADHERENT!A$5:H$60,3,0) -> MBOGNING TUGMA GUY | C10: =IF(E10="ECHEC",0,IF(E10="",0,100000)) -> 100000 | D10: =IF(E10="ESPECES",0,0) -> 0 | E10: BANQUE | J10: =TONTAVRIL!F10+TONTAVRIL!G10 -> 0 | N10: =IF(O10=0,0,($C$38-O10)) -> 0
A11: AS201649 | B11: =VLOOKUP(A11,[1]LISTADHERENT!A$5:H$60,3,0) -> MBOGNING TUGMA GUY | C11: =IF(E11="ECHEC",0,IF(E11="",0,100000)) -> 100000 | D11: =IF(E11="ESPECES",0,0) -> 0 | E11: BANQUE | J11: =TONTAVRIL!F11+TONTAVRIL!G11 -> 0 | N11: =IF(O11=0,0,($C$38-O11)) -> 0
A12: AS201639 | B12: =VLOOKUP(A12,[1]LISTADHERENT!A$5:H$60,3,0) -> NANGUEN MARTIN | C12: =IF(E12="ECHEC",0,IF(E12="",0,100000)) -> 100000 | D12: =IF(E12="ESPECES",0,0) -> 0 | E12: BANQUE | J12: =TONTAVRIL!F12+TONTAVRIL!G12 -> 0 | N12: =IF(O12=0,0,($C$38-O12)) -> 0
A13: AS201622 | B13: =VLOOKUP(A13,[1]LISTADHERENT!A$5:H$60,3,0) -> NDJOMO ETIENNE | C13: =IF(E13="ECHEC",0,IF(E13="",0,100000)) -> 100000 | D13: =IF(E13="ESPECES",0,0) -> 0 | E13: BANQUE | F13: 126000 | G13: 1000 | J13: =TONTAVRIL!F13+TONTAVRIL!G13 -> 0 | N13: =IF(O13=0,0,($C$38-O13)) -> 0
A14: AS201624 | B14: =VLOOKUP(A14,[1]LISTADHERENT!A$5:H$60,3,0) -> NGONDIEP CLAUDE | C14: =IF(E14="ECHEC",0,IF(E14="",0,100000)) -> 100000 | D14: =IF(E14="ESPECES",0,0) -> 0 | E14: BANQUE | J14: =TONTAVRIL!F14+TONTAVRIL!G14 -> 0 | N14: =IF(O14=0,0,($C$38-O14)) -> 1370000 | O14: 130000
A15: AS201614 | B15: =VLOOKUP(A15,[1]LISTADHERENT!A$5:H$60,3,0) -> NKEHE DAVID | C15: =IF(E15="ECHEC",0,IF(E15="",0,100000)) -> 100000 | D15: =IF(E15="ESPECES",0,0) -> 0 | E15: ESPECES | F15: 229500 | J15: =TONTAVRIL!F15+TONTAVRIL!G15 -> 229500 | K15: ECHEC | N15: =IF(O15=0,0,($C$38-O15)) -> 0
A16: AS201629 | B16: =VLOOKUP(A16,[1]LISTADHERENT!A$5:H$60,3,0) -> NKEPSEU DIEUDONNE | C16: =IF(E16="ECHEC",0,IF(E16="",0,100000)) -> 100000 | D16: =IF(E16="ESPECES",0,0) -> 0 | E16: BANQUE | J16: =TONTAVRIL!F16+TONTAVRIL!G16 -> 0 | N16: =IF(O16=0,0,($C$38-O16)) -> 0
A17: AS201636 | B17: =VLOOKUP(A17,[1]LISTADHERENT!A$5:H$60,3,0) -> SIMO FONGANG ERIC | C17: =IF(E17="ECHEC",0,IF(E17="",0,100000)) -> 100000 | D17: =IF(E17="ESPECES",0,0) -> 0 | E17: ESPECES | F17: 200000 | G17: 11000 | J17: =TONTAVRIL!F17+TONTAVRIL!G17 -> 0 | N17: =IF(O17=0,0,($C$38-O17)) -> 0
A18: AS201636 | B18: =VLOOKUP(A18,[1]LISTADHERENT!A$5:H$60,3,0) -> SIMO FONGANG ERIC | C18: =IF(E18="ECHEC",0,IF(E18="",0,100000)) -> 100000 | D18: =IF(E18="ESPECES",0,0) -> 0 | E18: ESPECES | J18: =TONTAVRIL!F18+TONTAVRIL!G18 -> 0 | N18: =IF(O18=0,0,($C$38-O18)) -> 0
A19: AS201637 | B19: =VLOOKUP(A19,[1]LISTADHERENT!A$5:H$60,3,0) -> SIME MATHIEU | C19: =IF(E19="ECHEC",0,IF(E19="",0,100000)) -> 100000 | D19: =IF(E19="ESPECES",0,0) -> 0 | E19: BANQUE | J19: =TONTAVRIL!F19+TONTAVRIL!G19 -> 0 | N19: =IF(O19=0,0,($C$38-O19)) -> 0
A20: AS201637 | B20: =VLOOKUP(A20,[1]LISTADHERENT!A$5:H$60,3,0) -> SIME MATHIEU | C20: =IF(E20="ECHEC",0,IF(E20="",0,100000)) -> 100000 | D20: =IF(E20="ESPECES",0,0) -> 0 | E20: BANQUE | J20: =TONTAVRIL!F20+TONTAVRIL!G20 -> 0 | N20: =IF(O20=0,0,($C$38-O20)) -> 0
A21: AS201641 | B21: =VLOOKUP(A21,[1]LISTADHERENT!A$5:H$60,3,0) -> TCHOUAMOU MATHIEU | C21: =IF(E21="ECHEC",0,IF(E21="",0,100000)) -> 100000 | D21: =IF(E21="ESPECES",0,0) -> 0 | E21: BANQUE | J21: =TONTAVRIL!F21+TONTAVRIL!G21 -> 0 | N21: =IF(O21=0,0,($C$38-O21)) -> 0
A22: AS201644 | B22: =VLOOKUP(A22,[1]LISTADHERENT!A$5:H$60,3,0) -> TIEYAM ERNEST | C22: =IF(E22="ECHEC",0,IF(E22="",0,100000)) -> 100000 | D22: =IF(E22="ESPECES",0,0) -> 0 | E22: BANQUE | F22: 100000 | G22: 6000 | J22: =TONTAVRIL!F22+TONTAVRIL!G22+206000 -> 412000 | K22: ESPECES | N22: =IF(O22=0,0,($C$38-O22)) -> 0
A23: AS201647 | B23: =VLOOKUP(A23,[1]LISTADHERENT!A$5:H$60,3,0) -> YOUMBI EMMANUEL | C23: =IF(E23="ECHEC",0,IF(E23="",0,100000)) -> 100000 | D23: =IF(E23="ESPECES",0,0) -> 0 | E23: BANQUE | J23: =TONTAVRIL!F23+TONTAVRIL!G23 -> 0 | N23: =IF(O23=0,0,($C$38-O23)) -> 0
A25: TOTAL | C25: =SUM(C6:C24) -> 1800000 | D25: =SUM(D6:D24) -> 0 | F25: =SUM(F6:F24) -> 855500 | G25: =SUM(G6:G24) -> 28000 | J25: =SUM(J6:J24) -> 641500 | N25: =SUM(N6:N24) -> 1370000 | O25: =SUM(O6:O24) -> 130000
C27: TONTINE | D27: REMBOURSEMENT PETIT LOT | E27: VENTE PETIT LOT | F27: VENTE LOT PRINCIPAL | G27: SOLDE EN CAISSE | K27: TONTINE + REMB + INTERET VENTE | L27: =C25+D32+O25 -> 2342000
K28: TONTINE | L28: =IF(L27>=3000000,1500000*2,1500000) -> 1500000
B29: ESPECES | C29: =SUMIFS(C6:C23,E6:E23,"ESPECES") -> 300000 | D29: =SUMIFS(J6:J23,K6:K23,"ESPECES") -> 412000 | E29: =SUMIFS(F6:F23,H6:H23,"ESPECES") -> 0 | F29: =SUMIFS(N6:N23,L6:L23,"ESPECES") -> 0 | G29: =C29+D29-E29-F29 -> 712000 | K29: PETIT LOT | L29: =L27-L28 -> 842000
B30: BANQUE | C30: =SUMIFS(C6:C23,E6:E23,"BANQUE") -> 1500000 | D30: =SUMIFS(J6:J23,K6:K23,"BANQUE") -> 0 | E30: =SUMIFS(F6:F23,H6:H23,"BANQUE") -> 0 | F30: =SUMIFS(N6:N23,L6:L23,"BANQUE") -> 0 | G30: =C30+D30-E30-F30 -> 1500000 | K30: RESTE | L30: =L29-F25 -> -13500
B32: TOTAL | C32: =C29+C30 -> 1800000 | D32: =D29+D30 -> 412000 | E32: =E29+E30 -> 0 | F32: =F29+F30 -> 0 | G32: =G29+G30 -> 2212000 | K32: ECHEC TONTINE | L32: 0
K33: ECHEC REMBOURSEMENT | L33: 229500
B35: INTERET LOT PRINCIPAL | C35: =O25 -> 130000
B36: INTERET PETIT LOT | C36: =+G25 -> 28000
B38: MONTANT TONTINE | C38: 1500000
B39: MONTANT PETIT LOT A VENDRE | C39: =L29 -> 842000

Sheet TONTJUIN
A1: ASSOCIATION | B1: ASELBY
A2: ANNEE | B2: 2019/2020
A3: TONTINE | B3: 100000
C4: 44003
A5: MATRICULE | B5: NOM ET PRENOM | C5: MONTANT TONTINE | D5: PENALITE | E5: MODE VERSEMENT TONTINE | F5: VENTE PETIT LOT | G5: INTERET PETIT LOT | H5: MODE VERSEMENT VENTE PETIT LOT | I5: NUMERO CHEQUE | J5: REMBOURSEMENT | K5: MODE VERSEMENT REMBOURSEMENT | L5: MODE VERSEMENT TONTINE PRINCIPAL | M5: NUMERO CHEQUE | N5: MONTANT TONTINE LOT PRINCIPAL | O5: INTERET LOT PRINCIPAL | P5: DATE VENTE
A6: AS201608 | B6: =VLOOKUP(A6,[1]LISTADHERENT!A$5:H$60,3,0) -> DJUOMBESSY ANTOINE | C6: =IF(E6="ECHEC",0,IF(E6="",0,100000)) -> 100000 | D6: =IF(E6="ESPECES",0,0) -> 0 | E6: BANQUE | J6: =TONTMAI!F6+TONTMAI!G6 -> 0 | N6: =IF(O6=0,0,($C$38-O6)) -> 0
A7: AS201613 | B7: =VLOOKUP(A7,[1]LISTADHERENT!A$5:H$60,3,0) -> HOTCHO BENJAMIN | C7: =IF(E7="ECHEC",0,IF(E7="",0,100000)) -> 100000 | D7: =IF(E7="ESPECES",0,0) -> 0 | E7: BANQUE | J7: =TONTMAI!F7+TONTMAI!G7 -> 0 | N7: =IF(O7=0,0,($C$38-O7)) -> 0
A8: AS201619 | B8: =VLOOKUP(A8,[1]LISTADHERENT!A$5:H$60,3,0) -> KOUATCHO MESSACK | C8: =IF(E8="ECHEC",0,IF(E8="",0,100000)) -> 100000 | D8: =IF(E8="ESPECES",0,0) -> 0 | E8: BANQUE | F8: 200000 | G8: 2000 | J8: =TONTMAI!F8+TONTMAI!G8 -> 210000 | K8: BANQUE | N8: =IF(O8=0,0,($C$38-O8)) -> 0
A9: AS201617 | B9: =VLOOKUP(A9,[1]LISTADHERENT!A$5:H$60,3,0) -> KOUAMOU MOISE | C9: =IF(E9="ECHEC",0,IF(E9="",0,100000)) -> 100000 | D9: =IF(E9="ESPECES",0,0) -> 0 | E9: BANQUE | J9: =TONTMAI!F9+TONTMAI!G9 -> 0 | N9: =IF(O9=0,0,($C$38-O9)) -> 0
A10: AS201649 | B10: =VLOOKUP(A10,[1]LISTADHERENT!A$5:H$60,3,0) -> MBOGNING TUGMA GUY | C10: =IF(E10="ECHEC",0,IF(E10="",0,100000)) -> 100000 | D10: =IF(E10="ESPECES",0,0) -> 0 | E10: BANQUE | F10: 100000 | G10: 1000 | J10: =TONTMAI!F10+TONTMAI!G10 -> 0 | N10: =IF(O10=0,0,($C$38-O10)) -> 0
A11: AS201649 | B11: =VLOOKUP(A11,[1]LISTADHERENT!A$5:H$60,3,0) -> MBOGNING TUGMA GUY | C11: =IF(E11="ECHEC",0,IF(E11="",0,100000)) -> 100000 | D11: =IF(E11="ESPECES",0,0) -> 0 | E11: BANQUE | J11: =TONTMAI!F11+TONTMAI!G11 -> 0 | N11: =IF(O11=0,0,($C$38-O11)) -> 0
A12: AS201639 | B12: =VLOOKUP(A12,[1]LISTADHERENT!A$5:H$60,3,0) -> NANGUEN MARTIN | C12: =IF(E12="ECHEC",0,IF(E12="",0,100000)) -> 100000 | D12: =IF(E12="ESPECES",0,0) -> 0 | E12: BANQUE | J12: =TONTMAI!F12+TONTMAI!G12 -> 0 | N12: =IF(O12=0,0,($C$38-O12)) -> 0
A13: AS201622 | B13: =VLOOKUP(A13,[1]LISTADHERENT!A$5:H$60,3,0) -> NDJOMO ETIENNE | C13: =IF(E13="ECHEC",0,IF(E13="",0,100000)) -> 100000 | D13: =IF(E13="ESPECES",0,0) -> 0 | E13: BANQUE | F13: 200000 | G13: 2000 | J13: =TONTMAI!F13+TONTMAI!G13 -> 127000 | K13: ESPECES | N13: =IF(O13=0,0,($C$38-O13)) -> 0
A14: AS201624 | B14: =VLOOKUP(A14,[1]LISTADHERENT!A$5:H$60,3,0) -> NGONDIEP CLAUDE | C14: =IF(E14="ECHEC",0,IF(E14="",0,100000)) -> 100000 | D14: =IF(E14="ESPECES",0,0) -> 0 | E14: BANQUE | J14: =TONTMAI!F14+TONTMAI!G14 -> 0 | N14: =IF(O14=0,0,($C$38-O14)) -> 0
A15: AS201614 | B15: =VLOOKUP(A15,[1]LISTADHERENT!A$5:H$60,3,0) -> NKEHE DAVID | C15: =IF(E15="ECHEC",0,IF(E15="",0,100000)) -> 0 | D15: =IF(E15="ESPECES",0,0) -> 0 | E15: ECHEC | F15: 229500 | J15: =TONTMAI!F15+TONTMAI!G15 -> 229500 | K15: ECHEC | N15: =IF(O15=0,0,($C$38-O15)) -> 0
A16: AS201629 | B16: =VLOOKUP(A16,[1]LISTADHERENT!A$5:H$60,3,0) -> NKEPSEU DIEUDONNE | C16: =IF(E16="ECHEC",0,IF(E16="",0,100000)) -> 100000 | D16: =IF(E16="ESPECES",0,0) -> 0 | E16: BANQUE | J16: =TONTMAI!F16+TONTMAI!G16 -> 0 | N16: =IF(O16=0,0,($C$38-O16)) -> 0
A17: AS201636 | B17: =VLOOKUP(A17,[1]LISTADHERENT!A$5:H$60,3,0) -> SIMO FONGANG ERIC | C17: =IF(E17="ECHEC",0,IF(E17="",0,100000)) -> 100000 | D17: =IF(E17="ESPECES",0,0) -> 0 | E17: ESPECES | F17: 233000 | G17: 22000 | J17: =TONTMAI!F17+TONTMAI!G17+22000 -> 233000 | K17: ECHEC | N17: =IF(O17=0,0,($C$38-O17)) -> 0
A18: AS201636 | B18: =VLOOKUP(A18,[1]LISTADHERENT!A$5:H$60,3,0) -> SIMO FONGANG ERIC | C18: =IF(E18="ECHEC",0,IF(E18="",0,100000)) -> 100000 | D18: =IF(E18="ESPECES",0,0) -> 0 | E18: ESPECES | J18: =TONTMAI!F18+TONTMAI!G18 -> 0 | N18: =IF(O18=0,0,($C$38-O18)) -> 0
A19: AS201637 | B19: =VLOOKUP(A19,[1]LISTADHERENT!A$5:H$60,3,0) -> SIME MATHIEU | C19: =IF(E19="ECHEC",0,IF(E19="",0,100000)) -> 100000 | D19: =IF(E19="ESPECES",0,0) -> 0 | E19: BANQUE | J19: =TONTMAI!F19+TONTMAI!G19 -> 0 | N19: =IF(O19=0,0,($C$38-O19)) -> 0
A20: AS201637 | B20: =VLOOKUP(A20,[1]LISTADHERENT!A$5:H$60,3,0) -> SIME MATHIEU | C20: =IF(E20="ECHEC",0,IF(E20="",0,100000)) -> 100000 | D20: =IF(E20="ESPECES",0,0) -> 0 | E20: BANQUE | J20: =TONTMAI!F20+TONTMAI!G20 -> 0 | N20: =IF(O20=0,0,($C$38-O20)) -> 0
A21: AS201641 | B21: =VLOOKUP(A21,[1]LISTADHERENT!A$5:H$60,3,0) -> TCHOUAMOU MATHIEU | C21: =IF(E21="ECHEC",0,IF(E21="",0,100000)) -> 100000 | D21: =IF(E21="ESPECES",0,0) -> 0 | E21: BANQUE | F21: 238000 | G21: 2000 | J21: =TONTMAI!F21+TONTMAI!G21 -> 0 | N21: =IF(O21=0,0,($C$38-O21)) -> 0
A22: AS201644 | B22: =VLOOKUP(A22,[1]LISTADHERENT!A$5:H$60,3,0) -> TIEYAM ERNEST | C22: =IF(E22="ECHEC",0,IF(E22="",0,100000)) -> 100000 | D22: =IF(E22="ESPECES",0,0) -> 0 | E22: ESPECES | F22: 100000 | G22: 1000 | J22: =TONTMAI!F22+TONTMAI!G22 -> 106000 | K22: BANQUE | N22: =IF(O22=0,0,($C$38-O22)) -> 1305000 | O22: 195000
A23: AS201647 | B23: =VLOOKUP(A23,[1]LISTADHERENT!A$5:H$60,3,0) -> YOUMBI EMMANUEL | C23: =IF(E23="ECHEC",0,IF(E23="",0,100000)) -> 100000 | D23: =IF(E23="ESPECES",0,0) -> 0 | E23: BANQUE | J23: =TONTMAI!F23+TONTMAI!G23 -> 0 | N23: =IF(O23=0,0,($C$38-O23)) -> 0
A25: TOTAL | C25: =SUM(C6:C24) -> 1700000 | D25: =SUM(D6:D24) -> 0 | F25: =SUM(F6:F24) -> 1300500 | G25: =SUM(G6:G24) -> 30000 | J25: =SUM(J6:J24) -> 905500 | N25: =SUM(N6:N24) -> 1305000 | O25: =SUM(O6:O24) -> 195000
C27: TONTINE | D27: REMBOURSEMENT PETIT LOT | E27: VENTE PETIT LOT | F27: VENTE LOT PRINCIPAL | G27: SOLDE EN CAISSE | K27: TONTINE + REMB + INTERET VENTE | L27: =C25+D32+O25 -> 2338000
K28: TONTINE | L28: =IF(L27>=3000000,1500000*2,1500000) -> 1500000
B29: ESPECES | C29: =SUMIFS(C6:C23,E6:E23,"ESPECES") -> 300000 | D29: =SUMIFS(J6:J23,K6:K23,"ESPECES") -> 127000 | E29: =SUMIFS(F6:F23,H6:H23,"ESPECES") -> 0 | F29: =SUMIFS(N6:N23,L6:L23,"ESPECES") -> 0 | G29: =C29+D29-E29-F29 -> 427000 | K29: PETIT LOT | L29: =L27-L28 -> 838000
B30: BANQUE | C30: =SUMIFS(C6:C23,E6:E23,"BANQUE") -> 1400000 | D30: =SUMIFS(J6:J23,K6:K23,"BANQUE") -> 316000 | E30: =SUMIFS(F6:F23,H6:H23,"BANQUE") -> 0 | F30: =SUMIFS(N6:N23,L6:L23,"BANQUE") -> 0 | G30: =C30+D30-E30-F30 -> 1716000 | K30: RESTE | L30: =L29-F25 -> -462500
B32: TOTAL | C32: =C29+C30 -> 1700000 | D32: =D29+D30 -> 443000 | E32: =E29+E30 -> 0 | F32: =F29+F30 -> 0 | G32: =G29+G30 -> 2143000 | K32: ECHEC TONTINE | L32: 100000 | M32: KEHEP DAVID
K33: ECHEC REMBOURSEMENT | L33: =229500+233000 -> 462500 | M33: KEHEP DAVID/SIMO ERIC
B35: INTERET LOT PRINCIPAL | C35: =O25 -> 195000
B36: INTERET PETIT LOT | C36: =+G25 -> 30000
B38: MONTANT TONTINE | C38: 1500000
B39: MONTANT PETIT LOT A VENDRE | C39: =L29 -> 838000

Sheet TONTJUIL
A1: ASSOCIATION | B1: ASELBY
A2: ANNEE | B2: 2019/2020
A3: TONTINE | B3: 100000
C4: 44031
A5: MATRICULE | B5: NOM ET PRENOM | C5: MONTANT TONTINE | D5: PENALITE | E5: MODE VERSEMENT TONTINE | F5: VENTE PETIT LOT | G5: INTERET PETIT LOT | H5: MODE VERSEMENT VENTE PETIT LOT | I5: NUMERO CHEQUE | J5: REMBOURSEMENT | K5: MODE VERSEMENT REMBOURSEMENT | L5: MODE VERSEMENT TONTINE PRINCIPAL | M5: NUMERO CHEQUE | N5: MONTANT TONTINE LOT PRINCIPAL | O5: INTERET LOT PRINCIPAL | P5: DATE VENTE
A6: AS201608 | B6: =VLOOKUP(A6,[1]LISTADHERENT!A$5:H$60,3,0) -> DJUOMBESSY ANTOINE | C6: =IF(E6="ECHEC",0,IF(E6="",0,100000)) -> 100000 | D6: =IF(E6="ESPECES",0,0) -> 0 | E6: BANQUE | J6: =TONTJUIN!F6+TONTJUIN!G6 -> 0 | N6: =IF(O6=0,0,($C$38-O6)) -> 0
A7: AS201613 | B7: =VLOOKUP(A7,[1]LISTADHERENT!A$5:H$60,3,0) -> HOTCHO BENJAMIN | C7: =IF(E7="ECHEC",0,IF(E7="",0,100000)) -> 100000 | D7: =IF(E7="ESPECES",0,0) -> 0 | E7: BANQUE | J7: =TONTJUIN!F7+TONTJUIN!G7 -> 0 | N7: =IF(O7=0,0,($C$38-O7)) -> 0
A8: AS201619 | B8: =VLOOKUP(A8,[1]LISTADHERENT!A$5:H$60,3,0) -> KOUATCHO MESSACK | C8: =IF(E8="ECHEC",0,IF(E8="",0,100000)) -> 100000 | D8: =IF(E8="ESPECES",0,0) -> 0 | E8: BANQUE | F8: 69000 | G8: 1500 | J8: =TONTJUIN!F8+TONTJUIN!G8 -> 202000 | K8: BANQUE | N8: =IF(O8=0,0,($C$38-O8)) -> 0
A9: AS201617 | B9: =VLOOKUP(A9,[1]LISTADHERENT!A$5:H$60,3,0) -> KOUAMOU MOISE | C9: =IF(E9="ECHEC",0,IF(E9="",0,100000)) -> 100000 | D9: =IF(E9="ESPECES",0,0) -> 0 | E9: BANQUE | J9: =TONTJUIN!F9+TONTJUIN!G9 -> 0 | N9: =IF(O9=0,0,($C$38-O9)) -> 0
A10: AS201649 | B10: =VLOOKUP(A10,[1]LISTADHERENT!A$5:H$60,3,0) -> MBOGNING TUGMA GUY | C10: =IF(E10="ECHEC",0,IF(E10="",0,100000)) -> 100000 | D10: =IF(E10="ESPECES",0,0) -> 0 | E10: BANQUE | J10: =TONTJUIN!F10+TONTJUIN!G10 -> 101000 | K10: ESPECES | N10: =IF(O10=0,0,($C$38-O10)) -> 0
A11: AS201649 | B11: =VLOOKUP(A11,[1]LISTADHERENT!A$5:H$60,3,0) -> MBOGNING TUGMA GUY | C11: =IF(E11="ECHEC",0,IF(E11="",0,100000)) -> 100000 | D11: =IF(E11="ESPECES",0,0) -> 0 | E11: BANQUE | J11: =TONTJUIN!F11+TONTJUIN!G11 -> 0 | N11: =IF(O11=0,0,($C$38-O11)) -> 1255000 | O11: 245000
A12: AS201639 | B12: =VLOOKUP(A12,[1]LISTADHERENT!A$5:H$60,3,0) -> NANGUEN MARTIN | C12: =IF(E12="ECHEC",0,IF(E12="",0,100000)) -> 100000 | D12: =IF(E12="ESPECES",0,0) -> 0 | E12: BANQUE | J12: =TONTJUIN!F12+TONTJUIN!G12 -> 0 | N12: =IF(O12=0,0,($C$38-O12)) -> 0
A13: AS201622 | B13: =VLOOKUP(A13,[1]LISTADHERENT!A$5:H$60,3,0) -> NDJOMO ETIENNE | C13: =IF(E13="ECHEC",0,IF(E13="",0,100000)) -> 100000 | D13: =IF(E13="ESPECES",0,0) -> 0 | E13: BANQUE | J13: =TONTJUIN!F13+TONTJUIN!G13 -> 202000 | K13: BANQUE | N13: =IF(O13=0,0,($C$38-O13)) -> 0
A14: AS201624 | B14: =VLOOKUP(A14,[1]LISTADHERENT!A$5:H$60,3,0) -> NGONDIEP CLAUDE | C14: =IF(E14="ECHEC",0,IF(E14="",0,100000)) -> 100000 | D14: =IF(E14="ESPECES",0,0) -> 0 | E14: BANQUE | J14: =TONTJUIN!F14+TONTJUIN!G14 -> 0 | N14: =IF(O14=0,0,($C$38-O14)) -> 0
