Workbook
Name BANQUE: #REF!
Name BANQUE: #REF!
Name BANQUE: #REF!
Name BANQUE: #REF!
Name BANQUE: #REF!
Name BANQUE: #REF!
Name BANQUE: #REF!
Name BANQUE: #REF!
Name BANQUE: #REF!
Name BANQUE: #REF!
Name BANQUE: #REF!
Name BANQUE: #REF!
Name BANQUE: #REF!
Name BANQUE: #REF!
Name BANQUE: #REF!
Name BANQUE: #REF!
Name BANQUE: #REF!
Name MODEPAID: [1]Feuil2!$A$1:$A$3
Name MODET25000: [2]MODEVERSEMENT!$A$1:$A$3
Name MODEVERSEMENT: #REF!
Name MODEVERSEMENT: #REF!
Name MODEVERSEMENT: #REF!
Name MODEVERSEMENT: #REF!
Name MODEVERSEMENT: #REF!
Name MODEVERSEMENT: #REF!
Name MODEVERSEMENT: #REF!
Name MODEVERSEMENT: #REF!
Name MODEVERSEMENT: #REF!
Name MODEVERSEMENT: #REF!
Name MODEVERSEMENT: #REF!
Name MODEVERSEMENT: #REF!
Name MODEVERSEMENT: #REF!
Name MODEVERSEMENT: #REF!
Name MODEVERSEMENT: #REF!
Name MODEVERSEMENT: #REF!
Name MODEVERSEMENT: #REF!
Name MODEVERSEMENTS: MODEVERSEMENT!$A$1:$A$3
Name MODPAID: TONTAOUT!#REF!
Name MODPAID: TONTAVRIL!#REF!
Name MODPAID: TONTDEC!#REF!
Name MODPAID: TONTDEC20!#REF!
Name MODPAID: TONTFEV!#REF!
Name MODPAID: TONTJANV!#REF!
Name MODPAID: TONTJUIL!#REF!
Name MODPAID: TONTJUIN!#REF!
Name MODPAID: TONTMAI!#REF!
Name MODPAID: TONTMARS!#REF!
Name MODPAID: TONTNOV!#REF!
Name MODPAID: TONTNOV20!#REF!
Name MODPAID: TONTOCT!#REF!
Name MODPAID: TONTRESUME!#REF!
Name MODPAID: TONTSEPT!#REF!
Name VALMODEPAID: [3]MODEPAID!$A$1:$A$3

Sheet MODEVERSEMENT
A1: BANQUE
A2: ESPECES
A3: ECHEC

Sheet TONTNOV
A1: ASSOCIATION | B1: ASELBY
A2: ANNEE | B2: 2019/2020
A3: TONTINE | B3: 30000
C4: 43793
A5: MATRICULE | B5: NOM ET PRENOM | C5: RESTE | D5: MONTANT TONTINE | E5: PENALITE VERSEMENT ESPECES | F5: MODE VERSEMENT | G5: MONTANT VERSE | H5: VENTE PETIT LOT | I5: INTERET PETIT LOT | J5: MODE VERSEMENT VENTE PETIT LOT | K5: NUMERO CHEQUE | L5: REMBOURSEMENT PETIT LOT | M5: MODE VERSEMENT REMBOURSEMENT | N5: MODE VERSEMENTLOT PRINCIPAL | O5: NUMERO CHEQUE | P5: MONTANT TONTINE LOT PRINCIPAL | Q5: INTERET LOT PRINCIPAL | R5: DEPOT
A6: AS201648 | B6: =VLOOKUP(A6,[4]LISTADHERENT!A$5:H$60,3,0) -> ASELBY | C6: =IF(G6=0,0,G6-D6) -> 0 | D6: =IF(F6="ECHEC",0,IF(F6="",0,20000)) -> 0 | E6: =IF(F6="ESPECES",3000,0) -> 0 | F6: ECHEC | G6: =IF(F6="BANQUE",30000,IF(F6="ESPECES",30000,0)) -> 0 | P6: =IF(Q6=0,0,($E$75-Q6)) -> 0
A7: AS201602 | B7: =VLOOKUP(A7,[4]LISTADHERENT!A$5:H$60,3,0) -> BOUTCHOUANG WILLIAM | C7: =IF(G7=0,0,G7-D7) -> 10000 | D7: =IF(F7="ECHEC",0,IF(F7="",0,20000)) -> 20000 | E7: =IF(F7="ESPECES",3000,0) -> 0 | F7: BANQUE | G7: =IF(F7="BANQUE",30000,IF(F7="ESPECES",30000,0)) -> 30000 | P7: =IF(Q7=0,0,($E$75-Q7)) -> 0
A8: AS201604 | B8: =VLOOKUP(A8,[4]LISTADHERENT!A$5:H$60,3,0) -> DJOMO JEAN PAUL | C8: =IF(G8=0,0,G8-D8) -> 10000 | D8: =IF(F8="ECHEC",0,IF(F8="",0,20000)) -> 20000 | E8: =IF(F8="ESPECES",3000,0) -> 0 | F8: BANQUE | G8: =IF(F8="BANQUE",30000,IF(F8="ESPECES",30000,0)) -> 30000 | P8: =IF(Q8=0,0,($E$75-Q8)) -> 268000 | Q8: 32000
A9: AS201654 | B9: =VLOOKUP(A9,[4]LISTADHERENT!A$5:H$60,3,0) -> DJOMOU TCHANDA | C9: =IF(G9=0,0,G9-D9) -> 0 | D9: =IF(F9="ECHEC",0,IF(F9="",0,20000)) -> 0 | E9: =IF(F9="ESPECES",3000,0) -> 0 | F9: ECHEC | P9: =IF(Q9=0,0,($E$75-Q9)) -> 0
A10: AS201605 | B10: =VLOOKUP(A10,[4]LISTADHERENT!A$5:H$60,3,0) -> DJOUKWE NANGUEN GUY BLAISE | C10: =IF(G10=0,0,G10-D10) -> 10000 | D10: =IF(F10="ECHEC",0,IF(F10="",0,20000)) -> 20000 | E10: =IF(F10="ESPECES",3000,0) -> 3000 | F10: ESPECES | G10: =IF(F10="BANQUE",30000,IF(F10="ESPECES",30000,0)) -> 30000 | P10: =IF(Q10=0,0,($E$75-Q10)) -> 0
A11: AS201608 | B11: =VLOOKUP(A11,[4]LISTADHERENT!A$5:H$60,3,0) -> DJUOMBESSY ANTOINE | C11: =IF(G11=0,0,G11-D11) -> 10000 | D11: =IF(F11="ECHEC",0,IF(F11="",0,20000)) -> 20000 | E11: =IF(F11="ESPECES",3000,0) -> 0 | F11: BANQUE | G11: =IF(F11="BANQUE",30000,IF(F11="ESPECES",30000,0)) -> 30000 | H11: 25000 | I11: 500 | J11: ESPECES | P11: =IF(Q11=0,0,($E$75-Q11)) -> 0
A12: AS201651 | B12: =VLOOKUP(A12,[4]LISTADHERENT!A$5:H$60,3,0) -> DOMOU FABIEN | C12: =IF(G12=0,0,G12-D12) -> 10000 | D12: =IF(F12="ECHEC",0,IF(F12="",0,20000)) -> 20000 | E12: =IF(F12="ESPECES",3000,0) -> 0 | F12: BANQUE | G12: =IF(F12="BANQUE",30000,IF(F12="ESPECES",30000,0)) -> 30000 | P12: =IF(Q12=0,0,($E$75-Q12)) -> 0
A13: AS201609 | B13: =VLOOKUP(A13,[4]LISTADHERENT!A$5:H$60,3,0) -> DONHOU DAVID | C13: =IF(G13=0,0,G13-D13) -> 10000 | D13: =IF(F13="ECHEC",0,IF(F13="",0,20000)) -> 20000 | E13: =IF(F13="ESPECES",3000,0) -> 0 | F13: BANQUE | G13: =IF(F13="BANQUE",30000,IF(F13="ESPECES",30000,0)) -> 30000 | P13: =IF(Q13=0,0,($E$75-Q13)) -> 0
A14: AS201610 | B14: =VLOOKUP(A14,[4]LISTADHERENT!A$5:H$60,3,0) -> FOTSO THOMAS | C14: =IF(G14=0,0,G14-D14) -> 10000 | D14: =IF(F14="ECHEC",0,IF(F14="",0,20000)) -> 20000 | E14: =IF(F14="ESPECES",3000,0) -> 0 | F14: BANQUE | G14: =IF(F14="BANQUE",30000,IF(F14="ESPECES",30000,0)) -> 30000 | H14: =25000+25000 -> 50000 | I14: 1000 | J14: ESPECES | P14: =IF(Q14=0,0,($E$75-Q14)) -> 0
A15: AS201611 | B15: =VLOOKUP(A15,[4]LISTADHERENT!A$5:H$60,3,0) -> HENGUE PAUL OMER | C15: =IF(G15=0,0,G15-D15) -> 10000 | D15: =IF(F15="ECHEC",0,IF(F15="",0,20000)) -> 20000 | E15: =IF(F15="ESPECES",3000,0) -> 0 | F15: BANQUE | G15: =IF(F15="BANQUE",30000,IF(F15="ESPECES",30000,0)) -> 30000 | P15: =IF(Q15=0,0,($E$75-Q15)) -> 0
A16: AS201613 | B16: =VLOOKUP(A16,[4]LISTADHERENT!A$5:H$60,3,0) -> HOTCHO BENJAMIN | C16: =IF(G16=0,0,G16-D16) -> 5000 | D16: =IF(F16="ECHEC",0,IF(F16="",0,20000)) -> 20000 | E16: =IF(F16="ESPECES",3000,0) -> 0 | F16: BANQUE | G16: =IF(F16="BANQUE",30000,IF(F16="ESPECES",30000,0))-5000 -> 25000 | P16: =IF(Q16=0,0,($E$75-Q16)) -> 0
A17: AS201615 | B17: =VLOOKUP(A17,[4]LISTADHERENT!A$5:H$60,3,0) -> KEPSEU FRANCIS | C17: =IF(G17=0,0,G17-D17) -> 18000 | D17: =IF(F17="ECHEC",0,IF(F17="",0,20000)) -> 20000 | E17: =IF(F17="ESPECES",3000,0) -> 0 | F17: BANQUE | G17: =IF(F17="BANQUE",30000,IF(F17="ESPECES",30000,0))+8000 -> 38000 | P17: =IF(Q17=0,0,($E$75-Q17)) -> 0
A18: AS201618 | B18: =VLOOKUP(A18,[4]LISTADHERENT!A$5:H$60,3,0) -> KOUAMO VICTOR PEGUY | C18: =IF(G18=0,0,G18-D18) -> 10000 | D18: =IF(F18="ECHEC",0,IF(F18="",0,20000)) -> 20000 | E18: =IF(F18="ESPECES",3000,0) -> 0 | F18: BANQUE | G18: =IF(F18="BANQUE",30000,IF(F18="ESPECES",30000,0)) -> 30000 | P18: =IF(Q18=0,0,($E$75-Q18)) -> 265000 | Q18: 35000
A19: AS201617 | B19: =VLOOKUP(A19,[4]LISTADHERENT!A$5:H$60,3,0) -> KOUAMOU MOISE | C19: =IF(G19=0,0,G19-D19) -> 10000 | D19: =IF(F19="ECHEC",0,IF(F19="",0,20000)) -> 20000 | E19: =IF(F19="ESPECES",3000,0) -> 0 | F19: BANQUE | G19: =IF(F19="BANQUE",30000,IF(F19="ESPECES",30000,0)) -> 30000 | P19: =IF(Q19=0,0,($E$75-Q19)) -> 0
A20: AS201619 | B20: =VLOOKUP(A20,[4]LISTADHERENT!A$5:H$60,3,0) -> KOUATCHO MESSACK | C20: =IF(G20=0,0,G20-D20) -> 10000 | D20: =IF(F20="ECHEC",0,IF(F20="",0,20000)) -> 20000 | E20: =IF(F20="ESPECES",3000,0) -> 0 | F20: BANQUE | G20: =IF(F20="BANQUE",30000,IF(F20="ESPECES",30000,0)) -> 30000 | P20: =IF(Q20=0,0,($E$75-Q20)) -> 0
A21: AS201620 | B21: =VLOOKUP(A21,[4]LISTADHERENT!A$5:H$60,3,0) -> LOWE JEAN | C21: =IF(G21=0,0,G21-D21) -> 10000 | D21: =IF(F21="ECHEC",0,IF(F21="",0,20000)) -> 20000 | E21: =IF(F21="ESPECES",3000,0) -> 0 | F21: BANQUE | G21: =IF(F21="BANQUE",30000,IF(F21="ESPECES",30000,0)) -> 30000 | P21: =IF(Q21=0,0,($E$75-Q21)) -> 0
A22: AS201649 | B22: =VLOOKUP(A22,[4]LISTADHERENT!A$5:H$60,3,0) -> MBOGNING TUGMA GUY | C22: =IF(G22=0,0,G22-D22) -> 10000 | D22: =IF(F22="ECHEC",0,IF(F22="",0,20000)) -> 20000 | E22: =IF(F22="ESPECES",3000,0) -> 0 | F22: BANQUE | G22: =IF(F22="BANQUE",30000,IF(F22="ESPECES",30000,0)) -> 30000 | P22: =IF(Q22=0,0,($E$75-Q22)) -> 0
A23: AS201639 | B23: =VLOOKUP(A23,[4]LISTADHERENT!A$5:H$60,3,0) -> NANGUEN MARTIN | C23: =IF(G23=0,0,G23-D23) -> 10000 | D23: =IF(F23="ECHEC",0,IF(F23="",0,20000)) -> 20000 | E23: =IF(F23="ESPECES",3000,0) -> 0 | F23: BANQUE | G23: =IF(F23="BANQUE",30000,IF(F23="ESPECES",30000,0)) -> 30000 | P23: =IF(Q23=0,0,($E$75-Q23)) -> 0
A24: AS201621 | B24: =VLOOKUP(A24,[4]LISTADHERENT!A$5:H$60,3,0) -> NANKAM APPOLINAIRE | C24: =IF(G24=0,0,G24-D24) -> 10000 | D24: =IF(F24="ECHEC",0,IF(F24="",0,20000)) -> 20000 | E24: =IF(F24="ESPECES",3000,0) -> 0 | F24: BANQUE | G24: =IF(F24="BANQUE",30000,IF(F24="ESPECES",30000,0)) -> 30000 | P24: =IF(Q24=0,0,($E$75-Q24)) -> 0
A25: AS201622 | B25: =VLOOKUP(A25,[4]LISTADHERENT!A$5:H$60,3,0) -> NDJOMO ETIENNE | C25: =IF(G25=0,0,G25-D25) -> 14000 | D25: =IF(F25="ECHEC",0,IF(F25="",0,20000)) -> 20000 | E25: =IF(F25="ESPECES",3000,0) -> 0 | F25: BANQUE | G25: =IF(F25="BANQUE",30000,IF(F25="ESPECES",30000,0))+4000 -> 34000 | P25: =IF(Q25=0,0,($E$75-Q25)) -> 0
A26: AS201624 | B26: =VLOOKUP(A26,[4]LISTADHERENT!A$5:H$60,3,0) -> NGONDIEP CLAUDE | C26: =IF(G26=0,0,G26-D26) -> 20000 | D26: =IF(F26="ECHEC",0,IF(F26="",0,20000)) -> 20000 | E26: =IF(F26="ESPECES",3000,0) -> 0 | F26: BANQUE | G26: =IF(F26="BANQUE",30000,IF(F26="ESPECES",30000,0))+10000 -> 40000 | P26: =IF(Q26=0,0,($E$75-Q26)) -> 0
A27: AS201626 | B27: =VLOOKUP(A27,[4]LISTADHERENT!A$5:H$60,3,0) -> NGUIEMEGNI MATHIEU BLAISE | C27: =IF(G27=0,0,G27-D27) -> 10000 | D27: =IF(F27="ECHEC",0,IF(F27="",0,20000)) -> 20000 | E27: =IF(F27="ESPECES",3000,0) -> 0 | F27: BANQUE | G27: =IF(F27="BANQUE",30000,IF(F27="ESPECES",30000,0)) -> 30000 | P27: =IF(Q27=0,0,($E$75-Q27)) -> 0
A28: AS201628 | B28: =VLOOKUP(A28,[4]LISTADHERENT!A$5:H$60,3,0) -> NKAMGANG JUSTIN DEJOLIE | C28: =IF(G28=0,0,G28-D28) -> 10000 | D28: =IF(F28="ECHEC",0,IF(F28="",0,20000)) -> 20000 | E28: =IF(F28="ESPECES",3000,0) -> 3000 | F28: ESPECES | G28: =IF(F28="BANQUE",30000,IF(F28="ESPECES",30000,0)) -> 30000 | P28: =IF(Q28=0,0,($E$75-Q28)) -> 0
A29: AS201614 | B29: =VLOOKUP(A29,[4]LISTADHERENT!A$5:H$60,3,0) -> NKEHE DAVID | C29: =IF(G29=0,0,G29-D29) -> 10000 | D29: =IF(F29="ECHEC",0,IF(F29="",0,20000)) -> 20000 | E29: =IF(F29="ESPECES",3000,0) -> 3000 | F29: ESPECES | G29: =IF(F29="BANQUE",30000,IF(F29="ESPECES",30000,0)) -> 30000 | H29: 32000 | I29: 500 | J29: ESPECES | P29: =IF(Q29=0,0,($E$75-Q29)) -> 0
A30: AS201629 | B30: =VLOOKUP(A30,[4]LISTADHERENT!A$5:H$60,3,0) -> NKEPSEU DIEUDONNE | C30: =IF(G30=0,0,G30-D30) -> 10000 | D30: =IF(F30="ECHEC",0,IF(F30="",0,20000)) -> 20000 | E30: =IF(F30="ESPECES",3000,0) -> 0 | F30: BANQUE | G30: =IF(F30="BANQUE",30000,IF(F30="ESPECES",30000,0)) -> 30000 | P30: =IF(Q30=0,0,($E$75-Q30)) -> 0
A31: AS201633 | B31: =VLOOKUP(A31,[4]LISTADHERENT!A$5:H$60,3,0) -> PATEGO NJOSSU GUSTAVE | C31: =IF(G31=0,0,G31-D31) -> 10000 | D31: =IF(F31="ECHEC",0,IF(F31="",0,20000)) -> 20000 | E31: =IF(F31="ESPECES",3000,0) -> 0 | F31: BANQUE | G31: =IF(F31="BANQUE",30000,IF(F31="ESPECES",30000,0)) -> 30000 | P31: =IF(Q31=0,0,($E$75-Q31)) -> 0
A32: AS201653 | B32: =VLOOKUP(A32,[4]LISTADHERENT!A$5:H$60,3,0) -> SIME BRICE | C32: =IF(G32=0,0,G32-D32) -> 30000 | D32: =IF(F32="ECHEC",0,IF(F32="",0,20000)) -> 20000 | E32: =IF(F32="ESPECES",3000,0) -> 0 | F32: BANQUE | G32: =IF(F32="BANQUE",30000,IF(F32="ESPECES",30000,0))+20000 -> 50000 | P32: =IF(Q32=0,0,($E$75-Q32)) -> 0
A33: AS201636 | B33: =VLOOKUP(A33,[4]LISTADHERENT!A$5:H$60,3,0) -> SIMO FONGANG ERIC | C33: =IF(G33=0,0,G33-D33) -> 10000 | D33: =IF(F33="ECHEC",0,IF(F33="",0,20000)) -> 20000 | E33: =IF(F33="ESPECES",3000,0) -> 0 | F33: BANQUE | G33: =IF(F33="BANQUE",30000,IF(F33="ESPECES",30000,0)) -> 30000 | P33: =IF(Q33=0,0,($E$75-Q33)) -> 0
A34: AS201637 | B34: =VLOOKUP(A34,[4]LISTADHERENT!A$5:H$60,3,0) -> SIME MATHIEU | C34: =IF(G34=0,0,G34-D34) -> 10000 | D34: =IF(F34="ECHEC",0,IF(F34="",0,20000)) -> 20000 | E34: =IF(F34="ESPECES",3000,0) -> 0 | F34: BANQUE | G34: =IF(F34="BANQUE",30000,IF(F34="ESPECES",30000,0)) -> 30000 | P34: =IF(Q34=0,0,($E$75-Q34)) -> 0
A35: AS201638 | B35: =VLOOKUP(A35,[4]LISTADHERENT!A$5:H$60,3,0) -> SIMO PIERRE | C35: =IF(G35=0,0,G35-D35) -> 10000 | D35: =IF(F35="ECHEC",0,IF(F35="",0,20000)) -> 20000 | E35: =IF(F35="ESPECES",3000,0) -> 0 | F35: BANQUE | G35: =IF(F35="BANQUE",30000,IF(F35="ESPECES",30000,0)) -> 30000 | P35: =IF(Q35=0,0,($E$75-Q35)) -> 0
A36: AS201641 | B36: =VLOOKUP(A36,[4]LISTADHERENT!A$5:H$60,3,0) -> TCHOUAMOU MATHIEU | C36: =IF(G36=0,0,G36-D36) -> 10000 | D36: =IF(F36="ECHEC",0,IF(F36="",0,20000)) -> 20000 | E36: =IF(F36="ESPECES",3000,0) -> 0 | F36: BANQUE | G36: =IF(F36="BANQUE",30000,IF(F36="ESPECES",30000,0)) -> 30000 | P36: =IF(Q36=0,0,($E$75-Q36)) -> 0
A37: AS201644 | B37: =VLOOKUP(A37,[4]LISTADHERENT!A$5:H$60,3,0) -> TIEYAM ERNEST | C37: =IF(G37=0,0,G37-D37) -> 10000 | D37: =IF(F37="ECHEC",0,IF(F37="",0,20000)) -> 20000 | E37: =IF(F37="ESPECES",3000,0) -> 0 | F37: BANQUE | G37: =IF(F37="BANQUE",30000,IF(F37="ESPECES",30000,0)) -> 30000 | P37: =IF(Q37=0,0,($E$75-Q37)) -> 0
A38: AS201646 | B38: =VLOOKUP(A38,[4]LISTADHERENT!A$5:H$60,3,0) -> YEPMOU JEAN JACQUES | C38: =IF(G38=0,0,G38-D38) -> 10000 | D38: =IF(F38="ECHEC",0,IF(F38="",0,20000)) -> 20000 | E38: =IF(F38="ESPECES",3000,0) -> 3000 | F38: ESPECES | G38: =IF(F38="BANQUE",30000,IF(F38="ESPECES",30000,0)) -> 30000 | P38: =IF(Q38=0,0,($E$75-Q38)) -> 0
A39: AS201647 | B39: =VLOOKUP(A39,[4]LISTADHERENT!A$5:H$60,3,0) -> YOUMBI EMMANUEL | C39: =IF(G39=0,0,G39-D39) -> 10000 | D39: =IF(F39="ECHEC",0,IF(F39="",0,20000)) -> 20000 | E39: =IF(F39="ESPECES",3000,0) -> 0 | F39: BANQUE | G39: =IF(F39="BANQUE",30000,IF(F39="ESPECES",30000,0)) -> 30000 | P39: =IF(Q39=0,0,($E$75-Q39)) -> 0
A40: AS201655 | B40: =VLOOKUP(A40,[4]LISTADHERENT!A$5:H$60,3,0) -> TCHEMHOU EMMANUEL
...

Sheet TONTDEC
A1: ASSOCIATION | B1: ASELBY
A2: ANNEE | B2: 2019/2020
A3: TONTINE | B3: 30000
C4: 43814
A5: MATRICULE | B5: NOM ET PRENOM | C5: RESTE | D5: MONTANT TONTINE | E5: PENALITE VERSEMENT ESPECES | F5: MODE VERSEMENT | G5: MONTANT VERSE | H5: VENTE PETIT LOT | I5: INTERET PETIT LOT | J5: MODE VERSEMENT VENTE PETIT LOT | K5: NUMERO CHEQUE | L5: REMBOURSEMENT PETIT LOT | M5: MODE VERSEMENT REMBOURSEMENT | N5: MODE VERSEMENTLOT PRINCIPAL | O5: NUMERO CHEQUE | P5: MONTANT TONTINE LOT PRINCIPAL | Q5: INTERET LOT PRINCIPAL | R5: DEPOT
A6: AS201648 | B6: =VLOOKUP(A6,[4]LISTADHERENT!A$5:H$60,3,0) -> ASELBY | C6: =IF(G6=0,0,G6-D6) -> 0 | D6: =IF(F6="ECHEC",0,IF(F6="",0,20000)) -> 0 | E6: =IF(F6="ESPECES",3000,0) -> 0 | F6: ECHEC | G6: =IF(F6="BANQUE",30000,IF(F6="ESPECES",30000,0)) -> 0 | L6: =TONTNOV!H6+TONTNOV!I6 -> 0 | P6: =IF(Q6=0,0,($E$76-Q6)) -> 0
A7: AS201602 | B7: =VLOOKUP(A7,[4]LISTADHERENT!A$5:H$60,3,0) -> BOUTCHOUANG WILLIAM | C7: =IF(G7=0,0,G7-D7) -> 10000 | D7: =IF(F7="ECHEC",0,IF(F7="",0,20000)) -> 20000 | E7: =IF(F7="ESPECES",3000,0) -> 0 | F7: BANQUE | G7: =IF(F7="BANQUE",30000,IF(F7="ESPECES",30000,0)) -> 30000 | L7: =TONTNOV!H7+TONTNOV!I7 -> 0 | P7: =IF(Q7=0,0,($E$75-Q7)) -> 0
A8: AS201604 | B8: =VLOOKUP(A8,[4]LISTADHERENT!A$5:H$60,3,0) -> DJOMO JEAN PAUL | C8: =IF(G8=0,0,G8-D8) -> 15000 | D8: =IF(F8="ECHEC",0,IF(F8="",0,20000)) -> 20000 | E8: =IF(F8="ESPECES",3000,0) -> 0 | F8: BANQUE | G8: 35000 | L8: =TONTNOV!H8+TONTNOV!I8 -> 0 | P8: =IF(Q8=0,0,($E$75-Q8)) -> 0
A9: AS201654 | B9: =VLOOKUP(A9,[4]LISTADHERENT!A$5:H$60,3,0) -> DJOMOU TCHANDA | C9: =IF(G9=0,0,G9-D9) -> 22000 | D9: 40000 | E9: =IF(F9="ESPECES",3000,0) -> 3000 | F9: ESPECES | G9: 62000 | L9: =TONTNOV!H9+TONTNOV!I9 -> 0 | P9: =IF(Q9=0,0,($E$75-Q9)) -> 0
A10: AS201605 | B10: =VLOOKUP(A10,[4]LISTADHERENT!A$5:H$60,3,0) -> DJOUKWE NANGUEN GUY BLAISE | C10: =IF(G10=0,0,G10-D10) -> 10000 | D10: =IF(F10="ECHEC",0,IF(F10="",0,20000)) -> 20000 | E10: =IF(F10="ESPECES",3000,0) -> 0 | F10: BANQUE | G10: =IF(F10="BANQUE",30000,IF(F10="ESPECES",30000,0)) -> 30000 | L10: =TONTNOV!H10+TONTNOV!I10 -> 0 | P10: =IF(Q10=0,0,($E$75-Q10)) -> 0
A11: AS201608 | B11: =VLOOKUP(A11,[4]LISTADHERENT!A$5:H$60,3,0) -> DJUOMBESSY ANTOINE | C11: =IF(G11=0,0,G11-D11) -> 14500 | D11: =IF(F11="ECHEC",0,IF(F11="",0,20000)) -> 20000 | E11: =IF(F11="ESPECES",3000,0) -> 0 | F11: BANQUE | G11: 34500 | L11: =TONTNOV!H11+TONTNOV!I11 -> 25500 | M11: BANQUE | P11: =IF(Q11=0,0,($E$75-Q11)) -> 0
A12: AS201651 | B12: =VLOOKUP(A12,[4]LISTADHERENT!A$5:H$60,3,0) -> DOMOU FABIEN | C12: =IF(G12=0,0,G12-D12) -> 10000 | D12: =IF(F12="ECHEC",0,IF(F12="",0,20000)) -> 20000 | E12: =IF(F12="ESPECES",3000,0) -> 0 | F12: BANQUE | G12: =IF(F12="BANQUE",30000,IF(F12="ESPECES",30000,0)) -> 30000 | L12: =TONTNOV!H12+TONTNOV!I12 -> 0 | P12: =IF(Q12=0,0,($E$75-Q12)) -> 0
A13: AS201609 | B13: =VLOOKUP(A13,[4]LISTADHERENT!A$5:H$60,3,0) -> DONHOU DAVID | C13: =IF(G13=0,0,G13-D13) -> 10000 | D13: =IF(F13="ECHEC",0,IF(F13="",0,20000)) -> 20000 | E13: =IF(F13="ESPECES",3000,0) -> 0 | F13: BANQUE | G13: =IF(F13="BANQUE",30000,IF(F13="ESPECES",30000,0)) -> 30000 | L13: =TONTNOV!H13+TONTNOV!I13 -> 0 | P13: =IF(Q13=0,0,($E$75-Q13)) -> 0
A14: AS201610 | B14: =VLOOKUP(A14,[4]LISTADHERENT!A$5:H$60,3,0) -> FOTSO THOMAS | C14: =IF(G14=0,0,G14-D14) -> 10000 | D14: =IF(F14="ECHEC",0,IF(F14="",0,20000)) -> 20000 | E14: =IF(F14="ESPECES",3000,0) -> 3000 | F14: ESPECES | G14: =IF(F14="BANQUE",30000,IF(F14="ESPECES",30000,0)) -> 30000 | H14: 50000 | I14: 1500 | L14: =TONTNOV!H14+TONTNOV!I14 -> 51000 | M14: ESPECES | P14: =IF(Q14=0,0,($E$75-Q14)) -> 0
A15: AS201611 | B15: =VLOOKUP(A15,[4]LISTADHERENT!A$5:H$60,3,0) -> HENGUE PAUL OMER | C15: 5000 | D15: =IF(F15="ECHEC",0,IF(F15="",0,20000)) -> 0 | E15: =IF(F15="ESPECES",3000,0) -> 0 | F15: ECHEC | G15: =IF(F15="BANQUE",30000,IF(F15="ESPECES",30000,0)) -> 0 | L15: =TONTNOV!H15+TONTNOV!I15 -> 0 | P15: =IF(Q15=0,0,($E$75-Q15)) -> 0
A16: AS201613 | B16: =VLOOKUP(A16,[4]LISTADHERENT!A$5:H$60,3,0) -> HOTCHO BENJAMIN | C16: =IF(G16=0,0,G16-D16) -> 10000 | D16: =IF(F16="ECHEC",0,IF(F16="",0,20000)) -> 20000 | E16: =IF(F16="ESPECES",3000,0) -> 0 | F16: BANQUE | G16: =IF(F16="BANQUE",30000,IF(F16="ESPECES",30000,0)) -> 30000 | L16: =TONTNOV!H16+TONTNOV!I16 -> 0 | P16: =IF(Q16=0,0,($E$75-Q16)) -> 0
A17: AS201615 | B17: =VLOOKUP(A17,[4]LISTADHERENT!A$5:H$60,3,0) -> KEPSEU FRANCIS | C17: =IF(G17=0,0,G17-D17) -> 40000 | D17: =IF(F17="ECHEC",0,IF(F17="",0,20000)) -> 20000 | E17: =IF(F17="ESPECES",3000,0) -> 0 | F17: BANQUE | G17: 60000 | L17: =TONTNOV!H17+TONTNOV!I17 -> 0 | P17: =IF(Q17=0,0,($E$75-Q17)) -> 0
A18: AS201618 | B18: =VLOOKUP(A18,[4]LISTADHERENT!A$5:H$60,3,0) -> KOUAMO VICTOR PEGUY | C18: =IF(G18=0,0,G18-D18) -> 7000 | D18: =IF(F18="ECHEC",0,IF(F18="",0,20000)) -> 20000 | E18: =IF(F18="ESPECES",3000,0) -> 3000 | F18: ESPECES | G18: 27000 | L18: =TONTNOV!H18+TONTNOV!I18 -> 0 | P18: =IF(Q18=0,0,($E$75-Q18)) -> 0
A19: AS201617 | B19: =VLOOKUP(A19,[4]LISTADHERENT!A$5:H$60,3,0) -> KOUAMOU MOISE | C19: =IF(G19=0,0,G19-D19) -> 10000 | D19: =IF(F19="ECHEC",0,IF(F19="",0,20000)) -> 20000 | E19: =IF(F19="ESPECES",3000,0) -> 0 | F19: BANQUE | G19: =IF(F19="BANQUE",30000,IF(F19="ESPECES",30000,0)) -> 30000 | L19: =TONTNOV!H19+TONTNOV!I19 -> 0 | P19: =IF(Q19=0,0,($E$75-Q19)) -> 0
A20: AS201619 | B20: =VLOOKUP(A20,[4]LISTADHERENT!A$5:H$60,3,0) -> KOUATCHO MESSACK | C20: =IF(G20=0,0,G20-D20) -> 10000 | D20: =IF(F20="ECHEC",0,IF(F20="",0,20000)) -> 20000 | E20: =IF(F20="ESPECES",3000,0) -> 0 | F20: BANQUE | G20: =IF(F20="BANQUE",30000,IF(F20="ESPECES",30000,0)) -> 30000 | L20: =TONTNOV!H20+TONTNOV!I20 -> 0 | P20: =IF(Q20=0,0,($E$75-Q20)) -> 0
A21: AS201620 | B21: =VLOOKUP(A21,[4]LISTADHERENT!A$5:H$60,3,0) -> LOWE JEAN | C21: =IF(G21=0,0,G21-D21) -> 10000 | D21: =IF(F21="ECHEC",0,IF(F21="",0,20000)) -> 20000 | E21: =IF(F21="ESPECES",3000,0) -> 0 | F21: BANQUE | G21: =IF(F21="BANQUE",30000,IF(F21="ESPECES",30000,0)) -> 30000 | L21: =TONTNOV!H21+TONTNOV!I21 -> 0 | P21: =IF(Q21=0,0,($E$75-Q21)) -> 0
A22: AS201649 | B22: =VLOOKUP(A22,[4]LISTADHERENT!A$5:H$60,3,0) -> MBOGNING TUGMA GUY | C22: =IF(G22=0,0,G22-D22) -> 10000 | D22: =IF(F22="ECHEC",0,IF(F22="",0,20000)) -> 20000 | E22: =IF(F22="ESPECES",3000,0) -> 0 | F22: BANQUE | G22: =IF(F22="BANQUE",30000,IF(F22="ESPECES",30000,0)) -> 30000 | L22: =TONTNOV!H22+TONTNOV!I22 -> 0 | P22: =IF(Q22=0,0,($E$75-Q22)) -> 0
A23: AS201639 | B23: =VLOOKUP(A23,[4]LISTADHERENT!A$5:H$60,3,0) -> NANGUEN MARTIN | C23: =IF(G23=0,0,G23-D23) -> 10000 | D23: =IF(F23="ECHEC",0,IF(F23="",0,20000)) -> 20000 | E23: =IF(F23="ESPECES",3000,0) -> 0 | F23: BANQUE | G23: =IF(F23="BANQUE",30000,IF(F23="ESPECES",30000,0)) -> 30000 | L23: =TONTNOV!H23+TONTNOV!I23 -> 0 | P23: =IF(Q23=0,0,($E$75-Q23)) -> 0
A24: AS201621 | B24: =VLOOKUP(A24,[4]LISTADHERENT!A$5:H$60,3,0) -> NANKAM APPOLINAIRE | C24: =IF(G24=0,0,G24-D24) -> 10000 | D24: =IF(F24="ECHEC",0,IF(F24="",0,20000)) -> 20000 | E24: =IF(F24="ESPECES",3000,0) -> 0 | F24: BANQUE | G24: =IF(F24="BANQUE",30000,IF(F24="ESPECES",30000,0)) -> 30000 | L24: =TONTNOV!H24+TONTNOV!I24 -> 0 | P24: =IF(Q24=0,0,($E$75-Q24)) -> 0
A25: AS201622 | B25: =VLOOKUP(A25,[4]LISTADHERENT!A$5:H$60,3,0) -> NDJOMO ETIENNE | C25: =IF(G25=0,0,G25-D25) -> 14000 | D25: =IF(F25="ECHEC",0,IF(F25="",0,20000)) -> 20000 | E25: =IF(F25="ESPECES",3000,0) -> 0 | F25: BANQUE | G25: 34000 | L25: =TONTNOV!H25+TONTNOV!I25 -> 0 | P25: =IF(Q25=0,0,($E$75-Q25)) -> 0
A26: AS201624 | B26: =VLOOKUP(A26,[4]LISTADHERENT!A$5:H$60,3,0) -> NGONDIEP CLAUDE | C26: =IF(G26=0,0,G26-D26) -> 20000 | D26: =IF(F26="ECHEC",0,IF(F26="",0,20000)) -> 20000 | E26: =IF(F26="ESPECES",3000,0) -> 0 | F26: BANQUE | G26: 40000 | L26: =TONTNOV!H26+TONTNOV!I26 -> 0 | P26: =IF(Q26=0,0,($E$75-Q26)) -> 0
A27: AS201626 | B27: =VLOOKUP(A27,[4]LISTADHERENT!A$5:H$60,3,0) -> NGUIEMEGNI MATHIEU BLAISE | C27: =IF(G27=0,0,G27-D27) -> 10000 | D27: =IF(F27="ECHEC",0,IF(F27="",0,20000)) -> 20000 | E27: =IF(F27="ESPECES",3000,0) -> 0 | F27: BANQUE | G27: =IF(F27="BANQUE",30000,IF(F27="ESPECES",30000,0)) -> 30000 | L27: =TONTNOV!H27+TONTNOV!I27 -> 0 | P27: =IF(Q27=0,0,($E$75-Q27)) -> 255000 | Q27: 45000
A28: AS201628 | B28: =VLOOKUP(A28,[4]LISTADHERENT!A$5:H$60,3,0) -> NKAMGANG JUSTIN DEJOLIE | C28: =IF(G28=0,0,G28-D28) -> 10000 | D28: =IF(F28="ECHEC",0,IF(F28="",0,20000)) -> 20000 | E28: =IF(F28="ESPECES",3000,0) -> 3000 | F28: ESPECES | G28: =IF(F28="BANQUE",30000,IF(F28="ESPECES",30000,0)) -> 30000 | H28: 50000 | I28: 2000 | L28: =TONTNOV!H28+TONTNOV!I28 -> 0 | P28: =IF(Q28=0,0,($E$75-Q28)) -> 0
A29: AS201614 | B29: =VLOOKUP(A29,[4]LISTADHERENT!A$5:H$60,3,0) -> NKEHE DAVID | C29: =IF(G29=0,0,G29-D29) -> 10000 | D29: =IF(F29="ECHEC",0,IF(F29="",0,20000)) -> 20000 | E29: =IF(F29="ESPECES",3000,0) -> 0 | F29: BANQUE | G29: =IF(F29="BANQUE",30000,IF(F29="ESPECES",30000,0)) -> 30000 | H29: 50000 | I29: 3000 | L29: =TONTNOV!H29+TONTNOV!I29 -> 32500 | M29: ESPECES | P29: =IF(Q29=0,0,($E$75-Q29)) -> 0
A30: AS201629 | B30: =VLOOKUP(A30,[4]LISTADHERENT!A$5:H$60,3,0) -> NKEPSEU DIEUDONNE | C30: =IF(G30=0,0,G30-D30) -> 10000 | D30: =IF(F30="ECHEC",0,IF(F30="",0,20000)) -> 20000 | E30: =IF(F30="ESPECES",3000,0) -> 3000 | F30: ESPECES | G30: =IF(F30="BANQUE",30000,IF(F30="ESPECES",30000,0)) -> 30000 | H30: 39000 | I30: 1000 | L30: =TONTNOV!H30+TONTNOV!I30 -> 0 | P30: =IF(Q30=0,0,($E$75-Q30)) -> 0
A31: AS201633 | B31: =VLOOKUP(A31,[4]LISTADHERENT!A$5:H$60,3,0) -> PATEGO NJOSSU GUSTAVE | C31: =IF(G31=0,0,G31-D31) -> 10000 | D31: =IF(F31="ECHEC",0,IF(F31="",0,20000)) -> 20000 | E31: =IF(F31="ESPECES",3000,0) -> 0 | F31: BANQUE | G31: =IF(F31="BANQUE",30000,IF(F31="ESPECES",30000,0)) -> 30000 | L31: =TONTNOV!H31+TONTNOV!I31 -> 0 | P31: =IF(Q31=0,0,($E$75-Q31)) -> 0
A32: AS201653 | B32: =VLOOKUP(A32,[4]LISTADHERENT!A$5:H$60,3,0) -> SIME BRICE | C32: =IF(G32=0,0,G32-D32) -> 50000 | D32: =IF(F32="ECHEC",0,IF(F32="",0,20000)) -> 20000 | E32: =IF(F32="ESPECES",3000,0) -> 3000 | F32: ESPECES | G32: 70000 | L32: =TONTNOV!H32+TONTNOV!I32 -> 0 | P32: =IF(Q32=0,0,($E$75-Q32)) -> 0
A33: AS201636 | B33: =VLOOKUP(A33,[4]LISTADHERENT!A$5:H$60,3,0) -> SIMO FONGANG ERIC | C33: =IF(G33=0,0,G33-D33) -> 10000 | D33: =IF(F33="ECHEC",0,IF(F33="",0,20000)) -> 20000 | E33: =IF(F33="ESPECES",3000,0) -> 3000 | F33: ESPECES | G33: =IF(F33="BANQUE",30000,IF(F33="ESPECES",30000,0)) -> 30000 | L33: =TONTNOV!H33+TONTNOV!I33 -> 0 | P33: =IF(Q33=0,0,($E$75-Q33)) -> 255000 | Q33: 45000
A34: AS201637 | B34: =VLOOKUP(A34,[4]LISTADHERENT!A$5:H$60,3,0) -> SIME MATHIEU | C34: =IF(G34=0,0,G34-D34) -> 10000 | D34: =IF(F34="ECHEC",0,IF(F34="",0,20000)) -> 20000 | E34: =IF(F34="ESPECES",3000,0) -> 0 | F34: BANQUE | G34: =IF(F34="BANQUE",30000,IF(F34="ESPECES",30000,0)) -> 30000 | L34: =TONTNOV!H34+TONTNOV!I34 -> 0 | P34: =IF(Q34=0,0,($E$75-Q34)) -> 0
A35: AS201638 | B35: =VLOOKUP(A35,[4]LISTADHERENT!A$5:H$60,3,0) -> SIMO PIERRE | C35: =IF(G35=0,0,G35-D35) -> 10000 | D35: =IF(F35="ECHEC",0,IF(F35="",0,20000)) -> 20000 | E35: =IF(F35="ESPECES",3000,0) -> 0 | F35: BANQUE | G35: =IF(F35="BANQUE",30000,IF(F35="ESPECES",30000,0)) -> 30000 | L35: =TONTNOV!H35+TONTNOV!I35 -> 0 | P35: =IF(Q35=0,0,($E$75-Q35)) -> 0
A36: AS201641 | B36: =VLOOKUP(A36,[4]LISTADHERENT!A$5:H$60,3,0) -> TCHOUAMOU MATHIEU | C36: =IF(G36=0,0,G36-D36) -> 10000 | D36: =IF(F36="ECHEC",0,IF(F36="",0,20000)) -> 20000 | E36: =IF(F36="ESPECES",3000,0) -> 0 | F36: BANQUE | G36: =IF(F36="BANQUE",30000,IF(F36="ESPECES",30000,0)) -> 30000 | L36: =TONTNOV!H36+TONTNOV!I36 -> 0 | P36: =IF(Q36=0,0,($E$75-Q36)) -> 0
A37: AS201644 | B37: =VLOOKUP(A37,[4]LISTADHERENT!A$5:H$60,3,0) -> TIEYAM ERNEST | C37: =IF(G37=0,0,G37-D37) -> 0 | D37: =IF(F37="ECHEC",0,IF(F37="",0,20000)) -> 0 | E37: =IF(F37="ESPECES",3000,0) -> 0 | F37: ECHEC | G37: =IF(F37="BANQUE",30000,IF(F37="ESPECES",30000,0)) -> 0 | H37: 50000 | I37: 3000 | L37: =TONTNOV!H37+TONTNOV!I37 -> 0 | P37: =IF(Q37=0,0,($E$75-Q37)) -> 0
A38: AS201646 | B38: =VLOOKUP(A38,[4]LISTADHERENT!A$5:H$60,3,0) -> YEPMOU JEAN JACQUES | C38: =IF(G38=0,0,G38-D38) -> 10000 | D38: =IF(F38="ECHEC",0,IF(F38="",0,20000)) -> 20000 | E38: =IF(F38="ESPECES",3000,0) -> 3000 | F38: ESPECES | G38: =IF(F38="BANQUE",30000,IF(F38="ESPECES",30000,0)) -> 30000 | L38: =TONTNOV!H38+TONTNOV!I38 -> 0 | P38: =IF(Q38=0,0,($E$75-Q38)) -> 0
A39: AS201647 | B39: =VLOOKUP(A39,[4]LISTADHERENT!A$5:H$60,3,0) -> YOUMBI EMMANUEL | C39: =IF(G39=0,0,G39-D39) -> 10000 | D39: =IF(F39="ECHEC",0,IF(F39="",0,20000)) -> 20000 | E39: =IF(F39="ESPECES",3000,0) -> 0 | F39: BANQUE | G39: =IF(F39="BANQUE",30000,IF(F39="ESPECES",30000,0)) -> 30000 | L39: =TONTNOV!H39+TONTNOV!I39 -> 0 | P39: =IF(Q39=0,0,($E$75-Q39)) -> 0
A40: AS201655 | B40: =VLOOKUP(A40,[4]LISTADHERENT!A$5:H$60,3,0) -> TCHEMHOU EMMANUEL
...

Sheet TONTJANV
A1: ASSOCIATION | B1: ASELBY
A2: ANNEE | B2: 2019/2020
A3: TONTINE | B3: 30000
C4: 43849
A5: MATRICULE | B5: NOM ET PRENOM | C5: RESTE | D5: MONTANT TONTINE | E5: PENALITE VERSEMENT ESPECES | F5: MODE VERSEMENT | G5: MONTANT VERSE | H5: VENTE PETIT LOT | I5: INTERET PETIT LOT | J5: MODE VERSEMENT VENTE PETIT LOT | K5: NUMERO CHEQUE | L5: REMBOURSEMENT PETIT LOT | M5: MODE VERSEMENT REMBOURSEMENT | N5: MODE VERSEMENTLOT PRINCIPAL | O5: NUMERO CHEQUE | P5: MONTANT TONTINE LOT PRINCIPAL | Q5: INTERET LOT PRINCIPAL | R5: DEPOT
A6: AS201648 | B6: =VLOOKUP(A6,[4]LISTADHERENT!A$5:H$60,3,0) -> ASELBY | C6: =IF(G6=0,0,G6-D6) -> 0 | D6: =IF(F6="ECHEC",0,IF(F6="",0,20000)) -> 0 | E6: =IF(F6="ESPECES",3000,0) -> 0 | G6: =IF(F6="BANQUE",30000,IF(F6="ESPECES",30000,0)) -> 0 | L6: =TONTDEC!H6+TONTDEC!I6 -> 0 | P6: =IF(Q6=0,0,($E$76-Q6)) -> 0
A7: AS201602 | B7: =VLOOKUP(A7,[4]LISTADHERENT!A$5:H$60,3,0) -> BOUTCHOUANG WILLIAM | C7: =IF(G7=0,0,G7-D7) -> 10000 | D7: =IF(F7="ECHEC",0,IF(F7="",0,20000)) -> 20000 | E7: =IF(F7="ESPECES",3000,0) -> 0 | F7: BANQUE | G7: =IF(F7="BANQUE",30000,IF(F7="ESPECES",30000,0)) -> 30000 | L7: =TONTDEC!H7+TONTDEC!I7 -> 0 | P7: =IF(Q7=0,0,($E$75-Q7)) -> 0
A8: AS201604 | B8: =VLOOKUP(A8,[4]LISTADHERENT!A$5:H$60,3,0) -> DJOMO JEAN PAUL | C8: =IF(G8=0,0,G8-D8) -> 10000 | D8: =IF(F8="ECHEC",0,IF(F8="",0,20000)) -> 20000 | E8: =IF(F8="ESPECES",3000,0) -> 0 | F8: BANQUE | G8: =IF(F8="BANQUE",30000,IF(F8="ESPECES",30000,0)) -> 30000 | L8: =TONTDEC!H8+TONTDEC!I8 -> 0 | P8: =IF(Q8=0,0,($E$75-Q8)) -> 0
A9: AS201654 | B9: =VLOOKUP(A9,[4]LISTADHERENT!A$5:H$60,3,0) -> DJOMOU TCHANDA | C9: =IF(G9=0,0,G9-D9) -> 110000 | D9: =IF(F9="ECHEC",0,IF(F9="",0,20000)) -> 20000 | E9: =IF(F9="ESPECES",3000,0) -> 0 | F9: BANQUE | G9: =IF(F9="BANQUE",30000,IF(F9="ESPECES",30000,0))+100000 -> 130000 | L9: =TONTDEC!H9+TONTDEC!I9 -> 0 | P9: =IF(Q9=0,0,($E$75-Q9)) -> 0
A10: AS201605 | B10: =VLOOKUP(A10,[4]LISTADHERENT!A$5:H$60,3,0) -> DJOUKWE NANGUEN GUY BLAISE | C10: =IF(G10=0,0,G10-D10) -> 10000 | D10: =IF(F10="ECHEC",0,IF(F10="",0,20000)) -> 20000 | E10: =IF(F10="ESPECES",3000,0) -> 0 | F10: BANQUE | G10: =IF(F10="BANQUE",30000,IF(F10="ESPECES",30000,0)) -> 30000 | L10: =TONTDEC!H10+TONTDEC!I10 -> 0 | P10: =IF(Q10=0,0,($E$75-Q10)) -> 0
A11: AS201608 | B11: =VLOOKUP(A11,[4]LISTADHERENT!A$5:H$60,3,0) -> DJUOMBESSY ANTOINE | C11: =IF(G11=0,0,G11-D11) -> 10000 | D11: =IF(F11="ECHEC",0,IF(F11="",0,20000)) -> 20000 | E11: =IF(F11="ESPECES",3000,0) -> 0 | F11: BANQUE | G11: =IF(F11="BANQUE",30000,IF(F11="ESPECES",30000,0)) -> 30000 | L11: =TONTDEC!H11+TONTDEC!I11 -> 0 | P11: =IF(Q11=0,0,($E$75-Q11)) -> 0
A12: AS201651 | B12: =VLOOKUP(A12,[4]LISTADHERENT!A$5:H$60,3,0) -> DOMOU FABIEN | C12: =IF(G12=0,0,G12-D12) -> 10000 | D12: =IF(F12="ECHEC",0,IF(F12="",0,20000)) -> 20000 | E12: =IF(F12="ESPECES",3000,0) -> 0 | F12: BANQUE | G12: =IF(F12="BANQUE",30000,IF(F12="ESPECES",30000,0)) -> 30000 | L12: =TONTDEC!H12+TONTDEC!I12 -> 0 | P12: =IF(Q12=0,0,($E$75-Q12)) -> 0
A13: AS201609 | B13: =VLOOKUP(A13,[4]LISTADHERENT!A$5:H$60,3,0) -> DONHOU DAVID | C13: =IF(G13=0,0,G13-D13) -> 10000 | D13: =IF(F13="ECHEC",0,IF(F13="",0,20000)) -> 20000 | E13: =IF(F13="ESPECES",3000,0) -> 0 | F13: BANQUE | G13: =IF(F13="BANQUE",30000,IF(F13="ESPECES",30000,0)) -> 30000 | L13: =TONTDEC!H13+TONTDEC!I13 -> 0 | P13: =IF(Q13=0,0,($E$75-Q13)) -> 0
A14: AS201610 | B14: =VLOOKUP(A14,[4]LISTADHERENT!A$5:H$60,3,0) -> FOTSO THOMAS | C14: =IF(G14=0,0,G14-D14) -> 10000 | D14: =IF(F14="ECHEC",0,IF(F14="",0,20000)) -> 20000 | E14: =IF(F14="ESPECES",3000,0) -> 0 | F14: BANQUE | G14: =IF(F14="BANQUE",30000,IF(F14="ESPECES",30000,0)) -> 30000 | H14: 51500 | I14: 3000 | L14: =TONTDEC!H14+TONTDEC!I14 -> 51500 | M14: ECHEC | P14: =IF(Q14=0,0,($E$75-Q14)) -> 0
A15: AS201611 | B15: =VLOOKUP(A15,[4]LISTADHERENT!A$5:H$60,3,0) -> HENGUE PAUL OMER | C15: =IF(G15=0,0,G15-D15) -> 15000 | D15: 40000 | E15: 3000 | F15: BANQUE | G15: =IF(F15="BANQUE",30000,IF(F15="ESPECES",30000,0))+25000 -> 55000 | L15: =TONTDEC!H15+TONTDEC!I15 -> 0 | P15: =IF(Q15=0,0,($E$75-Q15)) -> 0
A16: AS201613 | B16: =VLOOKUP(A16,[4]LISTADHERENT!A$5:H$60,3,0) -> HOTCHO BENJAMIN | C16: =IF(G16=0,0,G16-D16) -> 5000 | D16: =IF(F16="ECHEC",0,IF(F16="",0,20000)) -> 20000 | E16: =IF(F16="ESPECES",3000,0) -> 0 | F16: BANQUE | G16: =IF(F16="BANQUE",30000,IF(F16="ESPECES",30000,0))-5000 -> 25000 | L16: =TONTDEC!H16+TONTDEC!I16 -> 0 | P16: =IF(Q16=0,0,($E$75-Q16)) -> 0
A17: AS201615 | B17: =VLOOKUP(A17,[4]LISTADHERENT!A$5:H$60,3,0) -> KEPSEU FRANCIS | C17: =IF(G17=0,0,G17-D17) -> 10000 | D17: =IF(F17="ECHEC",0,IF(F17="",0,20000)) -> 20000 | E17: =IF(F17="ESPECES",3000,0) -> 0 | F17: BANQUE | G17: =IF(F17="BANQUE",30000,IF(F17="ESPECES",30000,0)) -> 30000 | L17: =TONTDEC!H17+TONTDEC!I17 -> 0 | P17: =IF(Q17=0,0,($E$75-Q17)) -> 0
A18: AS201618 | B18: =VLOOKUP(A18,[4]LISTADHERENT!A$5:H$60,3,0) -> KOUAMO VICTOR PEGUY | C18: =IF(G18=0,0,G18-D18) -> 10000 | D18: =IF(F18="ECHEC",0,IF(F18="",0,20000)) -> 20000 | E18: 0 | F18: ESPECES | G18: =IF(F18="BANQUE",30000,IF(F18="ESPECES",30000,0)) -> 30000 | L18: =TONTDEC!H18+TONTDEC!I18 -> 0 | P18: =IF(Q18=0,0,($E$75-Q18)) -> 0
A19: AS201617 | B19: =VLOOKUP(A19,[4]LISTADHERENT!A$5:H$60,3,0) -> KOUAMOU MOISE | C19: =IF(G19=0,0,G19-D19) -> 10000 | D19: =IF(F19="ECHEC",0,IF(F19="",0,20000)) -> 20000 | E19: =IF(F19="ESPECES",3000,0) -> 0 | F19: BANQUE | G19: =IF(F19="BANQUE",30000,IF(F19="ESPECES",30000,0)) -> 30000 | H19: 30000 | I19: 2500 | L19: =TONTDEC!H19+TONTDEC!I19 -> 0 | P19: =IF(Q19=0,0,($E$75-Q19)) -> 0
A20: AS201619 | B20: =VLOOKUP(A20,[4]LISTADHERENT!A$5:H$60,3,0) -> KOUATCHO MESSACK | C20: =IF(G20=0,0,G20-D20) -> 10000 | D20: =IF(F20="ECHEC",0,IF(F20="",0,20000)) -> 20000 | E20: =IF(F20="ESPECES",3000,0) -> 3000 | F20: ESPECES | G20: =IF(F20="BANQUE",30000,IF(F20="ESPECES",30000,0)) -> 30000 | L20: =TONTDEC!H20+TONTDEC!I20 -> 0 | P20: =IF(Q20=0,0,($E$75-Q20)) -> 277000 | Q20: 23000
A21: AS201620 | B21: =VLOOKUP(A21,[4]LISTADHERENT!A$5:H$60,3,0) -> LOWE JEAN | C21: =IF(G21=0,0,G21-D21) -> 10000 | D21: =IF(F21="ECHEC",0,IF(F21="",0,20000)) -> 20000 | E21: =IF(F21="ESPECES",3000,0) -> 0 | F21: BANQUE | G21: =IF(F21="BANQUE",30000,IF(F21="ESPECES",30000,0)) -> 30000 | L21: =TONTDEC!H21+TONTDEC!I21 -> 0 | P21: =IF(Q21=0,0,($E$75-Q21)) -> 0
A22: AS201649 | B22: =VLOOKUP(A22,[4]LISTADHERENT!A$5:H$60,3,0) -> MBOGNING TUGMA GUY | C22: =IF(G22=0,0,G22-D22) -> 10000 | D22: =IF(F22="ECHEC",0,IF(F22="",0,20000)) -> 20000 | E22: =IF(F22="ESPECES",3000,0) -> 0 | F22: BANQUE | G22: =IF(F22="BANQUE",30000,IF(F22="ESPECES",30000,0)) -> 30000 | L22: =TONTDEC!H22+TONTDEC!I22 -> 0 | P22: =IF(Q22=0,0,($E$75-Q22)) -> 0
A23: AS201639 | B23: =VLOOKUP(A23,[4]LISTADHERENT!A$5:H$60,3,0) -> NANGUEN MARTIN | C23: =IF(G23=0,0,G23-D23) -> 10000 | D23: =IF(F23="ECHEC",0,IF(F23="",0,20000)) -> 20000 | E23: =IF(F23="ESPECES",3000,0) -> 0 | F23: BANQUE | G23: =IF(F23="BANQUE",30000,IF(F23="ESPECES",30000,0)) -> 30000 | L23: =TONTDEC!H23+TONTDEC!I23 -> 0 | P23: =IF(Q23=0,0,($E$75-Q23)) -> 0
A24: AS201621 | B24: =VLOOKUP(A24,[4]LISTADHERENT!A$5:H$60,3,0) -> NANKAM APPOLINAIRE | C24: =IF(G24=0,0,G24-D24) -> 10000 | D24: =IF(F24="ECHEC",0,IF(F24="",0,20000)) -> 20000 | E24: =IF(F24="ESPECES",3000,0) -> 0 | F24: BANQUE | G24: =IF(F24="BANQUE",30000,IF(F24="ESPECES",30000,0)) -> 30000 | L24: =TONTDEC!H24+TONTDEC!I24 -> 0 | P24: =IF(Q24=0,0,($E$75-Q24)) -> 0
A25: AS201622 | B25: =VLOOKUP(A25,[4]LISTADHERENT!A$5:H$60,3,0) -> NDJOMO ETIENNE | C25: =IF(G25=0,0,G25-D25) -> 14000 | D25: =IF(F25="ECHEC",0,IF(F25="",0,20000)) -> 20000 | E25: =IF(F25="ESPECES",3000,0) -> 0 | F25: BANQUE | G25: =IF(F25="BANQUE",30000,IF(F25="ESPECES",30000,0))+4000 -> 34000 | L25: =TONTDEC!H25+TONTDEC!I25 -> 0 | P25: =IF(Q25=0,0,($E$75-Q25)) -> 0
A26: AS201624 | B26: =VLOOKUP(A26,[4]LISTADHERENT!A$5:H$60,3,0) -> NGONDIEP CLAUDE | C26: =IF(G26=0,0,G26-D26) -> 20000 | D26: =IF(F26="ECHEC",0,IF(F26="",0,20000)) -> 20000 | E26: =IF(F26="ESPECES",3000,0) -> 0 | F26: BANQUE | G26: =IF(F26="BANQUE",30000,IF(F26="ESPECES",30000,0))+10000 -> 40000 | L26: =TONTDEC!H26+TONTDEC!I26 -> 0 | P26: =IF(Q26=0,0,($E$75-Q26)) -> 0
A27: AS201626 | B27: =VLOOKUP(A27,[4]LISTADHERENT!A$5:H$60,3,0) -> NGUIEMEGNI MATHIEU BLAISE | C27: =IF(G27=0,0,G27-D27) -> 10000 | D27: =IF(F27="ECHEC",0,IF(F27="",0,20000)) -> 20000 | E27: =IF(F27="ESPECES",3000,0) -> 0 | F27: BANQUE | G27: =IF(F27="BANQUE",30000,IF(F27="ESPECES",30000,0)) -> 30000 | L27: =TONTDEC!H27+TONTDEC!I27 -> 0 | P27: =IF(Q27=0,0,($E$75-Q27)) -> 0
A28: AS201628 | B28: =VLOOKUP(A28,[4]LISTADHERENT!A$5:H$60,3,0) -> NKAMGANG JUSTIN DEJOLIE | C28: =IF(G28=0,0,G28-D28) -> 10000 | D28: =IF(F28="ECHEC",0,IF(F28="",0,20000)) -> 20000 | E28: =IF(F28="ESPECES",3000,0) -> 3000 | F28: ESPECES | G28: =IF(F28="BANQUE",30000,IF(F28="ESPECES",30000,0)) -> 30000 | L28: =TONTDEC!H28+TONTDEC!I28 -> 52000 | M28: ESPECES | P28: =IF(Q28=0,0,($E$75-Q28)) -> 263000 | Q28: 37000
A29: AS201614 | B29: =VLOOKUP(A29,[4]LISTADHERENT!A$5:H$60,3,0) -> NKEHE DAVID | C29: =IF(G29=0,0,G29-D29) -> 10000 | D29: =IF(F29="ECHEC",0,IF(F29="",0,20000)) -> 20000 | E29: =IF(F29="ESPECES",3000,0) -> 0 | F29: BANQUE | G29: =IF(F29="BANQUE",30000,IF(F29="ESPECES",30000,0)) -> 30000 | L29: =TONTDEC!H29+TONTDEC!I29 -> 53000 | M29: BANQUE | P29: =IF(Q29=0,0,($E$75-Q29)) -> 275000 | Q29: 25000
A30: AS201629 | B30: =VLOOKUP(A30,[4]LISTADHERENT!A$5:H$60,3,0) -> NKEPSEU DIEUDONNE | C30: =IF(G30=0,0,G30-D30) -> 20000 | D30: =IF(F30="ECHEC",0,IF(F30="",0,20000)) -> 20000 | E30: =IF(F30="ESPECES",3000,0) -> 0 | F30: BANQUE | G30: =IF(F30="BANQUE",30000,IF(F30="ESPECES",30000,0))+10000 -> 40000 | L30: =TONTDEC!H30+TONTDEC!I30 -> 40000 | M30: BANQUE | P30: =IF(Q30=0,0,($E$75-Q30)) -> 0
A31: AS201633 | B31: =VLOOKUP(A31,[4]LISTADHERENT!A$5:H$60,3,0) -> PATEGO NJOSSU GUSTAVE | C31: =IF(G31=0,0,G31-D31) -> 10000 | D31: =IF(F31="ECHEC",0,IF(F31="",0,20000)) -> 20000 | E31: =IF(F31="ESPECES",3000,0) -> 0 | F31: BANQUE | G31: =IF(F31="BANQUE",30000,IF(F31="ESPECES",30000,0)) -> 30000 | L31: =TONTDEC!H31+TONTDEC!I31 -> 0 | P31: =IF(Q31=0,0,($E$75-Q31)) -> 0
A32: AS201653 | B32: =VLOOKUP(A32,[4]LISTADHERENT!A$5:H$60,3,0) -> SIME BRICE | C32: =IF(G32=0,0,G32-D32) -> 50000 | D32: =IF(F32="ECHEC",0,IF(F32="",0,20000)) -> 20000 | E32: =IF(F32="ESPECES",3000,0) -> 0 | F32: BANQUE | G32: 70000 | L32: =TONTDEC!H32+TONTDEC!I32 -> 0 | P32: =IF(Q32=0,0,($E$75-Q32)) -> 0
A33: AS201636 | B33: =VLOOKUP(A33,[4]LISTADHERENT!A$5:H$60,3,0) -> SIMO FONGANG ERIC | C33: =IF(G33=0,0,G33-D33) -> 10000 | D33: =IF(F33="ECHEC",0,IF(F33="",0,20000)) -> 20000 | E33: =IF(F33="ESPECES",3000,0) -> 0 | F33: BANQUE | G33: =IF(F33="BANQUE",30000,IF(F33="ESPECES",30000,0)) -> 30000 | L33: =TONTDEC!H33+TONTDEC!I33 -> 0 | P33: =IF(Q33=0,0,($E$75-Q33)) -> 0
A34: AS201637 | B34: =VLOOKUP(A34,[4]LISTADHERENT!A$5:H$60,3,0) -> SIME MATHIEU | C34: =IF(G34=0,0,G34-D34) -> 10000 | D34: =IF(F34="ECHEC",0,IF(F34="",0,20000)) -> 20000 | E34: =IF(F34="ESPECES",3000,0) -> 0 | F34: BANQUE | G34: =IF(F34="BANQUE",30000,IF(F34="ESPECES",30000,0)) -> 30000 | L34: =TONTDEC!H34+TONTDEC!I34 -> 0 | P34: =IF(Q34=0,0,($E$75-Q34)) -> 0
A35: AS201638 | B35: =VLOOKUP(A35,[4]LISTADHERENT!A$5:H$60,3,0) -> SIMO PIERRE | C35: =IF(G35=0,0,G35-D35) -> 10000 | D35: =IF(F35="ECHEC",0,IF(F35="",0,20000)) -> 20000 | E35: =IF(F35="ESPECES",3000,0) -> 0 | F35: BANQUE | G35: =IF(F35="BANQUE",30000,IF(F35="ESPECES",30000,0)) -> 30000 | L35: =TONTDEC!H35+TONTDEC!I35 -> 0 | P35: =IF(Q35=0,0,($E$75-Q35)) -> 0
A36: AS201641 | B36: =VLOOKUP(A36,[4]LISTADHERENT!A$5:H$60,3,0) -> TCHOUAMOU MATHIEU | C36: =IF(G36=0,0,G36-D36) -> 10000 | D36: =IF(F36="ECHEC",0,IF(F36="",0,20000)) -> 20000 | E36: =IF(F36="ESPECES",3000,0) -> 0 | F36: BANQUE | G36: =IF(F36="BANQUE",30000,IF(F36="ESPECES",30000,0)) -> 30000 | L36: =TONTDEC!H36+TONTDEC!I36 -> 0 | P36: =IF(Q36=0,0,($E$75-Q36)) -> 0
A37: AS201644 | B37: =VLOOKUP(A37,[4]LISTADHERENT!A$5:H$60,3,0) -> TIEYAM ERNEST | C37: =IF(G37=0,0,G37-D37) -> 10000 | D37: =IF(F37="ECHEC",0,IF(F37="",0,20000)) -> 20000 | E37: =IF(F37="ESPECES",3000,0) -> 0 | F37: BANQUE | G37: =IF(F37="BANQUE",30000,IF(F37="ESPECES",30000,0)) -> 30000 | H37: 33000 | I37: 3000 | L37: =TONTDEC!H37+TONTDEC!I37 -> 53000 | M37: ESPECES | P37: =IF(Q37=0,0,($E$75-Q37)) -> 0
A38: AS201646 | B38: =VLOOKUP(A38,[4]LISTADHERENT!A$5:H$60,3,0) -> YEPMOU JEAN JACQUES | C38: =IF(G38=0,0,G38-D38) -> 10000 | D38: =IF(F38="ECHEC",0,IF(F38="",0,20000)) -> 20000 | E38: =IF(F38="ESPECES",3000,0) -> 3000 | F38: ESPECES | G38: =IF(F38="BANQUE",30000,IF(F38="ESPECES",30000,0)) -> 30000 | L38: =TONTDEC!H38+TONTDEC!I38 -> 0 | P38: =IF(Q38=0,0,($E$75-Q38)) -> 0
A39: AS201647 | B39: =VLOOKUP(A39,[4]LISTADHERENT!A$5:H$60,3,0) -> YOUMBI EMMANUEL | C39: =IF(G39=0,0,G39-D39) -> 10000 | D39: =IF(F39="ECHEC",0,IF(F39="",0,20000)) -> 20000 | E39: =IF(F39="ESPECES",3000,0) -> 0 | F39: BANQUE | G39: =IF(F39="BANQUE",30000,IF(F39="ESPECES",30000,0)) -> 30000 | L39: =TONTDEC!H39+TONTDEC!I39 -> 0 | P39: =IF(Q39=0,0,($E$75-Q39)) -> 0
A40: AS201655 | B40: =VLOOKUP(A40,[4]LISTADHERENT!A$5:H$60,3,0) -> TCHEMHOU EMMANUEL
...

Sheet TONTFEV
A1: ASSOCIATION | B1: ASELBY
A2: ANNEE | B2: 2019/2020
A3: TONTINE | B3: 30000
C4: 43877
A5: MATRICULE | B5: NOM ET PRENOM | C5: RESTE | D5: MONTANT TONTINE | E5: PENALITE VERSEMENT ESPECES | F5: MODE VERSEMENT | G5: MONTANT VERSE | H5: VENTE PETIT LOT | I5: INTERET PETIT LOT | J5: MODE VERSEMENT VENTE PETIT LOT | K5: NUMERO CHEQUE | L5: REMBOURSEMENT PETIT LOT | M5: MODE VERSEMENT REMBOURSEMENT | N5: MODE VERSEMENTLOT PRINCIPAL | O5: NUMERO CHEQUE | P5: MONTANT TONTINE LOT PRINCIPAL | Q5: INTERET LOT PRINCIPAL | R5: DEPOT
A6: AS201648 | B6: =VLOOKUP(A6,[4]LISTADHERENT!A$5:H$60,3,0) -> ASELBY | C6: =IF(G6=0,0,G6-D6) -> 0 | D6: =IF(F6="ECHEC",0,IF(F6="",0,20000)) -> 0 | E6: =IF(F6="ESPECES",3000,0) -> 0 | F6: ECHEC | G6: =IF(F6="BANQUE",30000,IF(F6="ESPECES",30000,0)) -> 0 | L6: =TONTJANV!H6+TONTJANV!I6 -> 0 | P6: =IF(Q6=0,0,($E$76-Q6)) -> 0
A7: AS201602 | B7: =VLOOKUP(A7,[4]LISTADHERENT!A$5:H$60,3,0) -> BOUTCHOUANG WILLIAM | C7: =IF(G7=0,0,G7-D7) -> 10000 | D7: =IF(F7="ECHEC",0,IF(F7="",0,20000)) -> 20000 | E7: =IF(F7="ESPECES",3000,0) -> 0 | F7: BANQUE | G7: =IF(F7="BANQUE",30000,IF(F7="ESPECES",30000,0)) -> 30000 | L7: =TONTJANV!H7+TONTJANV!I7 -> 0 | P7: =IF(Q7=0,0,($E$75-Q7)) -> 0
A8: AS201604 | B8: =VLOOKUP(A8,[4]LISTADHERENT!A$5:H$60,3,0) -> DJOMO JEAN PAUL | C8: =IF(G8=0,0,G8-D8) -> 10000 | D8: =IF(F8="ECHEC",0,IF(F8="",0,20000)) -> 20000 | E8: =IF(F8="ESPECES",3000,0) -> 0 | F8: BANQUE | G8: =IF(F8="BANQUE",30000,IF(F8="ESPECES",30000,0)) -> 30000 | H8: =30000+24500 -> 54500 | I8: =500+2500 -> 3000 | L8: =TONTJANV!H8+TONTJANV!I8 -> 0 | P8: =IF(Q8=0,0,($E$75-Q8)) -> 0
A9: AS201654 | B9: =VLOOKUP(A9,[4]LISTADHERENT!A$5:H$60,3,0) -> DJOMOU TCHANDA | C9: =IF(G9=0,0,G9-D9) -> 110000 | D9: =IF(F9="ECHEC",0,IF(F9="",0,20000)) -> 20000 | E9: =IF(F9="ESPECES",3000,0) -> 0 | F9: BANQUE | G9: =IF(F9="BANQUE",30000,IF(F9="ESPECES",30000,0))+100000 -> 130000 | L9: =TONTJANV!H9+TONTJANV!I9 -> 0 | P9: =IF(Q9=0,0,($E$75-Q9)) -> 0
A10: AS201605 | B10: =VLOOKUP(A10,[4]LISTADHERENT!A$5:H$60,3,0) -> DJOUKWE NANGUEN GUY BLAISE | C10: =IF(G10=0,0,G10-D10) -> 20000 | D10: =IF(F10="ECHEC",0,IF(F10="",0,20000)) -> 20000 | E10: =IF(F10="ESPECES",3000,0) -> 0 | F10: BANQUE | G10: =IF(F10="BANQUE",30000,IF(F10="ESPECES",30000,0))+10000 -> 40000 | L10: =TONTJANV!H10+TONTJANV!I10 -> 0 | P10: =IF(Q10=0,0,($E$75-Q10)) -> 0
A11: AS201608 | B11: =VLOOKUP(A11,[4]LISTADHERENT!A$5:H$60,3,0) -> DJUOMBESSY ANTOINE | C11: =IF(G11=0,0,G11-D11) -> 10000 | D11: =IF(F11="ECHEC",0,IF(F11="",0,20000)) -> 20000 | E11: =IF(F11="ESPECES",3000,0) -> 0 | F11: BANQUE | G11: =IF(F11="BANQUE",30000,IF(F11="ESPECES",30000,0)) -> 30000 | L11: =TONTJANV!H11+TONTJANV!I11 -> 0 | P11: =IF(Q11=0,0,($E$75-Q11)) -> 0
A12: AS201651 | B12: =VLOOKUP(A12,[4]LISTADHERENT!A$5:H$60,3,0) -> DOMOU FABIEN | C12: =IF(G12=0,0,G12-D12) -> 10000 | D12: =IF(F12="ECHEC",0,IF(F12="",0,20000)) -> 20000 | E12: =IF(F12="ESPECES",3000,0) -> 0 | F12: BANQUE | G12: =IF(F12="BANQUE",30000,IF(F12="ESPECES",30000,0)) -> 30000 | L12: =TONTJANV!H12+TONTJANV!I12 -> 0 | P12: =IF(Q12=0,0,($E$75-Q12)) -> 0
A13: AS201609 | B13: =VLOOKUP(A13,[4]LISTADHERENT!A$5:H$60,3,0) -> DONHOU DAVID | C13: =IF(G13=0,0,G13-D13) -> 10000 | D13: =IF(F13="ECHEC",0,IF(F13="",0,20000)) -> 20000 | E13: =IF(F13="ESPECES",3000,0) -> 0 | F13: BANQUE | G13: =IF(F13="BANQUE",30000,IF(F13="ESPECES",30000,0)) -> 30000 | L13: =TONTJANV!H13+TONTJANV!I13 -> 0 | P13: =IF(Q13=0,0,($E$75-Q13)) -> 0
A14: AS201610 | B14: =VLOOKUP(A14,[4]LISTADHERENT!A$5:H$60,3,0) -> FOTSO THOMAS | C14: =IF(G14=0,0,G14-D14) -> 7000 | D14: =IF(F14="ECHEC",0,IF(F14="",0,20000)) -> 20000 | E14: =IF(F14="ESPECES",3000,0) -> 3000 | F14: ESPECES | G14: =IF(F14="BANQUE",30000,IF(F14="ESPECES",30000,0))-3000 -> 27000 | H14: 54500 | I14: 0 | L14: =TONTJANV!H14+TONTJANV!I14 -> 54500 | M14: ECHEC | P14: =IF(Q14=0,0,($E$75-Q14)) -> 0
A15: AS201611 | B15: =VLOOKUP(A15,[4]LISTADHERENT!A$5:H$60,3,0) -> HENGUE PAUL OMER | C15: =IF(G15=0,0,G15-D15) -> 10000 | D15: =IF(F15="ECHEC",0,IF(F15="",0,20000)) -> 20000 | E15: =IF(F15="ESPECES",3000,0) -> 0 | F15: BANQUE | G15: =IF(F15="BANQUE",30000,IF(F15="ESPECES",30000,0)) -> 30000 | L15: =TONTJANV!H15+TONTJANV!I15 -> 0 | P15: =IF(Q15=0,0,($E$75-Q15)) -> 0
A16: AS201613 | B16: =VLOOKUP(A16,[4]LISTADHERENT!A$5:H$60,3,0) -> HOTCHO BENJAMIN | C16: =IF(G16=0,0,G16-D16) -> 25000 | D16: =IF(F16="ECHEC",0,IF(F16="",0,20000)) -> 20000 | E16: =IF(F16="ESPECES",3000,0) -> 0 | F16: BANQUE | G16: =IF(F16="BANQUE",30000,IF(F16="ESPECES",30000,0))+15000 -> 45000 | L16: =TONTJANV!H16+TONTJANV!I16 -> 0 | P16: =IF(Q16=0,0,($E$75-Q16)) -> 0
A17: AS201615 | B17: =VLOOKUP(A17,[4]LISTADHERENT!A$5:H$60,3,0) -> KEPSEU FRANCIS | C17: =IF(G17=0,0,G17-D17) -> 10000 | D17: =IF(F17="ECHEC",0,IF(F17="",0,20000)) -> 20000 | E17: =IF(F17="ESPECES",3000,0) -> 0 | F17: BANQUE | G17: =IF(F17="BANQUE",30000,IF(F17="ESPECES",30000,0)) -> 30000 | L17: =TONTJANV!H17+TONTJANV!I17 -> 0 | P17: =IF(Q17=0,0,($E$75-Q17)) -> 0
A18: AS201618 | B18: =VLOOKUP(A18,[4]LISTADHERENT!A$5:H$60,3,0) -> KOUAMO VICTOR PEGUY | C18: =IF(G18=0,0,G18-D18) -> 0 | D18: =IF(F18="ECHEC",0,IF(F18="",0,20000)) -> 0 | E18: =IF(F18="ESPECES",3000,0) -> 0 | F18: ECHEC | G18: =IF(F18="BANQUE",30000,IF(F18="ESPECES",30000,0)) -> 0 | L18: =TONTJANV!H18+TONTJANV!I18 -> 0 | P18: =IF(Q18=0,0,($E$75-Q18)) -> 0
A19: AS201617 | B19: =VLOOKUP(A19,[4]LISTADHERENT!A$5:H$60,3,0) -> KOUAMOU MOISE | C19: =IF(G19=0,0,G19-D19) -> 10000 | D19: =IF(F19="ECHEC",0,IF(F19="",0,20000)) -> 20000 | E19: =IF(F19="ESPECES",3000,0) -> 0 | F19: BANQUE | G19: =IF(F19="BANQUE",30000,IF(F19="ESPECES",30000,0)) -> 30000 | H19: 1000 | I19: 0 | L19: =TONTJANV!H19+TONTJANV!I19-1000 -> 31500 | M19: BANQUE | P19: =IF(Q19=0,0,($E$75-Q19)) -> 279000 | Q19: 21000
A20: AS201619 | B20: =VLOOKUP(A20,[4]LISTADHERENT!A$5:H$60,3,0) -> KOUATCHO MESSACK | C20: =IF(G20=0,0,G20-D20) -> 10000 | D20: =IF(F20="ECHEC",0,IF(F20="",0,20000)) -> 20000 | E20: =IF(F20="ESPECES",3000,0) -> 0 | F20: BANQUE | G20: =IF(F20="BANQUE",30000,IF(F20="ESPECES",30000,0)) -> 30000 | L20: =TONTJANV!H20+TONTJANV!I20 -> 0 | P20: =IF(Q20=0,0,($E$75-Q20)) -> 0
A21: AS201620 | B21: =VLOOKUP(A21,[4]LISTADHERENT!A$5:H$60,3,0) -> LOWE JEAN | C21: =IF(G21=0,0,G21-D21) -> 10000 | D21: =IF(F21="ECHEC",0,IF(F21="",0,20000)) -> 20000 | E21: =IF(F21="ESPECES",3000,0) -> 0 | F21: BANQUE | G21: =IF(F21="BANQUE",30000,IF(F21="ESPECES",30000,0)) -> 30000 | L21: =TONTJANV!H21+TONTJANV!I21 -> 0 | P21: =IF(Q21=0,0,($E$75-Q21)) -> 0
A22: AS201649 | B22: =VLOOKUP(A22,[4]LISTADHERENT!A$5:H$60,3,0) -> MBOGNING TUGMA GUY | C22: =IF(G22=0,0,G22-D22) -> 10000 | D22: =IF(F22="ECHEC",0,IF(F22="",0,20000)) -> 20000 | E22: =IF(F22="ESPECES",3000,0) -> 0 | F22: BANQUE | G22: =IF(F22="BANQUE",30000,IF(F22="ESPECES",30000,0)) -> 30000 | L22: =TONTJANV!H22+TONTJANV!I22 -> 0 | P22: =IF(Q22=0,0,($E$75-Q22)) -> 278000 | Q22: 22000
A23: AS201639 | B23: =VLOOKUP(A23,[4]LISTADHERENT!A$5:H$60,3,0) -> NANGUEN MARTIN | C23: =IF(G23=0,0,G23-D23) -> 10000 | D23: =IF(F23="ECHEC",0,IF(F23="",0,20000)) -> 20000 | E23: =IF(F23="ESPECES",3000,0) -> 0 | F23: BANQUE | G23: =IF(F23="BANQUE",30000,IF(F23="ESPECES",30000,0)) -> 30000 | L23: =TONTJANV!H23+TONTJANV!I23 -> 0 | P23: =IF(Q23=0,0,($E$75-Q23)) -> 0
A24: AS201621 | B24: =VLOOKUP(A24,[4]LISTADHERENT!A$5:H$60,3,0) -> NANKAM APPOLINAIRE | C24: =IF(G24=0,0,G24-D24) -> 10000 | D24: =IF(F24="ECHEC",0,IF(F24="",0,20000)) -> 20000 | E24: =IF(F24="ESPECES",3000,0) -> 0 | F24: BANQUE | G24: =IF(F24="BANQUE",30000,IF(F24="ESPECES",30000,0)) -> 30000 | L24: =TONTJANV!H24+TONTJANV!I24 -> 0 | P24: =IF(Q24=0,0,($E$75-Q24)) -> 0
A25: AS201622 | B25: =VLOOKUP(A25,[4]LISTADHERENT!A$5:H$60,3,0) -> NDJOMO ETIENNE | C25: =IF(G25=0,0,G25-D25) -> 14000 | D25: =IF(F25="ECHEC",0,IF(F25="",0,20000)) -> 20000 | E25: =IF(F25="ESPECES",3000,0) -> 0 | F25: BANQUE | G25: =IF(F25="BANQUE",30000,IF(F25="ESPECES",30000,0))+4000 -> 34000 | L25: =TONTJANV!H25+TONTJANV!I25 -> 0 | P25: =IF(Q25=0,0,($E$75-Q25)) -> 0
A26: AS201624 | B26: =VLOOKUP(A26,[4]LISTADHERENT!A$5:H$60,3,0) -> NGONDIEP CLAUDE | C26: =IF(G26=0,0,G26-D26) -> 20000 | D26: =IF(F26="ECHEC",0,IF(F26="",0,20000)) -> 20000 | E26: =IF(F26="ESPECES",3000,0) -> 0 | F26: BANQUE | G26: =IF(F26="BANQUE",30000,IF(F26="ESPECES",30000,0))+10000 -> 40000 | L26: =TONTJANV!H26+TONTJANV!I26 -> 0 | P26: =IF(Q26=0,0,($E$75-Q26)) -> 0
A27: AS201626 | B27: =VLOOKUP(A27,[4]LISTADHERENT!A$5:H$60,3,0) -> NGUIEMEGNI MATHIEU BLAISE | C27: =IF(G27=0,0,G27-D27) -> 10000 | D27: =IF(F27="ECHEC",0,IF(F27="",0,20000)) -> 20000 | E27: =IF(F27="ESPECES",3000,0) -> 0 | F27: BANQUE | G27: =IF(F27="BANQUE",30000,IF(F27="ESPECES",30000,0)) -> 30000 | L27: =TONTJANV!H27+TONTJANV!I27 -> 0 | P27: =IF(Q27=0,0,($E$75-Q27)) -> 0
A28: AS201628 | B28: =VLOOKUP(A28,[4]LISTADHERENT!A$5:H$60,3,0) -> NKAMGANG JUSTIN DEJOLIE | C28: =IF(G28=0,0,G28-D28) -> 10000 | D28: =IF(F28="ECHEC",0,IF(F28="",0,20000)) -> 20000 | E28: =IF(F28="ESPECES",3000,0) -> 3000 | F28: ESPECES | G28: =IF(F28="BANQUE",30000,IF(F28="ESPECES",30000,0)) -> 30000 | H28: 30000 | I28: 1000 | L28: =TONTJANV!H28+TONTJANV!I28 -> 0 | P28: =IF(Q28=0,0,($E$75-Q28)) -> 0
A29: AS201614 | B29: =VLOOKUP(A29,[4]LISTADHERENT!A$5:H$60,3,0) -> NKEHE DAVID | C29: =IF(G29=0,0,G29-D29) -> 10000 | D29: =IF(F29="ECHEC",0,IF(F29="",0,20000)) -> 20000 | E29: =IF(F29="ESPECES",3000,0) -> 3000 | F29: ESPECES | G29: =IF(F29="BANQUE",30000,IF(F29="ESPECES",30000,0)) -> 30000 | L29: =TONTJANV!H29+TONTJANV!I29 -> 0 | P29: =IF(Q29=0,0,($E$75-Q29)) -> 0
A30: AS201629 | B30: =VLOOKUP(A30,[4]LISTADHERENT!A$5:H$60,3,0) -> NKEPSEU DIEUDONNE | C30: =IF(G30=0,0,G30-D30) -> 10000 | D30: =IF(F30="ECHEC",0,IF(F30="",0,20000)) -> 20000 | E30: =IF(F30="ESPECES",3000,0) -> 0 | F30: BANQUE | G30: =IF(F30="BANQUE",30000,IF(F30="ESPECES",30000,0)) -> 30000 | H30: 30000 | I30: 2000 | L30: =TONTJANV!H30+TONTJANV!I30 -> 0 | P30: =IF(Q30=0,0,($E$75-Q30)) -> 0
A31: AS201633 | B31: =VLOOKUP(A31,[4]LISTADHERENT!A$5:H$60,3,0) -> PATEGO NJOSSU GUSTAVE | C31: =IF(G31=0,0,G31-D31) -> 10000 | D31: =IF(F31="ECHEC",0,IF(F31="",0,20000)) -> 20000 | E31: =IF(F31="ESPECES",3000,0) -> 0 | F31: BANQUE | G31: =IF(F31="BANQUE",30000,IF(F31="ESPECES",30000,0)) -> 30000 | L31: =TONTJANV!H31+TONTJANV!I31 -> 0 | P31: =IF(Q31=0,0,($E$75-Q31)) -> 0
A32: AS201653 | B32: =VLOOKUP(A32,[4]LISTADHERENT!A$5:H$60,3,0) -> SIME BRICE | C32: =IF(G32=0,0,G32-D32) -> 50000 | D32: =IF(F32="ECHEC",0,IF(F32="",0,20000)) -> 20000 | E32: =IF(F32="ESPECES",3000,0) -> 0 | F32: BANQUE | G32: =IF(F32="BANQUE",30000,IF(F32="ESPECES",30000,0))+40000 -> 70000 | L32: =TONTJANV!H32+TONTJANV!I32 -> 0 | P32: =IF(Q32=0,0,($E$75-Q32)) -> 0
A33: AS201636 | B33: =VLOOKUP(A33,[4]LISTADHERENT!A$5:H$60,3,0) -> SIMO FONGANG ERIC | C33: =IF(G33=0,0,G33-D33) -> 10000 | D33: =IF(F33="ECHEC",0,IF(F33="",0,20000)) -> 20000 | E33: =IF(F33="ESPECES",3000,0) -> 3000 | F33: ESPECES | G33: =IF(F33="BANQUE",30000,IF(F33="ESPECES",30000,0)) -> 30000 | L33: =TONTJANV!H33+TONTJANV!I33 -> 0 | P33: =IF(Q33=0,0,($E$75-Q33)) -> 0
A34: AS201637 | B34: =VLOOKUP(A34,[4]LISTADHERENT!A$5:H$60,3,0) -> SIME MATHIEU | C34: =IF(G34=0,0,G34-D34) -> 10000 | D34: =IF(F34="ECHEC",0,IF(F34="",0,20000)) -> 20000 | E34: =IF(F34="ESPECES",3000,0) -> 0 | F34: BANQUE | G34: =IF(F34="BANQUE",30000,IF(F34="ESPECES",30000,0)) -> 30000 | L34: =TONTJANV!H34+TONTJANV!I34 -> 0 | P34: =IF(Q34=0,0,($E$75-Q34)) -> 0
A35: AS201638 | B35: =VLOOKUP(A35,[4]LISTADHERENT!A$5:H$60,3,0) -> SIMO PIERRE | C35: =IF(G35=0,0,G35-D35) -> 15000 | D35: =IF(F35="ECHEC",0,IF(F35="",0,20000)) -> 20000 | E35: =IF(F35="ESPECES",3000,0) -> 0 | F35: BANQUE | G35: =IF(F35="BANQUE",30000,IF(F35="ESPECES",30000,0))+5000 -> 35000 | L35: =TONTJANV!H35+TONTJANV!I35 -> 0 | P35: =IF(Q35=0,0,($E$75-Q35)) -> 0
A36: AS201641 | B36: =VLOOKUP(A36,[4]LISTADHERENT!A$5:H$60,3,0) -> TCHOUAMOU MATHIEU | C36: =IF(G36=0,0,G36-D36) -> 10000 | D36: =IF(F36="ECHEC",0,IF(F36="",0,20000)) -> 20000 | E36: =IF(F36="ESPECES",3000,0) -> 0 | F36: BANQUE | G36: =IF(F36="BANQUE",30000,IF(F36="ESPECES",30000,0)) -> 30000 | L36: =TONTJANV!H36+TONTJANV!I36 -> 0 | P36: =IF(Q36=0,0,($E$75-Q36)) -> 0
A37: AS201644 | B37: =VLOOKUP(A37,[4]LISTADHERENT!A$5:H$60,3,0) -> TIEYAM ERNEST | C37: =IF(G37=0,0,G37-D37) -> 0 | D37: =IF(F37="ECHEC",0,IF(F37="",0,20000)) -> 0 | E37: =IF(F37="ESPECES",3000,0) -> 0 | F37: ECHEC | G37: =IF(F37="BANQUE",30000,IF(F37="ESPECES",30000,0)) -> 0 | H37: 36000 | I37: 6000 | L37: =TONTJANV!H37+TONTJANV!I37 -> 36000 | M37: ECHEC | P37: =IF(Q37=0,0,($E$75-Q37)) -> 0
A38: AS201646 | B38: =VLOOKUP(A38,[4]LISTADHERENT!A$5:H$60,3,0) -> YEPMOU JEAN JACQUES | C38: =IF(G38=0,0,G38-D38) -> 10000 | D38: =IF(F38="ECHEC",0,IF(F38="",0,20000)) -> 20000 | E38: =IF(F38="ESPECES",3000,0) -> 0 | F38: BANQUE | G38: =IF(F38="BANQUE",30000,IF(F38="ESPECES",30000,0)) -> 30000 | L38: =TONTJANV!H38+TONTJANV!I38 -> 0 | P38: =IF(Q38=0,0,($E$75-Q38)) -> 0
A39: AS201647 | B39: =VLOOKUP(A39,[4]LISTADHERENT!A$5:H$60,3,0) -> YOUMBI EMMANUEL | C39: =IF(G39=0,0,G39-D39) -> 10000 | D39: =IF(F39="ECHEC",0,IF(F39="",0,20000)) -> 20000 | E39: =IF(F39="ESPECES",3000,0) -> 0 | F39: BANQUE | G39: =IF(F39="BANQUE",30000,IF(F39="ESPECES",30000,0)) -> 30000 | L39: =TONTJANV!H39+TONTJANV!I39 -> 0 | P39: =IF(Q39=0,0,($E$75-Q39)) -> 0
A40: AS201655 | B40: =VLOOKUP(A40,[4]LISTADHERENT!A$5:H$60,3,0) -> TCHEMHOU EMMANUEL
...

Sheet TONTMARS
A1: ASSOCIATION | B1: ASELBY
A2: ANNEE | B2: 2019/2020
A3: TONTINE | B3: 30000
C4: 43912
A5: MATRICULE | B5: NOM ET PRENOM | C5: RESTE | D5: MONTANT TONTINE | E5: PENALITE VERSEMENT ESPECES | F5: MODE VERSEMENT | G5: MONTANT VERSE | H5: VENTE PETIT LOT | I5: INTERET PETIT LOT | J5: MODE VERSEMENT VENTE PETIT LOT | K5: NUMERO CHEQUE | L5: REMBOURSEMENT PETIT LOT | M5: MODE VERSEMENT REMBOURSEMENT | N5: MODE VERSEMENTLOT PRINCIPAL | O5: NUMERO CHEQUE | P5: MONTANT TONTINE LOT PRINCIPAL | Q5: INTERET LOT PRINCIPAL | R5: DEPOT
A6: AS201648 | B6: =VLOOKUP(A6,[4]LISTADHERENT!A$5:H$60,3,0) -> ASELBY | C6: =IF(G6=0,0,G6-D6) -> 0 | D6: =IF(F6="ECHEC",0,IF(F6="",0,20000)) -> 0 | E6: =IF(F6="ESPECES",3000,0) -> 0 | F6: ECHEC | G6: =IF(F6="BANQUE",30000,IF(F6="ESPECES",30000,0)) -> 0 | L6: =TONTFEV!H6+TONTFEV!I6 -> 0 | P6: =IF(Q6=0,0,($E$76-Q6)) -> 0
A7: AS201602 | B7: =VLOOKUP(A7,[4]LISTADHERENT!A$5:H$60,3,0) -> BOUTCHOUANG WILLIAM | C7: =IF(G7=0,0,G7-D7) -> 10000 | D7: =IF(F7="ECHEC",0,IF(F7="",0,20000)) -> 20000 | E7: =IF(F7="ESPECES",3000,0) -> 0 | F7: BANQUE | G7: =IF(F7="BANQUE",30000,IF(F7="ESPECES",30000,0)) -> 30000 | L7: =TONTFEV!H7+TONTFEV!I7 -> 0 | P7: =IF(Q7=0,0,($E$75-Q7)) -> 0
A8: AS201604 | B8: =VLOOKUP(A8,[4]LISTADHERENT!A$5:H$60,3,0) -> DJOMO JEAN PAUL | C8: =IF(G8=0,0,G8-D8) -> 10000 | D8: =IF(F8="ECHEC",0,IF(F8="",0,20000)) -> 20000 | E8: =IF(F8="ESPECES",3000,0) -> 0 | F8: BANQUE | G8: =IF(F8="BANQUE",30000,IF(F8="ESPECES",30000,0)) -> 30000 | L8: =TONTFEV!H8+TONTFEV!I8 -> 57500 | M8: BANQUE | P8: =IF(Q8=0,0,($E$75-Q8)) -> 0
A9: AS201654 | B9: =VLOOKUP(A9,[4]LISTADHERENT!A$5:H$60,3,0) -> DJOMOU TCHANDA | C9: =IF(G9=0,0,G9-D9) -> 40000 | D9: =IF(F9="ECHEC",0,IF(F9="",0,20000)) -> 20000 | E9: =IF(F9="ESPECES",3000,0) -> 0 | F9: BANQUE | G9: =IF(F9="BANQUE",30000,IF(F9="ESPECES",30000,0))+30000 -> 60000 | L9: =TONTFEV!H9+TONTFEV!I9 -> 0 | P9: =IF(Q9=0,0,($E$75-Q9)) -> 0
A10: AS201605 | B10: =VLOOKUP(A10,[4]LISTADHERENT!A$5:H$60,3,0) -> DJOUKWE NANGUEN GUY BLAISE | C10: =IF(G10=0,0,G10-D10) -> 10000 | D10: =IF(F10="ECHEC",0,IF(F10="",0,20000)) -> 20000 | E10: =IF(F10="ESPECES",3000,0) -> 0 | F10: BANQUE | G10: =IF(F10="BANQUE",30000,IF(F10="ESPECES",30000,0)) -> 30000 | L10: =TONTFEV!H10+TONTFEV!I10 -> 0 | P10: =IF(Q10=0,0,($E$75-Q10)) -> 0
A11: AS201608 | B11: =VLOOKUP(A11,[4]LISTADHERENT!A$5:H$60,3,0) -> DJUOMBESSY ANTOINE | C11: =IF(G11=0,0,G11-D11) -> 10000 | D11: =IF(F11="ECHEC",0,IF(F11="",0,20000)) -> 20000 | E11: =IF(F11="ESPECES",3000,0) -> 0 | F11: BANQUE | G11: =IF(F11="BANQUE",30000,IF(F11="ESPECES",30000,0)) -> 30000 | L11: =TONTFEV!H11+TONTFEV!I11 -> 0 | P11: =IF(Q11=0,0,($E$75-Q11)) -> 0
A12: AS201651 | B12: =VLOOKUP(A12,[4]LISTADHERENT!A$5:H$60,3,0) -> DOMOU FABIEN | C12: =IF(G12=0,0,G12-D12) -> 10000 | D12: =IF(F12="ECHEC",0,IF(F12="",0,20000)) -> 20000 | E12: =IF(F12="ESPECES",3000,0) -> 0 | F12: BANQUE | G12: =IF(F12="BANQUE",30000,IF(F12="ESPECES",30000,0)) -> 30000 | L12: =TONTFEV!H12+TONTFEV!I12 -> 0 | P12: =IF(Q12=0,0,($E$75-Q12)) -> 0
A13: AS201609 | B13: =VLOOKUP(A13,[4]LISTADHERENT!A$5:H$60,3,0) -> DONHOU DAVID | C13: =IF(G13=0,0,G13-D13) -> 10000 | D13: =IF(F13="ECHEC",0,IF(F13="",0,20000)) -> 20000 | E13: =IF(F13="ESPECES",3000,0) -> 3000 | F13: ESPECES | G13: =IF(F13="BANQUE",30000,IF(F13="ESPECES",30000,0)) -> 30000 | L13: =TONTFEV!H13+TONTFEV!I13 -> 0 | P13: =IF(Q13=0,0,($E$75-Q13)) -> 0
A14: AS201610 | B14: =VLOOKUP(A14,[4]LISTADHERENT!A$5:H$60,3,0) -> FOTSO THOMAS | C14: =IF(G14=0,0,G14-D14) -> 10000 | D14: =IF(F14="ECHEC",0,IF(F14="",0,20000)) -> 20000 | E14: =IF(F14="ESPECES",3000,0) -> 0 | F14: BANQUE | G14: =IF(F14="BANQUE",30000,IF(F14="ESPECES",30000,0)) -> 30000 | H14: 54500 | I14: 0 | L14: =TONTFEV!H14+TONTFEV!I14 -> 54500 | M14: ECHEC | P14: =IF(Q14=0,0,($E$75-Q14)) -> 0
A15: AS201611 | B15: =VLOOKUP(A15,[4]LISTADHERENT!A$5:H$60,3,0) -> HENGUE PAUL OMER | C15: =IF(G15=0,0,G15-D15) -> 10000 | D15: =IF(F15="ECHEC",0,IF(F15="",0,20000)) -> 20000 | E15: =IF(F15="ESPECES",3000,0) -> 0 | F15: BANQUE | G15: =IF(F15="BANQUE",30000,IF(F15="ESPECES",30000,0)) -> 30000 | L15: =TONTFEV!H15+TONTFEV!I15 -> 0 | P15: =IF(Q15=0,0,($E$75-Q15)) -> 0
A16: AS201613 | B16: =VLOOKUP(A16,[4]LISTADHERENT!A$5:H$60,3,0) -> HOTCHO BENJAMIN | C16: =IF(G16=0,0,G16-D16) -> 10000 | D16: =IF(F16="ECHEC",0,IF(F16="",0,20000)) -> 20000 | E16: =IF(F16="ESPECES",3000,0) -> 0 | F16: BANQUE | G16: =IF(F16="BANQUE",30000,IF(F16="ESPECES",30000,0)) -> 30000 | L16: =TONTFEV!H16+TONTFEV!I16 -> 0 | P16: =IF(Q16=0,0,($E$75-Q16)) -> 0
A17: AS201615 | B17: =VLOOKUP(A17,[4]LISTADHERENT!A$5:H$60,3,0) -> KEPSEU FRANCIS | C17: =IF(G17=0,0,G17-D17) -> 10000 | D17: =IF(F17="ECHEC",0,IF(F17="",0,20000)) -> 20000 | E17: =IF(F17="ESPECES",3000,0) -> 0 | F17: BANQUE | G17: =IF(F17="BANQUE",30000,IF(F17="ESPECES",30000,0)) -> 30000 | L17: =TONTFEV!H17+TONTFEV!I17 -> 0 | P17: =IF(Q17=0,0,($E$75-Q17)) -> 0
A18: AS201618 | B18: =VLOOKUP(A18,[4]LISTADHERENT!A$5:H$60,3,0) -> KOUAMO VICTOR PEGUY | C18: =IF(G18=0,0,G18-D18) -> 0 | D18: =IF(F18="ECHEC",0,IF(F18="",0,20000)) -> 0 | E18: =IF(F18="ESPECES",3000,0) -> 0 | F18: ECHEC | G18: =IF(F18="BANQUE",30000,IF(F18="ESPECES",30000,0)) -> 0 | L18: =TONTFEV!H18+TONTFEV!I18 -> 0 | P18: =IF(Q18=0,0,($E$75-Q18)) -> 0
A19: AS201617 | B19: =VLOOKUP(A19,[4]LISTADHERENT!A$5:H$60,3,0) -> KOUAMOU MOISE | C19: =IF(G19=0,0,G19-D19) -> 10000 | D19: =IF(F19="ECHEC",0,IF(F19="",0,20000)) -> 20000 | E19: =IF(F19="ESPECES",3000,0) -> 0 | F19: BANQUE | G19: =IF(F19="BANQUE",30000,IF(F19="ESPECES",30000,0)) -> 30000 | H19: 1000 | I19: 0 | L19: =TONTFEV!H19+TONTFEV!I19 -> 1000 | M19: E CHEC | P19: =IF(Q19=0,0,($E$75-Q19)) -> 0
A20: AS201619 | B20: =VLOOKUP(A20,[4]LISTADHERENT!A$5:H$60,3,0) -> KOUATCHO MESSACK | C20: =IF(G20=0,0,G20-D20) -> 10000 | D20: =IF(F20="ECHEC",0,IF(F20="",0,20000)) -> 20000 | E20: =IF(F20="ESPECES",3000,0) -> 0 | F20: BANQUE | G20: =IF(F20="BANQUE",30000,IF(F20="ESPECES",30000,0)) -> 30000 | L20: =TONTFEV!H20+TONTFEV!I20 -> 0 | P20: =IF(Q20=0,0,($E$75-Q20)) -> 0
A21: AS201620 | B21: =VLOOKUP(A21,[4]LISTADHERENT!A$5:H$60,3,0) -> LOWE JEAN | C21: =IF(G21=0,0,G21-D21) -> 10000 | D21: =IF(F21="ECHEC",0,IF(F21="",0,20000)) -> 20000 | E21: =IF(F21="ESPECES",3000,0) -> 3000 | F21: ESPECES | G21: =IF(F21="BANQUE",30000,IF(F21="ESPECES",30000,0)) -> 30000 | L21: =TONTFEV!H21+TONTFEV!I21 -> 0 | P21: =IF(Q21=0,0,($E$75-Q21)) -> 269000 | Q21: 31000
A22: AS201649 | B22: =VLOOKUP(A22,[4]LISTADHERENT!A$5:H$60,3,0) -> MBOGNING TUGMA GUY | C22: =IF(G22=0,0,G22-D22) -> 10000 | D22: =IF(F22="ECHEC",0,IF(F22="",0,20000)) -> 20000 | E22: =IF(F22="ESPECES",3000,0) -> 0 | F22: BANQUE | G22: =IF(F22="BANQUE",30000,IF(F22="ESPECES",30000,0)) -> 30000 | L22: =TONTFEV!H22+TONTFEV!I22 -> 0 | P22: =IF(Q22=0,0,($E$75-Q22)) -> 0
A23: AS201639 | B23: =VLOOKUP(A23,[4]LISTADHERENT!A$5:H$60,3,0) -> NANGUEN MARTIN | C23: =IF(G23=0,0,G23-D23) -> 10000 | D23: =IF(F23="ECHEC",0,IF(F23="",0,20000)) -> 20000 | E23: =IF(F23="ESPECES",3000,0) -> 3000 | F23: ESPECES | G23: =IF(F23="BANQUE",30000,IF(F23="ESPECES",30000,0)) -> 30000 | L23: =TONTFEV!H23+TONTFEV!I23 -> 0 | P23: =IF(Q23=0,0,($E$75-Q23)) -> 0
