Workbook

Sheet BROUILLARD DE CAISSE 2023
B1: BROUILLARD DE CAISSE 15 JANVIER 2023
C3: EPARGNE | D3: F R | E3: F EX | F3: COLL | G3: T PRESENCE | I3: T 75 | K3: T 100 | M3: REMB PRÊT | N3: DEPOT | O3: PENALITE | P3: INTERET PRÊT | Q3: FOYER | R3: MUTUELLE | S3: TOTAL VERSE
G4: COTISE | H4: REMB | I4: COTISE | J4: REMB | K4: COTISE | L4: REMB | S4: CUMUL | T4: ESPECE | U4: BANQUE
A5: 0 | B5: ASELBY | K5: 100000 | S5: =+R5+Q5+P5+O5+N5+M5+L5+K5+J5+I5+H5+G5+F5+E5+D5+C5 -> 100000 | U5: =+S5-T5 -> 100000
A6: =+A5+1 -> 1 | B6: BOUTCHOUANG WILLIAM | C6: 9000 | D6: 1000 | E6: 1000 | F6: 4000 | G6: 25000 | I6: 75000 | S6: =+R6+Q6+P6+O6+N6+M6+L6+K6+J6+I6+H6+G6+F6+E6+D6+C6 -> 115000 | T6: 10000 | U6: =+S6-T6 -> 105000
A7: =+A6+1 -> 2 | B7: DJOMO JEAN PAUL | C7: 29000 | D7: 1000 | E7: 1000 | F7: 4000 | G7: 25000 | K7: 100000 | Q7: 140000 | S7: =+R7+Q7+P7+O7+N7+M7+L7+K7+J7+I7+H7+G7+F7+E7+D7+C7 -> 300000 | U7: =+S7-T7 -> 300000
A8: =+A7+1 -> 3 | B8: DJOMOU TCHANDA | C8: 9000 | D8: 1000 | E8: 1000 | F8: 4000 | G8: 25000 | S8: =+R8+Q8+P8+O8+N8+M8+L8+K8+J8+I8+H8+G8+F8+E8+D8+C8 -> 40000 | U8: =+S8-T8 -> 40000
A9: =+A8+1 -> 4 | B9: DJOUKWE NANGUEN GUY BLAISE | C9: 9000 | D9: 1000 | E9: 1000 | F9: 4000 | G9: 25000 | I9: 75000 | S9: =+R9+Q9+P9+O9+N9+M9+L9+K9+J9+I9+H9+G9+F9+E9+D9+C9 -> 115000 | U9: =+S9-T9 -> 115000
A10: =+A9+1 -> 5 | B10: DJUOMBESSY ANTOINE | C10: 14000 | D10: 1000 | E10: 1000 | F10: 4000 | G10: 25000 | I10: 75000 | K10: 200000 | S10: =+R10+Q10+P10+O10+N10+M10+L10+K10+J10+I10+H10+G10+F10+E10+D10+C10 -> 320000 | U10: =+S10-T10 -> 320000
A11: =+A10+1 -> 6 | B11: DOMOU FABIEN | C11: 9000 | D11: 1000 | E11: 1000 | F11: 4000 | G11: 25000 | S11: =+R11+Q11+P11+O11+N11+M11+L11+K11+J11+I11+H11+G11+F11+E11+D11+C11 -> 40000 | U11: =+S11-T11 -> 40000
A12: =+A11+1 -> 7 | B12: DONHOU DAVID | C12: 9000 | D12: 1000 | E12: 1000 | F12: 4000 | G12: 25000 | S12: =+R12+Q12+P12+O12+N12+M12+L12+K12+J12+I12+H12+G12+F12+E12+D12+C12 -> 40000 | U12: =+S12-T12 -> 40000
A13: =+A12+1 -> 8 | B13: FOTSO THOMAS | S13: =+R13+Q13+P13+O13+N13+M13+L13+K13+J13+I13+H13+G13+F13+E13+D13+C13 -> 0 | U13: =+S13-T13 -> 0
A14: =+A13+1 -> 9 | B14: HENGUE PAUL OMER | C14: 9000 | D14: 1000 | E14: 1000 | F14: 4000 | G14: 25000 | I14: 75000 | S14: =+R14+Q14+P14+O14+N14+M14+L14+K14+J14+I14+H14+G14+F14+E14+D14+C14 -> 115000 | U14: =+S14-T14 -> 115000
A15: =+A14+1 -> 10 | B15: HOTCHO BENJAMIN | C15: 44000 | D15: 1000 | E15: 1000 | F15: 4000 | G15: 25000 | I15: 75000 | K15: 100000 | S15: =+R15+Q15+P15+O15+N15+M15+L15+K15+J15+I15+H15+G15+F15+E15+D15+C15 -> 250000 | U15: =+S15-T15 -> 250000
A16: =+A15+1 -> 11 | B16: KOUAMOU MOISE | C16: 9000 | D16: 1000 | E16: 1000 | F16: 4000 | G16: 25000 | K16: 100000 | S16: =+R16+Q16+P16+O16+N16+M16+L16+K16+J16+I16+H16+G16+F16+E16+D16+C16 -> 140000 | U16: =+S16-T16 -> 140000
A17: =+A16+1 -> 12 | B17: KOUATCHO MESSACK | C17: 9000 | D17: 1000 | E17: 1000 | F17: 4000 | G17: 25000 | I17: 75000 | K17: 100000 | Q17: 70000 | S17: =+R17+Q17+P17+O17+N17+M17+L17+K17+J17+I17+H17+G17+F17+E17+D17+C17 -> 285000 | T17: 35000 | U17: =+S17-T17 -> 250000
A18: =+A17+1 -> 13 | B18: LOWE JEAN | C18: 9000 | D18: 1000 | E18: 1000 | F18: 4000 | G18: 25000 | S18: =+R18+Q18+P18+O18+N18+M18+L18+K18+J18+I18+H18+G18+F18+E18+D18+C18 -> 40000 | U18: =+S18-T18 -> 40000
A19: =+A18+1 -> 14 | B19: MBOGNING TUGMA GUY | C19: 9000 | D19: 1000 | E19: 1000 | F19: 4000 | G19: 25000 | I19: 75000 | K19: 100000 | S19: =+R19+Q19+P19+O19+N19+M19+L19+K19+J19+I19+H19+G19+F19+E19+D19+C19 -> 215000 | U19: =+S19-T19 -> 215000
A20: =+A19+1 -> 15 | B20: NANGUEN MARTIN | C20: 9000 | D20: 1000 | E20: 1000 | F20: 4000 | G20: 25000 | S20: =+R20+Q20+P20+O20+N20+M20+L20+K20+J20+I20+H20+G20+F20+E20+D20+C20 -> 40000 | U20: =+S20-T20 -> 40000
A21: =+A20+1 -> 16 | B21: NANKAM APPOLINAIRE | C21: 9000 | D21: 1000 | E21: 1000 | F21: 4000 | G21: 25000 | I21: 75000 | S21: =+R21+Q21+P21+O21+N21+M21+L21+K21+J21+I21+H21+G21+F21+E21+D21+C21 -> 115000 | U21: =+S21-T21 -> 115000
A22: =+A21+1 -> 17 | B22: NDJOMO ETIENNE | C22: 19000 | D22: 1000 | E22: 1000 | F22: 4000 | G22: 25000 | K22: 200000 | S22: =+R22+Q22+P22+O22+N22+M22+L22+K22+J22+I22+H22+G22+F22+E22+D22+C22 -> 250000 | U22: =+S22-T22 -> 250000
A23: =+A22+1 -> 18 | B23: NGONDIEP CLAUDE | C23: 9000 | D23: 1000 | E23: 1000 | F23: 4000 | G23: 25000 | I23: 75000 | K23: 100000 | S23: =+R23+Q23+P23+O23+N23+M23+L23+K23+J23+I23+H23+G23+F23+E23+D23+C23 -> 215000 | T23: 5000 | U23: =+S23-T23 -> 210000
A24: =+A23+1 -> 19 | B24: NGUIEMEGNI MATHIEU BLAISE | C24: 9000 | D24: 1000 | E24: 1000 | F24: 4000 | G24: 25000 | I24: 150000 | K24: 100000 | S24: =+R24+Q24+P24+O24+N24+M24+L24+K24+J24+I24+H24+G24+F24+E24+D24+C24 -> 290000 | T24: 10000 | U24: =+S24-T24 -> 280000
A25: =+A24+1 -> 20 | B25: NKAMGANG JUSTIN DEJOLIE | C25: 9000 | D25: 1000 | E25: 1000 | F25: 4000 | G25: 25000 | S25: =+R25+Q25+P25+O25+N25+M25+L25+K25+J25+I25+H25+G25+F25+E25+D25+C25 -> 40000 | T25: 40000 | U25: =+S25-T25 -> 0
A26: =+A25+1 -> 21 | B26: NKEHE DAVID | S26: =+R26+Q26+P26+O26+N26+M26+L26+K26+J26+I26+H26+G26+F26+E26+D26+C26 -> 0 | U26: =+S26-T26 -> 0
A27: =+A26+1 -> 22 | B27: NOUBE ETIENNE | C27: 9000 | D27: 1000 | E27: 1000 | F27: 4000 | G27: 25000 | N27: 25000 | S27: =+R27+Q27+P27+O27+N27+M27+L27+K27+J27+I27+H27+G27+F27+E27+D27+C27 -> 65000 | T27: 65000 | U27: =+S27-T27 -> 0
A28: =+A27+1 -> 23 | B28: PATEGO NJOSSU GUSTAVE | C28: 9000 | D28: 1000 | E28: 1000 | F28: 4000 | G28: 25000 | I28: 75000 | S28: =+R28+Q28+P28+O28+N28+M28+L28+K28+J28+I28+H28+G28+F28+E28+D28+C28 -> 115000 | U28: =+S28-T28 -> 115000
A29: =+A28+1 -> 24 | B29: SEUMOU POLYCARPE | C29: 9000 | D29: 1000 | E29: 1000 | F29: 4000 | G29: 25000 | N29: 25000 | S29: =+R29+Q29+P29+O29+N29+M29+L29+K29+J29+I29+H29+G29+F29+E29+D29+C29 -> 65000 | T29: 65000 | U29: =+S29-T29 -> 0
A30: =+A29+1 -> 25 | B30: SIME BRICE | C30: 9000 | D30: 1000 | E30: 1000 | F30: 4000 | G30: 25000 | I30: 75000 | S30: =+R30+Q30+P30+O30+N30+M30+L30+K30+J30+I30+H30+G30+F30+E30+D30+C30 -> 115000 | T30: 115000 | U30: =+S30-T30 -> 0
A31: =+A30+1 -> 26 | B31: SIMO FONGANG ERIC | S31: =+R31+Q31+P31+O31+N31+M31+L31+K31+J31+I31+H31+G31+F31+E31+D31+C31 -> 0 | U31: =+S31-T31 -> 0
A32: =+A31+1 -> 27 | B32: SIMO PIERRE | C32: 119000 | D32: 1000 | E32: 1000 | F32: 4000 | G32: 25000 | K32: 100000 | S32: =+R32+Q32+P32+O32+N32+M32+L32+K32+J32+I32+H32+G32+F32+E32+D32+C32 -> 250000 | U32: =+S32-T32 -> 250000
A33: =+A32+1 -> 28 | B33: TCHOUAMOU MATHIEU | C33: 9000 | D33: 1000 | E33: 1000 | F33: 4000 | G33: 25000 | I33: 75000 | S33: =+R33+Q33+P33+O33+N33+M33+L33+K33+J33+I33+H33+G33+F33+E33+D33+C33 -> 115000 | U33: =+S33-T33 -> 115000
A34: =+A33+1 -> 29 | B34: TCHOUTOU NANA CLAUDE | C34: 9000 | D34: 1000 | E34: 1000 | F34: 4000 | G34: 25000 | S34: =+R34+Q34+P34+O34+N34+M34+L34+K34+J34+I34+H34+G34+F34+E34+D34+C34 -> 40000 | T34: 40000 | U34: =+S34-T34 -> 0
A35: =+A34+1 -> 30 | B35: TIEYAM ERNEST | S35: =+R35+Q35+P35+O35+N35+M35+L35+K35+J35+I35+H35+G35+F35+E35+D35+C35 -> 0 | U35: =+S35-T35 -> 0
A36: =+A35+1 -> 31 | B36: YEPMOU JEAN JACQUES | C36: 9000 | D36: 1000 | E36: 1000 | F36: 4000 | G36: 25000 | S36: =+R36+Q36+P36+O36+N36+M36+L36+K36+J36+I36+H36+G36+F36+E36+D36+C36 -> 40000 | T36: 40000 | U36: =+S36-T36 -> 0
A37: =+A36+1 -> 32 | B37: YOUMBI EMMANUEL | C37: 9000 | D37: 1000 | E37: 1000 | F37: 4000 | G37: 25000 | I37: 150000 | K37: 100000 | S37: =+R37+Q37+P37+O37+N37+M37+L37+K37+J37+I37+H37+G37+F37+E37+D37+C37 -> 290000 | U37: =+S37-T37 -> 290000
A38: =+A37+1 -> 33 | B38: BAKOP ACHILLE | C38: 73000 | D38: 1000 | E38: 1000 | F38: 4000 | G38: 25000 | S38: =+R38+Q38+P38+O38+N38+M38+L38+K38+J38+I38+H38+G38+F38+E38+D38+C38 -> 104000 | T38: 104000 | U38: =+S38-T38 -> 0
A39: =+A38+1 -> 34 | B39: YANTCHOU GERVAIS | C39: 9000 | D39: 1000 | E39: 1000 | F39: 4000 | G39: 25000 | N39: 25000 | R39: 35000 | S39: =+R39+Q39+P39+O39+N39+M39+L39+K39+J39+I39+H39+G39+F39+E39+D39+C39 -> 100000 | T39: 100000 | U39: =+S39-T39 -> 0
A40: =+A39+1 -> 35 | S40: =+R40+Q40+P40+O40+N40+M40+L40+K40+J40+I40+H40+G40+F40+E40+D40+C40 -> 0 | U40: =+S40-T40 -> 0
A41: =+A40+1 -> 36 | S41: =+R41+Q41+P41+O41+N41+M41+L41+K41+J41+I41+H41+G41+F41+E41+D41+C41 -> 0 | U41: =+S41-T41 -> 0
...

Sheet TONTINE PRESENCE EXO 2023 
B1: ANNEE 2023
F2: TOTINE AVEC RETENUE
B3: Date | C3: 44941 | E3: 12 fevrier 2023 | G3: 45004 | I3: 45032 | K3: 45067 | M3: 45095 | O3: 45123 | Q3: 27 aout 2023 | S3: 45186 | U3: 45214 | W3: 45249 | Y3: 17 decembre 2023
B4: Nom et Prénom | C4: Cotisation | D4: Mtant achat | E4: Cotisation | F4: Mtant achat | G4: Cotisation | H4: Mtant achat | I4: Cotisation | J4: Mtant achat | K4: Cotisation | L4: Mtant achat | M4: Cotisation | N4: Mtant achat | O4: Cotisation | P4: Mtant achat | Q4: Cotisation | R4: Mtant achat | S4: Cotisation | T4: Mtant achat | U4: cotisation | V4: mtant achat | W4: cotisation | X4: mtant achat | Y4: cotisation | Z4: mtant achat
A5: 1 | B5: BOUTCHOUANG WILLIAM | C5: 25000 | E5: 25000 | G5: 25000 | I5: 25000 | K5: 25000 | M5: 25000 | O5: 25000 | Q5: 25000 | S5: 25000 | U5: 25000 | V5: 2500 | W5: 25000
A6: =1+A5 -> 2 | B6: DJOMO JEAN PAUL | C6: 25000 | D6: 22500 | E6: 25000 | G6: 25000 | I6: 25000 | K6: 25000 | M6: 25000 | O6: 25000 | Q6: 25000 | S6: 25000 | U6: 25000 | W6: 25000
A7: =1+A6 -> 3 | B7: DJOMO TCHAPDA | C7: 25000 | E7: 25000 | G7: 25000 | I7: 25000 | J7: 11000 | K7: 25000 | M7: 25000 | O7: 25000 | Q7: 25000 | S7: 25000 | U7: 25000 | W7: 25000
A8: =1+A7 -> 4 | B8: DJOUKWEU GUY B | C8: 25000 | E8: 25000 | G8: 25000 | I8: 25000 | J8: 10000 | K8: 25000 | M8: 25000 | O8: 25000 | Q8: 25000 | S8: 25000 | U8: 25000 | W8: 25000
A9: =1+A8 -> 5 | B9: DJUOMBISSY ANTOINE | C9: 25000 | E9: 25000 | G9: 25000 | I9: 25000 | K9: 25000 | M9: 25000 | N9: 5000 | O9: 25000 | Q9: 25000 | S9: 25000 | U9: 25000 | W9: 25000
A10: =1+A9 -> 6 | B10: DOMOU FABIEN | C10: 25000 | E10: 25000 | G10: 25000 | H10: 10000 | I10: 25000 | K10: 25000 | M10: 25000 | O10: 25000 | Q10: 25000 | S10: 25000 | U10: 25000 | W10: 25000
A11: =1+A10 -> 7 | B11: DONHOU DAVID | C11: 25000 | E11: 25000 | G11: 25000 | I11: 25000 | K11: 25000 | M11: 25000 | O11: 25000 | Q11: 25000 | S11: 25000 | U11: 25000 | W11: 25000 | X11: 2500
A12: =1+A11 -> 8 | B12: HENGUE PAUL OMER | C12: 25000 | E12: 25000 | G12: 25000 | I12: 25000 | K12: 25000 | M12: 25000 | O12: 25000 | P12: 2500 | Q12: 25000 | S12: 25000 | U12: 25000 | W12: 25000
A13: =1+A12 -> 9 | B13: HOTCHO BENJAMIN | C13: 25000 | E13: 25000 | G13: 25000 | I13: 25000 | K13: 25000 | L13: 2500 | M13: 25000 | O13: 25000 | Q13: 25000 | S13: 25000 | U13: 25000 | W13: 25000
A14: =1+A13 -> 10 | B14: KOUAMOU MOISE | C14: 25000 | E14: 25000 | F14: 6500 | G14: 25000 | I14: 25000 | K14: 25000 | M14: 25000 | O14: 25000 | Q14: 25000 | S14: 25000 | U14: 25000 | W14: 25000
A15: =1+A14 -> 11 | B15: KOUATCHO | C15: 25000 | D15: 17500 | E15: 25000 | G15: 25000 | I15: 25000 | K15: 25000 | M15: 25000 | O15: 25000 | Q15: 25000 | S15: 25000 | U15: 25000 | W15: 25000
A16: =1+A15 -> 12 | B16: LOWE JEAN | C16: 25000 | E16: 25000 | G16: 25000 | I16: 25000 | K16: 25000 | L16: 3000 | M16: 25000 | O16: 25000 | Q16: 25000 | S16: 25000 | U16: 25000 | W16: 25000
A17: =1+A16 -> 13 | B17: MBOGNING TUGMA GUY | C17: 25000 | E17: 25000 | G17: 25000 | H17: 11000 | I17: 25000 | K17: 25000 | M17: 25000 | O17: 25000 | Q17: 25000 | S17: 25000 | U17: 25000 | W17: 25000
A18: =1+A17 -> 14 | B18: NANGUEN MARTIN | C18: 25000 | E18: 25000 | G18: 25000 | I18: 25000 | K18: 25000 | M18: 25000 | O18: 25000 | Q18: 25000 | R18: 2500 | S18: 25000 | U18: 25000 | W18: 25000
A19: =1+A18 -> 15 | B19: NANKAM APPOLINAIRE | C19: 25000 | E19: 25000 | G19: 25000 | I19: 25000 | K19: 25000 | M19: 25000 | N19: 4500 | O19: 25000 | Q19: 25000 | S19: 25000 | U19: 25000 | W19: 25000
A20: =1+A19 -> 16 | B20: NDJOMO ETIENNE | C20: 25000 | E20: 25000 | G20: 25000 | I20: 25000 | K20: 25000 | M20: 25000 | O20: 25000 | Q20: 25000 | S20: 25000 | T20: 2500 | U20: 25000 | W20: 25000
A21: =1+A20 -> 17 | B21: NGONDIEP CLAUDE | C21: 25000 | E21: 25000 | G21: 25000 | I21: 25000 | K21: 25000 | L21: 3000 | M21: 25000 | O21: 25000 | Q21: 25000 | S21: 25000 | U21: 25000 | W21: 25000
A22: =1+A21 -> 18 | B22: NGUIEMENI MATHIEU B | C22: 25000 | E22: 25000 | F22: 7500 | G22: 25000 | I22: 25000 | K22: 25000 | M22: 25000 | O22: 25000 | Q22: 25000 | S22: 25000 | U22: 25000 | W22: 25000
A23: =1+A22 -> 19 | B23: NKAMGANG JUSTIN DEJOLIE | C23: 25000 | E23: 25000 | F23: 3500 | G23: 25000 | I23: 25000 | K23: 25000 | M23: 25000 | O23: 25000 | Q23: 25000 | S23: 25000 | U23: 25000 | W23: 25000
A24: =1+A23 -> 20 | B24: PATEGO NJOSSU GUSTAVE | C24: 25000 | E24: 25000 | G24: 25000 | I24: 25000 | K24: 25000 | M24: 25000 | O24: 25000 | Q24: 25000 | S24: 25000 | U24: 25000 | W24: 25000 | X24: 2500
A25: =1+A24 -> 21 | B25: SIME BRICE | C25: 25000 | E25: 25000 | G25: 25000 | I25: 25000 | K25: 25000 | M25: 25000 | O25: 25000 | Q25: 25000 | R25: 3000 | S25: 25000 | U25: 25000 | W25: 25000
A26: =1+A25 -> 22 | B26: MBAKOP ACHILLE | C26: 25000 | E26: 25000 | G26: 25000 | I26: 25000 | K26: 25000 | M26: 25000 | O26: 25000 | P26: 3000 | Q26: 25000 | S26: 25000 | U26: 25000 | W26: 25000
A27: =1+A26 -> 23 | B27: SIME PIERRE | C27: 25000 | E27: 25000 | G27: 25000 | H27: 11000 | I27: 25000 | K27: 25000 | M27: 25000 | O27: 25000 | Q27: 25000 | S27: 25000 | U27: 25000 | W27: 25000
A28: =1+A27 -> 24 | B28: TCHOUAMOU MATHIEU | C28: 25000 | E28: 25000 | G28: 25000 | I28: 25000 | K28: 25000 | M28: 25000 | O28: 25000 | P28: 2500 | Q28: 25000 | S28: 25000 | U28: 25000 | W28: 25000
A29: =1+A28 -> 25 | B29: YEPMO JEAN JACQUES | C29: 25000 | E29: 25000 | G29: 25000 | I29: 0 | K29: 50000 | M29: 25000 | O29: 25000 | Q29: 25000 | S29: 25000 | U29: 25000 | W29: 25000 | Z29: 2500
A30: =1+A29 -> 26 | B30: YOUMBI EMMANUEL | C30: 25000 | E30: 25000 | G30: 25000 | I30: 25000 | K30: 25000 | M30: 25000 | O30: 25000 | Q30: 25000 | S30: 25000 | U30: 25000 | W30: 25000 | X30: 2500
A31: =1+A30 -> 27 | B31: SEUMOU POLYCARPE | C31: 25000 | E31: 25000 | G31: 25000 | I31: 25000 | K31: 25000 | M31: 25000 | O31: 25000 | Q31: 25000 | S31: 25000 | T31: 2500 | U31: 25000 | W31: 25000
A32: =1+A31 -> 28 | B32: NOUBE ETIENNE | C32: 25000 | E32: 25000 | G32: 25000 | I32: 25000 | K32: 25000 | M32: 25000 | O32: 25000 | Q32: 25000 | S32: 25000 | T32: 2500 | U32: 25000 | W32: 25000
A33: =1+A32 -> 29 | B33: TCHOUTOU NANA | C33: 25000 | E33: 25000 | G33: 25000 | I33: 25000 | K33: 25000 | M33: 25000 | O33: 25000 | Q33: 0 | S33: 0 | U33: 0 | W33: 75000
A34: =1+A33 -> 30 | B34: YANTCHOU GERVAIS | C34: 25000 | E34: 25000 | G34: 25000 | I34: 25000 | K34: 25000 | M34: 25000 | O34: 25000 | Q34: 25000 | S34: 25000 | U34: 25000 | V34: 2500 | W34: 25000 | Z34: 2500
B35: TOTAL | C35: =SUM(C5:C34) -> 750000 | D35: =SUM(D5:D34) -> 40000 | E35: =SUM(E5:E34) -> 750000 | F35: =SUM(F5:F34) -> 17500 | G35: =SUM(G5:G34) -> 750000 | H35: =SUM(H5:H34) -> 32000 | I35: =SUM(I5:I34) -> 725000 | J35: =SUM(J5:J34) -> 21000 | ... AA35: =SUM(AA5:AA34) -> 0 | AB35: =+Z35+X35+V35+T35+R35+P35+N35+L35+J35+H35+F35+D35 -> 167000 | AC35: =SUM(AC5:AC34) -> 0 | AD35: =SUM(AD5:AD34) -> 0 | AE35: =SUM(AE5:AE34) -> 0 | AF35: =SUM(AF5:AF34) -> 0 | AI35: =SUM(AI5:AI26) -> 0 | AJ35: =SUM(AJ5:AJ26) -> 0
C36: reliquat Janvier | E36: reliquat Février | G36: RELIQUAT MARS | I36: reliquat AVRIL | K36: RELIQUAT MAI | L36: 85500 | M36: reliquat fev | N36: 93500 | O36: reliquat mar | P36: 240500 | Q36: reliquat avr | R36: -53500 | S36: reliquat avr | T36: 0 | U36: reliquat avr | AB36: =+F53+F69+F85+F100+F117+F131+F146+F161+F176+F191+F212+F228 -> 26000 | AI36: Reliquat Juil | AJ36: 0
AB37: =SUM(AB35:AB36) -> 193000
C38: REMBOURSEMENTS ET EMPRUNTS DES SOUS-PRODUITS | O38: BILAN DE LA TONTINE VENTE | AB38: =+AB37/30 -> 6433.3333
B39: Dates | C39: Somme remboursée | E39: Somme empruntée | F39: Intérêt produit | G39: Montant à rembourser | H39: Solde en caisse | I39: Total disponible | K39: 44941 | O39: NOM | P39: Nbre de part | Q39: Mtant d'une part | R39: Net à percevoir
C40: Nom & Prénom | D40: Montant | J40: NOM | K40: Mt du lot | L40: Mt achat | M40: Net à percev | N40: 1 | P40: 1 | Q40: =D258/P74 -> 25806.452 | R40: =P40*$Q$40 -> 25806.452
...

Sheet TONTINE 75000 EXO 2023
B1: ANNEE 2023
F2: TOTINE AVEC RETENUE
B3: Date | C3: 44941 | E3: 12 fevrier 2023 | G3: 45004 | I3: 45032 | K3: 45067 | M3: 45095 | O3: 45123 | Q3: 21 aout 2023 | S3: 45186 | U3: 45214 | W3: 45249 | Y3: 17 decembre 2023
B4: Nom et Prénom | C4: Cotisation | D4: Mtant achat | E4: Cotisation | F4: Mtant achat | G4: Cotisation | H4: Mtant achat | I4: Cotisation | J4: Mtant achat | K4: Cotisation | L4: Mtant achat | M4: Cotisation | N4: Mtant achat | O4: Cotisation | P4: Mtant achat | Q4: Cotisation | R4: Mtant achat | S4: Cotisation | T4: Mtant achat | U4: cotisation | V4: mtant achat | W4: cotisation | X4: mtant achat | Y4: cotisation | Z4: mtant achat
A5: 1 | B5: BOUTCHOUANG WILLIAM | C5: 75000 | E5: 75000 | G5: 75000 | I5: 75000 | K5: 75000 | M5: 75000 | O5: 75000 | Q5: 75000 | S5: 75000 | T5: 7500 | U5: 75000 | W5: 75000 | Y5: 75000
A6: =1+A5 -> 2 | B6: DJOUKWE GUY | C6: 75000 | E6: 75000 | G6: 75000 | H6: 7500 | I6: 75000 | K6: 75000 | M6: 75000 | O6: 75000 | Q6: 75000 | S6: 75000 | U6: 75000 | W6: 75000 | Y6: 75000
A7: =1+A6 -> 3 | B7: DJUOMBISSY ANTOINE | C7: 75000 | E7: 75000 | G7: 75000 | I7: 75000 | K7: 75000 | L7: 10000 | M7: 75000 | O7: 75000 | Q7: 75000 | S7: 75000 | U7: 75000 | W7: 75000 | Y7: 75000
A8: =1+A7 -> 4 | B8: HENGUE PAUL OMER | C8: 75000 | E8: 75000 | G8: 75000 | I8: 75000 | K8: 75000 | M8: 75000 | O8: 75000 | P8: 7500 | Q8: 75000 | S8: 75000 | U8: 75000 | W8: 75000 | Y8: 75000
A9: =1+A8 -> 5 | B9: HOTCHO BENJAMIN | C9: 75000 | E9: 75000 | F9: 20000 | G9: 75000 | I9: 75000 | K9: 75000 | M9: 75000 | O9: 75000 | Q9: 75000 | S9: 75000 | U9: 75000 | W9: 75000 | Y9: 75000
A10: =1+A9 -> 6 | B10: KOUATCHO | C10: 75000 | E10: 75000 | G10: 75000 | I10: 75000 | J10: 13000 | K10: 75000 | M10: 75000 | O10: 75000 | Q10: 75000 | S10: 75000 | U10: 75000 | W10: 75000 | Y10: 75000
A11: =1+A10 -> 7 | B11: MBOGNING GUY | C11: 75000 | E11: 75000 | F11: 22000 | G11: 75000 | I11: 75000 | K11: 75000 | M11: 75000 | O11: 75000 | Q11: 75000 | S11: 75000 | U11: 75000 | W11: 75000 | Y11: 75000
A12: =1+A11 -> 8 | B12: NANKAM APPOLINAIRE | C12: 75000 | E12: 75000 | G12: 75000 | I12: 75000 | K12: 75000 | M12: 75000 | O12: 75000 | Q12: 75000 | S12: 75000 | T12: 7500 | U12: 75000 | W12: 75000 | Y12: 75000
A13: =1+A12 -> 9 | B13: NGONDIEP CLAUDE | C13: 75000 | D13: 37500 | E13: 75000 | G13: 75000 | I13: 75000 | K13: 75000 | M13: 75000 | O13: 75000 | Q13: 75000 | S13: 75000 | U13: 75000 | W13: 75000 | Y13: 75000
A14: =1+A13 -> 10 | B14: NGUIEMENI MATHIEU BLAISE 1 | C14: 75000 | E14: 75000 | G14: 75000 | I14: 75000 | K14: 75000 | L14: 15000 | M14: 75000 | O14: 75000 | Q14: 75000 | S14: 75000 | U14: 75000 | W14: 75000 | Y14: 75000
A15: =1+A14 -> 11 | B15: NGUIEMENI MATHIEU BLAISE 2 | C15: 75000 | E15: 75000 | G15: 75000 | I15: 75000 | K15: 75000 | M15: 75000 | O15: 75000 | Q15: 75000 | R15: 7500 | S15: 75000 | U15: 75000 | W15: 75000 | Y15: 75000
A16: =1+A15 -> 12 | B16: PATEGO GUSTAVE | C16: 75000 | E16: 75000 | G16: 75000 | I16: 75000 | K16: 75000 | M16: 75000 | O16: 75000 | Q16: 75000 | S16: 75000 | U16: 75000 | W16: 75000 | X16: 7500 | Y16: 75000
A17: =1+A16 -> 13 | B17: SIME BRICE | C17: 75000 | E17: 75000 | G17: 75000 | I17: 75000 | K17: 75000 | M17: 75000 | O17: 75000 | Q17: 75000 | R17: 7500 | S17: 75000 | U17: 75000 | W17: 75000 | Y17: 75000
A18: =1+A17 -> 14 | B18: TCHOUAMOU MATHIEU | C18: 75000 | E18: 75000 | G18: 75000 | H18: 7500 | I18: 75000 | K18: 75000 | M18: 75000 | O18: 75000 | Q18: 75000 | S18: 75000 | U18: 75000 | W18: 75000 | Y18: 75000
A19: =1+A18 -> 15 | B19: YOUMBI EMMANUEL 1 | C19: 75000 | E19: 75000 | G19: 75000 | I19: 75000 | K19: 75000 | M19: 75000 | O19: 75000 | Q19: 75000 | S19: 75000 | U19: 75000 | W19: 75000 | X19: 7500 | Y19: 75000
A20: =1+A19 -> 16 | B20: YOUMBI EMMANUEL 2 | C20: 75000 | E20: 75000 | G20: 75000 | I20: 75000 | K20: 75000 | M20: 75000 | N20: 7500 | O20: 75000 | Q20: 75000 | S20: 75000 | U20: 75000 | W20: 75000 | Y20: 75000
A21: =1+A20 -> 17 | B21: ASELBY | C21: 75000 | E21: 75000 | G21: 75000 | I21: 75000 | K21: 75000 | M21: 75000 | O21: 75000 | Q21: 75000 | S21: 75000 | U21: 75000 | W21: 75000 | Y21: 75000 | Z21: 7500
A22: =1+A21 -> 18
A23: =1+A22 -> 19
A24: =1+A23 -> 20
B25: TOTAL | C25: =SUM(C5:C24) -> 1275000 | D25: =SUM(D5:D24) -> 37500 | E25: =SUM(E5:E24) -> 1275000 | F25: =SUM(F5:F24) -> 42000 | G25: =SUM(G5:G24) -> 1275000 | H25: =SUM(H5:H24) -> 15000 | I25: =SUM(I5:I24) -> 1275000 | J25: =SUM(J5:J24) -> 13000 | ... S25: =SUM(S5:S24) -> 1275000 | T25: =SUM(T5:T16) -> 15000 | U25: =SUM(U5:U24) -> 1275000 | V25: =SUM(V5:V24) -> 0 | W25: =SUM(W5:W24) -> 1275000 | X25: =SUM(X5:X24) -> 15000 | Y25: =SUM(Y5:Y24) -> 1275000 | Z25: =SUM(Z5:Z24) -> 7500 | AA25: =SUM(AA5:AA24) -> 0 | AB25: =SUM(AB5:AB24) -> 0 | AC25: =+Z25+X25+V25+T25+R25+P25+N25+L25+J25+H25+F25+D25 -> 200000 | AD25: =SUM(AD5:AD24) -> 0 | AE25: =SUM(AE5:AE24) -> 0 | AF25: =SUM(AF5:AF24) -> 0 | AI25: =SUM(AI5:AI16) -> 0 | AJ25: =SUM(AJ5:AJ16) -> 0
C26: reliquat Janvier | D26: 75000 | E26: reliquat Février | G26: RELIQUAT MARS | I26: reliquat AVRIL | K26: RELIQUAT MAI | M26: reliquat fev | O26: reliquat mar | Q26: reliquat avr | S26: reliquat avr | T26: 0 | U26: reliquat avr | AC26: =+F43+F59+F75+F90+F107+F121+F136+F151+F166+F181+F202+F218 -> 49500 | AI26: Reliquat Juil | AJ26: 0
AC27: =SUM(AC25:AC26) -> 249500
C28: REMBOURSEMENTS ET EMPRUNTS DES SOUS-PRODUITS | O28: BILAN DE LA TONTINE VENTE | AC28: =+AC27/17 -> 14676.471
B29: Dates | C29: Somme remboursée | E29: Somme empruntée | F29: Intérêt produit | G29: Montant à rembourser | H29: Solde en caisse | I29: Total disponible | K29: 44941 | O29: NOM | P29: Nbre de part | Q29: Mtant d'une part | R29: Net à percevoir
C30: Nom & Prénom | D30: Montant | J30: NOM | K30: Mt du lot | L30: Mt achat | M30: Net à percev | P30: 1 | Q30: =D248/P64 -> 159375 | R30: =P30*$Q$30 -> 159375
B31: 44941 | C31: Disponible | D31: =C25-M34 -> 480000 | J31: NGONDIEP CL | K31: 900000 | L31: 105000 | M31: =K31-L31 -> 795000 | P31: 1 | Q31: 0 | R31: =P31*$Q$30 -> 159375
C32: KOUATCHO | D32: 0 | E32: 50000 | F32: 1000 | G32: =E32+F32 -> 51000 | H32: 51000 | K32: 0 | L32: 0 | M32: =K32-L32 -> 0 | P32: 1 | Q32: 0 | R32: =P32*$Q$30 -> 159375
C33: KOUATCHO | D33: 0 | E33: 50000 | F33: 1000 | G33: =E33+F33 -> 51000 | H33: 51000 | K33: 0 | L33: 0 | M33: =K33-L33 -> 0 | P33: 1 | Q33: 0 | R33: =P33*$Q$30 -> 159375
C34: NGUIEMENI | D34: 0 | E34: 50000 | F34: 1000 | G34: =E34+F34 -> 51000 | H34: 51000 | L34: =SUM(L31:L33) -> 105000 | M34: =SUM(M31:M33) -> 795000 | P34: 1 | Q34: 0 | R34: =P34*$Q$30 -> 159375
C35: NGONDIEP | D35: 0 | E35: 50000 | F35: 1000 | G35: =E35+F35 -> 51000 | H35: 51000 | P35: 1 | Q35: 0 | R35: =P35*$Q$30 -> 159375
C36: NGONDIEP | D36: 0 | E36: 50000 | F36: 1000 | G36: =E36+F36 -> 51000 | H36: 51000 | P36: 1 | Q36: 0 | R36: =P36*$Q$30 -> 159375
C37: NGUIEMENI | D37: 0 | E37: 50000 | F37: 1000 | G37: =E37+F37 -> 51000 | H37: 51000 | P37: 1 | Q37: 0 | R37: =P37*$Q$30 -> 159375
C38: MBOGNING | D38: 0 | E38: 50000 | F38: 1000 | G38: =E38+F38 -> 51000 | H38: 51000 | P38: 1 | Q38: 0 | R38: =P38*$Q$30 -> 159375
C39: MBOGNING | D39: 0 | E39: 55000 | F39: 1000 | G39: =E39+F39 -> 56000 | H39: 56000 | P39: 1 | Q39: 0 | R39: =P39*$Q$30 -> 159375
C40: ASELBY | D40: 0 | E40: 75000 | F40: 0 | G40: =E40+F40 -> 75000 | H40: 75000 | P40: 1 | Q40: 0 | R40: =P40*$Q$30 -> 159375
...

Sheet TONTINE DE 100 000 EXO 2023
B1: ANNEE 2023
F2: TOTINE AVEC RETENUE
B3: Date | C3: 44941 | E3: 12fevrier 2023 | G3: 45004 | I3: 45032 | K3: 45067 | M3: 45095 | O3: 45123 | Q3: 27 aout 2023 | S3: 45186 | U3: 45214 | W3: 45249 | Y3: 17 decembre 2023
B4: Nom et Prénom | C4: Cotisation | D4: Mtant achat | E4: Cotisation | F4: Mtant achat | G4: Cotisation | H4: Mtant achat | I4: Cotisation | J4: Mtant achat | K4: Cotisation | L4: Mtant achat | M4: Cotisation | N4: Mtant achat | O4: Cotisation | P4: Mtant achat | Q4: Cotisation | R4: Mtant achat | S4: Cotisation | T4: Mtant achat | U4: cotisation | V4: mtant achat | W4: cotisation | X4: mtant achat | Y4: cotisation | Z4: mtant achat
A5: 1 | B5: DJOMO JEAN PAUL | C5: 100000 | E5: 100000 | G5: 100000 | H5: 10000 | I5: 100000 | K5: 100000 | M5: 100000 | O5: 100000 | Q5: 100000 | S5: 100000 | U5: 100000
A6: =1+A5 -> 2 | B6: DJUOMBISSY ANTOINE 1 | C6: 100000 | E6: 100000 | G6: 100000 | H6: 10000 | I6: 100000 | K6: 100000 | M6: 100000 | O6: 100000 | Q6: 100000 | S6: 100000 | U6: 100000
A7: =1+A6 -> 3 | B7: DJUOMBISSY ANTOINE 2 | C7: 100000 | E7: 100000 | G7: 100000 | I7: 100000 | K7: 100000 | M7: 100000 | O7: 100000 | Q7: 100000 | R7: 10000 | S7: 100000 | U7: 100000
A8: =1+A7 -> 4 | B8: HOTCHO BENJAMIN | C8: 100000 | E8: 100000 | F8: 28000 | G8: 100000 | I8: 100000 | K8: 100000 | M8: 100000 | O8: 100000 | Q8: 100000 | S8: 100000 | U8: 100000
A9: =1+A8 -> 5 | B9: KOUAMOU MOISE | C9: 100000 | E9: 100000 | F9: 28000 | G9: 100000 | I9: 100000 | K9: 100000 | M9: 100000 | O9: 100000 | Q9: 100000 | S9: 100000 | U9: 100000
A10: =1+A9 -> 6 | B10: KOUATCHO | C10: 100000 | D10: 35000 | E10: 100000 | G10: 100000 | I10: 100000 | K10: 100000 | M10: 100000 | O10: 100000 | Q10: 100000 | S10: 100000 | U10: 100000
A11: =1+A10 -> 7 | B11: MBOGNING GUY | C11: 100000 | D11: 35000 | E11: 100000 | G11: 100000 | I11: 100000 | K11: 100000 | M11: 100000 | O11: 100000 | Q11: 100000 | S11: 100000 | U11: 100000
A12: =1+A11 -> 8 | B12: NDJOMO ETIENNE 1 | C12: 100000 | E12: 100000 | G12: 100000 | I12: 100000 | K12: 100000 | M12: 100000 | N12: 10000 | O12: 100000 | Q12: 100000 | S12: 100000 | U12: 100000
A13: =1+A12 -> 9 | B13: NDJOMO ETIENNE 2 | C13: 100000 | E13: 100000 | G13: 100000 | I13: 100000 | K13: 100000 | M13: 100000 | O13: 100000 | Q13: 100000 | R13: 10000 | S13: 100000 | U13: 100000
A14: =1+A13 -> 10 | B14: NGONDIEP CLAUDE | C14: 100000 | D14: 35000 | E14: 100000 | G14: 100000 | I14: 100000 | K14: 100000 | M14: 100000 | O14: 100000 | Q14: 100000 | S14: 100000 | U14: 100000
A15: =1+A14 -> 11 | B15: NGUIEMENI MATHIEU BALISE | C15: 100000 | E15: 100000 | G15: 100000 | I15: 100000 | J15: 20000 | K15: 100000 | M15: 100000 | O15: 100000 | Q15: 100000 | S15: 100000 | U15: 100000
A16: =1+A15 -> 12 | B16: SIME PIERRE | C16: 100000 | E16: 100000 | G16: 100000 | I16: 100000 | K16: 100000 | L16: 10000 | M16: 100000 | O16: 100000 | Q16: 100000 | S16: 100000 | U16: 100000
A17: =1+A16 -> 13 | B17: YOUMBI EMMANUEL | C17: 100000 | E17: 100000 | G17: 100000 | I17: 100000 | K17: 100000 | M17: 100000 | N17: 10000 | O17: 100000 | Q17: 100000 | S17: 100000 | U17: 100000
A18: =1+A17 -> 14 | B18: ASELBY | C18: 100000 | E18: 100000 | G18: 100000 | I18: 100000 | K18: 100000 | M18: 100000 | O18: 100000 | Q18: 100000 | S18: 100000 | U18: 100000 | X18: 10000
A19: =1+A18 -> 15
A20: =1+A19 -> 16
A21: =1+A20 -> 17
A22: =1+A21 -> 18
A23: =1+A22 -> 19
A24: =1+A23 -> 20
B25: TOTAL | C25: =SUM(C5:C24) -> 1400000 | D25: =SUM(D5:D24) -> 105000 | E25: =SUM(E5:E24) -> 1400000 | F25: =SUM(F5:F24) -> 56000 | G25: =SUM(G5:G24) -> 1400000 | H25: =SUM(H5:H24) -> 20000 | I25: =SUM(I5:I24) -> 1400000 | J25: =SUM(J5:J24) -> 20000 | ... S25: =SUM(S5:S24) -> 1400000 | T25: =SUM(T5:T16) -> 0 | U25: =SUM(U5:U24) -> 1400000 | V25: =SUM(V5:V24) -> 0 | W25: =SUM(W5:W24) -> 0 | X25: =SUM(X5:X24) -> 10000 | Y25: =SUM(Y5:Y24) -> 0 | Z25: =SUM(Z5:Z24) -> 0 | AA25: =+X25+V25+Z25+T25+R25+P25+N25+L25+J25+H25+F25+D25 -> 261000 | AB25: =SUM(AB5:AB24) -> 0 | AC25: =SUM(AC5:AC24) -> 0 | AD25: =SUM(AD5:AD24) -> 0 | AE25: =SUM(AE5:AE24) -> 0 | AF25: =SUM(AF5:AF24) -> 0 | AI25: =SUM(AI5:AI16) -> 0 | AJ25: =SUM(AJ5:AJ16) -> 0
C26: reliquat Janvier | D26: 250000 | E26: reliquat Février | G26: RELIQUAT MARS | I26: reliquat AVRIL | K26: RELIQUAT MAI | L26: 85500 | M26: reliquat fev | N26: 93500 | O26: reliquat mar | P26: 240500 | Q26: reliquat avr | R26: -53500 | S26: reliquat avr | T26: 0 | U26: reliquat avr | AA26: =+F43+F59+F75+F90+F107+F121+F136+F151+F166+F181+F202+F218 -> 76500 | AI26: Reliquat Juil | AJ26: 0
AA27: =SUM(AA25:AA26) -> 337500
C28: REMBOURSEMENTS ET EMPRUNTS DES SOUS-PRODUITS | O28: BILAN DE LA TONTINE VENTE | AA28: =+AA27/14 -> 24107.143
B29: Dates | C29: Somme remboursée | E29: Somme empruntée | F29: Intérêt produit | G29: Montant à rembourser | H29: Solde en caisse | I29: Total disponible | K29: 44941 | O29: NOM | P29: Nbre de part | Q29: Mtant d'une part | R29: Net à percevoir
C30: Nom & Prénom | D30: Montant | J30: NOM | K30: Mt du lot | L30: Mt achat | M30: Net à percev | P30: 1 | Q30: =D248/P64 -> 32625 | R30: =P30*$Q$30 -> 32625
B31: 44941 | C31: Disponible | D31: =C25-M34 -> -1825000 | J31: MBOGNING GUY | K31: 1200000 | L31: 125000 | M31: =K31-L31 -> 1075000 | P31: 1 | Q31: 0 | R31: =P31*$Q$30 -> 32625
C32: NGUIEMENI M B | D32: 0 | E32: 25000 | F32: 1000 | G32: =E32+F32 -> 26000 | H32: 26000 | J32: NGONDIEP CLAUDE | K32: 1200000 | L32: 125000 | M32: =K32-L32 -> 1075000 | P32: 1 | Q32: 0 | R32: =P32*$Q$30 -> 32625
C33: NGONDIEP CL | D33: 0 | E33: 100000 | F33: 4000 | G33: =E33+F33 -> 104000 | H33: 104000 | J33: KOUATCHO | K33: 1200000 | L33: 125000 | M33: =K33-L33 -> 1075000 | P33: 1 | Q33: 0 | R33: =P33*$Q$30 -> 32625
C34: DJOMO JEAN P | D34: 0 | E34: 50000 | F34: 2000 | G34: =E34+F34 -> 52000 | H34: 52000 | L34: =SUM(L31:L33) -> 375000 | M34: =SUM(M31:M33) -> 3225000 | P34: 1 | Q34: 0 | R34: =P34*$Q$30 -> 32625
C35: NGONDIEP CL | D35: 0 | E35: 100000 | F35: 4000 | G35: =E35+F35 -> 104000 | H35: 104000 | P35: 1 | Q35: 0 | R35: =P35*$Q$30 -> 32625
C36: NGUIEMENI M B | D36: 0 | E36: 50000 | F36: 2000 | G36: =E36+F36 -> 52000 | H36: 52000 | P36: 1 | Q36: 0 | R36: =P36*$Q$30 -> 32625
C37: ASELBY | D37: 0 | E37: 250000 | F37: 0 | G37: =E37+F37 -> 250000 | H37: 250000 | P37: 1 | Q37: 0 | R37: =P37*$Q$30 -> 32625
D38: 0 | E38: 0 | F38: 0 | G38: =E38+F38 -> 0 | P38: 1 | Q38: 0 | R38: =P38*$Q$30 -> 32625
D39: 0 | E39: 0 | F39: 0 | G39: =E39+F39 -> 0 | P39: 1 | Q39: 0 | R39: =P39*$Q$30 -> 32625
D40: 0 | E40: 0 | F40: 0 | G40: =E40+F40 -> 0 | P40: 1 | Q40: 0 | R40: =P40*$Q$30 -> 32625
...

Sheet EPARGNE 2023
B1: SITUATION FONDS DES MEMBRES DEC 2022 | F1: SITUATION FONDS DES MEMBRES DEC 2022 | K1: SITUATION FONDS DES MEMBRES DEC 2022 | P1: SITUATION FONDS DES MEMBRES DE2022 | V1: SITUATION FONDS DES MEMBRES DEC 2022 | AB1: SITUATION FONDS DES MEMBRES DEC 2022 | AI1: SITUATION FONDS DES MEMBRES DEC 2022 | AP1: SITUATION FONDS DES MEMBRES | AV1: SITUATION FONDS DES MEMBRES | BB1: SITUATION FONDS DES MEMBRES
A2: N° | B2: NOMS ET PRENOMS | C2: FONDS | D2: RECONDUCTIONS | E2: TOTAL | F2: DECEMBRE 2022 | H2: JANVIER 2023 | K2: FEVRIER 2023 | N2: MARS 2023 | Q2: AVRIL 2023 | T2: MAI 2023 | W2: JUIN 2023 | Z2: JUILLET 2023 | AC2: AOUT 2023 | AF2: SEPTEMBRE 2023 | AI2: OCTOBRE 2023 | AL2: NOVEMBRE 2023 | AO2: DECEMBRE 2023 | AR2: SYNTHESE ANNUELLE | AW2: OPERATION DE CASSATION
F3: 1268000 | H3: 0 | K3: =30000+0 -> 30000 | N3: =0+6000 -> 6000 | Q3: =10000+80000+12000+42000+60000 -> 204000 | T3: 30000 | W3: 74200 | Z3: 50000 | AC3: 64000 | AF3: 0 | AI3: 20000 | AL3: 0 | AR3: =+F3+H3+K3+N3+Q3+T3+W3+Z3+AC3+AF3+AI3+AL3+AO3 -> 1746200 | BE3: MONTANT DECHARGE | BF3: REPORT A NOUVEAU
F4: INTERET | G4: CUMUL | H4: EPARGNE | I4: INTERET | J4: CUMUL | K4: EPARGNE | L4: INTERET | M4: CUMUL | N4: EPARGNE | O4: INTERET | P4: CUMUL | Q4: EPARGNE | R4: INTERET | S4: CUMUL | T4: EPARGNE | U4: INTERET | V4: CUMUL | W4: EPARGNE | X4: INTERET | Y4: CUMUL | Z4: EPARGNE | AA4: INTERET | AB4: CUMUL | AC4: EPARGNE | AD4: INTERET | AE4: CUMUL | AF4: EPARGNE | AG4: INTERET | AH4: CUMUL | AI4: EPARGNE | AJ4: INTERET | AK4: CUMUL | AL4: EPARGNE | AM4: INTERET | AN4: CUMUL | AO4: EPARGNE | AP4: INTERET | AQ4: CUMUL | AR4: FONDS | AS4: RECONDUCTION | AT4: EPARGNE ANNUELLE | AU4: INTERET | AV4: CUMUL | AW4: RETRAIT FOND | AX4: RETRAIT MUTUEL | AY4: RETRAIT FOYER | AZ4: RETRAIT PENALITE | BA4: SAISIE REMB | BB4: RESTE | BC4: NOUVEAU FONDS | BD4: NAP
A5: AS201648 | B5: ASELBY | D5: =736543.521348481+80000 -> 816543.52 | E5: =+C5+D5 -> 816543.52 | F5: =+(1268000/19961560)*E5 -> 51868.551 | G5: =+E5+F5 -> 868412.07 | H5: 0 | I5: =+(0/(21229560+1050000))*(G5+H5) -> 0 | J5: =+G5+H5+I5 -> 868412.07 | K5: 0 | L5: =+(30000/((21638859-36000)+(328000-36000))*(J5+K5)) -> 1189.8849 | M5: =+J5+K5+L5 -> 869601.96 | N5: 0 | O5: =+(6000/(21996859-72000+345000-18000-19000-44000))*(M5+N5) -> 235.14556 | P5: =+M5+N5+O5 -> 869837.1 | Q5: 0 | R5: =+(204000/(22347859-54000-37000-62000+386000-18000-19000-66000))*(P5+Q5) -> 7894.2914 | S5: =+P5+Q5+R5 -> 877731.39 | T5: 0 | U5: =+((30000/(22937859+882000-36000-36000-56000-128000-6000-9000-409000-69000))*(S5+T5)) -> 1141.3507 | V5: =+S5+T5+U5 -> 878872.74 | W5: 0 | X5: =+(74200/(23849859+426500-42000-45000-465000-197000-9000-9000-14000-69000))*(V5+W5) -> 2783.7172 | Y5: =+V5+W5+X5 -> 881656.46 | Z5: 0 | AA5: =+(50000/(24350559+561768-51000-54000-479000-266000-9000-9000-19000-69000-153468))*(Y5+Z5) -> 1851.997 | AB5: =+Y5+Z5+AA5 -> 883508.46 | AC5: 0 | AD5: =+(64000/(24962327+403000-60000-63000-498000-335000-153468-9000-9000-19000-69000))*(AB5+AC5) -> 2341.4025 | AE5: =+AB5+AC5+AD5 -> 885849.86 | AF5: 0 | AG5: =+(0/20256265)*(AE5+AF5) -> 0 | AH5: =+AE5+AF5+AG5 -> 885849.86 | AI5: 0 | AJ5: =+((20000/(26194827+596000-60000-258500-9000-153468))*(AH5+AI5)) -> 673.39765 | AK5: =+AH5+AI5+AJ5 -> 886523.26 | AL5: 0 | AM5: =+(0/(23068716+171000))*(AK5+AL5) -> 0 | AN5: =+AK5+AL5+AM5 -> 886523.26 | AO5: 0 | AP5: =+(0/20000)*(AN5+AO5) -> 0 | AQ5: =+AN5+AO5+AP5 -> 886523.26 | AR5: =+C5 -> 0 | AS5: =+D5 -> 816543.52 | AT5: =+H5+K5+N5+Q5+T5+W5+Z5+AC5+AF5+AI5+AL5+AO5 -> 0 | AU5: =+F5+I5+L5+O5+R5+U5+X5+AA5+AD5+AG5+AJ5+AM5+AP5 -> 69979.738 | AV5: =+AN5+AO5+AP5 -> 886523.26 | BB5: =+AV5-AW5-AX5-AY5-AZ5-BA5 -> 886523.26 | BD5: =+BB5-BC5 -> 886523.26 | BE5: 0 | BF5: =+BD5-BE5 -> 886523.26 | BG5: 80000 DE NGANHOU JEAN
A6: AS201602 | B6: BOUTCHOUANG WILLIAM | C6: 600000 | D6: 7023.6611 | E6: =+C6+D6 -> 607023.66 | F6: =+(1268000/19961560)*E6 -> 38559.411 | G6: =+E6+F6 -> 645583.07 | H6: 9000 | I6: =+(0/(21229560+1050000))*(G6+H6) -> 0 | J6: =+G6+H6+I6 -> 654583.07 | K6: 9000 | L6: =+(30000/((21638859-36000)+(328000-36000))*(J6+K6)) -> 909.23135 | M6: =+J6+K6+L6 -> 664492.3 | N6: 9000 | O6: =+(6000/(21996859-72000+345000-18000-19000-44000))*(M6+N6) -> 182.11634 | P6: =+M6+N6+O6 -> 673674.42 | Q6: 9000 | R6: =+(204000/(22347859-54000-37000-62000+386000-18000-19000-66000))*(P6+Q6) -> 6195.6782 | S6: =+P6+Q6+R6 -> 688870.1 | T6: 9000 | U6: =+((30000/(22937859+882000-36000-36000-56000-128000-6000-9000-409000-69000))*(S6+T6)) -> 907.46959 | V6: =+S6+T6+U6 -> 698777.57 | W6: 9000 | X6: =+(74200/(23849859+426500-42000-45000-465000-197000-9000-9000-14000-69000))*(V6+W6) -> 2241.795 | Y6: =+V6+W6+X6 -> 710019.36 | Z6: 9000 | AA6: =+(50000/(24350559+561768-51000-54000-479000-266000-9000-9000-19000-69000-153468))*(Y6+Z6) -> 1510.3634 | AB6: =+Y6+Z6+AA6 -> 720529.73 | AC6: 9000 | AD6: =+(64000/(24962327+403000-60000-63000-498000-335000-153468-9000-9000-19000-69000))*(AB6+AC6) -> 1933.3406 | AE6: =+AB6+AC6+AD6 -> 731463.07 | AF6: 9000 | AG6: =+(0/20256265)*(AE6+AF6) -> 0 | AH6: =+AE6+AF6+AG6 -> 740463.07 | AI6: 9000 | AJ6: =+((20000/(26194827+596000-60000-258500-9000-153468))*(AH6+AI6)) -> 569.72032 | AK6: =+AH6+AI6+AJ6 -> 750032.79 | AL6: 9000 | AM6: =+(0/(23068716+171000))*(AK6+AL6) -> 0 | AN6: =+AK6+AL6+AM6 -> 759032.79 | AO6: 9000 | AP6: =+(0/20000)*(AN6+AO6) -> 0 | AQ6: =+AN6+AO6+AP6 -> 768032.79 | AR6: =+C6 -> 600000 | AS6: =+D6 -> 7023.6611 | AT6: =+H6+K6+N6+Q6+T6+W6+Z6+AC6+AF6+AI6+AL6+AO6 -> 108000 | AU6: =+F6+I6+L6+O6+R6+U6+X6+AA6+AD6+AG6+AJ6+AM6+AP6 -> 53009.126 | AV6: =+AN6+AO6+AP6 -> 768032.79 | AW6: 630000 | BB6: =+AV6-AW6-AX6-AY6-AZ6-BA6 -> 138032.79 | BD6: =+BB6 -> 138032.79 | BE6: 0 | BF6: =+BD6-BE6 -> 138032.79
A7: AS201604 | B7: DJOMO JEAN PAUL | C7: 600000 | D7: 4809.807 | E7: =+C7+D7 -> 604809.81 | F7: =+(1268000/19961560)*E7 -> 38418.783 | G7: =+E7+F7 -> 643228.59 | H7: 29000 | I7: =+(0/(21229560+1050000))*(G7+H7) -> 0 | J7: =+G7+H7+I7 -> 672228.59 | K7: 17000 | L7: =+(30000/((21638859-36000)+(328000-36000))*(J7+K7)) -> 944.37044 | M7: =+J7+K7+L7 -> 690172.96 | N7: 9000 | O7: =+(6000/(21996859-72000+345000-18000-19000-44000))*(M7+N7) -> 189.06054 | P7: =+M7+N7+O7 -> 699362.02 | Q7: 14000 | R7: =+(204000/(22347859-54000-37000-62000+386000-18000-19000-66000))*(P7+Q7) -> 6474.1865 | S7: =+P7+Q7+R7 -> 719836.21 | T7: 14000 | U7: =+((30000/(22937859+882000-36000-36000-56000-128000-6000-9000-409000-69000))*(S7+T7)) -> 954.23782 | V7: =+S7+T7+U7 -> 734790.44 | W7: 9000 | X7: =+(74200/(23849859+426500-42000-45000-465000-197000-9000-9000-14000-69000))*(V7+W7) -> 2355.8612 | Y7: =+V7+W7+X7 -> 746146.31 | Z7: 9000 | AA7: =+(50000/(24350559+561768-51000-54000-479000-266000-9000-9000-19000-69000-153468))*(Y7+Z7) -> 1586.2513 | AB7: =+Y7+Z7+AA7 -> 756732.56 | AC7: 9000 | AD7: =+(64000/(24962327+403000-60000-63000-498000-335000-153468-9000-9000-19000-69000))*(AB7+AC7) -> 2029.2824 | AE7: =+AB7+AC7+AD7 -> 767761.84 | AF7: 7000 | AG7: =+(0/20256265)*(AE7+AF7) -> 0 | AH7: =+AE7+AF7+AG7 -> 774761.84 | AI7: 9000 | AJ7: =+((20000/(26194827+596000-60000-258500-9000-153468))*(AH7+AI7)) -> 595.79327 | AK7: =+AH7+AI7+AJ7 -> 784357.63 | AL7: 9000 | AM7: =+(0/(23068716+171000))*(AK7+AL7) -> 0 | AN7: =+AK7+AL7+AM7 -> 793357.63 | AO7: 9000 | AP7: =+(0/20000)*(AN7+AO7) -> 0 | AQ7: =+AN7+AO7+AP7 -> 802357.63 | AR7: =+C7 -> 600000 | AS7: =+D7 -> 4809.807 | AT7: =+H7+K7+N7+Q7+T7+W7+Z7+AC7+AF7+AI7+AL7+AO7 -> 144000 | AU7: =+F7+I7+L7+O7+R7+U7+X7+AA7+AD7+AG7+AJ7+AM7+AP7 -> 53547.826 | AV7: =+AN7+AO7+AP7 -> 802357.63 | AW7: 630000 | BB7: =+AV7-AW7-AX7-AY7-AZ7-BA7 -> 172357.63 | BD7: =+BB7 -> 172357.63 | BE7: 0 | BF7: =+BD7-BE7 -> 172357.63
A8: AS201654 | B8: DJOMOU TCHANDA | C8: 600000 | D8: 48710.412 | E8: =+C8+D8 -> 648710.41 | F8: =+(1268000/19961560)*E8 -> 41207.441 | G8: =+E8+F8 -> 689917.85 | H8: 9000 | I8: =+(0/(21229560+1050000))*(G8+H8) -> 0 | J8: =+G8+H8+I8 -> 698917.85 | K8: 9000 | L8: =+(30000/((21638859-36000)+(328000-36000))*(J8+K8)) -> 969.97819 | M8: =+J8+K8+L8 -> 708887.83 | N8: 10000 | O8: =+(6000/(21996859-72000+345000-18000-19000-44000))*(M8+N8) -> 194.39156 | P8: =+M8+N8+O8 -> 719082.22 | Q8: 9000 | R8: =+(204000/(22347859-54000-37000-62000+386000-18000-19000-66000))*(P8+Q8) -> 6607.7812 | S8: =+P8+Q8+R8 -> 734690 | T8: 9000 | U8: =+((30000/(22937859+882000-36000-36000-56000-128000-6000-9000-409000-69000))*(S8+T8)) -> 967.05112 | V8: =+S8+T8+U8 -> 744657.06 | W8: 9000 | X8: =+(74200/(23849859+426500-42000-45000-465000-197000-9000-9000-14000-69000))*(V8+W8) -> 2387.1125 | Y8: =+V8+W8+X8 -> 756044.17 | Z8: 6000 | AA8: =+(50000/(24350559+561768-51000-54000-479000-266000-9000-9000-19000-69000-153468))*(Y8+Z8) -> 1600.7408 | AB8: =+Y8+Z8+AA8 -> 763644.91 | AC8: 9000 | AD8: =+(64000/(24962327+403000-60000-63000-498000-335000-153468-9000-9000-19000-69000))*(AB8+AC8) -> 2047.6009 | AE8: =+AB8+AC8+AD8 -> 774692.51 | AF8: 9000 | AG8: =+(0/20256265)*(AE8+AF8) -> 0 | AH8: =+AE8+AF8+AG8 -> 783692.51 | AI8: 9000 | AJ8: =+((20000/(26194827+596000-60000-258500-9000-153468))*(AH8+AI8)) -> 602.5821 | AK8: =+AH8+AI8+AJ8 -> 793295.09 | AL8: 9000 | AM8: =+(0/(23068716+171000))*(AK8+AL8) -> 0 | AN8: =+AK8+AL8+AM8 -> 802295.09 | AO8: 9000 | AP8: =+(0/20000)*(AN8+AO8) -> 0 | AQ8: =+AN8+AO8+AP8 -> 811295.09 | AR8: =+C8 -> 600000 | AS8: =+D8 -> 48710.412 | AT8: =+H8+K8+N8+Q8+T8+W8+Z8+AC8+AF8+AI8+AL8+AO8 -> 106000 | AU8: =+F8+I8+L8+O8+R8+U8+X8+AA8+AD8+AG8+AJ8+AM8+AP8 -> 56584.679 | AV8: =+AN8+AO8+AP8 -> 811295.09 | AW8: 630000 | BB8: =+AV8-AW8-AX8-AY8-AZ8-BA8 -> 181295.09 | BD8: =+BB8 -> 181295.09 | BE8: 0 | BF8: =+BD8-BE8 -> 181295.09
A9: AS201605 | B9: DJOUKWE NANGUEN GUY BLAISE | C9: 600000 | D9: 4750.0783 | E9: =+C9+D9 -> 604750.08 | F9: =+(1268000/19961560)*E9 -> 38414.989 | G9: =+E9+F9 -> 643165.07 | H9: 9000 | I9: =+(0/(21229560+1050000))*(G9+H9) -> 0 | J9: =+G9+H9+I9 -> 652165.07 | K9: 9000 | L9: =+(30000/((21638859-36000)+(328000-36000))*(J9+K9)) -> 905.91823 | M9: =+J9+K9+L9 -> 662070.99 | N9: 14000 | O9: =+(6000/(21996859-72000+345000-18000-19000-44000))*(M9+N9) -> 182.81363 | P9: =+M9+N9+O9 -> 676253.8 | Q9: 9000 | R9: =+(204000/(22347859-54000-37000-62000+386000-18000-19000-66000))*(P9+Q9) -> 6219.0876 | S9: =+P9+Q9+R9 -> 691472.89 | T9: 9000 | U9: =+((30000/(22937859+882000-36000-36000-56000-128000-6000-9000-409000-69000))*(S9+T9)) -> 910.8541 | V9: =+S9+T9+U9 -> 701383.74 | W9: 13000 | X9: =+(74200/(23849859+426500-42000-45000-465000-197000-9000-9000-14000-69000))*(V9+W9) -> 2262.7193 | Y9: =+V9+W9+X9 -> 716646.46 | Z9: 9000 | AA9: =+(50000/(24350559+561768-51000-54000-479000-266000-9000-9000-19000-69000-153468))*(Y9+Z9) -> 1524.2842 | AB9: =+Y9+Z9+AA9 -> 727170.74 | AC9: 9000 | AD9: =+(64000/(24962327+403000-60000-63000-498000-335000-153468-9000-9000-19000-69000))*(AB9+AC9) -> 1950.9401 | AE9: =+AB9+AC9+AD9 -> 738121.68 | AF9: 9500 | AG9: =+(0/20256265)*(AE9+AF9) -> 0 | AH9: =+AE9+AF9+AG9 -> 747621.68 | AI9: 9000 | AJ9: =+((20000/(26194827+596000-60000-258500-9000-153468))*(AH9+AI9)) -> 575.1621 | AK9: =+AH9+AI9+AJ9 -> 757196.85 | AL9: 9000 | AM9: =+(0/(23068716+171000))*(AK9+AL9) -> 0 | AN9: =+AK9+AL9+AM9 -> 766196.85 | AO9: 9000 | AP9: =+(0/20000)*(AN9+AO9) -> 0 | AQ9: =+AN9+AO9+AP9 -> 775196.85 | AR9: =+C9 -> 600000 | AS9: =+D9 -> 4750.0783 | AT9: =+H9+K9+N9+Q9+T9+W9+Z9+AC9+AF9+AI9+AL9+AO9 -> 117500 | AU9: =+F9+I9+L9+O9+R9+U9+X9+AA9+AD9+AG9+AJ9+AM9+AP9 -> 52946.768 | AV9: =+AN9+AO9+AP9 -> 775196.85 | AW9: 630000 | BB9: =+AV9-AW9-AX9-AY9-AZ9-BA9 -> 145196.85 | BD9: =+BB9 -> 145196.85 | BE9: 0 | BF9: =+BD9-BE9 -> 145196.85
A10: AS201608 | B10: DJUOMBESSY ANTOINE | C10: 600000 | D10: 10718.85 | E10: =+C10+D10 -> 610718.85 | F10: =+(1268000/19961560)*E10 -> 38794.137 | G10: =+E10+F10 -> 649512.99 | H10: 14000 | I10: =+(0/(21229560+1050000))*(G10+H10) -> 0 | J10: =+G10+H10+I10 -> 663512.99 | K10: 14000 | L10: =+(30000/((21638859-36000)+(328000-36000))*(J10+K10)) -> 928.3179 | M10: =+J10+K10+L10 -> 678441.31 | N10: 14000 | O10: =+(6000/(21996859-72000+345000-18000-19000-44000))*(M10+N10) -> 187.24026 | P10: =+M10+N10+O10 -> 692628.55 | Q10: 14000 | R10: =+(204000/(22347859-54000-37000-62000+386000-18000-19000-66000))*(P10+Q10) -> 6413.0762 | S10: =+P10+Q10+R10 -> 713041.62 | T10: 114000 | U10: =+((30000/(22937859+882000-36000-36000-56000-128000-6000-9000-409000-69000))*(S10+T10)) -> 1075.4367 | V10: =+S10+T10+U10 -> 828117.06 | W10: 43500 | X10: =+(74200/(23849859+426500-42000-45000-465000-197000-9000-9000-14000-69000))*(V10+W10) -> 2760.7357 | Y10: =+V10+W10+X10 -> 874377.79 | Z10: 25300 | AA10: =+(50000/(24350559+561768-51000-54000-479000-266000-9000-9000-19000-69000-153468))*(Y10+Z10) -> 1889.8524 | AB10: =+Y10+Z10+AA10 -> 901567.65 | AC10: 14000 | AD10: =+(64000/(24962327+403000-60000-63000-498000-335000-153468-9000-9000-19000-69000))*(AB10+AC10) -> 2426.3632 | AE10: =+AB10+AC10+AD10 -> 917994.01 | AF10: 14000 | AG10: =+(0/20256265)*(AE10+AF10) -> 0 | AH10: =+AE10+AF10+AG10 -> 931994.01 | AI10: 14000 | AJ10: =+((20000/(26194827+596000-60000-258500-9000-153468))*(AH10+AI10)) -> 719.11751 | AK10: =+AH10+AI10+AJ10 -> 946713.13 | AL10: 14000 | AM10: =+(0/(23068716+171000))*(AK10+AL10) -> 0 | AN10: =+AK10+AL10+AM10 -> 960713.13 | AO10: 14000 | AP10: =+(0/20000)*(AN10+AO10) -> 0 | AQ10: =+AN10+AO10+AP10 -> 974713.13 | AR10: =+C10 -> 600000 | AS10: =+D10 -> 10718.85 | AT10: =+H10+K10+N10+Q10+T10+W10+Z10+AC10+AF10+AI10+AL10+AO10 -> 308800 | AU10: =+F10+I10+L10+O10+R10+U10+X10+AA10+AD10+AG10+AJ10+AM10+AP10 -> 55194.277 | AV10: =+AN10+AO10+AP10 -> 974713.13 | AW10: 630000 | BB10: =+AV10-AW10-AX10-AY10-AZ10-BA10 -> 344713.13 | BD10: =+BB10 -> 344713.13 | BE10: 0 | BF10: =+BD10-BE10 -> 344713.13
A11: AS201651 | B11: DOMOU FABIEN | C11: 600000 | D11: 584.046 | E11: =+C11+D11 -> 600584.05 | F11: =+(1268000/19961560)*E11 -> 38150.353 | G11: =+E11+F11 -> 638734.4 | H11: 9000 | I11: =+(0/(21229560+1050000))*(G11+H11) -> 0 | J11: =+G11+H11+I11 -> 647734.4 | K11: 9000 | L11: =+(30000/((21638859-36000)+(328000-36000))*(J11+K11)) -> 899.8474 | M11: =+J11+K11+L11 -> 657634.25 | N11: 9000 | O11: =+(6000/(21996859-72000+345000-18000-19000-44000))*(M11+N11) -> 180.26188 | P11: =+M11+N11+O11 -> 666814.51 | Q11: 9000 | R11: =+(204000/(22347859-54000-37000-62000+386000-18000-19000-66000))*(P11+Q11) -> 6133.4204 | S11: =+P11+Q11+R11 -> 681947.93 | T11: 9000 | U11: =+((30000/(22937859+882000-36000-36000-56000-128000-6000-9000-409000-69000))*(S11+T11)) -> 898.4684 | V11: =+S11+T11+U11 -> 691846.4 | W11: 9000 | X11: =+(74200/(23849859+426500-42000-45000-465000-197000-9000-9000-14000-69000))*(V11+W11) -> 2219.8414 | Y11: =+V11+W11+X11 -> 703066.24 | Z11: 9000 | AA11: =+(50000/(24350559+561768-51000-54000-479000-266000-9000-9000-19000-69000-153468))*(Y11+Z11) -> 1495.7578 | AB11: =+Y11+Z11+AA11 -> 713562 | AC11: 9000 | AD11: =+(64000/(24962327+403000-60000-63000-498000-335000-153468-9000-9000-19000-69000))*(AB11+AC11) -> 1914.8753 | AE11: =+AB11+AC11+AD11 -> 724476.87 | AF11: 9000 | AG11: =+(0/20256265)*(AE11+AF11) -> 0 | AH11: =+AE11+AF11+AG11 -> 733476.87 | AI11: 9000 | AJ11: =+((20000/(26194827+596000-60000-258500-9000-153468))*(AH11+AI11)) -> 564.40962 | AK11: =+AH11+AI11+AJ11 -> 743041.28 | AL11: 9000 | AM11: =+(0/(23068716+171000))*(AK11+AL11) -> 0 | AN11: =+AK11+AL11+AM11 -> 752041.28 | AO11: 9000 | AP11: =+(0/20000)*(AN11+AO11) -> 0 | AQ11: =+AN11+AO11+AP11 -> 761041.28 | AR11: =+C11 -> 600000 | AS11: =+D11 -> 584.046 | AT11: =+H11+K11+N11+Q11+T11+W11+Z11+AC11+AF11+AI11+AL11+AO11 -> 108000 | AU11: =+F11+I11+L11+O11+R11+U11+X11+AA11+AD11+AG11+AJ11+AM11+AP11 -> 52457.236 | AV11: =+AN11+AO11+AP11 -> 761041.28 | AW11: 630000 | BB11: =+AV11-AW11-AX11-AY11-AZ11-BA11 -> 131041.28 | BD11: =+BB11 -> 131041.28 | BE11: 0 | BF11: =+BD11-BE11 -> 131041.28
A12: AS201609 | B12: DONHOU DAVID | C12: 600000 | D12: 458343.18 | E12: =+C12+D12 -> 1058343.2 | F12: =+(1268000/19961560)*E12 -> 67228.17 | G12: =+E12+F12 -> 1125571.3 | H12: 9000 | I12: =+(0/(21229560+1050000))*(G12+H12) -> 0 | J12: =+G12+H12+I12 -> 1134571.3 | K12: 9000 | L12: =+(30000/((21638859-36000)+(328000-36000))*(J12+K12)) -> 1566.9039 | M12: =+J12+K12+L12 -> 1145138.3 | N12: 9000 | O12: =+(6000/(21996859-72000+345000-18000-19000-44000))*(M12+N12) -> 312.08588 | P12: =+M12+N12+O12 -> 1154450.3 | Q12: 9000 | R12: =+(204000/(22347859-54000-37000-62000+386000-18000-19000-66000))*(P12+Q12) -> 10559.007 | S12: =+P12+Q12+R12 -> 1174009.3 | T12: 9000 | U12: =+((30000/(22937859+882000-36000-36000-56000-128000-6000-9000-409000-69000))*(S12+T12)) -> 1538.3164 | V12: =+S12+T12+U12 -> 1184547.7 | W12: 9000 | X12: =+(74200/(23849859+426500-42000-45000-465000-197000-9000-9000-14000-69000))*(V12+W12) -> 3780.4098 | Y12: =+V12+W12+X12 -> 1197328.1 | Z12: 9000 | AA12: =+(50000/(24350559+561768-51000-54000-479000-266000-9000-9000-19000-69000-153468))*(Y12+Z12) -> 2533.9983 | AB12: =+Y12+Z12+AA12 -> 1208862.1 | AC12: 9000 | AD12: =+(64000/(24962327+403000-60000-63000-498000-335000-153468-9000-9000-19000-69000))*(AB12+AC12) -> 3227.4794 | AE12: =+AB12+AC12+AD12 -> 1221089.5 | AF12: 9000 | AG12: =+(0/20256265)*(AE12+AF12) -> 0 | AH12: =+AE12+AF12+AG12 -> 1230089.5 | AI12: 9000 | AJ12: =+((20000/(26194827+596000-60000-258500-9000-153468))*(AH12+AI12)) -> 941.92033 | AK12: =+AH12+AI12+AJ12 -> 1240031.5 | AL12: 9000 | AM12: =+(0/(23068716+171000))*(AK12+AL12) -> 0 | AN12: =+AK12+AL12+AM12 -> 1249031.5 | AO12: 9000 | AP12: =+(0/20000)*(AN12+AO12) -> 0 | AQ12: =+AN12+AO12+AP12 -> 1258031.5 | AR12: =+C12 -> 600000 | AS12: =+D12 -> 458343.18 | AT12: =+H12+K12+N12+Q12+T12+W12+Z12+AC12+AF12+AI12+AL12+AO12 -> 108000 | AU12: =+F12+I12+L12+O12+R12+U12+X12+AA12+AD12+AG12+AJ12+AM12+AP12 -> 91688.291 | AV12: =+AN12+AO12+AP12 -> 1258031.5 | AW12: 630000 | BB12: =+AV12-AW12-AX12-AY12-AZ12-BA12 -> 628031.47 | BD12: =+BB12 -> 628031.47 | BE12: 0 | BF12: =+BD12-BE12 -> 628031.47
A13: AS201611 | B13: HENGUE PAUL OMER | C13: 600000 | D13: 51112.01 | E13: =+C13+D13 -> 651112.01 | F13: =+(1268000/19961560)*E13 -> 41359.995 | G13: =+E13+F13 -> 692472.01 | H13: 9000 | I13: =+(0/(21229560+1050000))*(G13+H13) -> 0 | J13: =+G13+H13+I13 -> 701472.01 | K13: 9000 | L13: =+(30000/((21638859-36000)+(328000-36000))*(J13+K13)) -> 973.47785 | M13: =+J13+K13+L13 -> 711445.48 | N13: 9000 | O13: =+(6000/(21996859-72000+345000-18000-19000-44000))*(M13+N13) -> 194.81276 | P13: =+M13+N13+O13 -> 720640.3 | Q13: 9000 | R13: =+(204000/(22347859-54000-37000-62000+386000-18000-19000-66000))*(P13+Q13) -> 6621.9216 | S13: =+P13+Q13+R13 -> 736262.22 | T13: 9000 | U13: =+((30000/(22937859+882000-36000-36000-56000-128000-6000-9000-409000-69000))*(S13+T13)) -> 969.09554 | V13: =+S13+T13+U13 -> 746231.31 | W13: 9000 | X13: =+(74200/(23849859+426500-42000-45000-465000-197000-9000-9000-14000-69000))*(V13+W13) -> 2392.0987 | Y13: =+V13+W13+X13 -> 757623.41 | Z13: 9000 | AA13: =+(50000/(24350559+561768-51000-54000-479000-266000-9000-9000-19000-69000-153468))*(Y13+Z13) -> 1610.3599 | AB13: =+Y13+Z13+AA13 -> 768233.77 | AC13: 9000 | AD13: =+(64000/(24962327+403000-60000-63000-498000-335000-153468-9000-9000-19000-69000))*(AB13+AC13) -> 2059.762 | AE13: =+AB13+AC13+AD13 -> 779293.53 | AF13: 9000 | AG13: =+(0/20256265)*(AE13+AF13) -> 0 | AH13: =+AE13+AF13+AG13 -> 788293.53 | AI13: 9000 | AJ13: =+((20000/(26194827+596000-60000-258500-9000-153468))*(AH13+AI13)) -> 606.07967 | AK13: =+AH13+AI13+AJ13 -> 797899.61 | AL13: 9000 | AM13: =+(0/(23068716+171000))*(AK13+AL13) -> 0 | AN13: =+AK13+AL13+AM13 -> 806899.61 | AO13: 9000 | AP13: =+(0/20000)*(AN13+AO13) -> 0 | AQ13: =+AN13+AO13+AP13 -> 815899.61 | AR13: =+C13 -> 600000 | AS13: =+D13 -> 51112.01 | AT13: =+H13+K13+N13+Q13+T13+W13+Z13+AC13+AF13+AI13+AL13+AO13 -> 108000 | AU13: =+F13+I13+L13+O13+R13+U13+X13+AA13+AD13+AG13+AJ13+AM13+AP13 -> 56787.603 | AV13: =+AN13+AO13+AP13 -> 815899.61 | AW13: 630000 | BB13: =+AV13-AW13-AX13-AY13-AZ13-BA13 -> 185899.61 | BD13: =+BB13 -> 185899.61 | BE13: 0 | BF13: =+BD13-BE13 -> 185899.61
A14: AS201613 | B14: HOTCHO BENJAMIN | C14: 600000 | D14: 16229.566 | E14: =+C14+D14 -> 616229.57 | F14: =+(1268000/19961560)*E14 -> 39144.19 | G14: =+E14+F14 -> 655373.76 | H14: 44000 | I14: =+(0/(21229560+1050000))*(G14+H14) -> 0 | J14: =+G14+H14+I14 -> 699373.76 | K14: 44000 | L14: =+(30000/((21638859-36000)+(328000-36000))*(J14+K14)) -> 1018.5593 | M14: =+J14+K14+L14 -> 744392.32 | N14: 44000 | O14: =+(6000/(21996859-72000+345000-18000-19000-44000))*(M14+N14) -> 213.18599 | P14: =+M14+N14+O14 -> 788605.5 | Q14: 44000 | R14: =+(204000/(22347859-54000-37000-62000+386000-18000-19000-66000))*(P14+Q14) -> 7556.3924 | S14: =+P14+Q14+R14 -> 840161.89 | T14: 24000 | U14: =+((30000/(22937859+882000-36000-36000-56000-128000-6000-9000-409000-69000))*(S14+T14)) -> 1123.7057 | V14: =+S14+T14+U14 -> 865285.6 | W14: 44000 | X14: =+(74200/(23849859+426500-42000-45000-465000-197000-9000-9000-14000-69000))*(V14+W14) -> 2880.046 | Y14: =+V14+W14+X14 -> 912165.65 | Z14: 44000 | AA14: =+(50000/(24350559+561768-51000-54000-479000-266000-9000-9000-19000-69000-153468))*(Y14+Z14) -> 2008.5101 | AB14: =+Y14+Z14+AA14 -> 958174.16 | AC14: 44000 | AD14: =+(64000/(24962327+403000-60000-63000-498000-335000-153468-9000-9000-19000-69000))*(AB14+AC14) -> 2655.8808 | AE14: =+AB14+AC14+AD14 -> 1004830 | AF14: 44000 | AG14: =+(0/20256265)*(AE14+AF14) -> 0 | AH14: =+AE14+AF14+AG14 -> 1048830 | AI14: 44000 | AJ14: =+((20000/(26194827+596000-60000-258500-9000-153468))*(AH14+AI14)) -> 830.73804 | AK14: =+AH14+AI14+AJ14 -> 1093660.8 | AL14: 44000 | AM14: =+(0/(23068716+171000))*(AK14+AL14) -> 0 | AN14: =+AK14+AL14+AM14 -> 1137660.8 | AO14: 44000 | AP14: =+(0/20000)*(AN14+AO14) -> 0 | AQ14: =+AN14+AO14+AP14 -> 1181660.8 | AR14: =+C14 -> 600000 | AS14: =+D14 -> 16229.566 | AT14: =+H14+K14+N14+Q14+T14+W14+Z14+AC14+AF14+AI14+AL14+AO14 -> 508000 | AU14: =+F14+I14+L14+O14+R14+U14+X14+AA14+AD14+AG14+AJ14+AM14+AP14 -> 57431.208 | AV14: =+AN14+AO14+AP14 -> 1181660.8 | AW14: 630000 | BB14: =+AV14-AW14-AX14-AY14-AZ14-BA14 -> 551660.77 | BD14: =+BB14 -> 551660.77 | BE14: 0 | BF14: =+BD14-BE14 -> 551660.77
A15: AS201617 | B15: KOUAMOU MOISE | C15: 600000 | D15: 53292.832 | E15: =+C15+D15 -> 653292.83 | F15: =+(1268000/19961560)*E15 -> 41498.526 | G15: =+E15+F15 -> 694791.36 | H15: 9000 | I15: =+(0/(21229560+1050000))*(G15+H15) -> 0 | J15: =+G15+H15+I15 -> 703791.36 | K15: 9000 | L15: =+(30000/((21638859-36000)+(328000-36000))*(J15+K15)) -> 976.65579 | M15: =+J15+K15+L15 -> 713768.01 | N15: 9000 | O15: =+(6000/(21996859-72000+345000-18000-19000-44000))*(M15+N15) -> 195.44079 | P15: =+M15+N15+O15 -> 722963.45 | Q15: 9000 | R15: =+(204000/(22347859-54000-37000-62000+386000-18000-19000-66000))*(P15+Q15) -> 6643.0057 | S15: =+P15+Q15+R15 -> 738606.46 | T15: 9000 | U15: =+((30000/(22937859+882000-36000-36000-56000-128000-6000-9000-409000-69000))*(S15+T15)) -> 972.14385 | V15: =+S15+T15+U15 -> 748578.6 | W15: 9000 | X15: =+(74200/(23849859+426500-42000-45000-465000-197000-9000-9000-14000-69000))*(V15+W15) -> 2399.5335 | Y15: =+V15+W15+X15 -> 759978.14 | Z15: 9000 | AA15: =+(50000/(24350559+561768-51000-54000-479000-266000-9000-9000-19000-69000-153468))*(Y15+Z15) -> 1615.3062 | AB15: =+Y15+Z15+AA15 -> 770593.44 | AC15: 9000 | AD15: =+(64000/(24962327+403000-60000-63000-498000-335000-153468-9000-9000-19000-69000))*(AB15+AC15) -> 2066.0154 | AE15: =+AB15+AC15+AD15 -> 781659.46 | AF15: 9000 | AG15: =+(0/20256265)*(AE15+AF15) -> 0 | AH15: =+AE15+AF15+AG15 -> 790659.46 | AI15: 9000 | AJ15: =+((20000/(26194827+596000-60000-258500-9000-153468))*(AH15+AI15)) -> 607.87818 | AK15: =+AH15+AI15+AJ15 -> 800267.34 | AL15: 9000 | AM15: =+(0/(23068716+171000))*(AK15+AL15) -> 0 | AN15: =+AK15+AL15+AM15 -> 809267.34 | AO15: 9000 | AP15: =+(0/20000)*(AN15+AO15) -> 0 | AQ15: =+AN15+AO15+AP15 -> 818267.34 | AR15: =+C15 -> 600000 | AS15: =+D15 -> 53292.832 | AT15: =+H15+K15+N15+Q15+T15+W15+Z15+AC15+AF15+AI15+AL15+AO15 -> 108000 | AU15: =+F15+I15+L15+O15+R15+U15+X15+AA15+AD15+AG15+AJ15+AM15+AP15 -> 56974.505 | AV15: =+AN15+AO15+AP15 -> 818267.34 | AW15: 630000 | BB15: =+AV15-AW15-AX15-AY15-AZ15-BA15 -> 188267.34 | BD15: =+BB15 -> 188267.34 | BE15: 0 | BF15: =+BD15-BE15 -> 188267.34
A16: AS201619 | B16: KOUATCHO MESSACK | C16: 600000 | D16: 6459.0432 | E16: =+C16+D16 -> 606459.04 | F16: =+(1268000/19961560)*E16 -> 38523.546 | G16: =+E16+F16 -> 644982.59 | H16: 9000 | I16: =+(0/(21229560+1050000))*(G16+H16) -> 0 | J16: =+G16+H16+I16 -> 653982.59 | K16: 9000 | L16: =+(30000/((21638859-36000)+(328000-36000))*(J16+K16)) -> 908.40858 | M16: =+J16+K16+L16 -> 663891 | N16: 8000 | O16: =+(6000/(21996859-72000+345000-18000-19000-44000))*(M16+N16) -> 181.68334 | P16: =+M16+N16+O16 -> 672072.68 | Q16: 11000 | R16: =+(204000/(22347859-54000-37000-62000+386000-18000-19000-66000))*(P16+Q16) -> 6199.2927 | S16: =+P16+Q16+R16 -> 689271.97 | T16: 8000 | U16: =+((30000/(22937859+882000-36000-36000-56000-128000-6000-9000-409000-69000))*(S16+T16)) -> 906.69182 | V16: =+S16+T16+U16 -> 698178.67 | W16: 9000 | X16: =+(74200/(23849859+426500-42000-45000-465000-197000-9000-9000-14000-69000))*(V16+W16) -> 2239.8981 | Y16: =+V16+W16+X16 -> 709418.56 | Z16: 9000 | AA16: =+(50000/(24350559+561768-51000-54000-479000-266000-9000-9000-19000-69000-153468))*(Y16+Z16) -> 1509.1014 | AB16: =+Y16+Z16+AA16 -> 719927.66 | AC16: 9000 | AD16: =+(64000/(24962327+403000-60000-63000-498000-335000-153468-9000-9000-19000-69000))*(AB16+AC16) -> 1931.745 | AE16: =+AB16+AC16+AD16 -> 730859.41 | AF16: 9000 | AG16: =+(0/20256265)*(AE16+AF16) -> 0 | AH16: =+AE16+AF16+AG16 -> 739859.41 | AI16: 9000 | AJ16: =+((20000/(26194827+596000-60000-258500-9000-153468))*(AH16+AI16)) -> 569.26144 | AK16: =+AH16+AI16+AJ16 -> 749428.67 | AL16: 9000 | AM16: =+(0/(23068716+171000))*(AK16+AL16) -> 0 | AN16: =+AK16+AL16+AM16 -> 758428.67 | AO16: 9000 | AP16: =+(0/20000)*(AN16+AO16) -> 0 | AQ16: =+AN16+AO16+AP16 -> 767428.67 | AR16: =+C16 -> 600000 | AS16: =+D16 -> 6459.0432 | AT16: =+H16+K16+N16+Q16+T16+W16+Z16+AC16+AF16+AI16+AL16+AO16 -> 108000 | AU16: =+F16+I16+L16+O16+R16+U16+X16+AA16+AD16+AG16+AJ16+AM16+AP16 -> 52969.628 | AV16: =+AN16+AO16+AP16 -> 767428.67 | AW16: 630000 | BB16: =+AV16-AW16-AX16-AY16-AZ16-BA16 -> 137428.67 | BD16: =+BB16 -> 137428.67 | BE16: 0 | BF16: =+BD16-BE16 -> 137428.67
A17: AS201620 | B17: LOWE JEAN | C17: 600000 | D17: 746.1759 | E17: =+C17+D17 -> 600746.18 | F17: =+(1268000/19961560)*E17 -> 38160.652 | G17: =+E17+F17 -> 638906.83 | H17: 9000 | I17: =+(0/(21229560+1050000))*(G17+H17) -> 0 | J17: =+G17+H17+I17 -> 647906.83 | K17: 9000 | L17: =+(30000/((21638859-36000)+(328000-36000))*(J17+K17)) -> 900.08366 | M17: =+J17+K17+L17 -> 657806.91 | N17: 9000 | O17: =+(6000/(21996859-72000+345000-18000-19000-44000))*(M17+N17) -> 180.30857 | P17: =+M17+N17+O17 -> 666987.22 | Q17: 9000 | R17: =+(204000/(22347859-54000-37000-62000+386000-18000-19000-66000))*(P17+Q17) -> 6134.9879 | S17: =+P17+Q17+R17 -> 682122.21 | T17: 9000 | U17: =+((30000/(22937859+882000-36000-36000-56000-128000-6000-9000-409000-69000))*(S17+T17)) -> 898.69503 | V17: =+S17+T17+U17 -> 692020.9 | W17: 9000 | X17: =+(74200/(23849859+426500-42000-45000-465000-197000-9000-9000-14000-69000))*(V17+W17) -> 2220.3942 | Y17: =+V17+W17+X17 -> 703241.3 | Z17: 9000 | AA17: =+(50000/(24350559+561768-51000-54000-479000-266000-9000-9000-19000-69000-153468))*(Y17+Z17) -> 1496.1255 | AB17: =+Y17+Z17+AA17 -> 713737.42 | AC17: 9000 | AD17: =+(64000/(24962327+403000-60000-63000-498000-335000-153468-9000-9000-19000-69000))*(AB17+AC17) -> 1915.3402 | AE17: =+AB17+AC17+AD17 -> 724652.76 | AF17: 9000 | AG17: =+(0/20256265)*(AE17+AF17) -> 0 | AH17: =+AE17+AF17+AG17 -> 733652.76 | AI17: 9000 | AJ17: =+((20000/(26194827+596000-60000-258500-9000-153468))*(AH17+AI17)) -> 564.54332 | AK17: =+AH17+AI17+AJ17 -> 743217.31 | AL17: 9000 | AM17: =+(0/(23068716+171000))*(AK17+AL17) -> 0 | AN17: =+AK17+AL17+AM17 -> 752217.31 | AO17: 9000 | AP17: =+(0/20000)*(AN17+AO17) -> 0 | AQ17: =+AN17+AO17+AP17 -> 761217.31 | AR17: =+C17 -> 600000 | AS17: =+D17 -> 746.1759 | AT17: =+H17+K17+N17+Q17+T17+W17+Z17+AC17+AF17+AI17+AL17+AO17 -> 108000 | AU17: =+F17+I17+L17+O17+R17+U17+X17+AA17+AD17+AG17+AJ17+AM17+AP17 -> 52471.131 | AV17: =+AN17+AO17+AP17 -> 761217.31 | AW17: 630000 | BB17: =+AV17-AW17-AX17-AY17-AZ17-BA17 -> 131217.31 | BD17: =+BB17 -> 131217.31 | BE17: 0 | BF17: =+BD17-BE17 -> 131217.31
