Workbook
Name BANQUE: #REF!
Name BANQUE: #REF!
Name BANQUE: #REF!
Name BANQUE: #REF!
Name MODEPAID: [1]Feuil2!$A$1:$A$3
Name MODEVERSEMENT: #REF!
Name MODEVERSEMENT: #REF!
Name MODEVERSEMENT: #REF!
Name MODEVERSEMENT: #REF!
Name MODEVERSEMENTS: MODEVERSEMENT!$A$1:$A$3
Name MODPAID: TONTAOUT!#REF!
Name MODPAID: TONTSEPT!#REF!

Sheet MODEVERSEMENT
A1: BANQUE
A2: ESPECES
A3: ECHEC

Sheet TONTAOUT
A1: ASSOCIATION | B1: ASELBY
A2: ANNEE | B2: 2016/2017
A3: TONTINE | B3: 25 000
A4: MATRICULE | B4: NOM ET PRENOM | C4: RESTE | D4: EPARGNE CUMULE | E4: MONTANT TONTINE | F4: PENALITE | G4: MODE VERSEMENT | H4: MONTANT VERSE | I4: PRÊT LOT | J4: INTERET PRÊT LOT | K4: REMBOURSEMENT LOT | L4: MODE VERSEMENT REMBOURSEMENT | M4: MODE VERSEMENT TONTINE | N4: MONTANT TONTINE BENEFICIE | O4: INTERET ACHAT | P4: DATE ACHAT | Q4: AVALISTE
A5: AS201601 | B5: =VLOOKUP(A5,[2]LISTADHERENT!A$5:H$52,2,0) -> BAKOP ACHILLE | C5: =IF(H5=0,0,H5-E5) -> 70000 | E5: =IF(G5="ECHEC",0,18000) -> 18000 | F5: 9500 | G5: ESPECES | H5: =30000+5000+10000+25000+18000 -> 88000 | L5: ECHEC | M5: ECHEC | N5: =IF(O5=0,0,($F$74-O5)) -> 0
A6: AS201602 | B6: =VLOOKUP(A6,[2]LISTADHERENT!A$5:H$51,2) -> BOUTCHOUANG WILLIAM | C6: =IF(H6=0,0,H6-E6) -> 7000 | E6: =IF(G6="ECHEC",0,18000) -> 18000 | F6: =IF(G6="ESPECES",1000,0) -> 1000 | G6: ESPECES | H6: 25000 | L6: ECHEC | M6: ECHEC | N6: =IF(O6=0,0,($F$74-O6)) -> 0
A7: AS201603 | B7: =VLOOKUP(A7,[2]LISTADHERENT!A$5:H$51,2) -> CHINGUE FABRICE | C7: =IF(H7=0,0,H7-E7) -> 7000 | E7: =IF(G7="ECHEC",0,18000) -> 18000 | F7: =IF(G7="ESPECES",1000,0) -> 1000 | G7: ESPECES | H7: 25000 | L7: ECHEC | M7: ECHEC | N7: =IF(O7=0,0,($F$74-O7)) -> 0
A8: AS201604 | B8: =VLOOKUP(A8,[2]LISTADHERENT!A$5:H$51,2) -> DJOMO JEAN PAUL | C8: =IF(H8=0,0,H8-E8) -> 7000 | E8: =IF(G8="ECHEC",0,18000) -> 18000 | F8: =IF(G8="ESPECES",1000,0) -> 0 | G8: BANQUE | H8: 25000 | L8: ECHEC | M8: ECHEC | N8: =IF(O8=0,0,($F$74-O8)) -> 0
A9: AS201605 | B9: =VLOOKUP(A9,[2]LISTADHERENT!A$5:H$51,2) -> DJOUKWE NANGUEN GUY BLAISE | C9: =IF(H9=0,0,H9-E9) -> 7000 | E9: =IF(G9="ECHEC",0,18000) -> 18000 | F9: =IF(G9="ESPECES",1000,0) -> 1000 | G9: ESPECES | H9: 25000 | L9: ECHEC | M9: ECHEC | N9: =IF(O9=0,0,($F$74-O9)) -> 0
A10: AS201607 | B10: =VLOOKUP(A10,[2]LISTADHERENT!A$5:H$51,2) -> DJOUNKEP SAMUEL | C10: =IF(H10=0,0,H10-E10) -> 7000 | E10: =IF(G10="ECHEC",0,18000) -> 18000 | F10: =IF(G10="ESPECES",1000,0) -> 0 | G10: BANQUE | H10: 25000 | L10: ECHEC | M10: ECHEC | N10: =IF(O10=0,0,($F$74-O10)) -> 0
A11: AS201608 | B11: =VLOOKUP(A11,[2]LISTADHERENT!A$5:H$51,2) -> DJUOMBESSY ANTOINE | C11: =IF(H11=0,0,H11-E11) -> 7000 | E11: =IF(G11="ECHEC",0,18000) -> 18000 | F11: =IF(G11="ESPECES",1000,0) -> 0 | G11: BANQUE | H11: 25000 | L11: ECHEC | M11: ECHEC | N11: =IF(O11=0,0,($F$74-O11)) -> 0
A12: AS201609 | B12: =VLOOKUP(A12,[2]LISTADHERENT!A$5:H$51,2) -> DONHOU DAVID | C12: =IF(H12=0,0,H12-E12) -> 7000 | E12: =IF(G12="ECHEC",0,18000) -> 18000 | F12: =IF(G12="ESPECES",1000,0) -> 1000 | G12: ESPECES | H12: 25000 | L12: ECHEC | M12: ECHEC | N12: =IF(O12=0,0,($F$74-O12)) -> 0
A13: AS201610 | B13: =VLOOKUP(A13,[2]LISTADHERENT!A$5:H$51,2) -> FOTSO THOMAS | C13: =IF(H13=0,0,H13-E13) -> 7000 | E13: =IF(G13="ECHEC",0,18000) -> 18000 | F13: =IF(G13="ESPECES",1000,0) -> 1000 | G13: ESPECES | H13: 25000 | L13: ECHEC | M13: ECHEC | N13: =IF(O13=0,0,($F$74-O13)) -> 0
A14: AS201611 | B14: =VLOOKUP(A14,[2]LISTADHERENT!A$5:H$51,2) -> HENGUE PAUL OMER | C14: =IF(H14=0,0,H14-E14) -> 7000 | E14: =IF(G14="ECHEC",0,18000) -> 18000 | F14: =IF(G14="ESPECES",1000,0) -> 0 | G14: BANQUE | H14: 25000 | L14: ECHEC | M14: ECHEC | N14: =IF(O14=0,0,($F$74-O14)) -> 0
A15: AS201612 | B15: =VLOOKUP(A15,[2]LISTADHERENT!A$5:H$51,2) -> HODIEP JULES | C15: =IF(H15=0,0,H15-E15) -> 0 | E15: =IF(G15="ECHEC",0,18000) -> 0 | F15: =IF(G15="ESPECES",1000,0) -> 0 | G15: ECHEC | L15: ECHEC | M15: ECHEC | N15: =IF(O15=0,0,($F$74-O15)) -> 0
A16: AS201613 | B16: =VLOOKUP(A16,[2]LISTADHERENT!A$5:H$51,2) -> HOTCHO BENJAMIN | C16: =IF(H16=0,0,H16-E16) -> 7000 | E16: =IF(G16="ECHEC",0,18000) -> 18000 | F16: =IF(G16="ESPECES",1000,0) -> 0 | G16: BANQUE | H16: 25000 | L16: ECHEC | M16: ECHEC | N16: =IF(O16=0,0,($F$74-O16)) -> 0
A17: AS201614 | B17: =VLOOKUP(A17,[2]LISTADHERENT!A$5:H$51,2) -> KEPHE DAVID | C17: =IF(H17=0,0,H17-E17) -> 0 | E17: =IF(G17="ECHEC",0,18000) -> 0 | F17: =IF(G17="ESPECES",1000,0) -> 0 | G17: ECHEC | L17: ECHEC | M17: ECHEC | N17: =IF(O17=0,0,($F$74-O17)) -> 0
A18: AS201615 | B18: =VLOOKUP(A18,[2]LISTADHERENT!A$5:H$51,2) -> KEPSEU FRANCIS | C18: =IF(H18=0,0,H18-E18) -> 10000 | E18: =IF(G18="ECHEC",0,18000) -> 18000 | F18: =IF(G18="ESPECES",1000,0) -> 0 | G18: BANQUE | H18: 28000 | L18: ECHEC | M18: ECHEC | N18: =IF(O18=0,0,($F$74-O18)) -> 0
A19: AS201616 | B19: =VLOOKUP(A19,[2]LISTADHERENT!A$5:H$51,2) -> KOUAMOU EMMANUEL | C19: =IF(H19=0,0,H19-E19) -> 7000 | E19: =IF(G19="ECHEC",0,18000) -> 18000 | F19: =IF(G19="ESPECES",1000,0) -> 1000 | G19: ESPECES | H19: 25000 | L19: ECHEC | M19: ECHEC | N19: =IF(O19=0,0,($F$74-O19)) -> 0
A20: AS201617 | B20: =VLOOKUP(A20,[2]LISTADHERENT!A$5:H$51,2) -> KOUAMOU MOISE | C20: =IF(H20=0,0,H20-E20) -> 7000 | E20: =IF(G20="ECHEC",0,18000) -> 18000 | F20: =IF(G20="ESPECES",1000,0) -> 0 | G20: BANQUE | H20: 25000 | L20: ECHEC | M20: ECHEC | N20: =IF(O20=0,0,($F$74-O20)) -> 0
A21: AS201618 | B21: =VLOOKUP(A21,[2]LISTADHERENT!A$5:H$51,2) -> KOUAMO VICTOR PEGUY | C21: =IF(H21=0,0,H21-E21) -> 7000 | E21: =IF(G21="ECHEC",0,18000) -> 18000 | F21: =IF(G21="ESPECES",1000,0) -> 1000 | G21: ESPECES | H21: 25000 | I21: 31000 | J21: 1000 | L21: ESPECES | M21: BANQUE | N21: =IF(O21=0,0,($F$74-O21)) -> 171000 | O21: 51000 | P21: 42967 | Q21: DJOMO JEAN PAUL
A22: AS201619 | B22: =VLOOKUP(A22,[2]LISTADHERENT!A$5:H$51,2) -> KOUATCHO MESSACK | C22: =IF(H22=0,0,H22-E22) -> 7000 | E22: =IF(G22="ECHEC",0,18000) -> 18000 | F22: =IF(G22="ESPECES",1000,0) -> 1000 | G22: ESPECES | H22: 25000 | J22: 500 | L22: ECHEC | M22: ECHEC | N22: =IF(O22=0,0,($F$74-O22)) -> 0
A23: AS201620 | B23: =VLOOKUP(A23,[2]LISTADHERENT!A$5:H$51,2) -> LOWE JEAN | C23: =IF(H23=0,0,H23-E23) -> 7000 | E23: =IF(G23="ECHEC",0,18000) -> 18000 | F23: =IF(G23="ESPECES",1000,0) -> 1000 | G23: ESPECES | H23: 25000 | L23: ECHEC | M23: ECHEC | N23: =IF(O23=0,0,($F$74-O23)) -> 0
A24: AS201621 | B24: =VLOOKUP(A24,[2]LISTADHERENT!A$5:H$51,2) -> NANKAM APPOLINAIRE | C24: =IF(H24=0,0,H24-E24) -> 7000 | E24: =IF(G24="ECHEC",0,18000) -> 18000 | F24: =IF(G24="ESPECES",1000,0) -> 0 | G24: BANQUE | H24: 25000 | L24: ECHEC | M24: ECHEC | N24: =IF(O24=0,0,($F$74-O24)) -> 0
A25: AS201622 | B25: =VLOOKUP(A25,[2]LISTADHERENT!A$5:H$51,2) -> NDJOMO ETIENNE | C25: =IF(H25=0,0,H25-E25) -> 12000 | E25: =IF(G25="ECHEC",0,18000) -> 18000 | F25: =IF(G25="ESPECES",1000,0) -> 0 | G25: BANQUE | H25: 30000 | L25: ECHEC | M25: ECHEC | N25: =IF(O25=0,0,($F$74-O25)) -> 0
A26: AS201623 | B26: =VLOOKUP(A26,[2]LISTADHERENT!A$5:H$51,2) -> NDOMBOU JEAN CLAUDE | C26: =IF(H26=0,0,H26-E26) -> 7000 | E26: =IF(G26="ECHEC",0,18000) -> 18000 | F26: =IF(G26="ESPECES",1000,0) -> 0 | G26: BANQUE | H26: 25000 | L26: ECHEC | M26: ECHEC | N26: =IF(O26=0,0,($F$74-O26)) -> 0
A27: AS201624 | B27: =VLOOKUP(A27,[2]LISTADHERENT!A$5:H$51,2) -> NGONDIEP CLAUDE | C27: =IF(H27=0,0,H27-E27) -> 7000 | E27: =IF(G27="ECHEC",0,18000) -> 18000 | F27: =IF(G27="ESPECES",1000,0) -> 0 | G27: BANQUE | H27: 25000 | L27: ECHEC | M27: ECHEC | N27: =IF(O27=0,0,($F$74-O27)) -> 0
A28: AS201625 | B28: =VLOOKUP(A28,[2]LISTADHERENT!A$5:H$51,2) -> NGONGANG JEAN THEODORE | C28: =IF(H28=0,0,H28-E28) -> 0 | E28: =IF(G28="ECHEC",0,18000) -> 0 | F28: =IF(G28="ESPECES",1000,0) -> 0 | G28: ECHEC | L28: ECHEC | M28: ECHEC | N28: =IF(O28=0,0,($F$74-O28)) -> 0
A29: AS201626 | B29: =VLOOKUP(A29,[2]LISTADHERENT!A$5:H$51,2) -> NGUIEMEGNI MATHIEU BLAISE | C29: =IF(H29=0,0,H29-E29) -> 7000 | E29: =IF(G29="ECHEC",0,18000) -> 18000 | F29: =IF(G29="ESPECES",1000,0) -> 1000 | G29: ESPECES | H29: 25000 | L29: ECHEC | M29: ECHEC | N29: =IF(O29=0,0,($F$74-O29)) -> 0
A30: AS201627 | B30: =VLOOKUP(A30,[2]LISTADHERENT!A$5:H$51,2) -> NJEPDJIO MBOUKAM DELUXE | C30: =IF(H30=0,0,H30-E30) -> 7000 | E30: =IF(G30="ECHEC",0,18000) -> 18000 | F30: =IF(G30="ESPECES",1000,0) -> 1000 | G30: ESPECES | H30: 25000 | L30: ECHEC | M30: ECHEC | N30: =IF(O30=0,0,($F$74-O30)) -> 0
A31: AS201628 | B31: =VLOOKUP(A31,[2]LISTADHERENT!A$5:H$51,2) -> NKAMGANG JUSTIN DEJOLIE | C31: =IF(H31=0,0,H31-E31) -> 10000 | E31: =IF(G31="ECHEC",0,18000) -> 18000 | F31: =IF(G31="ESPECES",1000,0) -> 1000 | G31: ESPECES | H31: 28000 | L31: ECHEC | M31: BANQUE | N31: =IF(O31=0,0,($F$74-O31)) -> 172000 | O31: 50000 | P31: 42967 | Q31: DJOUKWE NANGUEN GUY BLAISE
A32: AS201629 | B32: =VLOOKUP(A32,[2]LISTADHERENT!A$5:H$51,2) -> NKEPSEU DIEUDONNE | C32: =IF(H32=0,0,H32-E32) -> 12000 | E32: =IF(G32="ECHEC",0,18000) -> 18000 | F32: =IF(G32="ESPECES",1000,0) -> 1000 | G32: ESPECES | H32: 30000 | L32: ECHEC | M32: ECHEC | N32: =IF(O32=0,0,($F$74-O32)) -> 0
A33: AS201631 | B33: =VLOOKUP(A33,[2]LISTADHERENT!A$5:H$51,2) -> NTEPDIE TUEMAC MZ | C33: =IF(H33=0,0,H33-E33) -> 0 | E33: =IF(G33="ECHEC",0,18000) -> 0 | F33: =IF(G33="ESPECES",1000,0) -> 0 | G33: ECHEC | L33: ECHEC | M33: ECHEC | N33: =IF(O33=0,0,($F$74-O33)) -> 0
A34: AS201633 | B34: =VLOOKUP(A34,[2]LISTADHERENT!A$5:H$51,2) -> PATEGO NJOSSU GUSTAVE | C34: =IF(H34=0,0,H34-E34) -> 7000 | E34: =IF(G34="ECHEC",0,18000) -> 18000 | F34: =IF(G34="ESPECES",1000,0) -> 0 | G34: BANQUE | H34: 25000 | L34: ECHEC | M34: ECHEC | N34: =IF(O34=0,0,($F$74-O34)) -> 0
A35: AS201634 | B35: =VLOOKUP(A35,[2]LISTADHERENT!A$5:H$51,2) -> SEUNOU RICHELOT | C35: =IF(H35=0,0,H35-E35) -> 7000 | E35: =IF(G35="ECHEC",0,18000) -> 18000 | F35: =IF(G35="ESPECES",1000,0) -> 1000 | G35: ESPECES | H35: 25000 | L35: ECHEC | M35: ECHEC | N35: =IF(O35=0,0,($F$74-O35)) -> 0
A36: AS201635 | B36: =VLOOKUP(A36,[2]LISTADHERENT!A$5:H$51,2) -> SIME ABEL | C36: =IF(H36=0,0,H36-E36) -> 7000 | E36: =IF(G36="ECHEC",0,18000) -> 18000 | F36: =IF(G36="ESPECES",1000,0) -> 1000 | G36: ESPECES | H36: 25000 | I36: 60000 | J36: 1000 | L36: ESPECES | M36: ECHEC | N36: =IF(O36=0,0,($F$74-O36)) -> 0
A37: AS201636 | B37: =VLOOKUP(A37,[2]LISTADHERENT!A$5:H$51,2) -> SIME FONGANG ERIC | C37: =IF(H37=0,0,H37-E37) -> 7000 | E37: =IF(G37="ECHEC",0,18000) -> 18000 | F37: =IF(G37="ESPECES",1000,0) -> 0 | G37: BANQUE | H37: 25000 | L37: ECHEC | M37: ECHEC | N37: =IF(O37=0,0,($F$74-O37)) -> 0
A38: AS201637 | B38: =VLOOKUP(A38,[2]LISTADHERENT!A$5:H$51,2) -> SIME MATHIEU | C38: =IF(H38=0,0,H38-E38) -> 7000 | E38: =IF(G38="ECHEC",0,18000) -> 18000 | F38: =IF(G38="ESPECES",1000,0) -> 0 | G38: BANQUE | H38: 25000 | L38: ECHEC | M38: ECHEC | N38: =IF(O38=0,0,($F$74-O38)) -> 0
A39: AS201638 | B39: =VLOOKUP(A39,[2]LISTADHERENT!A$5:H$51,2) -> SIME PIERRE | C39: =IF(H39=0,0,H39-E39) -> 12000 | E39: =IF(G39="ECHEC",0,18000) -> 18000 | F39: =IF(G39="ESPECES",1000,0) -> 0 | G39: BANQUE | H39: 30000 | L39: ECHEC | M39: ECHEC | N39: =IF(O39=0,0,($F$74-O39)) -> 0
A40: AS201639 | B40: =VLOOKUP(A40,[2]LISTADHERENT!A$5:H$51,2) -> TAGNE NANGUEN MARTIN | C40: =IF(H40=0,0,H40-E40) -> 7000 | E40: =IF(G40="ECHEC",0,18000) -> 18000 | F40: =IF(G40="ESPECES",1000,0) -> 0 | G40: BANQUE | H40: 25000 | L40: ECHEC | M40: ECHEC | N40: =IF(O40=0,0,($F$74-O40)) -> 0
...

Sheet TONTSEPT
A1: ASSOCIATION | B1: ASELBY
A2: ANNEE | B2: 2016/2017
A3: TONTINE | B3: 25 000
A4: MATRICULE | B4: NOM ET PRENOM | C4: RESTE | D4: EPARGNE CUMULE | E4: MONTANT TONTINE | F4: PENALITE VERSEMENT ESPECES | G4: MODE VERSEMENT | H4: MONTANT VERSE | I4: VENTE PETIT LOT | J4: INTERET PETIT LOT | K4: MODE VERSEMENT VENTE PETIT LOT | L4: REMBOURSEMENT PETIT LOT | M4: MODE VERSEMENT REMBOURSEMENT | N4: MODE VERSEMENTLOT PRINCIPAL | O4: MONTANT TONTINE LOT PRINCIPAL | P4: INTERET LOT PRINCIPAL | Q4: INTERET LOT PRINCIPAL CUMULE | R4: DATE VENTE | S4: AVALISTE
A5: AS201601 | B5: =VLOOKUP(A5,[2]LISTADHERENT!A$5:H$52,2,0) -> BAKOP ACHILLE | C5: =IF(H5=0,0,H5-E5) -> 0 | E5: =IF(G5="ECHEC",0,18000) -> 0 | F5: =IF(G5="ESPECES",1000,0) -> 0 | G5: ECHEC | K5: ECHEC | L5: =TONTAOUT!I5+TONTAOUT!J5 -> 0 | M5: ECHEC | N5: ECHEC | O5: =IF(P5=0,0,($F$80-P5)) -> 0
A6: AS201602 | B6: =VLOOKUP(A6,[2]LISTADHERENT!A$5:H$51,2) -> BOUTCHOUANG WILLIAM | C6: =IF(H6=0,0,H6-E6) -> 0 | E6: =IF(G6="ECHEC",0,18000) -> 0 | F6: =IF(G6="ESPECES",1000,0) -> 0 | G6: ECHEC | K6: ECHEC | L6: =TONTAOUT!I6+TONTAOUT!J6 -> 0 | M6: ECHEC | N6: ECHEC | O6: =IF(P6=0,0,($F$80-P6)) -> 0
A7: AS201603 | B7: =VLOOKUP(A7,[2]LISTADHERENT!A$5:H$51,2) -> CHINGUE FABRICE | C7: =IF(H7=0,0,H7-E7) -> 0 | E7: =IF(G7="ECHEC",0,18000) -> 0 | F7: =IF(G7="ESPECES",1000,0) -> 0 | G7: ECHEC | K7: ECHEC | L7: =TONTAOUT!I7+TONTAOUT!J7 -> 0 | M7: ECHEC | N7: ECHEC | O7: =IF(P7=0,0,($F$80-P7)) -> 0
A8: AS201604 | B8: =VLOOKUP(A8,[2]LISTADHERENT!A$5:H$51,2) -> DJOMO JEAN PAUL | C8: =IF(H8=0,0,H8-E8) -> 0 | E8: =IF(G8="ECHEC",0,18000) -> 0 | F8: =IF(G8="ESPECES",1000,0) -> 0 | G8: ECHEC | K8: ECHEC | L8: =TONTAOUT!I8+TONTAOUT!J8 -> 0 | M8: ECHEC | N8: ECHEC | O8: =IF(P8=0,0,($F$80-P8)) -> 0
A9: AS201605 | B9: =VLOOKUP(A9,[2]LISTADHERENT!A$5:H$51,2) -> DJOUKWE NANGUEN GUY BLAISE | C9: =IF(H9=0,0,H9-E9) -> 0 | E9: =IF(G9="ECHEC",0,18000) -> 0 | F9: =IF(G9="ESPECES",1000,0) -> 0 | G9: ECHEC | K9: ECHEC | L9: =TONTAOUT!I9+TONTAOUT!J9 -> 0 | M9: ECHEC | N9: ECHEC | O9: =IF(P9=0,0,($F$80-P9)) -> 0
A10: AS201607 | B10: =VLOOKUP(A10,[2]LISTADHERENT!A$5:H$51,2) -> DJOUNKEP SAMUEL | C10: =IF(H10=0,0,H10-E10) -> 0 | E10: =IF(G10="ECHEC",0,18000) -> 0 | F10: =IF(G10="ESPECES",1000,0) -> 0 | G10: ECHEC | K10: ECHEC | L10: =TONTAOUT!I10+TONTAOUT!J10 -> 0 | M10: ECHEC | N10: ECHEC | O10: =IF(P10=0,0,($F$80-P10)) -> 0
A11: AS201608 | B11: =VLOOKUP(A11,[2]LISTADHERENT!A$5:H$51,2) -> DJUOMBESSY ANTOINE | C11: =IF(H11=0,0,H11-E11) -> 0 | E11: =IF(G11="ECHEC",0,18000) -> 0 | F11: =IF(G11="ESPECES",1000,0) -> 0 | G11: ECHEC | K11: ECHEC | L11: =TONTAOUT!I11+TONTAOUT!J11 -> 0 | M11: ECHEC | N11: ECHEC | O11: =IF(P11=0,0,($F$80-P11)) -> 0
A12: AS201609 | B12: =VLOOKUP(A12,[2]LISTADHERENT!A$5:H$51,2) -> DONHOU DAVID | C12: =IF(H12=0,0,H12-E12) -> 0 | E12: =IF(G12="ECHEC",0,18000) -> 0 | F12: =IF(G12="ESPECES",1000,0) -> 0 | G12: ECHEC | K12: ECHEC | L12: =TONTAOUT!I12+TONTAOUT!J12 -> 0 | M12: ECHEC | N12: ECHEC | O12: =IF(P12=0,0,($F$80-P12)) -> 0
A13: AS201610 | B13: =VLOOKUP(A13,[2]LISTADHERENT!A$5:H$51,2) -> FOTSO THOMAS | C13: =IF(H13=0,0,H13-E13) -> 0 | E13: =IF(G13="ECHEC",0,18000) -> 0 | F13: =IF(G13="ESPECES",1000,0) -> 0 | G13: ECHEC | K13: ECHEC | L13: =TONTAOUT!I13+TONTAOUT!J13 -> 0 | M13: ECHEC | N13: ECHEC | O13: =IF(P13=0,0,($F$80-P13)) -> 0
A14: AS201611 | B14: =VLOOKUP(A14,[2]LISTADHERENT!A$5:H$51,2) -> HENGUE PAUL OMER | C14: =IF(H14=0,0,H14-E14) -> 0 | E14: =IF(G14="ECHEC",0,18000) -> 0 | F14: =IF(G14="ESPECES",1000,0) -> 0 | G14: ECHEC | K14: ECHEC | L14: =TONTAOUT!I14+TONTAOUT!J14 -> 0 | M14: ECHEC | N14: ECHEC | O14: =IF(P14=0,0,($F$80-P14)) -> 0
A15: AS201612 | B15: =VLOOKUP(A15,[2]LISTADHERENT!A$5:H$51,2) -> HODIEP JULES | C15: =IF(H15=0,0,H15-E15) -> 0 | E15: =IF(G15="ECHEC",0,18000) -> 0 | F15: =IF(G15="ESPECES",1000,0) -> 0 | G15: ECHEC | K15: ECHEC | L15: =TONTAOUT!I15+TONTAOUT!J15 -> 0 | M15: ECHEC | N15: ECHEC | O15: =IF(P15=0,0,($F$80-P15)) -> 0
A16: AS201613 | B16: =VLOOKUP(A16,[2]LISTADHERENT!A$5:H$51,2) -> HOTCHO BENJAMIN | C16: =IF(H16=0,0,H16-E16) -> 0 | E16: =IF(G16="ECHEC",0,18000) -> 0 | F16: =IF(G16="ESPECES",1000,0) -> 0 | G16: ECHEC | K16: ECHEC | L16: =TONTAOUT!I16+TONTAOUT!J16 -> 0 | M16: ECHEC | N16: ECHEC | O16: =IF(P16=0,0,($F$80-P16)) -> 0
A17: AS201614 | B17: =VLOOKUP(A17,[2]LISTADHERENT!A$5:H$51,2) -> KEPHE DAVID | C17: =IF(H17=0,0,H17-E17) -> 0 | E17: =IF(G17="ECHEC",0,18000) -> 0 | F17: =IF(G17="ESPECES",1000,0) -> 0 | G17: ECHEC | K17: ECHEC | L17: =TONTAOUT!I17+TONTAOUT!J17 -> 0 | M17: ECHEC | N17: ECHEC | O17: =IF(P17=0,0,($F$80-P17)) -> 0
... A20: AS201617 | B20: =VLOOKUP(A20,[2]LISTADHERENT!A$5:H$51,2) -> KOUAMOU MOISE | C20: =IF(H20=0,0,H20-E20) -> 0 | E20: =IF(G20="ECHEC",0,18000) -> 0 | F20: =IF(G20="ESPECES",1000,0) -> 0 | G20: ECHEC | K20: ECHEC | L20: =TONTAOUT!I20+TONTAOUT!J20 -> 0 | M20: ECHEC | N20: ECHEC | O20: =IF(P20=0,0,($F$80-P20)) -> 0
A21: AS201618 | B21: =VLOOKUP(A21,[2]LISTADHERENT!A$5:H$51,2) -> KOUAMO VICTOR PEGUY | C21: =IF(H21=0,0,H21-E21) -> 0 | E21: =IF(G21="ECHEC",0,18000) -> 0 | F21: =IF(G21="ESPECES",1000,0) -> 0 | G21: ECHEC | K21: ECHEC | L21: =TONTAOUT!I21+TONTAOUT!J21 -> 32000 | M21: ECHEC | N21: ECHEC | O21: =IF(P21=0,0,($F$80-P21)) -> 0 | Q21: 51000 | R21: 42967 | S21: DJOMO JEAN PAUL
A22: AS201619 | B22: =VLOOKUP(A22,[2]LISTADHERENT!A$5:H$51,2) -> KOUATCHO MESSACK | C22: =IF(H22=0,0,H22-E22) -> 0 | E22: =IF(G22="ECHEC",0,18000) -> 0 | F22: =IF(G22="ESPECES",1000,0) -> 0 | G22: ECHEC | K22: ECHEC | L22: =TONTAOUT!I22+TONTAOUT!J22 -> 500 | M22: ECHEC | N22: ECHEC | O22: =IF(P22=0,0,($F$80-P22)) -> 0
A23: AS201620 | B23: =VLOOKUP(A23,[2]LISTADHERENT!A$5:H$51,2) -> LOWE JEAN | C23: =IF(H23=0,0,H23-E23) -> 0 | E23: =IF(G23="ECHEC",0,18000) -> 0 | F23: =IF(G23="ESPECES",1000,0) -> 0 | G23: ECHEC | K23: ECHEC | L23: =TONTAOUT!I23+TONTAOUT!J23 -> 0 | M23: ECHEC | N23: ECHEC | O23: =IF(P23=0,0,($F$80-P23)) -> 0
A24: AS201621 | B24: =VLOOKUP(A24,[2]LISTADHERENT!A$5:H$51,2) -> NANKAM APPOLINAIRE | C24: =IF(H24=0,0,H24-E24) -> 0 | E24: =IF(G24="ECHEC",0,18000) -> 0 | F24: =IF(G24="ESPECES",1000,0) -> 0 | G24: ECHEC | K24: ECHEC | L24: =TONTAOUT!I24+TONTAOUT!J24 -> 0 | M24: ECHEC | N24: ECHEC | O24: =IF(P24=0,0,($F$80-P24)) -> 0
A25: AS201622 | B25: =VLOOKUP(A25,[2]LISTADHERENT!A$5:H$51,2) -> NDJOMO ETIENNE | C25: =IF(H25=0,0,H25-E25) -> 0 | E25: =IF(G25="ECHEC",0,18000) -> 0 | F25: =IF(G25="ESPECES",1000,0) -> 0 | G25: ECHEC | K25: ECHEC | L25: =TONTAOUT!I25+TONTAOUT!J25 -> 0 | M25: ECHEC | N25: ECHEC | O25: =IF(P25=0,0,($F$80-P25)) -> 0
A26: AS201623 | B26: =VLOOKUP(A26,[2]LISTADHERENT!A$5:H$51,2) -> NDOMBOU JEAN CLAUDE | C26: =IF(H26=0,0,H26-E26) -> 0 | E26: =IF(G26="ECHEC",0,18000) -> 0 | F26: =IF(G26="ESPECES",1000,0) -> 0 | G26: ECHEC | K26: ECHEC | L26: =TONTAOUT!I26+TONTAOUT!J26 -> 0 | M26: ECHEC | N26: ECHEC | O26: =IF(P26=0,0,($F$80-P26)) -> 0
A27: AS201624 | B27: =VLOOKUP(A27,[2]LISTADHERENT!A$5:H$51,2) -> NGONDIEP CLAUDE | C27: =IF(H27=0,0,H27-E27) -> 0 | E27: =IF(G27="ECHEC",0,18000) -> 0 | F27: =IF(G27="ESPECES",1000,0) -> 0 | G27: ECHEC | K27: ECHEC | L27: =TONTAOUT!I27+TONTAOUT!J27 -> 0 | M27: ECHEC | N27: ECHEC | O27: =IF(P27=0,0,($F$80-P27)) -> 0
A28: AS201625 | B28: =VLOOKUP(A28,[2]LISTADHERENT!A$5:H$51,2) -> NGONGANG JEAN THEODORE | C28: =IF(H28=0,0,H28-E28) -> 0 | E28: =IF(G28="ECHEC",0,18000) -> 0 | F28: =IF(G28="ESPECES",1000,0) -> 0 | G28: ECHEC | K28: ECHEC | L28: =TONTAOUT!I28+TONTAOUT!J28 -> 0 | M28: ECHEC | N28: ECHEC | O28: =IF(P28=0,0,($F$80-P28)) -> 0
A29: AS201626 | B29: =VLOOKUP(A29,[2]LISTADHERENT!A$5:H$51,2) -> NGUIEMEGNI MATHIEU BLAISE | C29: =IF(H29=0,0,H29-E29) -> 0 | E29: =IF(G29="ECHEC",0,18000) -> 0 | F29: =IF(G29="ESPECES",1000,0) -> 0 | G29: ECHEC | K29: ECHEC | L29: =TONTAOUT!I29+TONTAOUT!J29 -> 0 | M29: ECHEC | N29: ECHEC | O29: =IF(P29=0,0,($F$80-P29)) -> 0
A30: AS201627 | B30: =VLOOKUP(A30,[2]LISTADHERENT!A$5:H$51,2) -> NJEPDJIO MBOUKAM DELUXE | C30: =IF(H30=0,0,H30-E30) -> 0 | E30: =IF(G30="ECHEC",0,18000) -> 0 | F30: =IF(G30="ESPECES",1000,0) -> 0 | G30: ECHEC | K30: ECHEC | L30: =TONTAOUT!I30+TONTAOUT!J30 -> 0 | M30: ECHEC | N30: ECHEC | O30: =IF(P30=0,0,($F$80-P30)) -> 0
A31: AS201628 | B31: =VLOOKUP(A31,[2]LISTADHERENT!A$5:H$51,2) -> NKAMGANG JUSTIN DEJOLIE | C31: =IF(H31=0,0,H31-E31) -> 0 | E31: =IF(G31="ECHEC",0,18000) -> 0 | F31: =IF(G31="ESPECES",1000,0) -> 0 | G31: ECHEC | K31: ECHEC | L31: =TONTAOUT!I31+TONTAOUT!J31 -> 0 | M31: ECHEC | N31: ECHEC | O31: =IF(P31=0,0,($F$80-P31)) -> 0 | Q31: 50000 | R31: 42967 | S31: DJOUKWE NANGUEN GUY BLAISE
A32: AS201629 | B32: =VLOOKUP(A32,[2]LISTADHERENT!A$5:H$51,2) -> NKEPSEU DIEUDONNE | C32: =IF(H32=0,0,H32-E32) -> 0 | E32: =IF(G32="ECHEC",0,18000) -> 0 | F32: =IF(G32="ESPECES",1000,0) -> 0 | G32: ECHEC | K32: ECHEC | L32: =TONTAOUT!I32+TONTAOUT!J32 -> 0 | M32: ECHEC | N32: ECHEC | O32: =IF(P32=0,0,($F$80-P32)) -> 0
A33: AS201631 | B33: =VLOOKUP(A33,[2]LISTADHERENT!A$5:H$51,2) -> NTEPDIE TUEMAC MZ | C33: =IF(H33=0,0,H33-E33) -> 0 | E33: =IF(G33="ECHEC",0,18000) -> 0 | F33: =IF(G33="ESPECES",1000,0) -> 0 | G33: ECHEC | K33: ECHEC | L33: =TONTAOUT!I33+TONTAOUT!J33 -> 0 | M33: ECHEC | N33: ECHEC | O33: =IF(P33=0,0,($F$80-P33)) -> 0
A34: AS201633 | B34: =VLOOKUP(A34,[2]LISTADHERENT!A$5:H$51,2) -> PATEGO NJOSSU GUSTAVE | C34: =IF(H34=0,0,H34-E34) -> 0 | E34: =IF(G34="ECHEC",0,18000) -> 0 | F34: =IF(G34="ESPECES",1000,0) -> 0 | G34: ECHEC | K34: ECHEC | L34: =TONTAOUT!I34+TONTAOUT!J34 -> 0 | M34: ECHEC | N34: ECHEC | O34: =IF(P34=0,0,($F$80-P34)) -> 0
A35: AS201634 | B35: =VLOOKUP(A35,[2]LISTADHERENT!A$5:H$51,2) -> SEUNOU RICHELOT | C35: =IF(H35=0,0,H35-E35) -> 0 | E35: =IF(G35="ECHEC",0,18000) -> 0 | F35: =IF(G35="ESPECES",1000,0) -> 0 | G35: ECHEC | K35: ECHEC | L35: =TONTAOUT!I35+TONTAOUT!J35 -> 0 | M35: ECHEC | N35: ECHEC | O35: =IF(P35=0,0,($F$80-P35)) -> 0
A36: AS201635 | B36: =VLOOKUP(A36,[2]LISTADHERENT!A$5:H$51,2) -> SIME ABEL | C36: =IF(H36=0,0,H36-E36) -> 0 | E36: =IF(G36="ECHEC",0,18000) -> 0 | F36: =IF(G36="ESPECES",1000,0) -> 0 | G36: ECHEC | K36: ECHEC | L36: =TONTAOUT!I36+TONTAOUT!J36 -> 61000 | M36: ECHEC | N36: ECHEC | O36: =IF(P36=0,0,($F$80-P36)) -> 0
A37: AS201636 | B37: =VLOOKUP(A37,[2]LISTADHERENT!A$5:H$51,2) -> SIME FONGANG ERIC | C37: =IF(H37=0,0,H37-E37) -> 0 | E37: =IF(G37="ECHEC",0,18000) -> 0 | F37: =IF(G37="ESPECES",1000,0) -> 0 | G37: ECHEC | K37: ECHEC | L37: =TONTAOUT!I37+TONTAOUT!J37 -> 0 | M37: ECHEC | N37: ECHEC | O37: =IF(P37=0,0,($F$80-P37)) -> 0
A38: AS201637 | B38: =VLOOKUP(A38,[2]LISTADHERENT!A$5:H$51,2) -> SIME MATHIEU | C38: =IF(H38=0,0,H38-E38) -> 0 | E38: =IF(G38="ECHEC",0,18000) -> 0 | F38: =IF(G38="ESPECES",1000,0) -> 0 | G38: ECHEC | K38: ECHEC | L38: =TONTAOUT!I38+TONTAOUT!J38 -> 0 | M38: ECHEC | N38: ECHEC | O38: =IF(P38=0,0,($F$80-P38)) -> 0
A39: AS201638 | B39: =VLOOKUP(A39,[2]LISTADHERENT!A$5:H$51,2) -> SIME PIERRE | C39: =IF(H39=0,0,H39-E39) -> 0 | E39: =IF(G39="ECHEC",0,18000) -> 0 | F39: =IF(G39="ESPECES",1000,0) -> 0 | G39: ECHEC | K39: ECHEC | L39: =TONTAOUT!I39+TONTAOUT!J39 -> 0 | M39: ECHEC | N39: ECHEC | O39: =IF(P39=0,0,($F$80-P39)) -> 0
A40: AS201639 | B40: =VLOOKUP(A40,[2]LISTADHERENT!A$5:H$51,2) -> TAGNE NANGUEN MARTIN | C40: =IF(H40=0,0,H40-E40) -> 0 | E40: =IF(G40="ECHEC",0,18000) -> 0 | F40: =IF(G40="ESPECES",1000,0) -> 0 | G40: ECHEC | K40: ECHEC | L40: =TONTAOUT!I40+TONTAOUT!J40 -> 0 | M40: ECHEC | N40: ECHEC | O40: =IF(P40=0,0,($F$80-P40)) -> 0
A41: AS201640 | B41: =VLOOKUP(A41,[2]LISTADHERENT!A$5:H$51,2) -> TCHOUAMOU JEAN PAUL | C41: =IF(H41=0,0,H41-E41) -> 0 | E41: =IF(G41="ECHEC",0,18000) -> 0 | F41: =IF(G41="ESPECES",1000,0) -> 0 | G41: ECHEC | K41: ECHEC | L41: =TONTAOUT!I41+TONTAOUT!J41 -> 0 | M41: ECHEC | N41: ECHEC | O41: =IF(P41=0,0,($F$80-P41)) -> 0
A42: AS201641 | B42: =VLOOKUP(A42,[2]LISTADHERENT!A$5:H$51,2) -> TCHOUAMOU MATHIEU | C42: =IF(H42=0,0,H42-E42) -> 0 | E42: =IF(G42="ECHEC",0,18000) -> 0 | F42: =IF(G42="ESPECES",1000,0) -> 0 | G42: ECHEC | K42: ECHEC | L42: =TONTAOUT!I42+TONTAOUT!J42 -> 0 | M42: ECHEC | N42: ECHEC | O42: =IF(P42=0,0,($F$80-P42)) -> 0
...
