Workbook
Name BANQUE: #REF!
Name BANQUE: #REF!
Name BANQUE: #REF!
Name BANQUE: #REF!
Name BANQUE: #REF!
Name BANQUE: #REF!
Name BANQUE: #REF!
Name BANQUE: #REF!
Name BANQUE: #REF!
Name BANQUE: #REF!
Name BANQUE: #REF!
Name BANQUE: #REF!
Name BANQUE: #REF!
Name MODEPAID: [1]Feuil2!$A$1:$A$3
Name MODEVERSEMENT: #REF!
Name MODEVERSEMENT: #REF!
Name MODEVERSEMENT: #REF!
Name MODEVERSEMENT: #REF!
Name MODEVERSEMENT: #REF!
Name MODEVERSEMENT: #REF!
Name MODEVERSEMENT: #REF!
Name MODEVERSEMENT: #REF!
Name MODEVERSEMENT: #REF!
Name MODEVERSEMENT: #REF!
Name MODEVERSEMENT: #REF!
Name MODEVERSEMENT: #REF!
Name MODEVERSEMENT: #REF!
Name MODEVERSEMENTS: [2]MODEVERSEMENT!$A$1:$A$3
Name VALMODEPAID: [3]MODEPAID!$A$1:$A$3

Sheet COMPTE TRESORERIE
A1: COMPTE TRESORERIE
A3: DATE | B3: COMPTE CAISSE | F3: COMPTE BANQUE CCA
B4: LIBELLE | C4: ENTREE | D4: SORTIE | E4: SOLDE EN CAISSE | F4: LIBELLE | G4: SORTIE | H4: ENTREE | I4: SOLDE EN BANQUE
A5: REPORT | C5: 0 | H5: 8418637
A6: 42904 | B6: MOUVEMENT ESPECES | C6: =MVTJUIN2017!$B$71 -> 2529500 | D6: =MVTJUIN2017!$C$71 -> 2529500 | E6: =C5+C6-D6 -> 0 | F6: MOUVEMENT BANCAIRE | G6: =MVTJUIN2017!$E$71 -> 5530500 | H6: =MVTJUIN2017!$F$71 -> 5296000 | I6: =H5+H6-G6 -> 8184137
A7: 42932 | B7: MOUVEMENT ESPECES | C7: =MVTJUIL2017!$B$71 -> 3573000 | D7: =MVTJUIL2017!$C$71 -> 3573000 | E7: =E6+C7-D7 -> 0 | F7: MOUVEMENT BANCAIRE | G7: =MVTJUIL2017!$E$71 -> 3367000 | H7: =MVTJUIL2017!$F$71 -> 3402500 | I7: =I6+H7-G7 -> 8219637
A8: 42967 | B8: MOUVEMENT ESPECES | C8: =MVTAOUT2017!$B$71 -> 3823000 | D8: =MVTAOUT2017!$C$71 -> 3657500 | E8: =E7+C8-D8 -> 165500 | F8: MOUVEMENT BANCAIRE | G8: =MVTAOUT2017!$G$71 -> 2079500 | H8: =MVTAOUT2017!$H$71 -> 2689000 | I8: =I7+H8-G8 -> 8829137
A9: 42999 | B9: MOUVEMENT ESPECES | C9: =MVTSEPT2017!$B$70 -> 0 | D9: =MVTSEPT2017!$C$70 -> 0 | E9: =E8+C9-D9 -> 165500 | F9: MOUVEMENT BANCAIRE | G9: =MVTSEPT2017!$G$70 -> 0 | H9: =MVTSEPT2017!$H$70 -> 0 | I9: =I8+H9-G9 -> 8829137
A10: 43023 | B10: MOUVEMENT ESPECES | C10: =MVTOCT2017!$B$71 -> 0 | D10: =MVTOCT2017!$C$71 -> 0 | E10: =E9+C10-D10 -> 165500 | F10: MOUVEMENT BANCAIRE | G10: =MVTOCT2017!$G$71 -> 0 | H10: =MVTOCT2017!$H$71 -> 0 | I10: =I9+H10-G10 -> 8829137
A11: 43058 | B11: MOUVEMENT ESPECES | C11: =MVTNOV2017!$B$71 -> 0 | D11: =MVTNOV2017!$C$71 -> 0 | E11: =E10+C11-D11 -> 165500 | F11: MOUVEMENT BANCAIRE | G11: =MVTNOV2017!$G$71 -> 0 | H11: =MVTNOV2017!$H$71 -> 0 | I11: =I10+H11-G11 -> 8829137
A12: 43086 | B12: MOUVEMENT ESPECES | C12: =MVTDEC2017!$B$71 -> 0 | D12: =MVTDEC2017!$C$71 -> 0 | E12: =E11+C12-D12 -> 165500 | F12: MOUVEMENT BANCAIRE | G12: =MVTDEC2017!$G$71 -> 0 | H12: =MVTDEC2017!$H$71 -> 0 | I12: =I11+H12-G12 -> 8829137
A13: 43121 | B13: MOUVEMENT ESPECES | C13: =MVTJANV2018!$B$71 -> 0 | D13: =MVTJANV2018!$C$71 -> 0 | E13: =E12+C13-D13 -> 165500 | F13: MOUVEMENT BANCAIRE | G13: =MVTJANV2018!$G$71 -> 0 | H13: =MVTJANV2018!$H$71 -> 0 | I13: =I12+H13-G13 -> 8829137
A14: 43149 | B14: MOUVEMENT ESPECES | C14: =MVTFEV2018!$B$71 -> 0 | D14: =MVTFEV2018!$C$71 -> 0 | E14: =E13+C14-D14 -> 165500 | F14: MOUVEMENT BANCAIRE | G14: =MVTFEV2018!$G$71 -> 0 | H14: =MVTFEV2018!$H$71 -> 0 | I14: =I13+H14-G14 -> 8829137
A15: 43177 | B15: MOUVEMENT ESPECES | C15: =MVTMARS2018!$B$71 -> 0 | D15: =MVTMARS2018!$C$71 -> 0 | E15: =E14+C15-D15 -> 165500 | F15: MOUVEMENT BANCAIRE | G15: =MVTMARS2018!$G$71 -> 0 | H15: =MVTMARS2018!$H$71 -> 0 | I15: =I14+H15-G15 -> 8829137
A16: 43212 | B16: MOUVEMENT ESPECES | C16: =MVTAVRIL2018!$B$71 -> 0 | D16: =MVTAVRIL2018!$C$71 -> 0 | E16: =E15+C16-D16 -> 165500 | F16: MOUVEMENT BANCAIRE | G16: =MVTAVRIL2018!$G$71 -> 0 | H16: =MVTAVRIL2018!$H$71 -> 0 | I16: =I15+H16-G16 -> 8829137
A17: 43240 | B17: MOUVEMENT ESPECES | C17: =MVTMAI2018!$B$71 -> 0 | D17: =MVTMAI2018!$C$71 -> 0 | E17: =E16+C17-D17 -> 165500 | F17: MOUVEMENT BANCAIRE | G17: =MVTMAI2018!$G$71 -> 0 | H17: =MVTMAI2018!$H$71 -> 0 | I17: =I16+H17-G17 -> 8829137
A18: 43268 | B18: MOUVEMENT ESPECES | C18: =MVTJUIN2018!$B$71 -> 0 | D18: =MVTJUIN2018!$C$71 -> 0 | E18: =E17+C18-D18 -> 165500 | F18: MOUVEMENT BANCAIRE | G18: =MVTJUIN2018!$G$71 -> 0 | H18: =MVTJUIN2018!$H$71 -> 0 | I18: =I17+H18-G18 -> 8829137
A19: 43296 | B19: MOUVEMENT ESPECES | C19: =MVTJUIL2018!$B$71 -> 0 | D19: =MVTJUIL2018!$C$71 -> 0 | E19: =E18+C19-D19 -> 165500 | F19: MOUVEMENT BANCAIRE | G19: =MVTJUIL2018!$G$71 -> 0 | H19: =MVTJUIL2018!$H$71 -> 0 | I19: =I18+H19-G19 -> 8829137
A20: 43331 | B20: MOUVEMENT ESPECES | C20: =MVTAOUT2018!$B$71 -> 0 | D20: =MVTAOUT2018!$C$71 -> 0 | E20: =E19+C20-D20 -> 165500 | F20: MOUVEMENT BANCAIRE | G20: =MVTAOUT2018!$G$71 -> 0 | H20: =MVTAOUT2018!$H$71 -> 0 | I20: =I19+H20-G20 -> 8829137

Sheet MVTJUIN2017
A1: MOUVEMENT TRESORERIE
A2: DATE | B2: 42904
A3: COMPTE CAISSE | D3: COMPTE BANQUE
A4: LIBELLE | B4: ENTREE | C4: SORTIE | D4: LIBELLE | E4: SORTIE | F4: ENTREE
A6: TONTINE13 000 | B6: =[2]TONT20000JUIN2017!$L$72-14000 -> 1100500 | D6: TONTINE 13 000 | F6: =[2]TONT20000JUIN2017!$L$73 -> 1879000
A7: TONTINE 60 000 | B7: =[4]TONTJUIN!$F$36 -> 540000 | D7: TONTINE 60 000 | F7: =[4]TONTJUIN!$F$37 -> 1112000
A8: TONTINE 100 000 | B8: =[3]TONTJUIN!$F$36 -> 875000 | D8: TONTINE 100 000 | F8: =[3]TONTJUIN!$F$37 -> 2305000
A9: PENALITE RETARD | B9: 14000
A10: APPERITIF DOHOU DAVID | C10: 100000
A11: ACHAT INTERET T60 000 | D11: PRÊT FONDS
A14: NKAMGANG | C14: 120000 | D14: SEUNOU RICHELOT | E14: 900000
A15: SIME ABEL | C15: 120000 | D15: NGONDIEP CLAUDE | E15: 2399500
A16: TYAM ERNEST | C16: 120000 | D16: DJUOMBESSY ANTOINE | E16: 131000
A17: NJEPJO DELUXE | C17: 120000 | D17: SIMO PIERRE | E17: 400000
A18: DJOMO J P | C18: 120000 | D18: HOTCHO BENJAMIN | E18: 700000
A25: SEUNOU RICHELOT | C25: 32000 | D25: DJOUOKEP SAMUEL | E25: 1000000
A26: NKOUTCHO | C26: 120000
A27: INTERET T100 000
A28: TYAM ERNEST | C28: 200000
A29: NKAMGANG | C29: 200000
A30: KOUMOU MOISE | C30: 31000
A31: BENEFICIAIRE T13 000
A32: NGONDIEP CLAUDE | C32: 115500
A33: SIME MATHIEU | C33: 140000
A34: PRÊT FONDS
A35: DJUOMBESSY ANTOINE | C35: 569000
A36: COMMISSION
A37: KEPSEU FRANCIS | C37: 15000
A38: BUREAU | C38: 33000
A39: BENEFICIAIRE T100000
A40: KEPSEU FRANCIS | C40: 374000
A71: TOTAL | B71: =SUM(B5:B70) -> 2529500 | C71: =SUM(C5:C70) -> 2529500 | E71: =SUM(E5:E70) -> 5530500 | F71: =SUM(F5:F70) -> 5296000

Sheet MVTJUIL2017
A2: DATE | B2: 42932
A3: COMPTE CAISSE | D3: COMPTE BANQUE CCA
A4: LIBELLE | B4: ENTREE | C4: SORTIE | D4: LIBELLE | E4: SORTIE | F4: ENTREE
A6: TONTINE 13 000 | B6: =[2]TONT20000JUIL2017!$F$71 -> 283000 | D6: TONTINE 13 000 | F6: =[2]TONT20000JUIL2017!$F$72 -> 521500
A7: TONTINE 60 000 | B7: =[4]TONTJUIL!$C$36 -> 600000 | D7: TONTINE 60 000 | F7: =[4]TONTJUIL!$C$37 -> 900000
A8: TONTINE 100 000 | B8: =[3]TONTJUIL!$C$36 -> 900000 | D8: TONTINE 100 000 | F8: =[3]TONTJUIL!$C$37 -> 1700000
A9: PENALITE RETARD | B9: =[2]TONT20000JUIL2017!$G$56-1000 -> 15000 | D9: PENALITE RETARD
A10: REMBBOURSEMENT PRÊT FONDS | D10: REMBOURSEMENT
A11: NGONDIEP CLAUDE | B11: 100000 | D11: T60 000 DJOMO JP | F11: 61000
A12: KOUAMOU EMMANUEL | B12: 120000
A13: SIME PIERRE | B13: 300000
A14: REMBOURSEMENT 100 000 | D14: T13 000 CHINGUIE | F14: 20000
A15: NKAMGANG JUSTIN DEJOLIE | B15: 204000 | D15: REMBBOURSEMENT PRÊT FONDS
A16: KOUAMOU MOISE | B16: 31500 | D16: NGONDIEP CLAUDE | F16: 100000
A17: TIEYAM ERNEST | B17: 207000 | D17: NANKAM APPOLINAIRE | F17: 100000
A18: KOUAMO VICTOR PEGUY | B18: 36000 | D18: TONTINE 100 000NDJOMO ETIENNE | E18: 1399000
A19: SAISIE
A20: HODIEP JULES SAISIE | B20: 39000
A21: TCHOUAMOU JEAN PAUL SAISIE | B21: 34000
A22: KEPHE DAVID SAISIE | B22: 4000
A23: TCHOUTOU NANA CLAUDE | B23: 4000
A24: NGONGANG JEAN THEODORE | B24: 4000
A25: REMBOURSEMENT 13 000 | D25: TONTINE 100 000NDJOMO YOMBI EMMA | E25: 1400000
A26: CHINGUIE | B26: 4500 | D26: TONTINE 60 000DJOMO JP | E26: 568000
A27: FOTSO THOMAS | B27: 24500
A28: REMBOURSEMENT 60 000
A29: TYAMERNEST | B29: 122500
A30: SIME ABEL | B30: 122500
A31: NKAMGANG JD | B31: 122000
A32: SEUMOU RICHELOT | B32: 32500
A33: KOUATCHO MESSACK | B33: 122000
A34: T60 000 DJOMO JP | B34: 61500
A35: PRÊT T60 000
A36: FOTSO THOMAS | C36: 50000
A37: SIME ABEL | C37: 31000
A38: TCHOUANTE FRANCOIS | C38: 100000
A39: TIEYAM ERNEST | C39: 100000
A40: PRÊT T100 000
A41: KOUAMOU MOISE | C41: 79500
A42: NKAMGANG JUSTIN DEJOLIE | C42: 100000
...

Sheet MVTAOUT2017
A2: DATE | B2: 42967
A3: COMPTE CAISSE | E3: COMPTE BANQUE CCA
A4: LIBELLE | B4: ENTREE | C4: SORTIE | D4: CONTRE PARTIE | E4: LIBELLE | F4: CONTRE PARTIE | G4: SORTIE | H4: ENTREE
A6: TONTINE 25 000 | B6: =[5]TONTAOUT!$G$76 -> 761000 | E6: TONTINE 25 000 | H6: =[5]TONTAOUT!$G$77 -> 448000
A7: TONTINE 60 000 | B7: =[4]TONTAOUT!$C$36 -> 900000 | E7: TONTINE 60 000 | H7: =[4]TONTAOUT!$C$37 -> 600000
A8: TONTINE 100 000 | B8: =[3]TONTAOUT!$C$37 -> 1200000 | E8: TONTINE 100 000 | H8: =[3]TONTAOUT!$C$38 -> 1400000
A9: PENALITE RETARD | B9: =[5]TONTAOUT!$F$58 -> 52500
A10: REMBBOURSEMENT PETIT LOT | E10: REMBBOURSEMENT PETIT LOT
A11: TONTINE 25 000 | B11: =[6]AOUT2017!$G$77 -> 0 | E11: TONTINE 25 000
A12: TONTINE 60 000 | B12: =[4]TONTAOUT!$C$38 -> 306000 | E12: TONTINE 60 000
A13: TONTINE 100 000 | B13: =[3]TONTAOUT!$C$39 -> 303500 | E13: TONTINE 100 000
A14: EN CAISSE | E14: EN CAISSE
A15: NGONGANG JEAN THEODORE | B15: 30000 | E15: NGONGANG JEAN THEODORE
A16: TCHOUAMOU JEAN PAUL | B16: 20000 | E16: TCHOUAMOU JEAN PAUL
A17: ACHAT LOT PRINCIPAL | E17: ACHAT LOT PRINCIPAL
A18: TONTINE 25 000 | C18: =[5]TONTAOUT!$J$57 -> 515000 | E18: TONTINE 25 000
A19: TONTINE 60 000 | C19: =[4]TONTAOUT!$H$36-G19 -> 1190500 | E19: TONTINE 60 000 | G19: 679500
A20: TONTINE 100 000 | E20: TONTINE 100 000 | G20: =[3]TONTAOUT!$C$38 -> 1400000
A21: ACHAT PETIT LOT | E21: ACHAT PETIT LOT
A22: TONTINE 25 000 | C22: =[5]TONTAOUT!$F$59 -> 151000 | E22: TONTINE 25 000
A23: TONTINE 60 000 | C23: =[4]TONTAOUT!$C$39 -> 0 | E23: TONTINE 60 000
A24: TONTINE 100 000 | C24: =[3]TONTAOUT!$C$40 -> 0 | E24: TONTINE 100 000
A25: REMBBOURSEMENT PRÊT FONDS | B25: =[7]MVTAOUT!$O$20+[7]MVTAOUT!$O$33 -> 250000 | E25: REMBBOURSEMENT PRÊT FONDS | H25: =[7]MVTAOUT!$F$64-B25 -> 141000
A26: RECONTITUTION FONDS | E26: RECONTITUTION FONDS | H26: =[2]FONDSDECAISSE!$K$19 -> 100000
A27: EMPRUNT FONDS | C27: 150000 | E27: EMPRUNT FONDS
A28: COLLATION | E28: COLLATION
A29: NKEPSEU DIEUDONNE | C29: 100000 | E29: NKEPSEU DIEUDONNE
A30: COMPLEMENT TONTINE T60000 | C30: =+[4]TONTAOUT!$H$36-([4]TONTAOUT!$C$36+[4]TONTAOUT!$C$37+[4]TONTAOUT!$C$38) -> 64000 | E30: COMPLEMENT TONTINE T60000
A31: FRAIS DE COMMUNICATION | C31: 5000 | E31: FRAIS DE COMMUNICATION
A32: DISTRIBUTION INTERET T100000 | C32: =[3]TONTAOUT!$M$33-[3]TONTAOUT!$N$33 -> 1482000 | E32: DISTRIBUTION INTERET T100000
B71: =SUM(B5:B70) -> 3823000 | C71: =SUM(C5:C70) -> 3657500 | G71: =SUM(G5:G70) -> 2079500 | H71: =SUM(H5:H70) -> 2689000
C73: =B71-C71 -> 165500

Sheet MVTSEPT2017
A2: DATE | B2: 42995
A3: COMPTE CAISSE | E3: COMPTE BANQUE CCA
A4: LIBELLE | B4: ENTREE | C4: SORTIE | D4: CONTRE PARTIE | E4: LIBELLE | F4: CONTRE PARTIE | G4: SORTIE | H4: ENTREE
A6: TONTINE 25 000 | B6: =[5]TONTSEPT!$G$76 -> 0 | E6: TONTINE 25 000 | H6: =[5]TONTSEPT!$G$77 -> 0
A7: TONTINE 60 000 | B7: =[4]TONTSEPT!$C$36 -> 0 | E7: TONTINE 60 000 | H7: =[4]TONTSEPT!$C$37 -> 0
A8: TONTINE 100 000 | B8: =[3]TONTSEPT!$C$37 -> 0 | E8: TONTINE 100 000 | H8: =[3]TONTSEPT!$C$38 -> 0
A9: PENALITE RETARD | B9: =[5]TONTSEPT!$F$58 -> 0
A10: REMBBOURSEMENT PETIT LOT | E10: REMBBOURSEMENT PETIT LOT
A11: TONTINE 25 000 | B11: =[5]TONTSEPT!$H$76 -> 0 | E11: TONTINE 25 000 | H11: =[5]TONTSEPT!$H$77 -> 0
A12: TONTINE 60 000 | B12: =[4]TONTSEPT!$D$36 -> 0 | E12: TONTINE 60 000 | H12: =[4]TONTSEPT!$D$37 -> 0
A13: TONTINE 100 000 | B13: =[3]TONTSEPT!$D$37 -> 0 | E13: TONTINE 100 000 | H13: =[3]TONTSEPT!$D$38 -> 0
A14: VENTE LOT PRINCIPAL | E14: VENTE LOT PRINCIPAL
A15: TONTINE 25 000 | C15: =[5]TONTSEPT!$J$76 -> 0 | E15: TONTINE 25 000 | G15: =[5]TONTSEPT!$J$77 -> 0
A16: TONTINE 60 000 | C16: =[4]TONTSEPT!$F$36 -> 0 | E16: TONTINE 60 000 | G16: =[4]TONTSEPT!$F$37 -> 0
A17: TONTINE 100 000 | C17: =[3]TONTSEPT!$F$37 -> 0 | E17: TONTINE 100 000 | G17: =[3]TONTSEPT!$F$38 -> 0
A18: VENTE PETIT LOT | E18: VENTE PETIT LOT
A19: TONTINE 25 000 | C19: =[5]TONTSEPT!$I$76 -> 0 | E19: TONTINE 25 000 | G19: =[5]TONTSEPT!$I$77 -> 0
A20: TONTINE 60 000 | C20: =[4]TONTSEPT!$E$36 -> 0 | E20: TONTINE 60 000 | G20: =[4]TONTSEPT!$E$37 -> 0
A21: TONTINE 100 000 | C21: =[3]TONTSEPT!$E$37 -> 0 | E21: TONTINE 100 000 | G21: =+[3]TONTSEPT!$E$38 -> 0
A22: REMBBOURSEMENT PRÊT FONDS | B22: =[7]MVTSEPT!$G$69 -> 0 | E22: REMBBOURSEMENT PRÊT FONDS | H22: =[7]MVTSEPT!$G$70 -> 0
A23: RECONTITUTION FONDS | E23: RECONTITUTION FONDS
A24: EMPRUNT FONDS | C24: =[7]MVTSEPT!$F$69 -> 0 | E24: EMPRUNT FONDS | G24: =[7]MVTSEPT!$F$70 -> 0
A25: COLLATION | E25: COLLATION
A26: COMPLEMENT TONTINE T60000 | E26: COMPLEMENT TONTINE T60000
A27: FRAIS DE COMMUNICATION | E27: FRAIS DE COMMUNICATION
A28: DISTRIBUTION INTERET T100000 | E28: DISTRIBUTION INTERET T100000
A29: REMBOURSEMENT COMPLEMENT TONTINE T60000 | E29: REMBOURSEMENT COMPLEMENT TONTINE T60000
A30: EN CAISSE | E30: EN CAISSE
A31: NGONGANG JEAN THEODORE | E31: NGONGANG JEAN THEODORE
A32: TCHOUAMOU JEAN PAUL | E32: TCHOUAMOU JEAN PAUL
B70: =SUM(B5:B69) -> 0 | C70: =SUM(C5:C69) -> 0 | G70: =SUM(G5:G69) -> 0 | H70: =SUM(H5:H69) -> 0
C72: =B70-C70 -> 0

Sheet MVTOCT2017
A2: DATE | B2: 43030
A3: COMPTE CAISSE | E3: COMPTE BANQUE CCA
A4: LIBELLE | B4: ENTREE | C4: SORTIE | D4: CONTRE PARTIE | E4: LIBELLE | F4: CONTRE PARTIE | G4: SORTIE | H4: ENTREE
A6: TONTINE 25 000 | B6: =[5]TONTSEPT!$G$76 -> 0 | E6: TONTINE 25 000 | H6: =[5]TONTSEPT!$G$77 -> 0
A7: TONTINE 60 000 | B7: =[4]TONTSEPT!$C$36 -> 0 | E7: TONTINE 60 000 | H7: =[4]TONTSEPT!$C$37 -> 0
A8: TONTINE 100 000 | B8: =[3]TONTSEPT!$C$37 -> 0 | E8: TONTINE 100 000 | H8: =[3]TONTSEPT!$C$38 -> 0
A9: PENALITE RETARD | B9: =[5]TONTSEPT!$F$58 -> 0
A10: REMBBOURSEMENT PETIT LOT | E10: REMBBOURSEMENT PETIT LOT
A11: TONTINE 25 000 | B11: =[5]TONTSEPT!$H$76 -> 0 | E11: TONTINE 25 000 | H11: =[5]TONTSEPT!$H$77 -> 0
A12: TONTINE 60 000 | B12: =[4]TONTSEPT!$D$36 -> 0 | E12: TONTINE 60 000 | H12: =[4]TONTSEPT!$D$37 -> 0
A13: TONTINE 100 000 | B13: =[3]TONTSEPT!$D$37 -> 0 | E13: TONTINE 100 000 | H13: =[3]TONTSEPT!$D$38 -> 0
A14: ACHAT LOT PRINCIPAL | E14: ACHAT LOT PRINCIPAL
A15: TONTINE 25 000 | C15: =[5]TONTSEPT!$J$76 -> 0 | E15: TONTINE 25 000 | G15: =[5]TONTSEPT!$J$77 -> 0
A16: TONTINE 60 000 | E16: TONTINE 60 000
A17: TONTINE 100 000 | C17: =[3]TONTSEPT!$F$37 -> 0 | E17: TONTINE 100 000 | G17: =[3]TONTSEPT!$F$38 -> 0
A18: ACHAT PETIT LOT | E18: ACHAT PETIT LOT
A19: TONTINE 25 000 | C19: =[5]TONTSEPT!$F$59 -> 0 | E19: TONTINE 25 000 | G19: =[5]TONTSEPT!$F$59 -> 0
A20: TONTINE 60 000 | C20: =[4]TONTSEPT!$C$43 -> 0 | E20: TONTINE 60 000
A21: TONTINE 100 000 | C21: =[3]TONTSEPT!$E$37 -> 0 | E21: TONTINE 100 000 | G21: =+[3]TONTSEPT!$E$38 -> 0
A22: REMBBOURSEMENT PRÊT FONDS | B22: =[7]MVTSEPT!$G$69 -> 0 | E22: REMBBOURSEMENT PRÊT FONDS | H22: =[7]MVTSEPT!$G$70 -> 0
A23: RECONTITUTION FONDS | E23: RECONTITUTION FONDS
A24: EMPRUNT FONDS | C24: =[7]MVTSEPT!$F$69 -> 0 | E24: EMPRUNT FONDS | G24: =[7]MVTSEPT!$F$70 -> 0
A25: COLLATION | E25: COLLATION
A26: COMPLEMENT TONTINE T60000 | E26: COMPLEMENT TONTINE T60000
A27: FRAIS DE COMMUNICATION | E27: FRAIS DE COMMUNICATION
A28: DISTRIBUTION INTERET T100000 | E28: DISTRIBUTION INTERET T100000
A29: REMBOURSEMENT COMPLEMENT TONTINE T60000 | E29: REMBOURSEMENT COMPLEMENT TONTINE T60000
A30: EN CAISSE | E30: EN CAISSE
A31: NGONGANG JEAN THEODORE | E31: NGONGANG JEAN THEODORE
A32: TCHOUAMOU JEAN PAUL | E32: TCHOUAMOU JEAN PAUL
B71: =SUM(B5:B70) -> 0 | C71: =SUM(C5:C70) -> 0 | G71: =SUM(G5:G70) -> 0 | H71: =SUM(H5:H70) -> 0
C73: =B71-C71 -> 0

Sheet MVTNOV2017
A2: DATE | B2: 43058
A3: COMPTE CAISSE | E3: COMPTE BANQUE CCA
A4: LIBELLE | B4: ENTREE | C4: SORTIE | D4: CONTRE PARTIE | E4: LIBELLE | F4: CONTRE PARTIE | G4: SORTIE | H4: ENTREE
A6: TONTINE 25 000 | B6: =[5]TONTSEPT!$G$76 -> 0 | E6: TONTINE 25 000 | H6: =[5]TONTSEPT!$G$77 -> 0
A7: TONTINE 60 000 | B7: =[4]TONTSEPT!$C$36 -> 0 | E7: TONTINE 60 000 | H7: =[4]TONTSEPT!$C$37 -> 0
A8: TONTINE 100 000 | B8: =[3]TONTSEPT!$C$37 -> 0 | E8: TONTINE 100 000 | H8: =[3]TONTSEPT!$C$38 -> 0
A9: PENALITE RETARD | B9: =[5]TONTSEPT!$F$58 -> 0
A10: REMBBOURSEMENT PETIT LOT | E10: REMBBOURSEMENT PETIT LOT
A11: TONTINE 25 000 | B11: =[5]TONTSEPT!$H$76 -> 0 | E11: TONTINE 25 000 | H11: =[5]TONTSEPT!$H$77 -> 0
A12: TONTINE 60 000 | B12: =[4]TONTSEPT!$D$36 -> 0 | E12: TONTINE 60 000 | H12: =[4]TONTSEPT!$D$37 -> 0
A13: TONTINE 100 000 | B13: =[3]TONTSEPT!$D$37 -> 0 | E13: TONTINE 100 000 | H13: =[3]TONTSEPT!$D$38 -> 0
A14: ACHAT LOT PRINCIPAL | E14: ACHAT LOT PRINCIPAL
A15: TONTINE 25 000 | C15: =[5]TONTSEPT!$J$76 -> 0 | E15: TONTINE 25 000 | G15: =[5]TONTSEPT!$J$77 -> 0
A16: TONTINE 60 000 | E16: TONTINE 60 000
A17: TONTINE 100 000 | C17: =[3]TONTSEPT!$F$37 -> 0 | E17: TONTINE 100 000 | G17: =[3]TONTSEPT!$F$38 -> 0
A18: ACHAT PETIT LOT | E18: ACHAT PETIT LOT
A19: TONTINE 25 000 | C19: =[5]TONTSEPT!$F$59 -> 0 | E19: TONTINE 25 000 | G19: =[5]TONTSEPT!$F$59 -> 0
A20: TONTINE 60 000 | C20: =[4]TONTSEPT!$C$43 -> 0 | E20: TONTINE 60 000
A21: TONTINE 100 000 | C21: =[3]TONTSEPT!$E$37 -> 0 | E21: TONTINE 100 000 | G21: =+[3]TONTSEPT!$E$38 -> 0
A22: REMBBOURSEMENT PRÊT FONDS | B22: =[7]MVTSEPT!$G$69 -> 0 | E22: REMBBOURSEMENT PRÊT FONDS | H22: =[7]MVTSEPT!$G$70 -> 0
A23: RECONTITUTION FONDS | E23: RECONTITUTION FONDS
A24: EMPRUNT FONDS | C24: =[7]MVTSEPT!$F$69 -> 0 | E24: EMPRUNT FONDS | G24: =[7]MVTSEPT!$F$70 -> 0
A25: COLLATION | E25: COLLATION
A26: COMPLEMENT TONTINE T60000 | E26: COMPLEMENT TONTINE T60000
A27: FRAIS DE COMMUNICATION | E27: FRAIS DE COMMUNICATION
A28: DISTRIBUTION INTERET T100000 | E28: DISTRIBUTION INTERET T100000
A29: REMBOURSEMENT COMPLEMENT TONTINE T60000 | E29: REMBOURSEMENT COMPLEMENT TONTINE T60000
A30: EN CAISSE | E30: EN CAISSE
A31: NGONGANG JEAN THEODORE | E31: NGONGANG JEAN THEODORE
A32: TCHOUAMOU JEAN PAUL | E32: TCHOUAMOU JEAN PAUL
B71: =SUM(B5:B70) -> 0 | C71: =SUM(C5:C70) -> 0 | G71: =SUM(G5:G70) -> 0 | H71: =SUM(H5:H70) -> 0
C73: =B71-C71 -> 0

Sheet MVTDEC2017
A2: DATE | B2: 43086
A3: COMPTE CAISSE | E3: COMPTE BANQUE CCA
A4: LIBELLE | B4: ENTREE | C4: SORTIE | D4: CONTRE PARTIE | E4: LIBELLE | F4: CONTRE PARTIE | G4: SORTIE | H4: ENTREE
A6: TONTINE 25 000 | B6: =[5]TONTSEPT!$G$76 -> 0 | E6: TONTINE 25 000 | H6: =[5]TONTSEPT!$G$77 -> 0
A7: TONTINE 60 000 | B7: =[4]TONTSEPT!$C$36 -> 0 | E7: TONTINE 60 000 | H7: =[4]TONTSEPT!$C$37 -> 0
A8: TONTINE 100 000 | B8: =[3]TONTSEPT!$C$37 -> 0 | E8: TONTINE 100 000 | H8: =[3]TONTSEPT!$C$38 -> 0
A9: PENALITE RETARD | B9: =[5]TONTSEPT!$F$58 -> 0
A10: REMBBOURSEMENT PETIT LOT | E10: REMBBOURSEMENT PETIT LOT
A11: TONTINE 25 000 | B11: =[5]TONTSEPT!$H$76 -> 0 | E11: TONTINE 25 000 | H11: =[5]TONTSEPT!$H$77 -> 0
A12: TONTINE 60 000 | B12: =[4]TONTSEPT!$D$36 -> 0 | E12: TONTINE 60 000 | H12: =[4]TONTSEPT!$D$37 -> 0
A13: TONTINE 100 000 | B13: =[3]TONTSEPT!$D$37 -> 0 | E13: TONTINE 100 000 | H13: =[3]TONTSEPT!$D$38 -> 0
A14: ACHAT LOT PRINCIPAL | E14: ACHAT LOT PRINCIPAL
A15: TONTINE 25 000 | C15: =[5]TONTSEPT!$J$76 -> 0 | E15: TONTINE 25 000 | G15: =[5]TONTSEPT!$J$77 -> 0
A16: TONTINE 60 000 | E16: TONTINE 60 000
A17: TONTINE 100 000 | C17: =[3]TONTSEPT!$F$37 -> 0 | E17: TONTINE 100 000 | G17: =[3]TONTSEPT!$F$38 -> 0
A18: ACHAT PETIT LOT | E18: ACHAT PETIT LOT
A19: TONTINE 25 000 | C19: =[5]TONTSEPT!$F$59 -> 0 | E19: TONTINE 25 000 | G19: =[5]TONTSEPT!$F$59 -> 0
A20: TONTINE 60 000 | C20: =[4]TONTSEPT!$C$43 -> 0 | E20: TONTINE 60 000
A21: TONTINE 100 000 | C21: =[3]TONTSEPT!$E$37 -> 0 | E21: TONTINE 100 000 | G21: =+[3]TONTSEPT!$E$38 -> 0
A22: REMBBOURSEMENT PRÊT FONDS | B22: =[7]MVTSEPT!$G$69 -> 0 | E22: REMBBOURSEMENT PRÊT FONDS | H22: =[7]MVTSEPT!$G$70 -> 0
A23: RECONTITUTION FONDS | E23: RECONTITUTION FONDS
A24: EMPRUNT FONDS | C24: =[7]MVTSEPT!$F$69 -> 0 | E24: EMPRUNT FONDS | G24: =[7]MVTSEPT!$F$70 -> 0
A25: COLLATION | E25: COLLATION
A26: COMPLEMENT TONTINE T60000 | E26: COMPLEMENT TONTINE T60000
A27: FRAIS DE COMMUNICATION | E27: FRAIS DE COMMUNICATION
A28: DISTRIBUTION INTERET T100000 | E28: DISTRIBUTION INTERET T100000
A29: REMBOURSEMENT COMPLEMENT TONTINE T60000 | E29: REMBOURSEMENT COMPLEMENT TONTINE T60000
A30: EN CAISSE | E30: EN CAISSE
A31: NGONGANG JEAN THEODORE | E31: NGONGANG JEAN THEODORE
A32: TCHOUAMOU JEAN PAUL | E32: TCHOUAMOU JEAN PAUL
B71: =SUM(B5:B70) -> 0 | C71: =SUM(C5:C70) -> 0 | G71: =SUM(G5:G70) -> 0 | H71: =SUM(H5:H70) -> 0
C73: =B71-C71 -> 0

Sheet MVTJANV2018
A2: DATE | B2: 43121
A3: COMPTE CAISSE | E3: COMPTE BANQUE CCA
A4: LIBELLE | B4: ENTREE | C4: SORTIE | D4: CONTRE PARTIE | E4: LIBELLE | F4: CONTRE PARTIE | G4: SORTIE | H4: ENTREE
A6: TONTINE 25 000 | B6: =[5]TONTSEPT!$G$76 -> 0 | E6: TONTINE 25 000 | H6: =[5]TONTSEPT!$G$77 -> 0
A7: TONTINE 60 000 | B7: =[4]TONTSEPT!$C$36 -> 0 | E7: TONTINE 60 000 | H7: =[4]TONTSEPT!$C$37 -> 0
A8: TONTINE 100 000 | B8: =[3]TONTSEPT!$C$37 -> 0 | E8: TONTINE 100 000 | H8: =[3]TONTSEPT!$C$38 -> 0
A9: PENALITE RETARD | B9: =[5]TONTSEPT!$F$58 -> 0
A10: REMBBOURSEMENT PETIT LOT | E10: REMBBOURSEMENT PETIT LOT
A11: TONTINE 25 000 | B11: =[5]TONTSEPT!$H$76 -> 0 | E11: TONTINE 25 000 | H11: =[5]TONTSEPT!$H$77 -> 0
A12: TONTINE 60 000 | B12: =[4]TONTSEPT!$D$36 -> 0 | E12: TONTINE 60 000 | H12: =[4]TONTSEPT!$D$37 -> 0
A13: TONTINE 100 000 | B13: =[3]TONTSEPT!$D$37 -> 0 | E13: TONTINE 100 000 | H13: =[3]TONTSEPT!$D$38 -> 0
A14: ACHAT LOT PRINCIPAL | E14: ACHAT LOT PRINCIPAL
A15: TONTINE 25 000 | C15: =[5]TONTSEPT!$J$76 -> 0 | E15: TONTINE 25 000 | G15: =[5]TONTSEPT!$J$77 -> 0
A16: TONTINE 60 000 | E16: TONTINE 60 000
A17: TONTINE 100 000 | C17: =[3]TONTSEPT!$F$37 -> 0 | E17: TONTINE 100 000 | G17: =[3]TONTSEPT!$F$38 -> 0
A18: ACHAT PETIT LOT | E18: ACHAT PETIT LOT
A19: TONTINE 25 000 | C19: =[5]TONTSEPT!$F$59 -> 0 | E19: TONTINE 25 000 | G19: =[5]TONTSEPT!$F$59 -> 0
A20: TONTINE 60 000 | C20: =[4]TONTSEPT!$C$43 -> 0 | E20: TONTINE 60 000
A21: TONTINE 100 000 | C21: =[3]TONTSEPT!$E$37 -> 0 | E21: TONTINE 100 000 | G21: =+[3]TONTSEPT!$E$38 -> 0
A22: REMBBOURSEMENT PRÊT FONDS | B22: =[7]MVTSEPT!$G$69 -> 0 | E22: REMBBOURSEMENT PRÊT FONDS | H22: =[7]MVTSEPT!$G$70 -> 0
A23: RECONTITUTION FONDS | E23: RECONTITUTION FONDS
A24: EMPRUNT FONDS | C24: =[7]MVTSEPT!$F$69 -> 0 | E24: EMPRUNT FONDS | G24: =[7]MVTSEPT!$F$70 -> 0
A25: COLLATION | E25: COLLATION
A26: COMPLEMENT TONTINE T60000 | E26: COMPLEMENT TONTINE T60000
A27: FRAIS DE COMMUNICATION | E27: FRAIS DE COMMUNICATION
A28: DISTRIBUTION INTERET T100000 | E28: DISTRIBUTION INTERET T100000
A29: REMBOURSEMENT COMPLEMENT TONTINE T60000 | E29: REMBOURSEMENT COMPLEMENT TONTINE T60000
A30: EN CAISSE | E30: EN CAISSE
A31: NGONGANG JEAN THEODORE | E31: NGONGANG JEAN THEODORE
A32: TCHOUAMOU JEAN PAUL | E32: TCHOUAMOU JEAN PAUL
B71: =SUM(B5:B70) -> 0 | C71: =SUM(C5:C70) -> 0 | G71: =SUM(G5:G70) -> 0 | H71: =SUM(H5:H70) -> 0
C73: =B71-C71 -> 0

Sheet MVTFEV2018
A2: DATE | B2: 43149
A3: COMPTE CAISSE | E3: COMPTE BANQUE CCA
A4: LIBELLE | B4: ENTREE | C4: SORTIE | D4: CONTRE PARTIE | E4: LIBELLE | F4: CONTRE PARTIE | G4: SORTIE | H4: ENTREE
A6: TONTINE 25 000 | B6: =[5]TONTSEPT!$G$76 -> 0 | E6: TONTINE 25 000 | H6: =[5]TONTSEPT!$G$77 -> 0
A7: TONTINE 60 000 | B7: =[4]TONTSEPT!$C$36 -> 0 | E7: TONTINE 60 000 | H7: =[4]TONTSEPT!$C$37 -> 0
A8: TONTINE 100 000 | B8: =[3]TONTSEPT!$C$37 -> 0 | E8: TONTINE 100 000 | H8: =[3]TONTSEPT!$C$38 -> 0
A9: PENALITE RETARD | B9: =[5]TONTSEPT!$F$58 -> 0
A10: REMBBOURSEMENT PETIT LOT | E10: REMBBOURSEMENT PETIT LOT
A11: TONTINE 25 000 | B11: =[5]TONTSEPT!$H$76 -> 0 | E11: TONTINE 25 000 | H11: =[5]TONTSEPT!$H$77 -> 0
A12: TONTINE 60 000 | B12: =[4]TONTSEPT!$D$36 -> 0 | E12: TONTINE 60 000 | H12: =[4]TONTSEPT!$D$37 -> 0
A13: TONTINE 100 000 | B13: =[3]TONTSEPT!$D$37 -> 0 | E13: TONTINE 100 000 | H13: =[3]TONTSEPT!$D$38 -> 0
A14: ACHAT LOT PRINCIPAL | E14: ACHAT LOT PRINCIPAL
A15: TONTINE 25 000 | C15: =[5]TONTSEPT!$J$76 -> 0 | E15: TONTINE 25 000 | G15: =[5]TONTSEPT!$J$77 -> 0
A16: TONTINE 60 000 | E16: TONTINE 60 000
A17: TONTINE 100 000 | C17: =[3]TONTSEPT!$F$37 -> 0 | E17: TONTINE 100 000 | G17: =[3]TONTSEPT!$F$38 -> 0
A18: ACHAT PETIT LOT | E18: ACHAT PETIT LOT
A19: TONTINE 25 000 | C19: =[5]TONTSEPT!$F$59 -> 0 | E19: TONTINE 25 000 | G19: =[5]TONTSEPT!$F$59 -> 0
A20: TONTINE 60 000 | C20: =[4]TONTSEPT!$C$43 -> 0 | E20: TONTINE 60 000
A21: TONTINE 100 000 | C21: =[3]TONTSEPT!$E$37 -> 0 | E21: TONTINE 100 000 | G21: =+[3]TONTSEPT!$E$38 -> 0
A22: REMBBOURSEMENT PRÊT FONDS | B22: =[7]MVTSEPT!$G$69 -> 0 | E22: REMBBOURSEMENT PRÊT FONDS | H22: =[7]MVTSEPT!$G$70 -> 0
A23: RECONTITUTION FONDS | E23: RECONTITUTION FONDS
A24: EMPRUNT FONDS | C24: =[7]MVTSEPT!$F$69 -> 0 | E24: EMPRUNT FONDS | G24: =[7]MVTSEPT!$F$70 -> 0
A25: COLLATION | E25: COLLATION
A26: COMPLEMENT TONTINE T60000 | E26: COMPLEMENT TONTINE T60000
A27: FRAIS DE COMMUNICATION | E27: FRAIS DE COMMUNICATION
A28: DISTRIBUTION INTERET T100000 | E28: DISTRIBUTION INTERET T100000
A29: REMBOURSEMENT COMPLEMENT TONTINE T60000 | E29: REMBOURSEMENT COMPLEMENT TONTINE T60000
A30: EN CAISSE | E30: EN CAISSE
A31: NGONGANG JEAN THEODORE | E31: NGONGANG JEAN THEODORE
A32: TCHOUAMOU JEAN PAUL | E32: TCHOUAMOU JEAN PAUL
B71: =SUM(B5:B70) -> 0 | C71: =SUM(C5:C70) -> 0 | G71: =SUM(G5:G70) -> 0 | H71: =SUM(H5:H70) -> 0
C73: =B71-C71 -> 0

Sheet MVTMARS2018
A2: DATE | B2: 43177
A3: COMPTE CAISSE | E3: COMPTE BANQUE CCA
A4: LIBELLE | B4: ENTREE | C4: SORTIE | D4: CONTRE PARTIE | E4: LIBELLE | F4: CONTRE PARTIE | G4: SORTIE | H4: ENTREE
A6: TONTINE 25 000 | B6: =[5]TONTSEPT!$G$76 -> 0 | E6: TONTINE 25 000 | H6: =[5]TONTSEPT!$G$77 -> 0
A7: TONTINE 60 000 | B7: =[4]TONTSEPT!$C$36 -> 0 | E7: TONTINE 60 000 | H7: =[4]TONTSEPT!$C$37 -> 0
A8: TONTINE 100 000 | B8: =[3]TONTSEPT!$C$37 -> 0 | E8: TONTINE 100 000 | H8: =[3]TONTSEPT!$C$38 -> 0
A9: PENALITE RETARD | B9: =[5]TONTSEPT!$F$58 -> 0
A10: REMBBOURSEMENT PETIT LOT | E10: REMBBOURSEMENT PETIT LOT
A11: TONTINE 25 000 | B11: =[5]TONTSEPT!$H$76 -> 0 | E11: TONTINE 25 000 | H11: =[5]TONTSEPT!$H$77 -> 0
A12: TONTINE 60 000 | B12: =[4]TONTSEPT!$D$36 -> 0 | E12: TONTINE 60 000 | H12: =[4]TONTSEPT!$D$37 -> 0
A13: TONTINE 100 000 | B13: =[3]TONTSEPT!$D$37 -> 0 | E13: TONTINE 100 000 | H13: =[3]TONTSEPT!$D$38 -> 0
A14: ACHAT LOT PRINCIPAL | E14: ACHAT LOT PRINCIPAL
A15: TONTINE 25 000 | C15: =[5]TONTSEPT!$J$76 -> 0 | E15: TONTINE 25 000 | G15: =[5]TONTSEPT!$J$77 -> 0
A16: TONTINE 60 000 | E16: TONTINE 60 000
A17: TONTINE 100 000 | C17: =[3]TONTSEPT!$F$37 -> 0 | E17: TONTINE 100 000 | G17: =[3]TONTSEPT!$F$38 -> 0
A18: ACHAT PETIT LOT | E18: ACHAT PETIT LOT
A19: TONTINE 25 000 | C19: =[5]TONTSEPT!$F$59 -> 0 | E19: TONTINE 25 000 | G19: =[5]TONTSEPT!$F$59 -> 0
A20: TONTINE 60 000 | C20: =[4]TONTSEPT!$C$43 -> 0 | E20: TONTINE 60 000
A21: TONTINE 100 000 | C21: =[3]TONTSEPT!$E$37 -> 0 | E21: TONTINE 100 000 | G21: =+[3]TONTSEPT!$E$38 -> 0
A22: REMBBOURSEMENT PRÊT FONDS | B22: =[7]MVTSEPT!$G$69 -> 0 | E22: REMBBOURSEMENT PRÊT FONDS | H22: =[7]MVTSEPT!$G$70 -> 0
A23: RECONTITUTION FONDS | E23: RECONTITUTION FONDS
A24: EMPRUNT FONDS | C24: =[7]MVTSEPT!$F$69 -> 0 | E24: EMPRUNT FONDS | G24: =[7]MVTSEPT!$F$70 -> 0
A25: COLLATION | E25: COLLATION
A26: COMPLEMENT TONTINE T60000 | E26: COMPLEMENT TONTINE T60000
A27: FRAIS DE COMMUNICATION | E27: FRAIS DE COMMUNICATION
A28: DISTRIBUTION INTERET T100000 | E28: DISTRIBUTION INTERET T100000
A29: REMBOURSEMENT COMPLEMENT TONTINE T60000 | E29: REMBOURSEMENT COMPLEMENT TONTINE T60000
A30: EN CAISSE | E30: EN CAISSE
A31: NGONGANG JEAN THEODORE | E31: NGONGANG JEAN THEODORE
A32: TCHOUAMOU JEAN PAUL | E32: TCHOUAMOU JEAN PAUL
B71: =SUM(B5:B70) -> 0 | C71: =SUM(C5:C70) -> 0 | G71: =SUM(G5:G70) -> 0 | H71: =SUM(H5:H70) -> 0
C73: =B71-C71 -> 0

Sheet MVTAVRIL2018
A2: DATE | B2: 43212
A3: COMPTE CAISSE | E3: COMPTE BANQUE CCA
A4: LIBELLE | B4: ENTREE | C4: SORTIE | D4: CONTRE PARTIE | E4: LIBELLE | F4: CONTRE PARTIE | G4: SORTIE | H4: ENTREE
A6: TONTINE 25 000 | B6: =[5]TONTSEPT!$G$76 -> 0 | E6: TONTINE 25 000 | H6: =[5]TONTSEPT!$G$77 -> 0
A7: TONTINE 60 000 | B7: =[4]TONTSEPT!$C$36 -> 0 | E7: TONTINE 60 000 | H7: =[4]TONTSEPT!$C$37 -> 0
A8: TONTINE 100 000 | B8: =[3]TONTSEPT!$C$37 -> 0 | E8: TONTINE 100 000 | H8: =[3]TONTSEPT!$C$38 -> 0
A9: PENALITE RETARD | B9: =[5]TONTSEPT!$F$58 -> 0
A10: REMBBOURSEMENT PETIT LOT | E10: REMBBOURSEMENT PETIT LOT
A11: TONTINE 25 000 | B11: =[5]TONTSEPT!$H$76 -> 0 | E11: TONTINE 25 000 | H11: =[5]TONTSEPT!$H$77 -> 0
A12: TONTINE 60 000 | B12: =[4]TONTSEPT!$D$36 -> 0 | E12: TONTINE 60 000 | H12: =[4]TONTSEPT!$D$37 -> 0
A13: TONTINE 100 000 | B13: =[3]TONTSEPT!$D$37 -> 0 | E13: TONTINE 100 000 | H13: =[3]TONTSEPT!$D$38 -> 0
A14: ACHAT LOT PRINCIPAL | E14: ACHAT LOT PRINCIPAL
A15: TONTINE 25 000 | C15: =[5]TONTSEPT!$J$76 -> 0 | E15: TONTINE 25 000 | G15: =[5]TONTSEPT!$J$77 -> 0
A16: TONTINE 60 000 | E16: TONTINE 60 000
A17: TONTINE 100 000 | C17: =[3]TONTSEPT!$F$37 -> 0 | E17: TONTINE 100 000 | G17: =[3]TONTSEPT!$F$38 -> 0
A18: ACHAT PETIT LOT | E18: ACHAT PETIT LOT
A19: TONTINE 25 000 | C19: =[5]TONTSEPT!$F$59 -> 0 | E19: TONTINE 25 000 | G19: =[5]TONTSEPT!$F$59 -> 0
A20: TONTINE 60 000 | C20: =[4]TONTSEPT!$C$43 -> 0 | E20: TONTINE 60 000
A21: TONTINE 100 000 | C21: =[3]TONTSEPT!$E$37 -> 0 | E21: TONTINE 100 000 | G21: =+[3]TONTSEPT!$E$38 -> 0
A22: REMBBOURSEMENT PRÊT FONDS | B22: =[7]MVTSEPT!$G$69 -> 0 | E22: REMBBOURSEMENT PRÊT FONDS | H22: =[7]MVTSEPT!$G$70 -> 0
A23: RECONTITUTION FONDS | E23: RECONTITUTION FONDS
A24: EMPRUNT FONDS | C24: =[7]MVTSEPT!$F$69 -> 0 | E24: EMPRUNT FONDS | G24: =[7]MVTSEPT!$F$70 -> 0
A25: COLLATION | E25: COLLATION
A26: COMPLEMENT TONTINE T60000 | E26: COMPLEMENT TONTINE T60000
A27: FRAIS DE COMMUNICATION | E27: FRAIS DE COMMUNICATION
A28: DISTRIBUTION INTERET T100000 | E28: DISTRIBUTION INTERET T100000
A29: REMBOURSEMENT COMPLEMENT TONTINE T60000 | E29: REMBOURSEMENT COMPLEMENT TONTINE T60000
A30: EN CAISSE | E30: EN CAISSE
A31: NGONGANG JEAN THEODORE | E31: NGONGANG JEAN THEODORE
A32: TCHOUAMOU JEAN PAUL | E32: TCHOUAMOU JEAN PAUL
B71: =SUM(B5:B70) -> 0 | C71: =SUM(C5:C70) -> 0 | G71: =SUM(G5:G70) -> 0 | H71: =SUM(H5:H70) -> 0
C73: =B71-C71 -> 0

Sheet MVTMAI2018
A2: DATE | B2: 43240
A3: COMPTE CAISSE | E3: COMPTE BANQUE CCA
A4: LIBELLE | B4: ENTREE | C4: SORTIE | D4: CONTRE PARTIE | E4: LIBELLE | F4: CONTRE PARTIE | G4: SORTIE | H4: ENTREE
A6: TONTINE 25 000 | B6: =[5]TONTSEPT!$G$76 -> 0 | E6: TONTINE 25 000 | H6: =[5]TONTSEPT!$G$77 -> 0
A7: TONTINE 60 000 | B7: =[4]TONTSEPT!$C$36 -> 0 | E7: TONTINE 60 000 | H7: =[4]TONTSEPT!$C$37 -> 0
A8: TONTINE 100 000 | B8: =[3]TONTSEPT!$C$37 -> 0 | E8: TONTINE 100 000 | H8: =[3]TONTSEPT!$C$38 -> 0
A9: PENALITE RETARD | B9: =[5]TONTSEPT!$F$58 -> 0
A10: REMBBOURSEMENT PETIT LOT | E10: REMBBOURSEMENT PETIT LOT
A11: TONTINE 25 000 | B11: =[5]TONTSEPT!$H$76 -> 0 | E11: TONTINE 25 000 | H11: =[5]TONTSEPT!$H$77 -> 0
A12: TONTINE 60 000 | B12: =[4]TONTSEPT!$D$36 -> 0 | E12: TONTINE 60 000 | H12: =[4]TONTSEPT!$D$37 -> 0
A13: TONTINE 100 000 | B13: =[3]TONTSEPT!$D$37 -> 0 | E13: TONTINE 100 000 | H13: =[3]TONTSEPT!$D$38 -> 0
A14: ACHAT LOT PRINCIPAL | E14: ACHAT LOT PRINCIPAL
A15: TONTINE 25 000 | C15: =[5]TONTSEPT!$J$76 -> 0 | E15: TONTINE 25 000 | G15: =[5]TONTSEPT!$J$77 -> 0
A16: TONTINE 60 000 | E16: TONTINE 60 000
A17: TONTINE 100 000 | C17: =[3]TONTSEPT!$F$37 -> 0 | E17: TONTINE 100 000 | G17: =[3]TONTSEPT!$F$38 -> 0
A18: ACHAT PETIT LOT | E18: ACHAT PETIT LOT
A19: TONTINE 25 000 | C19: =[5]TONTSEPT!$F$59 -> 0 | E19: TONTINE 25 000 | G19: =[5]TONTSEPT!$F$59 -> 0
A20: TONTINE 60 000 | C20: =[4]TONTSEPT!$C$43 -> 0 | E20: TONTINE 60 000
A21: TONTINE 100 000 | C21: =[3]TONTSEPT!$E$37 -> 0 | E21: TONTINE 100 000 | G21: =+[3]TONTSEPT!$E$38 -> 0
A22: REMBBOURSEMENT PRÊT FONDS | B22: =[7]MVTSEPT!$G$69 -> 0 | E22: REMBBOURSEMENT PRÊT FONDS | H22: =[7]MVTSEPT!$G$70 -> 0
A23: RECONTITUTION FONDS | E23: RECONTITUTION FONDS
A24: EMPRUNT FONDS | C24: =[7]MVTSEPT!$F$69 -> 0 | E24: EMPRUNT FONDS | G24: =[7]MVTSEPT!$F$70 -> 0
A25: COLLATION | E25: COLLATION
A26: COMPLEMENT TONTINE T60000 | E26: COMPLEMENT TONTINE T60000
A27: FRAIS DE COMMUNICATION | E27: FRAIS DE COMMUNICATION
A28: DISTRIBUTION INTERET T100000 | E28: DISTRIBUTION INTERET T100000
A29: REMBOURSEMENT COMPLEMENT TONTINE T60000 | E29: REMBOURSEMENT COMPLEMENT TONTINE T60000
A30: EN CAISSE | E30: EN CAISSE
A31: NGONGANG JEAN THEODORE | E31: NGONGANG JEAN THEODORE
A32: TCHOUAMOU JEAN PAUL | E32: TCHOUAMOU JEAN PAUL
B71: =SUM(B5:B70) -> 0 | C71: =SUM(C5:C70) -> 0 | G71: =SUM(G5:G70) -> 0 | H71: =SUM(H5:H70) -> 0
C73: =B71-C71 -> 0

Sheet MVTJUIN2018
A2: DATE | B2: 17/20/2018
A3: COMPTE CAISSE | E3: COMPTE BANQUE CCA
A4: LIBELLE | B4: ENTREE | C4: SORTIE | D4: CONTRE PARTIE | E4: LIBELLE | F4: CONTRE PARTIE | G4: SORTIE | H4: ENTREE
A6: TONTINE 25 000 | B6: =[5]TONTSEPT!$G$76 -> 0 | E6: TONTINE 25 000 | H6: =[5]TONTSEPT!$G$77 -> 0
A7: TONTINE 60 000 | B7: =[4]TONTSEPT!$C$36 -> 0 | E7: TONTINE 60 000 | H7: =[4]TONTSEPT!$C$37 -> 0
A8: TONTINE 100 000 | B8: =[3]TONTSEPT!$C$37 -> 0 | E8: TONTINE 100 000 | H8: =[3]TONTSEPT!$C$38 -> 0
A9: PENALITE RETARD | B9: =[5]TONTSEPT!$F$58 -> 0
A10: REMBBOURSEMENT PETIT LOT | E10: REMBBOURSEMENT PETIT LOT
A11: TONTINE 25 000 | B11: =[5]TONTSEPT!$H$76 -> 0 | E11: TONTINE 25 000 | H11: =[5]TONTSEPT!$H$77 -> 0
A12: TONTINE 60 000 | B12: =[4]TONTSEPT!$D$36 -> 0 | E12: TONTINE 60 000 | H12: =[4]TONTSEPT!$D$37 -> 0
A13: TONTINE 100 000 | B13: =[3]TONTSEPT!$D$37 -> 0 | E13: TONTINE 100 000 | H13: =[3]TONTSEPT!$D$38 -> 0
A14: ACHAT LOT PRINCIPAL | E14: ACHAT LOT PRINCIPAL
A15: TONTINE 25 000 | C15: =[5]TONTSEPT!$J$76 -> 0 | E15: TONTINE 25 000 | G15: =[5]TONTSEPT!$J$77 -> 0
A16: TONTINE 60 000 | E16: TONTINE 60 000
A17: TONTINE 100 000 | C17: =[3]TONTSEPT!$F$37 -> 0 | E17: TONTINE 100 000 | G17: =[3]TONTSEPT!$F$38 -> 0
A18: ACHAT PETIT LOT | E18: ACHAT PETIT LOT
A19: TONTINE 25 000 | C19: =[5]TONTSEPT!$F$59 -> 0 | E19: TONTINE 25 000 | G19: =[5]TONTSEPT!$F$59 -> 0
A20: TONTINE 60 000 | C20: =[4]TONTSEPT!$C$43 -> 0 | E20: TONTINE 60 000
A21: TONTINE 100 000 | C21: =[3]TONTSEPT!$E$37 -> 0 | E21: TONTINE 100 000 | G21: =+[3]TONTSEPT!$E$38 -> 0
A22: REMBBOURSEMENT PRÊT FONDS | B22: =[7]MVTSEPT!$G$69 -> 0 | E22: REMBBOURSEMENT PRÊT FONDS | H22: =[7]MVTSEPT!$G$70 -> 0
A23: RECONTITUTION FONDS | E23: RECONTITUTION FONDS
A24: EMPRUNT FONDS | C24: =[7]MVTSEPT!$F$69 -> 0 | E24: EMPRUNT FONDS | G24: =[7]MVTSEPT!$F$70 -> 0
A25: COLLATION | E25: COLLATION
A26: COMPLEMENT TONTINE T60000 | E26: COMPLEMENT TONTINE T60000
A27: FRAIS DE COMMUNICATION | E27: FRAIS DE COMMUNICATION
A28: DISTRIBUTION INTERET T100000 | E28: DISTRIBUTION INTERET T100000
A29: REMBOURSEMENT COMPLEMENT TONTINE T60000 | E29: REMBOURSEMENT COMPLEMENT TONTINE T60000
A30: EN CAISSE | E30: EN CAISSE
A31: NGONGANG JEAN THEODORE | E31: NGONGANG JEAN THEODORE
A32: TCHOUAMOU JEAN PAUL | E32: TCHOUAMOU JEAN PAUL
B71: =SUM(B5:B70) -> 0 | C71: =SUM(C5:C70) -> 0 | G71: =SUM(G5:G70) -> 0 | H71: =SUM(H5:H70) -> 0
C73: =B71-C71 -> 0

Sheet MVTJUIL2018
A2: DATE | B2: 43296
A3: COMPTE CAISSE | E3: COMPTE BANQUE CCA
A4: LIBELLE | B4: ENTREE | C4: SORTIE | D4: CONTRE PARTIE | E4: LIBELLE | F4: CONTRE PARTIE | G4: SORTIE | H4: ENTREE
A6: TONTINE 25 000 | B6: =[5]TONTSEPT!$G$76 -> 0 | E6: TONTINE 25 000 | H6: =[5]TONTSEPT!$G$77 -> 0
A7: TONTINE 60 000 | B7: =[4]TONTSEPT!$C$36 -> 0 | E7: TONTINE 60 000 | H7: =[4]TONTSEPT!$C$37 -> 0
A8: TONTINE 100 000 | B8: =[3]TONTSEPT!$C$37 -> 0 | E8: TONTINE 100 000 | H8: =[3]TONTSEPT!$C$38 -> 0
A9: PENALITE RETARD | B9: =[5]TONTSEPT!$F$58 -> 0
A10: REMBBOURSEMENT PETIT LOT | E10: REMBBOURSEMENT PETIT LOT
A11: TONTINE 25 000 | B11: =[5]TONTSEPT!$H$76 -> 0 | E11: TONTINE 25 000 | H11: =[5]TONTSEPT!$H$77 -> 0
A12: TONTINE 60 000 | B12: =[4]TONTSEPT!$D$36 -> 0 | E12: TONTINE 60 000 | H12: =[4]TONTSEPT!$D$37 -> 0
A13: TONTINE 100 000 | B13: =[3]TONTSEPT!$D$37 -> 0 | E13: TONTINE 100 000 | H13: =[3]TONTSEPT!$D$38 -> 0
A14: ACHAT LOT PRINCIPAL | E14: ACHAT LOT PRINCIPAL
A15: TONTINE 25 000 | C15: =[5]TONTSEPT!$J$76 -> 0 | E15: TONTINE 25 000 | G15: =[5]TONTSEPT!$J$77 -> 0
A16: TONTINE 60 000 | E16: TONTINE 60 000
A17: TONTINE 100 000 | C17: =[3]TONTSEPT!$F$37 -> 0 | E17: TONTINE 100 000 | G17: =[3]TONTSEPT!$F$38 -> 0
A18: ACHAT PETIT LOT | E18: ACHAT PETIT LOT
A19: TONTINE 25 000 | C19: =[5]TONTSEPT!$F$59 -> 0 | E19: TONTINE 25 000 | G19: =[5]TONTSEPT!$F$59 -> 0
A20: TONTINE 60 000 | C20: =[4]TONTSEPT!$C$43 -> 0 | E20: TONTINE 60 000
A21: TONTINE 100 000 | C21: =[3]TONTSEPT!$E$37 -> 0 | E21: TONTINE 100 000 | G21: =+[3]TONTSEPT!$E$38 -> 0
A22: REMBBOURSEMENT PRÊT FONDS | B22: =[7]MVTSEPT!$G$69 -> 0 | E22: REMBBOURSEMENT PRÊT FONDS | H22: =[7]MVTSEPT!$G$70 -> 0
A23: RECONTITUTION FONDS | E23: RECONTITUTION FONDS
A24: EMPRUNT FONDS | C24: =[7]MVTSEPT!$F$69 -> 0 | E24: EMPRUNT FONDS | G24: =[7]MVTSEPT!$F$70 -> 0
A25: COLLATION | E25: COLLATION
A26: COMPLEMENT TONTINE T60000 | E26: COMPLEMENT TONTINE T60000
A27: FRAIS DE COMMUNICATION | E27: FRAIS DE COMMUNICATION
A28: DISTRIBUTION INTERET T100000 | E28: DISTRIBUTION INTERET T100000
A29: REMBOURSEMENT COMPLEMENT TONTINE T60000 | E29: REMBOURSEMENT COMPLEMENT TONTINE T60000
A30: EN CAISSE | E30: EN CAISSE
A31: NGONGANG JEAN THEODORE | E31: NGONGANG JEAN THEODORE
A32: TCHOUAMOU JEAN PAUL | E32: TCHOUAMOU JEAN PAUL
B71: =SUM(B5:B70) -> 0 | C71: =SUM(C5:C70) -> 0 | G71: =SUM(G5:G70) -> 0 | H71: =SUM(H5:H70) -> 0
C73: =B71-C71 -> 0

Sheet MVTAOUT2018
A2: DATE | B2: 19/20/2018
A3: COMPTE CAISSE | E3: COMPTE BANQUE CCA
A4: LIBELLE | B4: ENTREE | C4: SORTIE | D4: CONTRE PARTIE | E4: LIBELLE | F4: CONTRE PARTIE | G4: SORTIE | H4: ENTREE
A6: TONTINE 25 000 | B6: =[5]TONTSEPT!$G$76 -> 0 | E6: TONTINE 25 000 | H6: =[5]TONTSEPT!$G$77 -> 0
A7: TONTINE 60 000 | B7: =[4]TONTSEPT!$C$36 -> 0 | E7: TONTINE 60 000 | H7: =[4]TONTSEPT!$C$37 -> 0
A8: TONTINE 100 000 | B8: =[3]TONTSEPT!$C$37 -> 0 | E8: TONTINE 100 000 | H8: =[3]TONTSEPT!$C$38 -> 0
A9: PENALITE RETARD | B9: =[5]TONTSEPT!$F$58 -> 0
A10: REMBBOURSEMENT PETIT LOT | E10: REMBBOURSEMENT PETIT LOT
A11: TONTINE 25 000 | B11: =[5]TONTSEPT!$H$76 -> 0 | E11: TONTINE 25 000 | H11: =[5]TONTSEPT!$H$77 -> 0
A12: TONTINE 60 000 | B12: =[4]TONTSEPT!$D$36 -> 0 | E12: TONTINE 60 000 | H12: =[4]TONTSEPT!$D$37 -> 0
A13: TONTINE 100 000 | B13: =[3]TONTSEPT!$D$37 -> 0 | E13: TONTINE 100 000 | H13: =[3]TONTSEPT!$D$38 -> 0
A14: ACHAT LOT PRINCIPAL | E14: ACHAT LOT PRINCIPAL
A15: TONTINE 25 000 | C15: =[5]TONTSEPT!$J$76 -> 0 | E15: TONTINE 25 000 | G15: =[5]TONTSEPT!$J$77 -> 0
A16: TONTINE 60 000 | E16: TONTINE 60 000
A17: TONTINE 100 000 | C17: =[3]TONTSEPT!$F$37 -> 0 | E17: TONTINE 100 000 | G17: =[3]TONTSEPT!$F$38 -> 0
A18: ACHAT PETIT LOT | E18: ACHAT PETIT LOT
A19: TONTINE 25 000 | C19: =[5]TONTSEPT!$F$59 -> 0 | E19: TONTINE 25 000 | G19: =[5]TONTSEPT!$F$59 -> 0
A20: TONTINE 60 000 | C20: =[4]TONTSEPT!$C$43 -> 0 | E20: TONTINE 60 000
A21: TONTINE 100 000 | C21: =[3]TONTSEPT!$E$37 -> 0 | E21: TONTINE 100 000 | G21: =+[3]TONTSEPT!$E$38 -> 0
A22: REMBBOURSEMENT PRÊT FONDS | B22: =[7]MVTSEPT!$G$69 -> 0 | E22: REMBBOURSEMENT PRÊT FONDS | H22: =[7]MVTSEPT!$G$70 -> 0
A23: RECONTITUTION FONDS | E23: RECONTITUTION FONDS
A24: EMPRUNT FONDS | C24: =[7]MVTSEPT!$F$69 -> 0 | E24: EMPRUNT FONDS | G24: =[7]MVTSEPT!$F$70 -> 0
A25: COLLATION | E25: COLLATION
A26: COMPLEMENT TONTINE T60000 | E26: COMPLEMENT TONTINE T60000
A27: FRAIS DE COMMUNICATION | E27: FRAIS DE COMMUNICATION
A28: DISTRIBUTION INTERET T100000 | E28: DISTRIBUTION INTERET T100000
A29: REMBOURSEMENT COMPLEMENT TONTINE T60000 | E29: REMBOURSEMENT COMPLEMENT TONTINE T60000
A30: EN CAISSE | E30: EN CAISSE
A31: NGONGANG JEAN THEODORE | E31: NGONGANG JEAN THEODORE
A32: TCHOUAMOU JEAN PAUL | E32: TCHOUAMOU JEAN PAUL
B71: =SUM(B5:B70) -> 0 | C71: =SUM(C5:C70) -> 0 | G71: =SUM(G5:G70) -> 0 | H71: =SUM(H5:H70) -> 0
C73: =B71-C71 -> 0
