Workbook
Name MODEPAID: [1]Feuil2!$A$1:$A$3

Sheet LISTADHERENT
A1: ASELBY
A2: LISTE DES ADHERENTS 19 JUN 2016
A4: MLE | B4: NOM ET PRENOM | C4: FONCTION | D4: DATE ADHESION | E4: CONTACT | F4: CONTACT 2 | G4: RESIDENCE | H4: DATE RECEPTION
A5: AS201601 | B5: BAKOP ACHILLE | C5: FONCTIONNAIRE DE POLICE | E5: 677841881 | G5: NKOLBISSON | H5: 42887
A6: AS201602 | B6: BOUTCHOUANG WILLIAM | C6: OPERATEUR ECONOMIQUE | E6: 677704694 | G6: EMANA | H6: 43191
A7: AS201603 | B7: CHINGUE FABRICE | C7: OPERATEUR ECONOMIQUE | E7: 677881912 | G7: SANTA BARBARA | H7: 43466
A8: AS201604 | B8: DJOMO JEAN PAUL | C8: RETRAITE | E8: 677986676 | G8: RUE MANGUIERS | H8: 43132
A9: AS201605 | B9: DJOUKWE GUY | C9: PROFESSEUR DES LYCEES TECHNIQUE | E9: 675250451 | G9: RUE MANGUIERS | H9: 43313
A10: AS201606 | B10: DJOSSEU JOSUE | C10: PROFESSEUR DES LYCEES TECHNIQUE | E10: 675250451 | G10: RUE MANGUIERS | H10: 43313
A11: AS201607 | B11: DJOUNKEP SAMUEL | C11: COMPTABLE RETRAITE | E11: 697103557 | G11: BIYEM ASSI LYCEE | H11: 42401
A12: AS201608 | B12: DJUOMBESSY ANTOINE | C12: ANALYSTE CONCEPTEUR SI | E12: 677501239 | F12: 699324095 | G12: MESSASSI | H12: 43647
A13: AS201609 | B13: DONHOU DAVID | C13: MAGISTRAT | E13: 699908065 | G13: TONGOLO | H13: 42979
A14: AS201610 | B14: FOTSO THOMAS | C14: CADRE BANQUE | E14: 677910278 | G14: OYOMABANG | H14: 43344
A15: AS201611 | B15: HENGUE PAUL OMER | C15: SOCIOLOGUE | E15: 694468080 | G15: MESSASSI | H15: 42583
A16: AS201612 | B16: HODIEP JULES | C16: CADRE CNPS | E16: 675291170 | G16: NYOM 2 | H16: 43009
A17: AS201613 | B17: HOTCHO BENJAMIN | C17: COMPTABLE | E17: 699956355 | G17: DAMAS | H17: 42614
A18: AS201614 | B18: KEPHE DAVID | C18: OPERATEUR ECONOMIQUE | E18: 677053815 | G18: MESSASSI | H18: 43374
A19: AS201615 | B19: KEPSEU FRANCIS | C19: OFFICIER DE POLICE RETRAITE | E19: 699528700 | G19: SIMBOCK | H19: 43405
A20: AS201616 | B20: KOUAMOU EMMANUEL | C20: OPERATEUR ECONOMIQUE | E20: 699335584 | G20: MONTEE JOUVENCE | H20: 42795
A21: AS201617 | B21: KOUAMOU MOISE | C21: INGENIEUR E-F | E21: 675836725 | G21: DAMAS | H21: 42370
A22: AS201618 | B22: KOUAMOU VICTOR PEGUY | C22: S/OFFICIER SUPERIEUR | E22: 696564847 | G22: MESSASSI | H22: 43617
A23: AS201619 | B23: KOUATCHO MESSACK | C23: INSPECTEUR DE TRAVAIL | E23: 677735778 | G23: SANTA BARBARA | H23: 42644
A24: AS201620 | B24: LOWE JEAN | C24: PROFESSEUR DE LYCEE
A25: AS201621 | B25: NANKAM APPOLINAIRE | C25: ENSEIGNANT | E25: 693055118 | G25: DAMAS | H25: 43678
A26: AS201622 | B26: NDJOMO ETIENNE | C26: COMPTABLE | E26: 677553702 | G26: MONTEE JOUVENCE | H26: 42705
A27: AS201623 | B27: NDOMBOU JEAN CLAUDE | C27: ING AGRONOME RETRAITE | E27: 699358350 | G27: ETOUG EBE | H27: 42767
A28: AS201624 | B28: NGONDIEP CLAUDE | C28: DAS(DIRECTEUR ADMINISTRATEUR SOCIETE) | E28: 675249207 | G28: CITE VERTE | H28: 43070
A29: AS201625 | B29: NGONGANG JEAN THEODORE | C29: CHEF ENTREPRISE | E29: 677766503 | G29: RUE MANGUIERS | H29: 42491
A30: AS201626 | B30: NGUIEMEGNI MATHIEU BLAISE | C30: CADRE CADASTRE | E30: 677068360 | G30: MONATELE | H30: 43101
A31: AS201627 | B31: NJEPDJIO MBOUKAM DELUXE | C31: OPERATEUR ECONOMIQUE | E31: 670909070 | G31: MENDONG | H31: 43586
A32: AS201628 | B32: NKAMGANG JUSTIN DEJOLIE | C32: DELEGUE COMMERCIAL | E32: 676659191 | G32: MENDONG | H32: 43497
A33: AS201629 | B33: NKEPSEU DIEUDONNE | C33: OPERATEUR ECONOMIQUE | E33: 677575366 | G33: ESSOS | H33: 42917
A34: AS201630 | B34: NKEPSEU HENANG RENE | C34: CADRE SONEL RETRAITE | E34: 699843118 | G34: BIYEM ASSI LYCEE | H34: 42522
A35: AS201631 | B35: NTEPDIE TUEMAC MZ | C35: OPERATEUR ECONOMIQUE | E35: 677377251 | G35: MONTEE JOUVENCE | H35: 43282
A36: AS201632 | B36: NTOMBOU ADOLPHE | C36: INGENIEUR | E36: 677867173 | G36: BIYEM ASSI LYCEE | H36: 42461
... A51: AS201647 | B51: YOUMBI EMMANUEL | C51: PROFESSEUR DES UNIVERSITES | E51: 677547311 | G51: MENDONG (GUINNESS) | H51: 42675

Sheet RECAPTONT20000
A1: ASSOCIATION | B1: ASELBY
A2: ANNEE | B2: 2016/2017
A3: TONTINE | B3: 20 000
A4: MATRICULE | B4: NOM ET PRENOM | C4: FONDS | D4: RELIQUAT 2015 | E4: SANCTION | F4: MONTANT VERSE | G4: EPARGNE | H4: FONDS DE ROULEMENT | I4: FRAIS EXCEPTIONNEL | J4: COLLATION | K4: MUTUELLE | L4: TONTINE | M4: EMPRUNT | N4: INTERET EMPRUNT | O4: REMBOURSEMENT | P4: PENALITE EMPRUNT | Q4: PENALITE FONDS | R4: INTERET ACHAT | S4: DATE ACHAT
A5: AS201601 | B5: =VLOOKUP(A5,LISTADHERENT!A$5:H$51,2) -> BAKOP ACHILLE | C5: 390000 | D5: 33536 | F5: =G5+H5+I5+J5+K5+L5+Q5 -> 225000 | G5: =TONT20000DEC2015!D5+TONT20000JANV!D5+TONT20000FEV!D5+TONT20000MARS!D5+TONT20000AVRIL!D5+TONT20000MAI!D5+TONT20000JUIN!D5+TONT20000JUIL!D5+TONT20000AOUT!D5+TONT20000SEPT!D5+TONT20000OCT!D5+TONT20000NOV!D5 -> 30000 | H5: =TONT20000DEC2015!E5+TONT20000JANV!E5+TONT20000FEV!E5+TONT20000MARS!E5+TONT20000AVRIL!E5+TONT20000MAI!E5+TONT20000JUIN!E5+TONT20000JUIL!E5+TONT20000AOUT!E5+TONT20000SEPT!E5+TONT20000OCT!E5+TONT20000NOV!E5 -> 5000 | I5: =TONT20000DEC2015!F5+TONT20000JANV!F5+TONT20000FEV!F5+TONT20000MARS!F5+TONT20000AVRIL!F5+TONT20000MAI!F5+TONT20000JUIN!F5+TONT20000JUIL!F5+TONT20000AOUT!F5+TONT20000SEPT!F5+TONT20000OCT!F5+TONT20000NOV!F5 -> 10000 | J5: =TONT20000DEC2015!G5+TONT20000JANV!G5+TONT20000FEV!G5+TONT20000MARS!G5+TONT20000AVRIL!G5+TONT20000MAI!G5+TONT20000JUIN!G5+TONT20000JUIL!G5+TONT20000AOUT!G5+TONT20000SEPT!G5+TONT20000OCT!G5+TONT20000NOV!G5 -> 25000 | K5: =TONT20000DEC2015!H5+TONT20000JANV!H5+TONT20000FEV!H5+TONT20000MARS!H5+TONT20000AVRIL!H5+TONT20000MAI!H5+TONT20000JUIN!H5+TONT20000JUIL!H5+TONT20000AOUT!H5+TONT20000SEPT!H5+TONT20000OCT!H5+TONT20000NOV!H5 -> 25000 | L5: =TONT20000DEC2015!I5+TONT20000JANV!I5+TONT20000FEV!I5+TONT20000MARS!I5+TONT20000AVRIL!I5+TONT20000MAI!I5+TONT20000JUIN!I5+TONT20000JUIL!I5+TONT20000AOUT!I5+TONT20000SEPT!I5+TONT20000OCT!I5+TONT20000NOV!I5 -> 130000 | M5: =TONT20000DEC2015!J5+TONT20000JANV!J5+TONT20000FEV!J5+TONT20000MARS!J5+TONT20000AVRIL!J5+TONT20000MAI!J5+TONT20000JUIN!J5+TONT20000JUIL!J5+TONT20000AOUT!J5+TONT20000SEPT!J5+TONT20000OCT!J5+TONT20000NOV!J5 -> 500000 | N5: =TONT20000DEC2015!K5+TONT20000JANV!K5+TONT20000FEV!K5+TONT20000MARS!K5+TONT20000AVRIL!K5+TONT20000MAI!K5+TONT20000JUIN!K5+TONT20000JUIL!K5+TONT20000AOUT!K5+TONT20000SEPT!K5+TONT20000OCT!K5+TONT20000NOV!K5 -> 15000 | O5: =TONT20000DEC2015!L5+TONT20000JANV!L5+TONT20000FEV!L5+TONT20000MARS!L5+TONT20000AVRIL!L5+TONT20000MAI!L5+TONT20000JUIN!L5+TONT20000JUIL!L5+TONT20000AOUT!L5+TONT20000SEPT!L5+TONT20000OCT!L5+TONT20000NOV!L5 -> 0 | P5: =TONT20000DEC2015!M5+TONT20000JANV!M5+TONT20000FEV!M5+TONT20000MARS!M5+TONT20000AVRIL!M5+TONT20000MAI!M5+TONT20000JUIN!M5+TONT20000JUIL!M5+TONT20000AOUT!M5+TONT20000SEPT!N5+TONT20000OCT!M5+TONT20000NOV!M5 -> 0 | Q5: =TONT20000DEC2015!M5+TONT20000JANV!M5+TONT20000FEV!M5+TONT20000MARS!M5+TONT20000AVRIL!M5+TONT20000MAI!M5+TONT20000JUIN!M5+TONT20000JUIL!M5+TONT20000AOUT!M5+TONT20000SEPT!N5+TONT20000OCT!M5+TONT20000NOV!M5 -> 0
A6: AS201602 | B6: =VLOOKUP(A6,LISTADHERENT!A$5:H$51,2) -> BOUTCHOUANG WILLIAM | C6: 390000 | D6: 1704 | F6: =G6+H6+I6+J6+K6+L6+Q6 -> 240000 | G6: =TONT20000DEC2015!D6+TONT20000JANV!D6+TONT20000FEV!D6+TONT20000MARS!D6+TONT20000AVRIL!D6+TONT20000MAI!D6+TONT20000JUIN!D6+TONT20000JUIL!D6+TONT20000AOUT!D6+TONT20000SEPT!D6+TONT20000OCT!D6+TONT20000NOV!D6 -> 36000 | H6: =TONT20000DEC2015!E6+TONT20000JANV!E6+TONT20000FEV!E6+TONT20000MARS!E6+TONT20000AVRIL!E6+TONT20000MAI!E6+TONT20000JUIN!E6+TONT20000JUIL!E6+TONT20000AOUT!E6+TONT20000SEPT!E6+TONT20000OCT!E6+TONT20000NOV!E6 -> 6000 | I6: =TONT20000DEC2015!F6+TONT20000JANV!F6+TONT20000FEV!F6+TONT20000MARS!F6+TONT20000AVRIL!F6+TONT20000MAI!F6+TONT20000JUIN!F6+TONT20000JUIL!F6+TONT20000AOUT!F6+TONT20000SEPT!F6+TONT20000OCT!F6+TONT20000NOV!F6 -> 12000 | J6: =TONT20000DEC2015!G6+TONT20000JANV!G6+TONT20000FEV!G6+TONT20000MARS!G6+TONT20000AVRIL!G6+TONT20000MAI!G6+TONT20000JUIN!G6+TONT20000JUIL!G6+TONT20000AOUT!G6+TONT20000SEPT!G6+TONT20000OCT!G6+TONT20000NOV!G6 -> 30000 | K6: =TONT20000DEC2015!H6+TONT20000JANV!H6+TONT20000FEV!H6+TONT20000MARS!H6+TONT20000AVRIL!H6+TONT20000MAI!H6+TONT20000JUIN!H6+TONT20000JUIL!H6+TONT20000AOUT!H6+TONT20000SEPT!H6+TONT20000OCT!H6+TONT20000NOV!H6 -> 0 | L6: =TONT20000DEC2015!I6+TONT20000JANV!I6+TONT20000FEV!I6+TONT20000MARS!I6+TONT20000AVRIL!I6+TONT20000MAI!I6+TONT20000JUIN!I6+TONT20000JUIL!I6+TONT20000AOUT!I6+TONT20000SEPT!I6+TONT20000OCT!I6+TONT20000NOV!I6 -> 156000 | M6: =TONT20000DEC2015!J6+TONT20000JANV!J6+TONT20000FEV!J6+TONT20000MARS!J6+TONT20000AVRIL!J6+TONT20000MAI!J6+TONT20000JUIN!J6+TONT20000JUIL!J6+TONT20000AOUT!J6+TONT20000SEPT!J6+TONT20000OCT!J6+TONT20000NOV!J6 -> 1700000 | N6: =TONT20000DEC2015!K6+TONT20000JANV!K6+TONT20000FEV!K6+TONT20000MARS!K6+TONT20000AVRIL!K6+TONT20000MAI!K6+TONT20000JUIN!K6+TONT20000JUIL!K6+TONT20000AOUT!K6+TONT20000SEPT!K6+TONT20000OCT!K6+TONT20000NOV!K6 -> 124000 | O6: =TONT20000DEC2015!L6+TONT20000JANV!L6+TONT20000FEV!L6+TONT20000MARS!L6+TONT20000AVRIL!L6+TONT20000MAI!L6+TONT20000JUIN!L6+TONT20000JUIL!L6+TONT20000AOUT!L6+TONT20000SEPT!L6+TONT20000OCT!L6+TONT20000NOV!L6 -> 1000000 | P6: =TONT20000DEC2015!M6+TONT20000JANV!M6+TONT20000FEV!M6+TONT20000MARS!M6+TONT20000AVRIL!M6+TONT20000MAI!M6+TONT20000JUIN!M6+TONT20000JUIL!M6+TONT20000AOUT!M6+TONT20000SEPT!N6+TONT20000OCT!M6+TONT20000NOV!M6 -> 0 | Q6: =TONT20000DEC2015!M6+TONT20000JANV!M6+TONT20000FEV!M6+TONT20000MARS!M6+TONT20000AVRIL!M6+TONT20000MAI!M6+TONT20000JUIN!M6+TONT20000JUIL!M6+TONT20000AOUT!M6+TONT20000SEPT!N6+TONT20000OCT!M6+TONT20000NOV!M6 -> 0
A7: AS201603 | B7: =VLOOKUP(A7,LISTADHERENT!A$5:H$51,2) -> CHINGUE FABRICE | C7: 390000 | D7: 1842 | F7: =G7+H7+I7+J7+K7+L7+Q7 -> 240000 | G7: =TONT20000DEC2015!D7+TONT20000JANV!D7+TONT20000FEV!D7+TONT20000MARS!D7+TONT20000AVRIL!D7+TONT20000MAI!D7+TONT20000JUIN!D7+TONT20000JUIL!D7+TONT20000AOUT!D7+TONT20000SEPT!D7+TONT20000OCT!D7+TONT20000NOV!D7 -> 36000 | H7: =TONT20000DEC2015!E7+TONT20000JANV!E7+TONT20000FEV!E7+TONT20000MARS!E7+TONT20000AVRIL!E7+TONT20000MAI!E7+TONT20000JUIN!E7+TONT20000JUIL!E7+TONT20000AOUT!E7+TONT20000SEPT!E7+TONT20000OCT!E7+TONT20000NOV!E7 -> 6000 | I7: =TONT20000DEC2015!F7+TONT20000JANV!F7+TONT20000FEV!F7+TONT20000MARS!F7+TONT20000AVRIL!F7+TONT20000MAI!F7+TONT20000JUIN!F7+TONT20000JUIL!F7+TONT20000AOUT!F7+TONT20000SEPT!F7+TONT20000OCT!F7+TONT20000NOV!F7 -> 12000 | J7: =TONT20000DEC2015!G7+TONT20000JANV!G7+TONT20000FEV!G7+TONT20000MARS!G7+TONT20000AVRIL!G7+TONT20000MAI!G7+TONT20000JUIN!G7+TONT20000JUIL!G7+TONT20000AOUT!G7+TONT20000SEPT!G7+TONT20000OCT!G7+TONT20000NOV!G7 -> 30000 | K7: =TONT20000DEC2015!H7+TONT20000JANV!H7+TONT20000FEV!H7+TONT20000MARS!H7+TONT20000AVRIL!H7+TONT20000MAI!H7+TONT20000JUIN!H7+TONT20000JUIL!H7+TONT20000AOUT!H7+TONT20000SEPT!H7+TONT20000OCT!H7+TONT20000NOV!H7 -> 0 | L7: =TONT20000DEC2015!I7+TONT20000JANV!I7+TONT20000FEV!I7+TONT20000MARS!I7+TONT20000AVRIL!I7+TONT20000MAI!I7+TONT20000JUIN!I7+TONT20000JUIL!I7+TONT20000AOUT!I7+TONT20000SEPT!I7+TONT20000OCT!I7+TONT20000NOV!I7 -> 156000 | M7: =TONT20000DEC2015!J7+TONT20000JANV!J7+TONT20000FEV!J7+TONT20000MARS!J7+TONT20000AVRIL!J7+TONT20000MAI!J7+TONT20000JUIN!J7+TONT20000JUIL!J7+TONT20000AOUT!J7+TONT20000SEPT!J7+TONT20000OCT!J7+TONT20000NOV!J7 -> 2000000 | N7: =TONT20000DEC2015!K7+TONT20000JANV!K7+TONT20000FEV!K7+TONT20000MARS!K7+TONT20000AVRIL!K7+TONT20000MAI!K7+TONT20000JUIN!K7+TONT20000JUIL!K7+TONT20000AOUT!K7+TONT20000SEPT!K7+TONT20000OCT!K7+TONT20000NOV!K7 -> 180000 | O7: =TONT20000DEC2015!L7+TONT20000JANV!L7+TONT20000FEV!L7+TONT20000MARS!L7+TONT20000AVRIL!L7+TONT20000MAI!L7+TONT20000JUIN!L7+TONT20000JUIL!L7+TONT20000AOUT!L7+TONT20000SEPT!L7+TONT20000OCT!L7+TONT20000NOV!L7 -> 1000000 | P7: =TONT20000DEC2015!M7+TONT20000JANV!M7+TONT20000FEV!M7+TONT20000MARS!M7+TONT20000AVRIL!M7+TONT20000MAI!M7+TONT20000JUIN!M7+TONT20000JUIL!M7+TONT20000AOUT!M7+TONT20000SEPT!N7+TONT20000OCT!M7+TONT20000NOV!M7 -> 0 | Q7: =TONT20000DEC2015!M7+TONT20000JANV!M7+TONT20000FEV!M7+TONT20000MARS!M7+TONT20000AVRIL!M7+TONT20000MAI!M7+TONT20000JUIN!M7+TONT20000JUIL!M7+TONT20000AOUT!M7+TONT20000SEPT!N7+TONT20000OCT!M7+TONT20000NOV!M7 -> 0
A8: AS201604 | B8: =VLOOKUP(A8,LISTADHERENT!A$5:H$51,2) -> DJOMO JEAN PAUL | C8: 390000 | D8: 8156 | F8: =G8+H8+I8+J8+K8+L8+Q8 -> 247000 | G8: =TONT20000DEC2015!D8+TONT20000JANV!D8+TONT20000FEV!D8+TONT20000MARS!D8+TONT20000AVRIL!D8+TONT20000MAI!D8+TONT20000JUIN!D8+TONT20000JUIL!D8+TONT20000AOUT!D8+TONT20000SEPT!D8+TONT20000OCT!D8+TONT20000NOV!D8 -> 43000 | H8: =TONT20000DEC2015!E8+TONT20000JANV!E8+TONT20000FEV!E8+TONT20000MARS!E8+TONT20000AVRIL!E8+TONT20000MAI!E8+TONT20000JUIN!E8+TONT20000JUIL!E8+TONT20000AOUT!E8+TONT20000SEPT!E8+TONT20000OCT!E8+TONT20000NOV!E8 -> 6000 | I8: =TONT20000DEC2015!F8+TONT20000JANV!F8+TONT20000FEV!F8+TONT20000MARS!F8+TONT20000AVRIL!F8+TONT20000MAI!F8+TONT20000JUIN!F8+TONT20000JUIL!F8+TONT20000AOUT!F8+TONT20000SEPT!F8+TONT20000OCT!F8+TONT20000NOV!F8 -> 12000 | J8: =TONT20000DEC2015!G8+TONT20000JANV!G8+TONT20000FEV!G8+TONT20000MARS!G8+TONT20000AVRIL!G8+TONT20000MAI!G8+TONT20000JUIN!G8+TONT20000JUIL!G8+TONT20000AOUT!G8+TONT20000SEPT!G8+TONT20000OCT!G8+TONT20000NOV!G8 -> 30000 | K8: =TONT20000DEC2015!H8+TONT20000JANV!H8+TONT20000FEV!H8+TONT20000MARS!H8+TONT20000AVRIL!H8+TONT20000MAI!H8+TONT20000JUIN!H8+TONT20000JUIL!H8+TONT20000AOUT!H8+TONT20000SEPT!H8+TONT20000OCT!H8+TONT20000NOV!H8 -> 0 | L8: =TONT20000DEC2015!I8+TONT20000JANV!I8+TONT20000FEV!I8+TONT20000MARS!I8+TONT20000AVRIL!I8+TONT20000MAI!I8+TONT20000JUIN!I8+TONT20000JUIL!I8+TONT20000AOUT!I8+TONT20000SEPT!I8+TONT20000OCT!I8+TONT20000NOV!I8 -> 156000 | M8: =TONT20000DEC2015!J8+TONT20000JANV!J8+TONT20000FEV!J8+TONT20000MARS!J8+TONT20000AVRIL!J8+TONT20000MAI!J8+TONT20000JUIN!J8+TONT20000JUIL!J8+TONT20000AOUT!J8+TONT20000SEPT!J8+TONT20000OCT!J8+TONT20000NOV!J8 -> 200000 | N8: =TONT20000DEC2015!K8+TONT20000JANV!K8+TONT20000FEV!K8+TONT20000MARS!K8+TONT20000AVRIL!K8+TONT20000MAI!K8+TONT20000JUIN!K8+TONT20000JUIL!K8+TONT20000AOUT!K8+TONT20000SEPT!K8+TONT20000OCT!K8+TONT20000NOV!K8 -> 6000 | O8: =TONT20000DEC2015!L8+TONT20000JANV!L8+TONT20000FEV!L8+TONT20000MARS!L8+TONT20000AVRIL!L8+TONT20000MAI!L8+TONT20000JUIN!L8+TONT20000JUIL!L8+TONT20000AOUT!L8+TONT20000SEPT!L8+TONT20000OCT!L8+TONT20000NOV!L8 -> 0 | P8: =TONT20000DEC2015!M8+TONT20000JANV!M8+TONT20000FEV!M8+TONT20000MARS!M8+TONT20000AVRIL!M8+TONT20000MAI!M8+TONT20000JUIN!M8+TONT20000JUIL!M8+TONT20000AOUT!M8+TONT20000SEPT!N8+TONT20000OCT!M8+TONT20000NOV!M8 -> 0 | Q8: =TONT20000DEC2015!M8+TONT20000JANV!M8+TONT20000FEV!M8+TONT20000MARS!M8+TONT20000AVRIL!M8+TONT20000MAI!M8+TONT20000JUIN!M8+TONT20000JUIL!M8+TONT20000AOUT!M8+TONT20000SEPT!N8+TONT20000OCT!M8+TONT20000NOV!M8 -> 0
A9: AS201605 | B9: =VLOOKUP(A9,LISTADHERENT!A$5:H$51,2) -> DJOUKWE GUY | C9: 390000 | D9: 5905 | F9: =G9+H9+I9+J9+K9+L9+Q9 -> 280000 | G9: =TONT20000DEC2015!D9+TONT20000JANV!D9+TONT20000FEV!D9+TONT20000MARS!D9+TONT20000AVRIL!D9+TONT20000MAI!D9+TONT20000JUIN!D9+TONT20000JUIL!D9+TONT20000AOUT!D9+TONT20000SEPT!D9+TONT20000OCT!D9+TONT20000NOV!D9 -> 76000 | H9: =TONT20000DEC2015!E9+TONT20000JANV!E9+TONT20000FEV!E9+TONT20000MARS!E9+TONT20000AVRIL!E9+TONT20000MAI!E9+TONT20000JUIN!E9+TONT20000JUIL!E9+TONT20000AOUT!E9+TONT20000SEPT!E9+TONT20000OCT!E9+TONT20000NOV!E9 -> 6000 | I9: =TONT20000DEC2015!F9+TONT20000JANV!F9+TONT20000FEV!F9+TONT20000MARS!F9+TONT20000AVRIL!F9+TONT20000MAI!F9+TONT20000JUIN!F9+TONT20000JUIL!F9+TONT20000AOUT!F9+TONT20000SEPT!F9+TONT20000OCT!F9+TONT20000NOV!F9 -> 12000 | J9: =TONT20000DEC2015!G9+TONT20000JANV!G9+TONT20000FEV!G9+TONT20000MARS!G9+TONT20000AVRIL!G9+TONT20000MAI!G9+TONT20000JUIN!G9+TONT20000JUIL!G9+TONT20000AOUT!G9+TONT20000SEPT!G9+TONT20000OCT!G9+TONT20000NOV!G9 -> 30000 | K9: =TONT20000DEC2015!H9+TONT20000JANV!H9+TONT20000FEV!H9+TONT20000MARS!H9+TONT20000AVRIL!H9+TONT20000MAI!H9+TONT20000JUIN!H9+TONT20000JUIL!H9+TONT20000AOUT!H9+TONT20000SEPT!H9+TONT20000OCT!H9+TONT20000NOV!H9 -> 0 | L9: =TONT20000DEC2015!I9+TONT20000JANV!I9+TONT20000FEV!I9+TONT20000MARS!I9+TONT20000AVRIL!I9+TONT20000MAI!I9+TONT20000JUIN!I9+TONT20000JUIL!I9+TONT20000AOUT!I9+TONT20000SEPT!I9+TONT20000OCT!I9+TONT20000NOV!I9 -> 156000 | M9: =TONT20000DEC2015!J9+TONT20000JANV!J9+TONT20000FEV!J9+TONT20000MARS!J9+TONT20000AVRIL!J9+TONT20000MAI!J9+TONT20000JUIN!J9+TONT20000JUIL!J9+TONT20000AOUT!J9+TONT20000SEPT!J9+TONT20000OCT!J9+TONT20000NOV!J9 -> 250000 | N9: =TONT20000DEC2015!K9+TONT20000JANV!K9+TONT20000FEV!K9+TONT20000MARS!K9+TONT20000AVRIL!K9+TONT20000MAI!K9+TONT20000JUIN!K9+TONT20000JUIL!K9+TONT20000AOUT!K9+TONT20000SEPT!K9+TONT20000OCT!K9+TONT20000NOV!K9 -> 7500 | O9: =TONT20000DEC2015!L9+TONT20000JANV!L9+TONT20000FEV!L9+TONT20000MARS!L9+TONT20000AVRIL!L9+TONT20000MAI!L9+TONT20000JUIN!L9+TONT20000JUIL!L9+TONT20000AOUT!L9+TONT20000SEPT!L9+TONT20000OCT!L9+TONT20000NOV!L9 -> 0 | P9: =TONT20000DEC2015!M9+TONT20000JANV!M9+TONT20000FEV!M9+TONT20000MARS!M9+TONT20000AVRIL!M9+TONT20000MAI!M9+TONT20000JUIN!M9+TONT20000JUIL!M9+TONT20000AOUT!M9+TONT20000SEPT!N9+TONT20000OCT!M9+TONT20000NOV!M9 -> 0 | Q9: =TONT20000DEC2015!M9+TONT20000JANV!M9+TONT20000FEV!M9+TONT20000MARS!M9+TONT20000AVRIL!M9+TONT20000MAI!M9+TONT20000JUIN!M9+TONT20000JUIL!M9+TONT20000AOUT!M9+TONT20000SEPT!N9+TONT20000OCT!M9+TONT20000NOV!M9 -> 0
A10: AS201606 | B10: =VLOOKUP(A10,LISTADHERENT!A$5:H$51,2) -> DJOSSEU JOSUE | C10: 0 | D10: 0 | F10: =G10+H10+I10+J10+K10+L10+Q10 -> 22000 | G10: =TONT20000DEC2015!D10+TONT20000JANV!D10+TONT20000FEV!D10+TONT20000MARS!D10+TONT20000AVRIL!D10+TONT20000MAI!D10+TONT20000JUIN!D10+TONT20000JUIL!D10+TONT20000AOUT!D10+TONT20000SEPT!D10+TONT20000OCT!D10+TONT20000NOV!D10 -> 5000 | H10: =TONT20000DEC2015!E10+TONT20000JANV!E10+TONT20000FEV!E10+TONT20000MARS!E10+TONT20000AVRIL!E10+TONT20000MAI!E10+TONT20000JUIN!E10+TONT20000JUIL!E10+TONT20000AOUT!E10+TONT20000SEPT!E10+TONT20000OCT!E10+TONT20000NOV!E10 -> 500 | I10: =TONT20000DEC2015!F10+TONT20000JANV!F10+TONT20000FEV!F10+TONT20000MARS!F10+TONT20000AVRIL!F10+TONT20000MAI!F10+TONT20000JUIN!F10+TONT20000JUIL!F10+TONT20000AOUT!F10+TONT20000SEPT!F10+TONT20000OCT!F10+TONT20000NOV!F10 -> 1000 | J10: =TONT20000DEC2015!G10+TONT20000JANV!G10+TONT20000FEV!G10+TONT20000MARS!G10+TONT20000AVRIL!G10+TONT20000MAI!G10+TONT20000JUIN!G10+TONT20000JUIL!G10+TONT20000AOUT!G10+TONT20000SEPT!G10+TONT20000OCT!G10+TONT20000NOV!G10 -> 2500 | K10: =TONT20000DEC2015!H10+TONT20000JANV!H10+TONT20000FEV!H10+TONT20000MARS!H10+TONT20000AVRIL!H10+TONT20000MAI!H10+TONT20000JUIN!H10+TONT20000JUIL!H10+TONT20000AOUT!H10+TONT20000SEPT!H10+TONT20000OCT!H10+TONT20000NOV!H10 -> 0 | L10: =TONT20000DEC2015!I10+TONT20000JANV!I10+TONT20000FEV!I10+TONT20000MARS!I10+TONT20000AVRIL!I10+TONT20000MAI!I10+TONT20000JUIN!I10+TONT20000JUIL!I10+TONT20000AOUT!I10+TONT20000SEPT!I10+TONT20000OCT!I10+TONT20000NOV!I10 -> 13000 | M10: =TONT20000DEC2015!J10+TONT20000JANV!J10+TONT20000FEV!J10+TONT20000MARS!J10+TONT20000AVRIL!J10+TONT20000MAI!J10+TONT20000JUIN!J10+TONT20000JUIL!J10+TONT20000AOUT!J10+TONT20000SEPT!J10+TONT20000OCT!J10+TONT20000NOV!J10 -> 0 | N10: =TONT20000DEC2015!K10+TONT20000JANV!K10+TONT20000FEV!K10+TONT20000MARS!K10+TONT20000AVRIL!K10+TONT20000MAI!K10+TONT20000JUIN!K10+TONT20000JUIL!K10+TONT20000AOUT!K10+TONT20000SEPT!K10+TONT20000OCT!K10+TONT20000NOV!K10 -> 0 | O10: =TONT20000DEC2015!L10+TONT20000JANV!L10+TONT20000FEV!L10+TONT20000MARS!L10+TONT20000AVRIL!L10+TONT20000MAI!L10+TONT20000JUIN!L10+TONT20000JUIL!L10+TONT20000AOUT!L10+TONT20000SEPT!L10+TONT20000OCT!L10+TONT20000NOV!L10 -> 0 | P10: =TONT20000DEC2015!M10+TONT20000JANV!M10+TONT20000FEV!M10+TONT20000MARS!M10+TONT20000AVRIL!M10+TONT20000MAI!M10+TONT20000JUIN!M10+TONT20000JUIL!M10+TONT20000AOUT!M10+TONT20000SEPT!N10+TONT20000OCT!M10+TONT20000NOV!M10 -> 0 | Q10: =TONT20000DEC2015!M10+TONT20000JANV!M10+TONT20000FEV!M10+TONT20000MARS!M10+TONT20000AVRIL!M10+TONT20000MAI!M10+TONT20000JUIN!M10+TONT20000JUIL!M10+TONT20000AOUT!M10+TONT20000SEPT!N10+TONT20000OCT!M10+TONT20000NOV!M10 -> 0
A11: AS201607 | B11: =VLOOKUP(A11,LISTADHERENT!A$5:H$51,2) -> DJOUNKEP SAMUEL | C11: 390000 | D11: 1055294 | F11: =G11+H11+I11+J11+K11+L11+Q11 -> 760000 | G11: =TONT20000DEC2015!D11+TONT20000JANV!D11+TONT20000FEV!D11+TONT20000MARS!D11+TONT20000AVRIL!D11+TONT20000MAI!D11+TONT20000JUIN!D11+TONT20000JUIL!D11+TONT20000AOUT!D11+TONT20000SEPT!D11+TONT20000OCT!D11+TONT20000NOV!D11 -> 556000 | H11: =TONT20000DEC2015!E11+TONT20000JANV!E11+TONT20000FEV!E11+TONT20000MARS!E11+TONT20000AVRIL!E11+TONT20000MAI!E11+TONT20000JUIN!E11+TONT20000JUIL!E11+TONT20000AOUT!E11+TONT20000SEPT!E11+TONT20000OCT!E11+TONT20000NOV!E11 -> 6000 | I11: =TONT20000DEC2015!F11+TONT20000JANV!F11+TONT20000FEV!F11+TONT20000MARS!F11+TONT20000AVRIL!F11+TONT20000MAI!F11+TONT20000JUIN!F11+TONT20000JUIL!F11+TONT20000AOUT!F11+TONT20000SEPT!F11+TONT20000OCT!F11+TONT20000NOV!F11 -> 12000 | J11: =TONT20000DEC2015!G11+TONT20000JANV!G11+TONT20000FEV!G11+TONT20000MARS!G11+TONT20000AVRIL!G11+TONT20000MAI!G11+TONT20000JUIN!G11+TONT20000JUIL!G11+TONT20000AOUT!G11+TONT20000SEPT!G11+TONT20000OCT!G11+TONT20000NOV!G11 -> 30000 | K11: =TONT20000DEC2015!H11+TONT20000JANV!H11+TONT20000FEV!H11+TONT20000MARS!H11+TONT20000AVRIL!H11+TONT20000MAI!H11+TONT20000JUIN!H11+TONT20000JUIL!H11+TONT20000AOUT!H11+TONT20000SEPT!H11+TONT20000OCT!H11+TONT20000NOV!H11 -> 0 | L11: =TONT20000DEC2015!I11+TONT20000JANV!I11+TONT20000FEV!I11+TONT20000MARS!I11+TONT20000AVRIL!I11+TONT20000MAI!I11+TONT20000JUIN!I11+TONT20000JUIL!I11+TONT20000AOUT!I11+TONT20000SEPT!I11+TONT20000OCT!I11+TONT20000NOV!I11 -> 156000 | M11: =TONT20000DEC2015!J11+TONT20000JANV!J11+TONT20000FEV!J11+TONT20000MARS!J11+TONT20000AVRIL!J11+TONT20000MAI!J11+TONT20000JUIN!J11+TONT20000JUIL!J11+TONT20000AOUT!J11+TONT20000SEPT!J11+TONT20000OCT!J11+TONT20000NOV!J11 -> 0 | N11: =TONT20000DEC2015!K11+TONT20000JANV!K11+TONT20000FEV!K11+TONT20000MARS!K11+TONT20000AVRIL!K11+TONT20000MAI!K11+TONT20000JUIN!K11+TONT20000JUIL!K11+TONT20000AOUT!K11+TONT20000SEPT!K11+TONT20000OCT!K11+TONT20000NOV!K11 -> 0 | O11: =TONT20000DEC2015!L11+TONT20000JANV!L11+TONT20000FEV!L11+TONT20000MARS!L11+TONT20000AVRIL!L11+TONT20000MAI!L11+TONT20000JUIN!L11+TONT20000JUIL!L11+TONT20000AOUT!L11+TONT20000SEPT!L11+TONT20000OCT!L11+TONT20000NOV!L11 -> 0 | P11: =TONT20000DEC2015!M11+TONT20000JANV!M11+TONT20000FEV!M11+TONT20000MARS!M11+TONT20000AVRIL!M11+TONT20000MAI!M11+TONT20000JUIN!M11+TONT20000JUIL!M11+TONT20000AOUT!M11+TONT20000SEPT!N11+TONT20000OCT!M11+TONT20000NOV!M11 -> 0 | Q11: =TONT20000DEC2015!M11+TONT20000JANV!M11+TONT20000FEV!M11+TONT20000MARS!M11+TONT20000AVRIL!M11+TONT20000MAI!M11+TONT20000JUIN!M11+TONT20000JUIL!M11+TONT20000AOUT!M11+TONT20000SEPT!N11+TONT20000OCT!M11+TONT20000NOV!M11 -> 0
A12: AS201608 | B12: =VLOOKUP(A12,LISTADHERENT!A$5:H$51,2) -> DJUOMBESSY ANTOINE | C12: =390000-70866 -> 319134 | D12: 0 | F12: =G12+H12+I12+J12+K12+L12+Q12 -> 320000 | G12: =TONT20000DEC2015!D12+TONT20000JANV!D12+TONT20000FEV!D12+TONT20000MARS!D12+TONT20000AVRIL!D12+TONT20000MAI!D12+TONT20000JUIN!D12+TONT20000JUIL!D12+TONT20000AOUT!D12+TONT20000SEPT!D12+TONT20000OCT!D12+TONT20000NOV!D12 -> 67560 | H12: =TONT20000DEC2015!E12+TONT20000JANV!E12+TONT20000FEV!E12+TONT20000MARS!E12+TONT20000AVRIL!E12+TONT20000MAI!E12+TONT20000JUIN!E12+TONT20000JUIL!E12+TONT20000AOUT!E12+TONT20000SEPT!E12+TONT20000OCT!E12+TONT20000NOV!E12 -> 6000 | I12: =TONT20000DEC2015!F12+TONT20000JANV!F12+TONT20000FEV!F12+TONT20000MARS!F12+TONT20000AVRIL!F12+TONT20000MAI!F12+TONT20000JUIN!F12+TONT20000JUIL!F12+TONT20000AOUT!F12+TONT20000SEPT!F12+TONT20000OCT!F12+TONT20000NOV!F12 -> 12000 | J12: =TONT20000DEC2015!G12+TONT20000JANV!G12+TONT20000FEV!G12+TONT20000MARS!G12+TONT20000AVRIL!G12+TONT20000MAI!G12+TONT20000JUIN!G12+TONT20000JUIL!G12+TONT20000AOUT!G12+TONT20000SEPT!G12+TONT20000OCT!G12+TONT20000NOV!G12 -> 30000 | K12: =TONT20000DEC2015!H12+TONT20000JANV!H12+TONT20000FEV!H12+TONT20000MARS!H12+TONT20000AVRIL!H12+TONT20000MAI!H12+TONT20000JUIN!H12+TONT20000JUIL!H12+TONT20000AOUT!H12+TONT20000SEPT!H12+TONT20000OCT!H12+TONT20000NOV!H12 -> 0 | L12: =TONT20000DEC2015!I12+TONT20000JANV!I12+TONT20000FEV!I12+TONT20000MARS!I12+TONT20000AVRIL!I12+TONT20000MAI!I12+TONT20000JUIN!I12+TONT20000JUIL!I12+TONT20000AOUT!I12+TONT20000SEPT!I12+TONT20000OCT!I12+TONT20000NOV!I12 -> 156000 | M12: =TONT20000DEC2015!J12+TONT20000JANV!J12+TONT20000FEV!J12+TONT20000MARS!J12+TONT20000AVRIL!J12+TONT20000MAI!J12+TONT20000JUIN!J12+TONT20000JUIL!J12+TONT20000AOUT!J12+TONT20000SEPT!J12+TONT20000OCT!J12+TONT20000NOV!J12 -> 700000 | N12: =TONT20000DEC2015!K12+TONT20000JANV!K12+TONT20000FEV!K12+TONT20000MARS!K12+TONT20000AVRIL!K12+TONT20000MAI!K12+TONT20000JUIN!K12+TONT20000JUIL!K12+TONT20000AOUT!K12+TONT20000SEPT!K12+TONT20000OCT!K12+TONT20000NOV!K12 -> 84000 | O12: =TONT20000DEC2015!L12+TONT20000JANV!L12+TONT20000FEV!L12+TONT20000MARS!L12+TONT20000AVRIL!L12+TONT20000MAI!L12+TONT20000JUIN!L12+TONT20000JUIL!L12+TONT20000AOUT!L12+TONT20000SEPT!L12+TONT20000OCT!L12+TONT20000NOV!L12 -> 0 | P12: =TONT20000DEC2015!M12+TONT20000JANV!M12+TONT20000FEV!M12+TONT20000MARS!M12+TONT20000AVRIL!M12+TONT20000MAI!M12+TONT20000JUIN!M12+TONT20000JUIL!M12+TONT20000AOUT!M12+TONT20000SEPT!N12+TONT20000OCT!M12+TONT20000NOV!M12 -> 48440 | Q12: =TONT20000DEC2015!M12+TONT20000JANV!M12+TONT20000FEV!M12+TONT20000MARS!M12+TONT20000AVRIL!M12+TONT20000MAI!M12+TONT20000JUIN!M12+TONT20000JUIL!M12+TONT20000AOUT!M12+TONT20000SEPT!N12+TONT20000OCT!M12+TONT20000NOV!M12 -> 48440
A13: AS201609 | B13: =VLOOKUP(A13,LISTADHERENT!A$5:H$51,2) -> DONHOU DAVID | C13: 390000 | D13: 44734 | F13: =G13+H13+I13+J13+K13+L13+Q13 -> 240000 | G13: =TONT20000DEC2015!D13+TONT20000JANV!D13+TONT20000FEV!D13+TONT20000MARS!D13+TONT20000AVRIL!D13+TONT20000MAI!D13+TONT20000JUIN!D13+TONT20000JUIL!D13+TONT20000AOUT!D13+TONT20000SEPT!D13+TONT20000OCT!D13+TONT20000NOV!D13 -> 36000 | H13: =TONT20000DEC2015!E13+TONT20000JANV!E13+TONT20000FEV!E13+TONT20000MARS!E13+TONT20000AVRIL!E13+TONT20000MAI!E13+TONT20000JUIN!E13+TONT20000JUIL!E13+TONT20000AOUT!E13+TONT20000SEPT!E13+TONT20000OCT!E13+TONT20000NOV!E13 -> 6000 | I13: =TONT20000DEC2015!F13+TONT20000JANV!F13+TONT20000FEV!F13+TONT20000MARS!F13+TONT20000AVRIL!F13+TONT20000MAI!F13+TONT20000JUIN!F13+TONT20000JUIL!F13+TONT20000AOUT!F13+TONT20000SEPT!F13+TONT20000OCT!F13+TONT20000NOV!F13 -> 12000 | J13: =TONT20000DEC2015!G13+TONT20000JANV!G13+TONT20000FEV!G13+TONT20000MARS!G13+TONT20000AVRIL!G13+TONT20000MAI!G13+TONT20000JUIN!G13+TONT20000JUIL!G13+TONT20000AOUT!G13+TONT20000SEPT!G13+TONT20000OCT!G13+TONT20000NOV!G13 -> 30000 | K13: =TONT20000DEC2015!H13+TONT20000JANV!H13+TONT20000FEV!H13+TONT20000MARS!H13+TONT20000AVRIL!H13+TONT20000MAI!H13+TONT20000JUIN!H13+TONT20000JUIL!H13+TONT20000AOUT!H13+TONT20000SEPT!H13+TONT20000OCT!H13+TONT20000NOV!H13 -> 0 | L13: =TONT20000DEC2015!I13+TONT20000JANV!I13+TONT20000FEV!I13+TONT20000MARS!I13+TONT20000AVRIL!I13+TONT20000MAI!I13+TONT20000JUIN!I13+TONT20000JUIL!I13+TONT20000AOUT!I13+TONT20000SEPT!I13+TONT20000OCT!I13+TONT20000NOV!I13 -> 156000 | M13: =TONT20000DEC2015!J13+TONT20000JANV!J13+TONT20000FEV!J13+TONT20000MARS!J13+TONT20000AVRIL!J13+TONT20000MAI!J13+TONT20000JUIN!J13+TONT20000JUIL!J13+TONT20000AOUT!J13+TONT20000SEPT!J13+TONT20000OCT!J13+TONT20000NOV!J13 -> 0 | N13: =TONT20000DEC2015!K13+TONT20000JANV!K13+TONT20000FEV!K13+TONT20000MARS!K13+TONT20000AVRIL!K13+TONT20000MAI!K13+TONT20000JUIN!K13+TONT20000JUIL!K13+TONT20000AOUT!K13+TONT20000SEPT!K13+TONT20000OCT!K13+TONT20000NOV!K13 -> 0 | O13: =TONT20000DEC2015!L13+TONT20000JANV!L13+TONT20000FEV!L13+TONT20000MARS!L13+TONT20000AVRIL!L13+TONT20000MAI!L13+TONT20000JUIN!L13+TONT20000JUIL!L13+TONT20000AOUT!L13+TONT20000SEPT!L13+TONT20000OCT!L13+TONT20000NOV!L13 -> 0 | P13: =TONT20000DEC2015!M13+TONT20000JANV!M13+TONT20000FEV!M13+TONT20000MARS!M13+TONT20000AVRIL!M13+TONT20000MAI!M13+TONT20000JUIN!M13+TONT20000JUIL!M13+TONT20000AOUT!M13+TONT20000SEPT!N13+TONT20000OCT!M13+TONT20000NOV!M13 -> 0 | Q13: =TONT20000DEC2015!M13+TONT20000JANV!M13+TONT20000FEV!M13+TONT20000MARS!M13+TONT20000AVRIL!M13+TONT20000MAI!M13+TONT20000JUIN!M13+TONT20000JUIL!M13+TONT20000AOUT!M13+TONT20000SEPT!N13+TONT20000OCT!M13+TONT20000NOV!M13 -> 0
A14: AS201610 | B14: =VLOOKUP(A14,LISTADHERENT!A$5:H$51,2) -> FOTSO THOMAS | C14: 390000 | D14: 3318 | F14: =G14+H14+I14+J14+K14+L14+Q14 -> 240000 | G14: =TONT20000DEC2015!D14+TONT20000JANV!D14+TONT20000FEV!D14+TONT20000MARS!D14+TONT20000AVRIL!D14+TONT20000MAI!D14+TONT20000JUIN!D14+TONT20000JUIL!D14+TONT20000AOUT!D14+TONT20000SEPT!D14+TONT20000OCT!D14+TONT20000NOV!D14 -> 36000 | H14: =TONT20000DEC2015!E14+TONT20000JANV!E14+TONT20000FEV!E14+TONT20000MARS!E14+TONT20000AVRIL!E14+TONT20000MAI!E14+TONT20000JUIN!E14+TONT20000JUIL!E14+TONT20000AOUT!E14+TONT20000SEPT!E14+TONT20000OCT!E14+TONT20000NOV!E14 -> 6000 | I14: =TONT20000DEC2015!F14+TONT20000JANV!F14+TONT20000FEV!F14+TONT20000MARS!F14+TONT20000AVRIL!F14+TONT20000MAI!F14+TONT20000JUIN!F14+TONT20000JUIL!F14+TONT20000AOUT!F14+TONT20000SEPT!F14+TONT20000OCT!F14+TONT20000NOV!F14 -> 12000 | J14: =TONT20000DEC2015!G14+TONT20000JANV!G14+TONT20000FEV!G14+TONT20000MARS!G14+TONT20000AVRIL!G14+TONT20000MAI!G14+TONT20000JUIN!G14+TONT20000JUIL!G14+TONT20000AOUT!G14+TONT20000SEPT!G14+TONT20000OCT!G14+TONT20000NOV!G14 -> 30000 | K14: =TONT20000DEC2015!H14+TONT20000JANV!H14+TONT20000FEV!H14+TONT20000MARS!H14+TONT20000AVRIL!H14+TONT20000MAI!H14+TONT20000JUIN!H14+TONT20000JUIL!H14+TONT20000AOUT!H14+TONT20000SEPT!H14+TONT20000OCT!H14+TONT20000NOV!H14 -> 0 | L14: =TONT20000DEC2015!I14+TONT20000JANV!I14+TONT20000FEV!I14+TONT20000MARS!I14+TONT20000AVRIL!I14+TONT20000MAI!I14+TONT20000JUIN!I14+TONT20000JUIL!I14+TONT20000AOUT!I14+TONT20000SEPT!I14+TONT20000OCT!I14+TONT20000NOV!I14 -> 156000 | M14: =TONT20000DEC2015!J14+TONT20000JANV!J14+TONT20000FEV!J14+TONT20000MARS!J14+TONT20000AVRIL!J14+TONT20000MAI!J14+TONT20000JUIN!J14+TONT20000JUIL!J14+TONT20000AOUT!J14+TONT20000SEPT!J14+TONT20000OCT!J14+TONT20000NOV!J14 -> 1000000 | N14: =TONT20000DEC2015!K14+TONT20000JANV!K14+TONT20000FEV!K14+TONT20000MARS!K14+TONT20000AVRIL!K14+TONT20000MAI!K14+TONT20000JUIN!K14+TONT20000JUIL!K14+TONT20000AOUT!K14+TONT20000SEPT!K14+TONT20000OCT!K14+TONT20000NOV!K14 -> 120000 | O14: =TONT20000DEC2015!L14+TONT20000JANV!L14+TONT20000FEV!L14+TONT20000MARS!L14+TONT20000AVRIL!L14+TONT20000MAI!L14+TONT20000JUIN!L14+TONT20000JUIL!L14+TONT20000AOUT!L14+TONT20000SEPT!L14+TONT20000OCT!L14+TONT20000NOV!L14 -> 0 | P14: =TONT20000DEC2015!M14+TONT20000JANV!M14+TONT20000FEV!M14+TONT20000MARS!M14+TONT20000AVRIL!M14+TONT20000MAI!M14+TONT20000JUIN!M14+TONT20000JUIL!M14+TONT20000AOUT!M14+TONT20000SEPT!N14+TONT20000OCT!M14+TONT20000NOV!M14 -> 0 | Q14: =TONT20000DEC2015!M14+TONT20000JANV!M14+TONT20000FEV!M14+TONT20000MARS!M14+TONT20000AVRIL!M14+TONT20000MAI!M14+TONT20000JUIN!M14+TONT20000JUIL!M14+TONT20000AOUT!M14+TONT20000SEPT!N14+TONT20000OCT!M14+TONT20000NOV!M14 -> 0
A15: AS201611 | B15: =VLOOKUP(A15,LISTADHERENT!A$5:H$51,2) -> HENGUE PAUL OMER | C15: 390000 | D15: 1083990 | F15: =G15+H15+I15+J15+K15+L15+Q15 -> 200000 | G15: =TONT20000DEC2015!D15+TONT20000JANV!D15+TONT20000FEV!D15+TONT20000MARS!D15+TONT20000AVRIL!D15+TONT20000MAI!D15+TONT20000JUIN!D15+TONT20000JUIL!D15+TONT20000AOUT!D15+TONT20000SEPT!D15+TONT20000OCT!D15+TONT20000NOV!D15 -> 30000 | H15: =TONT20000DEC2015!E15+TONT20000JANV!E15+TONT20000FEV!E15+TONT20000MARS!E15+TONT20000AVRIL!E15+TONT20000MAI!E15+TONT20000JUIN!E15+TONT20000JUIL!E15+TONT20000AOUT!E15+TONT20000SEPT!E15+TONT20000OCT!E15+TONT20000NOV!E15 -> 5000 | I15: =TONT20000DEC2015!F15+TONT20000JANV!F15+TONT20000FEV!F15+TONT20000MARS!F15+TONT20000AVRIL!F15+TONT20000MAI!F15+TONT20000JUIN!F15+TONT20000JUIL!F15+TONT20000AOUT!F15+TONT20000SEPT!F15+TONT20000OCT!F15+TONT20000NOV!F15 -> 10000 | J15: =TONT20000DEC2015!G15+TONT20000JANV!G15+TONT20000FEV!G15+TONT20000MARS!G15+TONT20000AVRIL!G15+TONT20000MAI!G15+TONT20000JUIN!G15+TONT20000JUIL!G15+TONT20000AOUT!G15+TONT20000SEPT!G15+TONT20000OCT!G15+TONT20000NOV!G15 -> 25000 | K15: =TONT20000DEC2015!H15+TONT20000JANV!H15+TONT20000FEV!H15+TONT20000MARS!H15+TONT20000AVRIL!H15+TONT20000MAI!H15+TONT20000JUIN!H15+TONT20000JUIL!H15+TONT20000AOUT!H15+TONT20000SEPT!H15+TONT20000OCT!H15+TONT20000NOV!H15 -> 0 | L15: =TONT20000DEC2015!I15+TONT20000JANV!I15+TONT20000FEV!I15+TONT20000MARS!I15+TONT20000AVRIL!I15+TONT20000MAI!I15+TONT20000JUIN!I15+TONT20000JUIL!I15+TONT20000AOUT!I15+TONT20000SEPT!I15+TONT20000OCT!I15+TONT20000NOV!I15 -> 130000 | M15: =TONT20000DEC2015!J15+TONT20000JANV!J15+TONT20000FEV!J15+TONT20000MARS!J15+TONT20000AVRIL!J15+TONT20000MAI!J15+TONT20000JUIN!J15+TONT20000JUIL!J15+TONT20000AOUT!J15+TONT20000SEPT!J15+TONT20000OCT!J15+TONT20000NOV!J15 -> 0 | N15: =TONT20000DEC2015!K15+TONT20000JANV!K15+TONT20000FEV!K15+TONT20000MARS!K15+TONT20000AVRIL!K15+TONT20000MAI!K15+TONT20000JUIN!K15+TONT20000JUIL!K15+TONT20000AOUT!K15+TONT20000SEPT!K15+TONT20000OCT!K15+TONT20000NOV!K15 -> 0 | O15: =TONT20000DEC2015!L15+TONT20000JANV!L15+TONT20000FEV!L15+TONT20000MARS!L15+TONT20000AVRIL!L15+TONT20000MAI!L15+TONT20000JUIN!L15+TONT20000JUIL!L15+TONT20000AOUT!L15+TONT20000SEPT!L15+TONT20000OCT!L15+TONT20000NOV!L15 -> 0 | P15: =TONT20000DEC2015!M15+TONT20000JANV!M15+TONT20000FEV!M15+TONT20000MARS!M15+TONT20000AVRIL!M15+TONT20000MAI!M15+TONT20000JUIN!M15+TONT20000JUIL!M15+TONT20000AOUT!M15+TONT20000SEPT!N15+TONT20000OCT!M15+TONT20000NOV!M15 -> 0 | Q15: =TONT20000DEC2015!M15+TONT20000JANV!M15+TONT20000FEV!M15+TONT20000MARS!M15+TONT20000AVRIL!M15+TONT20000MAI!M15+TONT20000JUIN!M15+TONT20000JUIL!M15+TONT20000AOUT!M15+TONT20000SEPT!N15+TONT20000OCT!M15+TONT20000NOV!M15 -> 0
A16: AS201612 | B16: =VLOOKUP(A16,LISTADHERENT!A$5:H$51,2) -> HODIEP JULES | C16: =390000-111192 -> 278808 | D16: 0 | F16: =G16+H16+I16+J16+K16+L16+Q16 -> 240000 | G16: =TONT20000DEC2015!D16+TONT20000JANV!D16+TONT20000FEV!D16+TONT20000MARS!D16+TONT20000AVRIL!D16+TONT20000MAI!D16+TONT20000JUIN!D16+TONT20000JUIL!D16+TONT20000AOUT!D16+TONT20000SEPT!D16+TONT20000OCT!D16+TONT20000NOV!D16 -> 36000 | H16: =TONT20000DEC2015!E16+TONT20000JANV!E16+TONT20000FEV!E16+TONT20000MARS!E16+TONT20000AVRIL!E16+TONT20000MAI!E16+TONT20000JUIN!E16+TONT20000JUIL!E16+TONT20000AOUT!E16+TONT20000SEPT!E16+TONT20000OCT!E16+TONT20000NOV!E16 -> 6000 | I16: =TONT20000DEC2015!F16+TONT20000JANV!F16+TONT20000FEV!F16+TONT20000MARS!F16+TONT20000AVRIL!F16+TONT20000MAI!F16+TONT20000JUIN!F16+TONT20000JUIL!F16+TONT20000AOUT!F16+TONT20000SEPT!F16+TONT20000OCT!F16+TONT20000NOV!F16 -> 12000 | J16: =TONT20000DEC2015!G16+TONT20000JANV!G16+TONT20000FEV!G16+TONT20000MARS!G16+TONT20000AVRIL!G16+TONT20000MAI!G16+TONT20000JUIN!G16+TONT20000JUIL!G16+TONT20000AOUT!G16+TONT20000SEPT!G16+TONT20000OCT!G16+TONT20000NOV!G16 -> 30000 | K16: =TONT20000DEC2015!H16+TONT20000JANV!H16+TONT20000FEV!H16+TONT20000MARS!H16+TONT20000AVRIL!H16+TONT20000MAI!H16+TONT20000JUIN!H16+TONT20000JUIL!H16+TONT20000AOUT!H16+TONT20000SEPT!H16+TONT20000OCT!H16+TONT20000NOV!H16 -> 0 | L16: =TONT20000DEC2015!I16+TONT20000JANV!I16+TONT20000FEV!I16+TONT20000MARS!I16+TONT20000AVRIL!I16+TONT20000MAI!I16+TONT20000JUIN!I16+TONT20000JUIL!I16+TONT20000AOUT!I16+TONT20000SEPT!I16+TONT20000OCT!I16+TONT20000NOV!I16 -> 156000 | M16: =TONT20000DEC2015!J16+TONT20000JANV!J16+TONT20000FEV!J16+TONT20000MARS!J16+TONT20000AVRIL!J16+TONT20000MAI!J16+TONT20000JUIN!J16+TONT20000JUIL!J16+TONT20000AOUT!J16+TONT20000SEPT!J16+TONT20000OCT!J16+TONT20000NOV!J16 -> 0 | N16: =TONT20000DEC2015!K16+TONT20000JANV!K16+TONT20000FEV!K16+TONT20000MARS!K16+TONT20000AVRIL!K16+TONT20000MAI!K16+TONT20000JUIN!K16+TONT20000JUIL!K16+TONT20000AOUT!K16+TONT20000SEPT!K16+TONT20000OCT!K16+TONT20000NOV!K16 -> 0 | O16: =TONT20000DEC2015!L16+TONT20000JANV!L16+TONT20000FEV!L16+TONT20000MARS!L16+TONT20000AVRIL!L16+TONT20000MAI!L16+TONT20000JUIN!L16+TONT20000JUIL!L16+TONT20000AOUT!L16+TONT20000SEPT!L16+TONT20000OCT!L16+TONT20000NOV!L16 -> 0 | P16: =TONT20000DEC2015!M16+TONT20000JANV!M16+TONT20000FEV!M16+TONT20000MARS!M16+TONT20000AVRIL!M16+TONT20000MAI!M16+TONT20000JUIN!M16+TONT20000JUIL!M16+TONT20000AOUT!M16+TONT20000SEPT!N16+TONT20000OCT!M16+TONT20000NOV!M16 -> 0 | Q16: =TONT20000DEC2015!M16+TONT20000JANV!M16+TONT20000FEV!M16+TONT20000MARS!M16+TONT20000AVRIL!M16+TONT20000MAI!M16+TONT20000JUIN!M16+TONT20000JUIL!M16+TONT20000AOUT!M16+TONT20000SEPT!N16+TONT20000OCT!M16+TONT20000NOV!M16 -> 0
A17: AS201613 | B17: =VLOOKUP(A17,LISTADHERENT!A$5:H$51,2) -> HOTCHO BENJAMIN | C17: 390000 | D17: 8723 | F17: =G17+H17+I17+J17+K17+L17+Q17 -> 338000 | G17: =TONT20000DEC2015!D17+TONT20000JANV!D17+TONT20000FEV!D17+TONT20000MARS!D17+TONT20000AVRIL!D17+TONT20000MAI!D17+TONT20000JUIN!D17+TONT20000JUIL!D17+TONT20000AOUT!D17+TONT20000SEPT!D17+TONT20000OCT!D17+TONT20000NOV!D17 -> 84000 | H17: =TONT20000DEC2015!E17+TONT20000JANV!E17+TONT20000FEV!E17+TONT20000MARS!E17+TONT20000AVRIL!E17+TONT20000MAI!E17+TONT20000JUIN!E17+TONT20000JUIL!E17+TONT20000AOUT!E17+TONT20000SEPT!E17+TONT20000OCT!E17+TONT20000NOV!E17 -> 6000 | I17: =TONT20000DEC2015!F17+TONT20000JANV!F17+TONT20000FEV!F17+TONT20000MARS!F17+TONT20000AVRIL!F17+TONT20000MAI!F17+TONT20000JUIN!F17+TONT20000JUIL!F17+TONT20000AOUT!F17+TONT20000SEPT!F17+TONT20000OCT!F17+TONT20000NOV!F17 -> 12000 | J17: =TONT20000DEC2015!G17+TONT20000JANV!G17+TONT20000FEV!G17+TONT20000MARS!G17+TONT20000AVRIL!G17+TONT20000MAI!G17+TONT20000JUIN!G17+TONT20000JUIL!G17+TONT20000AOUT!G17+TONT20000SEPT!G17+TONT20000OCT!G17+TONT20000NOV!G17 -> 30000 | K17: =TONT20000DEC2015!H17+TONT20000JANV!H17+TONT20000FEV!H17+TONT20000MARS!H17+TONT20000AVRIL!H17+TONT20000MAI!H17+TONT20000JUIN!H17+TONT20000JUIL!H17+TONT20000AOUT!H17+TONT20000SEPT!H17+TONT20000OCT!H17+TONT20000NOV!H17 -> 50000 | L17: =TONT20000DEC2015!I17+TONT20000JANV!I17+TONT20000FEV!I17+TONT20000MARS!I17+TONT20000AVRIL!I17+TONT20000MAI!I17+TONT20000JUIN!I17+TONT20000JUIL!I17+TONT20000AOUT!I17+TONT20000SEPT!I17+TONT20000OCT!I17+TONT20000NOV!I17 -> 156000 | M17: =TONT20000DEC2015!J17+TONT20000JANV!J17+TONT20000FEV!J17+TONT20000MARS!J17+TONT20000AVRIL!J17+TONT20000MAI!J17+TONT20000JUIN!J17+TONT20000JUIL!J17+TONT20000AOUT!J17+TONT20000SEPT!J17+TONT20000OCT!J17+TONT20000NOV!J17 -> 0 | N17: =TONT20000DEC2015!K17+TONT20000JANV!K17+TONT20000FEV!K17+TONT20000MARS!K17+TONT20000AVRIL!K17+TONT20000MAI!K17+TONT20000JUIN!K17+TONT20000JUIL!K17+TONT20000AOUT!K17+TONT20000SEPT!K17+TONT20000OCT!K17+TONT20000NOV!K17 -> 0 | O17: =TONT20000DEC2015!L17+TONT20000JANV!L17+TONT20000FEV!L17+TONT20000MARS!L17+TONT20000AVRIL!L17+TONT20000MAI!L17+TONT20000JUIN!L17+TONT20000JUIL!L17+TONT20000AOUT!L17+TONT20000SEPT!L17+TONT20000OCT!L17+TONT20000NOV!L17 -> 0 | P17: =TONT20000DEC2015!M17+TONT20000JANV!M17+TONT20000FEV!M17+TONT20000MARS!M17+TONT20000AVRIL!M17+TONT20000MAI!M17+TONT20000JUIN!M17+TONT20000JUIL!M17+TONT20000AOUT!M17+TONT20000SEPT!N17+TONT20000OCT!M17+TONT20000NOV!M17 -> 0 | Q17: =TONT20000DEC2015!M17+TONT20000JANV!M17+TONT20000FEV!M17+TONT20000MARS!M17+TONT20000AVRIL!M17+TONT20000MAI!M17+TONT20000JUIN!M17+TONT20000JUIL!M17+TONT20000AOUT!M17+TONT20000SEPT!N17+TONT20000OCT!M17+TONT20000NOV!M17 -> 0
A18: AS201614 | B18: =VLOOKUP(A18,LISTADHERENT!A$5:H$51,2) -> KEPHE DAVID | C18: 0 | D18: 12795 | F18: =G18+H18+I18+J18+K18+L18+Q18 -> 243000 | G18: =TONT20000DEC2015!D18+TONT20000JANV!D18+TONT20000FEV!D18+TONT20000MARS!D18+TONT20000AVRIL!D18+TONT20000MAI!D18+TONT20000JUIN!D18+TONT20000JUIL!D18+TONT20000AOUT!D18+TONT20000SEPT!D18+TONT20000OCT!D18+TONT20000NOV!D18 -> 39000 | H18: =TONT20000DEC2015!E18+TONT20000JANV!E18+TONT20000FEV!E18+TONT20000MARS!E18+TONT20000AVRIL!E18+TONT20000MAI!E18+TONT20000JUIN!E18+TONT20000JUIL!E18+TONT20000AOUT!E18+TONT20000SEPT!E18+TONT20000OCT!E18+TONT20000NOV!E18 -> 6000 | I18: =TONT20000DEC2015!F18+TONT20000JANV!F18+TONT20000FEV!F18+TONT20000MARS!F18+TONT20000AVRIL!F18+TONT20000MAI!F18+TONT20000JUIN!F18+TONT20000JUIL!F18+TONT20000AOUT!F18+TONT20000SEPT!F18+TONT20000OCT!F18+TONT20000NOV!F18 -> 12000 | J18: =TONT20000DEC2015!G18+TONT20000JANV!G18+TONT20000FEV!G18+TONT20000MARS!G18+TONT20000AVRIL!G18+TONT20000MAI!G18+TONT20000JUIN!G18+TONT20000JUIL!G18+TONT20000AOUT!G18+TONT20000SEPT!G18+TONT20000OCT!G18+TONT20000NOV!G18 -> 30000 | K18: =TONT20000DEC2015!H18+TONT20000JANV!H18+TONT20000FEV!H18+TONT20000MARS!H18+TONT20000AVRIL!H18+TONT20000MAI!H18+TONT20000JUIN!H18+TONT20000JUIL!H18+TONT20000AOUT!H18+TONT20000SEPT!H18+TONT20000OCT!H18+TONT20000NOV!H18 -> 0 | L18: =TONT20000DEC2015!I18+TONT20000JANV!I18+TONT20000FEV!I18+TONT20000MARS!I18+TONT20000AVRIL!I18+TONT20000MAI!I18+TONT20000JUIN!I18+TONT20000JUIL!I18+TONT20000AOUT!I18+TONT20000SEPT!I18+TONT20000OCT!I18+TONT20000NOV!I18 -> 156000 | M18: =TONT20000DEC2015!J18+TONT20000JANV!J18+TONT20000FEV!J18+TONT20000MARS!J18+TONT20000AVRIL!J18+TONT20000MAI!J18+TONT20000JUIN!J18+TONT20000JUIL!J18+TONT20000AOUT!J18+TONT20000SEPT!J18+TONT20000OCT!J18+TONT20000NOV!J18 -> 0 | N18: =TONT20000DEC2015!K18+TONT20000JANV!K18+TONT20000FEV!K18+TONT20000MARS!K18+TONT20000AVRIL!K18+TONT20000MAI!K18+TONT20000JUIN!K18+TONT20000JUIL!K18+TONT20000AOUT!K18+TONT20000SEPT!K18+TONT20000OCT!K18+TONT20000NOV!K18 -> 0 | O18: =TONT20000DEC2015!L18+TONT20000JANV!L18+TONT20000FEV!L18+TONT20000MARS!L18+TONT20000AVRIL!L18+TONT20000MAI!L18+TONT20000JUIN!L18+TONT20000JUIL!L18+TONT20000AOUT!L18+TONT20000SEPT!L18+TONT20000OCT!L18+TONT20000NOV!L18 -> 0 | P18: =TONT20000DEC2015!M18+TONT20000JANV!M18+TONT20000FEV!M18+TONT20000MARS!M18+TONT20000AVRIL!M18+TONT20000MAI!M18+TONT20000JUIN!M18+TONT20000JUIL!M18+TONT20000AOUT!M18+TONT20000SEPT!N18+TONT20000OCT!M18+TONT20000NOV!M18 -> 0 | Q18: =TONT20000DEC2015!M18+TONT20000JANV!M18+TONT20000FEV!M18+TONT20000MARS!M18+TONT20000AVRIL!M18+TONT20000MAI!M18+TONT20000JUIN!M18+TONT20000JUIL!M18+TONT20000AOUT!M18+TONT20000SEPT!N18+TONT20000OCT!M18+TONT20000NOV!M18 -> 0
A19: AS201615 | B19: =VLOOKUP(A19,LISTADHERENT!A$5:H$51,2) -> KEPSEU FRANCIS | C19: 390000 | D19: 186997 | F19: =G19+H19+I19+J19+K19+L19+Q19 -> 753000 | G19: =TONT20000DEC2015!D19+TONT20000JANV!D19+TONT20000FEV!D19+TONT20000MARS!D19+TONT20000AVRIL!D19+TONT20000MAI!D19+TONT20000JUIN!D19+TONT20000JUIL!D19+TONT20000AOUT!D19+TONT20000SEPT!D19+TONT20000OCT!D19+TONT20000NOV!D19 -> 549000 | H19: =TONT20000DEC2015!E19+TONT20000JANV!E19+TONT20000FEV!E19+TONT20000MARS!E19+TONT20000AVRIL!E19+TONT20000MAI!E19+TONT20000JUIN!E19+TONT20000JUIL!E19+TONT20000AOUT!E19+TONT20000SEPT!E19+TONT20000OCT!E19+TONT20000NOV!E19 -> 6000 | I19: =TONT20000DEC2015!F19+TONT20000JANV!F19+TONT20000FEV!F19+TONT20000MARS!F19+TONT20000AVRIL!F19+TONT20000MAI!F19+TONT20000JUIN!F19+TONT20000JUIL!F19+TONT20000AOUT!F19+TONT20000SEPT!F19+TONT20000OCT!F19+TONT20000NOV!F19 -> 12000 | J19: =TONT20000DEC2015!G19+TONT20000JANV!G19+TONT20000FEV!G19+TONT20000MARS!G19+TONT20000AVRIL!G19+TONT20000MAI!G19+TONT20000JUIN!G19+TONT20000JUIL!G19+TONT20000AOUT!G19+TONT20000SEPT!G19+TONT20000OCT!G19+TONT20000NOV!G19 -> 30000 | K19: =TONT20000DEC2015!H19+TONT20000JANV!H19+TONT20000FEV!H19+TONT20000MARS!H19+TONT20000AVRIL!H19+TONT20000MAI!H19+TONT20000JUIN!H19+TONT20000JUIL!H19+TONT20000AOUT!H19+TONT20000SEPT!H19+TONT20000OCT!H19+TONT20000NOV!H19 -> 0 | L19: =TONT20000DEC2015!I19+TONT20000JANV!I19+TONT20000FEV!I19+TONT20000MARS!I19+TONT20000AVRIL!I19+TONT20000MAI!I19+TONT20000JUIN!I19+TONT20000JUIL!I19+TONT20000AOUT!I19+TONT20000SEPT!I19+TONT20000OCT!I19+TONT20000NOV!I19 -> 156000 | M19: =TONT20000DEC2015!J19+TONT20000JANV!J19+TONT20000FEV!J19+TONT20000MARS!J19+TONT20000AVRIL!J19+TONT20000MAI!J19+TONT20000JUIN!J19+TONT20000JUIL!J19+TONT20000AOUT!J19+TONT20000SEPT!J19+TONT20000OCT!J19+TONT20000NOV!J19 -> 0 | N19: =TONT20000DEC2015!K19+TONT20000JANV!K19+TONT20000FEV!K19+TONT20000MARS!K19+TONT20000AVRIL!K19+TONT20000MAI!K19+TONT20000JUIN!K19+TONT20000JUIL!K19+TONT20000AOUT!K19+TONT20000SEPT!K19+TONT20000OCT!K19+TONT20000NOV!K19 -> 0 | O19: =TONT20000DEC2015!L19+TONT20000JANV!L19+TONT20000FEV!L19+TONT20000MARS!L19+TONT20000AVRIL!L19+TONT20000MAI!L19+TONT20000JUIN!L19+TONT20000JUIL!L19+TONT20000AOUT!L19+TONT20000SEPT!L19+TONT20000OCT!L19+TONT20000NOV!L19 -> 0 | P19: =TONT20000DEC2015!M19+TONT20000JANV!M19+TONT20000FEV!M19+TONT20000MARS!M19+TONT20000AVRIL!M19+TONT20000MAI!M19+TONT20000JUIN!M19+TONT20000JUIL!M19+TONT20000AOUT!M19+TONT20000SEPT!N19+TONT20000OCT!M19+TONT20000NOV!M19 -> 0 | Q19: =TONT20000DEC2015!M19+TONT20000JANV!M19+TONT20000FEV!M19+TONT20000MARS!M19+TONT20000AVRIL!M19+TONT20000MAI!M19+TONT20000JUIN!M19+TONT20000JUIL!M19+TONT20000AOUT!M19+TONT20000SEPT!N19+TONT20000OCT!M19+TONT20000NOV!M19 -> 0
A20: AS201616 | B20: =VLOOKUP(A20,LISTADHERENT!A$5:H$51,2) -> KOUAMOU EMMANUEL | C20: 390000 | D20: 2723 | F20: =G20+H20+I20+J20+K20+L20+Q20 -> 240000 | G20: =TONT20000DEC2015!D20+TONT20000JANV!D20+TONT20000FEV!D20+TONT20000MARS!D20+TONT20000AVRIL!D20+TONT20000MAI!D20+TONT20000JUIN!D20+TONT20000JUIL!D20+TONT20000AOUT!D20+TONT20000SEPT!D20+TONT20000OCT!D20+TONT20000NOV!D20 -> 36000 | H20: =TONT20000DEC2015!E20+TONT20000JANV!E20+TONT20000FEV!E20+TONT20000MARS!E20+TONT20000AVRIL!E20+TONT20000MAI!E20+TONT20000JUIN!E20+TONT20000JUIL!E20+TONT20000AOUT!E20+TONT20000SEPT!E20+TONT20000OCT!E20+TONT20000NOV!E20 -> 6000 | I20: =TONT20000DEC2015!F20+TONT20000JANV!F20+TONT20000FEV!F20+TONT20000MARS!F20+TONT20000AVRIL!F20+TONT20000MAI!F20+TONT20000JUIN!F20+TONT20000JUIL!F20+TONT20000AOUT!F20+TONT20000SEPT!F20+TONT20000OCT!F20+TONT20000NOV!F20 -> 12000 | J20: =TONT20000DEC2015!G20+TONT20000JANV!G20+TONT20000FEV!G20+TONT20000MARS!G20+TONT20000AVRIL!G20+TONT20000MAI!G20+TONT20000JUIN!G20+TONT20000JUIL!G20+TONT20000AOUT!G20+TONT20000SEPT!G20+TONT20000OCT!G20+TONT20000NOV!G20 -> 30000 | K20: =TONT20000DEC2015!H20+TONT20000JANV!H20+TONT20000FEV!H20+TONT20000MARS!H20+TONT20000AVRIL!H20+TONT20000MAI!H20+TONT20000JUIN!H20+TONT20000JUIL!H20+TONT20000AOUT!H20+TONT20000SEPT!H20+TONT20000OCT!H20+TONT20000NOV!H20 -> 0 | L20: =TONT20000DEC2015!I20+TONT20000JANV!I20+TONT20000FEV!I20+TONT20000MARS!I20+TONT20000AVRIL!I20+TONT20000MAI!I20+TONT20000JUIN!I20+TONT20000JUIL!I20+TONT20000AOUT!I20+TONT20000SEPT!I20+TONT20000OCT!I20+TONT20000NOV!I20 -> 156000 | M20: =TONT20000DEC2015!J20+TONT20000JANV!J20+TONT20000FEV!J20+TONT20000MARS!J20+TONT20000AVRIL!J20+TONT20000MAI!J20+TONT20000JUIN!J20+TONT20000JUIL!J20+TONT20000AOUT!J20+TONT20000SEPT!J20+TONT20000OCT!J20+TONT20000NOV!J20 -> 1000000 | N20: =TONT20000DEC2015!K20+TONT20000JANV!K20+TONT20000FEV!K20+TONT20000MARS!K20+TONT20000AVRIL!K20+TONT20000MAI!K20+TONT20000JUIN!K20+TONT20000JUIL!K20+TONT20000AOUT!K20+TONT20000SEPT!K20+TONT20000OCT!K20+TONT20000NOV!K20 -> 120000 | O20: =TONT20000DEC2015!L20+TONT20000JANV!L20+TONT20000FEV!L20+TONT20000MARS!L20+TONT20000AVRIL!L20+TONT20000MAI!L20+TONT20000JUIN!L20+TONT20000JUIL!L20+TONT20000AOUT!L20+TONT20000SEPT!L20+TONT20000OCT!L20+TONT20000NOV!L20 -> 0 | P20: =TONT20000DEC2015!M20+TONT20000JANV!M20+TONT20000FEV!M20+TONT20000MARS!M20+TONT20000AVRIL!M20+TONT20000MAI!M20+TONT20000JUIN!M20+TONT20000JUIL!M20+TONT20000AOUT!M20+TONT20000SEPT!N20+TONT20000OCT!M20+TONT20000NOV!M20 -> 0 | Q20: =TONT20000DEC2015!M20+TONT20000JANV!M20+TONT20000FEV!M20+TONT20000MARS!M20+TONT20000AVRIL!M20+TONT20000MAI!M20+TONT20000JUIN!M20+TONT20000JUIL!M20+TONT20000AOUT!M20+TONT20000SEPT!N20+TONT20000OCT!M20+TONT20000NOV!M20 -> 0
A21: AS201617 | B21: =VLOOKUP(A21,LISTADHERENT!A$5:H$51,2) -> KOUAMOU MOISE | C21: 390000 | D21: 2099 | F21: =G21+H21+I21+J21+K21+L21+Q21 -> 240000 | G21: =TONT20000DEC2015!D21+TONT20000JANV!D21+TONT20000FEV!D21+TONT20000MARS!D21+TONT20000AVRIL!D21+TONT20000MAI!D21+TONT20000JUIN!D21+TONT20000JUIL!D21+TONT20000AOUT!D21+TONT20000SEPT!D21+TONT20000OCT!D21+TONT20000NOV!D21 -> 36000 | H21: =TONT20000DEC2015!E21+TONT20000JANV!E21+TONT20000FEV!E21+TONT20000MARS!E21+TONT20000AVRIL!E21+TONT20000MAI!E21+TONT20000JUIN!E21+TONT20000JUIL!E21+TONT20000AOUT!E21+TONT20000SEPT!E21+TONT20000OCT!E21+TONT20000NOV!E21 -> 6000 | I21: =TONT20000DEC2015!F21+TONT20000JANV!F21+TONT20000FEV!F21+TONT20000MARS!F21+TONT20000AVRIL!F21+TONT20000MAI!F21+TONT20000JUIN!F21+TONT20000JUIL!F21+TONT20000AOUT!F21+TONT20000SEPT!F21+TONT20000OCT!F21+TONT20000NOV!F21 -> 12000 | J21: =TONT20000DEC2015!G21+TONT20000JANV!G21+TONT20000FEV!G21+TONT20000MARS!G21+TONT20000AVRIL!G21+TONT20000MAI!G21+TONT20000JUIN!G21+TONT20000JUIL!G21+TONT20000AOUT!G21+TONT20000SEPT!G21+TONT20000OCT!G21+TONT20000NOV!G21 -> 30000 | K21: =TONT20000DEC2015!H21+TONT20000JANV!H21+TONT20000FEV!H21+TONT20000MARS!H21+TONT20000AVRIL!H21+TONT20000MAI!H21+TONT20000JUIN!H21+TONT20000JUIL!H21+TONT20000AOUT!H21+TONT20000SEPT!H21+TONT20000OCT!H21+TONT20000NOV!H21 -> 0 | L21: =TONT20000DEC2015!I21+TONT20000JANV!I21+TONT20000FEV!I21+TONT20000MARS!I21+TONT20000AVRIL!I21+TONT20000MAI!I21+TONT20000JUIN!I21+TONT20000JUIL!I21+TONT20000AOUT!I21+TONT20000SEPT!I21+TONT20000OCT!I21+TONT20000NOV!I21 -> 156000 | M21: =TONT20000DEC2015!J21+TONT20000JANV!J21+TONT20000FEV!J21+TONT20000MARS!J21+TONT20000AVRIL!J21+TONT20000MAI!J21+TONT20000JUIN!J21+TONT20000JUIL!J21+TONT20000AOUT!J21+TONT20000SEPT!J21+TONT20000OCT!J21+TONT20000NOV!J21 -> 860000 | N21: =TONT20000DEC2015!K21+TONT20000JANV!K21+TONT20000FEV!K21+TONT20000MARS!K21+TONT20000AVRIL!K21+TONT20000MAI!K21+TONT20000JUIN!K21+TONT20000JUIL!K21+TONT20000AOUT!K21+TONT20000SEPT!K21+TONT20000OCT!K21+TONT20000NOV!K21 -> 97800 | O21: =TONT20000DEC2015!L21+TONT20000JANV!L21+TONT20000FEV!L21+TONT20000MARS!L21+TONT20000AVRIL!L21+TONT20000MAI!L21+TONT20000JUIN!L21+TONT20000JUIL!L21+TONT20000AOUT!L21+TONT20000SEPT!L21+TONT20000OCT!L21+TONT20000NOV!L21 -> 0 | P21: =TONT20000DEC2015!M21+TONT20000JANV!M21+TONT20000FEV!M21+TONT20000MARS!M21+TONT20000AVRIL!M21+TONT20000MAI!M21+TONT20000JUIN!M21+TONT20000JUIL!M21+TONT20000AOUT!M21+TONT20000SEPT!N21+TONT20000OCT!M21+TONT20000NOV!M21 -> 0 | Q21: =TONT20000DEC2015!M21+TONT20000JANV!M21+TONT20000FEV!M21+TONT20000MARS!M21+TONT20000AVRIL!M21+TONT20000MAI!M21+TONT20000JUIN!M21+TONT20000JUIL!M21+TONT20000AOUT!M21+TONT20000SEPT!N21+TONT20000OCT!M21+TONT20000NOV!M21 -> 0
A22: AS201618 | B22: =VLOOKUP(A22,LISTADHERENT!A$5:H$51,2) -> KOUAMOU VICTOR PEGUY | C22: 390000 | D22: 36629 | F22: =G22+H22+I22+J22+K22+L22+Q22 -> 239000 | G22: =TONT20000DEC2015!D22+TONT20000JANV!D22+TONT20000FEV!D22+TONT20000MARS!D22+TONT20000AVRIL!D22+TONT20000MAI!D22+TONT20000JUIN!D22+TONT20000JUIL!D22+TONT20000AOUT!D22+TONT20000SEPT!D22+TONT20000OCT!D22+TONT20000NOV!D22 -> 35000 | H22: =TONT20000DEC2015!E22+TONT20000JANV!E22+TONT20000FEV!E22+TONT20000MARS!E22+TONT20000AVRIL!E22+TONT20000MAI!E22+TONT20000JUIN!E22+TONT20000JUIL!E22+TONT20000AOUT!E22+TONT20000SEPT!E22+TONT20000OCT!E22+TONT20000NOV!E22 -> 6000 | I22: =TONT20000DEC2015!F22+TONT20000JANV!F22+TONT20000FEV!F22+TONT20000MARS!F22+TONT20000AVRIL!F22+TONT20000MAI!F22+TONT20000JUIN!F22+TONT20000JUIL!F22+TONT20000AOUT!F22+TONT20000SEPT!F22+TONT20000OCT!F22+TONT20000NOV!F22 -> 12000 | J22: =TONT20000DEC2015!G22+TONT20000JANV!G22+TONT20000FEV!G22+TONT20000MARS!G22+TONT20000AVRIL!G22+TONT20000MAI!G22+TONT20000JUIN!G22+TONT20000JUIL!G22+TONT20000AOUT!G22+TONT20000SEPT!G22+TONT20000OCT!G22+TONT20000NOV!G22 -> 30000 | K22: =TONT20000DEC2015!H22+TONT20000JANV!H22+TONT20000FEV!H22+TONT20000MARS!H22+TONT20000AVRIL!H22+TONT20000MAI!H22+TONT20000JUIN!H22+TONT20000JUIL!H22+TONT20000AOUT!H22+TONT20000SEPT!H22+TONT20000OCT!H22+TONT20000NOV!H22 -> 0 | L22: =TONT20000DEC2015!I22+TONT20000JANV!I22+TONT20000FEV!I22+TONT20000MARS!I22+TONT20000AVRIL!I22+TONT20000MAI!I22+TONT20000JUIN!I22+TONT20000JUIL!I22+TONT20000AOUT!I22+TONT20000SEPT!I22+TONT20000OCT!I22+TONT20000NOV!I22 -> 156000 | M22: =TONT20000DEC2015!J22+TONT20000JANV!J22+TONT20000FEV!J22+TONT20000MARS!J22+TONT20000AVRIL!J22+TONT20000MAI!J22+TONT20000JUIN!J22+TONT20000JUIL!J22+TONT20000AOUT!J22+TONT20000SEPT!J22+TONT20000OCT!J22+TONT20000NOV!J22 -> 1800000 | N22: =TONT20000DEC2015!K22+TONT20000JANV!K22+TONT20000FEV!K22+TONT20000MARS!K22+TONT20000AVRIL!K22+TONT20000MAI!K22+TONT20000JUIN!K22+TONT20000JUIL!K22+TONT20000AOUT!K22+TONT20000SEPT!K22+TONT20000OCT!K22+TONT20000NOV!K22 -> 128000 | O22: =TONT20000DEC2015!L22+TONT20000JANV!L22+TONT20000FEV!L22+TONT20000MARS!L22+TONT20000AVRIL!L22+TONT20000MAI!L22+TONT20000JUIN!L22+TONT20000JUIL!L22+TONT20000AOUT!L22+TONT20000SEPT!L22+TONT20000OCT!L22+TONT20000NOV!L22 -> 1000000 | P22: =TONT20000DEC2015!M22+TONT20000JANV!M22+TONT20000FEV!M22+TONT20000MARS!M22+TONT20000AVRIL!M22+TONT20000MAI!M22+TONT20000JUIN!M22+TONT20000JUIL!M22+TONT20000AOUT!M22+TONT20000SEPT!N22+TONT20000OCT!M22+TONT20000NOV!M22 -> 0 | Q22: =TONT20000DEC2015!M22+TONT20000JANV!M22+TONT20000FEV!M22+TONT20000MARS!M22+TONT20000AVRIL!M22+TONT20000MAI!M22+TONT20000JUIN!M22+TONT20000JUIL!M22+TONT20000AOUT!M22+TONT20000SEPT!N22+TONT20000OCT!M22+TONT20000NOV!M22 -> 0
A23: AS201619 | B23: =VLOOKUP(A23,LISTADHERENT!A$5:H$51,2) -> KOUATCHO MESSACK | C23: 390000 | D23: 0 | F23: =G23+H23+I23+J23+K23+L23+Q23 -> 240000 | G23: =TONT20000DEC2015!D23+TONT20000JANV!D23+TONT20000FEV!D23+TONT20000MARS!D23+TONT20000AVRIL!D23+TONT20000MAI!D23+TONT20000JUIN!D23+TONT20000JUIL!D23+TONT20000AOUT!D23+TONT20000SEPT!D23+TONT20000OCT!D23+TONT20000NOV!D23 -> 36000 | H23: =TONT20000DEC2015!E23+TONT20000JANV!E23+TONT20000FEV!E23+TONT20000MARS!E23+TONT20000AVRIL!E23+TONT20000MAI!E23+TONT20000JUIN!E23+TONT20000JUIL!E23+TONT20000AOUT!E23+TONT20000SEPT!E23+TONT20000OCT!E23+TONT20000NOV!E23 -> 6000 | I23: =TONT20000DEC2015!F23+TONT20000JANV!F23+TONT20000FEV!F23+TONT20000MARS!F23+TONT20000AVRIL!F23+TONT20000MAI!F23+TONT20000JUIN!F23+TONT20000JUIL!F23+TONT20000AOUT!F23+TONT20000SEPT!F23+TONT20000OCT!F23+TONT20000NOV!F23 -> 12000 | J23: =TONT20000DEC2015!G23+TONT20000JANV!G23+TONT20000FEV!G23+TONT20000MARS!G23+TONT20000AVRIL!G23+TONT20000MAI!G23+TONT20000JUIN!G23+TONT20000JUIL!G23+TONT20000AOUT!G23+TONT20000SEPT!G23+TONT20000OCT!G23+TONT20000NOV!G23 -> 30000 | K23: =TONT20000DEC2015!H23+TONT20000JANV!H23+TONT20000FEV!H23+TONT20000MARS!H23+TONT20000AVRIL!H23+TONT20000MAI!H23+TONT20000JUIN!H23+TONT20000JUIL!H23+TONT20000AOUT!H23+TONT20000SEPT!H23+TONT20000OCT!H23+TONT20000NOV!H23 -> 0 | L23: =TONT20000DEC2015!I23+TONT20000JANV!I23+TONT20000FEV!I23+TONT20000MARS!I23+TONT20000AVRIL!I23+TONT20000MAI!I23+TONT20000JUIN!I23+TONT20000JUIL!I23+TONT20000AOUT!I23+TONT20000SEPT!I23+TONT20000OCT!I23+TONT20000NOV!I23 -> 156000 | M23: =TONT20000DEC2015!J23+TONT20000JANV!J23+TONT20000FEV!J23+TONT20000MARS!J23+TONT20000AVRIL!J23+TONT20000MAI!J23+TONT20000JUIN!J23+TONT20000JUIL!J23+TONT20000AOUT!J23+TONT20000SEPT!J23+TONT20000OCT!J23+TONT20000NOV!J23 -> 1600000 | N23: =TONT20000DEC2015!K23+TONT20000JANV!K23+TONT20000FEV!K23+TONT20000MARS!K23+TONT20000AVRIL!K23+TONT20000MAI!K23+TONT20000JUIN!K23+TONT20000JUIL!K23+TONT20000AOUT!K23+TONT20000SEPT!K23+TONT20000OCT!K23+TONT20000NOV!K23 -> 192000 | O23: =TONT20000DEC2015!L23+TONT20000JANV!L23+TONT20000FEV!L23+TONT20000MARS!L23+TONT20000AVRIL!L23+TONT20000MAI!L23+TONT20000JUIN!L23+TONT20000JUIL!L23+TONT20000AOUT!L23+TONT20000SEPT!L23+TONT20000OCT!L23+TONT20000NOV!L23 -> 0 | P23: =TONT20000DEC2015!M23+TONT20000JANV!M23+TONT20000FEV!M23+TONT20000MARS!M23+TONT20000AVRIL!M23+TONT20000MAI!M23+TONT20000JUIN!M23+TONT20000JUIL!M23+TONT20000AOUT!M23+TONT20000SEPT!N23+TONT20000OCT!M23+TONT20000NOV!M23 -> 0 | Q23: =TONT20000DEC2015!M23+TONT20000JANV!M23+TONT20000FEV!M23+TONT20000MARS!M23+TONT20000AVRIL!M23+TONT20000MAI!M23+TONT20000JUIN!M23+TONT20000JUIL!M23+TONT20000AOUT!M23+TONT20000SEPT!N23+TONT20000OCT!M23+TONT20000NOV!M23 -> 0
A24: AS201620 | B24: =VLOOKUP(A24,LISTADHERENT!A$5:H$51,2) -> LOWE JEAN | C24: 390000 | D24: 4331 | F24: =G24+H24+I24+J24+K24+L24+Q24 -> 240000 | G24: =TONT20000DEC2015!D24+TONT20000JANV!D24+TONT20000FEV!D24+TONT20000MARS!D24+TONT20000AVRIL!D24+TONT20000MAI!D24+TONT20000JUIN!D24+TONT20000JUIL!D24+TONT20000AOUT!D24+TONT20000SEPT!D24+TONT20000OCT!D24+TONT20000NOV!D24 -> 36000 | H24: =TONT20000DEC2015!E24+TONT20000JANV!E24+TONT20000FEV!E24+TONT20000MARS!E24+TONT20000AVRIL!E24+TONT20000MAI!E24+TONT20000JUIN!E24+TONT20000JUIL!E24+TONT20000AOUT!E24+TONT20000SEPT!E24+TONT20000OCT!E24+TONT20000NOV!E24 -> 6000 | I24: =TONT20000DEC2015!F24+TONT20000JANV!F24+TONT20000FEV!F24+TONT20000MARS!F24+TONT20000AVRIL!F24+TONT20000MAI!F24+TONT20000JUIN!F24+TONT20000JUIL!F24+TONT20000AOUT!F24+TONT20000SEPT!F24+TONT20000OCT!F24+TONT20000NOV!F24 -> 12000 | J24: =TONT20000DEC2015!G24+TONT20000JANV!G24+TONT20000FEV!G24+TONT20000MARS!G24+TONT20000AVRIL!G24+TONT20000MAI!G24+TONT20000JUIN!G24+TONT20000JUIL!G24+TONT20000AOUT!G24+TONT20000SEPT!G24+TONT20000OCT!G24+TONT20000NOV!G24 -> 30000 | K24: =TONT20000DEC2015!H24+TONT20000JANV!H24+TONT20000FEV!H24+TONT20000MARS!H24+TONT20000AVRIL!H24+TONT20000MAI!H24+TONT20000JUIN!H24+TONT20000JUIL!H24+TONT20000AOUT!H24+TONT20000SEPT!H24+TONT20000OCT!H24+TONT20000NOV!H24 -> 0 | L24: =TONT20000DEC2015!I24+TONT20000JANV!I24+TONT20000FEV!I24+TONT20000MARS!I24+TONT20000AVRIL!I24+TONT20000MAI!I24+TONT20000JUIN!I24+TONT20000JUIL!I24+TONT20000AOUT!I24+TONT20000SEPT!I24+TONT20000OCT!I24+TONT20000NOV!I24 -> 156000 | M24: =TONT20000DEC2015!J24+TONT20000JANV!J24+TONT20000FEV!J24+TONT20000MARS!J24+TONT20000AVRIL!J24+TONT20000MAI!J24+TONT20000JUIN!J24+TONT20000JUIL!J24+TONT20000AOUT!J24+TONT20000SEPT!J24+TONT20000OCT!J24+TONT20000NOV!J24 -> 240000 | N24: =TONT20000DEC2015!K24+TONT20000JANV!K24+TONT20000FEV!K24+TONT20000MARS!K24+TONT20000AVRIL!K24+TONT20000MAI!K24+TONT20000JUIN!K24+TONT20000JUIL!K24+TONT20000AOUT!K24+TONT20000SEPT!K24+TONT20000OCT!K24+TONT20000NOV!K24 -> 7200 | O24: =TONT20000DEC2015!L24+TONT20000JANV!L24+TONT20000FEV!L24+TONT20000MARS!L24+TONT20000AVRIL!L24+TONT20000MAI!L24+TONT20000JUIN!L24+TONT20000JUIL!L24+TONT20000AOUT!L24+TONT20000SEPT!L24+TONT20000OCT!L24+TONT20000NOV!L24 -> 160000 | P24: =TONT20000DEC2015!M24+TONT20000JANV!M24+TONT20000FEV!M24+TONT20000MARS!M24+TONT20000AVRIL!M24+TONT20000MAI!M24+TONT20000JUIN!M24+TONT20000JUIL!M24+TONT20000AOUT!M24+TONT20000SEPT!N24+TONT20000OCT!M24+TONT20000NOV!M24 -> 0 | Q24: =TONT20000DEC2015!M24+TONT20000JANV!M24+TONT20000FEV!M24+TONT20000MARS!M24+TONT20000AVRIL!M24+TONT20000MAI!M24+TONT20000JUIN!M24+TONT20000JUIL!M24+TONT20000AOUT!M24+TONT20000SEPT!N24+TONT20000OCT!M24+TONT20000NOV!M24 -> 0
