Workbook
Name MODEPAID: [1]Feuil2!$A$1:$A$3

Sheet FICHESUIVI
A1: LIEU RECEPTION | D1: TONTINE 20 000 | E1: TONTINE 60 000 | F1: TONTINE 100 000
A2: NOM ADHERENT
A3: DATE TONTINE
A4: NOM ACHETEUR
A5: MONTANT INTERET ACHAT
A6: NATURE OPERATION | B6: EPARGNE | D6: FONDS DE ROULEMENT | F6: FRAIS EXCEPTIONNEL | H6: COLLATION | J6: EMPRUNT/REMBOURSEMENT | L6: PENALITE EMPRUNT | M6: PENALITE FONDS | N6: INTERET ACHAT TONTINE | O6: COMPLEMENT TONTINE | Q6: SANCTION
B7: ENTREE | C7: SORTIE | D7: ENTREE | E7: SORTIE | F7: ENTREE | G7: SORTIE | H7: ENTREE | I7: SORTIE | J7: ENTREE | K7: SORTIE | L7: ENTREE | M7: ENTREE | N7: ENTREE | O7: ENTREE | P7: SORTIE | Q7: ENTREE | R7: SORTIE

Sheet TRAVAUXINVENTAIRE
A1: ASSOCIATION | B1: ASELBY
A2: ANNEE | B2: 2016/2017
A3: TONTINE | B3: 20 000
A4: MATRICULE | B4: NOM ET PRENOM | C4: FONDS DE CAISSE | D4: RELIQUAT 2015 | E4: CAPITAL DEPART | F4: REPARTITION INTERET | G4: CAPITAL COMPOSE FIN | H4: CAPITAL TOTAL A PERCEVOIR | I4: RETENUE | J4: CAPITAL A DISTRIBUER | K4: MONTANT EFFECTIVEMENT VERSE | L4: COMPLEMENT FONDS | M4: SANCTION | N4: RETOUR EN CAISSE MUTUELLE | O4: FRAIS FIXE A PRELEVER | P4: MONTANT VERSE | Q4: EPARGNE | R4: FONDS DE ROULEMENT | S4: FRAIS EXCEPTIONNEL | T4: COLLATION | U4: MUTUELLE | V4: TONTINE | W4: EMPRUNT | X4: INTERET EMPRUNT | Y4: REMBOURSEMENT | Z4: PENALITE EMPRUNT | AA4: PENALITE FONDS | AB4: INTERET ACHAT | AC4: DATE ACHAT
A5: AS201648 | B5: =VLOOKUP(A5,[2]LISTADHERENT!A$5:H$52,2,0) -> ASELBY | C5: =VLOOKUP(A5,[2]FONDSDECAISSE!A$5:C$52,3,0) -> 0 | D5: 318145 | E5: =C5+D5+Q5 -> 318145 | F5: =INT([2]TONT20000DEC2015!E5+[2]TONT20000JANV!C5+[2]TONT20000FEV!C5+[2]TONT20000MARS!C5+[2]TONT20000AVRIL!C5+[2]TONT20000MAI!C5+[2]TONT20000JUIN!C5+[2]TONT20000JUIL!C5+[2]TONT20000AOUT!C5+[2]TONT20000SEPT!C5+[2]TONT20000OCT!C5+[2]TONT20000NOV!C5) -> 36952 | G5: =[2]TONT20000NOV!E5 -> 355097.52 | H5: =D5+F5+Q5 -> 355097 | I5: =L5+M5+N5+O5 -> 0 | J5: =H5-I5 -> 355097 | K5: 353000 | L5: 0 | M5: 0 | N5: 0 | O5: 0 | P5: =[2]TONT20000DEC2015!H5+[2]TONT20000JANV!F5+[2]TONT20000FEV!F5+[2]TONT20000MARS!F5+[2]TONT20000AVRIL!F5+[2]TONT20000MAI!F5+[2]TONT20000JUIN!F5+[2]TONT20000JUIL!F5+[2]TONT20000AOUT!F5+[2]TONT20000SEPT!F5+[2]TONT20000OCT!F5+[2]TONT20000NOV!G5 -> 0 | Q5: =[2]TONT20000DEC2015!I5+[2]TONT20000JANV!G5+[2]TONT20000FEV!G5+[2]TONT20000MARS!G5+[2]TONT20000AVRIL!G5+[2]TONT20000MAI!G5+[2]TONT20000JUIN!G5+[2]TONT20000JUIL!G5+[2]TONT20000AOUT!G5+[2]TONT20000SEPT!G5+[2]TONT20000OCT!G5+[2]TONT20000NOV!H5 -> 0 | R5: =[2]TONT20000DEC2015!J5+[2]TONT20000JANV!H5+[2]TONT20000FEV!H5+[2]TONT20000MARS!H5+[2]TONT20000AVRIL!H5+[2]TONT20000MAI!H5+[2]TONT20000JUIN!H5+[2]TONT20000JUIL!H5+[2]TONT20000AOUT!H5+[2]TONT20000SEPT!H5+[2]TONT20000OCT!H5+[2]TONT20000NOV!I5 -> 0 | S5: =[2]TONT20000DEC2015!K5+[2]TONT20000JANV!I5+[2]TONT20000FEV!I5+[2]TONT20000MARS!I5+[2]TONT20000AVRIL!I5+[2]TONT20000MAI!I5+[2]TONT20000JUIN!I5+[2]TONT20000JUIL!I5+[2]TONT20000AOUT!I5+[2]TONT20000SEPT!I5+[2]TONT20000OCT!I5+[2]TONT20000NOV!J5 -> 0 | T5: =[2]TONT20000DEC2015!L5+[2]TONT20000JANV!J5+[2]TONT20000FEV!J5+[2]TONT20000MARS!J5+[2]TONT20000AVRIL!J5+[2]TONT20000MAI!J5+[2]TONT20000JUIN!J5+[2]TONT20000JUIL!J5+[2]TONT20000AOUT!J5+[2]TONT20000SEPT!J5+[2]TONT20000OCT!J5+[2]TONT20000NOV!K5 -> 0 | U5: =[2]TONT20000DEC2015!M5+[2]TONT20000JANV!K5+[2]TONT20000FEV!K5+[2]TONT20000MARS!K5+[2]TONT20000AVRIL!K5+[2]TONT20000MAI!K5+[2]TONT20000JUIN!K5+[2]TONT20000JUIL!K5+[2]TONT20000AOUT!K5+[2]TONT20000SEPT!K5+[2]TONT20000OCT!K5+[2]TONT20000NOV!L5 -> 0 | V5: =[2]TONT20000DEC2015!N5+[2]TONT20000JANV!L5+[2]TONT20000FEV!L5+[2]TONT20000MARS!L5+[2]TONT20000AVRIL!L5+[2]TONT20000MAI!L5+[2]TONT20000JUIN!L5+[2]TONT20000JUIL!L5+[2]TONT20000AOUT!L5+[2]TONT20000SEPT!L5+[2]TONT20000OCT!L5+[2]TONT20000NOV!M5 -> 0 | W5: =[2]TONT20000DEC2015!O5+[2]TONT20000JANV!M5+[2]TONT20000FEV!M5+[2]TONT20000MARS!M5+[2]TONT20000AVRIL!M5+[2]TONT20000MAI!M5+[2]TONT20000JUIN!M5+[2]TONT20000JUIL!M5+[2]TONT20000AOUT!M5+[2]TONT20000SEPT!M5+[2]TONT20000OCT!M5+[2]TONT20000NOV!N5 -> 0 | ... AB5: =[2]TONT20000DEC2015!T5+[2]TONT20000JANV!R5+[2]TONT20000FEV!R5+[2]TONT20000MARS!R5+[2]TONT20000AVRIL!R5+[2]TONT20000MAI!R5+[2]TONT20000JUIN!R5+[2]TONT20000JUIL!R5+[2]TONT20000AOUT!R5+[2]TONT20000SEPT!R5+[2]TONT20000OCT!R5+[2]TONT20000NOV!S5 -> 0
A6: AS201601 | B6: =VLOOKUP(A6,[2]LISTADHERENT!A$5:H$52,2,0) -> BAKOP ACHILLE | C6: =VLOOKUP(A6,[2]FONDSDECAISSE!A$5:C$52,3,0) -> 390000 | D6: 33536 | E6: =C6+D6+Q6 -> 453536 | F6: =INT([2]TONT20000DEC2015!E6+[2]TONT20000JANV!C6+[2]TONT20000FEV!C6+[2]TONT20000MARS!C6+[2]TONT20000AVRIL!C6+[2]TONT20000MAI!C6+[2]TONT20000JUIN!C6+[2]TONT20000JUIL!C6+[2]TONT20000AOUT!C6+[2]TONT20000SEPT!C6+[2]TONT20000OCT!C6+[2]TONT20000NOV!C6) -> 51457 | G6: =[2]TONT20000NOV!E6 -> 504993.98 | H6: =D6+F6+Q6 -> 114993 | I6: =L6+M6+N6+O6 -> 63000 | J6: =H6-I6 -> 51993 | K6: 0 | L6: 30000 | N6: 25000 | O6: =48000-(R6+S6+T6) -> 8000 | P6: =[2]TONT20000DEC2015!H6+[2]TONT20000JANV!F6+[2]TONT20000FEV!F6+[2]TONT20000MARS!F6+[2]TONT20000AVRIL!F6+[2]TONT20000MAI!F6+[2]TONT20000JUIN!F6+[2]TONT20000JUIL!F6+[2]TONT20000AOUT!F6+[2]TONT20000SEPT!F6+[2]TONT20000OCT!F6+[2]TONT20000NOV!G6 -> 225000 | Q6: =[2]TONT20000DEC2015!I6+[2]TONT20000JANV!G6+[2]TONT20000FEV!G6+[2]TONT20000MARS!G6+[2]TONT20000AVRIL!G6+[2]TONT20000MAI!G6+[2]TONT20000JUIN!G6+[2]TONT20000JUIL!G6+[2]TONT20000AOUT!G6+[2]TONT20000SEPT!G6+[2]TONT20000OCT!G6+[2]TONT20000NOV!H6 -> 30000 | R6: =[2]TONT20000DEC2015!J6+[2]TONT20000JANV!H6+[2]TONT20000FEV!H6+[2]TONT20000MARS!H6+[2]TONT20000AVRIL!H6+[2]TONT20000MAI!H6+[2]TONT20000JUIN!H6+[2]TONT20000JUIL!H6+[2]TONT20000AOUT!H6+[2]TONT20000SEPT!H6+[2]TONT20000OCT!H6+[2]TONT20000NOV!I6 -> 5000 | S6: =[2]TONT20000DEC2015!K6+[2]TONT20000JANV!I6+[2]TONT20000FEV!I6+[2]TONT20000MARS!I6+[2]TONT20000AVRIL!I6+[2]TONT20000MAI!I6+[2]TONT20000JUIN!I6+[2]TONT20000JUIL!I6+[2]TONT20000AOUT!I6+[2]TONT20000SEPT!I6+[2]TONT20000OCT!I6+[2]TONT20000NOV!J6 -> 10000 | T6: =[2]TONT20000DEC2015!L6+[2]TONT20000JANV!J6+[2]TONT20000FEV!J6+[2]TONT20000MARS!J6+[2]TONT20000AVRIL!J6+[2]TONT20000MAI!J6+[2]TONT20000JUIN!J6+[2]TONT20000JUIL!J6+[2]TONT20000AOUT!J6+[2]TONT20000SEPT!J6+[2]TONT20000OCT!J6+[2]TONT20000NOV!K6 -> 25000 | U6: =[2]TONT20000DEC2015!M6+[2]TONT20000JANV!K6+[2]TONT20000FEV!K6+[2]TONT20000MARS!K6+[2]TONT20000AVRIL!K6+[2]TONT20000MAI!K6+[2]TONT20000JUIN!K6+[2]TONT20000JUIL!K6+[2]TONT20000AOUT!K6+[2]TONT20000SEPT!K6+[2]TONT20000OCT!K6+[2]TONT20000NOV!L6 -> 25000 | V6: =[2]TONT20000DEC2015!N6+[2]TONT20000JANV!L6+[2]TONT20000FEV!L6+[2]TONT20000MARS!L6+[2]TONT20000AVRIL!L6+[2]TONT20000MAI!L6+[2]TONT20000JUIN!L6+[2]TONT20000JUIL!L6+[2]TONT20000AOUT!L6+[2]TONT20000SEPT!L6+[2]TONT20000OCT!L6+[2]TONT20000NOV!M6 -> 130000 | W6: =[2]TONT20000DEC2015!O6+[2]TONT20000JANV!M6+[2]TONT20000FEV!M6+[2]TONT20000MARS!M6+[2]TONT20000AVRIL!M6+[2]TONT20000MAI!M6+[2]TONT20000JUIN!M6+[2]TONT20000JUIL!M6+[2]TONT20000AOUT!M6+[2]TONT20000SEPT!M6+[2]TONT20000OCT!M6+[2]TONT20000NOV!N6 -> 500000 | ... AB6: =[2]TONT20000DEC2015!T6+[2]TONT20000JANV!R6+[2]TONT20000FEV!R6+[2]TONT20000MARS!R6+[2]TONT20000AVRIL!R6+[2]TONT20000MAI!R6+[2]TONT20000JUIN!R6+[2]TONT20000JUIL!R6+[2]TONT20000AOUT!R6+[2]TONT20000SEPT!R6+[2]TONT20000OCT!R6+[2]TONT20000NOV!S6 -> 0
A7: AS201602 | B7: =VLOOKUP(A7,[2]LISTADHERENT!A$5:H$52,2,0) -> BOUTCHOUANG WILLIAM | C7: =VLOOKUP(A7,[2]FONDSDECAISSE!A$5:C$52,3,0) -> 390000 | D7: 1704 | E7: =C7+D7+Q7 -> 427704 | F7: =INT([2]TONT20000DEC2015!E7+[2]TONT20000JANV!C7+[2]TONT20000FEV!C7+[2]TONT20000MARS!C7+[2]TONT20000AVRIL!C7+[2]TONT20000MAI!C7+[2]TONT20000JUIN!C7+[2]TONT20000JUIL!C7+[2]TONT20000AOUT!C7+[2]TONT20000SEPT!C7+[2]TONT20000OCT!C7+[2]TONT20000NOV!C7) -> 48016 | G7: =[2]TONT20000NOV!E7 -> 475720.56 | H7: =D7+F7+Q7 -> 85720 | I7: =L7+M7+N7+O7 -> 80000 | J7: =H7-I7 -> 5720 | K7: 3000 | L7: 30000 | N7: 50000 | O7: =48000-(R7+S7+T7) -> 0 | P7: =[2]TONT20000DEC2015!H7+[2]TONT20000JANV!F7+[2]TONT20000FEV!F7+[2]TONT20000MARS!F7+[2]TONT20000AVRIL!F7+[2]TONT20000MAI!F7+[2]TONT20000JUIN!F7+[2]TONT20000JUIL!F7+[2]TONT20000AOUT!F7+[2]TONT20000SEPT!F7+[2]TONT20000OCT!F7+[2]TONT20000NOV!G7 -> 240000 | Q7: =[2]TONT20000DEC2015!I7+[2]TONT20000JANV!G7+[2]TONT20000FEV!G7+[2]TONT20000MARS!G7+[2]TONT20000AVRIL!G7+[2]TONT20000MAI!G7+[2]TONT20000JUIN!G7+[2]TONT20000JUIL!G7+[2]TONT20000AOUT!G7+[2]TONT20000SEPT!G7+[2]TONT20000OCT!G7+[2]TONT20000NOV!H7 -> 36000 | R7: =[2]TONT20000DEC2015!J7+[2]TONT20000JANV!H7+[2]TONT20000FEV!H7+[2]TONT20000MARS!H7+[2]TONT20000AVRIL!H7+[2]TONT20000MAI!H7+[2]TONT20000JUIN!H7+[2]TONT20000JUIL!H7+[2]TONT20000AOUT!H7+[2]TONT20000SEPT!H7+[2]TONT20000OCT!H7+[2]TONT20000NOV!I7 -> 6000 | S7: =[2]TONT20000DEC2015!K7+[2]TONT20000JANV!I7+[2]TONT20000FEV!I7+[2]TONT20000MARS!I7+[2]TONT20000AVRIL!I7+[2]TONT20000MAI!I7+[2]TONT20000JUIN!I7+[2]TONT20000JUIL!I7+[2]TONT20000AOUT!I7+[2]TONT20000SEPT!I7+[2]TONT20000OCT!I7+[2]TONT20000NOV!J7 -> 12000 | T7: =[2]TONT20000DEC2015!L7+[2]TONT20000JANV!J7+[2]TONT20000FEV!J7+[2]TONT20000MARS!J7+[2]TONT20000AVRIL!J7+[2]TONT20000MAI!J7+[2]TONT20000JUIN!J7+[2]TONT20000JUIL!J7+[2]TONT20000AOUT!J7+[2]TONT20000SEPT!J7+[2]TONT20000OCT!J7+[2]TONT20000NOV!K7 -> 30000 | U7: =[2]TONT20000DEC2015!M7+[2]TONT20000JANV!K7+[2]TONT20000FEV!K7+[2]TONT20000MARS!K7+[2]TONT20000AVRIL!K7+[2]TONT20000MAI!K7+[2]TONT20000JUIN!K7+[2]TONT20000JUIL!K7+[2]TONT20000AOUT!K7+[2]TONT20000SEPT!K7+[2]TONT20000OCT!K7+[2]TONT20000NOV!L7 -> 0 | V7: =[2]TONT20000DEC2015!N7+[2]TONT20000JANV!L7+[2]TONT20000FEV!L7+[2]TONT20000MARS!L7+[2]TONT20000AVRIL!L7+[2]TONT20000MAI!L7+[2]TONT20000JUIN!L7+[2]TONT20000JUIL!L7+[2]TONT20000AOUT!L7+[2]TONT20000SEPT!L7+[2]TONT20000OCT!L7+[2]TONT20000NOV!M7 -> 156000 | W7: =[2]TONT20000DEC2015!O7+[2]TONT20000JANV!M7+[2]TONT20000FEV!M7+[2]TONT20000MARS!M7+[2]TONT20000AVRIL!M7+[2]TONT20000MAI!M7+[2]TONT20000JUIN!M7+[2]TONT20000JUIL!M7+[2]TONT20000AOUT!M7+[2]TONT20000SEPT!M7+[2]TONT20000OCT!M7+[2]TONT20000NOV!N7 -> 1700000 | ... AB7: =[2]TONT20000DEC2015!T7+[2]TONT20000JANV!R7+[2]TONT20000FEV!R7+[2]TONT20000MARS!R7+[2]TONT20000AVRIL!R7+[2]TONT20000MAI!R7+[2]TONT20000JUIN!R7+[2]TONT20000JUIL!R7+[2]TONT20000AOUT!R7+[2]TONT20000SEPT!R7+[2]TONT20000OCT!R7+[2]TONT20000NOV!S7 -> 0
A8: AS201603 | B8: =VLOOKUP(A8,[2]LISTADHERENT!A$5:H$52,2,0) -> CHINGUE FABRICE | C8: =VLOOKUP(A8,[2]FONDSDECAISSE!A$5:C$52,3,0) -> 390000 | D8: 1842 | E8: =C8+D8+Q8 -> 427842 | F8: =INT([2]TONT20000DEC2015!E8+[2]TONT20000JANV!C8+[2]TONT20000FEV!C8+[2]TONT20000MARS!C8+[2]TONT20000AVRIL!C8+[2]TONT20000MAI!C8+[2]TONT20000JUIN!C8+[2]TONT20000JUIL!C8+[2]TONT20000AOUT!C8+[2]TONT20000SEPT!C8+[2]TONT20000OCT!C8+[2]TONT20000NOV!C8) -> 48032 | G8: =[2]TONT20000NOV!E8 -> 475874.59 | H8: =D8+F8+Q8 -> 85874 | I8: =L8+M8+N8+O8 -> 80000 | J8: =H8-I8 -> 5874 | K8: 0 | L8: 30000 | N8: 50000 | O8: =48000-(R8+S8+T8) -> 0 | P8: =[2]TONT20000DEC2015!H8+[2]TONT20000JANV!F8+[2]TONT20000FEV!F8+[2]TONT20000MARS!F8+[2]TONT20000AVRIL!F8+[2]TONT20000MAI!F8+[2]TONT20000JUIN!F8+[2]TONT20000JUIL!F8+[2]TONT20000AOUT!F8+[2]TONT20000SEPT!F8+[2]TONT20000OCT!F8+[2]TONT20000NOV!G8 -> 240000 | Q8: =[2]TONT20000DEC2015!I8+[2]TONT20000JANV!G8+[2]TONT20000FEV!G8+[2]TONT20000MARS!G8+[2]TONT20000AVRIL!G8+[2]TONT20000MAI!G8+[2]TONT20000JUIN!G8+[2]TONT20000JUIL!G8+[2]TONT20000AOUT!G8+[2]TONT20000SEPT!G8+[2]TONT20000OCT!G8+[2]TONT20000NOV!H8 -> 36000 | R8: =[2]TONT20000DEC2015!J8+[2]TONT20000JANV!H8+[2]TONT20000FEV!H8+[2]TONT20000MARS!H8+[2]TONT20000AVRIL!H8+[2]TONT20000MAI!H8+[2]TONT20000JUIN!H8+[2]TONT20000JUIL!H8+[2]TONT20000AOUT!H8+[2]TONT20000SEPT!H8+[2]TONT20000OCT!H8+[2]TONT20000NOV!I8 -> 6000 | S8: =[2]TONT20000DEC2015!K8+[2]TONT20000JANV!I8+[2]TONT20000FEV!I8+[2]TONT20000MARS!I8+[2]TONT20000AVRIL!I8+[2]TONT20000MAI!I8+[2]TONT20000JUIN!I8+[2]TONT20000JUIL!I8+[2]TONT20000AOUT!I8+[2]TONT20000SEPT!I8+[2]TONT20000OCT!I8+[2]TONT20000NOV!J8 -> 12000 | T8: =[2]TONT20000DEC2015!L8+[2]TONT20000JANV!J8+[2]TONT20000FEV!J8+[2]TONT20000MARS!J8+[2]TONT20000AVRIL!J8+[2]TONT20000MAI!J8+[2]TONT20000JUIN!J8+[2]TONT20000JUIL!J8+[2]TONT20000AOUT!J8+[2]TONT20000SEPT!J8+[2]TONT20000OCT!J8+[2]TONT20000NOV!K8 -> 30000 | U8: =[2]TONT20000DEC2015!M8+[2]TONT20000JANV!K8+[2]TONT20000FEV!K8+[2]TONT20000MARS!K8+[2]TONT20000AVRIL!K8+[2]TONT20000MAI!K8+[2]TONT20000JUIN!K8+[2]TONT20000JUIL!K8+[2]TONT20000AOUT!K8+[2]TONT20000SEPT!K8+[2]TONT20000OCT!K8+[2]TONT20000NOV!L8 -> 0 | V8: =[2]TONT20000DEC2015!N8+[2]TONT20000JANV!L8+[2]TONT20000FEV!L8+[2]TONT20000MARS!L8+[2]TONT20000AVRIL!L8+[2]TONT20000MAI!L8+[2]TONT20000JUIN!L8+[2]TONT20000JUIL!L8+[2]TONT20000AOUT!L8+[2]TONT20000SEPT!L8+[2]TONT20000OCT!L8+[2]TONT20000NOV!M8 -> 156000 | W8: =[2]TONT20000DEC2015!O8+[2]TONT20000JANV!M8+[2]TONT20000FEV!M8+[2]TONT20000MARS!M8+[2]TONT20000AVRIL!M8+[2]TONT20000MAI!M8+[2]TONT20000JUIN!M8+[2]TONT20000JUIL!M8+[2]TONT20000AOUT!M8+[2]TONT20000SEPT!M8+[2]TONT20000OCT!M8+[2]TONT20000NOV!N8 -> 2000000 | ... AB8: =[2]TONT20000DEC2015!T8+[2]TONT20000JANV!R8+[2]TONT20000FEV!R8+[2]TONT20000MARS!R8+[2]TONT20000AVRIL!R8+[2]TONT20000MAI!R8+[2]TONT20000JUIN!R8+[2]TONT20000JUIL!R8+[2]TONT20000AOUT!R8+[2]TONT20000SEPT!R8+[2]TONT20000OCT!R8+[2]TONT20000NOV!S8 -> 0
A9: AS201604 | B9: =VLOOKUP(A9,[2]LISTADHERENT!A$5:H$52,2,0) -> DJOMO JEAN PAUL | C9: =VLOOKUP(A9,[2]FONDSDECAISSE!A$5:C$52,3,0) -> 390000 | D9: 8156 | E9: =C9+D9+Q9 -> 441156 | F9: =INT([2]TONT20000DEC2015!E9+[2]TONT20000JANV!C9+[2]TONT20000FEV!C9+[2]TONT20000MARS!C9+[2]TONT20000AVRIL!C9+[2]TONT20000MAI!C9+[2]TONT20000JUIN!C9+[2]TONT20000JUIL!C9+[2]TONT20000AOUT!C9+[2]TONT20000SEPT!C9+[2]TONT20000OCT!C9+[2]TONT20000NOV!C9) -> 48914 | G9: =[2]TONT20000NOV!E9 -> 490070.36 | H9: =D9+F9+Q9 -> 100070 | I9: =L9+M9+N9+O9 -> 80000 | J9: =H9-I9 -> 20070 | K9: 17500 | L9: 30000 | N9: 50000 | O9: =48000-(R9+S9+T9) -> 0 | P9: =[2]TONT20000DEC2015!H9+[2]TONT20000JANV!F9+[2]TONT20000FEV!F9+[2]TONT20000MARS!F9+[2]TONT20000AVRIL!F9+[2]TONT20000MAI!F9+[2]TONT20000JUIN!F9+[2]TONT20000JUIL!F9+[2]TONT20000AOUT!F9+[2]TONT20000SEPT!F9+[2]TONT20000OCT!F9+[2]TONT20000NOV!G9 -> 247000 | Q9: =[2]TONT20000DEC2015!I9+[2]TONT20000JANV!G9+[2]TONT20000FEV!G9+[2]TONT20000MARS!G9+[2]TONT20000AVRIL!G9+[2]TONT20000MAI!G9+[2]TONT20000JUIN!G9+[2]TONT20000JUIL!G9+[2]TONT20000AOUT!G9+[2]TONT20000SEPT!G9+[2]TONT20000OCT!G9+[2]TONT20000NOV!H9 -> 43000 | R9: =[2]TONT20000DEC2015!J9+[2]TONT20000JANV!H9+[2]TONT20000FEV!H9+[2]TONT20000MARS!H9+[2]TONT20000AVRIL!H9+[2]TONT20000MAI!H9+[2]TONT20000JUIN!H9+[2]TONT20000JUIL!H9+[2]TONT20000AOUT!H9+[2]TONT20000SEPT!H9+[2]TONT20000OCT!H9+[2]TONT20000NOV!I9 -> 6000 | S9: =[2]TONT20000DEC2015!K9+[2]TONT20000JANV!I9+[2]TONT20000FEV!I9+[2]TONT20000MARS!I9+[2]TONT20000AVRIL!I9+[2]TONT20000MAI!I9+[2]TONT20000JUIN!I9+[2]TONT20000JUIL!I9+[2]TONT20000AOUT!I9+[2]TONT20000SEPT!I9+[2]TONT20000OCT!I9+[2]TONT20000NOV!J9 -> 12000 | T9: =[2]TONT20000DEC2015!L9+[2]TONT20000JANV!J9+[2]TONT20000FEV!J9+[2]TONT20000MARS!J9+[2]TONT20000AVRIL!J9+[2]TONT20000MAI!J9+[2]TONT20000JUIN!J9+[2]TONT20000JUIL!J9+[2]TONT20000AOUT!J9+[2]TONT20000SEPT!J9+[2]TONT20000OCT!J9+[2]TONT20000NOV!K9 -> 30000 | U9: =[2]TONT20000DEC2015!M9+[2]TONT20000JANV!K9+[2]TONT20000FEV!K9+[2]TONT20000MARS!K9+[2]TONT20000AVRIL!K9+[2]TONT20000MAI!K9+[2]TONT20000JUIN!K9+[2]TONT20000JUIL!K9+[2]TONT20000AOUT!K9+[2]TONT20000SEPT!K9+[2]TONT20000OCT!K9+[2]TONT20000NOV!L9 -> 0 | V9: =[2]TONT20000DEC2015!N9+[2]TONT20000JANV!L9+[2]TONT20000FEV!L9+[2]TONT20000MARS!L9+[2]TONT20000AVRIL!L9+[2]TONT20000MAI!L9+[2]TONT20000JUIN!L9+[2]TONT20000JUIL!L9+[2]TONT20000AOUT!L9+[2]TONT20000SEPT!L9+[2]TONT20000OCT!L9+[2]TONT20000NOV!M9 -> 156000 | W9: =[2]TONT20000DEC2015!O9+[2]TONT20000JANV!M9+[2]TONT20000FEV!M9+[2]TONT20000MARS!M9+[2]TONT20000AVRIL!M9+[2]TONT20000MAI!M9+[2]TONT20000JUIN!M9+[2]TONT20000JUIL!M9+[2]TONT20000AOUT!M9+[2]TONT20000SEPT!M9+[2]TONT20000OCT!M9+[2]TONT20000NOV!N9 -> 200000 | ... AB9: =[2]TONT20000DEC2015!T9+[2]TONT20000JANV!R9+[2]TONT20000FEV!R9+[2]TONT20000MARS!R9+[2]TONT20000AVRIL!R9+[2]TONT20000MAI!R9+[2]TONT20000JUIN!R9+[2]TONT20000JUIL!R9+[2]TONT20000AOUT!R9+[2]TONT20000SEPT!R9+[2]TONT20000OCT!R9+[2]TONT20000NOV!S9 -> 0
A10: AS201605 | B10: =VLOOKUP(A10,[2]LISTADHERENT!A$5:H$52,2,0) -> DJOUKWE GUY | C10: =VLOOKUP(A10,[2]FONDSDECAISSE!A$5:C$52,3,0) -> 390000 | D10: 5905 | E10: =C10+D10+Q10 -> 471905 | F10: =INT([2]TONT20000DEC2015!E10+[2]TONT20000JANV!C10+[2]TONT20000FEV!C10+[2]TONT20000MARS!C10+[2]TONT20000AVRIL!C10+[2]TONT20000MAI!C10+[2]TONT20000JUIN!C10+[2]TONT20000JUIL!C10+[2]TONT20000AOUT!C10+[2]TONT20000SEPT!C10+[2]TONT20000OCT!C10+[2]TONT20000NOV!C10) -> 51792 | G10: =[2]TONT20000NOV!E10 -> 523697.05 | H10: =D10+F10+Q10 -> 133697 | I10: =L10+M10+N10+O10 -> 80000 | J10: =H10-I10 -> 53697 | K10: 51000 | L10: 30000 | N10: 50000 | O10: =48000-(R10+S10+T10) -> 0 | P10: =[2]TONT20000DEC2015!H10+[2]TONT20000JANV!F10+[2]TONT20000FEV!F10+[2]TONT20000MARS!F10+[2]TONT20000AVRIL!F10+[2]TONT20000MAI!F10+[2]TONT20000JUIN!F10+[2]TONT20000JUIL!F10+[2]TONT20000AOUT!F10+[2]TONT20000SEPT!F10+[2]TONT20000OCT!F10+[2]TONT20000NOV!G10 -> 280000 | Q10: =[2]TONT20000DEC2015!I10+[2]TONT20000JANV!G10+[2]TONT20000FEV!G10+[2]TONT20000MARS!G10+[2]TONT20000AVRIL!G10+[2]TONT20000MAI!G10+[2]TONT20000JUIN!G10+[2]TONT20000JUIL!G10+[2]TONT20000AOUT!G10+[2]TONT20000SEPT!G10+[2]TONT20000OCT!G10+[2]TONT20000NOV!H10 -> 76000 | R10: =[2]TONT20000DEC2015!J10+[2]TONT20000JANV!H10+[2]TONT20000FEV!H10+[2]TONT20000MARS!H10+[2]TONT20000AVRIL!H10+[2]TONT20000MAI!H10+[2]TONT20000JUIN!H10+[2]TONT20000JUIL!H10+[2]TONT20000AOUT!H10+[2]TONT20000SEPT!H10+[2]TONT20000OCT!H10+[2]TONT20000NOV!I10 -> 6000 | S10: =[2]TONT20000DEC2015!K10+[2]TONT20000JANV!I10+[2]TONT20000FEV!I10+[2]TONT20000MARS!I10+[2]TONT20000AVRIL!I10+[2]TONT20000MAI!I10+[2]TONT20000JUIN!I10+[2]TONT20000JUIL!I10+[2]TONT20000AOUT!I10+[2]TONT20000SEPT!I10+[2]TONT20000OCT!I10+[2]TONT20000NOV!J10 -> 12000 | T10: =[2]TONT20000DEC2015!L10+[2]TONT20000JANV!J10+[2]TONT20000FEV!J10+[2]TONT20000MARS!J10+[2]TONT20000AVRIL!J10+[2]TONT20000MAI!J10+[2]TONT20000JUIN!J10+[2]TONT20000JUIL!J10+[2]TONT20000AOUT!J10+[2]TONT20000SEPT!J10+[2]TONT20000OCT!J10+[2]TONT20000NOV!K10 -> 30000 | U10: =[2]TONT20000DEC2015!M10+[2]TONT20000JANV!K10+[2]TONT20000FEV!K10+[2]TONT20000MARS!K10+[2]TONT20000AVRIL!K10+[2]TONT20000MAI!K10+[2]TONT20000JUIN!K10+[2]TONT20000JUIL!K10+[2]TONT20000AOUT!K10+[2]TONT20000SEPT!K10+[2]TONT20000OCT!K10+[2]TONT20000NOV!L10 -> 0 | V10: =[2]TONT20000DEC2015!N10+[2]TONT20000JANV!L10+[2]TONT20000FEV!L10+[2]TONT20000MARS!L10+[2]TONT20000AVRIL!L10+[2]TONT20000MAI!L10+[2]TONT20000JUIN!L10+[2]TONT20000JUIL!L10+[2]TONT20000AOUT!L10+[2]TONT20000SEPT!L10+[2]TONT20000OCT!L10+[2]TONT20000NOV!M10 -> 156000 | W10: =[2]TONT20000DEC2015!O10+[2]TONT20000JANV!M10+[2]TONT20000FEV!M10+[2]TONT20000MARS!M10+[2]TONT20000AVRIL!M10+[2]TONT20000MAI!M10+[2]TONT20000JUIN!M10+[2]TONT20000JUIL!M10+[2]TONT20000AOUT!M10+[2]TONT20000SEPT!M10+[2]TONT20000OCT!M10+[2]TONT20000NOV!N10 -> 250000 | ... AB10: =[2]TONT20000DEC2015!T10+[2]TONT20000JANV!R10+[2]TONT20000FEV!R10+[2]TONT20000MARS!R10+[2]TONT20000AVRIL!R10+[2]TONT20000MAI!R10+[2]TONT20000JUIN!R10+[2]TONT20000JUIL!R10+[2]TONT20000AOUT!R10+[2]TONT20000SEPT!R10+[2]TONT20000OCT!R10+[2]TONT20000NOV!S10 -> 0
A11: AS201606 | B11: =VLOOKUP(A11,[2]LISTADHERENT!A$5:H$52,2,0) -> DJOSSEU JOSUE
A12: AS201607 | B12: =VLOOKUP(A12,[2]LISTADHERENT!A$5:H$52,2,0) -> DJOUNKEP SAMUEL | C12: =VLOOKUP(A12,[2]FONDSDECAISSE!A$5:C$52,3,0) -> 390000 | D12: 1055294 | E12: =C12+D12+Q12 -> 2001294 | F12: =INT([2]TONT20000DEC2015!E12+[2]TONT20000JANV!C12+[2]TONT20000FEV!C12+[2]TONT20000MARS!C12+[2]TONT20000AVRIL!C12+[2]TONT20000MAI!C12+[2]TONT20000JUIN!C12+[2]TONT20000JUIL!C12+[2]TONT20000AOUT!C12+[2]TONT20000SEPT!C12+[2]TONT20000OCT!C12+[2]TONT20000NOV!C12) -> 204246 | G12: =[2]TONT20000NOV!E12 -> 2135835.7 | H12: =D12+F12+Q12 -> 1815540 | I12: =L12+M12+N12+O12 -> 80000 | J12: =H12-I12 -> 1735540 | K12: 1100000 | L12: 30000 | N12: 50000 | O12: =48000-(R12+S12+T12) -> 0 | P12: =[2]TONT20000DEC2015!H12+[2]TONT20000JANV!F12+[2]TONT20000FEV!F12+[2]TONT20000MARS!F12+[2]TONT20000AVRIL!F12+[2]TONT20000MAI!F12+[2]TONT20000JUIN!F12+[2]TONT20000JUIL!F12+[2]TONT20000AOUT!F12+[2]TONT20000SEPT!F12+[2]TONT20000OCT!F12+[2]TONT20000NOV!G12 -> 760000 | Q12: =[2]TONT20000DEC2015!I12+[2]TONT20000JANV!G12+[2]TONT20000FEV!G12+[2]TONT20000MARS!G12+[2]TONT20000AVRIL!G12+[2]TONT20000MAI!G12+[2]TONT20000JUIN!G12+[2]TONT20000JUIL!G12+[2]TONT20000AOUT!G12+[2]TONT20000SEPT!G12+[2]TONT20000OCT!G12+[2]TONT20000NOV!H12 -> 556000 | R12: =[2]TONT20000DEC2015!J12+[2]TONT20000JANV!H12+[2]TONT20000FEV!H12+[2]TONT20000MARS!H12+[2]TONT20000AVRIL!H12+[2]TONT20000MAI!H12+[2]TONT20000JUIN!H12+[2]TONT20000JUIL!H12+[2]TONT20000AOUT!H12+[2]TONT20000SEPT!H12+[2]TONT20000OCT!H12+[2]TONT20000NOV!I12 -> 6000 | S12: =[2]TONT20000DEC2015!K12+[2]TONT20000JANV!I12+[2]TONT20000FEV!I12+[2]TONT20000MARS!I12+[2]TONT20000AVRIL!I12+[2]TONT20000MAI!I12+[2]TONT20000JUIN!I12+[2]TONT20000JUIL!I12+[2]TONT20000AOUT!I12+[2]TONT20000SEPT!I12+[2]TONT20000OCT!I12+[2]TONT20000NOV!J12 -> 12000 | T12: =[2]TONT20000DEC2015!L12+[2]TONT20000JANV!J12+[2]TONT20000FEV!J12+[2]TONT20000MARS!J12+[2]TONT20000AVRIL!J12+[2]TONT20000MAI!J12+[2]TONT20000JUIN!J12+[2]TONT20000JUIL!J12+[2]TONT20000AOUT!J12+[2]TONT20000SEPT!J12+[2]TONT20000OCT!J12+[2]TONT20000NOV!K12 -> 30000 | U12: =[2]TONT20000DEC2015!M12+[2]TONT20000JANV!K12+[2]TONT20000FEV!K12+[2]TONT20000MARS!K12+[2]TONT20000AVRIL!K12+[2]TONT20000MAI!K12+[2]TONT20000JUIN!K12+[2]TONT20000JUIL!K12+[2]TONT20000AOUT!K12+[2]TONT20000SEPT!K12+[2]TONT20000OCT!K12+[2]TONT20000NOV!L12 -> 0 | V12: =[2]TONT20000DEC2015!N12+[2]TONT20000JANV!L12+[2]TONT20000FEV!L12+[2]TONT20000MARS!L12+[2]TONT20000AVRIL!L12+[2]TONT20000MAI!L12+[2]TONT20000JUIN!L12+[2]TONT20000JUIL!L12+[2]TONT20000AOUT!L12+[2]TONT20000SEPT!L12+[2]TONT20000OCT!L12+[2]TONT20000NOV!M12 -> 156000 | W12: =[2]TONT20000DEC2015!O12+[2]TONT20000JANV!M12+[2]TONT20000FEV!M12+[2]TONT20000MARS!M12+[2]TONT20000AVRIL!M12+[2]TONT20000MAI!M12+[2]TONT20000JUIN!M12+[2]TONT20000JUIL!M12+[2]TONT20000AOUT!M12+[2]TONT20000SEPT!M12+[2]TONT20000OCT!M12+[2]TONT20000NOV!N12 -> 0 | ... AB12: =[2]TONT20000DEC2015!T12+[2]TONT20000JANV!R12+[2]TONT20000FEV!R12+[2]TONT20000MARS!R12+[2]TONT20000AVRIL!R12+[2]TONT20000MAI!R12+[2]TONT20000JUIN!R12+[2]TONT20000JUIL!R12+[2]TONT20000AOUT!R12+[2]TONT20000SEPT!R12+[2]TONT20000OCT!R12+[2]TONT20000NOV!S12 -> 0
A13: AS201608 | B13: =VLOOKUP(A13,[2]LISTADHERENT!A$5:H$52,2,0) -> DJUOMBESSY ANTOINE | C13: 390000 | D13: 0 | E13: =C13+D13+Q13 -> 457560 | F13: =INT([2]TONT20000DEC2015!E13+[2]TONT20000JANV!C13+[2]TONT20000FEV!C13+[2]TONT20000MARS!C13+[2]TONT20000AVRIL!C13+[2]TONT20000MAI!C13+[2]TONT20000JUIN!C13+[2]TONT20000JUIL!C13+[2]TONT20000AOUT!C13+[2]TONT20000SEPT!C13+[2]TONT20000OCT!C13+[2]TONT20000NOV!C13) -> 43186 | G13: =[2]TONT20000NOV!E13 -> 500746.25 | H13: =D13+F13+Q13 -> 110746 | I13: =L13+M13+N13+O13 -> 80000 | J13: =H13-I13 -> 30746 | K13: 28000 | L13: 30000 | N13: 50000 | O13: =48000-(R13+S13+T13) -> 0 | P13: =[2]TONT20000DEC2015!H13+[2]TONT20000JANV!F13+[2]TONT20000FEV!F13+[2]TONT20000MARS!F13+[2]TONT20000AVRIL!F13+[2]TONT20000MAI!F13+[2]TONT20000JUIN!F13+[2]TONT20000JUIL!F13+[2]TONT20000AOUT!F13+[2]TONT20000SEPT!F13+[2]TONT20000OCT!F13+[2]TONT20000NOV!G13 -> 271560 | Q13: =[2]TONT20000DEC2015!I13+[2]TONT20000JANV!G13+[2]TONT20000FEV!G13+[2]TONT20000MARS!G13+[2]TONT20000AVRIL!G13+[2]TONT20000MAI!G13+[2]TONT20000JUIN!G13+[2]TONT20000JUIL!G13+[2]TONT20000AOUT!G13+[2]TONT20000SEPT!G13+[2]TONT20000OCT!G13+[2]TONT20000NOV!H13 -> 67560 | R13: =[2]TONT20000DEC2015!J13+[2]TONT20000JANV!H13+[2]TONT20000FEV!H13+[2]TONT20000MARS!H13+[2]TONT20000AVRIL!H13+[2]TONT20000MAI!H13+[2]TONT20000JUIN!H13+[2]TONT20000JUIL!H13+[2]TONT20000AOUT!H13+[2]TONT20000SEPT!H13+[2]TONT20000OCT!H13+[2]TONT20000NOV!I13 -> 6000 | S13: =[2]TONT20000DEC2015!K13+[2]TONT20000JANV!I13+[2]TONT20000FEV!I13+[2]TONT20000MARS!I13+[2]TONT20000AVRIL!I13+[2]TONT20000MAI!I13+[2]TONT20000JUIN!I13+[2]TONT20000JUIL!I13+[2]TONT20000AOUT!I13+[2]TONT20000SEPT!I13+[2]TONT20000OCT!I13+[2]TONT20000NOV!J13 -> 12000 | T13: =[2]TONT20000DEC2015!L13+[2]TONT20000JANV!J13+[2]TONT20000FEV!J13+[2]TONT20000MARS!J13+[2]TONT20000AVRIL!J13+[2]TONT20000MAI!J13+[2]TONT20000JUIN!J13+[2]TONT20000JUIL!J13+[2]TONT20000AOUT!J13+[2]TONT20000SEPT!J13+[2]TONT20000OCT!J13+[2]TONT20000NOV!K13 -> 30000 | U13: =[2]TONT20000DEC2015!M13+[2]TONT20000JANV!K13+[2]TONT20000FEV!K13+[2]TONT20000MARS!K13+[2]TONT20000AVRIL!K13+[2]TONT20000MAI!K13+[2]TONT20000JUIN!K13+[2]TONT20000JUIL!K13+[2]TONT20000AOUT!K13+[2]TONT20000SEPT!K13+[2]TONT20000OCT!K13+[2]TONT20000NOV!L13 -> 0 | V13: =[2]TONT20000DEC2015!N13+[2]TONT20000JANV!L13+[2]TONT20000FEV!L13+[2]TONT20000MARS!L13+[2]TONT20000AVRIL!L13+[2]TONT20000MAI!L13+[2]TONT20000JUIN!L13+[2]TONT20000JUIL!L13+[2]TONT20000AOUT!L13+[2]TONT20000SEPT!L13+[2]TONT20000OCT!L13+[2]TONT20000NOV!M13 -> 156000 | W13: =[2]TONT20000DEC2015!O13+[2]TONT20000JANV!M13+[2]TONT20000FEV!M13+[2]TONT20000MARS!M13+[2]TONT20000AVRIL!M13+[2]TONT20000MAI!M13+[2]TONT20000JUIN!M13+[2]TONT20000JUIL!M13+[2]TONT20000AOUT!M13+[2]TONT20000SEPT!M13+[2]TONT20000OCT!M13+[2]TONT20000NOV!N13 -> 700000 | ... AB13: =[2]TONT20000DEC2015!T13+[2]TONT20000JANV!R13+[2]TONT20000FEV!R13+[2]TONT20000MARS!R13+[2]TONT20000AVRIL!R13+[2]TONT20000MAI!R13+[2]TONT20000JUIN!R13+[2]TONT20000JUIL!R13+[2]TONT20000AOUT!R13+[2]TONT20000SEPT!R13+[2]TONT20000OCT!R13+[2]TONT20000NOV!S13 -> 0
A14: AS201609 | B14: =VLOOKUP(A14,[2]LISTADHERENT!A$5:H$52,2,0) -> DONHOU DAVID | C14: =VLOOKUP(A14,[2]FONDSDECAISSE!A$5:C$52,3,0) -> 390000 | D14: 44734 | E14: =C14+D14+Q14 -> 470734 | F14: =INT([2]TONT20000DEC2015!E14+[2]TONT20000JANV!C14+[2]TONT20000FEV!C14+[2]TONT20000MARS!C14+[2]TONT20000AVRIL!C14+[2]TONT20000MAI!C14+[2]TONT20000JUIN!C14+[2]TONT20000JUIL!C14+[2]TONT20000AOUT!C14+[2]TONT20000SEPT!C14+[2]TONT20000OCT!C14+[2]TONT20000NOV!C14) -> 53014 | G14: =[2]TONT20000NOV!E14 -> 523748.49 | H14: =D14+F14+Q14 -> 133748 | I14: =L14+M14+N14+O14 -> 80000 | J14: =H14-I14 -> 53748 | K14: 0 | L14: 30000 | N14: 50000 | O14: =48000-(R14+S14+T14) -> 0 | P14: =[2]TONT20000DEC2015!H14+[2]TONT20000JANV!F14+[2]TONT20000FEV!F14+[2]TONT20000MARS!F14+[2]TONT20000AVRIL!F14+[2]TONT20000MAI!F14+[2]TONT20000JUIN!F14+[2]TONT20000JUIL!F14+[2]TONT20000AOUT!F14+[2]TONT20000SEPT!F14+[2]TONT20000OCT!F14+[2]TONT20000NOV!G14 -> 240000 | Q14: =[2]TONT20000DEC2015!I14+[2]TONT20000JANV!G14+[2]TONT20000FEV!G14+[2]TONT20000MARS!G14+[2]TONT20000AVRIL!G14+[2]TONT20000MAI!G14+[2]TONT20000JUIN!G14+[2]TONT20000JUIL!G14+[2]TONT20000AOUT!G14+[2]TONT20000SEPT!G14+[2]TONT20000OCT!G14+[2]TONT20000NOV!H14 -> 36000 | R14: =[2]TONT20000DEC2015!J14+[2]TONT20000JANV!H14+[2]TONT20000FEV!H14+[2]TONT20000MARS!H14+[2]TONT20000AVRIL!H14+[2]TONT20000MAI!H14+[2]TONT20000JUIN!H14+[2]TONT20000JUIL!H14+[2]TONT20000AOUT!H14+[2]TONT20000SEPT!H14+[2]TONT20000OCT!H14+[2]TONT20000NOV!I14 -> 6000 | S14: =[2]TONT20000DEC2015!K14+[2]TONT20000JANV!I14+[2]TONT20000FEV!I14+[2]TONT20000MARS!I14+[2]TONT20000AVRIL!I14+[2]TONT20000MAI!I14+[2]TONT20000JUIN!I14+[2]TONT20000JUIL!I14+[2]TONT20000AOUT!I14+[2]TONT20000SEPT!I14+[2]TONT20000OCT!I14+[2]TONT20000NOV!J14 -> 12000 | T14: =[2]TONT20000DEC2015!L14+[2]TONT20000JANV!J14+[2]TONT20000FEV!J14+[2]TONT20000MARS!J14+[2]TONT20000AVRIL!J14+[2]TONT20000MAI!J14+[2]TONT20000JUIN!J14+[2]TONT20000JUIL!J14+[2]TONT20000AOUT!J14+[2]TONT20000SEPT!J14+[2]TONT20000OCT!J14+[2]TONT20000NOV!K14 -> 30000 | U14: =[2]TONT20000DEC2015!M14+[2]TONT20000JANV!K14+[2]TONT20000FEV!K14+[2]TONT20000MARS!K14+[2]TONT20000AVRIL!K14+[2]TONT20000MAI!K14+[2]TONT20000JUIN!K14+[2]TONT20000JUIL!K14+[2]TONT20000AOUT!K14+[2]TONT20000SEPT!K14+[2]TONT20000OCT!K14+[2]TONT20000NOV!L14 -> 0 | V14: =[2]TONT20000DEC2015!N14+[2]TONT20000JANV!L14+[2]TONT20000FEV!L14+[2]TONT20000MARS!L14+[2]TONT20000AVRIL!L14+[2]TONT20000MAI!L14+[2]TONT20000JUIN!L14+[2]TONT20000JUIL!L14+[2]TONT20000AOUT!L14+[2]TONT20000SEPT!L14+[2]TONT20000OCT!L14+[2]TONT20000NOV!M14 -> 156000 | W14: =[2]TONT20000DEC2015!O14+[2]TONT20000JANV!M14+[2]TONT20000FEV!M14+[2]TONT20000MARS!M14+[2]TONT20000AVRIL!M14+[2]TONT20000MAI!M14+[2]TONT20000JUIN!M14+[2]TONT20000JUIL!M14+[2]TONT20000AOUT!M14+[2]TONT20000SEPT!M14+[2]TONT20000OCT!M14+[2]TONT20000NOV!N14 -> 0 | ... AB14: =[2]TONT20000DEC2015!T14+[2]TONT20000JANV!R14+[2]TONT20000FEV!R14+[2]TONT20000MARS!R14+[2]TONT20000AVRIL!R14+[2]TONT20000MAI!R14+[2]TONT20000JUIN!R14+[2]TONT20000JUIL!R14+[2]TONT20000AOUT!R14+[2]TONT20000SEPT!R14+[2]TONT20000OCT!R14+[2]TONT20000NOV!S14 -> 0
A15: AS201610 | B15: =VLOOKUP(A15,[2]LISTADHERENT!A$5:H$52,2,0) -> FOTSO THOMAS | C15: =VLOOKUP(A15,[2]FONDSDECAISSE!A$5:C$52,3,0) -> 390000 | D15: 3318 | E15: =C15+D15+Q15 -> 429318 | F15: =INT([2]TONT20000DEC2015!E15+[2]TONT20000JANV!C15+[2]TONT20000FEV!C15+[2]TONT20000MARS!C15+[2]TONT20000AVRIL!C15+[2]TONT20000MAI!C15+[2]TONT20000JUIN!C15+[2]TONT20000JUIL!C15+[2]TONT20000AOUT!C15+[2]TONT20000SEPT!C15+[2]TONT20000OCT!C15+[2]TONT20000NOV!C15) -> 48204 | G15: =[2]TONT20000NOV!E15 -> 477522.03 | H15: =D15+F15+Q15 -> 87522 | I15: =L15+M15+N15+O15 -> 80000 | J15: =H15-I15 -> 7522 | K15: 5000 | L15: 30000 | N15: 50000 | O15: =48000-(R15+S15+T15) -> 0 | P15: =[2]TONT20000DEC2015!H15+[2]TONT20000JANV!F15+[2]TONT20000FEV!F15+[2]TONT20000MARS!F15+[2]TONT20000AVRIL!F15+[2]TONT20000MAI!F15+[2]TONT20000JUIN!F15+[2]TONT20000JUIL!F15+[2]TONT20000AOUT!F15+[2]TONT20000SEPT!F15+[2]TONT20000OCT!F15+[2]TONT20000NOV!G15 -> 240000 | Q15: =[2]TONT20000DEC2015!I15+[2]TONT20000JANV!G15+[2]TONT20000FEV!G15+[2]TONT20000MARS!G15+[2]TONT20000AVRIL!G15+[2]TONT20000MAI!G15+[2]TONT20000JUIN!G15+[2]TONT20000JUIL!G15+[2]TONT20000AOUT!G15+[2]TONT20000SEPT!G15+[2]TONT20000OCT!G15+[2]TONT20000NOV!H15 -> 36000 | R15: =[2]TONT20000DEC2015!J15+[2]TONT20000JANV!H15+[2]TONT20000FEV!H15+[2]TONT20000MARS!H15+[2]TONT20000AVRIL!H15+[2]TONT20000MAI!H15+[2]TONT20000JUIN!H15+[2]TONT20000JUIL!H15+[2]TONT20000AOUT!H15+[2]TONT20000SEPT!H15+[2]TONT20000OCT!H15+[2]TONT20000NOV!I15 -> 6000 | S15: =[2]TONT20000DEC2015!K15+[2]TONT20000JANV!I15+[2]TONT20000FEV!I15+[2]TONT20000MARS!I15+[2]TONT20000AVRIL!I15+[2]TONT20000MAI!I15+[2]TONT20000JUIN!I15+[2]TONT20000JUIL!I15+[2]TONT20000AOUT!I15+[2]TONT20000SEPT!I15+[2]TONT20000OCT!I15+[2]TONT20000NOV!J15 -> 12000 | T15: =[2]TONT20000DEC2015!L15+[2]TONT20000JANV!J15+[2]TONT20000FEV!J15+[2]TONT20000MARS!J15+[2]TONT20000AVRIL!J15+[2]TONT20000MAI!J15+[2]TONT20000JUIN!J15+[2]TONT20000JUIL!J15+[2]TONT20000AOUT!J15+[2]TONT20000SEPT!J15+[2]TONT20000OCT!J15+[2]TONT20000NOV!K15 -> 30000 | U15: =[2]TONT20000DEC2015!M15+[2]TONT20000JANV!K15+[2]TONT20000FEV!K15+[2]TONT20000MARS!K15+[2]TONT20000AVRIL!K15+[2]TONT20000MAI!K15+[2]TONT20000JUIN!K15+[2]TONT20000JUIL!K15+[2]TONT20000AOUT!K15+[2]TONT20000SEPT!K15+[2]TONT20000OCT!K15+[2]TONT20000NOV!L15 -> 0 | V15: =[2]TONT20000DEC2015!N15+[2]TONT20000JANV!L15+[2]TONT20000FEV!L15+[2]TONT20000MARS!L15+[2]TONT20000AVRIL!L15+[2]TONT20000MAI!L15+[2]TONT20000JUIN!L15+[2]TONT20000JUIL!L15+[2]TONT20000AOUT!L15+[2]TONT20000SEPT!L15+[2]TONT20000OCT!L15+[2]TONT20000NOV!M15 -> 156000 | W15: =[2]TONT20000DEC2015!O15+[2]TONT20000JANV!M15+[2]TONT20000FEV!M15+[2]TONT20000MARS!M15+[2]TONT20000AVRIL!M15+[2]TONT20000MAI!M15+[2]TONT20000JUIN!M15+[2]TONT20000JUIL!M15+[2]TONT20000AOUT!M15+[2]TONT20000SEPT!M15+[2]TONT20000OCT!M15+[2]TONT20000NOV!N15 -> 1000000 | ... AB15: =[2]TONT20000DEC2015!T15+[2]TONT20000JANV!R15+[2]TONT20000FEV!R15+[2]TONT20000MARS!R15+[2]TONT20000AVRIL!R15+[2]TONT20000MAI!R15+[2]TONT20000JUIN!R15+[2]TONT20000JUIL!R15+[2]TONT20000AOUT!R15+[2]TONT20000SEPT!R15+[2]TONT20000OCT!R15+[2]TONT20000NOV!S15 -> 0
A16: AS201611 | B16: =VLOOKUP(A16,[2]LISTADHERENT!A$5:H$52,2,0) -> HENGUE PAUL OMER | C16: =VLOOKUP(A16,[2]FONDSDECAISSE!A$5:C$52,3,0) -> 390000 | E16: =C16+D16+Q16 -> 420000 | F16: =INT([2]TONT20000DEC2015!E16+[2]TONT20000JANV!C16+[2]TONT20000FEV!C16+[2]TONT20000MARS!C16+[2]TONT20000AVRIL!C16+[2]TONT20000MAI!C16+[2]TONT20000JUIN!C16+[2]TONT20000JUIL!C16+[2]TONT20000AOUT!C16+[2]TONT20000SEPT!C16+[2]TONT20000OCT!C16+[2]TONT20000NOV!C16) -> 47702 | G16: =[2]TONT20000NOV!E16 -> 467702.04 | H16: =D16+F16+Q16 -> 77702 | I16: =L16+M16+N16+O16 -> 88000 | J16: =H16-I16 -> -10298 | K16: 0 | L16: 30000 | N16: 50000 | O16: =48000-(R16+S16+T16) -> 8000 | P16: =[2]TONT20000DEC2015!H16+[2]TONT20000JANV!F16+[2]TONT20000FEV!F16+[2]TONT20000MARS!F16+[2]TONT20000AVRIL!F16+[2]TONT20000MAI!F16+[2]TONT20000JUIN!F16+[2]TONT20000JUIL!F16+[2]TONT20000AOUT!F16+[2]TONT20000SEPT!F16+[2]TONT20000OCT!F16+[2]TONT20000NOV!G16 -> 200000 | Q16: =[2]TONT20000DEC2015!I16+[2]TONT20000JANV!G16+[2]TONT20000FEV!G16+[2]TONT20000MARS!G16+[2]TONT20000AVRIL!G16+[2]TONT20000MAI!G16+[2]TONT20000JUIN!G16+[2]TONT20000JUIL!G16+[2]TONT20000AOUT!G16+[2]TONT20000SEPT!G16+[2]TONT20000OCT!G16+[2]TONT20000NOV!H16 -> 30000 | R16: =[2]TONT20000DEC2015!J16+[2]TONT20000JANV!H16+[2]TONT20000FEV!H16+[2]TONT20000MARS!H16+[2]TONT20000AVRIL!H16+[2]TONT20000MAI!H16+[2]TONT20000JUIN!H16+[2]TONT20000JUIL!H16+[2]TONT20000AOUT!H16+[2]TONT20000SEPT!H16+[2]TONT20000OCT!H16+[2]TONT20000NOV!I16 -> 5000 | S16: =[2]TONT20000DEC2015!K16+[2]TONT20000JANV!I16+[2]TONT20000FEV!I16+[2]TONT20000MARS!I16+[2]TONT20000AVRIL!I16+[2]TONT20000MAI!I16+[2]TONT20000JUIN!I16+[2]TONT20000JUIL!I16+[2]TONT20000AOUT!I16+[2]TONT20000SEPT!I16+[2]TONT20000OCT!I16+[2]TONT20000NOV!J16 -> 10000 | T16: =[2]TONT20000DEC2015!L16+[2]TONT20000JANV!J16+[2]TONT20000FEV!J16+[2]TONT20000MARS!J16+[2]TONT20000AVRIL!J16+[2]TONT20000MAI!J16+[2]TONT20000JUIN!J16+[2]TONT20000JUIL!J16+[2]TONT20000AOUT!J16+[2]TONT20000SEPT!J16+[2]TONT20000OCT!J16+[2]TONT20000NOV!K16 -> 25000 | U16: =[2]TONT20000DEC2015!M16+[2]TONT20000JANV!K16+[2]TONT20000FEV!K16+[2]TONT20000MARS!K16+[2]TONT20000AVRIL!K16+[2]TONT20000MAI!K16+[2]TONT20000JUIN!K16+[2]TONT20000JUIL!K16+[2]TONT20000AOUT!K16+[2]TONT20000SEPT!K16+[2]TONT20000OCT!K16+[2]TONT20000NOV!L16 -> 0 | V16: =[2]TONT20000DEC2015!N16+[2]TONT20000JANV!L16+[2]TONT20000FEV!L16+[2]TONT20000MARS!L16+[2]TONT20000AVRIL!L16+[2]TONT20000MAI!L16+[2]TONT20000JUIN!L16+[2]TONT20000JUIL!L16+[2]TONT20000AOUT!L16+[2]TONT20000SEPT!L16+[2]TONT20000OCT!L16+[2]TONT20000NOV!M16 -> 130000 | W16: =[2]TONT20000DEC2015!O16+[2]TONT20000JANV!M16+[2]TONT20000FEV!M16+[2]TONT20000MARS!M16+[2]TONT20000AVRIL!M16+[2]TONT20000MAI!M16+[2]TONT20000JUIN!M16+[2]TONT20000JUIL!M16+[2]TONT20000AOUT!M16+[2]TONT20000SEPT!M16+[2]TONT20000OCT!M16+[2]TONT20000NOV!N16 -> 0 | ... AB16: =[2]TONT20000DEC2015!T16+[2]TONT20000JANV!R16+[2]TONT20000FEV!R16+[2]TONT20000MARS!R16+[2]TONT20000AVRIL!R16+[2]TONT20000MAI!R16+[2]TONT20000JUIN!R16+[2]TONT20000JUIL!R16+[2]TONT20000AOUT!R16+[2]TONT20000SEPT!R16+[2]TONT20000OCT!R16+[2]TONT20000NOV!S16 -> 0
A17: AS201612 | B17: =VLOOKUP(A17,[2]LISTADHERENT!A$5:H$52,2,0) -> HODIEP JULES | C17: 50000 | D17: 0 | E17: =C17+D17+Q17 -> 58100 | F17: =INT([2]TONT20000DEC2015!E17+[2]TONT20000JANV!C17+[2]TONT20000FEV!C17+[2]TONT20000MARS!C17+[2]TONT20000AVRIL!C17+[2]TONT20000MAI!C17+[2]TONT20000JUIN!C17+[2]TONT20000JUIL!C17+[2]TONT20000AOUT!C17+[2]TONT20000SEPT!C17+[2]TONT20000OCT!C17+[2]TONT20000NOV!C17) -> 6252 | G17: =[2]TONT20000NOV!E17 -> 92252.382 | H17: =D17+F17+Q17 -> 14352 | I17: =L17+M17+N17+O17 -> 14092 | J17: =H17-I17 -> 260 | K17: 0 | N17: =50000-35908 -> 14092 | O17: =48000-(R17+S17+T17) -> 0 | P17: =[2]TONT20000DEC2015!H17+[2]TONT20000JANV!F17+[2]TONT20000FEV!F17+[2]TONT20000MARS!F17+[2]TONT20000AVRIL!F17+[2]TONT20000MAI!F17+[2]TONT20000JUIN!F17+[2]TONT20000JUIL!F17+[2]TONT20000AOUT!F17+[2]TONT20000SEPT!F17+[2]TONT20000OCT!F17+[2]TONT20000NOV!G17 -> 240000 | Q17: =[2]TONT20000DEC2015!I17+[2]TONT20000JANV!G17+[2]TONT20000FEV!G17+[2]TONT20000MARS!G17+[2]TONT20000AVRIL!G17+[2]TONT20000MAI!G17+[2]TONT20000JUIN!G17+[2]TONT20000JUIL!G17+[2]TONT20000AOUT!G17+[2]TONT20000SEPT!G17+[2]TONT20000OCT!G17+[2]TONT20000NOV!H17-18000-9900 -> 8100 | R17: =[2]TONT20000DEC2015!J17+[2]TONT20000JANV!H17+[2]TONT20000FEV!H17+[2]TONT20000MARS!H17+[2]TONT20000AVRIL!H17+[2]TONT20000MAI!H17+[2]TONT20000JUIN!H17+[2]TONT20000JUIL!H17+[2]TONT20000AOUT!H17+[2]TONT20000SEPT!H17+[2]TONT20000OCT!H17+[2]TONT20000NOV!I17 -> 6000 | S17: =[2]TONT20000DEC2015!K17+[2]TONT20000JANV!I17+[2]TONT20000FEV!I17+[2]TONT20000MARS!I17+[2]TONT20000AVRIL!I17+[2]TONT20000MAI!I17+[2]TONT20000JUIN!I17+[2]TONT20000JUIL!I17+[2]TONT20000AOUT!I17+[2]TONT20000SEPT!I17+[2]TONT20000OCT!I17+[2]TONT20000NOV!J17 -> 12000 | T17: =[2]TONT20000DEC2015!L17+[2]TONT20000JANV!J17+[2]TONT20000FEV!J17+[2]TONT20000MARS!J17+[2]TONT20000AVRIL!J17+[2]TONT20000MAI!J17+[2]TONT20000JUIN!J17+[2]TONT20000JUIL!J17+[2]TONT20000AOUT!J17+[2]TONT20000SEPT!J17+[2]TONT20000OCT!J17+[2]TONT20000NOV!K17 -> 30000 | U17: =[2]TONT20000DEC2015!M17+[2]TONT20000JANV!K17+[2]TONT20000FEV!K17+[2]TONT20000MARS!K17+[2]TONT20000AVRIL!K17+[2]TONT20000MAI!K17+[2]TONT20000JUIN!K17+[2]TONT20000JUIL!K17+[2]TONT20000AOUT!K17+[2]TONT20000SEPT!K17+[2]TONT20000OCT!K17+[2]TONT20000NOV!L17 -> 0 | V17: =[2]TONT20000DEC2015!N17+[2]TONT20000JANV!L17+[2]TONT20000FEV!L17+[2]TONT20000MARS!L17+[2]TONT20000AVRIL!L17+[2]TONT20000MAI!L17+[2]TONT20000JUIN!L17+[2]TONT20000JUIL!L17+[2]TONT20000AOUT!L17+[2]TONT20000SEPT!L17+[2]TONT20000OCT!L17+[2]TONT20000NOV!M17 -> 156000 | W17: =[2]TONT20000DEC2015!O17+[2]TONT20000JANV!M17+[2]TONT20000FEV!M17+[2]TONT20000MARS!M17+[2]TONT20000AVRIL!M17+[2]TONT20000MAI!M17+[2]TONT20000JUIN!M17+[2]TONT20000JUIL!M17+[2]TONT20000AOUT!M17+[2]TONT20000SEPT!M17+[2]TONT20000OCT!M17+[2]TONT20000NOV!N17 -> 0 | X17: =[2]TONT20000DEC2015!P17+[2]TONT20000JANV!N17+[2]TONT20000FEV!N17+[2]TONT20000MARS!N17+[2]TONT20000AVRIL!N17+[2]TONT20000MAI!N17+[2]TONT20000JUIN!N17+[2]TONT20000JUIL!N17+[2]TONT20000AOUT!N17+[2]TONT20000SEPT!N17+[2]TONT20000OCT!N17+[2]TONT20000NOV!O17 -> 0 | Y17: =[2]TONT20000DEC2015!Q17+[2]TONT20000JANV!O17+[2]TONT20000FEV!O17+[2]TONT20000MARS!O17+[2]TONT20000AVRIL!O17+[2]TONT20000MAI!O17+[2]TONT20000JUIN!O17+[2]TONT20000JUIL!O17+[2]TONT20000AOUT!O17+[2]TONT20000SEPT!O17+[2]TONT20000OCT!O17+[2]TONT20000NOV!P17 -> 0 | ... AB17: =[2]TONT20000DEC2015!T17+[2]TONT20000JANV!R17+[2]TONT20000FEV!R17+[2]TONT20000MARS!R17+[2]TONT20000AVRIL!R17+[2]TONT20000MAI!R17+[2]TONT20000JUIN!R17+[2]TONT20000JUIL!R17+[2]TONT20000AOUT!R17+[2]TONT20000SEPT!R17+[2]TONT20000OCT!R17+[2]TONT20000NOV!S17 -> 0
A18: AS201613 | B18: =VLOOKUP(A18,[2]LISTADHERENT!A$5:H$52,2,0) -> HOTCHO BENJAMIN | C18: =VLOOKUP(A18,[2]FONDSDECAISSE!A$5:C$52,3,0) -> 390000 | D18: 8723 | E18: =C18+D18+Q18 -> 482723 | F18: =INT([2]TONT20000DEC2015!E18+[2]TONT20000JANV!C18+[2]TONT20000FEV!C18+[2]TONT20000MARS!C18+[2]TONT20000AVRIL!C18+[2]TONT20000MAI!C18+[2]TONT20000JUIN!C18+[2]TONT20000JUIL!C18+[2]TONT20000AOUT!C18+[2]TONT20000SEPT!C18+[2]TONT20000OCT!C18+[2]TONT20000NOV!C18) -> 49962 | G18: =[2]TONT20000NOV!E18 -> 532685.38 | H18: =D18+F18+Q18 -> 142685 | I18: =L18+M18+N18+O18 -> 30000 | J18: =H18-I18 -> 112685 | K18: 0 | L18: 30000 | N18: 0 | O18: =48000-(R18+S18+T18) -> 0 | P18: =[2]TONT20000DEC2015!H18+[2]TONT20000JANV!F18+[2]TONT20000FEV!F18+[2]TONT20000MARS!F18+[2]TONT20000AVRIL!F18+[2]TONT20000MAI!F18+[2]TONT20000JUIN!F18+[2]TONT20000JUIL!F18+[2]TONT20000AOUT!F18+[2]TONT20000SEPT!F18+[2]TONT20000OCT!F18+[2]TONT20000NOV!G18 -> 338000 | Q18: =[2]TONT20000DEC2015!I18+[2]TONT20000JANV!G18+[2]TONT20000FEV!G18+[2]TONT20000MARS!G18+[2]TONT20000AVRIL!G18+[2]TONT20000MAI!G18+[2]TONT20000JUIN!G18+[2]TONT20000JUIL!G18+[2]TONT20000AOUT!G18+[2]TONT20000SEPT!G18+[2]TONT20000OCT!G18+[2]TONT20000NOV!H18 -> 84000 | R18: =[2]TONT20000DEC2015!J18+[2]TONT20000JANV!H18+[2]TONT20000FEV!H18+[2]TONT20000MARS!H18+[2]TONT20000AVRIL!H18+[2]TONT20000MAI!H18+[2]TONT20000JUIN!H18+[2]TONT20000JUIL!H18+[2]TONT20000AOUT!H18+[2]TONT20000SEPT!H18+[2]TONT20000OCT!H18+[2]TONT20000NOV!I18 -> 6000 | S18: =[2]TONT20000DEC2015!K18+[2]TONT20000JANV!I18+[2]TONT20000FEV!I18+[2]TONT20000MARS!I18+[2]TONT20000AVRIL!I18+[2]TONT20000MAI!I18+[2]TONT20000JUIN!I18+[2]TONT20000JUIL!I18+[2]TONT20000AOUT!I18+[2]TONT20000SEPT!I18+[2]TONT20000OCT!I18+[2]TONT20000NOV!J18 -> 12000 | T18: =[2]TONT20000DEC2015!L18+[2]TONT20000JANV!J18+[2]TONT20000FEV!J18+[2]TONT20000MARS!J18+[2]TONT20000AVRIL!J18+[2]TONT20000MAI!J18+[2]TONT20000JUIN!J18+[2]TONT20000JUIL!J18+[2]TONT20000AOUT!J18+[2]TONT20000SEPT!J18+[2]TONT20000OCT!J18+[2]TONT20000NOV!K18 -> 30000 | U18: =[2]TONT20000DEC2015!M18+[2]TONT20000JANV!K18+[2]TONT20000FEV!K18+[2]TONT20000MARS!K18+[2]TONT20000AVRIL!K18+[2]TONT20000MAI!K18+[2]TONT20000JUIN!K18+[2]TONT20000JUIL!K18+[2]TONT20000AOUT!K18+[2]TONT20000SEPT!K18+[2]TONT20000OCT!K18+[2]TONT20000NOV!L18 -> 50000 | V18: =[2]TONT20000DEC2015!N18+[2]TONT20000JANV!L18+[2]TONT20000FEV!L18+[2]TONT20000MARS!L18+[2]TONT20000AVRIL!L18+[2]TONT20000MAI!L18+[2]TONT20000JUIN!L18+[2]TONT20000JUIL!L18+[2]TONT20000AOUT!L18+[2]TONT20000SEPT!L18+[2]TONT20000OCT!L18+[2]TONT20000NOV!M18 -> 156000 | W18: =[2]TONT20000DEC2015!O18+[2]TONT20000JANV!M18+[2]TONT20000FEV!M18+[2]TONT20000MARS!M18+[2]TONT20000AVRIL!M18+[2]TONT20000MAI!M18+[2]TONT20000JUIN!M18+[2]TONT20000JUIL!M18+[2]TONT20000AOUT!M18+[2]TONT20000SEPT!M18+[2]TONT20000OCT!M18+[2]TONT20000NOV!N18 -> 0 | ... AB18: =[2]TONT20000DEC2015!T18+[2]TONT20000JANV!R18+[2]TONT20000FEV!R18+[2]TONT20000MARS!R18+[2]TONT20000AVRIL!R18+[2]TONT20000MAI!R18+[2]TONT20000JUIN!R18+[2]TONT20000JUIL!R18+[2]TONT20000AOUT!R18+[2]TONT20000SEPT!R18+[2]TONT20000OCT!R18+[2]TONT20000NOV!S18 -> 0
A19: AS201614 | B19: =VLOOKUP(A19,[2]LISTADHERENT!A$5:H$52,2,0) -> KEPHE DAVID | C19: =VLOOKUP(A19,[2]FONDSDECAISSE!A$5:C$52,3,0) -> 0 | D19: 12795 | E19: =C19+D19+Q19 -> 18000 | F19: =INT([2]TONT20000DEC2015!E19+[2]TONT20000JANV!C19+[2]TONT20000FEV!C19+[2]TONT20000MARS!C19+[2]TONT20000AVRIL!C19+[2]TONT20000MAI!C19+[2]TONT20000JUIN!C19+[2]TONT20000JUIL!C19+[2]TONT20000AOUT!C19+[2]TONT20000SEPT!C19+[2]TONT20000OCT!C19+[2]TONT20000NOV!C19) -> 4006 | G19: =[2]TONT20000NOV!E19 -> 52801.313 | H19: =D19+F19+Q19 -> 22006 | I19: =L19+M19+N19+O19 -> 21829 | J19: =H19-I19 -> 177 | K19: 0 | N19: =50000-24839-3332 -> 21829 | O19: =48000-(R19+S19+T19) -> 0 | P19: =[2]TONT20000DEC2015!H19+[2]TONT20000JANV!F19+[2]TONT20000FEV!F19+[2]TONT20000MARS!F19+[2]TONT20000AVRIL!F19+[2]TONT20000MAI!F19+[2]TONT20000JUIN!F19+[2]TONT20000JUIL!F19+[2]TONT20000AOUT!F19+[2]TONT20000SEPT!F19+[2]TONT20000OCT!F19+[2]TONT20000NOV!G19 -> 240000 | Q19: =[2]TONT20000DEC2015!I19+[2]TONT20000JANV!G19+[2]TONT20000FEV!G19+[2]TONT20000MARS!G19+[2]TONT20000AVRIL!G19+[2]TONT20000MAI!G19+[2]TONT20000JUIN!G19+[2]TONT20000JUIL!G19+[2]TONT20000AOUT!G19+[2]TONT20000SEPT!G19+[2]TONT20000OCT!G19+[2]TONT20000NOV!H19-30795 -> 5205 | R19: =[2]TONT20000DEC2015!J19+[2]TONT20000JANV!H19+[2]TONT20000FEV!H19+[2]TONT20000MARS!H19+[2]TONT20000AVRIL!H19+[2]TONT20000MAI!H19+[2]TONT20000JUIN!H19+[2]TONT20000JUIL!H19+[2]TONT20000AOUT!H19+[2]TONT20000SEPT!H19+[2]TONT20000OCT!H19+[2]TONT20000NOV!I19 -> 6000 | S19: =[2]TONT20000DEC2015!K19+[2]TONT20000JANV!I19+[2]TONT20000FEV!I19+[2]TONT20000MARS!I19+[2]TONT20000AVRIL!I19+[2]TONT20000MAI!I19+[2]TONT20000JUIN!I19+[2]TONT20000JUIL!I19+[2]TONT20000AOUT!I19+[2]TONT20000SEPT!I19+[2]TONT20000OCT!I19+[2]TONT20000NOV!J19 -> 12000 | T19: =[2]TONT20000DEC2015!L19+[2]TONT20000JANV!J19+[2]TONT20000FEV!J19+[2]TONT20000MARS!J19+[2]TONT20000AVRIL!J19+[2]TONT20000MAI!J19+[2]TONT20000JUIN!J19+[2]TONT20000JUIL!J19+[2]TONT20000AOUT!J19+[2]TONT20000SEPT!J19+[2]TONT20000OCT!J19+[2]TONT20000NOV!K19 -> 30000 | U19: =[2]TONT20000DEC2015!M19+[2]TONT20000JANV!K19+[2]TONT20000FEV!K19+[2]TONT20000MARS!K19+[2]TONT20000AVRIL!K19+[2]TONT20000MAI!K19+[2]TONT20000JUIN!K19+[2]TONT20000JUIL!K19+[2]TONT20000AOUT!K19+[2]TONT20000SEPT!K19+[2]TONT20000OCT!K19+[2]TONT20000NOV!L19 -> 0 | V19: =[2]TONT20000DEC2015!N19+[2]TONT20000JANV!L19+[2]TONT20000FEV!L19+[2]TONT20000MARS!L19+[2]TONT20000AVRIL!L19+[2]TONT20000MAI!L19+[2]TONT20000JUIN!L19+[2]TONT20000JUIL!L19+[2]TONT20000AOUT!L19+[2]TONT20000SEPT!L19+[2]TONT20000OCT!L19+[2]TONT20000NOV!M19 -> 156000 | W19: =[2]TONT20000DEC2015!O19+[2]TONT20000JANV!M19+[2]TONT20000FEV!M19+[2]TONT20000MARS!M19+[2]TONT20000AVRIL!M19+[2]TONT20000MAI!M19+[2]TONT20000JUIN!M19+[2]TONT20000JUIL!M19+[2]TONT20000AOUT!M19+[2]TONT20000SEPT!M19+[2]TONT20000OCT!M19+[2]TONT20000NOV!N19 -> 0 | X19: =[2]TONT20000DEC2015!P19+[2]TONT20000JANV!N19+[2]TONT20000FEV!N19+[2]TONT20000MARS!N19+[2]TONT20000AVRIL!N19+[2]TONT20000MAI!N19+[2]TONT20000JUIN!N19+[2]TONT20000JUIL!N19+[2]TONT20000AOUT!N19+[2]TONT20000SEPT!N19+[2]TONT20000OCT!N19+[2]TONT20000NOV!O19 -> 0 | Y19: =[2]TONT20000DEC2015!Q19+[2]TONT20000JANV!O19+[2]TONT20000FEV!O19+[2]TONT20000MARS!O19+[2]TONT20000AVRIL!O19+[2]TONT20000MAI!O19+[2]TONT20000JUIN!O19+[2]TONT20000JUIL!O19+[2]TONT20000AOUT!O19+[2]TONT20000SEPT!O19+[2]TONT20000OCT!O19+[2]TONT20000NOV!P19 -> 0 | ... AB19: =[2]TONT20000DEC2015!T19+[2]TONT20000JANV!R19+[2]TONT20000FEV!R19+[2]TONT20000MARS!R19+[2]TONT20000AVRIL!R19+[2]TONT20000MAI!R19+[2]TONT20000JUIN!R19+[2]TONT20000JUIL!R19+[2]TONT20000AOUT!R19+[2]TONT20000SEPT!R19+[2]TONT20000OCT!R19+[2]TONT20000NOV!S19 -> 0
A20: AS201615 | B20: =VLOOKUP(A20,[2]LISTADHERENT!A$5:H$52,2,0) -> KEPSEU FRANCIS | C20: =VLOOKUP(A20,[2]FONDSDECAISSE!A$5:C$52,3,0) -> 390000 | D20: 186997 | E20: =C20+D20+Q20 -> 1128997 | F20: =INT([2]TONT20000DEC2015!E20+[2]TONT20000JANV!C20+[2]TONT20000FEV!C20+[2]TONT20000MARS!C20+[2]TONT20000AVRIL!C20+[2]TONT20000MAI!C20+[2]TONT20000JUIN!C20+[2]TONT20000JUIL!C20+[2]TONT20000AOUT!C20+[2]TONT20000SEPT!C20+[2]TONT20000OCT!C20+[2]TONT20000NOV!C20) -> 117428 | G20: =[2]TONT20000NOV!E20 -> 1246425.8 | H20: =D20+F20+Q20 -> 856425 | I20: =L20+M20+N20+O20 -> 80000 | J20: =H20-I20 -> 776425 | K20: 71000 | L20: 30000 | N20: 50000 | O20: =48000-(R20+S20+T20) -> 0 | P20: =[2]TONT20000DEC2015!H20+[2]TONT20000JANV!F20+[2]TONT20000FEV!F20+[2]TONT20000MARS!F20+[2]TONT20000AVRIL!F20+[2]TONT20000MAI!F20+[2]TONT20000JUIN!F20+[2]TONT20000JUIL!F20+[2]TONT20000AOUT!F20+[2]TONT20000SEPT!F20+[2]TONT20000OCT!F20+[2]TONT20000NOV!G20 -> 756000 | Q20: =[2]TONT20000DEC2015!I20+[2]TONT20000JANV!G20+[2]TONT20000FEV!G20+[2]TONT20000MARS!G20+[2]TONT20000AVRIL!G20+[2]TONT20000MAI!G20+[2]TONT20000JUIN!G20+[2]TONT20000JUIL!G20+[2]TONT20000AOUT!G20+[2]TONT20000SEPT!G20+[2]TONT20000OCT!G20+[2]TONT20000NOV!H20 -> 552000 | R20: =[2]TONT20000DEC2015!J20+[2]TONT20000JANV!H20+[2]TONT20000FEV!H20+[2]TONT20000MARS!H20+[2]TONT20000AVRIL!H20+[2]TONT20000MAI!H20+[2]TONT20000JUIN!H20+[2]TONT20000JUIL!H20+[2]TONT20000AOUT!H20+[2]TONT20000SEPT!H20+[2]TONT20000OCT!H20+[2]TONT20000NOV!I20 -> 6000 | S20: =[2]TONT20000DEC2015!K20+[2]TONT20000JANV!I20+[2]TONT20000FEV!I20+[2]TONT20000MARS!I20+[2]TONT20000AVRIL!I20+[2]TONT20000MAI!I20+[2]TONT20000JUIN!I20+[2]TONT20000JUIL!I20+[2]TONT20000AOUT!I20+[2]TONT20000SEPT!I20+[2]TONT20000OCT!I20+[2]TONT20000NOV!J20 -> 12000 | T20: =[2]TONT20000DEC2015!L20+[2]TONT20000JANV!J20+[2]TONT20000FEV!J20+[2]TONT20000MARS!J20+[2]TONT20000AVRIL!J20+[2]TONT20000MAI!J20+[2]TONT20000JUIN!J20+[2]TONT20000JUIL!J20+[2]TONT20000AOUT!J20+[2]TONT20000SEPT!J20+[2]TONT20000OCT!J20+[2]TONT20000NOV!K20 -> 30000 | U20: =[2]TONT20000DEC2015!M20+[2]TONT20000JANV!K20+[2]TONT20000FEV!K20+[2]TONT20000MARS!K20+[2]TONT20000AVRIL!K20+[2]TONT20000MAI!K20+[2]TONT20000JUIN!K20+[2]TONT20000JUIL!K20+[2]TONT20000AOUT!K20+[2]TONT20000SEPT!K20+[2]TONT20000OCT!K20+[2]TONT20000NOV!L20 -> 0 | V20: =[2]TONT20000DEC2015!N20+[2]TONT20000JANV!L20+[2]TONT20000FEV!L20+[2]TONT20000MARS!L20+[2]TONT20000AVRIL!L20+[2]TONT20000MAI!L20+[2]TONT20000JUIN!L20+[2]TONT20000JUIL!L20+[2]TONT20000AOUT!L20+[2]TONT20000SEPT!L20+[2]TONT20000OCT!L20+[2]TONT20000NOV!M20 -> 156000 | W20: =[2]TONT20000DEC2015!O20+[2]TONT20000JANV!M20+[2]TONT20000FEV!M20+[2]TONT20000MARS!M20+[2]TONT20000AVRIL!M20+[2]TONT20000MAI!M20+[2]TONT20000JUIN!M20+[2]TONT20000JUIL!M20+[2]TONT20000AOUT!M20+[2]TONT20000SEPT!M20+[2]TONT20000OCT!M20+[2]TONT20000NOV!N20 -> 0 | ... AB20: =[2]TONT20000DEC2015!T20+[2]TONT20000JANV!R20+[2]TONT20000FEV!R20+[2]TONT20000MARS!R20+[2]TONT20000AVRIL!R20+[2]TONT20000MAI!R20+[2]TONT20000JUIN!R20+[2]TONT20000JUIL!R20+[2]TONT20000AOUT!R20+[2]TONT20000SEPT!R20+[2]TONT20000OCT!R20+[2]TONT20000NOV!S20 -> 0
A21: AS201616 | B21: =VLOOKUP(A21,[2]LISTADHERENT!A$5:H$52,2,0) -> KOUAMOU EMMANUEL | C21: =VLOOKUP(A21,[2]FONDSDECAISSE!A$5:C$52,3,0) -> 390000 | D21: 2723 | E21: =C21+D21+Q21 -> 428723 | F21: =INT([2]TONT20000DEC2015!E21+[2]TONT20000JANV!C21+[2]TONT20000FEV!C21+[2]TONT20000MARS!C21+[2]TONT20000AVRIL!C21+[2]TONT20000MAI!C21+[2]TONT20000JUIN!C21+[2]TONT20000JUIL!C21+[2]TONT20000AOUT!C21+[2]TONT20000SEPT!C21+[2]TONT20000OCT!C21+[2]TONT20000NOV!C21) -> 48134 | G21: =[2]TONT20000NOV!E21 -> 476857.92 | H21: =D21+F21+Q21 -> 86857 | I21: =L21+M21+N21+O21 -> 80000 | J21: =H21-I21 -> 6857 | K21: 4500 | L21: 30000 | N21: 50000 | O21: =48000-(R21+S21+T21) -> 0 | P21: =[2]TONT20000DEC2015!H21+[2]TONT20000JANV!F21+[2]TONT20000FEV!F21+[2]TONT20000MARS!F21+[2]TONT20000AVRIL!F21+[2]TONT20000MAI!F21+[2]TONT20000JUIN!F21+[2]TONT20000JUIL!F21+[2]TONT20000AOUT!F21+[2]TONT20000SEPT!F21+[2]TONT20000OCT!F21+[2]TONT20000NOV!G21 -> 240000 | Q21: =[2]TONT20000DEC2015!I21+[2]TONT20000JANV!G21+[2]TONT20000FEV!G21+[2]TONT20000MARS!G21+[2]TONT20000AVRIL!G21+[2]TONT20000MAI!G21+[2]TONT20000JUIN!G21+[2]TONT20000JUIL!G21+[2]TONT20000AOUT!G21+[2]TONT20000SEPT!G21+[2]TONT20000OCT!G21+[2]TONT20000NOV!H21 -> 36000 | R21: =[2]TONT20000DEC2015!J21+[2]TONT20000JANV!H21+[2]TONT20000FEV!H21+[2]TONT20000MARS!H21+[2]TONT20000AVRIL!H21+[2]TONT20000MAI!H21+[2]TONT20000JUIN!H21+[2]TONT20000JUIL!H21+[2]TONT20000AOUT!H21+[2]TONT20000SEPT!H21+[2]TONT20000OCT!H21+[2]TONT20000NOV!I21 -> 6000 | S21: =[2]TONT20000DEC2015!K21+[2]TONT20000JANV!I21+[2]TONT20000FEV!I21+[2]TONT20000MARS!I21+[2]TONT20000AVRIL!I21+[2]TONT20000MAI!I21+[2]TONT20000JUIN!I21+[2]TONT20000JUIL!I21+[2]TONT20000AOUT!I21+[2]TONT20000SEPT!I21+[2]TONT20000OCT!I21+[2]TONT20000NOV!J21 -> 12000 | T21: =[2]TONT20000DEC2015!L21+[2]TONT20000JANV!J21+[2]TONT20000FEV!J21+[2]TONT20000MARS!J21+[2]TONT20000AVRIL!J21+[2]TONT20000MAI!J21+[2]TONT20000JUIN!J21+[2]TONT20000JUIL!J21+[2]TONT20000AOUT!J21+[2]TONT20000SEPT!J21+[2]TONT20000OCT!J21+[2]TONT20000NOV!K21 -> 30000 | U21: =[2]TONT20000DEC2015!M21+[2]TONT20000JANV!K21+[2]TONT20000FEV!K21+[2]TONT20000MARS!K21+[2]TONT20000AVRIL!K21+[2]TONT20000MAI!K21+[2]TONT20000JUIN!K21+[2]TONT20000JUIL!K21+[2]TONT20000AOUT!K21+[2]TONT20000SEPT!K21+[2]TONT20000OCT!K21+[2]TONT20000NOV!L21 -> 0 | V21: =[2]TONT20000DEC2015!N21+[2]TONT20000JANV!L21+[2]TONT20000FEV!L21+[2]TONT20000MARS!L21+[2]TONT20000AVRIL!L21+[2]TONT20000MAI!L21+[2]TONT20000JUIN!L21+[2]TONT20000JUIL!L21+[2]TONT20000AOUT!L21+[2]TONT20000SEPT!L21+[2]TONT20000OCT!L21+[2]TONT20000NOV!M21 -> 156000 | W21: =[2]TONT20000DEC2015!O21+[2]TONT20000JANV!M21+[2]TONT20000FEV!M21+[2]TONT20000MARS!M21+[2]TONT20000AVRIL!M21+[2]TONT20000MAI!M21+[2]TONT20000JUIN!M21+[2]TONT20000JUIL!M21+[2]TONT20000AOUT!M21+[2]TONT20000SEPT!M21+[2]TONT20000OCT!M21+[2]TONT20000NOV!N21 -> 1000000 | ... AB21: =[2]TONT20000DEC2015!T21+[2]TONT20000JANV!R21+[2]TONT20000FEV!R21+[2]TONT20000MARS!R21+[2]TONT20000AVRIL!R21+[2]TONT20000MAI!R21+[2]TONT20000JUIN!R21+[2]TONT20000JUIL!R21+[2]TONT20000AOUT!R21+[2]TONT20000SEPT!R21+[2]TONT20000OCT!R21+[2]TONT20000NOV!S21 -> 0
A22: AS201617 | B22: =VLOOKUP(A22,[2]LISTADHERENT!A$5:H$52,2,0) -> KOUAMOU MOISE | C22: 390000 | D22: 2099 | E22: =C22+D22+Q22 -> 428099 | F22: =INT([2]TONT20000DEC2015!E22+[2]TONT20000JANV!C22+[2]TONT20000FEV!C22+[2]TONT20000MARS!C22+[2]TONT20000AVRIL!C22+[2]TONT20000MAI!C22+[2]TONT20000JUIN!C22+[2]TONT20000JUIL!C22+[2]TONT20000AOUT!C22+[2]TONT20000SEPT!C22+[2]TONT20000OCT!C22+[2]TONT20000NOV!C22) -> 44949 | G22: =[2]TONT20000NOV!E22 -> 473048.51 | H22: =D22+F22+Q22 -> 83048 | I22: =L22+M22+N22+O22 -> 80000 | J22: =H22-I22 -> 3048 | K22: 0 | L22: 30000 | N22: 50000 | O22: =48000-(R22+S22+T22) -> 0 | P22: =[2]TONT20000DEC2015!H22+[2]TONT20000JANV!F22+[2]TONT20000FEV!F22+[2]TONT20000MARS!F22+[2]TONT20000AVRIL!F22+[2]TONT20000MAI!F22+[2]TONT20000JUIN!F22+[2]TONT20000JUIL!F22+[2]TONT20000AOUT!F22+[2]TONT20000SEPT!F22+[2]TONT20000OCT!F22+[2]TONT20000NOV!G22 -> 240000 | Q22: =[2]TONT20000DEC2015!I22+[2]TONT20000JANV!G22+[2]TONT20000FEV!G22+[2]TONT20000MARS!G22+[2]TONT20000AVRIL!G22+[2]TONT20000MAI!G22+[2]TONT20000JUIN!G22+[2]TONT20000JUIL!G22+[2]TONT20000AOUT!G22+[2]TONT20000SEPT!G22+[2]TONT20000OCT!G22+[2]TONT20000NOV!H22 -> 36000 | R22: =[2]TONT20000DEC2015!J22+[2]TONT20000JANV!H22+[2]TONT20000FEV!H22+[2]TONT20000MARS!H22+[2]TONT20000AVRIL!H22+[2]TONT20000MAI!H22+[2]TONT20000JUIN!H22+[2]TONT20000JUIL!H22+[2]TONT20000AOUT!H22+[2]TONT20000SEPT!H22+[2]TONT20000OCT!H22+[2]TONT20000NOV!I22 -> 6000 | S22: =[2]TONT20000DEC2015!K22+[2]TONT20000JANV!I22+[2]TONT20000FEV!I22+[2]TONT20000MARS!I22+[2]TONT20000AVRIL!I22+[2]TONT20000MAI!I22+[2]TONT20000JUIN!I22+[2]TONT20000JUIL!I22+[2]TONT20000AOUT!I22+[2]TONT20000SEPT!I22+[2]TONT20000OCT!I22+[2]TONT20000NOV!J22 -> 12000 | T22: =[2]TONT20000DEC2015!L22+[2]TONT20000JANV!J22+[2]TONT20000FEV!J22+[2]TONT20000MARS!J22+[2]TONT20000AVRIL!J22+[2]TONT20000MAI!J22+[2]TONT20000JUIN!J22+[2]TONT20000JUIL!J22+[2]TONT20000AOUT!J22+[2]TONT20000SEPT!J22+[2]TONT20000OCT!J22+[2]TONT20000NOV!K22 -> 30000 | U22: =[2]TONT20000DEC2015!M22+[2]TONT20000JANV!K22+[2]TONT20000FEV!K22+[2]TONT20000MARS!K22+[2]TONT20000AVRIL!K22+[2]TONT20000MAI!K22+[2]TONT20000JUIN!K22+[2]TONT20000JUIL!K22+[2]TONT20000AOUT!K22+[2]TONT20000SEPT!K22+[2]TONT20000OCT!K22+[2]TONT20000NOV!L22 -> 0 | V22: =[2]TONT20000DEC2015!N22+[2]TONT20000JANV!L22+[2]TONT20000FEV!L22+[2]TONT20000MARS!L22+[2]TONT20000AVRIL!L22+[2]TONT20000MAI!L22+[2]TONT20000JUIN!L22+[2]TONT20000JUIL!L22+[2]TONT20000AOUT!L22+[2]TONT20000SEPT!L22+[2]TONT20000OCT!L22+[2]TONT20000NOV!M22 -> 156000 | W22: =[2]TONT20000DEC2015!O22+[2]TONT20000JANV!M22+[2]TONT20000FEV!M22+[2]TONT20000MARS!M22+[2]TONT20000AVRIL!M22+[2]TONT20000MAI!M22+[2]TONT20000JUIN!M22+[2]TONT20000JUIL!M22+[2]TONT20000AOUT!M22+[2]TONT20000SEPT!M22+[2]TONT20000OCT!M22+[2]TONT20000NOV!N22 -> 860000 | ... AB22: =[2]TONT20000DEC2015!T22+[2]TONT20000JANV!R22+[2]TONT20000FEV!R22+[2]TONT20000MARS!R22+[2]TONT20000AVRIL!R22+[2]TONT20000MAI!R22+[2]TONT20000JUIN!R22+[2]TONT20000JUIL!R22+[2]TONT20000AOUT!R22+[2]TONT20000SEPT!R22+[2]TONT20000OCT!R22+[2]TONT20000NOV!S22 -> 0
A23: AS201618 | B23: =VLOOKUP(A23,[2]LISTADHERENT!A$5:H$52,2,0) -> KOUAMOU VICTOR PEGUY | C23: =VLOOKUP(A23,[2]FONDSDECAISSE!A$5:C$52,3,0) -> 390000 | D23: 36629 | E23: =C23+D23+Q23 -> 461629 | F23: =INT([2]TONT20000DEC2015!E23+[2]TONT20000JANV!C23+[2]TONT20000FEV!C23+[2]TONT20000MARS!C23+[2]TONT20000AVRIL!C23+[2]TONT20000MAI!C23+[2]TONT20000JUIN!C23+[2]TONT20000JUIL!C23+[2]TONT20000AOUT!C23+[2]TONT20000SEPT!C23+[2]TONT20000OCT!C23+[2]TONT20000NOV!C23) -> 52057 | G23: =[2]TONT20000NOV!E23 -> 513686.78 | H23: =D23+F23+Q23 -> 123686 | I23: =L23+M23+N23+O23 -> 80000 | J23: =H23-I23 -> 43686 | K23: 41000 | L23: 30000 | N23: 50000 | O23: =48000-(R23+S23+T23) -> 0 | P23: =[2]TONT20000DEC2015!H23+[2]TONT20000JANV!F23+[2]TONT20000FEV!F23+[2]TONT20000MARS!F23+[2]TONT20000AVRIL!F23+[2]TONT20000MAI!F23+[2]TONT20000JUIN!F23+[2]TONT20000JUIL!F23+[2]TONT20000AOUT!F23+[2]TONT20000SEPT!F23+[2]TONT20000OCT!F23+[2]TONT20000NOV!G23 -> 239000 | Q23: =[2]TONT20000DEC2015!I23+[2]TONT20000JANV!G23+[2]TONT20000FEV!G23+[2]TONT20000MARS!G23+[2]TONT20000AVRIL!G23+[2]TONT20000MAI!G23+[2]TONT20000JUIN!G23+[2]TONT20000JUIL!G23+[2]TONT20000AOUT!G23+[2]TONT20000SEPT!G23+[2]TONT20000OCT!G23+[2]TONT20000NOV!H23 -> 35000 | R23: =[2]TONT20000DEC2015!J23+[2]TONT20000JANV!H23+[2]TONT20000FEV!H23+[2]TONT20000MARS!H23+[2]TONT20000AVRIL!H23+[2]TONT20000MAI!H23+[2]TONT20000JUIN!H23+[2]TONT20000JUIL!H23+[2]TONT20000AOUT!H23+[2]TONT20000SEPT!H23+[2]TONT20000OCT!H23+[2]TONT20000NOV!I23 -> 6000 | S23: =[2]TONT20000DEC2015!K23+[2]TONT20000JANV!I23+[2]TONT20000FEV!I23+[2]TONT20000MARS!I23+[2]TONT20000AVRIL!I23+[2]TONT20000MAI!I23+[2]TONT20000JUIN!I23+[2]TONT20000JUIL!I23+[2]TONT20000AOUT!I23+[2]TONT20000SEPT!I23+[2]TONT20000OCT!I23+[2]TONT20000NOV!J23 -> 12000 | T23: =[2]TONT20000DEC2015!L23+[2]TONT20000JANV!J23+[2]TONT20000FEV!J23+[2]TONT20000MARS!J23+[2]TONT20000AVRIL!J23+[2]TONT20000MAI!J23+[2]TONT20000JUIN!J23+[2]TONT20000JUIL!J23+[2]TONT20000AOUT!J23+[2]TONT20000SEPT!J23+[2]TONT20000OCT!J23+[2]TONT20000NOV!K23 -> 30000 | U23: =[2]TONT20000DEC2015!M23+[2]TONT20000JANV!K23+[2]TONT20000FEV!K23+[2]TONT20000MARS!K23+[2]TONT20000AVRIL!K23+[2]TONT20000MAI!K23+[2]TONT20000JUIN!K23+[2]TONT20000JUIL!K23+[2]TONT20000AOUT!K23+[2]TONT20000SEPT!K23+[2]TONT20000OCT!K23+[2]TONT20000NOV!L23 -> 0 | V23: =[2]TONT20000DEC2015!N23+[2]TONT20000JANV!L23+[2]TONT20000FEV!L23+[2]TONT20000MARS!L23+[2]TONT20000AVRIL!L23+[2]TONT20000MAI!L23+[2]TONT20000JUIN!L23+[2]TONT20000JUIL!L23+[2]TONT20000AOUT!L23+[2]TONT20000SEPT!L23+[2]TONT20000OCT!L23+[2]TONT20000NOV!M23 -> 156000 | W23: =[2]TONT20000DEC2015!O23+[2]TONT20000JANV!M23+[2]TONT20000FEV!M23+[2]TONT20000MARS!M23+[2]TONT20000AVRIL!M23+[2]TONT20000MAI!M23+[2]TONT20000JUIN!M23+[2]TONT20000JUIL!M23+[2]TONT20000AOUT!M23+[2]TONT20000SEPT!M23+[2]TONT20000OCT!M23+[2]TONT20000NOV!N23 -> 1800000 | ... AB23: =[2]TONT20000DEC2015!T23+[2]TONT20000JANV!R23+[2]TONT20000FEV!R23+[2]TONT20000MARS!R23+[2]TONT20000AVRIL!R23+[2]TONT20000MAI!R23+[2]TONT20000JUIN!R23+[2]TONT20000JUIL!R23+[2]TONT20000AOUT!R23+[2]TONT20000SEPT!R23+[2]TONT20000OCT!R23+[2]TONT20000NOV!S23 -> 0
