Workbook
Name MODEPAID: [1]Feuil2!$A$1:$A$3

Sheet RECAPEMPRUNTREMB
A1: ASSOCIATION | B1: ASELBY
A2: ANNEE | B2: 2016/2017
A3: TONTINE | B3: 20 000 | C3: DECEMBRE 2015 | F3: JANVIER | I3: FÉVRIER | L3: MARS | O3: AVRIL | R3: MAI | U3: JUIN | X3: JUILLET | AA3: AOÛT | AD3: SEPTEMBRE | AG3: OCTOBRE | AJ3: NOVEMBRE
A4: MATRICULE | B4: NOM ET PRENOM | C4: EMPRUNT | D4: INTERET EMPRUNT | E4: REMBOURSEMENT | F4: EMPRUNT | G4: INTERET EMPRUNT | H4: REMBOURSEMENT | I4: EMPRUNT | J4: INTERET EMPRUNT | K4: REMBOURSEMENT | L4: EMPRUNT | M4: INTERET EMPRUNT | N4: REMBOURSEMENT | O4: EMPRUNT | P4: INTERET EMPRUNT | Q4: REMBOURSEMENT | R4: EMPRUNT | S4: INTERET EMPRUNT | T4: REMBOURSEMENT | U4: EMPRUNT | V4: INTERET EMPRUNT | W4: REMBOURSEMENT | X4: EMPRUNT | Y4: INTERET EMPRUNT | Z4: REMBOURSEMENT | AA4: EMPRUNT | AB4: INTERET EMPRUNT | AC4: REMBOURSEMENT | AD4: EMPRUNT | AE4: INTERET EMPRUNT | AF4: REMBOURSEMENT | AG4: EMPRUNT | AH4: INTERET EMPRUNT | AI4: REMBOURSEMENT | AJ4: EMPRUNT | AK4: INTERET EMPRUNT | AL4: REMBOURSEMENT
A5: AS201648 | B5: =VLOOKUP(A5,LISTADHERENT!A$5:H$52,2,0) -> ASELBY | C5: =TONT20000DEC2015!$O5 -> 0 | D5: =TONT20000DEC2015!$P5 -> 0 | E5: =TONT20000DEC2015!$Q5 -> 0 | F5: =TONT20000JANV!$M5 -> 0 | G5: =TONT20000JANV!$N5 -> 0 | H5: =TONT20000JANV!$O5 -> 0 | I5: =TONT20000FEV!$M5 -> 0 | J5: =TONT20000FEV!$N5 -> 0 | K5: =TONT20000FEV!$O5 -> 0 | L5: =TONT20000MARS!$M5 -> 0 | M5: =TONT20000MARS!$N5 -> 0 | N5: =TONT20000MARS!$O5 -> 0 | O5: =TONT20000AVRIL!$M5 -> 0 | P5: =TONT20000AVRIL!$N5 -> 0 | Q5: =TONT20000AVRIL!$O5 -> 0 | R5: =TONT20000MAI!$M5 -> 0 | S5: =TONT20000MAI!$N5 -> 0 | T5: =TONT20000MAI!$O5 -> 0 | U5: =TONT20000JUIN!$M5 -> 0 | V5: =TONT20000JUIN!$N5 -> 0 | W5: =TONT20000JUIN!$O5 -> 0 | X5: =TONT20000JUIL!$M5 -> 0 | Y5: =TONT20000JUIL!$N5 -> 0 | Z5: =TONT20000JUIL!$O5 -> 0 | AA5: =TONT20000AOUT!$M5 -> 0 | AB5: =TONT20000AOUT!$N5 -> 0 | AC5: =TONT20000AOUT!$O5 -> 0 | AD5: =TONT20000SEPT!$M5 -> 0 | AE5: =TONT20000SEPT!$N5 -> 0 | AF5: =TONT20000SEPT!$O5 -> 0 | AG5: =TONT20000OCT!$M5 -> 0 | AH5: =TONT20000OCT!$N5 -> 0 | AI5: =TONT20000OCT!$O5 -> 0 | AJ5: =TONT20000NOV!$N5 -> 0 | AK5: =TONT20000NOV!$O5 -> 0 | AL5: =TONT20000NOV!$P5 -> 0
A6: AS201601 | B6: =VLOOKUP(A6,LISTADHERENT!A$5:H$52,2,0) -> BAKOP ACHILLE | C6: =TONT20000DEC2015!$O6 -> 0 | D6: =TONT20000DEC2015!$P6 -> 0 | E6: =TONT20000DEC2015!$Q6 -> 0 | F6: =TONT20000JANV!$M6 -> 0 | G6: =TONT20000JANV!$N6 -> 0 | H6: =TONT20000JANV!$O6 -> 0 | I6: =TONT20000FEV!$M6 -> 0 | J6: =TONT20000FEV!$N6 -> 0 | K6: =TONT20000FEV!$O6 -> 0 | L6: =TONT20000MARS!$M6 -> 0 | M6: =TONT20000MARS!$N6 -> 0 | N6: =TONT20000MARS!$O6 -> 0 | O6: =TONT20000AVRIL!$M6 -> 0 | P6: =TONT20000AVRIL!$N6 -> 0 | Q6: =TONT20000AVRIL!$O6 -> 0 | R6: =TONT20000MAI!$M6 -> 0 | S6: =TONT20000MAI!$N6 -> 0 | T6: =TONT20000MAI!$O6 -> 0 | U6: =TONT20000JUIN!$M6 -> 0 | V6: =TONT20000JUIN!$N6 -> 0 | W6: =TONT20000JUIN!$O6 -> 0 | X6: =TONT20000JUIL!$M6 -> 0 | Y6: =TONT20000JUIL!$N6 -> 0 | Z6: =TONT20000JUIL!$O6 -> 0 | AA6: =TONT20000AOUT!$M6 -> 500000 | AB6: =TONT20000AOUT!$N6 -> 15000 | AC6: =TONT20000AOUT!$O6 -> 0 | AD6: =TONT20000SEPT!$M6 -> 0 | AE6: =TONT20000SEPT!$N6 -> 0 | AF6: =TONT20000SEPT!$O6 -> 0 | AG6: =TONT20000OCT!$M6 -> 0 | AH6: =TONT20000OCT!$N6 -> 0 | AI6: =TONT20000OCT!$O6 -> 0 | AJ6: =TONT20000NOV!$N6 -> 0 | AK6: =TONT20000NOV!$O6 -> 0 | AL6: =TONT20000NOV!$P6 -> 0
A7: AS201602 | B7: =VLOOKUP(A7,LISTADHERENT!A$5:H$51,2) -> BOUTCHOUANG WILLIAM | C7: =TONT20000DEC2015!$O7 -> 0 | D7: =TONT20000DEC2015!$P7 -> 0 | E7: =TONT20000DEC2015!$Q7 -> 0 | F7: =TONT20000JANV!$M7 -> 0 | G7: =TONT20000JANV!$N7 -> 0 | H7: =TONT20000JANV!$O7 -> 0 | I7: =TONT20000FEV!$M7 -> 0 | J7: =TONT20000FEV!$N7 -> 0 | K7: =TONT20000FEV!$O7 -> 0 | L7: =TONT20000MARS!$M7 -> 0 | M7: =TONT20000MARS!$N7 -> 0 | N7: =TONT20000MARS!$O7 -> 0 | O7: =TONT20000AVRIL!$M7 -> 0 | P7: =TONT20000AVRIL!$N7 -> 0 | Q7: =TONT20000AVRIL!$O7 -> 0 | R7: =TONT20000MAI!$M7 -> 0 | S7: =TONT20000MAI!$N7 -> 0 | T7: =TONT20000MAI!$O7 -> 0 | U7: =TONT20000JUIN!$M7 -> 0 | V7: =TONT20000JUIN!$N7 -> 0 | W7: =TONT20000JUIN!$O7 -> 0 | X7: =TONT20000JUIL!$M7 -> 1000000 | Y7: =TONT20000JUIL!$N7 -> 40000 | Z7: =TONT20000JUIL!$O7 -> 0 | AA7: =TONT20000AOUT!$M7 -> 0 | AB7: =TONT20000AOUT!$N7 -> 0 | AC7: =TONT20000AOUT!$O7 -> 0 | AD7: =TONT20000SEPT!$M7 -> 0 | AE7: =TONT20000SEPT!$N7 -> 0 | AF7: =TONT20000SEPT!$O7 -> 0 | AG7: =TONT20000OCT!$M7 -> 0 | AH7: =TONT20000OCT!$N7 -> 0 | AI7: =TONT20000OCT!$O7 -> 0 | AJ7: =TONT20000NOV!$N7 -> 700000 | AK7: =TONT20000NOV!$O7 -> 84000 | AL7: =TONT20000NOV!$P7 -> 1000000
A8: AS201603 | B8: =VLOOKUP(A8,LISTADHERENT!A$5:H$51,2) -> CHINGUE FABRICE | C8: =TONT20000DEC2015!$O8 -> 0 | D8: =TONT20000DEC2015!$P8 -> 0 | E8: =TONT20000DEC2015!$Q8 -> 0 | F8: =TONT20000JANV!$M8 -> 1000000 | G8: =TONT20000JANV!$N8 -> 60000 | H8: =TONT20000JANV!$O8 -> 0 | I8: =TONT20000FEV!$M8 -> 0 | J8: =TONT20000FEV!$N8 -> 0 | K8: =TONT20000FEV!$O8 -> 0 | L8: =TONT20000MARS!$M8 -> 0 | M8: =TONT20000MARS!$N8 -> 0 | N8: =TONT20000MARS!$O8 -> 0 | O8: =TONT20000AVRIL!$M8 -> 0 | P8: =TONT20000AVRIL!$N8 -> 0 | Q8: =TONT20000AVRIL!$O8 -> 0 | R8: =TONT20000MAI!$M8 -> 0 | S8: =TONT20000MAI!$N8 -> 0 | T8: =TONT20000MAI!$O8 -> 0 | U8: =TONT20000JUIN!$M8 -> 1000000 | V8: =TONT20000JUIN!$N8 -> 120000 | W8: =TONT20000JUIN!$O8 -> 1000000 | X8: =TONT20000JUIL!$M8 -> 0 | Y8: =TONT20000JUIL!$N8 -> 0 | Z8: =TONT20000JUIL!$O8 -> 0 | AA8: =TONT20000AOUT!$M8 -> 0 | AB8: =TONT20000AOUT!$N8 -> 0 | AC8: =TONT20000AOUT!$O8 -> 0 | AD8: =TONT20000SEPT!$M8 -> 0 | AE8: =TONT20000SEPT!$N8 -> 0 | AF8: =TONT20000SEPT!$O8 -> 0 | AG8: =TONT20000OCT!$M8 -> 0 | AH8: =TONT20000OCT!$N8 -> 0 | AI8: =TONT20000OCT!$O8 -> 0 | AJ8: =TONT20000NOV!$N8 -> 0 | AK8: =TONT20000NOV!$O8 -> 0 | AL8: =TONT20000NOV!$P8 -> 0
A9: AS201604 | B9: =VLOOKUP(A9,LISTADHERENT!A$5:H$51,2) -> DJOMO JEAN PAUL | C9: =TONT20000DEC2015!$O9 -> 0 | D9: =TONT20000DEC2015!$P9 -> 0 | E9: =TONT20000DEC2015!$Q9 -> 0 | F9: =TONT20000JANV!$M9 -> 0 | G9: =TONT20000JANV!$N9 -> 0 | H9: =TONT20000JANV!$O9 -> 0 | I9: =TONT20000FEV!$M9 -> 0 | J9: =TONT20000FEV!$N9 -> 0 | K9: =TONT20000FEV!$O9 -> 0 | L9: =TONT20000MARS!$M9 -> 0 | M9: =TONT20000MARS!$N9 -> 0 | N9: =TONT20000MARS!$O9 -> 0 | O9: =TONT20000AVRIL!$M9 -> 0 | P9: =TONT20000AVRIL!$N9 -> 0 | Q9: =TONT20000AVRIL!$O9 -> 0 | R9: =TONT20000MAI!$M9 -> 0 | S9: =TONT20000MAI!$N9 -> 0 | T9: =TONT20000MAI!$O9 -> 0 | U9: =TONT20000JUIN!$M9 -> 0 | V9: =TONT20000JUIN!$N9 -> 0 | W9: =TONT20000JUIN!$O9 -> 0 | X9: =TONT20000JUIL!$M9 -> 0 | Y9: =TONT20000JUIL!$N9 -> 0 | Z9: =TONT20000JUIL!$O9 -> 0 | AA9: =TONT20000AOUT!$M9 -> 100000 | AB9: =TONT20000AOUT!$N9 -> 3000 | AC9: =TONT20000AOUT!$O9 -> 0 | AD9: =TONT20000SEPT!$M9 -> 0 | AE9: =TONT20000SEPT!$N9 -> 0 | AF9: =TONT20000SEPT!$O9 -> 0 | AG9: =TONT20000OCT!$M9 -> 0 | AH9: =TONT20000OCT!$N9 -> 0 | AI9: =TONT20000OCT!$O9 -> 0 | AJ9: =TONT20000NOV!$N9 -> 100000 | AK9: =TONT20000NOV!$O9 -> 3000 | AL9: =TONT20000NOV!$P9 -> 0
A10: AS201605 | B10: =VLOOKUP(A10,LISTADHERENT!A$5:H$51,2) -> DJOUKWE GUY | C10: =TONT20000DEC2015!$O10 -> 0 | D10: =TONT20000DEC2015!$P10 -> 0 | E10: =TONT20000DEC2015!$Q10 -> 0 | F10: =TONT20000JANV!$M10 -> 0 | G10: =TONT20000JANV!$N10 -> 0 | H10: =TONT20000JANV!$O10 -> 0 | I10: =TONT20000FEV!$M10 -> 250000 | J10: =TONT20000FEV!$N10 -> 7500 | K10: =TONT20000FEV!$O10 -> 0 | L10: =TONT20000MARS!$M10 -> 0 | M10: =TONT20000MARS!$N10 -> 0 | N10: =TONT20000MARS!$O10 -> 0 | O10: =TONT20000AVRIL!$M10 -> 0 | P10: =TONT20000AVRIL!$N10 -> 0 | Q10: =TONT20000AVRIL!$O10 -> 0 | R10: =TONT20000MAI!$M10 -> 0 | S10: =TONT20000MAI!$N10 -> 0 | T10: =TONT20000MAI!$O10 -> 0 | U10: =TONT20000JUIN!$M10 -> 0 | V10: =TONT20000JUIN!$N10 -> 0 | W10: =TONT20000JUIN!$O10 -> 0 | X10: =TONT20000JUIL!$M10 -> 0 | Y10: =TONT20000JUIL!$N10 -> 0 | Z10: =TONT20000JUIL!$O10 -> 0 | AA10: =TONT20000AOUT!$M10 -> 0 | AB10: =TONT20000AOUT!$N10 -> 0 | AC10: =TONT20000AOUT!$O10 -> 0 | AD10: =TONT20000SEPT!$M10 -> 0 | AE10: =TONT20000SEPT!$N10 -> 0 | AF10: =TONT20000SEPT!$O10 -> 0 | AG10: =TONT20000OCT!$M10 -> 0 | AH10: =TONT20000OCT!$N10 -> 0 | AI10: =TONT20000OCT!$O10 -> 0 | AJ10: =TONT20000NOV!$N10 -> 0 | AK10: =TONT20000NOV!$O10 -> 0 | AL10: =TONT20000NOV!$P10 -> 0
A11: AS201606 | B11: =VLOOKUP(A11,LISTADHERENT!A$5:H$51,2) -> DJOSSEU JOSUE | C11: =TONT20000DEC2015!$O11 -> 0 | D11: =TONT20000DEC2015!$P11 -> 0 | E11: =TONT20000DEC2015!$Q11 -> 0 | F11: =TONT20000JANV!$M11 -> 0 | G11: =TONT20000JANV!$N11 -> 0 | H11: =TONT20000JANV!$O11 -> 0 | I11: =TONT20000FEV!$M11 -> 0 | J11: =TONT20000FEV!$N11 -> 0 | K11: =TONT20000FEV!$O11 -> 0 | L11: =TONT20000MARS!$M11 -> 0 | M11: =TONT20000MARS!$N11 -> 0 | N11: =TONT20000MARS!$O11 -> 0 | O11: =TONT20000AVRIL!$M11 -> 0 | P11: =TONT20000AVRIL!$N11 -> 0 | Q11: =TONT20000AVRIL!$O11 -> 0 | R11: =TONT20000MAI!$M11 -> 0 | S11: =TONT20000MAI!$N11 -> 0 | T11: =TONT20000MAI!$O11 -> 0 | U11: =TONT20000JUIN!$M11 -> 0 | V11: =TONT20000JUIN!$N11 -> 0 | W11: =TONT20000JUIN!$O11 -> 0 | X11: =TONT20000JUIL!$M11 -> 0 | Y11: =TONT20000JUIL!$N11 -> 0 | Z11: =TONT20000JUIL!$O11 -> 0 | AA11: =TONT20000AOUT!$M11 -> 0 | AB11: =TONT20000AOUT!$N11 -> 0 | AC11: =TONT20000AOUT!$O11 -> 0 | AD11: =TONT20000SEPT!$M11 -> 0 | AE11: =TONT20000SEPT!$N11 -> 0 | AF11: =TONT20000SEPT!$O11 -> 0 | AG11: =TONT20000OCT!$M11 -> 0 | AH11: =TONT20000OCT!$N11 -> 0 | AI11: =TONT20000OCT!$O11 -> 0 | AJ11: =TONT20000NOV!$N11 -> 0 | AK11: =TONT20000NOV!$O11 -> 0 | AL11: =TONT20000NOV!$P11 -> 0
A12: AS201607 | B12: =VLOOKUP(A12,LISTADHERENT!A$5:H$51,2) -> DJOUNKEP SAMUEL | C12: =TONT20000DEC2015!$O12 -> 0 | D12: =TONT20000DEC2015!$P12 -> 0 | E12: =TONT20000DEC2015!$Q12 -> 0 | F12: =TONT20000JANV!$M12 -> 0 | G12: =TONT20000JANV!$N12 -> 0 | H12: =TONT20000JANV!$O12 -> 0 | I12: =TONT20000FEV!$M12 -> 0 | J12: =TONT20000FEV!$N12 -> 0 | K12: =TONT20000FEV!$O12 -> 0 | L12: =TONT20000MARS!$M12 -> 0 | M12: =TONT20000MARS!$N12 -> 0 | N12: =TONT20000MARS!$O12 -> 0 | O12: =TONT20000AVRIL!$M12 -> 0 | P12: =TONT20000AVRIL!$N12 -> 0 | Q12: =TONT20000AVRIL!$O12 -> 0 | R12: =TONT20000MAI!$M12 -> 0 | S12: =TONT20000MAI!$N12 -> 0 | T12: =TONT20000MAI!$O12 -> 0 | U12: =TONT20000JUIN!$M12 -> 0 | V12: =TONT20000JUIN!$N12 -> 0 | W12: =TONT20000JUIN!$O12 -> 0 | X12: =TONT20000JUIL!$M12 -> 0 | Y12: =TONT20000JUIL!$N12 -> 0 | Z12: =TONT20000JUIL!$O12 -> 0 | AA12: =TONT20000AOUT!$M12 -> 0 | AB12: =TONT20000AOUT!$N12 -> 0 | AC12: =TONT20000AOUT!$O12 -> 0 | AD12: =TONT20000SEPT!$M12 -> 0 | AE12: =TONT20000SEPT!$N12 -> 0 | AF12: =TONT20000SEPT!$O12 -> 0 | AG12: =TONT20000OCT!$M12 -> 0 | AH12: =TONT20000OCT!$N12 -> 0 | AI12: =TONT20000OCT!$O12 -> 0 | AJ12: =TONT20000NOV!$N12 -> 0 | AK12: =TONT20000NOV!$O12 -> 0 | AL12: =TONT20000NOV!$P12 -> 0
A13: AS201608 | B13: =VLOOKUP(A13,LISTADHERENT!A$5:H$51,2) -> DJUOMBESSY ANTOINE | C13: =TONT20000DEC2015!$O13 -> 0 | D13: =TONT20000DEC2015!$P13 -> 0 | E13: =TONT20000DEC2015!$Q13 -> 0 | F13: =TONT20000JANV!$M13 -> 0 | G13: =TONT20000JANV!$N13 -> 0 | H13: =TONT20000JANV!$O13 -> 0 | I13: =TONT20000FEV!$M13 -> 0 | J13: =TONT20000FEV!$N13 -> 0 | K13: =TONT20000FEV!$O13 -> 0 | L13: =TONT20000MARS!$M13 -> 0 | M13: =TONT20000MARS!$N13 -> 0 | N13: =TONT20000MARS!$O13 -> 0 | O13: =TONT20000AVRIL!$M13 -> 0 | P13: =TONT20000AVRIL!$N13 -> 0 | Q13: =TONT20000AVRIL!$O13 -> 0 | R13: =TONT20000MAI!$M13 -> 0 | S13: =TONT20000MAI!$N13 -> 0 | T13: =TONT20000MAI!$O13 -> 0 | U13: =TONT20000JUIN!$M13 -> 0 | V13: =TONT20000JUIN!$N13 -> 0 | W13: =TONT20000JUIN!$O13 -> 0 | X13: =TONT20000JUIL!$M13 -> 0 | Y13: =TONT20000JUIL!$N13 -> 0 | Z13: =TONT20000JUIL!$O13 -> 0 | AA13: =TONT20000AOUT!$M13 -> 700000 | AB13: =TONT20000AOUT!$N13 -> 84000 | AC13: =TONT20000AOUT!$O13 -> 0 | AD13: =TONT20000SEPT!$M13 -> 0 | AE13: =TONT20000SEPT!$N13 -> 0 | AF13: =TONT20000SEPT!$O13 -> 0 | AG13: =TONT20000OCT!$M13 -> 0 | AH13: =TONT20000OCT!$N13 -> 0 | AI13: =TONT20000OCT!$O13 -> 0 | AJ13: =TONT20000NOV!$N13 -> 0 | AK13: =TONT20000NOV!$O13 -> 0 | AL13: =TONT20000NOV!$P13 -> 0
A14: AS201609 | B14: =VLOOKUP(A14,LISTADHERENT!A$5:H$51,2) -> DONHOU DAVID | C14: =TONT20000DEC2015!$O14 -> 0 | D14: =TONT20000DEC2015!$P14 -> 0 | E14: =TONT20000DEC2015!$Q14 -> 0 | F14: =TONT20000JANV!$M14 -> 0 | G14: =TONT20000JANV!$N14 -> 0 | H14: =TONT20000JANV!$O14 -> 0 | I14: =TONT20000FEV!$M14 -> 0 | J14: =TONT20000FEV!$N14 -> 0 | K14: =TONT20000FEV!$O14 -> 0 | L14: =TONT20000MARS!$M14 -> 0 | M14: =TONT20000MARS!$N14 -> 0 | N14: =TONT20000MARS!$O14 -> 0 | O14: =TONT20000AVRIL!$M14 -> 0 | P14: =TONT20000AVRIL!$N14 -> 0 | Q14: =TONT20000AVRIL!$O14 -> 0 | R14: =TONT20000MAI!$M14 -> 0 | S14: =TONT20000MAI!$N14 -> 0 | T14: =TONT20000MAI!$O14 -> 0 | U14: =TONT20000JUIN!$M14 -> 0 | V14: =TONT20000JUIN!$N14 -> 0 | W14: =TONT20000JUIN!$O14 -> 0 | X14: =TONT20000JUIL!$M14 -> 0 | Y14: =TONT20000JUIL!$N14 -> 0 | Z14: =TONT20000JUIL!$O14 -> 0 | AA14: =TONT20000AOUT!$M14 -> 0 | AB14: =TONT20000AOUT!$N14 -> 0 | AC14: =TONT20000AOUT!$O14 -> 0 | AD14: =TONT20000SEPT!$M14 -> 0 | AE14: =TONT20000SEPT!$N14 -> 0 | AF14: =TONT20000SEPT!$O14 -> 0 | AG14: =TONT20000OCT!$M14 -> 0 | AH14: =TONT20000OCT!$N14 -> 0 | AI14: =TONT20000OCT!$O14 -> 0 | AJ14: =TONT20000NOV!$N14 -> 0 | AK14: =TONT20000NOV!$O14 -> 0 | AL14: =TONT20000NOV!$P14 -> 0
A15: AS201610 | B15: =VLOOKUP(A15,LISTADHERENT!A$5:H$51,2) -> FOTSO THOMAS | C15: =TONT20000DEC2015!$O15 -> 0 | D15: =TONT20000DEC2015!$P15 -> 0 | E15: =TONT20000DEC2015!$Q15 -> 0 | F15: =TONT20000JANV!$M15 -> 0 | G15: =TONT20000JANV!$N15 -> 0 | H15: =TONT20000JANV!$O15 -> 0 | I15: =TONT20000FEV!$M15 -> 0 | J15: =TONT20000FEV!$N15 -> 0 | K15: =TONT20000FEV!$O15 -> 0 | L15: =TONT20000MARS!$M15 -> 0 | M15: =TONT20000MARS!$N15 -> 0 | N15: =TONT20000MARS!$O15 -> 0 | O15: =TONT20000AVRIL!$M15 -> 1000000 | P15: =TONT20000AVRIL!$N15 -> 120000 | Q15: =TONT20000AVRIL!$O15 -> 0 | R15: =TONT20000MAI!$M15 -> 0 | S15: =TONT20000MAI!$N15 -> 0 | T15: =TONT20000MAI!$O15 -> 0 | U15: =TONT20000JUIN!$M15 -> 0 | V15: =TONT20000JUIN!$N15 -> 0 | W15: =TONT20000JUIN!$O15 -> 0 | X15: =TONT20000JUIL!$M15 -> 0 | Y15: =TONT20000JUIL!$N15 -> 0 | Z15: =TONT20000JUIL!$O15 -> 0 | AA15: =TONT20000AOUT!$M15 -> 0 | AB15: =TONT20000AOUT!$N15 -> 0 | AC15: =TONT20000AOUT!$O15 -> 0 | AD15: =TONT20000SEPT!$M15 -> 0 | AE15: =TONT20000SEPT!$N15 -> 0 | AF15: =TONT20000SEPT!$O15 -> 0 | AG15: =TONT20000OCT!$M15 -> 0 | AH15: =TONT20000OCT!$N15 -> 0 | AI15: =TONT20000OCT!$O15 -> 0 | AJ15: =TONT20000NOV!$N15 -> 0 | AK15: =TONT20000NOV!$O15 -> 0 | AL15: =TONT20000NOV!$P15 -> 0
A16: AS201611 | B16: =VLOOKUP(A16,LISTADHERENT!A$5:H$51,2) -> HENGUE PAUL OMER | C16: =TONT20000DEC2015!$O16 -> 0 | D16: =TONT20000DEC2015!$P16 -> 0 | E16: =TONT20000DEC2015!$Q16 -> 0 | F16: =TONT20000JANV!$M16 -> 0 | G16: =TONT20000JANV!$N16 -> 0 | H16: =TONT20000JANV!$O16 -> 0 | I16: =TONT20000FEV!$M16 -> 0 | J16: =TONT20000FEV!$N16 -> 0 | K16: =TONT20000FEV!$O16 -> 0 | L16: =TONT20000MARS!$M16 -> 0 | M16: =TONT20000MARS!$N16 -> 0 | N16: =TONT20000MARS!$O16 -> 0 | O16: =TONT20000AVRIL!$M16 -> 0 | P16: =TONT20000AVRIL!$N16 -> 0 | Q16: =TONT20000AVRIL!$O16 -> 0 | R16: =TONT20000MAI!$M16 -> 0 | S16: =TONT20000MAI!$N16 -> 0 | T16: =TONT20000MAI!$O16 -> 0 | U16: =TONT20000JUIN!$M16 -> 0 | V16: =TONT20000JUIN!$N16 -> 0 | W16: =TONT20000JUIN!$O16 -> 0 | X16: =TONT20000JUIL!$M16 -> 0 | Y16: =TONT20000JUIL!$N16 -> 0 | Z16: =TONT20000JUIL!$O16 -> 0 | AA16: =TONT20000AOUT!$M16 -> 0 | AB16: =TONT20000AOUT!$N16 -> 0 | AC16: =TONT20000AOUT!$O16 -> 0 | AD16: =TONT20000SEPT!$M16 -> 0 | AE16: =TONT20000SEPT!$N16 -> 0 | AF16: =TONT20000SEPT!$O16 -> 0 | AG16: =TONT20000OCT!$M16 -> 0 | AH16: =TONT20000OCT!$N16 -> 0 | AI16: =TONT20000OCT!$O16 -> 0 | AJ16: =TONT20000NOV!$N16 -> 0 | AK16: =TONT20000NOV!$O16 -> 0 | AL16: =TONT20000NOV!$P16 -> 0
A17: AS201612 | B17: =VLOOKUP(A17,LISTADHERENT!A$5:H$51,2) -> HODIEP JULES | C17: =TONT20000DEC2015!$O17 -> 0 | D17: =TONT20000DEC2015!$P17 -> 0 | E17: =TONT20000DEC2015!$Q17 -> 0 | F17: =TONT20000JANV!$M17 -> 0 | G17: =TONT20000JANV!$N17 -> 0 | H17: =TONT20000JANV!$O17 -> 0 | I17: =TONT20000FEV!$M17 -> 0 | J17: =TONT20000FEV!$N17 -> 0 | K17: =TONT20000FEV!$O17 -> 0 | L17: =TONT20000MARS!$M17 -> 0 | M17: =TONT20000MARS!$N17 -> 0 | N17: =TONT20000MARS!$O17 -> 0 | O17: =TONT20000AVRIL!$M17 -> 0 | P17: =TONT20000AVRIL!$N17 -> 0 | Q17: =TONT20000AVRIL!$O17 -> 0 | R17: =TONT20000MAI!$M17 -> 0 | S17: =TONT20000MAI!$N17 -> 0 | T17: =TONT20000MAI!$O17 -> 0 | U17: =TONT20000JUIN!$M17 -> 0 | V17: =TONT20000JUIN!$N17 -> 0 | W17: =TONT20000JUIN!$O17 -> 0 | X17: =TONT20000JUIL!$M17 -> 0 | Y17: =TONT20000JUIL!$N17 -> 0 | Z17: =TONT20000JUIL!$O17 -> 0 | AA17: =TONT20000AOUT!$M17 -> 0 | AB17: =TONT20000AOUT!$N17 -> 0 | AC17: =TONT20000AOUT!$O17 -> 0 | AD17: =TONT20000SEPT!$M17 -> 0 | AE17: =TONT20000SEPT!$N17 -> 0 | AF17: =TONT20000SEPT!$O17 -> 0 | AG17: =TONT20000OCT!$M17 -> 0 | AH17: =TONT20000OCT!$N17 -> 0 | AI17: =TONT20000OCT!$O17 -> 0 | AJ17: =TONT20000NOV!$N17 -> 0 | AK17: =TONT20000NOV!$O17 -> 0 | AL17: =TONT20000NOV!$P17 -> 0
A18: AS201613 | B18: =VLOOKUP(A18,LISTADHERENT!A$5:H$51,2) -> HOTCHO BENJAMIN | C18: =TONT20000DEC2015!$O18 -> 0 | D18: =TONT20000DEC2015!$P18 -> 0 | E18: =TONT20000DEC2015!$Q18 -> 0 | F18: =TONT20000JANV!$M18 -> 0 | G18: =TONT20000JANV!$N18 -> 0 | H18: =TONT20000JANV!$O18 -> 0 | I18: =TONT20000FEV!$M18 -> 0 | J18: =TONT20000FEV!$N18 -> 0 | K18: =TONT20000FEV!$O18 -> 0 | L18: =TONT20000MARS!$M18 -> 0 | M18: =TONT20000MARS!$N18 -> 0 | N18: =TONT20000MARS!$O18 -> 0 | O18: =TONT20000AVRIL!$M18 -> 0 | P18: =TONT20000AVRIL!$N18 -> 0 | Q18: =TONT20000AVRIL!$O18 -> 0 | R18: =TONT20000MAI!$M18 -> 0 | S18: =TONT20000MAI!$N18 -> 0 | T18: =TONT20000MAI!$O18 -> 0 | U18: =TONT20000JUIN!$M18 -> 0 | V18: =TONT20000JUIN!$N18 -> 0 | W18: =TONT20000JUIN!$O18 -> 0 | X18: =TONT20000JUIL!$M18 -> 0 | Y18: =TONT20000JUIL!$N18 -> 0 | Z18: =TONT20000JUIL!$O18 -> 0 | AA18: =TONT20000AOUT!$M18 -> 0 | AB18: =TONT20000AOUT!$N18 -> 0 | AC18: =TONT20000AOUT!$O18 -> 0 | AD18: =TONT20000SEPT!$M18 -> 0 | AE18: =TONT20000SEPT!$N18 -> 0 | AF18: =TONT20000SEPT!$O18 -> 0 | AG18: =TONT20000OCT!$M18 -> 0 | AH18: =TONT20000OCT!$N18 -> 0 | AI18: =TONT20000OCT!$O18 -> 0 | AJ18: =TONT20000NOV!$N18 -> 0 | AK18: =TONT20000NOV!$O18 -> 0 | AL18: =TONT20000NOV!$P18 -> 0
... A52: AS201647 | B52: =VLOOKUP(A52,LISTADHERENT!A$5:H$51,2) -> YOUMBI EMMANUEL | C52: =TONT20000DEC2015!$O52 -> 0 | D52: =TONT20000DEC2015!$P52 -> 0 | E52: =TONT20000DEC2015!$Q52 -> 0 | F52: =TONT20000JANV!$M52 -> 0 | G52: =TONT20000JANV!$N52 -> 0 | H52: =TONT20000JANV!$O52 -> 0 | I52: =TONT20000FEV!$M52 -> 0 | J52: =TONT20000FEV!$N52 -> 0 | K52: =TONT20000FEV!$O52 -> 0 | L52: =TONT20000MARS!$M52 -> 0 | M52: =TONT20000MARS!$N52 -> 0 | N52: =TONT20000MARS!$O52 -> 0 | O52: =TONT20000AVRIL!$M52 -> 0 | P52: =TONT20000AVRIL!$N52 -> 0 | Q52: =TONT20000AVRIL!$O52 -> 0 | R52: =TONT20000MAI!$M52 -> 0 | S52: =TONT20000MAI!$N52 -> 0 | T52: =TONT20000MAI!$O52 -> 0 | U52: =TONT20000JUIN!$M52 -> 0 | V52: =TONT20000JUIN!$N52 -> 0 | W52: =TONT20000JUIN!$O52 -> 0 | X52: =TONT20000JUIL!$M52 -> 0 | Y52: =TONT20000JUIL!$N52 -> 0 | Z52: =TONT20000JUIL!$O52 -> 0 | AA52: =TONT20000AOUT!$M52 -> 0 | AB52: =TONT20000AOUT!$N52 -> 0 | AC52: =TONT20000AOUT!$O52 -> 0 | AD52: =TONT20000SEPT!$M52 -> 0 | AE52: =TONT20000SEPT!$N52 -> 0 | AF52: =TONT20000SEPT!$O52 -> 0 | AG52: =TONT20000OCT!$M52 -> 0 | AH52: =TONT20000OCT!$N52 -> 0 | AI52: =TONT20000OCT!$O52 -> 0 | AJ52: =TONT20000NOV!$N52 -> 0 | AK52: =TONT20000NOV!$O52 -> 0 | AL52: =TONT20000NOV!$P52 -> 0
B54: REMBOURSEMENT INTERET
A56: TOTAL | C56: =SUM(C5:C52) -> 1500000 | D56: =SUM(D5:D52) -> 99000 | E56: =SUM(E5:E52) -> 0 | F56: =SUM(F5:F52) -> 2200000 | G56: =SUM(G5:G52) -> 186000 | H56: =SUM(H5:H52) -> 0 | I56: =SUM(I5:I52) -> 750000 | J56: =SUM(J5:J52) -> 22500 | ... AL56: =SUM(AL5:AL52) -> 2070000
C58: =G56+D56+J56+M56+P56+S56+V56+Y56+AB56+AE56+AH56+AK56 -> 2282100

Sheet LISTADHERENT
A1: ASELBY
A2: LISTE DES ADHERENTS 19 JUN 2016
A4: MLE | B4: NOM ET PRENOM | C4: FONCTION | D4: DATE ADHESION | E4: CONTACT | F4: CONTACT 2 | G4: RESIDENCE | H4: DATE RECEPTION
A5: AS201601 | B5: BAKOP ACHILLE | C5: FONCTIONNAIRE DE POLICE | E5: 677841881 | G5: NKOLBISSON | H5: 42887
A6: AS201602 | B6: BOUTCHOUANG WILLIAM | C6: OPERATEUR ECONOMIQUE | E6: 677704694 | G6: EMANA | H6: 43191
A7: AS201603 | B7: CHINGUE FABRICE | C7: OPERATEUR ECONOMIQUE | E7: 677881912 | G7: SANTA BARBARA | H7: 43466
A8: AS201604 | B8: DJOMO JEAN PAUL | C8: RETRAITE | E8: 677986676 | G8: RUE MANGUIERS | H8: 43132
A9: AS201605 | B9: DJOUKWE GUY | C9: PROFESSEUR DES LYCEES TECHNIQUE | E9: 675250451 | G9: RUE MANGUIERS | H9: 43313
A10: AS201606 | B10: DJOSSEU JOSUE | C10: PROFESSEUR DES LYCEES TECHNIQUE | E10: 675250451 | G10: RUE MANGUIERS | H10: 43313
A11: AS201607 | B11: DJOUNKEP SAMUEL | C11: COMPTABLE RETRAITE | E11: 697103557 | G11: BIYEM ASSI LYCEE | H11: 42401
A12: AS201608 | B12: DJUOMBESSY ANTOINE | C12: ANALYSTE CONCEPTEUR SI | E12: 677501239 | F12: 699324095 | G12: MESSASSI | H12: 43647
A13: AS201609 | B13: DONHOU DAVID | C13: MAGISTRAT | E13: 699908065 | G13: TONGOLO | H13: 42979
A14: AS201610 | B14: FOTSO THOMAS | C14: CADRE BANQUE | E14: 677910278 | G14: OYOMABANG | H14: 43344
A15: AS201611 | B15: HENGUE PAUL OMER | C15: SOCIOLOGUE | E15: 694468080 | G15: MESSASSI | H15: 42583
A16: AS201612 | B16: HODIEP JULES | C16: CADRE CNPS | E16: 675291170 | G16: NYOM 2 | H16: 43009
A17: AS201613 | B17: HOTCHO BENJAMIN | C17: COMPTABLE | E17: 699956355 | G17: DAMAS | H17: 42614
A18: AS201614 | B18: KEPHE DAVID | C18: OPERATEUR ECONOMIQUE | E18: 677053815 | G18: MESSASSI | H18: 43374
A19: AS201615 | B19: KEPSEU FRANCIS | C19: OFFICIER DE POLICE RETRAITE | E19: 699528700 | G19: SIMBOCK | H19: 43405
A20: AS201616 | B20: KOUAMOU EMMANUEL | C20: OPERATEUR ECONOMIQUE | E20: 699335584 | G20: MONTEE JOUVENCE | H20: 42795
A21: AS201617 | B21: KOUAMOU MOISE | C21: INGENIEUR E-F | E21: 675836725 | G21: DAMAS | H21: 42370
A22: AS201618 | B22: KOUAMOU VICTOR PEGUY | C22: S/OFFICIER SUPERIEUR | E22: 696564847 | G22: MESSASSI | H22: 43617
A23: AS201619 | B23: KOUATCHO MESSACK | C23: INSPECTEUR DE TRAVAIL | E23: 677735778 | G23: SANTA BARBARA | H23: 42644
A24: AS201620 | B24: LOWE JEAN | C24: PROFESSEUR DE LYCEE
A25: AS201621 | B25: NANKAM APPOLINAIRE | C25: ENSEIGNANT | E25: 693055118 | G25: DAMAS | H25: 43678
A26: AS201622 | B26: NDJOMO ETIENNE | C26: COMPTABLE | E26: 677553702 | G26: MONTEE JOUVENCE | H26: 42705
A27: AS201623 | B27: NDOMBOU JEAN CLAUDE | C27: ING AGRONOME RETRAITE | E27: 699358350 | G27: ETOUG EBE | H27: 42767
A28: AS201624 | B28: NGONDIEP CLAUDE | C28: DAS(DIRECTEUR ADMINISTRATEUR SOCIETE) | E28: 675249207 | G28: CITE VERTE | H28: 43070
A29: AS201625 | B29: NGONGANG JEAN THEODORE | C29: CHEF ENTREPRISE | E29: 677766503 | G29: RUE MANGUIERS | H29: 42491
A30: AS201626 | B30: NGUIEMEGNI MATHIEU BLAISE | C30: CADRE CADASTRE | E30: 677068360 | G30: MONATELE | H30: 43101
A31: AS201627 | B31: NJEPDJIO MBOUKAM DELUXE | C31: OPERATEUR ECONOMIQUE | E31: 670909070 | G31: MENDONG | H31: 43586
A32: AS201628 | B32: NKAMGANG JUSTIN DEJOLIE | C32: DELEGUE COMMERCIAL | E32: 676659191 | G32: MENDONG | H32: 43497
A33: AS201629 | B33: NKEPSEU DIEUDONNE | C33: OPERATEUR ECONOMIQUE | E33: 677575366 | G33: ESSOS | H33: 42917
A34: AS201630 | B34: NKEPSEU HENANG RENE | C34: CADRE SONEL RETRAITE | E34: 699843118 | G34: BIYEM ASSI LYCEE | H34: 42522
A35: AS201631 | B35: NTEPDIE TUEMAC MZ | C35: OPERATEUR ECONOMIQUE | E35: 677377251 | G35: MONTEE JOUVENCE | H35: 43282
A36: AS201632 | B36: NTOMBOU ADOLPHE | C36: INGENIEUR | E36: 677867173 | G36: BIYEM ASSI LYCEE | H36: 42461
... A51: AS201647 | B51: YOUMBI EMMANUEL | C51: PROFESSEUR DES UNIVERSITES | E51: 677547311 | G51: MENDONG (GUINNESS) | H51: 42675
A52: AS201648 | B52: ASELBY | C52: ASSOCIATION DES ELITES BANGOU DE YAOUNDE

Sheet TRAVAUXINVENTAIREBACKUP
A1: ASSOCIATION | B1: ASELBY
A2: ANNEE | B2: 2016/2017
A3: TONTINE | B3: 20 000
A4: MATRICULE | B4: NOM ET PRENOM | C4: FONDS DE CAISSE | D4: RELIQUAT 2015 | E4: CAPITAL DEPART | F4: REPARTITION INTERET | G4: CAPITAL COMPOSE FIN | H4: CAPITAL TOTAL A PERCEVOIR | I4: RETENUE | J4: CAPITAL A DISTRIBUER | K4: COMPLEMENT FONDS | L4: SANCTION | M4: RETOUR EN CAISSE MUTUELLE | N4: FRAIS FIXE A PRELEVER | O4: MONTANT VERSE | P4: EPARGNE | Q4: FONDS DE ROULEMENT | R4: FRAIS EXCEPTIONNEL | S4: COLLATION | T4: MUTUELLE | U4: TONTINE | V4: EMPRUNT | W4: INTERET EMPRUNT | X4: REMBOURSEMENT | Y4: PENALITE EMPRUNT | Z4: PENALITE FONDS | AA4: INTERET ACHAT | AB4: DATE ACHAT
A5: AS201648 | B5: =VLOOKUP(A5,LISTADHERENT!A$5:H$52,2,0) -> ASELBY | C5: =VLOOKUP(A5,FONDSDECAISSE!A$5:C$52,3,0) -> 0 | D5: 318145 | E5: =C5+D5+P5 -> 318145 | F5: =TONT20000DEC2015!E5+TONT20000JANV!C5+TONT20000FEV!C5+TONT20000MARS!C5+TONT20000AVRIL!C5+TONT20000MAI!C5+TONT20000JUIN!C5+TONT20000JUIL!C5+TONT20000AOUT!C5+TONT20000SEPT!C5+TONT20000OCT!C5+TONT20000NOV!C5 -> 36952.515 | G5: =TONT20000NOV!E5 -> 355097.52 | H5: =D5+F5+P5 -> 355097.52 | I5: =K5+L5+M5+N5 -> 0 | J5: =H5-I5 -> 355097.52 | O5: =TONT20000DEC2015!H5+TONT20000JANV!F5+TONT20000FEV!F5+TONT20000MARS!F5+TONT20000AVRIL!F5+TONT20000MAI!F5+TONT20000JUIN!F5+TONT20000JUIL!F5+TONT20000AOUT!F5+TONT20000SEPT!F5+TONT20000OCT!F5+TONT20000NOV!G5 -> 0 | P5: =TONT20000DEC2015!I5+TONT20000JANV!G5+TONT20000FEV!G5+TONT20000MARS!G5+TONT20000AVRIL!G5+TONT20000MAI!G5+TONT20000JUIN!G5+TONT20000JUIL!G5+TONT20000AOUT!G5+TONT20000SEPT!G5+TONT20000OCT!G5+TONT20000NOV!H5 -> 0 | Q5: =TONT20000DEC2015!J5+TONT20000JANV!H5+TONT20000FEV!H5+TONT20000MARS!H5+TONT20000AVRIL!H5+TONT20000MAI!H5+TONT20000JUIN!H5+TONT20000JUIL!H5+TONT20000AOUT!H5+TONT20000SEPT!H5+TONT20000OCT!H5+TONT20000NOV!I5 -> 0 | R5: =TONT20000DEC2015!K5+TONT20000JANV!I5+TONT20000FEV!I5+TONT20000MARS!I5+TONT20000AVRIL!I5+TONT20000MAI!I5+TONT20000JUIN!I5+TONT20000JUIL!I5+TONT20000AOUT!I5+TONT20000SEPT!I5+TONT20000OCT!I5+TONT20000NOV!J5 -> 0 | S5: =TONT20000DEC2015!L5+TONT20000JANV!J5+TONT20000FEV!J5+TONT20000MARS!J5+TONT20000AVRIL!J5+TONT20000MAI!J5+TONT20000JUIN!J5+TONT20000JUIL!J5+TONT20000AOUT!J5+TONT20000SEPT!J5+TONT20000OCT!J5+TONT20000NOV!K5 -> 0 | T5: =TONT20000DEC2015!M5+TONT20000JANV!K5+TONT20000FEV!K5+TONT20000MARS!K5+TONT20000AVRIL!K5+TONT20000MAI!K5+TONT20000JUIN!K5+TONT20000JUIL!K5+TONT20000AOUT!K5+TONT20000SEPT!K5+TONT20000OCT!K5+TONT20000NOV!L5 -> 0 | U5: =TONT20000DEC2015!N5+TONT20000JANV!L5+TONT20000FEV!L5+TONT20000MARS!L5+TONT20000AVRIL!L5+TONT20000MAI!L5+TONT20000JUIN!L5+TONT20000JUIL!L5+TONT20000AOUT!L5+TONT20000SEPT!L5+TONT20000OCT!L5+TONT20000NOV!M5 -> 0 | V5: =TONT20000DEC2015!O5+TONT20000JANV!M5+TONT20000FEV!M5+TONT20000MARS!M5+TONT20000AVRIL!M5+TONT20000MAI!M5+TONT20000JUIN!M5+TONT20000JUIL!M5+TONT20000AOUT!M5+TONT20000SEPT!M5+TONT20000OCT!M5+TONT20000NOV!N5 -> 0 | ... AA5: =TONT20000DEC2015!T5+TONT20000JANV!R5+TONT20000FEV!R5+TONT20000MARS!R5+TONT20000AVRIL!R5+TONT20000MAI!R5+TONT20000JUIN!R5+TONT20000JUIL!R5+TONT20000AOUT!R5+TONT20000SEPT!R5+TONT20000OCT!R5+TONT20000NOV!S5 -> 0
A6: AS201601 | B6: =VLOOKUP(A6,LISTADHERENT!A$5:H$52,2,0) -> BAKOP ACHILLE | C6: =VLOOKUP(A6,FONDSDECAISSE!A$5:C$52,3,0) -> 390000 | D6: 33536 | E6: =C6+D6+P6 -> 453536 | F6: =TONT20000DEC2015!E6+TONT20000JANV!C6+TONT20000FEV!C6+TONT20000MARS!C6+TONT20000AVRIL!C6+TONT20000MAI!C6+TONT20000JUIN!C6+TONT20000JUIL!C6+TONT20000AOUT!C6+TONT20000SEPT!C6+TONT20000OCT!C6+TONT20000NOV!C6 -> 51457.983 | G6: =TONT20000NOV!E6 -> 504993.98 | H6: =D6+F6+P6 -> 114993.98 | I6: =K6+L6+M6+N6 -> 63000 | J6: =H6-I6 -> 51993.983 | K6: 30000 | M6: 25000 | N6: =48000-(Q6+R6+S6) -> 8000 | O6: =TONT20000DEC2015!H6+TONT20000JANV!F6+TONT20000FEV!F6+TONT20000MARS!F6+TONT20000AVRIL!F6+TONT20000MAI!F6+TONT20000JUIN!F6+TONT20000JUIL!F6+TONT20000AOUT!F6+TONT20000SEPT!F6+TONT20000OCT!F6+TONT20000NOV!G6 -> 225000 | P6: =TONT20000DEC2015!I6+TONT20000JANV!G6+TONT20000FEV!G6+TONT20000MARS!G6+TONT20000AVRIL!G6+TONT20000MAI!G6+TONT20000JUIN!G6+TONT20000JUIL!G6+TONT20000AOUT!G6+TONT20000SEPT!G6+TONT20000OCT!G6+TONT20000NOV!H6 -> 30000 | Q6: =TONT20000DEC2015!J6+TONT20000JANV!H6+TONT20000FEV!H6+TONT20000MARS!H6+TONT20000AVRIL!H6+TONT20000MAI!H6+TONT20000JUIN!H6+TONT20000JUIL!H6+TONT20000AOUT!H6+TONT20000SEPT!H6+TONT20000OCT!H6+TONT20000NOV!I6 -> 5000 | R6: =TONT20000DEC2015!K6+TONT20000JANV!I6+TONT20000FEV!I6+TONT20000MARS!I6+TONT20000AVRIL!I6+TONT20000MAI!I6+TONT20000JUIN!I6+TONT20000JUIL!I6+TONT20000AOUT!I6+TONT20000SEPT!I6+TONT20000OCT!I6+TONT20000NOV!J6 -> 10000 | S6: =TONT20000DEC2015!L6+TONT20000JANV!J6+TONT20000FEV!J6+TONT20000MARS!J6+TONT20000AVRIL!J6+TONT20000MAI!J6+TONT20000JUIN!J6+TONT20000JUIL!J6+TONT20000AOUT!J6+TONT20000SEPT!J6+TONT20000OCT!J6+TONT20000NOV!K6 -> 25000 | T6: =TONT20000DEC2015!M6+TONT20000JANV!K6+TONT20000FEV!K6+TONT20000MARS!K6+TONT20000AVRIL!K6+TONT20000MAI!K6+TONT20000JUIN!K6+TONT20000JUIL!K6+TONT20000AOUT!K6+TONT20000SEPT!K6+TONT20000OCT!K6+TONT20000NOV!L6 -> 25000 | U6: =TONT20000DEC2015!N6+TONT20000JANV!L6+TONT20000FEV!L6+TONT20000MARS!L6+TONT20000AVRIL!L6+TONT20000MAI!L6+TONT20000JUIN!L6+TONT20000JUIL!L6+TONT20000AOUT!L6+TONT20000SEPT!L6+TONT20000OCT!L6+TONT20000NOV!M6 -> 130000 | V6: =TONT20000DEC2015!O6+TONT20000JANV!M6+TONT20000FEV!M6+TONT20000MARS!M6+TONT20000AVRIL!M6+TONT20000MAI!M6+TONT20000JUIN!M6+TONT20000JUIL!M6+TONT20000AOUT!M6+TONT20000SEPT!M6+TONT20000OCT!M6+TONT20000NOV!N6 -> 500000 | ... AA6: =TONT20000DEC2015!T6+TONT20000JANV!R6+TONT20000FEV!R6+TONT20000MARS!R6+TONT20000AVRIL!R6+TONT20000MAI!R6+TONT20000JUIN!R6+TONT20000JUIL!R6+TONT20000AOUT!R6+TONT20000SEPT!R6+TONT20000OCT!R6+TONT20000NOV!S6 -> 0
A7: AS201602 | B7: =VLOOKUP(A7,LISTADHERENT!A$5:H$52,2,0) -> BOUTCHOUANG WILLIAM | C7: =VLOOKUP(A7,FONDSDECAISSE!A$5:C$52,3,0) -> 390000 | D7: 1704 | E7: =C7+D7+P7 -> 427704 | F7: =TONT20000DEC2015!E7+TONT20000JANV!C7+TONT20000FEV!C7+TONT20000MARS!C7+TONT20000AVRIL!C7+TONT20000MAI!C7+TONT20000JUIN!C7+TONT20000JUIL!C7+TONT20000AOUT!C7+TONT20000SEPT!C7+TONT20000OCT!C7+TONT20000NOV!C7 -> 48016.562 | G7: =TONT20000NOV!E7 -> 475720.56 | H7: =D7+F7+P7 -> 85720.562 | I7: =K7+L7+M7+N7 -> 80000 | J7: =H7-I7 -> 5720.5624 | K7: 30000 | M7: 50000 | N7: =48000-(Q7+R7+S7) -> 0 | O7: =TONT20000DEC2015!H7+TONT20000JANV!F7+TONT20000FEV!F7+TONT20000MARS!F7+TONT20000AVRIL!F7+TONT20000MAI!F7+TONT20000JUIN!F7+TONT20000JUIL!F7+TONT20000AOUT!F7+TONT20000SEPT!F7+TONT20000OCT!F7+TONT20000NOV!G7 -> 240000 | P7: =TONT20000DEC2015!I7+TONT20000JANV!G7+TONT20000FEV!G7+TONT20000MARS!G7+TONT20000AVRIL!G7+TONT20000MAI!G7+TONT20000JUIN!G7+TONT20000JUIL!G7+TONT20000AOUT!G7+TONT20000SEPT!G7+TONT20000OCT!G7+TONT20000NOV!H7 -> 36000 | Q7: =TONT20000DEC2015!J7+TONT20000JANV!H7+TONT20000FEV!H7+TONT20000MARS!H7+TONT20000AVRIL!H7+TONT20000MAI!H7+TONT20000JUIN!H7+TONT20000JUIL!H7+TONT20000AOUT!H7+TONT20000SEPT!H7+TONT20000OCT!H7+TONT20000NOV!I7 -> 6000 | R7: =TONT20000DEC2015!K7+TONT20000JANV!I7+TONT20000FEV!I7+TONT20000MARS!I7+TONT20000AVRIL!I7+TONT20000MAI!I7+TONT20000JUIN!I7+TONT20000JUIL!I7+TONT20000AOUT!I7+TONT20000SEPT!I7+TONT20000OCT!I7+TONT20000NOV!J7 -> 12000 | S7: =TONT20000DEC2015!L7+TONT20000JANV!J7+TONT20000FEV!J7+TONT20000MARS!J7+TONT20000AVRIL!J7+TONT20000MAI!J7+TONT20000JUIN!J7+TONT20000JUIL!J7+TONT20000AOUT!J7+TONT20000SEPT!J7+TONT20000OCT!J7+TONT20000NOV!K7 -> 30000 | T7: =TONT20000DEC2015!M7+TONT20000JANV!K7+TONT20000FEV!K7+TONT20000MARS!K7+TONT20000AVRIL!K7+TONT20000MAI!K7+TONT20000JUIN!K7+TONT20000JUIL!K7+TONT20000AOUT!K7+TONT20000SEPT!K7+TONT20000OCT!K7+TONT20000NOV!L7 -> 0 | U7: =TONT20000DEC2015!N7+TONT20000JANV!L7+TONT20000FEV!L7+TONT20000MARS!L7+TONT20000AVRIL!L7+TONT20000MAI!L7+TONT20000JUIN!L7+TONT20000JUIL!L7+TONT20000AOUT!L7+TONT20000SEPT!L7+TONT20000OCT!L7+TONT20000NOV!M7 -> 156000 | V7: =TONT20000DEC2015!O7+TONT20000JANV!M7+TONT20000FEV!M7+TONT20000MARS!M7+TONT20000AVRIL!M7+TONT20000MAI!M7+TONT20000JUIN!M7+TONT20000JUIL!M7+TONT20000AOUT!M7+TONT20000SEPT!M7+TONT20000OCT!M7+TONT20000NOV!N7 -> 1700000 | ... AA7: =TONT20000DEC2015!T7+TONT20000JANV!R7+TONT20000FEV!R7+TONT20000MARS!R7+TONT20000AVRIL!R7+TONT20000MAI!R7+TONT20000JUIN!R7+TONT20000JUIL!R7+TONT20000AOUT!R7+TONT20000SEPT!R7+TONT20000OCT!R7+TONT20000NOV!S7 -> 0
A8: AS201603 | B8: =VLOOKUP(A8,LISTADHERENT!A$5:H$52,2,0) -> CHINGUE FABRICE | C8: =VLOOKUP(A8,FONDSDECAISSE!A$5:C$52,3,0) -> 390000 | D8: 1842 | E8: =C8+D8+P8 -> 427842 | F8: =TONT20000DEC2015!E8+TONT20000JANV!C8+TONT20000FEV!C8+TONT20000MARS!C8+TONT20000AVRIL!C8+TONT20000MAI!C8+TONT20000JUIN!C8+TONT20000JUIL!C8+TONT20000AOUT!C8+TONT20000SEPT!C8+TONT20000OCT!C8+TONT20000NOV!C8 -> 48032.591 | G8: =TONT20000NOV!E8 -> 475874.59 | H8: =D8+F8+P8 -> 85874.591 | I8: =K8+L8+M8+N8 -> 80000 | J8: =H8-I8 -> 5874.591 | K8: 30000 | M8: 50000 | N8: =48000-(Q8+R8+S8) -> 0 | O8: =TONT20000DEC2015!H8+TONT20000JANV!F8+TONT20000FEV!F8+TONT20000MARS!F8+TONT20000AVRIL!F8+TONT20000MAI!F8+TONT20000JUIN!F8+TONT20000JUIL!F8+TONT20000AOUT!F8+TONT20000SEPT!F8+TONT20000OCT!F8+TONT20000NOV!G8 -> 240000 | P8: =TONT20000DEC2015!I8+TONT20000JANV!G8+TONT20000FEV!G8+TONT20000MARS!G8+TONT20000AVRIL!G8+TONT20000MAI!G8+TONT20000JUIN!G8+TONT20000JUIL!G8+TONT20000AOUT!G8+TONT20000SEPT!G8+TONT20000OCT!G8+TONT20000NOV!H8 -> 36000 | Q8: =TONT20000DEC2015!J8+TONT20000JANV!H8+TONT20000FEV!H8+TONT20000MARS!H8+TONT20000AVRIL!H8+TONT20000MAI!H8+TONT20000JUIN!H8+TONT20000JUIL!H8+TONT20000AOUT!H8+TONT20000SEPT!H8+TONT20000OCT!H8+TONT20000NOV!I8 -> 6000 | R8: =TONT20000DEC2015!K8+TONT20000JANV!I8+TONT20000FEV!I8+TONT20000MARS!I8+TONT20000AVRIL!I8+TONT20000MAI!I8+TONT20000JUIN!I8+TONT20000JUIL!I8+TONT20000AOUT!I8+TONT20000SEPT!I8+TONT20000OCT!I8+TONT20000NOV!J8 -> 12000 | S8: =TONT20000DEC2015!L8+TONT20000JANV!J8+TONT20000FEV!J8+TONT20000MARS!J8+TONT20000AVRIL!J8+TONT20000MAI!J8+TONT20000JUIN!J8+TONT20000JUIL!J8+TONT20000AOUT!J8+TONT20000SEPT!J8+TONT20000OCT!J8+TONT20000NOV!K8 -> 30000 | T8: =TONT20000DEC2015!M8+TONT20000JANV!K8+TONT20000FEV!K8+TONT20000MARS!K8+TONT20000AVRIL!K8+TONT20000MAI!K8+TONT20000JUIN!K8+TONT20000JUIL!K8+TONT20000AOUT!K8+TONT20000SEPT!K8+TONT20000OCT!K8+TONT20000NOV!L8 -> 0 | U8: =TONT20000DEC2015!N8+TONT20000JANV!L8+TONT20000FEV!L8+TONT20000MARS!L8+TONT20000AVRIL!L8+TONT20000MAI!L8+TONT20000JUIN!L8+TONT20000JUIL!L8+TONT20000AOUT!L8+TONT20000SEPT!L8+TONT20000OCT!L8+TONT20000NOV!M8 -> 156000 | V8: =TONT20000DEC2015!O8+TONT20000JANV!M8+TONT20000FEV!M8+TONT20000MARS!M8+TONT20000AVRIL!M8+TONT20000MAI!M8+TONT20000JUIN!M8+TONT20000JUIL!M8+TONT20000AOUT!M8+TONT20000SEPT!M8+TONT20000OCT!M8+TONT20000NOV!N8 -> 2000000 | ... AA8: =TONT20000DEC2015!T8+TONT20000JANV!R8+TONT20000FEV!R8+TONT20000MARS!R8+TONT20000AVRIL!R8+TONT20000MAI!R8+TONT20000JUIN!R8+TONT20000JUIL!R8+TONT20000AOUT!R8+TONT20000SEPT!R8+TONT20000OCT!R8+TONT20000NOV!S8 -> 0
A9: AS201604 | B9: =VLOOKUP(A9,LISTADHERENT!A$5:H$52,2,0) -> DJOMO JEAN PAUL | C9: =VLOOKUP(A9,FONDSDECAISSE!A$5:C$52,3,0) -> 390000 | D9: 8156 | E9: =C9+D9+P9 -> 441156 | F9: =TONT20000DEC2015!E9+TONT20000JANV!C9+TONT20000FEV!C9+TONT20000MARS!C9+TONT20000AVRIL!C9+TONT20000MAI!C9+TONT20000JUIN!C9+TONT20000JUIL!C9+TONT20000AOUT!C9+TONT20000SEPT!C9+TONT20000OCT!C9+TONT20000NOV!C9 -> 48914.356 | G9: =TONT20000NOV!E9 -> 490070.36 | H9: =D9+F9+P9 -> 100070.36 | I9: =K9+L9+M9+N9 -> 80000 | J9: =H9-I9 -> 20070.356 | K9: 30000 | M9: 50000 | N9: =48000-(Q9+R9+S9) -> 0 | O9: =TONT20000DEC2015!H9+TONT20000JANV!F9+TONT20000FEV!F9+TONT20000MARS!F9+TONT20000AVRIL!F9+TONT20000MAI!F9+TONT20000JUIN!F9+TONT20000JUIL!F9+TONT20000AOUT!F9+TONT20000SEPT!F9+TONT20000OCT!F9+TONT20000NOV!G9 -> 247000 | P9: =TONT20000DEC2015!I9+TONT20000JANV!G9+TONT20000FEV!G9+TONT20000MARS!G9+TONT20000AVRIL!G9+TONT20000MAI!G9+TONT20000JUIN!G9+TONT20000JUIL!G9+TONT20000AOUT!G9+TONT20000SEPT!G9+TONT20000OCT!G9+TONT20000NOV!H9 -> 43000 | Q9: =TONT20000DEC2015!J9+TONT20000JANV!H9+TONT20000FEV!H9+TONT20000MARS!H9+TONT20000AVRIL!H9+TONT20000MAI!H9+TONT20000JUIN!H9+TONT20000JUIL!H9+TONT20000AOUT!H9+TONT20000SEPT!H9+TONT20000OCT!H9+TONT20000NOV!I9 -> 6000 | R9: =TONT20000DEC2015!K9+TONT20000JANV!I9+TONT20000FEV!I9+TONT20000MARS!I9+TONT20000AVRIL!I9+TONT20000MAI!I9+TONT20000JUIN!I9+TONT20000JUIL!I9+TONT20000AOUT!I9+TONT20000SEPT!I9+TONT20000OCT!I9+TONT20000NOV!J9 -> 12000 | S9: =TONT20000DEC2015!L9+TONT20000JANV!J9+TONT20000FEV!J9+TONT20000MARS!J9+TONT20000AVRIL!J9+TONT20000MAI!J9+TONT20000JUIN!J9+TONT20000JUIL!J9+TONT20000AOUT!J9+TONT20000SEPT!J9+TONT20000OCT!J9+TONT20000NOV!K9 -> 30000 | T9: =TONT20000DEC2015!M9+TONT20000JANV!K9+TONT20000FEV!K9+TONT20000MARS!K9+TONT20000AVRIL!K9+TONT20000MAI!K9+TONT20000JUIN!K9+TONT20000JUIL!K9+TONT20000AOUT!K9+TONT20000SEPT!K9+TONT20000OCT!K9+TONT20000NOV!L9 -> 0 | U9: =TONT20000DEC2015!N9+TONT20000JANV!L9+TONT20000FEV!L9+TONT20000MARS!L9+TONT20000AVRIL!L9+TONT20000MAI!L9+TONT20000JUIN!L9+TONT20000JUIL!L9+TONT20000AOUT!L9+TONT20000SEPT!L9+TONT20000OCT!L9+TONT20000NOV!M9 -> 156000 | V9: =TONT20000DEC2015!O9+TONT20000JANV!M9+TONT20000FEV!M9+TONT20000MARS!M9+TONT20000AVRIL!M9+TONT20000MAI!M9+TONT20000JUIN!M9+TONT20000JUIL!M9+TONT20000AOUT!M9+TONT20000SEPT!M9+TONT20000OCT!M9+TONT20000NOV!N9 -> 200000 | ... AA9: =TONT20000DEC2015!T9+TONT20000JANV!R9+TONT20000FEV!R9+TONT20000MARS!R9+TONT20000AVRIL!R9+TONT20000MAI!R9+TONT20000JUIN!R9+TONT20000JUIL!R9+TONT20000AOUT!R9+TONT20000SEPT!R9+TONT20000OCT!R9+TONT20000NOV!S9 -> 0
A10: AS201605 | B10: =VLOOKUP(A10,LISTADHERENT!A$5:H$52,2,0) -> DJOUKWE GUY | C10: =VLOOKUP(A10,FONDSDECAISSE!A$5:C$52,3,0) -> 390000 | D10: 5905 | E10: =C10+D10+P10 -> 471905 | F10: =TONT20000DEC2015!E10+TONT20000JANV!C10+TONT20000FEV!C10+TONT20000MARS!C10+TONT20000AVRIL!C10+TONT20000MAI!C10+TONT20000JUIN!C10+TONT20000JUIL!C10+TONT20000AOUT!C10+TONT20000SEPT!C10+TONT20000OCT!C10+TONT20000NOV!C10 -> 51792.05 | G10: =TONT20000NOV!E10 -> 523697.05 | H10: =D10+F10+P10 -> 133697.05 | I10: =K10+L10+M10+N10 -> 80000 | J10: =H10-I10 -> 53697.05 | K10: 30000 | M10: 50000 | N10: =48000-(Q10+R10+S10) -> 0 | O10: =TONT20000DEC2015!H10+TONT20000JANV!F10+TONT20000FEV!F10+TONT20000MARS!F10+TONT20000AVRIL!F10+TONT20000MAI!F10+TONT20000JUIN!F10+TONT20000JUIL!F10+TONT20000AOUT!F10+TONT20000SEPT!F10+TONT20000OCT!F10+TONT20000NOV!G10 -> 280000 | P10: =TONT20000DEC2015!I10+TONT20000JANV!G10+TONT20000FEV!G10+TONT20000MARS!G10+TONT20000AVRIL!G10+TONT20000MAI!G10+TONT20000JUIN!G10+TONT20000JUIL!G10+TONT20000AOUT!G10+TONT20000SEPT!G10+TONT20000OCT!G10+TONT20000NOV!H10 -> 76000 | Q10: =TONT20000DEC2015!J10+TONT20000JANV!H10+TONT20000FEV!H10+TONT20000MARS!H10+TONT20000AVRIL!H10+TONT20000MAI!H10+TONT20000JUIN!H10+TONT20000JUIL!H10+TONT20000AOUT!H10+TONT20000SEPT!H10+TONT20000OCT!H10+TONT20000NOV!I10 -> 6000 | R10: =TONT20000DEC2015!K10+TONT20000JANV!I10+TONT20000FEV!I10+TONT20000MARS!I10+TONT20000AVRIL!I10+TONT20000MAI!I10+TONT20000JUIN!I10+TONT20000JUIL!I10+TONT20000AOUT!I10+TONT20000SEPT!I10+TONT20000OCT!I10+TONT20000NOV!J10 -> 12000 | S10: =TONT20000DEC2015!L10+TONT20000JANV!J10+TONT20000FEV!J10+TONT20000MARS!J10+TONT20000AVRIL!J10+TONT20000MAI!J10+TONT20000JUIN!J10+TONT20000JUIL!J10+TONT20000AOUT!J10+TONT20000SEPT!J10+TONT20000OCT!J10+TONT20000NOV!K10 -> 30000 | T10: =TONT20000DEC2015!M10+TONT20000JANV!K10+TONT20000FEV!K10+TONT20000MARS!K10+TONT20000AVRIL!K10+TONT20000MAI!K10+TONT20000JUIN!K10+TONT20000JUIL!K10+TONT20000AOUT!K10+TONT20000SEPT!K10+TONT20000OCT!K10+TONT20000NOV!L10 -> 0 | U10: =TONT20000DEC2015!N10+TONT20000JANV!L10+TONT20000FEV!L10+TONT20000MARS!L10+TONT20000AVRIL!L10+TONT20000MAI!L10+TONT20000JUIN!L10+TONT20000JUIL!L10+TONT20000AOUT!L10+TONT20000SEPT!L10+TONT20000OCT!L10+TONT20000NOV!M10 -> 156000 | V10: =TONT20000DEC2015!O10+TONT20000JANV!M10+TONT20000FEV!M10+TONT20000MARS!M10+TONT20000AVRIL!M10+TONT20000MAI!M10+TONT20000JUIN!M10+TONT20000JUIL!M10+TONT20000AOUT!M10+TONT20000SEPT!M10+TONT20000OCT!M10+TONT20000NOV!N10 -> 250000 | ... AA10: =TONT20000DEC2015!T10+TONT20000JANV!R10+TONT20000FEV!R10+TONT20000MARS!R10+TONT20000AVRIL!R10+TONT20000MAI!R10+TONT20000JUIN!R10+TONT20000JUIL!R10+TONT20000AOUT!R10+TONT20000SEPT!R10+TONT20000OCT!R10+TONT20000NOV!S10 -> 0
A11: AS201606 | B11: =VLOOKUP(A11,LISTADHERENT!A$5:H$52,2,0) -> DJOSSEU JOSUE | C11: =VLOOKUP(A11,FONDSDECAISSE!A$5:C$52,3,0) -> 0 | D11: 0 | E11: =C11+D11+P11 -> 5000 | F11: =TONT20000DEC2015!E11+TONT20000JANV!C11+TONT20000FEV!C11+TONT20000MARS!C11+TONT20000AVRIL!C11+TONT20000MAI!C11+TONT20000JUIN!C11+TONT20000JUIL!C11+TONT20000AOUT!C11+TONT20000SEPT!C11+TONT20000OCT!C11+TONT20000NOV!C11 -> 580.74958 | G11: =TONT20000NOV!E11 -> 5580.7496 | H11: =D11+F11+P11 -> 5580.7496 | I11: =K11+L11+M11+N11 -> 0 | J11: =H11-I11 -> 5580.7496 | O11: =TONT20000DEC2015!H11+TONT20000JANV!F11+TONT20000FEV!F11+TONT20000MARS!F11+TONT20000AVRIL!F11+TONT20000MAI!F11+TONT20000JUIN!F11+TONT20000JUIL!F11+TONT20000AOUT!F11+TONT20000SEPT!F11+TONT20000OCT!F11+TONT20000NOV!G11 -> 22000 | P11: =TONT20000DEC2015!I11+TONT20000JANV!G11+TONT20000FEV!G11+TONT20000MARS!G11+TONT20000AVRIL!G11+TONT20000MAI!G11+TONT20000JUIN!G11+TONT20000JUIL!G11+TONT20000AOUT!G11+TONT20000SEPT!G11+TONT20000OCT!G11+TONT20000NOV!H11 -> 5000 | Q11: =TONT20000DEC2015!J11+TONT20000JANV!H11+TONT20000FEV!H11+TONT20000MARS!H11+TONT20000AVRIL!H11+TONT20000MAI!H11+TONT20000JUIN!H11+TONT20000JUIL!H11+TONT20000AOUT!H11+TONT20000SEPT!H11+TONT20000OCT!H11+TONT20000NOV!I11 -> 500 | R11: =TONT20000DEC2015!K11+TONT20000JANV!I11+TONT20000FEV!I11+TONT20000MARS!I11+TONT20000AVRIL!I11+TONT20000MAI!I11+TONT20000JUIN!I11+TONT20000JUIL!I11+TONT20000AOUT!I11+TONT20000SEPT!I11+TONT20000OCT!I11+TONT20000NOV!J11 -> 1000 | S11: =TONT20000DEC2015!L11+TONT20000JANV!J11+TONT20000FEV!J11+TONT20000MARS!J11+TONT20000AVRIL!J11+TONT20000MAI!J11+TONT20000JUIN!J11+TONT20000JUIL!J11+TONT20000AOUT!J11+TONT20000SEPT!J11+TONT20000OCT!J11+TONT20000NOV!K11 -> 2500 | T11: =TONT20000DEC2015!M11+TONT20000JANV!K11+TONT20000FEV!K11+TONT20000MARS!K11+TONT20000AVRIL!K11+TONT20000MAI!K11+TONT20000JUIN!K11+TONT20000JUIL!K11+TONT20000AOUT!K11+TONT20000SEPT!K11+TONT20000OCT!K11+TONT20000NOV!L11 -> 0 | U11: =TONT20000DEC2015!N11+TONT20000JANV!L11+TONT20000FEV!L11+TONT20000MARS!L11+TONT20000AVRIL!L11+TONT20000MAI!L11+TONT20000JUIN!L11+TONT20000JUIL!L11+TONT20000AOUT!L11+TONT20000SEPT!L11+TONT20000OCT!L11+TONT20000NOV!M11 -> 13000 | V11: =TONT20000DEC2015!O11+TONT20000JANV!M11+TONT20000FEV!M11+TONT20000MARS!M11+TONT20000AVRIL!M11+TONT20000MAI!M11+TONT20000JUIN!M11+TONT20000JUIL!M11+TONT20000AOUT!M11+TONT20000SEPT!M11+TONT20000OCT!M11+TONT20000NOV!N11 -> 0 | ... AA11: =TONT20000DEC2015!T11+TONT20000JANV!R11+TONT20000FEV!R11+TONT20000MARS!R11+TONT20000AVRIL!R11+TONT20000MAI!R11+TONT20000JUIN!R11+TONT20000JUIL!R11+TONT20000AOUT!R11+TONT20000SEPT!R11+TONT20000OCT!R11+TONT20000NOV!S11 -> 0
A12: AS201607 | B12: =VLOOKUP(A12,LISTADHERENT!A$5:H$52,2,0) -> DJOUNKEP SAMUEL | C12: =VLOOKUP(A12,FONDSDECAISSE!A$5:C$52,3,0) -> 390000 | D12: 1055294 | E12: =C12+D12+P12 -> 2001294 | F12: =TONT20000DEC2015!E12+TONT20000JANV!C12+TONT20000FEV!C12+TONT20000MARS!C12+TONT20000AVRIL!C12+TONT20000MAI!C12+TONT20000JUIN!C12+TONT20000JUIL!C12+TONT20000AOUT!C12+TONT20000SEPT!C12+TONT20000OCT!C12+TONT20000NOV!C12 -> 204246.73 | G12: =TONT20000NOV!E12 -> 2135835.7 | H12: =D12+F12+P12 -> 1815540.7 | I12: =K12+L12+M12+N12 -> 80000 | J12: =H12-I12 -> 1735540.7 | K12: 30000 | M12: 50000 | N12: =48000-(Q12+R12+S12) -> 0 | O12: =TONT20000DEC2015!H12+TONT20000JANV!F12+TONT20000FEV!F12+TONT20000MARS!F12+TONT20000AVRIL!F12+TONT20000MAI!F12+TONT20000JUIN!F12+TONT20000JUIL!F12+TONT20000AOUT!F12+TONT20000SEPT!F12+TONT20000OCT!F12+TONT20000NOV!G12 -> 760000 | P12: =TONT20000DEC2015!I12+TONT20000JANV!G12+TONT20000FEV!G12+TONT20000MARS!G12+TONT20000AVRIL!G12+TONT20000MAI!G12+TONT20000JUIN!G12+TONT20000JUIL!G12+TONT20000AOUT!G12+TONT20000SEPT!G12+TONT20000OCT!G12+TONT20000NOV!H12 -> 556000 | Q12: =TONT20000DEC2015!J12+TONT20000JANV!H12+TONT20000FEV!H12+TONT20000MARS!H12+TONT20000AVRIL!H12+TONT20000MAI!H12+TONT20000JUIN!H12+TONT20000JUIL!H12+TONT20000AOUT!H12+TONT20000SEPT!H12+TONT20000OCT!H12+TONT20000NOV!I12 -> 6000 | R12: =TONT20000DEC2015!K12+TONT20000JANV!I12+TONT20000FEV!I12+TONT20000MARS!I12+TONT20000AVRIL!I12+TONT20000MAI!I12+TONT20000JUIN!I12+TONT20000JUIL!I12+TONT20000AOUT!I12+TONT20000SEPT!I12+TONT20000OCT!I12+TONT20000NOV!J12 -> 12000 | S12: =TONT20000DEC2015!L12+TONT20000JANV!J12+TONT20000FEV!J12+TONT20000MARS!J12+TONT20000AVRIL!J12+TONT20000MAI!J12+TONT20000JUIN!J12+TONT20000JUIL!J12+TONT20000AOUT!J12+TONT20000SEPT!J12+TONT20000OCT!J12+TONT20000NOV!K12 -> 30000 | T12: =TONT20000DEC2015!M12+TONT20000JANV!K12+TONT20000FEV!K12+TONT20000MARS!K12+TONT20000AVRIL!K12+TONT20000MAI!K12+TONT20000JUIN!K12+TONT20000JUIL!K12+TONT20000AOUT!K12+TONT20000SEPT!K12+TONT20000OCT!K12+TONT20000NOV!L12 -> 0 | U12: =TONT20000DEC2015!N12+TONT20000JANV!L12+TONT20000FEV!L12+TONT20000MARS!L12+TONT20000AVRIL!L12+TONT20000MAI!L12+TONT20000JUIN!L12+TONT20000JUIL!L12+TONT20000AOUT!L12+TONT20000SEPT!L12+TONT20000OCT!L12+TONT20000NOV!M12 -> 156000 | V12: =TONT20000DEC2015!O12+TONT20000JANV!M12+TONT20000FEV!M12+TONT20000MARS!M12+TONT20000AVRIL!M12+TONT20000MAI!M12+TONT20000JUIN!M12+TONT20000JUIL!M12+TONT20000AOUT!M12+TONT20000SEPT!M12+TONT20000OCT!M12+TONT20000NOV!N12 -> 0 | ... AA12: =TONT20000DEC2015!T12+TONT20000JANV!R12+TONT20000FEV!R12+TONT20000MARS!R12+TONT20000AVRIL!R12+TONT20000MAI!R12+TONT20000JUIN!R12+TONT20000JUIL!R12+TONT20000AOUT!R12+TONT20000SEPT!R12+TONT20000OCT!R12+TONT20000NOV!S12 -> 0
A13: AS201608 | B13: =VLOOKUP(A13,LISTADHERENT!A$5:H$52,2,0) -> DJUOMBESSY ANTOINE | C13: 390000 | D13: 0 | E13: =C13+D13+P13 -> 457560 | F13: =TONT20000DEC2015!E13+TONT20000JANV!C13+TONT20000FEV!C13+TONT20000MARS!C13+TONT20000AVRIL!C13+TONT20000MAI!C13+TONT20000JUIN!C13+TONT20000JUIL!C13+TONT20000AOUT!C13+TONT20000SEPT!C13+TONT20000OCT!C13+TONT20000NOV!C13 -> 43186.248 | G13: =TONT20000NOV!E13 -> 500746.25 | H13: =D13+F13+P13 -> 110746.25 | I13: =K13+L13+M13+N13 -> 80000 | J13: =H13-I13 -> 30746.248 | K13: 30000 | M13: 50000 | N13: =48000-(Q13+R13+S13) -> 0 | O13: =TONT20000DEC2015!H13+TONT20000JANV!F13+TONT20000FEV!F13+TONT20000MARS!F13+TONT20000AVRIL!F13+TONT20000MAI!F13+TONT20000JUIN!F13+TONT20000JUIL!F13+TONT20000AOUT!F13+TONT20000SEPT!F13+TONT20000OCT!F13+TONT20000NOV!G13 -> 271560 | P13: =TONT20000DEC2015!I13+TONT20000JANV!G13+TONT20000FEV!G13+TONT20000MARS!G13+TONT20000AVRIL!G13+TONT20000MAI!G13+TONT20000JUIN!G13+TONT20000JUIL!G13+TONT20000AOUT!G13+TONT20000SEPT!G13+TONT20000OCT!G13+TONT20000NOV!H13 -> 67560 | Q13: =TONT20000DEC2015!J13+TONT20000JANV!H13+TONT20000FEV!H13+TONT20000MARS!H13+TONT20000AVRIL!H13+TONT20000MAI!H13+TONT20000JUIN!H13+TONT20000JUIL!H13+TONT20000AOUT!H13+TONT20000SEPT!H13+TONT20000OCT!H13+TONT20000NOV!I13 -> 6000 | R13: =TONT20000DEC2015!K13+TONT20000JANV!I13+TONT20000FEV!I13+TONT20000MARS!I13+TONT20000AVRIL!I13+TONT20000MAI!I13+TONT20000JUIN!I13+TONT20000JUIL!I13+TONT20000AOUT!I13+TONT20000SEPT!I13+TONT20000OCT!I13+TONT20000NOV!J13 -> 12000 | S13: =TONT20000DEC2015!L13+TONT20000JANV!J13+TONT20000FEV!J13+TONT20000MARS!J13+TONT20000AVRIL!J13+TONT20000MAI!J13+TONT20000JUIN!J13+TONT20000JUIL!J13+TONT20000AOUT!J13+TONT20000SEPT!J13+TONT20000OCT!J13+TONT20000NOV!K13 -> 30000 | T13: =TONT20000DEC2015!M13+TONT20000JANV!K13+TONT20000FEV!K13+TONT20000MARS!K13+TONT20000AVRIL!K13+TONT20000MAI!K13+TONT20000JUIN!K13+TONT20000JUIL!K13+TONT20000AOUT!K13+TONT20000SEPT!K13+TONT20000OCT!K13+TONT20000NOV!L13 -> 0 | U13: =TONT20000DEC2015!N13+TONT20000JANV!L13+TONT20000FEV!L13+TONT20000MARS!L13+TONT20000AVRIL!L13+TONT20000MAI!L13+TONT20000JUIN!L13+TONT20000JUIL!L13+TONT20000AOUT!L13+TONT20000SEPT!L13+TONT20000OCT!L13+TONT20000NOV!M13 -> 156000 | V13: =TONT20000DEC2015!O13+TONT20000JANV!M13+TONT20000FEV!M13+TONT20000MARS!M13+TONT20000AVRIL!M13+TONT20000MAI!M13+TONT20000JUIN!M13+TONT20000JUIL!M13+TONT20000AOUT!M13+TONT20000SEPT!M13+TONT20000OCT!M13+TONT20000NOV!N13 -> 700000 | ... AA13: =TONT20000DEC2015!T13+TONT20000JANV!R13+TONT20000FEV!R13+TONT20000MARS!R13+TONT20000AVRIL!R13+TONT20000MAI!R13+TONT20000JUIN!R13+TONT20000JUIL!R13+TONT20000AOUT!R13+TONT20000SEPT!R13+TONT20000OCT!R13+TONT20000NOV!S13 -> 0
A14: AS201609 | B14: =VLOOKUP(A14,LISTADHERENT!A$5:H$52,2,0) -> DONHOU DAVID | C14: =VLOOKUP(A14,FONDSDECAISSE!A$5:C$52,3,0) -> 390000 | D14: 44734 | E14: =C14+D14+P14 -> 470734 | F14: =TONT20000DEC2015!E14+TONT20000JANV!C14+TONT20000FEV!C14+TONT20000MARS!C14+TONT20000AVRIL!C14+TONT20000MAI!C14+TONT20000JUIN!C14+TONT20000JUIL!C14+TONT20000AOUT!C14+TONT20000SEPT!C14+TONT20000OCT!C14+TONT20000NOV!C14 -> 53014.493 | G14: =TONT20000NOV!E14 -> 523748.49 | H14: =D14+F14+P14 -> 133748.49 | I14: =K14+L14+M14+N14 -> 80000 | J14: =H14-I14 -> 53748.493 | K14: 30000 | M14: 50000 | N14: =48000-(Q14+R14+S14) -> 0 | O14: =TONT20000DEC2015!H14+TONT20000JANV!F14+TONT20000FEV!F14+TONT20000MARS!F14+TONT20000AVRIL!F14+TONT20000MAI!F14+TONT20000JUIN!F14+TONT20000JUIL!F14+TONT20000AOUT!F14+TONT20000SEPT!F14+TONT20000OCT!F14+TONT20000NOV!G14 -> 240000 | P14: =TONT20000DEC2015!I14+TONT20000JANV!G14+TONT20000FEV!G14+TONT20000MARS!G14+TONT20000AVRIL!G14+TONT20000MAI!G14+TONT20000JUIN!G14+TONT20000JUIL!G14+TONT20000AOUT!G14+TONT20000SEPT!G14+TONT20000OCT!G14+TONT20000NOV!H14 -> 36000 | Q14: =TONT20000DEC2015!J14+TONT20000JANV!H14+TONT20000FEV!H14+TONT20000MARS!H14+TONT20000AVRIL!H14+TONT20000MAI!H14+TONT20000JUIN!H14+TONT20000JUIL!H14+TONT20000AOUT!H14+TONT20000SEPT!H14+TONT20000OCT!H14+TONT20000NOV!I14 -> 6000 | R14: =TONT20000DEC2015!K14+TONT20000JANV!I14+TONT20000FEV!I14+TONT20000MARS!I14+TONT20000AVRIL!I14+TONT20000MAI!I14+TONT20000JUIN!I14+TONT20000JUIL!I14+TONT20000AOUT!I14+TONT20000SEPT!I14+TONT20000OCT!I14+TONT20000NOV!J14 -> 12000 | S14: =TONT20000DEC2015!L14+TONT20000JANV!J14+TONT20000FEV!J14+TONT20000MARS!J14+TONT20000AVRIL!J14+TONT20000MAI!J14+TONT20000JUIN!J14+TONT20000JUIL!J14+TONT20000AOUT!J14+TONT20000SEPT!J14+TONT20000OCT!J14+TONT20000NOV!K14 -> 30000 | T14: =TONT20000DEC2015!M14+TONT20000JANV!K14+TONT20000FEV!K14+TONT20000MARS!K14+TONT20000AVRIL!K14+TONT20000MAI!K14+TONT20000JUIN!K14+TONT20000JUIL!K14+TONT20000AOUT!K14+TONT20000SEPT!K14+TONT20000OCT!K14+TONT20000NOV!L14 -> 0 | U14: =TONT20000DEC2015!N14+TONT20000JANV!L14+TONT20000FEV!L14+TONT20000MARS!L14+TONT20000AVRIL!L14+TONT20000MAI!L14+TONT20000JUIN!L14+TONT20000JUIL!L14+TONT20000AOUT!L14+TONT20000SEPT!L14+TONT20000OCT!L14+TONT20000NOV!M14 -> 156000 | V14: =TONT20000DEC2015!O14+TONT20000JANV!M14+TONT20000FEV!M14+TONT20000MARS!M14+TONT20000AVRIL!M14+TONT20000MAI!M14+TONT20000JUIN!M14+TONT20000JUIL!M14+TONT20000AOUT!M14+TONT20000SEPT!M14+TONT20000OCT!M14+TONT20000NOV!N14 -> 0 | ... AA14: =TONT20000DEC2015!T14+TONT20000JANV!R14+TONT20000FEV!R14+TONT20000MARS!R14+TONT20000AVRIL!R14+TONT20000MAI!R14+TONT20000JUIN!R14+TONT20000JUIL!R14+TONT20000AOUT!R14+TONT20000SEPT!R14+TONT20000OCT!R14+TONT20000NOV!S14 -> 0
A15: AS201610 | B15: =VLOOKUP(A15,LISTADHERENT!A$5:H$52,2,0) -> FOTSO THOMAS | C15: =VLOOKUP(A15,FONDSDECAISSE!A$5:C$52,3,0) -> 390000 | D15: 3318 | E15: =C15+D15+P15 -> 429318 | F15: =TONT20000DEC2015!E15+TONT20000JANV!C15+TONT20000FEV!C15+TONT20000MARS!C15+TONT20000AVRIL!C15+TONT20000MAI!C15+TONT20000JUIN!C15+TONT20000JUIL!C15+TONT20000AOUT!C15+TONT20000SEPT!C15+TONT20000OCT!C15+TONT20000NOV!C15 -> 48204.028 | G15: =TONT20000NOV!E15 -> 477522.03 | H15: =D15+F15+P15 -> 87522.028 | I15: =K15+L15+M15+N15 -> 80000 | J15: =H15-I15 -> 7522.0283 | K15: 30000 | M15: 50000 | N15: =48000-(Q15+R15+S15) -> 0 | O15: =TONT20000DEC2015!H15+TONT20000JANV!F15+TONT20000FEV!F15+TONT20000MARS!F15+TONT20000AVRIL!F15+TONT20000MAI!F15+TONT20000JUIN!F15+TONT20000JUIL!F15+TONT20000AOUT!F15+TONT20000SEPT!F15+TONT20000OCT!F15+TONT20000NOV!G15 -> 240000 | P15: =TONT20000DEC2015!I15+TONT20000JANV!G15+TONT20000FEV!G15+TONT20000MARS!G15+TONT20000AVRIL!G15+TONT20000MAI!G15+TONT20000JUIN!G15+TONT20000JUIL!G15+TONT20000AOUT!G15+TONT20000SEPT!G15+TONT20000OCT!G15+TONT20000NOV!H15 -> 36000 | Q15: =TONT20000DEC2015!J15+TONT20000JANV!H15+TONT20000FEV!H15+TONT20000MARS!H15+TONT20000AVRIL!H15+TONT20000MAI!H15+TONT20000JUIN!H15+TONT20000JUIL!H15+TONT20000AOUT!H15+TONT20000SEPT!H15+TONT20000OCT!H15+TONT20000NOV!I15 -> 6000 | R15: =TONT20000DEC2015!K15+TONT20000JANV!I15+TONT20000FEV!I15+TONT20000MARS!I15+TONT20000AVRIL!I15+TONT20000MAI!I15+TONT20000JUIN!I15+TONT20000JUIL!I15+TONT20000AOUT!I15+TONT20000SEPT!I15+TONT20000OCT!I15+TONT20000NOV!J15 -> 12000 | S15: =TONT20000DEC2015!L15+TONT20000JANV!J15+TONT20000FEV!J15+TONT20000MARS!J15+TONT20000AVRIL!J15+TONT20000MAI!J15+TONT20000JUIN!J15+TONT20000JUIL!J15+TONT20000AOUT!J15+TONT20000SEPT!J15+TONT20000OCT!J15+TONT20000NOV!K15 -> 30000 | T15: =TONT20000DEC2015!M15+TONT20000JANV!K15+TONT20000FEV!K15+TONT20000MARS!K15+TONT20000AVRIL!K15+TONT20000MAI!K15+TONT20000JUIN!K15+TONT20000JUIL!K15+TONT20000AOUT!K15+TONT20000SEPT!K15+TONT20000OCT!K15+TONT20000NOV!L15 -> 0 | U15: =TONT20000DEC2015!N15+TONT20000JANV!L15+TONT20000FEV!L15+TONT20000MARS!L15+TONT20000AVRIL!L15+TONT20000MAI!L15+TONT20000JUIN!L15+TONT20000JUIL!L15+TONT20000AOUT!L15+TONT20000SEPT!L15+TONT20000OCT!L15+TONT20000NOV!M15 -> 156000 | V15: =TONT20000DEC2015!O15+TONT20000JANV!M15+TONT20000FEV!M15+TONT20000MARS!M15+TONT20000AVRIL!M15+TONT20000MAI!M15+TONT20000JUIN!M15+TONT20000JUIL!M15+TONT20000AOUT!M15+TONT20000SEPT!M15+TONT20000OCT!M15+TONT20000NOV!N15 -> 1000000 | ... AA15: =TONT20000DEC2015!T15+TONT20000JANV!R15+TONT20000FEV!R15+TONT20000MARS!R15+TONT20000AVRIL!R15+TONT20000MAI!R15+TONT20000JUIN!R15+TONT20000JUIL!R15+TONT20000AOUT!R15+TONT20000SEPT!R15+TONT20000OCT!R15+TONT20000NOV!S15 -> 0
A16: AS201611 | B16: =VLOOKUP(A16,LISTADHERENT!A$5:H$52,2,0) -> HENGUE PAUL OMER | C16: =VLOOKUP(A16,FONDSDECAISSE!A$5:C$52,3,0) -> 390000 | D16: 1083990 | E16: =C16+D16+P16 -> 1503990 | F16: =TONT20000DEC2015!E16+TONT20000JANV!C16+TONT20000FEV!C16+TONT20000MARS!C16+TONT20000AVRIL!C16+TONT20000MAI!C16+TONT20000JUIN!C16+TONT20000JUIL!C16+TONT20000AOUT!C16+TONT20000SEPT!C16+TONT20000OCT!C16+TONT20000NOV!C16 -> 47702.041 | G16: =TONT20000NOV!E16 -> 467702.04 | H16: =D16+F16+P16 -> 1161692 | I16: =K16+L16+M16+N16 -> 88000 | J16: =H16-I16 -> 1073692 | K16: 30000 | M16: 50000 | N16: =48000-(Q16+R16+S16) -> 8000 | O16: =TONT20000DEC2015!H16+TONT20000JANV!F16+TONT20000FEV!F16+TONT20000MARS!F16+TONT20000AVRIL!F16+TONT20000MAI!F16+TONT20000JUIN!F16+TONT20000JUIL!F16+TONT20000AOUT!F16+TONT20000SEPT!F16+TONT20000OCT!F16+TONT20000NOV!G16 -> 200000 | P16: =TONT20000DEC2015!I16+TONT20000JANV!G16+TONT20000FEV!G16+TONT20000MARS!G16+TONT20000AVRIL!G16+TONT20000MAI!G16+TONT20000JUIN!G16+TONT20000JUIL!G16+TONT20000AOUT!G16+TONT20000SEPT!G16+TONT20000OCT!G16+TONT20000NOV!H16 -> 30000 | Q16: =TONT20000DEC2015!J16+TONT20000JANV!H16+TONT20000FEV!H16+TONT20000MARS!H16+TONT20000AVRIL!H16+TONT20000MAI!H16+TONT20000JUIN!H16+TONT20000JUIL!H16+TONT20000AOUT!H16+TONT20000SEPT!H16+TONT20000OCT!H16+TONT20000NOV!I16 -> 5000 | R16: =TONT20000DEC2015!K16+TONT20000JANV!I16+TONT20000FEV!I16+TONT20000MARS!I16+TONT20000AVRIL!I16+TONT20000MAI!I16+TONT20000JUIN!I16+TONT20000JUIL!I16+TONT20000AOUT!I16+TONT20000SEPT!I16+TONT20000OCT!I16+TONT20000NOV!J16 -> 10000 | S16: =TONT20000DEC2015!L16+TONT20000JANV!J16+TONT20000FEV!J16+TONT20000MARS!J16+TONT20000AVRIL!J16+TONT20000MAI!J16+TONT20000JUIN!J16+TONT20000JUIL!J16+TONT20000AOUT!J16+TONT20000SEPT!J16+TONT20000OCT!J16+TONT20000NOV!K16 -> 25000 | T16: =TONT20000DEC2015!M16+TONT20000JANV!K16+TONT20000FEV!K16+TONT20000MARS!K16+TONT20000AVRIL!K16+TONT20000MAI!K16+TONT20000JUIN!K16+TONT20000JUIL!K16+TONT20000AOUT!K16+TONT20000SEPT!K16+TONT20000OCT!K16+TONT20000NOV!L16 -> 0 | U16: =TONT20000DEC2015!N16+TONT20000JANV!L16+TONT20000FEV!L16+TONT20000MARS!L16+TONT20000AVRIL!L16+TONT20000MAI!L16+TONT20000JUIN!L16+TONT20000JUIL!L16+TONT20000AOUT!L16+TONT20000SEPT!L16+TONT20000OCT!L16+TONT20000NOV!M16 -> 130000 | V16: =TONT20000DEC2015!O16+TONT20000JANV!M16+TONT20000FEV!M16+TONT20000MARS!M16+TONT20000AVRIL!M16+TONT20000MAI!M16+TONT20000JUIN!M16+TONT20000JUIL!M16+TONT20000AOUT!M16+TONT20000SEPT!M16+TONT20000OCT!M16+TONT20000NOV!N16 -> 0 | ... AA16: =TONT20000DEC2015!T16+TONT20000JANV!R16+TONT20000FEV!R16+TONT20000MARS!R16+TONT20000AVRIL!R16+TONT20000MAI!R16+TONT20000JUIN!R16+TONT20000JUIL!R16+TONT20000AOUT!R16+TONT20000SEPT!R16+TONT20000OCT!R16+TONT20000NOV!S16 -> 0
A17: AS201612 | B17: =VLOOKUP(A17,LISTADHERENT!A$5:H$52,2,0) -> HODIEP JULES | C17: 50000 | D17: 0 | E17: =C17+D17+P17 -> 58100 | F17: =TONT20000DEC2015!E17+TONT20000JANV!C17+TONT20000FEV!C17+TONT20000MARS!C17+TONT20000AVRIL!C17+TONT20000MAI!C17+TONT20000JUIN!C17+TONT20000JUIL!C17+TONT20000AOUT!C17+TONT20000SEPT!C17+TONT20000OCT!C17+TONT20000NOV!C17 -> 6252.3821 | G17: =TONT20000NOV!E17 -> 92252.382 | H17: =D17+F17+P17 -> 14352.382 | I17: =K17+L17+M17+N17 -> 14092 | J17: =H17-I17 -> 260.38213 | M17: =50000-35908 -> 14092 | N17: =48000-(Q17+R17+S17) -> 0 | O17: =TONT20000DEC2015!H17+TONT20000JANV!F17+TONT20000FEV!F17+TONT20000MARS!F17+TONT20000AVRIL!F17+TONT20000MAI!F17+TONT20000JUIN!F17+TONT20000JUIL!F17+TONT20000AOUT!F17+TONT20000SEPT!F17+TONT20000OCT!F17+TONT20000NOV!G17 -> 240000 | P17: =TONT20000DEC2015!I17+TONT20000JANV!G17+TONT20000FEV!G17+TONT20000MARS!G17+TONT20000AVRIL!G17+TONT20000MAI!G17+TONT20000JUIN!G17+TONT20000JUIL!G17+TONT20000AOUT!G17+TONT20000SEPT!G17+TONT20000OCT!G17+TONT20000NOV!H17-18000-9900 -> 8100 | Q17: =TONT20000DEC2015!J17+TONT20000JANV!H17+TONT20000FEV!H17+TONT20000MARS!H17+TONT20000AVRIL!H17+TONT20000MAI!H17+TONT20000JUIN!H17+TONT20000JUIL!H17+TONT20000AOUT!H17+TONT20000SEPT!H17+TONT20000OCT!H17+TONT20000NOV!I17 -> 6000 | R17: =TONT20000DEC2015!K17+TONT20000JANV!I17+TONT20000FEV!I17+TONT20000MARS!I17+TONT20000AVRIL!I17+TONT20000MAI!I17+TONT20000JUIN!I17+TONT20000JUIL!I17+TONT20000AOUT!I17+TONT20000SEPT!I17+TONT20000OCT!I17+TONT20000NOV!J17 -> 12000 | S17: =TONT20000DEC2015!L17+TONT20000JANV!J17+TONT20000FEV!J17+TONT20000MARS!J17+TONT20000AVRIL!J17+TONT20000MAI!J17+TONT20000JUIN!J17+TONT20000JUIL!J17+TONT20000AOUT!J17+TONT20000SEPT!J17+TONT20000OCT!J17+TONT20000NOV!K17 -> 30000 | T17: =TONT20000DEC2015!M17+TONT20000JANV!K17+TONT20000FEV!K17+TONT20000MARS!K17+TONT20000AVRIL!K17+TONT20000MAI!K17+TONT20000JUIN!K17+TONT20000JUIL!K17+TONT20000AOUT!K17+TONT20000SEPT!K17+TONT20000OCT!K17+TONT20000NOV!L17 -> 0 | U17: =TONT20000DEC2015!N17+TONT20000JANV!L17+TONT20000FEV!L17+TONT20000MARS!L17+TONT20000AVRIL!L17+TONT20000MAI!L17+TONT20000JUIN!L17+TONT20000JUIL!L17+TONT20000AOUT!L17+TONT20000SEPT!L17+TONT20000OCT!L17+TONT20000NOV!M17 -> 156000 | V17: =TONT20000DEC2015!O17+TONT20000JANV!M17+TONT20000FEV!M17+TONT20000MARS!M17+TONT20000AVRIL!M17+TONT20000MAI!M17+TONT20000JUIN!M17+TONT20000JUIL!M17+TONT20000AOUT!M17+TONT20000SEPT!M17+TONT20000OCT!M17+TONT20000NOV!N17 -> 0 | W17: =TONT20000DEC2015!P17+TONT20000JANV!N17+TONT20000FEV!N17+TONT20000MARS!N17+TONT20000AVRIL!N17+TONT20000MAI!N17+TONT20000JUIN!N17+TONT20000JUIL!N17+TONT20000AOUT!N17+TONT20000SEPT!N17+TONT20000OCT!N17+TONT20000NOV!O17 -> 0 | X17: =TONT20000DEC2015!Q17+TONT20000JANV!O17+TONT20000FEV!O17+TONT20000MARS!O17+TONT20000AVRIL!O17+TONT20000MAI!O17+TONT20000JUIN!O17+TONT20000JUIL!O17+TONT20000AOUT!O17+TONT20000SEPT!O17+TONT20000OCT!O17+TONT20000NOV!P17 -> 0 | ... AA17: =TONT20000DEC2015!T17+TONT20000JANV!R17+TONT20000FEV!R17+TONT20000MARS!R17+TONT20000AVRIL!R17+TONT20000MAI!R17+TONT20000JUIN!R17+TONT20000JUIL!R17+TONT20000AOUT!R17+TONT20000SEPT!R17+TONT20000OCT!R17+TONT20000NOV!S17 -> 0
