Workbook
Name BANQUE: #REF!
Name BANQUE: #REF!
Name BANQUE: #REF!
Name BANQUE: #REF!
Name BANQUE: #REF!
Name BANQUE: #REF!
Name BANQUE: #REF!
Name BANQUE: #REF!
Name BANQUE: #REF!
Name BANQUE: #REF!
Name BANQUE: #REF!
Name BANQUE: #REF!
Name BANQUE: #REF!
Name BANQUE: #REF!
Name BANQUE: #REF!
Name BANQUE: #REF!
Name BANQUE: #REF!
Name BANQUE: #REF!
Name BANQUE: #REF!
Name BANQUE: #REF!
Name BANQUE: #REF!
Name BANQUE: #REF!
Name BANQUE: #REF!
Name BANQUE: #REF!
Name BANQUE: #REF!
Name BANQUE: #REF!
Name BANQUE: #REF!
Name BANQUE: #REF!
Name BANQUE: #REF!
Name BANQUE: #REF!
Name BANQUE: #REF!
Name BANQUE: #REF!
Name BANQUE: #REF!
Name BANQUE: #REF!
Name BANQUE: #REF!
Name BANQUE: #REF!
Name BANQUE: #REF!
Name BANQUE: #REF!
Name BANQUE: #REF!
Name ECHEC: #REF!
Name MODEET30000: [1]MODEVERSEMENT!$A$1:$A$3
Name MODEET30000: [2]MODEVERSEMENT!$A$1:$A$3
Name MODEET30000: [2]MODEVERSEMENT!$A$1:$A$3
Name MODEET30000: [2]MODEVERSEMENT!$A$1:$A$3
Name MODEET30000: [2]MODEVERSEMENT!$A$1:$A$3
Name MODEET30000: [2]MODEVERSEMENT!$A$1:$A$3
Name MODEET30000: [2]MODEVERSEMENT!$A$1:$A$3
Name MODEET30000: [2]MODEVERSEMENT!$A$1:$A$3
Name MODEET30000: [2]MODEVERSEMENT!$A$1:$A$3
Name MODEET30000: [2]MODEVERSEMENT!$A$1:$A$3
Name MODEET30000: [2]MODEVERSEMENT!$A$1:$A$3
Name MODEET30000: [2]MODEVERSEMENT!$A$1:$A$3
Name MODEET30000: [2]MODEVERSEMENT!$A$1:$A$3
Name MODEET30000: [2]MODEVERSEMENT!$A$1:$A$3
Name MODEET30000: [2]MODEVERSEMENT!$A$1:$A$3
Name MODEET30000: [2]MODEVERSEMENT!$A$1:$A$3
Name MODEET30000: [3]MODEVERSEMENT!$A$1:$A$3
Name MODEPAID: [4]Feuil2!$A$1:$A$3
Name MODEPAID: [5]Feuil2!$A$1:$A$3
Name MODEPAID: #REF!

Sheet TAF
A1: AIDE
A2: PRÊT
A3: REMBOURSEMENT
A4: AGIOS BANCAIRE
A5: DETAIL CHEQUE
A6: RAPPORT FINANCIER

Sheet MODEVERSEMENT
A1: BANQUE
A2: ESPECES
A3: ECHEC

Sheet MODET25000
A1: BANQUE
A2: ESPECES
A3: ECHEC

Sheet MVTDEC21
A1: ASSOCIATION | B1: ASELBY | G1: K
A2: ANNEE | B2: 2022
A3: TONTINE
J4: 44578
A5: MATRICULE | B5: NOM ET PRENOM | C5: FONDES DE DEPART | D5: RELIQUAT | E5: RETRAIT PARTIEL | F5: FONDS DEFINITIF | G5: REPARTITION INTERET | H5: CAPITAL COMPOSE | I5: SANCTION | J5: RESTE | K5: EPARGNE | L5: FONDS DE ROULEMENT | M5: FRAIS EXCEPTIONNEL | N5: COLLATION | O5: PENALITE VST ESPECES | P5: INSCRISPTION | Q5: MUTUELLE | R5: PRÊT FONDS | S5: INTERETPRET FONDS | T5: NUMERO CHEQUE | U5: REMBOURSEMENTPRET FONDS | V5: MODE VERSEMENT REMBOURSEMENT | W5: MODE VERSEMENT PRÊT | X5: NUMERO CHEQUE | Y5: PENALITE PRET FONDS | Z5: PENALITE FONDS | AA5: PENALITE ECHEC TONTINE | AB5: PENALITE RETARD TONTINE | AC5: REMBOURSEMENT TRANSPORT | AD5: CONTRIBUTION FOYER | AE5: DEPENSE FONCTIONNEMENT
A6: AS201648 | B6: =VLOOKUP(A6,[15]LISTADHERENT!$A$5:$J$50,3,0) -> ASELBY | C6: =MVTJANV23!C6 -> 0 | D6: =MVTJANV23!D6 -> 816543.52 | F6: =C6+D6-E6+K6 -> 816543.52 | G6: =$S$40/$H$40*H6 -> #REF! | H6: =F6+D6+K6 -> 1633087 | AE6: =[16]HISTOMVTDEPENSE!$T$39 -> 0
A7: AS201601 | B7: =VLOOKUP(A7,[15]LISTADHERENT!$A$5:$J$50,3,0) -> BAKOP ACHILLE | C7: =MVTJANV23!C7 -> 0 | D7: =MVTJANV23!D7 -> 0 | F7: =C7+D7-E7+K7 -> 0 | G7: =$S$40/$H$40*H7 -> #REF! | H7: =F7+D7+K7 -> 0 | Y7: 4000
A8: AS201602 | B8: =VLOOKUP(A8,[15]LISTADHERENT!$A$5:$J$50,3,0) -> BOUTCHOUANG WILLIAM | C8: =MVTJANV23!C8 -> 600000 | D8: =MVTJANV23!D8 -> 7024 | F8: =C8+D8-E8+K8 -> 610024 | G8: =$S$40/$H$40*H8 -> #REF! | H8: =F8+D8+K8 -> 620048 | I8: =VLOOKUP($A8,[16]HISTOJANV22!$A$6:$AQ$37,22,0) -> 0 | J8: =VLOOKUP($A8,[16]HISTOJANV22!$A$6:$AU$39,45,0) -> 7000 | K8: =IF(J8=0,0,J8-(L8+M8+N8)) -> 3000 | L8: =IF(J8=0,0,500) -> 500 | M8: =IF(J8=0,0,1000) -> 1000 | N8: =IF(J8=0,0,2500) -> 2500 | O8: =VLOOKUP($A8,[16]HISTOJANV22!$A$6:$AU$39,7,0) -> 0 | P8: =VLOOKUP($A8,[16]HISTOJANV22!$A$6:$AU$39,23,0) -> 0 | Q8: =VLOOKUP($A8,[16]HISTOJANV22!$A$6:$AU$39,46,0) -> 0 | R8: =VLOOKUP($A8,[16]HISTODEC21!$A$6:$AU$39,26,0) -> 525000 | S8: =R8*12/1200*12 -> 63000 | T8: =VLOOKUP($A8,[16]HISTOJANV22!$A$6:$AU$39,28,0) -> 0 | U8: =VLOOKUP($A8,[16]HISTOJANV22!$A$6:$AU$39,19,0) -> 0 | V8: =VLOOKUP($A8,[16]HISTOJANV22!$A$6:$AU$39,20,0) -> 0 | W8: =VLOOKUP($A8,[16]HISTOJANV22!$A$6:$AU$39,27,0) -> 0 | X8: =VLOOKUP($A8,[16]HISTOJANV22!$A$6:$AU$39,33,0) -> 0 | AA8: =VLOOKUP($A8,[16]HISTOJANV22!$A$6:$AU$39,43,0) -> 0 | AB8: =VLOOKUP($A8,[16]HISTOJANV22!$A$6:$AU$39,44,0) -> 0 | AC8: =VLOOKUP($A8,[16]HISTOJANV22!$A$6:$AU$39,47,0) -> 0 | AD8: =VLOOKUP(A8,[16]HISTOJANV22!$A$6:$BB$36,54,0) -> 0
A9: AS201604 | B9: =VLOOKUP(A9,[15]LISTADHERENT!$A$5:$J$50,3,0) -> DJOMO JEAN PAUL | C9: =MVTJANV23!C9 -> 600000 | D9: =MVTJANV23!D9 -> 4810 | F9: =C9+D9-E9+K9 -> 652810 | G9: =$S$40/$H$40*H9 -> #REF! | H9: =F9+D9+K9 -> 705620 | I9: =VLOOKUP($A9,[16]HISTOJANV22!$A$6:$AQ$37,22,0) -> 0 | J9: =VLOOKUP($A9,[16]HISTOJANV22!$A$6:$AU$39,45,0) -> 52000 | K9: =IF(J9=0,0,J9-(L9+M9+N9)) -> 48000 | L9: =IF(J9=0,0,500) -> 500 | M9: =IF(J9=0,0,1000) -> 1000 | N9: =IF(J9=0,0,2500) -> 2500 | O9: =VLOOKUP($A9,[16]HISTOJANV22!$A$6:$AU$39,7,0) -> 0 | P9: =VLOOKUP($A9,[16]HISTOJANV22!$A$6:$AU$39,23,0) -> 0 | Q9: =VLOOKUP($A9,[16]HISTOJANV22!$A$6:$AU$39,46,0) -> 0 | R9: =VLOOKUP($A9,[16]HISTODEC21!$A$6:$AU$39,26,0) -> 1000000 | S9: =R9*12/1200*12 -> 120000 | T9: =VLOOKUP($A9,[16]HISTOJANV22!$A$6:$AU$39,28,0) -> OKK | U9: =VLOOKUP($A9,[16]HISTOJANV22!$A$6:$AU$39,19,0) -> 0 | V9: =VLOOKUP($A9,[16]HISTOJANV22!$A$6:$AU$39,20,0) -> 0 | W9: =VLOOKUP($A9,[16]HISTOJANV22!$A$6:$AU$39,27,0) -> BANQUE | X9: =VLOOKUP($A9,[16]HISTOJANV22!$A$6:$AU$39,33,0) -> 0 | AA9: =VLOOKUP($A9,[16]HISTOJANV22!$A$6:$AU$39,43,0) -> 0 | AB9: =VLOOKUP($A9,[16]HISTOJANV22!$A$6:$AU$39,44,0) -> 0 | AC9: =VLOOKUP($A9,[16]HISTOJANV22!$A$6:$AU$39,47,0) -> 0 | AD9: =VLOOKUP(A9,[16]HISTOJANV22!$A$6:$BB$36,54,0) -> 0
A10: AS201654 | B10: =VLOOKUP(A10,[15]LISTADHERENT!$A$5:$J$50,3,0) -> DJOMOU TCHAPDA | C10: =MVTJANV23!C10 -> 600000 | D10: =MVTJANV23!D10 -> 48710 | F10: =C10+D10-E10+K10 -> 651710 | G10: =$S$40/$H$40*H10 -> #REF! | H10: =F10+D10+K10 -> 703420 | I10: =VLOOKUP($A10,[16]HISTOJANV22!$A$6:$AQ$37,22,0) -> 0 | J10: =VLOOKUP($A10,[16]HISTOJANV22!$A$6:$AU$39,45,0) -> 7000 | K10: =IF(J10=0,0,J10-(L10+M10+N10)) -> 3000 | L10: =IF(J10=0,0,500) -> 500 | M10: =IF(J10=0,0,1000) -> 1000 | N10: =IF(J10=0,0,2500) -> 2500 | O10: =VLOOKUP($A10,[16]HISTOJANV22!$A$6:$AU$39,7,0) -> 0 | P10: =VLOOKUP($A10,[16]HISTOJANV22!$A$6:$AU$39,23,0) -> 0 | Q10: =VLOOKUP($A10,[16]HISTOJANV22!$A$6:$AU$39,46,0) -> 0 | R10: =VLOOKUP($A10,[16]HISTODEC21!$A$6:$AU$39,26,0) -> #REF! | S10: =R10*1/1200*12 -> #REF! | T10: =VLOOKUP($A10,[16]HISTOJANV22!$A$6:$AU$39,28,0) -> 0 | U10: =VLOOKUP($A10,[16]HISTOJANV22!$A$6:$AU$39,19,0) -> 0 | V10: =VLOOKUP($A10,[16]HISTOJANV22!$A$6:$AU$39,20,0) -> 0 | W10: =VLOOKUP($A10,[16]HISTOJANV22!$A$6:$AU$39,27,0) -> 0 | X10: =VLOOKUP($A10,[16]HISTOJANV22!$A$6:$AU$39,33,0) -> 0 | AA10: =VLOOKUP($A10,[16]HISTOJANV22!$A$6:$AU$39,43,0) -> 0 | AB10: =VLOOKUP($A10,[16]HISTOJANV22!$A$6:$AU$39,44,0) -> 0 | AC10: =VLOOKUP($A10,[16]HISTOJANV22!$A$6:$AU$39,47,0) -> 0 | AD10: =VLOOKUP(A10,[16]HISTOJANV22!$A$6:$BB$36,54,0) -> 0
A11: AS201605 | B11: =VLOOKUP(A11,[15]LISTADHERENT!$A$5:$J$50,3,0) -> DJOUKWE NANGUEN GUY BLAISE | C11: =MVTJANV23!C11 -> 600000 | D11: =MVTJANV23!D11 -> 4750 | F11: =C11+D11-E11+K11 -> 612750 | G11: =$S$40/$H$40*H11 -> #REF! | H11: =F11+D11+K11 -> 625500 | I11: =VLOOKUP($A11,[16]HISTOJANV22!$A$6:$AQ$37,22,0) -> 0 | J11: =VLOOKUP($A11,[16]HISTOJANV22!$A$6:$AU$39,45,0) -> 12000 | K11: =IF(J11=0,0,J11-(L11+M11+N11)) -> 8000 | L11: =IF(J11=0,0,500) -> 500 | M11: =IF(J11=0,0,1000) -> 1000 | N11: =IF(J11=0,0,2500) -> 2500 | O11: =VLOOKUP($A11,[16]HISTOJANV22!$A$6:$AU$39,7,0) -> 0 | P11: =VLOOKUP($A11,[16]HISTOJANV22!$A$6:$AU$39,23,0) -> 0 | Q11: =VLOOKUP($A11,[16]HISTOJANV22!$A$6:$AU$39,46,0) -> 0 | R11: =VLOOKUP($A11,[16]HISTODEC21!$A$6:$AU$39,26,0) -> 1000000 | S11: =R11*1/1200*12 -> 10000 | T11: =VLOOKUP($A11,[16]HISTOJANV22!$A$6:$AU$39,28,0) -> OKK | U11: =VLOOKUP($A11,[16]HISTOJANV22!$A$6:$AU$39,19,0) -> 0 | V11: =VLOOKUP($A11,[16]HISTOJANV22!$A$6:$AU$39,20,0) -> 0 | W11: =VLOOKUP($A11,[16]HISTOJANV22!$A$6:$AU$39,27,0) -> BANQUE | X11: =VLOOKUP($A11,[16]HISTOJANV22!$A$6:$AU$39,33,0) -> 0 | Y11: 29000 | AA11: =VLOOKUP($A11,[16]HISTOJANV22!$A$6:$AU$39,43,0) -> 0 | AB11: =VLOOKUP($A11,[16]HISTOJANV22!$A$6:$AU$39,44,0) -> 0 | AC11: =VLOOKUP($A11,[16]HISTOJANV22!$A$6:$AU$39,47,0) -> 0 | AD11: =VLOOKUP(A11,[16]HISTOJANV22!$A$6:$BB$36,54,0) -> 0
A12: AS201608 | B12: =VLOOKUP(A12,[15]LISTADHERENT!$A$5:$J$50,3,0) -> DJUOMBESSY ANTOINE | C12: =MVTJANV23!C12 -> 600000 | D12: =MVTJANV23!D12 -> 10719 | F12: =C12+D12-E12+K12 -> 613719 | G12: =$S$40/$H$40*H12 -> #REF! | H12: =F12+D12+K12 -> 627438 | I12: =VLOOKUP($A12,[16]HISTOJANV22!$A$6:$AQ$37,22,0) -> 0 | J12: =VLOOKUP($A12,[16]HISTOJANV22!$A$6:$AU$39,45,0) -> 7000 | K12: =IF(J12=0,0,J12-(L12+M12+N12)) -> 3000 | L12: =IF(J12=0,0,500) -> 500 | M12: =IF(J12=0,0,1000) -> 1000 | N12: =IF(J12=0,0,2500) -> 2500 | O12: =VLOOKUP($A12,[16]HISTOJANV22!$A$6:$AU$39,7,0) -> 0 | P12: =VLOOKUP($A12,[16]HISTOJANV22!$A$6:$AU$39,23,0) -> 0 | Q12: =VLOOKUP($A12,[16]HISTOJANV22!$A$6:$AU$39,46,0) -> 0 | R12: =VLOOKUP($A12,[16]HISTODEC21!$A$6:$AU$39,26,0) -> 1029000 | S12: =R12*12/1200*12 -> 123480 | T12: =VLOOKUP($A12,[16]HISTOJANV22!$A$6:$AU$39,28,0) -> 0 | U12: =VLOOKUP($A12,[16]HISTOJANV22!$A$6:$AU$39,19,0) -> 1000000 | V12: =VLOOKUP($A12,[16]HISTOJANV22!$A$6:$AU$39,20,0) -> BANQUE | W12: =VLOOKUP($A12,[16]HISTOJANV22!$A$6:$AU$39,27,0) -> 0 | X12: =VLOOKUP($A12,[16]HISTOJANV22!$A$6:$AU$39,33,0) -> 0 | AA12: =VLOOKUP($A12,[16]HISTOJANV22!$A$6:$AU$39,43,0) -> 0 | AB12: =VLOOKUP($A12,[16]HISTOJANV22!$A$6:$AU$39,44,0) -> 0 | AC12: =VLOOKUP($A12,[16]HISTOJANV22!$A$6:$AU$39,47,0) -> 0 | AD12: =VLOOKUP(A12,[16]HISTOJANV22!$A$6:$BB$36,54,0) -> 61000
A13: AS201651 | B13: =VLOOKUP(A13,[15]LISTADHERENT!$A$5:$J$50,3,0) -> DOMOU FABIEN | C13: =MVTJANV23!C13 -> 600000 | D13: =MVTJANV23!D13 -> 584 | F13: =C13+D13-E13+K13 -> 608584 | G13: =$S$40/$H$40*H13 -> #REF! | H13: =F13+D13+K13 -> 617168 | I13: =VLOOKUP($A13,[16]HISTOJANV22!$A$6:$AQ$37,22,0) -> 0 | J13: =VLOOKUP($A13,[16]HISTOJANV22!$A$6:$AU$39,45,0) -> 12000 | K13: =IF(J13=0,0,J13-(L13+M13+N13)) -> 8000 | L13: =IF(J13=0,0,500) -> 500 | M13: =IF(J13=0,0,1000) -> 1000 | N13: =IF(J13=0,0,2500) -> 2500 | O13: =VLOOKUP($A13,[16]HISTOJANV22!$A$6:$AU$39,7,0) -> 0 | P13: =VLOOKUP($A13,[16]HISTOJANV22!$A$6:$AU$39,23,0) -> 0 | Q13: =VLOOKUP($A13,[16]HISTOJANV22!$A$6:$AU$39,46,0) -> 0 | R13: =VLOOKUP($A13,[16]HISTODEC21!$A$6:$AU$39,26,0) -> 1000000 | S13: =R13*12/1200*12 -> 120000 | T13: =VLOOKUP($A13,[16]HISTOJANV22!$A$6:$AU$39,28,0) -> OKK | U13: =VLOOKUP($A13,[16]HISTOJANV22!$A$6:$AU$39,19,0) -> 0 | V13: =VLOOKUP($A13,[16]HISTOJANV22!$A$6:$AU$39,20,0) -> 0 | W13: =VLOOKUP($A13,[16]HISTOJANV22!$A$6:$AU$39,27,0) -> BANQUE | X13: =VLOOKUP($A13,[16]HISTOJANV22!$A$6:$AU$39,33,0) -> 0 | AA13: =VLOOKUP($A13,[16]HISTOJANV22!$A$6:$AU$39,43,0) -> 0 | AB13: =VLOOKUP($A13,[16]HISTOJANV22!$A$6:$AU$39,44,0) -> 0 | AC13: =VLOOKUP($A13,[16]HISTOJANV22!$A$6:$AU$39,47,0) -> 0 | AD13: =VLOOKUP(A13,[16]HISTOJANV22!$A$6:$BB$36,54,0) -> 57000
A14: AS201609 | B14: =VLOOKUP(A14,[15]LISTADHERENT!$A$5:$J$50,3,0) -> DONHOU DAVID | C14: =MVTJANV23!C14 -> 600000 | D14: =MVTJANV23!D14 -> 458343 | F14: =C14+D14-E14+K14 -> 1061343 | G14: =$S$40/$H$40*H14 -> #REF! | H14: =F14+D14+K14 -> 1522686 | I14: =VLOOKUP($A14,[16]HISTOJANV22!$A$6:$AQ$37,22,0) -> 0 | J14: =VLOOKUP($A14,[16]HISTOJANV22!$A$6:$AU$39,45,0) -> 7000 | K14: =IF(J14=0,0,J14-(L14+M14+N14)) -> 3000 | L14: =IF(J14=0,0,500) -> 500 | M14: =IF(J14=0,0,1000) -> 1000 | N14: =IF(J14=0,0,2500) -> 2500 | O14: =VLOOKUP($A14,[16]HISTOJANV22!$A$6:$AU$39,7,0) -> 0 | P14: =VLOOKUP($A14,[16]HISTOJANV22!$A$6:$AU$39,23,0) -> 0 | Q14: =VLOOKUP($A14,[16]HISTOJANV22!$A$6:$AU$39,46,0) -> 0 | R14: =VLOOKUP($A14,[16]HISTODEC21!$A$6:$AU$39,26,0) -> #REF! | S14: =R14*0/1200*12 -> #REF! | T14: =VLOOKUP($A14,[16]HISTOJANV22!$A$6:$AU$39,28,0) -> 0 | U14: =VLOOKUP($A14,[16]HISTOJANV22!$A$6:$AU$39,19,0) -> 0 | V14: =VLOOKUP($A14,[16]HISTOJANV22!$A$6:$AU$39,20,0) -> 0 | W14: =VLOOKUP($A14,[16]HISTOJANV22!$A$6:$AU$39,27,0) -> 0 | X14: =VLOOKUP($A14,[16]HISTOJANV22!$A$6:$AU$39,33,0) -> 0 | Y14: 155000 | AA14: =VLOOKUP($A14,[16]HISTOJANV22!$A$6:$AU$39,43,0) -> 0 | AB14: =VLOOKUP($A14,[16]HISTOJANV22!$A$6:$AU$39,44,0) -> 0 | AC14: =VLOOKUP($A14,[16]HISTOJANV22!$A$6:$AU$39,47,0) -> 0 | AD14: =VLOOKUP(A14,[16]HISTOJANV22!$A$6:$BB$36,54,0) -> 70000
A15: AS201611 | B15: =VLOOKUP(A15,[15]LISTADHERENT!$A$5:$J$50,3,0) -> HENGUE PAUL OMER | C15: =MVTJANV23!C15 -> 600000 | D15: =MVTJANV23!D15 -> 51112 | F15: =C15+D15-E15+K15 -> 654112 | G15: =$S$40/$H$40*H15 -> #REF! | H15: =F15+D15+K15 -> 708224 | I15: =VLOOKUP($A15,[16]HISTOJANV22!$A$6:$AQ$37,22,0) -> 0 | J15: =VLOOKUP($A15,[16]HISTOJANV22!$A$6:$AU$39,45,0) -> 7000 | K15: =IF(J15=0,0,J15-(L15+M15+N15)) -> 3000 | L15: =IF(J15=0,0,500) -> 500 | M15: =IF(J15=0,0,1000) -> 1000 | N15: =IF(J15=0,0,2500) -> 2500 | O15: =VLOOKUP($A15,[16]HISTOJANV22!$A$6:$AU$39,7,0) -> 0 | P15: =VLOOKUP($A15,[16]HISTOJANV22!$A$6:$AU$39,23,0) -> 0 | Q15: =VLOOKUP($A15,[16]HISTOJANV22!$A$6:$AU$39,46,0) -> 0 | R15: =VLOOKUP($A15,[16]HISTODEC21!$A$6:$AU$39,26,0) -> #REF! | S15: =R15*12/1200*12 -> #REF! | T15: =VLOOKUP($A15,[16]HISTOJANV22!$A$6:$AU$39,28,0) -> 0 | U15: =VLOOKUP($A15,[16]HISTOJANV22!$A$6:$AU$39,19,0) -> 0 | V15: =VLOOKUP($A15,[16]HISTOJANV22!$A$6:$AU$39,20,0) -> 0 | W15: =VLOOKUP($A15,[16]HISTOJANV22!$A$6:$AU$39,27,0) -> 0 | X15: =VLOOKUP($A15,[16]HISTOJANV22!$A$6:$AU$39,33,0) -> 0 | AA15: =VLOOKUP($A15,[16]HISTOJANV22!$A$6:$AU$39,43,0) -> 0 | AB15: =VLOOKUP($A15,[16]HISTOJANV22!$A$6:$AU$39,44,0) -> 0 | AC15: =VLOOKUP($A15,[16]HISTOJANV22!$A$6:$AU$39,47,0) -> 0 | AD15: =VLOOKUP(A15,[16]HISTOJANV22!$A$6:$BB$36,54,0) -> 0
A16: AS201613 | B16: =VLOOKUP(A16,[15]LISTADHERENT!$A$5:$J$50,3,0) -> HOTCHO BENJAMIN | C16: =MVTJANV23!C16 -> 600000 | D16: =MVTJANV23!D16 -> 16230 | F16: =C16+D16-E16+K16 -> 664230 | G16: =$S$40/$H$40*H16 -> #REF! | H16: =F16+D16+K16 -> 728460 | I16: =VLOOKUP($A16,[16]HISTOJANV22!$A$6:$AQ$37,22,0) -> 0 | J16: =VLOOKUP($A16,[16]HISTOJANV22!$A$6:$AU$39,45,0) -> 52000 | K16: =IF(J16=0,0,J16-(L16+M16+N16)) -> 48000 | L16: =IF(J16=0,0,500) -> 500 | M16: =IF(J16=0,0,1000) -> 1000 | N16: =IF(J16=0,0,2500) -> 2500 | O16: =VLOOKUP($A16,[16]HISTOJANV22!$A$6:$AU$39,7,0) -> 0 | P16: =VLOOKUP($A16,[16]HISTOJANV22!$A$6:$AU$39,23,0) -> 0 | Q16: =VLOOKUP($A16,[16]HISTOJANV22!$A$6:$AU$39,46,0) -> 0 | R16: =VLOOKUP($A16,[16]HISTODEC21!$A$6:$AU$39,26,0) -> #REF! | S16: =R16*12/1200*12 -> #REF! | T16: =VLOOKUP($A16,[16]HISTOJANV22!$A$6:$AU$39,28,0) -> 0 | U16: =VLOOKUP($A16,[16]HISTOJANV22!$A$6:$AU$39,19,0) -> 0 | V16: =VLOOKUP($A16,[16]HISTOJANV22!$A$6:$AU$39,20,0) -> 0 | W16: =VLOOKUP($A16,[16]HISTOJANV22!$A$6:$AU$39,27,0) -> 0 | X16: =VLOOKUP($A16,[16]HISTOJANV22!$A$6:$AU$39,33,0) -> 0 | AA16: =VLOOKUP($A16,[16]HISTOJANV22!$A$6:$AU$39,43,0) -> 0 | AB16: =VLOOKUP($A16,[16]HISTOJANV22!$A$6:$AU$39,44,0) -> 0 | AC16: =VLOOKUP($A16,[16]HISTOJANV22!$A$6:$AU$39,47,0) -> 0 | AD16: =VLOOKUP(A16,[16]HISTOJANV22!$A$6:$BB$36,54,0) -> 70000
A17: AS201617 | B17: =VLOOKUP(A17,[15]LISTADHERENT!$A$5:$J$50,3,0) -> KOUAMOU MOISE | C17: =MVTJANV23!C17 -> 600000 | D17: =MVTJANV23!D17 -> 53293 | F17: =C17+D17-E17+K17 -> 656293 | G17: =$S$40/$H$40*H17 -> #REF! | H17: =F17+D17+K17 -> 712586 | I17: =VLOOKUP($A17,[16]HISTOJANV22!$A$6:$AQ$37,22,0) -> 0 | J17: =VLOOKUP($A17,[16]HISTOJANV22!$A$6:$AU$39,45,0) -> 7000 | K17: =IF(J17=0,0,J17-(L17+M17+N17)) -> 3000 | L17: =IF(J17=0,0,500) -> 500 | M17: =IF(J17=0,0,1000) -> 1000 | N17: =IF(J17=0,0,2500) -> 2500 | O17: =VLOOKUP($A17,[16]HISTOJANV22!$A$6:$AU$39,7,0) -> 0 | P17: =VLOOKUP($A17,[16]HISTOJANV22!$A$6:$AU$39,23,0) -> 0 | Q17: =VLOOKUP($A17,[16]HISTOJANV22!$A$6:$AU$39,46,0) -> 0 | R17: =VLOOKUP($A17,[16]HISTODEC21!$A$6:$AU$39,26,0) -> #REF! | S17: =R17*12/1200*12 -> #REF! | T17: =VLOOKUP($A17,[16]HISTOJANV22!$A$6:$AU$39,28,0) -> 0 | U17: =VLOOKUP($A17,[16]HISTOJANV22!$A$6:$AU$39,19,0) -> 0 | V17: =VLOOKUP($A17,[16]HISTOJANV22!$A$6:$AU$39,20,0) -> 0 | W17: =VLOOKUP($A17,[16]HISTOJANV22!$A$6:$AU$39,27,0) -> 0 | X17: =VLOOKUP($A17,[16]HISTOJANV22!$A$6:$AU$39,33,0) -> 0 | AA17: =VLOOKUP($A17,[16]HISTOJANV22!$A$6:$AU$39,43,0) -> 0 | AB17: =VLOOKUP($A17,[16]HISTOJANV22!$A$6:$AU$39,44,0) -> 0 | AC17: =VLOOKUP($A17,[16]HISTOJANV22!$A$6:$AU$39,47,0) -> 0 | AD17: =VLOOKUP(A17,[16]HISTOJANV22!$A$6:$BB$36,54,0) -> 0
A18: AS201619 | B18: =VLOOKUP(A18,[15]LISTADHERENT!$A$5:$J$50,3,0) -> KOUATCHO MESSACK | C18: =MVTJANV23!C18 -> 600000 | D18: =MVTJANV23!D18 -> 6459 | F18: =C18+D18-E18+K18 -> 609459 | G18: =$S$40/$H$40*H18 -> #REF! | H18: =F18+D18+K18 -> 618918 | I18: =VLOOKUP($A18,[16]HISTOJANV22!$A$6:$AQ$37,22,0) -> 0 | J18: =VLOOKUP($A18,[16]HISTOJANV22!$A$6:$AU$39,45,0) -> 7000 | K18: =IF(J18=0,0,J18-(L18+M18+N18)) -> 3000 | L18: =IF(J18=0,0,500) -> 500 | M18: =IF(J18=0,0,1000) -> 1000 | N18: =IF(J18=0,0,2500) -> 2500 | O18: =VLOOKUP($A18,[16]HISTOJANV22!$A$6:$AU$39,7,0) -> 0 | P18: =VLOOKUP($A18,[16]HISTOJANV22!$A$6:$AU$39,23,0) -> 0 | Q18: =VLOOKUP($A18,[16]HISTOJANV22!$A$6:$AU$39,46,0) -> 0 | R18: =VLOOKUP($A18,[16]HISTODEC21!$A$6:$AU$39,26,0) -> 1000000 | S18: =R18*12/1200*12 -> 120000 | T18: =VLOOKUP($A18,[16]HISTOJANV22!$A$6:$AU$39,28,0) -> OKK | U18: =VLOOKUP($A18,[16]HISTOJANV22!$A$6:$AU$39,19,0) -> 0 | V18: =VLOOKUP($A18,[16]HISTOJANV22!$A$6:$AU$39,20,0) -> 0 | W18: =VLOOKUP($A18,[16]HISTOJANV22!$A$6:$AU$39,27,0) -> BANQUE | X18: =VLOOKUP($A18,[16]HISTOJANV22!$A$6:$AU$39,33,0) -> 0 | AA18: =VLOOKUP($A18,[16]HISTOJANV22!$A$6:$AU$39,43,0) -> 0 | AB18: =VLOOKUP($A18,[16]HISTOJANV22!$A$6:$AU$39,44,0) -> 0 | AC18: =VLOOKUP($A18,[16]HISTOJANV22!$A$6:$AU$39,47,0) -> 0 | AD18: =VLOOKUP(A18,[16]HISTOJANV22!$A$6:$BB$36,54,0) -> 0
A19: AS201620 | B19: =VLOOKUP(A19,[15]LISTADHERENT!$A$5:$J$50,3,0) -> LOWE JEAN | C19: =MVTJANV23!C19 -> 600000 | D19: =MVTJANV23!D19 -> 746 | F19: =C19+D19-E19+K19 -> 603746 | G19: =$S$40/$H$40*H19 -> #REF! | H19: =F19+D19+K19 -> 607492 | I19: =VLOOKUP($A19,[16]HISTOJANV22!$A$6:$AQ$37,22,0) -> 0 | J19: =VLOOKUP($A19,[16]HISTOJANV22!$A$6:$AU$39,45,0) -> 7000 | K19: =IF(J19=0,0,J19-(L19+M19+N19)) -> 3000 | L19: =IF(J19=0,0,500) -> 500 | M19: =IF(J19=0,0,1000) -> 1000 | N19: =IF(J19=0,0,2500) -> 2500 | O19: =VLOOKUP($A19,[16]HISTOJANV22!$A$6:$AU$39,7,0) -> 0 | P19: =VLOOKUP($A19,[16]HISTOJANV22!$A$6:$AU$39,23,0) -> 0 | Q19: =VLOOKUP($A19,[16]HISTOJANV22!$A$6:$AU$39,46,0) -> 0 | R19: =VLOOKUP($A19,[16]HISTODEC21!$A$6:$AU$39,26,0) -> 500000 | S19: =R19*12/1200*12 -> 60000 | T19: =VLOOKUP($A19,[16]HISTOJANV22!$A$6:$AU$39,28,0) -> OKK | U19: =VLOOKUP($A19,[16]HISTOJANV22!$A$6:$AU$39,19,0) -> 0 | V19: =VLOOKUP($A19,[16]HISTOJANV22!$A$6:$AU$39,20,0) -> 0 | W19: =VLOOKUP($A19,[16]HISTOJANV22!$A$6:$AU$39,27,0) -> BANQUE | X19: =VLOOKUP($A19,[16]HISTOJANV22!$A$6:$AU$39,33,0) -> 0 | AA19: =VLOOKUP($A19,[16]HISTOJANV22!$A$6:$AU$39,43,0) -> 0 | AB19: =VLOOKUP($A19,[16]HISTOJANV22!$A$6:$AU$39,44,0) -> 0 | AC19: =VLOOKUP($A19,[16]HISTOJANV22!$A$6:$AU$39,47,0) -> 0 | AD19: =VLOOKUP(A19,[16]HISTOJANV22!$A$6:$BB$36,54,0) -> 0
A20: AS201649 | B20: =VLOOKUP(A20,[15]LISTADHERENT!$A$5:$J$50,3,0) -> MBOGNING TUGMA GUY | C20: =MVTJANV23!C20 -> 600000 | D20: =MVTJANV23!D20 -> 47746 | F20: =C20+D20-E20+K20 -> 650746 | G20: =$S$40/$H$40*H20 -> #REF! | H20: =F20+D20+K20 -> 701492 | I20: =VLOOKUP($A20,[16]HISTOJANV22!$A$6:$AQ$37,22,0) -> 0 | J20: =VLOOKUP($A20,[16]HISTOJANV22!$A$6:$AU$39,45,0) -> 7000 | K20: =IF(J20=0,0,J20-(L20+M20+N20)) -> 3000 | L20: =IF(J20=0,0,500) -> 500 | M20: =IF(J20=0,0,1000) -> 1000 | N20: =IF(J20=0,0,2500) -> 2500 | O20: =VLOOKUP($A20,[16]HISTOJANV22!$A$6:$AU$39,7,0) -> 0 | P20: =VLOOKUP($A20,[16]HISTOJANV22!$A$6:$AU$39,23,0) -> 0 | Q20: =VLOOKUP($A20,[16]HISTOJANV22!$A$6:$AU$39,46,0) -> 0 | R20: =VLOOKUP($A20,[16]HISTODEC21!$A$6:$AU$39,26,0) -> 1050000 | S20: =R20*12/1200*12 -> 126000 | T20: =VLOOKUP($A20,[16]HISTOJANV22!$A$6:$AU$39,28,0) -> 0 | U20: =VLOOKUP($A20,[16]HISTOJANV22!$A$6:$AU$39,19,0) -> 1050000 | V20: =VLOOKUP($A20,[16]HISTOJANV22!$A$6:$AU$39,20,0) -> BANQUE | W20: =VLOOKUP($A20,[16]HISTOJANV22!$A$6:$AU$39,27,0) -> BANQUE | X20: =VLOOKUP($A20,[16]HISTOJANV22!$A$6:$AU$39,33,0) -> 0 | AA20: =VLOOKUP($A20,[16]HISTOJANV22!$A$6:$AU$39,43,0) -> 0 | AB20: =VLOOKUP($A20,[16]HISTOJANV22!$A$6:$AU$39,44,0) -> 0 | AC20: =VLOOKUP($A20,[16]HISTOJANV22!$A$6:$AU$39,47,0) -> 0 | AD20: =VLOOKUP(A20,[16]HISTOJANV22!$A$6:$BB$36,54,0) -> 0
A21: AS201639 | B21: =VLOOKUP(A21,[15]LISTADHERENT!$A$5:$J$50,3,0) -> NANGUEN MARTIN | C21: =MVTJANV23!C21 -> 600000 | D21: =MVTJANV23!D21 -> 51343 | F21: =C21+D21-E21+K21 -> 654343 | G21: =$S$40/$H$40*H21 -> #REF! | H21: =F21+D21+K21 -> 708686 | I21: =VLOOKUP($A21,[16]HISTOJANV22!$A$6:$AQ$37,22,0) -> 0 | J21: =VLOOKUP($A21,[16]HISTOJANV22!$A$6:$AU$39,45,0) -> 7000 | K21: =IF(J21=0,0,J21-(L21+M21+N21)) -> 3000 | L21: =IF(J21=0,0,500) -> 500 | M21: =IF(J21=0,0,1000) -> 1000 | N21: =IF(J21=0,0,2500) -> 2500 | O21: =VLOOKUP($A21,[16]HISTOJANV22!$A$6:$AU$39,7,0) -> 0 | P21: =VLOOKUP($A21,[16]HISTOJANV22!$A$6:$AU$39,23,0) -> 0 | Q21: =VLOOKUP($A21,[16]HISTOJANV22!$A$6:$AU$39,46,0) -> 0 | R21: =VLOOKUP($A21,[16]HISTODEC21!$A$6:$AU$39,26,0) -> #REF! | S21: =R21*12/1200*12 -> #REF! | T21: =VLOOKUP($A21,[16]HISTOJANV22!$A$6:$AU$39,28,0) -> 0 | U21: =VLOOKUP($A21,[16]HISTOJANV22!$A$6:$AU$39,19,0) -> 0 | V21: =VLOOKUP($A21,[16]HISTOJANV22!$A$6:$AU$39,20,0) -> 0 | W21: =VLOOKUP($A21,[16]HISTOJANV22!$A$6:$AU$39,27,0) -> 0 | X21: =VLOOKUP($A21,[16]HISTOJANV22!$A$6:$AU$39,33,0) -> 0 | AA21: =VLOOKUP($A21,[16]HISTOJANV22!$A$6:$AU$39,43,0) -> 0 | AB21: =VLOOKUP($A21,[16]HISTOJANV22!$A$6:$AU$39,44,0) -> 0 | AC21: =VLOOKUP($A21,[16]HISTOJANV22!$A$6:$AU$39,47,0) -> 0 | AD21: =VLOOKUP(A21,[16]HISTOJANV22!$A$6:$BB$36,54,0) -> 0
A22: AS201621 | B22: =VLOOKUP(A22,[15]LISTADHERENT!$A$5:$J$50,3,0) -> NANKAM APPOLINAIRE | C22: =MVTJANV23!C22 -> 600000 | D22: =MVTJANV23!D22 -> 140918 | F22: =C22+D22-E22+K22 -> 743918 | G22: =$S$40/$H$40*H22 -> #REF! | H22: =F22+D22+K22 -> 887836 | I22: =VLOOKUP($A22,[16]HISTOJANV22!$A$6:$AQ$37,22,0) -> 0 | J22: =VLOOKUP($A22,[16]HISTOJANV22!$A$6:$AU$39,45,0) -> 7000 | K22: =IF(J22=0,0,J22-(L22+M22+N22)) -> 3000 | L22: =IF(J22=0,0,500) -> 500 | M22: =IF(J22=0,0,1000) -> 1000 | N22: =IF(J22=0,0,2500) -> 2500 | O22: =VLOOKUP($A22,[16]HISTOJANV22!$A$6:$AU$39,7,0) -> 0 | P22: =VLOOKUP($A22,[16]HISTOJANV22!$A$6:$AU$39,23,0) -> 0 | Q22: =VLOOKUP($A22,[16]HISTOJANV22!$A$6:$AU$39,46,0) -> 0 | R22: =VLOOKUP($A22,[16]HISTODEC21!$A$6:$AU$39,26,0) -> 924000 | S22: =R22*12/1200*12 -> 110880 | T22: =VLOOKUP($A22,[16]HISTOJANV22!$A$6:$AU$39,28,0) -> 0 | U22: =VLOOKUP($A22,[16]HISTOJANV22!$A$6:$AU$39,19,0) -> 924000 | V22: =VLOOKUP($A22,[16]HISTOJANV22!$A$6:$AU$39,20,0) -> BANQUE | W22: =VLOOKUP($A22,[16]HISTOJANV22!$A$6:$AU$39,27,0) -> 0 | X22: =VLOOKUP($A22,[16]HISTOJANV22!$A$6:$AU$39,33,0) -> 0 | Y22: 50000 | AA22: =VLOOKUP($A22,[16]HISTOJANV22!$A$6:$AU$39,43,0) -> 0 | AB22: =VLOOKUP($A22,[16]HISTOJANV22!$A$6:$AU$39,44,0) -> 0 | AC22: =VLOOKUP($A22,[16]HISTOJANV22!$A$6:$AU$39,47,0) -> 0 | AD22: =VLOOKUP(A22,[16]HISTOJANV22!$A$6:$BB$36,54,0) -> 0
A23: AS201622 | B23: =VLOOKUP(A23,[15]LISTADHERENT!$A$5:$J$50,3,0) -> NDJOMO ETIENNE | C23: =MVTJANV23!C23 -> 600000 | D23: =MVTJANV23!D23 -> 283210 | F23: =C23+D23-E23+K23 -> 896210 | G23: =$S$40/$H$40*H23 -> #REF! | H23: =F23+D23+K23 -> 1192420 | I23: =VLOOKUP($A23,[16]HISTOJANV22!$A$6:$AQ$37,22,0) -> 0 | J23: =VLOOKUP($A23,[16]HISTOJANV22!$A$6:$AU$39,45,0) -> 17000 | K23: =IF(J23=0,0,J23-(L23+M23+N23)) -> 13000 | L23: =IF(J23=0,0,500) -> 500 | M23: =IF(J23=0,0,1000) -> 1000 | N23: =IF(J23=0,0,2500) -> 2500 | O23: =VLOOKUP($A23,[16]HISTOJANV22!$A$6:$AU$39,7,0) -> 0 | P23: =VLOOKUP($A23,[16]HISTOJANV22!$A$6:$AU$39,23,0) -> 0 | Q23: =VLOOKUP($A23,[16]HISTOJANV22!$A$6:$AU$39,46,0) -> 0 | R23: =VLOOKUP($A23,[16]HISTODEC21!$A$6:$AU$39,26,0) -> 500000 | S23: =R23*12/1200*12 -> 60000 | T23: =VLOOKUP($A23,[16]HISTOJANV22!$A$6:$AU$39,28,0) -> OKK | U23: =VLOOKUP($A23,[16]HISTOJANV22!$A$6:$AU$39,19,0) -> 0 | V23: =VLOOKUP($A23,[16]HISTOJANV22!$A$6:$AU$39,20,0) -> 0 | W23: =VLOOKUP($A23,[16]HISTOJANV22!$A$6:$AU$39,27,0) -> BANQUE | X23: =VLOOKUP($A23,[16]HISTOJANV22!$A$6:$AU$39,33,0) -> 0 | AA23: =VLOOKUP($A23,[16]HISTOJANV22!$A$6:$AU$39,43,0) -> 0 | AB23: =VLOOKUP($A23,[16]HISTOJANV22!$A$6:$AU$39,44,0) -> 0 | AC23: =VLOOKUP($A23,[16]HISTOJANV22!$A$6:$AU$39,47,0) -> 0 | AD23: =VLOOKUP(A23,[16]HISTOJANV22!$A$6:$BB$36,54,0) -> 0
A24: AS201624 | B24: =VLOOKUP(A24,[15]LISTADHERENT!$A$5:$J$50,3,0) -> NGONDIEP CLAUDE | C24: =MVTJANV23!C24 -> 600000 | D24: =MVTJANV23!D24 -> 39787 | F24: =C24+D24-E24+K24 -> 647787 | G24: =$S$40/$H$40*H24 -> #REF! | H24: =F24+D24+K24 -> 695574 | I24: =VLOOKUP($A24,[16]HISTOJANV22!$A$6:$AQ$37,22,0) -> 0 | J24: =VLOOKUP($A24,[16]HISTOJANV22!$A$6:$AU$39,45,0) -> 12000 | K24: =IF(J24=0,0,J24-(L24+M24+N24)) -> 8000 | L24: =IF(J24=0,0,500) -> 500 | M24: =IF(J24=0,0,1000) -> 1000 | N24: =IF(J24=0,0,2500) -> 2500 | O24: =VLOOKUP($A24,[16]HISTOJANV22!$A$6:$AU$39,7,0) -> 0 | P24: =VLOOKUP($A24,[16]HISTOJANV22!$A$6:$AU$39,23,0) -> 0 | Q24: =VLOOKUP($A24,[16]HISTOJANV22!$A$6:$AU$39,46,0) -> 0 | R24: =VLOOKUP($A24,[16]HISTODEC21!$A$6:$AU$39,26,0) -> 1000000 | S24: =R24*12/1200*12 -> 120000 | T24: =VLOOKUP($A24,[16]HISTOJANV22!$A$6:$AU$39,28,0) -> OKK | U24: =VLOOKUP($A24,[16]HISTOJANV22!$A$6:$AU$39,19,0) -> 0 | V24: =VLOOKUP($A24,[16]HISTOJANV22!$A$6:$AU$39,20,0) -> 0 | W24: =VLOOKUP($A24,[16]HISTOJANV22!$A$6:$AU$39,27,0) -> BANQUE | X24: =VLOOKUP($A24,[16]HISTOJANV22!$A$6:$AU$39,33,0) -> 0 | AA24: =VLOOKUP($A24,[16]HISTOJANV22!$A$6:$AU$39,43,0) -> 0 | AB24: =VLOOKUP($A24,[16]HISTOJANV22!$A$6:$AU$39,44,0) -> 0 | AC24: =VLOOKUP($A24,[16]HISTOJANV22!$A$6:$AU$39,47,0) -> 0 | AD24: =VLOOKUP(A24,[16]HISTOJANV22!$A$6:$BB$36,54,0) -> 70000
A25: AS201626 | B25: =VLOOKUP(A25,[15]LISTADHERENT!$A$5:$J$50,3,0) -> NGUIEMEGNI MATHIEU BLAISE | C25: =MVTJANV23!C25 -> 600000 | D25: =MVTJANV23!D25 -> 13696 | F25: =C25+D25-E25+K25 -> 616696 | G25: =$S$40/$H$40*H25 -> #REF! | H25: =F25+D25+K25 -> 633392 | I25: =VLOOKUP($A25,[16]HISTOJANV22!$A$6:$AQ$37,22,0) -> 0 | J25: =VLOOKUP($A25,[16]HISTOJANV22!$A$6:$AU$39,45,0) -> 7000 | K25: =IF(J25=0,0,J25-(L25+M25+N25)) -> 3000 | L25: =IF(J25=0,0,500) -> 500 | M25: =IF(J25=0,0,1000) -> 1000 | N25: =IF(J25=0,0,2500) -> 2500 | O25: =VLOOKUP($A25,[16]HISTOJANV22!$A$6:$AU$39,7,0) -> 0 | P25: =VLOOKUP($A25,[16]HISTOJANV22!$A$6:$AU$39,23,0) -> 0 | Q25: =VLOOKUP($A25,[16]HISTOJANV22!$A$6:$AU$39,46,0) -> 0 | R25: =VLOOKUP($A25,[16]HISTODEC21!$A$6:$AU$39,26,0) -> 1000000 | S25: =R25*12/1200*12 -> 120000 | T25: =VLOOKUP($A25,[16]HISTOJANV22!$A$6:$AU$39,28,0) -> OKK | U25: =VLOOKUP($A25,[16]HISTOJANV22!$A$6:$AU$39,19,0) -> 0 | V25: =VLOOKUP($A25,[16]HISTOJANV22!$A$6:$AU$39,20,0) -> 0 | W25: =VLOOKUP($A25,[16]HISTOJANV22!$A$6:$AU$39,27,0) -> BANQUE | X25: =VLOOKUP($A25,[16]HISTOJANV22!$A$6:$AU$39,33,0) -> 0 | AA25: =VLOOKUP($A25,[16]HISTOJANV22!$A$6:$AU$39,43,0) -> 0 | AB25: =VLOOKUP($A25,[16]HISTOJANV22!$A$6:$AU$39,44,0) -> 0 | AC25: =VLOOKUP($A25,[16]HISTOJANV22!$A$6:$AU$39,47,0) -> 0 | AD25: =VLOOKUP(A25,[16]HISTOJANV22!$A$6:$BB$36,54,0) -> 70000
A26: AS201628 | B26: =VLOOKUP(A26,[15]LISTADHERENT!$A$5:$J$50,3,0) -> NKAMGANG JUSTIN DEJOLIE | C26: =MVTJANV23!C26 -> 600000 | D26: =MVTJANV23!D26 -> 575 | F26: =C26+D26-E26+K26 -> 603575 | G26: =$S$40/$H$40*H26 -> #REF! | H26: =F26+D26+K26 -> 607150 | I26: =VLOOKUP($A26,[16]HISTOJANV22!$A$6:$AQ$37,22,0) -> 0 | J26: =VLOOKUP($A26,[16]HISTOJANV22!$A$6:$AU$39,45,0) -> 7000 | K26: =IF(J26=0,0,J26-(L26+M26+N26)) -> 3000 | L26: =IF(J26=0,0,500) -> 500 | M26: =IF(J26=0,0,1000) -> 1000 | N26: =IF(J26=0,0,2500) -> 2500 | O26: =VLOOKUP($A26,[16]HISTOJANV22!$A$6:$AU$39,7,0) -> 0 | P26: =VLOOKUP($A26,[16]HISTOJANV22!$A$6:$AU$39,23,0) -> 0 | Q26: =VLOOKUP($A26,[16]HISTOJANV22!$A$6:$AU$39,46,0) -> 0 | R26: =VLOOKUP($A26,[16]HISTODEC21!$A$6:$AU$39,26,0) -> 1155000 | S26: =R26*0/1200*12 -> 0 | T26: =VLOOKUP($A26,[16]HISTOJANV22!$A$6:$AU$39,28,0) -> 0 | U26: =VLOOKUP($A26,[16]HISTOJANV22!$A$6:$AU$39,19,0) -> 0 | V26: =VLOOKUP($A26,[16]HISTOJANV22!$A$6:$AU$39,20,0) -> 0 | W26: =VLOOKUP($A26,[16]HISTOJANV22!$A$6:$AU$39,27,0) -> BANQUE | X26: =VLOOKUP($A26,[16]HISTOJANV22!$A$6:$AU$39,33,0) -> 0 | Y26: 155000 | AA26: =VLOOKUP($A26,[16]HISTOJANV22!$A$6:$AU$39,43,0) -> 0 | AB26: =VLOOKUP($A26,[16]HISTOJANV22!$A$6:$AU$39,44,0) -> 0 | AC26: =VLOOKUP($A26,[16]HISTOJANV22!$A$6:$AU$39,47,0) -> 0 | AD26: =VLOOKUP(A26,[16]HISTOJANV22!$A$6:$BB$36,54,0) -> 0
A27: AS201656 | B27: =VLOOKUP(A27,[15]LISTADHERENT!$A$5:$J$50,3,0) -> NOUBE ETIENNE | C27: =MVTJANV23!C27 -> 0 | D27: =MVTJANV23!D27 -> 0 | F27: =C27+D27-E27+K27 -> #N/A | G27: =$S$40/$H$40*H27 -> #REF! | H27: =F27+D27+K27 -> #N/A | I27: =VLOOKUP($A27,[16]HISTOJANV22!$A$6:$AQ$37,22,0) -> #N/A | J27: =VLOOKUP($A27,[16]HISTOJANV22!$A$6:$AU$39,45,0) -> #N/A | K27: =IF(J27=0,0,J27-(L27+M27+N27)) -> #N/A | L27: =IF(J27=0,0,500) -> #N/A | M27: =IF(J27=0,0,1000) -> #N/A | N27: =IF(J27=0,0,2500) -> #N/A | O27: =VLOOKUP($A27,[16]HISTOJANV22!$A$6:$AU$39,7,0) -> #N/A | P27: =VLOOKUP($A27,[16]HISTOJANV22!$A$6:$AU$39,23,0) -> #N/A | Q27: =VLOOKUP($A27,[16]HISTOJANV22!$A$6:$AU$39,46,0) -> #N/A | R27: =VLOOKUP($A27,[16]HISTODEC21!$A$6:$AU$39,26,0) -> #N/A | S27: =R27*12/1200*12 -> #N/A | T27: =VLOOKUP($A27,[16]HISTOJANV22!$A$6:$AU$39,28,0) -> #N/A | U27: =VLOOKUP($A27,[16]HISTOJANV22!$A$6:$AU$39,19,0) -> #N/A | V27: =VLOOKUP($A27,[16]HISTOJANV22!$A$6:$AU$39,20,0) -> #N/A | W27: =VLOOKUP($A27,[16]HISTOJANV22!$A$6:$AU$39,27,0) -> #N/A | X27: =VLOOKUP($A27,[16]HISTOJANV22!$A$6:$AU$39,33,0) -> #N/A | AA27: =VLOOKUP($A27,[16]HISTOJANV22!$A$6:$AU$39,43,0) -> #N/A | AB27: =VLOOKUP($A27,[16]HISTOJANV22!$A$6:$AU$39,44,0) -> #N/A | AC27: =VLOOKUP($A27,[16]HISTOJANV22!$A$6:$AU$39,47,0) -> #N/A | AD27: =VLOOKUP(A27,[16]HISTOJANV22!$A$6:$BB$36,54,0) -> #N/A
A28: AS201633 | B28: =VLOOKUP(A28,[15]LISTADHERENT!$A$5:$J$50,3,0) -> PATEGO NJOSSU GUSTAVE | C28: =MVTJANV23!C28 -> 600000 | D28: =MVTJANV23!D28 -> 21452 | F28: =C28+D28-E28+K28 -> 624452 | G28: =$S$40/$H$40*H28 -> #REF! | H28: =F28+D28+K28 -> 648904 | I28: =VLOOKUP($A28,[16]HISTOJANV22!$A$6:$AQ$37,22,0) -> 0 | J28: =VLOOKUP($A28,[16]HISTOJANV22!$A$6:$AU$39,45,0) -> 7000 | K28: =IF(J28=0,0,J28-(L28+M28+N28)) -> 3000 | L28: =IF(J28=0,0,500) -> 500 | M28: =IF(J28=0,0,1000) -> 1000 | N28: =IF(J28=0,0,2500) -> 2500 | O28: =VLOOKUP($A28,[16]HISTOJANV22!$A$6:$AU$39,7,0) -> 0 | P28: =VLOOKUP($A28,[16]HISTOJANV22!$A$6:$AU$39,23,0) -> 0 | Q28: =VLOOKUP($A28,[16]HISTOJANV22!$A$6:$AU$39,46,0) -> 0 | R28: =VLOOKUP($A28,[16]HISTODEC21!$A$6:$AU$39,26,0) -> #REF! | S28: =R28*12/1200*12 -> #REF! | T28: =VLOOKUP($A28,[16]HISTOJANV22!$A$6:$AU$39,28,0) -> 0 | U28: =VLOOKUP($A28,[16]HISTOJANV22!$A$6:$AU$39,19,0) -> 0 | V28: =VLOOKUP($A28,[16]HISTOJANV22!$A$6:$AU$39,20,0) -> 0 | W28: =VLOOKUP($A28,[16]HISTOJANV22!$A$6:$AU$39,27,0) -> 0 | X28: =VLOOKUP($A28,[16]HISTOJANV22!$A$6:$AU$39,33,0) -> 0 | AA28: =VLOOKUP($A28,[16]HISTOJANV22!$A$6:$AU$39,43,0) -> 0 | AB28: =VLOOKUP($A28,[16]HISTOJANV22!$A$6:$AU$39,44,0) -> 0 | AC28: =VLOOKUP($A28,[16]HISTOJANV22!$A$6:$AU$39,47,0) -> 0 | AD28: =VLOOKUP(A28,[16]HISTOJANV22!$A$6:$BB$36,54,0) -> 0
A29: AS201657 | B29: =VLOOKUP(A29,[15]LISTADHERENT!$A$5:$J$50,3,0) -> SEUMO POLYCARPE | C29: =MVTJANV23!C29 -> 0 | D29: =MVTJANV23!D29 -> 0 | F29: =C29+D29-E29+K29 -> #N/A | G29: =$S$40/$H$40*H29 -> #REF! | H29: =F29+D29+K29 -> #N/A | I29: =VLOOKUP($A29,[16]HISTOJANV22!$A$6:$AQ$37,22,0) -> #N/A | J29: =VLOOKUP($A29,[16]HISTOJANV22!$A$6:$AU$39,45,0) -> #N/A | K29: =IF(J29=0,0,J29-(L29+M29+N29)) -> #N/A | L29: =IF(J29=0,0,500) -> #N/A | M29: =IF(J29=0,0,1000) -> #N/A | N29: =IF(J29=0,0,2500) -> #N/A | O29: =VLOOKUP($A29,[16]HISTOJANV22!$A$6:$AU$39,7,0) -> #N/A | P29: =VLOOKUP($A29,[16]HISTOJANV22!$A$6:$AU$39,23,0) -> #N/A | Q29: =VLOOKUP($A29,[16]HISTOJANV22!$A$6:$AU$39,46,0) -> #N/A | R29: =VLOOKUP($A29,[16]HISTODEC21!$A$6:$AU$39,26,0) -> #N/A | S29: =R29*12/1200*12 -> #N/A | T29: =VLOOKUP($A29,[16]HISTOJANV22!$A$6:$AU$39,28,0) -> #N/A | U29: =VLOOKUP($A29,[16]HISTOJANV22!$A$6:$AU$39,19,0) -> #N/A | V29: =VLOOKUP($A29,[16]HISTOJANV22!$A$6:$AU$39,20,0) -> #N/A | W29: =VLOOKUP($A29,[16]HISTOJANV22!$A$6:$AU$39,27,0) -> #N/A | X29: =VLOOKUP($A29,[16]HISTOJANV22!$A$6:$AU$39,33,0) -> #N/A | AA29: =VLOOKUP($A29,[16]HISTOJANV22!$A$6:$AU$39,43,0) -> #N/A | AB29: =VLOOKUP($A29,[16]HISTOJANV22!$A$6:$AU$39,44,0) -> #N/A | AC29: =VLOOKUP($A29,[16]HISTOJANV22!$A$6:$AU$39,47,0) -> #N/A | AD29: =VLOOKUP(A29,[16]HISTOJANV22!$A$6:$BB$36,54,0) -> #N/A
A30: AS201653 | B30: =VLOOKUP(A30,[15]LISTADHERENT!$A$5:$J$50,3,0) -> SIME BRICE | C30: =MVTJANV23!C30 -> 600000 | D30: =MVTJANV23!D30 -> 200752 | F30: =C30+D30-E30+K30 -> 803752 | G30: =$S$40/$H$40*H30 -> #REF! | H30: =F30+D30+K30 -> 1007504 | I30: =VLOOKUP($A30,[16]HISTOJANV22!$A$6:$AQ$37,22,0) -> 0 | J30: =VLOOKUP($A30,[16]HISTOJANV22!$A$6:$AU$39,45,0) -> 7000 | K30: =IF(J30=0,0,J30-(L30+M30+N30)) -> 3000 | L30: =IF(J30=0,0,500) -> 500 | M30: =IF(J30=0,0,1000) -> 1000 | N30: =IF(J30=0,0,2500) -> 2500 | O30: =VLOOKUP($A30,[16]HISTOJANV22!$A$6:$AU$39,7,0) -> 0 | P30: =VLOOKUP($A30,[16]HISTOJANV22!$A$6:$AU$39,23,0) -> 0 | Q30: =VLOOKUP($A30,[16]HISTOJANV22!$A$6:$AU$39,46,0) -> 0 | R30: =VLOOKUP($A30,[16]HISTODEC21!$A$6:$AU$39,26,0) -> #REF! | S30: =R30*12/1200*12 -> #REF! | T30: =VLOOKUP($A30,[16]HISTOJANV22!$A$6:$AU$39,28,0) -> 0 | U30: =VLOOKUP($A30,[16]HISTOJANV22!$A$6:$AU$39,19,0) -> 0 | V30: =VLOOKUP($A30,[16]HISTOJANV22!$A$6:$AU$39,20,0) -> 0 | W30: =VLOOKUP($A30,[16]HISTOJANV22!$A$6:$AU$39,27,0) -> 0 | X30: =VLOOKUP($A30,[16]HISTOJANV22!$A$6:$AU$39,33,0) -> 0 | AA30: =VLOOKUP($A30,[16]HISTOJANV22!$A$6:$AU$39,43,0) -> 0 | AB30: =VLOOKUP($A30,[16]HISTOJANV22!$A$6:$AU$39,44,0) -> 0 | AC30: =VLOOKUP($A30,[16]HISTOJANV22!$A$6:$AU$39,47,0) -> 0 | AD30: =VLOOKUP(A30,[16]HISTOJANV22!$A$6:$BB$36,54,0) -> 0
A31: AS201638 | B31: =VLOOKUP(A31,[15]LISTADHERENT!$A$5:$J$50,3,0) -> SIMO PIERRE | C31: =MVTJANV23!C31 -> 600000 | D31: =MVTJANV23!D31 -> 103606 | F31: =C31+D31-E31+K31 -> 721606 | G31: =$S$40/$H$40*H31 -> #REF! | H31: =F31+D31+K31 -> 843212 | I31: =VLOOKUP($A31,[16]HISTOJANV22!$A$6:$AQ$37,22,0) -> 0 | J31: =VLOOKUP($A31,[16]HISTOJANV22!$A$6:$AU$39,45,0) -> 22000 | K31: =IF(J31=0,0,J31-(L31+M31+N31)) -> 18000 | L31: =IF(J31=0,0,500) -> 500 | M31: =IF(J31=0,0,1000) -> 1000 | N31: =IF(J31=0,0,2500) -> 2500 | O31: =VLOOKUP($A31,[16]HISTOJANV22!$A$6:$AU$39,7,0) -> 0 | P31: =VLOOKUP($A31,[16]HISTOJANV22!$A$6:$AU$39,23,0) -> 0 | Q31: =VLOOKUP($A31,[16]HISTOJANV22!$A$6:$AU$39,46,0) -> 0 | R31: =VLOOKUP($A31,[16]HISTODEC21!$A$6:$AU$39,26,0) -> #REF! | S31: =R31*12/1200*12 -> #REF! | T31: =VLOOKUP($A31,[16]HISTOJANV22!$A$6:$AU$39,28,0) -> 0 | U31: =VLOOKUP($A31,[16]HISTOJANV22!$A$6:$AU$39,19,0) -> 0 | V31: =VLOOKUP($A31,[16]HISTOJANV22!$A$6:$AU$39,20,0) -> 0 | W31: =VLOOKUP($A31,[16]HISTOJANV22!$A$6:$AU$39,27,0) -> BANQUE | X31: =VLOOKUP($A31,[16]HISTOJANV22!$A$6:$AU$39,33,0) -> 0 | AA31: =VLOOKUP($A31,[16]HISTOJANV22!$A$6:$AU$39,43,0) -> 0 | AB31: =VLOOKUP($A31,[16]HISTOJANV22!$A$6:$AU$39,44,0) -> 0 | AC31: =VLOOKUP($A31,[16]HISTOJANV22!$A$6:$AU$39,47,0) -> 0 | AD31: =VLOOKUP(A31,[16]HISTOJANV22!$A$6:$BB$36,54,0) -> 70000
A32: AS201641 | B32: =VLOOKUP(A32,[15]LISTADHERENT!$A$5:$J$50,3,0) -> TCHOUAMOU MATHIEU | C32: =MVTJANV23!C32 -> 600000 | D32: =MVTJANV23!D32 -> 4208 | F32: =C32+D32-E32+K32 -> 607208 | G32: =$S$40/$H$40*H32 -> #REF! | H32: =F32+D32+K32 -> 614416 | I32: =VLOOKUP($A32,[16]HISTOJANV22!$A$6:$AQ$37,22,0) -> 0 | J32: =VLOOKUP($A32,[16]HISTOJANV22!$A$6:$AU$39,45,0) -> 7000 | K32: =IF(J32=0,0,J32-(L32+M32+N32)) -> 3000 | L32: =IF(J32=0,0,500) -> 500 | M32: =IF(J32=0,0,1000) -> 1000 | N32: =IF(J32=0,0,2500) -> 2500 | O32: =VLOOKUP($A32,[16]HISTOJANV22!$A$6:$AU$39,7,0) -> 0 | P32: =VLOOKUP($A32,[16]HISTOJANV22!$A$6:$AU$39,23,0) -> 0 | Q32: =VLOOKUP($A32,[16]HISTOJANV22!$A$6:$AU$39,46,0) -> 0 | R32: =VLOOKUP($A32,[16]HISTODEC21!$A$6:$AU$39,26,0) -> 560000 | S32: =R32*12/1200*12 -> 67200 | T32: =VLOOKUP($A32,[16]HISTOJANV22!$A$6:$AU$39,28,0) -> OKK | U32: =VLOOKUP($A32,[16]HISTOJANV22!$A$6:$AU$39,19,0) -> 0 | V32: =VLOOKUP($A32,[16]HISTOJANV22!$A$6:$AU$39,20,0) -> 0 | W32: =VLOOKUP($A32,[16]HISTOJANV22!$A$6:$AU$39,27,0) -> BANQUE | X32: =VLOOKUP($A32,[16]HISTOJANV22!$A$6:$AU$39,33,0) -> 0 | AA32: =VLOOKUP($A32,[16]HISTOJANV22!$A$6:$AU$39,43,0) -> 0 | AB32: =VLOOKUP($A32,[16]HISTOJANV22!$A$6:$AU$39,44,0) -> 0 | AC32: =VLOOKUP($A32,[16]HISTOJANV22!$A$6:$AU$39,47,0) -> 0 | AD32: =VLOOKUP(A32,[16]HISTOJANV22!$A$6:$BB$36,54,0) -> 0
A33: AS201643 | B33: =VLOOKUP(A33,[15]LISTADHERENT!$A$5:$J$50,3,0) -> TCHOUTOU NANA CLAUDE | C33: =MVTJANV23!C33 -> 0 | D33: =MVTJANV23!D33 -> 0 | F33: =C33+D33-E33+K33 -> #N/A | G33: =$S$40/$H$40*H33 -> #REF! | H33: =F33+D33+K33 -> #N/A | I33: =VLOOKUP($A33,[16]HISTOJANV22!$A$6:$AQ$37,22,0) -> #N/A | J33: =VLOOKUP($A33,[16]HISTOJANV22!$A$6:$AU$39,45,0) -> #N/A | K33: =IF(J33=0,0,J33-(L33+M33+N33)) -> #N/A | L33: =IF(J33=0,0,500) -> #N/A | M33: =IF(J33=0,0,1000) -> #N/A | N33: =IF(J33=0,0,2500) -> #N/A | O33: =VLOOKUP($A33,[16]HISTOJANV22!$A$6:$AU$39,7,0) -> #N/A | P33: =VLOOKUP($A33,[16]HISTOJANV22!$A$6:$AU$39,23,0) -> #N/A | Q33: =VLOOKUP($A33,[16]HISTOJANV22!$A$6:$AU$39,46,0) -> #N/A | R33: =VLOOKUP($A33,[16]HISTODEC21!$A$6:$AU$39,26,0) -> #N/A | S33: =R33*12/1200*12 -> #N/A | T33: =VLOOKUP($A33,[16]HISTOJANV22!$A$6:$AU$39,28,0) -> #N/A | U33: =VLOOKUP($A33,[16]HISTOJANV22!$A$6:$AU$39,19,0) -> #N/A | V33: =VLOOKUP($A33,[16]HISTOJANV22!$A$6:$AU$39,20,0) -> #N/A | W33: =VLOOKUP($A33,[16]HISTOJANV22!$A$6:$AU$39,27,0) -> #N/A | X33: =VLOOKUP($A33,[16]HISTOJANV22!$A$6:$AU$39,33,0) -> #N/A | AA33: =VLOOKUP($A33,[16]HISTOJANV22!$A$6:$AU$39,43,0) -> #N/A | AB33: =VLOOKUP($A33,[16]HISTOJANV22!$A$6:$AU$39,44,0) -> #N/A | AC33: =VLOOKUP($A33,[16]HISTOJANV22!$A$6:$AU$39,47,0) -> #N/A | AD33: =VLOOKUP(A33,[16]HISTOJANV22!$A$6:$BB$36,54,0) -> #N/A
A34: AS201658 | B34: =VLOOKUP(A34,[15]LISTADHERENT!$A$5:$J$50,3,0) -> YANTCHOU GERVAIS | C34: =MVTJANV23!C34 -> 0 | D34: =MVTJANV23!D34 -> 0 | F34: =C34+D34-E34+K34 -> #N/A | G34: =$S$40/$H$40*H34 -> #REF! | H34: =F34+D34+K34 -> #N/A | I34: =VLOOKUP($A34,[16]HISTOJANV22!$A$6:$AQ$37,22,0) -> #N/A | J34: =VLOOKUP($A34,[16]HISTOJANV22!$A$6:$AU$39,45,0) -> #N/A | K34: =IF(J34=0,0,J34-(L34+M34+N34)) -> #N/A | L34: =IF(J34=0,0,500) -> #N/A | M34: =IF(J34=0,0,1000) -> #N/A | N34: =IF(J34=0,0,2500) -> #N/A | O34: =VLOOKUP($A34,[16]HISTOJANV22!$A$6:$AU$39,7,0) -> #N/A | P34: =VLOOKUP($A34,[16]HISTOJANV22!$A$6:$AU$39,23,0) -> #N/A | Q34: =VLOOKUP($A34,[16]HISTOJANV22!$A$6:$AU$39,46,0) -> #N/A | R34: =VLOOKUP($A34,[16]HISTODEC21!$A$6:$AU$39,26,0) -> #N/A | S34: =R34*12/1200*12 -> #N/A | T34: =VLOOKUP($A34,[16]HISTOJANV22!$A$6:$AU$39,28,0) -> #N/A | U34: =VLOOKUP($A34,[16]HISTOJANV22!$A$6:$AU$39,19,0) -> #N/A | V34: =VLOOKUP($A34,[16]HISTOJANV22!$A$6:$AU$39,20,0) -> #N/A | W34: =VLOOKUP($A34,[16]HISTOJANV22!$A$6:$AU$39,27,0) -> #N/A | X34: =VLOOKUP($A34,[16]HISTOJANV22!$A$6:$AU$39,33,0) -> #N/A | AA34: =VLOOKUP($A34,[16]HISTOJANV22!$A$6:$AU$39,43,0) -> #N/A | AB34: =VLOOKUP($A34,[16]HISTOJANV22!$A$6:$AU$39,44,0) -> #N/A | AC34: =VLOOKUP($A34,[16]HISTOJANV22!$A$6:$AU$39,47,0) -> #N/A | AD34: =VLOOKUP(A34,[16]HISTOJANV22!$A$6:$BB$36,54,0) -> #N/A
A35: AS201646 | B35: =VLOOKUP(A35,[15]LISTADHERENT!$A$5:$J$50,3,0) -> YEPMOU JEAN JACQUES | C35: =MVTJANV23!C35 -> 600000 | D35: =MVTJANV23!D35 -> 914734 | F35: =C35+D35-E35+K35 -> 1517734 | G35: =$S$40/$H$40*H35 -> #REF! | H35: =F35+D35+K35 -> 2435468 | I35: =VLOOKUP($A35,[16]HISTOJANV22!$A$6:$AQ$37,22,0) -> 0 | J35: =VLOOKUP($A35,[16]HISTOJANV22!$A$6:$AU$39,45,0) -> 7000 | K35: =IF(J35=0,0,J35-(L35+M35+N35)) -> 3000 | L35: =IF(J35=0,0,500) -> 500 | M35: =IF(J35=0,0,1000) -> 1000 | N35: =IF(J35=0,0,2500) -> 2500 | O35: =VLOOKUP($A35,[16]HISTOJANV22!$A$6:$AU$39,7,0) -> 3000 | P35: =VLOOKUP($A35,[16]HISTOJANV22!$A$6:$AU$39,23,0) -> 0 | Q35: =VLOOKUP($A35,[16]HISTOJANV22!$A$6:$AU$39,46,0) -> 0 | R35: =VLOOKUP($A35,[16]HISTODEC21!$A$6:$AU$39,26,0) -> 1155000 | S35: =R35*0/1200*12 -> 0 | T35: =VLOOKUP($A35,[16]HISTOJANV22!$A$6:$AU$39,28,0) -> 0 | U35: =VLOOKUP($A35,[16]HISTOJANV22!$A$6:$AU$39,19,0) -> 0 | V35: =VLOOKUP($A35,[16]HISTOJANV22!$A$6:$AU$39,20,0) -> 0 | W35: =VLOOKUP($A35,[16]HISTOJANV22!$A$6:$AU$39,27,0) -> BANQUE | X35: =VLOOKUP($A35,[16]HISTOJANV22!$A$6:$AU$39,33,0) -> 0 | Y35: 155000 | AA35: =VLOOKUP($A35,[16]HISTOJANV22!$A$6:$AU$39,43,0) -> 0 | AB35: =VLOOKUP($A35,[16]HISTOJANV22!$A$6:$AU$39,44,0) -> 0 | AC35: =VLOOKUP($A35,[16]HISTOJANV22!$A$6:$AU$39,47,0) -> 0 | AD35: =VLOOKUP(A35,[16]HISTOJANV22!$A$6:$BB$36,54,0) -> 0
A36: AS201647 | B36: =VLOOKUP(A36,[15]LISTADHERENT!$A$5:$J$50,3,0) -> YOUMBI EMMANUEL | C36: =MVTJANV23!C36 -> 600000 | D36: =MVTJANV23!D36 -> 1057774 | F36: =C36+D36-E36+K36 -> 1660774 | G36: =$S$40/$H$40*H36 -> #REF! | H36: =F36+D36+K36 -> 2721548 | I36: =VLOOKUP($A36,[16]HISTOJANV22!$A$6:$AQ$37,22,0) -> 0 | J36: =VLOOKUP($A36,[16]HISTOJANV22!$A$6:$AU$39,45,0) -> 7000 | K36: =IF(J36=0,0,J36-(L36+M36+N36)) -> 3000 | L36: =IF(J36=0,0,500) -> 500 | M36: =IF(J36=0,0,1000) -> 1000 | N36: =IF(J36=0,0,2500) -> 2500 | O36: =VLOOKUP($A36,[16]HISTOJANV22!$A$6:$AU$39,7,0) -> 0 | P36: =VLOOKUP($A36,[16]HISTOJANV22!$A$6:$AU$39,23,0) -> 0 | Q36: =VLOOKUP($A36,[16]HISTOJANV22!$A$6:$AU$39,46,0) -> 0 | R36: =VLOOKUP($A36,[16]HISTODEC21!$A$6:$AU$39,26,0) -> #REF! | S36: =R36*12/1200*12 -> #REF! | T36: =VLOOKUP($A36,[16]HISTOJANV22!$A$6:$AU$39,28,0) -> 0 | U36: =VLOOKUP($A36,[16]HISTOJANV22!$A$6:$AU$39,19,0) -> 0 | V36: =VLOOKUP($A36,[16]HISTOJANV22!$A$6:$AU$39,20,0) -> 0 | W36: =VLOOKUP($A36,[16]HISTOJANV22!$A$6:$AU$39,27,0) -> 0 | X36: =VLOOKUP($A36,[16]HISTOJANV22!$A$6:$AU$39,33,0) -> 0 | AA36: =VLOOKUP($A36,[16]HISTOJANV22!$A$6:$AU$39,43,0) -> 0 | AB36: =VLOOKUP($A36,[16]HISTOJANV22!$A$6:$AU$39,44,0) -> 0 | AC36: =VLOOKUP($A36,[16]HISTOJANV22!$A$6:$AU$39,47,0) -> 0 | AD36: =VLOOKUP(A36,[16]HISTOJANV22!$A$6:$BB$36,54,0) -> 70000
A40: TOTAL | C40: =SUM(C6:C39) -> 15000000 | D40: =SUM(D6:D39) -> 4359124.5 | E40: =SUM(E6:E39) -> 0 | F40: =SUM(F6:F39) -> #N/A | G40: =SUM(G6:G39) -> #REF! | H40: =SUM(H6:H39) -> #N/A | I40: =SUM(I6:I39) -> #N/A | J40: =SUM(J6:J39) -> #N/A | ... AE40: =SUM(AE6:AE39) -> 0

Sheet MVTDEC22
A1: ASSOCIATION | B1: ASELBY | G1: K
A2: ANNEE | B2: 2022
A3: TONTINE
J4: 44912
A5: MATRICULE | B5: NOM ET PRENOM | C5: FONDES DE DEPART | D5: RELIQUAT | E5: RETRAIT PARTIEL | F5: FONDS DEFINITIF | G5: REPARTITION INTERET | H5: CAPITAL COMPOSE | I5: SANCTION | J5: RESTE | K5: EPARGNE | L5: FONDS DE ROULEMENT | M5: FRAIS EXCEPTIONNEL | N5: COLLATION | O5: PENALITE VST ESPECES | P5: INSCRISPTION | Q5: MUTUELLE | R5: PRÊT FONDS | S5: INTERETPRET FONDS | T5: NUMERO CHEQUE | U5: REMBOURSEMENTPRET FONDS | V5: MODE VERSEMENT REMBOURSEMENT | W5: MODE VERSEMENT PRÊT | X5: NUMERO CHEQUE | Y5: PENALITE PRET FONDS | Z5: PENALITE FONDS | AA5: PENALITE ECHEC TONTINE | AB5: PENALITE RETARD TONTINE | AC5: REMBOURSEMENT TRANSPORT | AD5: CONTRIBUTION FOYER | AE5: FONDS DE ROULEMENT | AF5: FRAIS EXCEPTIONNEL | AG5: FONDS MUTUELLE | AH5: COLLATION RECEPTION | AI5: PENALITE PRET FONDS | AJ5: DEPENSE PENALITE VERSEMENT BANQUE
A6: AS201648 | B6: =VLOOKUP(A6,[15]LISTADHERENT!$A$5:$J$45,3,0) -> ASELBY | C6: 0 | D6: =VLOOKUP(A6,'[17]EPARGNE 2023'!$A$5:$BF$47,4,0) -> 816543.52 | F6: =C6+D6-E6 -> 816543.52 | G6: 51868.55 | H6: =+F6+G6 -> 868412.07 | AE6: =VLOOKUP($A6,[16]HISTODEC22!$A$6:$CA$36,60,0) -> 6000 | AF6: =VLOOKUP($A6,[16]HISTODEC22!$A$6:$CA$36,61,0) -> 0 | AG6: =VLOOKUP($A6,[16]HISTODEC22!$A$6:$CA$36,62,0) -> 0 | AH6: =VLOOKUP($A6,[16]HISTODEC22!$A$6:$CA$36,63,0) -> 0 | AI6: =VLOOKUP($A6,[16]HISTODEC22!$A$6:$CA$36,64,0) -> 0 | AJ6: =VLOOKUP($A6,[16]HISTODEC22!$A$6:$CA$36,65,0) -> 0
A7: AS201601 | B7: =VLOOKUP(A7,[15]LISTADHERENT!$A$5:$J$45,3,0) -> BAKOP ACHILLE | C7: 0 | D7: =VLOOKUP(A7,'[17]EPARGNE 2023'!$A$5:$BF$47,4,0) -> 0 | F7: =C7+D7-E7 -> 0 | G7: 0 | H7: =+F7+G7 -> 0
A8: AS201602 | B8: =VLOOKUP(A8,[15]LISTADHERENT!$A$5:$J$45,3,0) -> BOUTCHOUANG WILLIAM | C8: 600000 | D8: =VLOOKUP(A8,'[17]EPARGNE 2023'!$A$5:$BF$47,4,0) -> 7023.6611 | F8: =C8+D8-E8 -> 607023.66 | G8: 38559.411 | H8: =+F8+G8 -> 645583.07 | I8: =VLOOKUP($A8,[16]HISTODEC22!$A$6:$AQ$37,22,0) -> 0 | J8: =VLOOKUP($A8,[16]HISTODEC22!$A$6:$AU$39,45,0) -> 7000 | L8: =IF(J8=0,0,500) -> 500 | M8: =IF(J8=0,0,1000) -> 1000 | N8: =IF(J8=0,0,2500) -> 2500 | O8: =VLOOKUP($A8,[16]HISTODEC22!$A$6:$AU$39,7,0) -> 0 | P8: =VLOOKUP($A8,[16]HISTODEC22!$A$6:$AU$39,23,0) -> 0 | Q8: =VLOOKUP($A8,[16]HISTODEC22!$A$6:$AU$39,46,0) -> 0 | R8: =VLOOKUP($A8,[18]HISTODEC22!$A$6:$AU$39,26,0) -> 500000 | S8: =VLOOKUP($A8,[18]HISTODEC22!$A$6:$BG$39,58,0) -> 10000 | T8: =VLOOKUP($A8,[16]HISTODEC22!$A$6:$AU$39,28,0) -> 0 | U8: =VLOOKUP($A8,[16]HISTODEC22!$A$6:$AU$39,19,0) -> 0 | V8: =VLOOKUP($A8,[16]HISTODEC22!$A$6:$AU$39,20,0) -> 0 | W8: =VLOOKUP($A8,[16]HISTODEC22!$A$6:$AU$39,27,0) -> BANQUE | X8: =VLOOKUP($A8,[16]HISTODEC22!$A$6:$AU$39,33,0) -> 0 | Y8: =VLOOKUP($A8,[16]HISTODEC22!$A$6:$BP$39,65,0) -> 0 | AA8: =VLOOKUP($A8,[16]HISTODEC22!$A$6:$AU$39,43,0) -> 0 | AB8: =VLOOKUP($A8,[16]HISTODEC22!$A$6:$AU$39,44,0) -> 0 | AC8: =VLOOKUP($A8,[16]HISTODEC22!$A$6:$AU$39,47,0) -> 0 | AD8: =VLOOKUP(A8,[16]HISTODEC22!$A$6:$BB$36,54,0) -> 0 | AE8: =VLOOKUP($A8,[16]HISTODEC22!$A$6:$CA$36,60,0) -> 0 | AF8: =VLOOKUP($A8,[16]HISTODEC22!$A$6:$CA$36,61,0) -> 0 | AG8: =VLOOKUP($A8,[16]HISTODEC22!$A$6:$CA$36,62,0) -> 0 | AH8: =VLOOKUP($A8,[16]HISTODEC22!$A$6:$CA$36,63,0) -> 0 | AI8: =VLOOKUP($A8,[16]HISTODEC22!$A$6:$CA$36,64,0) -> 0 | AJ8: =VLOOKUP($A8,[16]HISTODEC22!$A$6:$CA$36,65,0) -> 0
A9: AS201604 | B9: =VLOOKUP(A9,[15]LISTADHERENT!$A$5:$J$45,3,0) -> DJOMO JEAN PAUL | C9: 600000 | D9: =VLOOKUP(A9,'[17]EPARGNE 2023'!$A$5:$BF$47,4,0) -> 4809.807 | F9: =C9+D9-E9 -> 604809.81 | G9: 38418.782 | H9: =+F9+G9 -> 643228.59 | I9: =VLOOKUP($A9,[16]HISTODEC22!$A$6:$AQ$37,22,0) -> 0 | J9: =VLOOKUP($A9,[16]HISTODEC22!$A$6:$AU$39,45,0) -> 7000 | L9: =IF(J9=0,0,500) -> 500 | M9: =IF(J9=0,0,1000) -> 1000 | N9: =IF(J9=0,0,2500) -> 2500 | O9: =VLOOKUP($A9,[16]HISTODEC22!$A$6:$AU$39,7,0) -> 0 | P9: =VLOOKUP($A9,[16]HISTODEC22!$A$6:$AU$39,23,0) -> 0 | Q9: =VLOOKUP($A9,[16]HISTODEC22!$A$6:$AU$39,46,0) -> 0 | R9: =VLOOKUP($A9,[18]HISTODEC22!$A$6:$AU$39,26,0) -> 1000000 | S9: =VLOOKUP($A9,[18]HISTODEC22!$A$6:$BG$39,58,0) -> 120000 | T9: =VLOOKUP($A9,[16]HISTODEC22!$A$6:$AU$39,28,0) -> 0 | U9: =VLOOKUP($A9,[16]HISTODEC22!$A$6:$AU$39,19,0) -> 1000000 | V9: =VLOOKUP($A9,[16]HISTODEC22!$A$6:$AU$39,20,0) -> BANQUE | W9: =VLOOKUP($A9,[16]HISTODEC22!$A$6:$AU$39,27,0) -> BANQUE | X9: =VLOOKUP($A9,[16]HISTODEC22!$A$6:$AU$39,33,0) -> 0 | Y9: =VLOOKUP($A9,[16]HISTODEC22!$A$6:$BP$39,65,0) -> 0 | AA9: =VLOOKUP($A9,[16]HISTODEC22!$A$6:$AU$39,43,0) -> 0 | AB9: =VLOOKUP($A9,[16]HISTODEC22!$A$6:$AU$39,44,0) -> 0 | AC9: =VLOOKUP($A9,[16]HISTODEC22!$A$6:$AU$39,47,0) -> 0 | AD9: =VLOOKUP(A9,[16]HISTODEC22!$A$6:$BB$36,54,0) -> 0 | AE9: =VLOOKUP($A9,[16]HISTODEC22!$A$6:$CA$36,60,0) -> 0 | AF9: =VLOOKUP($A9,[16]HISTODEC22!$A$6:$CA$36,61,0) -> 0 | AG9: =VLOOKUP($A9,[16]HISTODEC22!$A$6:$CA$36,62,0) -> 0 | AH9: =VLOOKUP($A9,[16]HISTODEC22!$A$6:$CA$36,63,0) -> 0 | AI9: =VLOOKUP($A9,[16]HISTODEC22!$A$6:$CA$36,64,0) -> 0 | AJ9: =VLOOKUP($A9,[16]HISTODEC22!$A$6:$CA$36,65,0) -> 0
A10: AS201654 | B10: =VLOOKUP(A10,[15]LISTADHERENT!$A$5:$J$45,3,0) -> DJOMOU TCHAPDA | C10: 600000 | D10: =VLOOKUP(A10,'[17]EPARGNE 2023'!$A$5:$BF$47,4,0) -> 48710.412 | F10: =C10+D10-E10 -> 648710.41 | G10: 41207.44 | H10: =+F10+G10 -> 689917.85 | I10: =VLOOKUP($A10,[16]HISTODEC22!$A$6:$AQ$37,22,0) -> 0 | J10: =VLOOKUP($A10,[16]HISTODEC22!$A$6:$AU$39,45,0) -> 7000 | L10: =IF(J10=0,0,500) -> 500 | M10: =IF(J10=0,0,1000) -> 1000 | N10: =IF(J10=0,0,2500) -> 2500 | O10: =VLOOKUP($A10,[16]HISTODEC22!$A$6:$AU$39,7,0) -> 0 | P10: =VLOOKUP($A10,[16]HISTODEC22!$A$6:$AU$39,23,0) -> 0 | Q10: =VLOOKUP($A10,[16]HISTODEC22!$A$6:$AU$39,46,0) -> 0 | R10: =VLOOKUP($A10,[18]HISTODEC22!$A$6:$AU$39,26,0) -> 0 | S10: =VLOOKUP($A10,[18]HISTODEC22!$A$6:$BG$39,58,0) -> 0 | T10: =VLOOKUP($A10,[16]HISTODEC22!$A$6:$AU$39,28,0) -> 0 | U10: =VLOOKUP($A10,[16]HISTODEC22!$A$6:$AU$39,19,0) -> 0 | V10: =VLOOKUP($A10,[16]HISTODEC22!$A$6:$AU$39,20,0) -> 0 | W10: =VLOOKUP($A10,[16]HISTODEC22!$A$6:$AU$39,27,0) -> 0 | X10: =VLOOKUP($A10,[16]HISTODEC22!$A$6:$AU$39,33,0) -> 0 | Y10: =VLOOKUP($A10,[16]HISTODEC22!$A$6:$BP$39,65,0) -> 0 | AA10: =VLOOKUP($A10,[16]HISTODEC22!$A$6:$AU$39,43,0) -> 0 | AB10: =VLOOKUP($A10,[16]HISTODEC22!$A$6:$AU$39,44,0) -> 0 | AC10: =VLOOKUP($A10,[16]HISTODEC22!$A$6:$AU$39,47,0) -> 0 | AD10: =VLOOKUP(A10,[16]HISTODEC22!$A$6:$BB$36,54,0) -> 0 | AE10: =VLOOKUP($A10,[16]HISTODEC22!$A$6:$CA$36,60,0) -> 0 | AF10: =VLOOKUP($A10,[16]HISTODEC22!$A$6:$CA$36,61,0) -> 0 | AG10: =VLOOKUP($A10,[16]HISTODEC22!$A$6:$CA$36,62,0) -> 0 | AH10: =VLOOKUP($A10,[16]HISTODEC22!$A$6:$CA$36,63,0) -> 0 | AI10: =VLOOKUP($A10,[16]HISTODEC22!$A$6:$CA$36,64,0) -> 0 | AJ10: =VLOOKUP($A10,[16]HISTODEC22!$A$6:$CA$36,65,0) -> 0
A11: AS201605 | B11: =VLOOKUP(A11,[15]LISTADHERENT!$A$5:$J$45,3,0) -> DJOUKWE NANGUEN GUY BLAISE | C11: 600000 | D11: =VLOOKUP(A11,'[17]EPARGNE 2023'!$A$5:$BF$47,4,0) -> 4750.0783 | F11: =C11+D11-E11 -> 604750.08 | G11: 38414.988 | H11: =+F11+G11 -> 643165.07 | I11: =VLOOKUP($A11,[16]HISTODEC22!$A$6:$AQ$37,22,0) -> 0 | J11: =VLOOKUP($A11,[16]HISTODEC22!$A$6:$AU$39,45,0) -> 7000 | L11: =IF(J11=0,0,500) -> 500 | M11: =IF(J11=0,0,1000) -> 1000 | N11: =IF(J11=0,0,2500) -> 2500 | O11: =VLOOKUP($A11,[16]HISTODEC22!$A$6:$AU$39,7,0) -> 0 | P11: =VLOOKUP($A11,[16]HISTODEC22!$A$6:$AU$39,23,0) -> 0 | Q11: =VLOOKUP($A11,[16]HISTODEC22!$A$6:$AU$39,46,0) -> 0 | R11: =VLOOKUP($A11,[18]HISTODEC22!$A$6:$AU$39,26,0) -> 1000000 | S11: =VLOOKUP($A11,[18]HISTODEC22!$A$6:$BG$39,58,0) -> 40000 | T11: =VLOOKUP($A11,[16]HISTODEC22!$A$6:$AU$39,28,0) -> 0 | U11: =VLOOKUP($A11,[16]HISTODEC22!$A$6:$AU$39,19,0) -> 1000000 | V11: =VLOOKUP($A11,[16]HISTODEC22!$A$6:$AU$39,20,0) -> BANQUE | W11: =VLOOKUP($A11,[16]HISTODEC22!$A$6:$AU$39,27,0) -> BANQUE | X11: =VLOOKUP($A11,[16]HISTODEC22!$A$6:$AU$39,33,0) -> 0 | Y11: =VLOOKUP($A11,[16]HISTODEC22!$A$6:$BP$39,65,0) -> 0 | AA11: =VLOOKUP($A11,[16]HISTODEC22!$A$6:$AU$39,43,0) -> 0 | AB11: =VLOOKUP($A11,[16]HISTODEC22!$A$6:$AU$39,44,0) -> 0 | AC11: =VLOOKUP($A11,[16]HISTODEC22!$A$6:$AU$39,47,0) -> 0 | AD11: =VLOOKUP(A11,[16]HISTODEC22!$A$6:$BB$36,54,0) -> 0 | AE11: =VLOOKUP($A11,[16]HISTODEC22!$A$6:$CA$36,60,0) -> 0 | AF11: =VLOOKUP($A11,[16]HISTODEC22!$A$6:$CA$36,61,0) -> 0 | AG11: =VLOOKUP($A11,[16]HISTODEC22!$A$6:$CA$36,62,0) -> 0 | AH11: =VLOOKUP($A11,[16]HISTODEC22!$A$6:$CA$36,63,0) -> 0 | AI11: =VLOOKUP($A11,[16]HISTODEC22!$A$6:$CA$36,64,0) -> 0 | AJ11: =VLOOKUP($A11,[16]HISTODEC22!$A$6:$CA$36,65,0) -> 0
A12: AS201608 | B12: =VLOOKUP(A12,[15]LISTADHERENT!$A$5:$J$45,3,0) -> DJUOMBESSY ANTOINE | C12: 600000 | D12: =VLOOKUP(A12,'[17]EPARGNE 2023'!$A$5:$BF$47,4,0) -> 10718.85 | F12: =C12+D12-E12 -> 610718.85 | G12: 38794.137 | H12: =+F12+G12 -> 649512.99 | I12: =VLOOKUP($A12,[16]HISTODEC22!$A$6:$AQ$37,22,0) -> 0 | J12: =VLOOKUP($A12,[16]HISTODEC22!$A$6:$AU$39,45,0) -> 8000 | L12: =IF(J12=0,0,500) -> 500 | M12: =IF(J12=0,0,1000) -> 1000 | N12: =IF(J12=0,0,2500) -> 2500 | O12: =VLOOKUP($A12,[16]HISTODEC22!$A$6:$AU$39,7,0) -> 0 | P12: =VLOOKUP($A12,[16]HISTODEC22!$A$6:$AU$39,23,0) -> 0 | Q12: =VLOOKUP($A12,[16]HISTODEC22!$A$6:$AU$39,46,0) -> 0 | R12: =VLOOKUP($A12,[18]HISTODEC22!$A$6:$AU$39,26,0) -> 1000000 | S12: =VLOOKUP($A12,[18]HISTODEC22!$A$6:$BG$39,58,0) -> 60000 | T12: =VLOOKUP($A12,[16]HISTODEC22!$A$6:$AU$39,28,0) -> 0 | U12: =VLOOKUP($A12,[16]HISTODEC22!$A$6:$AU$39,19,0) -> 0 | V12: =VLOOKUP($A12,[16]HISTODEC22!$A$6:$AU$39,20,0) -> 0 | W12: =VLOOKUP($A12,[16]HISTODEC22!$A$6:$AU$39,27,0) -> BANQUE | X12: =VLOOKUP($A12,[16]HISTODEC22!$A$6:$AU$39,33,0) -> 0 | Y12: =VLOOKUP($A12,[16]HISTODEC22!$A$6:$BP$39,65,0) -> 0 | AA12: =VLOOKUP($A12,[16]HISTODEC22!$A$6:$AU$39,43,0) -> 0 | AB12: =VLOOKUP($A12,[16]HISTODEC22!$A$6:$AU$39,44,0) -> 0 | AC12: =VLOOKUP($A12,[16]HISTODEC22!$A$6:$AU$39,47,0) -> 0 | AD12: =VLOOKUP(A12,[16]HISTODEC22!$A$6:$BB$36,54,0) -> 9000 | AE12: =VLOOKUP($A12,[16]HISTODEC22!$A$6:$CA$36,60,0) -> 0 | AF12: =VLOOKUP($A12,[16]HISTODEC22!$A$6:$CA$36,61,0) -> 0 | AG12: =VLOOKUP($A12,[16]HISTODEC22!$A$6:$CA$36,62,0) -> 0 | AH12: =VLOOKUP($A12,[16]HISTODEC22!$A$6:$CA$36,63,0) -> 0 | AI12: =VLOOKUP($A12,[16]HISTODEC22!$A$6:$CA$36,64,0) -> 0 | AJ12: =VLOOKUP($A12,[16]HISTODEC22!$A$6:$CA$36,65,0) -> 0
A13: AS201651 | B13: =VLOOKUP(A13,[15]LISTADHERENT!$A$5:$J$45,3,0) -> DOMOU FABIEN | C13: 600000 | D13: =VLOOKUP(A13,'[17]EPARGNE 2023'!$A$5:$BF$47,4,0) -> 584.046 | F13: =C13+D13-E13 -> 600584.05 | G13: 38150.353 | H13: =+F13+G13 -> 638734.4 | I13: =VLOOKUP($A13,[16]HISTODEC22!$A$6:$AQ$37,22,0) -> 0 | J13: =VLOOKUP($A13,[16]HISTODEC22!$A$6:$AU$39,45,0) -> 12000 | L13: =IF(J13=0,0,500) -> 500 | M13: =IF(J13=0,0,1000) -> 1000 | N13: =IF(J13=0,0,2500) -> 2500 | O13: =VLOOKUP($A13,[16]HISTODEC22!$A$6:$AU$39,7,0) -> 0 | P13: =VLOOKUP($A13,[16]HISTODEC22!$A$6:$AU$39,23,0) -> 0 | Q13: =VLOOKUP($A13,[16]HISTODEC22!$A$6:$AU$39,46,0) -> 0 | R13: =VLOOKUP($A13,[18]HISTODEC22!$A$6:$AU$39,26,0) -> 1000000 | S13: =VLOOKUP($A13,[18]HISTODEC22!$A$6:$BG$39,58,0) -> 120000 | T13: =VLOOKUP($A13,[16]HISTODEC22!$A$6:$AU$39,28,0) -> 0 | U13: =VLOOKUP($A13,[16]HISTODEC22!$A$6:$AU$39,19,0) -> 1000000 | V13: =VLOOKUP($A13,[16]HISTODEC22!$A$6:$AU$39,20,0) -> BANQUE | W13: =VLOOKUP($A13,[16]HISTODEC22!$A$6:$AU$39,27,0) -> BANQUE | X13: =VLOOKUP($A13,[16]HISTODEC22!$A$6:$AU$39,33,0) -> 0 | Y13: =VLOOKUP($A13,[16]HISTODEC22!$A$6:$BP$39,65,0) -> 0 | AA13: =VLOOKUP($A13,[16]HISTODEC22!$A$6:$AU$39,43,0) -> 0 | AB13: =VLOOKUP($A13,[16]HISTODEC22!$A$6:$AU$39,44,0) -> 0 | AC13: =VLOOKUP($A13,[16]HISTODEC22!$A$6:$AU$39,47,0) -> 0 | AD13: =VLOOKUP(A13,[16]HISTODEC22!$A$6:$BB$36,54,0) -> 0 | AE13: =VLOOKUP($A13,[16]HISTODEC22!$A$6:$CA$36,60,0) -> 0 | AF13: =VLOOKUP($A13,[16]HISTODEC22!$A$6:$CA$36,61,0) -> 0 | AG13: =VLOOKUP($A13,[16]HISTODEC22!$A$6:$CA$36,62,0) -> 0 | AH13: =VLOOKUP($A13,[16]HISTODEC22!$A$6:$CA$36,63,0) -> 0 | AI13: =VLOOKUP($A13,[16]HISTODEC22!$A$6:$CA$36,64,0) -> 0 | AJ13: =VLOOKUP($A13,[16]HISTODEC22!$A$6:$CA$36,65,0) -> 0
A14: AS201609 | B14: =VLOOKUP(A14,[15]LISTADHERENT!$A$5:$J$45,3,0) -> DONHOU DAVID | C14: 600000 | D14: =VLOOKUP(A14,'[17]EPARGNE 2023'!$A$5:$BF$47,4,0) -> 458343.18 | F14: =C14+D14-E14 -> 1058343.2 | G14: 67228.169 | H14: =+F14+G14 -> 1125571.3 | I14: =VLOOKUP($A14,[16]HISTODEC22!$A$6:$AQ$37,22,0) -> 0 | J14: =VLOOKUP($A14,[16]HISTODEC22!$A$6:$AU$39,45,0) -> 12000 | L14: =IF(J14=0,0,500) -> 500 | M14: =IF(J14=0,0,1000) -> 1000 | N14: =IF(J14=0,0,2500) -> 2500 | O14: =VLOOKUP($A14,[16]HISTODEC22!$A$6:$AU$39,7,0) -> 0 | P14: =VLOOKUP($A14,[16]HISTODEC22!$A$6:$AU$39,23,0) -> 0 | Q14: =VLOOKUP($A14,[16]HISTODEC22!$A$6:$AU$39,46,0) -> 0 | R14: =VLOOKUP($A14,[18]HISTODEC22!$A$6:$AU$39,26,0) -> 0 | S14: =VLOOKUP($A14,[18]HISTODEC22!$A$6:$BG$39,58,0) -> 0 | T14: =VLOOKUP($A14,[16]HISTODEC22!$A$6:$AU$39,28,0) -> 0 | U14: =VLOOKUP($A14,[16]HISTODEC22!$A$6:$AU$39,19,0) -> 0 | V14: =VLOOKUP($A14,[16]HISTODEC22!$A$6:$AU$39,20,0) -> 0 | W14: =VLOOKUP($A14,[16]HISTODEC22!$A$6:$AU$39,27,0) -> 0 | X14: =VLOOKUP($A14,[16]HISTODEC22!$A$6:$AU$39,33,0) -> 0 | Y14: =VLOOKUP($A14,[16]HISTODEC22!$A$6:$BP$39,65,0) -> 0 | AA14: =VLOOKUP($A14,[16]HISTODEC22!$A$6:$AU$39,43,0) -> 0 | AB14: =VLOOKUP($A14,[16]HISTODEC22!$A$6:$AU$39,44,0) -> 0 | AC14: =VLOOKUP($A14,[16]HISTODEC22!$A$6:$AU$39,47,0) -> 0 | AD14: =VLOOKUP(A14,[16]HISTODEC22!$A$6:$BB$36,54,0) -> 0 | AE14: =VLOOKUP($A14,[16]HISTODEC22!$A$6:$CA$36,60,0) -> 0 | AF14: =VLOOKUP($A14,[16]HISTODEC22!$A$6:$CA$36,61,0) -> 0 | AG14: =VLOOKUP($A14,[16]HISTODEC22!$A$6:$CA$36,62,0) -> 0 | AH14: =VLOOKUP($A14,[16]HISTODEC22!$A$6:$CA$36,63,0) -> 0 | AI14: =VLOOKUP($A14,[16]HISTODEC22!$A$6:$CA$36,64,0) -> 0 | AJ14: =VLOOKUP($A14,[16]HISTODEC22!$A$6:$CA$36,65,0) -> 0
A15: AS201611 | B15: =VLOOKUP(A15,[15]LISTADHERENT!$A$5:$J$45,3,0) -> HENGUE PAUL OMER | C15: 600000 | D15: =VLOOKUP(A15,'[17]EPARGNE 2023'!$A$5:$BF$47,4,0) -> 51112.01 | F15: =C15+D15-E15 -> 651112.01 | G15: 41359.995 | H15: =+F15+G15 -> 692472.01 | I15: =VLOOKUP($A15,[16]HISTODEC22!$A$6:$AQ$37,22,0) -> 0 | J15: =VLOOKUP($A15,[16]HISTODEC22!$A$6:$AU$39,45,0) -> 7000 | L15: =IF(J15=0,0,500) -> 500 | M15: =IF(J15=0,0,1000) -> 1000 | N15: =IF(J15=0,0,2500) -> 2500 | O15: =VLOOKUP($A15,[16]HISTODEC22!$A$6:$AU$39,7,0) -> 0 | P15: =VLOOKUP($A15,[16]HISTODEC22!$A$6:$AU$39,23,0) -> 0 | Q15: =VLOOKUP($A15,[16]HISTODEC22!$A$6:$AU$39,46,0) -> 0 | R15: =VLOOKUP($A15,[18]HISTODEC22!$A$6:$AU$39,26,0) -> 0 | S15: =VLOOKUP($A15,[18]HISTODEC22!$A$6:$BG$39,58,0) -> 0 | T15: =VLOOKUP($A15,[16]HISTODEC22!$A$6:$AU$39,28,0) -> 0 | U15: =VLOOKUP($A15,[16]HISTODEC22!$A$6:$AU$39,19,0) -> 0 | V15: =VLOOKUP($A15,[16]HISTODEC22!$A$6:$AU$39,20,0) -> 0 | W15: =VLOOKUP($A15,[16]HISTODEC22!$A$6:$AU$39,27,0) -> 0 | X15: =VLOOKUP($A15,[16]HISTODEC22!$A$6:$AU$39,33,0) -> 0 | Y15: =VLOOKUP($A15,[16]HISTODEC22!$A$6:$BP$39,65,0) -> 0 | AA15: =VLOOKUP($A15,[16]HISTODEC22!$A$6:$AU$39,43,0) -> 0 | AB15: =VLOOKUP($A15,[16]HISTODEC22!$A$6:$AU$39,44,0) -> 0 | AC15: =VLOOKUP($A15,[16]HISTODEC22!$A$6:$AU$39,47,0) -> 0 | AD15: =VLOOKUP(A15,[16]HISTODEC22!$A$6:$BB$36,54,0) -> 0 | AE15: =VLOOKUP($A15,[16]HISTODEC22!$A$6:$CA$36,60,0) -> 0 | AF15: =VLOOKUP($A15,[16]HISTODEC22!$A$6:$CA$36,61,0) -> 0 | AG15: =VLOOKUP($A15,[16]HISTODEC22!$A$6:$CA$36,62,0) -> 0 | AH15: =VLOOKUP($A15,[16]HISTODEC22!$A$6:$CA$36,63,0) -> 0 | AI15: =VLOOKUP($A15,[16]HISTODEC22!$A$6:$CA$36,64,0) -> 0 | AJ15: =VLOOKUP($A15,[16]HISTODEC22!$A$6:$CA$36,65,0) -> 0
A16: AS201613 | B16: =VLOOKUP(A16,[15]LISTADHERENT!$A$5:$J$45,3,0) -> HOTCHO BENJAMIN | C16: 600000 | D16: =VLOOKUP(A16,'[17]EPARGNE 2023'!$A$5:$BF$47,4,0) -> 16229.566 | F16: =C16+D16-E16 -> 616229.57 | G16: 39144.189 | H16: =+F16+G16 -> 655373.76 | I16: =VLOOKUP($A16,[16]HISTODEC22!$A$6:$AQ$37,22,0) -> 0 | J16: =VLOOKUP($A16,[16]HISTODEC22!$A$6:$AU$39,45,0) -> 52000 | L16: =IF(J16=0,0,500) -> 500 | M16: =IF(J16=0,0,1000) -> 1000 | N16: =IF(J16=0,0,2500) -> 2500 | O16: =VLOOKUP($A16,[16]HISTODEC22!$A$6:$AU$39,7,0) -> 0 | P16: =VLOOKUP($A16,[16]HISTODEC22!$A$6:$AU$39,23,0) -> 0 | Q16: =VLOOKUP($A16,[16]HISTODEC22!$A$6:$AU$39,46,0) -> 0 | R16: =VLOOKUP($A16,[18]HISTODEC22!$A$6:$AU$39,26,0) -> 1000000 | S16: =VLOOKUP($A16,[18]HISTODEC22!$A$6:$BG$39,58,0) -> 120000 | T16: =VLOOKUP($A16,[16]HISTODEC22!$A$6:$AU$39,28,0) -> 0 | U16: =VLOOKUP($A16,[16]HISTODEC22!$A$6:$AU$39,19,0) -> 1000000 | V16: =VLOOKUP($A16,[16]HISTODEC22!$A$6:$AU$39,20,0) -> BANQUE | W16: =VLOOKUP($A16,[16]HISTODEC22!$A$6:$AU$39,27,0) -> BANQUE | X16: =VLOOKUP($A16,[16]HISTODEC22!$A$6:$AU$39,33,0) -> 0 | Y16: =VLOOKUP($A16,[16]HISTODEC22!$A$6:$BP$39,65,0) -> 0 | AA16: =VLOOKUP($A16,[16]HISTODEC22!$A$6:$AU$39,43,0) -> 0 | AB16: =VLOOKUP($A16,[16]HISTODEC22!$A$6:$AU$39,44,0) -> 0 | AC16: =VLOOKUP($A16,[16]HISTODEC22!$A$6:$AU$39,47,0) -> 0 | AD16: =VLOOKUP(A16,[16]HISTODEC22!$A$6:$BB$36,54,0) -> 0 | AE16: =VLOOKUP($A16,[16]HISTODEC22!$A$6:$CA$36,60,0) -> 0 | AF16: =VLOOKUP($A16,[16]HISTODEC22!$A$6:$CA$36,61,0) -> 0 | AG16: =VLOOKUP($A16,[16]HISTODEC22!$A$6:$CA$36,62,0) -> 0 | AH16: =VLOOKUP($A16,[16]HISTODEC22!$A$6:$CA$36,63,0) -> 0 | AI16: =VLOOKUP($A16,[16]HISTODEC22!$A$6:$CA$36,64,0) -> 0 | AJ16: =VLOOKUP($A16,[16]HISTODEC22!$A$6:$CA$36,65,0) -> 0
