Workbook
Name BANQUE: #REF!
Name BANQUE: #REF!
Name BANQUE: #REF!
Name BANQUE: #REF!
Name BANQUE: #REF!
Name BANQUE: #REF!
Name BANQUE: #REF!
Name BANQUE: #REF!
Name BANQUE: #REF!
Name BANQUE: #REF!
Name BANQUE: #REF!
Name BANQUE: #REF!
Name BANQUE: #REF!
Name BANQUE: #REF!
Name BANQUE: #REF!
Name BANQUE: #REF!
Name MODEPAID: [1]Feuil2!$A$1:$A$3
Name MODET25000: [2]MODEVERSEMENT!$A$1:$A$3
Name MODEVERSEMENT: #REF!
Name MODEVERSEMENT: #REF!
Name MODEVERSEMENT: #REF!
Name MODEVERSEMENT: #REF!
Name MODEVERSEMENT: #REF!
Name MODEVERSEMENT: #REF!
Name MODEVERSEMENT: #REF!
Name MODEVERSEMENT: #REF!
Name MODEVERSEMENT: #REF!
Name MODEVERSEMENT: #REF!
Name MODEVERSEMENT: #REF!
Name MODEVERSEMENT: #REF!
Name MODEVERSEMENT: #REF!
Name MODEVERSEMENT: #REF!
Name MODEVERSEMENT: #REF!
Name MODEVERSEMENT: #REF!
Name MODEVERSEMENTS: [3]MODEVERSEMENT!$A$1:$A$3
Name MODEVERSEMENTS: [3]MODEVERSEMENT!$A$1:$A$3
Name MODEVERSEMENTS: [3]MODEVERSEMENT!$A$1:$A$3
Name MODEVERSEMENTS: [3]MODEVERSEMENT!$A$1:$A$3
Name MODEVERSEMENTS: [3]MODEVERSEMENT!$A$1:$A$3
Name MODEVERSEMENTS: [3]MODEVERSEMENT!$A$1:$A$3
Name MODEVERSEMENTS: [3]MODEVERSEMENT!$A$1:$A$3
Name MODEVERSEMENTS: [3]MODEVERSEMENT!$A$1:$A$3
Name MODEVERSEMENTS: [3]MODEVERSEMENT!$A$1:$A$3
Name MODEVERSEMENTS: [3]MODEVERSEMENT!$A$1:$A$3
Name MODEVERSEMENTS: [3]MODEVERSEMENT!$A$1:$A$3
Name MODEVERSEMENTS: [3]MODEVERSEMENT!$A$1:$A$3
Name MODEVERSEMENTS: [3]MODEVERSEMENT!$A$1:$A$3
Name MODEVERSEMENTS: [3]MODEVERSEMENT!$A$1:$A$3
Name MODEVERSEMENTS: MODEVERSEMENT!$A$1:$A$3
Name VALMODEPAID: [4]MODEPAID!$A$1:$A$3

Sheet MODEVERSEMENT
A1: BANQUE
A2: ESPECES
A3: ECHEC

Sheet COMPTE BANQUE
C1: COMPTE BANQUE | H1: COMPTE CAISSE
A2: ANNEE | C2: 2021 | H2: 2021
A4: MOIS | B4: NUMERO CHEQUE | C4: SORTIE | D4: ENTREE | E4: SOLDE | G4: NUMERO PIECE | H4: ENTREE | I4: SORTIE | J4: SOLDE
A5: REPORT A NOUVEAU | E5: =14283661-6017000 -> 8266661
A6: JANVIER | C6: =#REF! -> #REF! | D6: =#REF! -> #REF! | E6: =IF(D6=0,0,E5+D6-C6) -> #REF!
A7: FÉVRIER | C7: =#REF! -> #REF! | D7: =#REF! -> #REF! | E7: =IF(D7=0,0,E6+D7-C7) -> #REF!
A8: MARS | C8: =#REF! -> #REF! | D8: =#REF! -> #REF! | E8: =IF(D8=0,0,E7+D8-C8) -> #REF!
A9: AVRIL | C9: =#REF! -> #REF! | D9: =#REF! -> #REF! | E9: =IF(D9=0,0,E8+D9-C9) -> #REF!
A10: MAI | C10: =#REF! -> #REF! | D10: =#REF! -> #REF! | E10: =IF(D10=0,0,E9+D10-C10) -> #REF!
A11: JUIN | C11: =#REF! -> #REF! | D11: =#REF! -> #REF! | E11: =IF(D11=0,0,E10+D11-C11) -> #REF!
A12: JUILLET | C12: =#REF! -> #REF! | D12: =#REF! -> #REF! | E12: =IF(D12=0,0,E11+D12-C12) -> #REF!
A13: AOÛT | C13: =#REF! -> #REF! | D13: =#REF! -> #REF! | E13: =IF(D13=0,0,E12+D13-C13) -> #REF!
A14: SEPTEMBRE | C14: =#REF! -> #REF! | D14: =#REF! -> #REF! | E14: =IF(D14=0,0,E13+D14-C14) -> #REF!
A15: OCTOBRE | C15: =#REF! -> #REF! | D15: =#REF! -> #REF! | E15: =IF(D15=0,0,E14+D15-C15) -> #REF!
A16: NOVEMBRE | C16: =#REF! -> #REF! | D16: =#REF! -> #REF! | E16: =IF(D16=0,0,E15+D16-C16) -> #REF!
A17: DÉCEMBRE | C17: =#REF! -> #REF! | D17: =#REF! -> #REF! | E17: =IF(D17=0,0,E16+D17-C17) -> #REF!
A19: TOTAL

Sheet HISTOBQUEJANV23
A1: ASSOCIATION | B1: ASELBY | C1: MOIS DE JANVIER
A2: ANNEE | B2: 2023
A3: 1 | B3: 2 | C3: 4 | D3: 5 | E3: 6 | F3: 21
B4: HISTORIQUE BANCAIRE
A5: MATRICULE | B5: NOM ET PRENOM | C5: HISTORIQUE BANQUE | D5: HITORIQUE ESPECES | E5: HITORIQUE TONTINE | F5: MONTANT ENGAGEMENT | G5: VERIFICATION | H5: AGIO
A6: AS201648 | B6: =VLOOKUP(A6,[5]LISTADHERENT!A$5:H$39,3,0) -> ASELBY | C6: 175000 | F6: =SUM(C6:E6) -> 175000
A7: AS201601 | B7: =VLOOKUP(A7,[5]LISTADHERENT!A$5:H$39,3,0) -> BAKOP ACHILLE | D7: 104000 | F7: =SUM(C7:E7) -> 104000
A8: AS201602 | B8: =VLOOKUP(A8,[5]LISTADHERENT!A$5:H$39,3,0) -> BOUTCHOUANG WILLIAM | C8: 105000 | D8: 10000 | F8: =SUM(C8:E8) -> 115000 | G8: 40000
A9: AS201604 | B9: =VLOOKUP(A9,[5]LISTADHERENT!A$5:H$39,3,0) -> DJOMO JEAN PAUL | C9: 160000 | F9: =SUM(C9:E9) -> 160000 | G9: 115000
A10: AS201654 | B10: =VLOOKUP(A10,[5]LISTADHERENT!A$5:H$39,3,0) -> DJOMOU TCHAPDA | C10: 40000 | F10: =SUM(C10:E10) -> 40000 | G10: 250000
A11: AS201605 | B11: =VLOOKUP(A11,[5]LISTADHERENT!A$5:H$39,3,0) -> DJOUKWE NANGUEN GUY BLAISE | C11: 115000 | F11: =SUM(C11:E11) -> 115000 | G11: 115000
A12: AS201608 | B12: =VLOOKUP(A12,[5]LISTADHERENT!A$5:H$39,3,0) -> DJUOMBESSY ANTOINE | C12: 320000 | F12: =SUM(C12:E12) -> 320000 | G12: 280000
A13: AS201651 | B13: =VLOOKUP(A13,[5]LISTADHERENT!A$5:H$39,3,0) -> DOMOU FABIEN | C13: 40000 | F13: =SUM(C13:E13) -> 40000 | G13: 115000
A14: AS201609 | B14: =VLOOKUP(A14,[5]LISTADHERENT!A$5:H$39,3,0) -> DONHOU DAVID | C14: 40000 | F14: =SUM(C14:E14) -> 40000 | G14: 140000
A15: AS201611 | B15: =VLOOKUP(A15,[5]LISTADHERENT!A$5:H$39,3,0) -> HENGUE PAUL OMER | C15: 115000 | F15: =SUM(C15:E15) -> 115000 | G15: 105000
A16: AS201613 | B16: =VLOOKUP(A16,[5]LISTADHERENT!A$5:H$39,3,0) -> HOTCHO BENJAMIN | C16: 250000 | F16: =SUM(C16:E16) -> 250000 | G16: 320000
A17: AS201617 | B17: =VLOOKUP(A17,[5]LISTADHERENT!A$5:H$39,3,0) -> KOUAMOU MOISE | C17: 140000 | F17: =SUM(C17:E17) -> 140000 | G17: 290000
A18: AS201619 | B18: =VLOOKUP(A18,[5]LISTADHERENT!A$5:H$39,3,0) -> KOUATCHO MESSACK | C18: =260000-80000 -> 180000 | D18: 35000 | F18: =SUM(C18:E18) -> 215000 | G18: 250000
A19: AS201620 | B19: =VLOOKUP(A19,[5]LISTADHERENT!A$5:H$39,3,0) -> LOWE JEAN | C19: 40000 | F19: =SUM(C19:E19) -> 40000 | G19: 40000
A20: AS201649 | B20: =VLOOKUP(A20,[5]LISTADHERENT!A$5:H$39,3,0) -> MBOGNING TUGMA GUY | C20: 215000 | F20: =SUM(C20:E20) -> 215000 | G20: 215000
A21: AS201639 | B21: =VLOOKUP(A21,[5]LISTADHERENT!A$5:H$39,3,0) -> NANGUEN MARTIN | C21: 40000 | F21: =SUM(C21:E21) -> 40000 | G21: 160000
A22: AS201621 | B22: =VLOOKUP(A22,[5]LISTADHERENT!A$5:H$39,3,0) -> NANKAM APPOLINAIRE | C22: 115000 | F22: =SUM(C22:E22) -> 115000 | G22: 115000
A23: AS201622 | B23: =VLOOKUP(A23,[5]LISTADHERENT!A$5:H$39,3,0) -> NDJOMO ETIENNE | C23: 250000 | F23: =SUM(C23:E23) -> 250000 | G23: 40000
A24: AS201624 | B24: =VLOOKUP(A24,[5]LISTADHERENT!A$5:H$39,3,0) -> NGONDIEP CLAUDE | C24: 210000 | D24: 5000 | F24: =SUM(C24:E24) -> 215000 | G24: 115000
A25: AS201626 | B25: =VLOOKUP(A25,[5]LISTADHERENT!A$5:H$39,3,0) -> NGUIEMEGNI MATHIEU BLAISE | C25: 280000 | D25: 10000 | F25: =SUM(C25:E25) -> 290000
A26: AS201628 | B26: =VLOOKUP(A26,[5]LISTADHERENT!A$5:H$39,3,0) -> NKAMGANG JUSTIN DEJOLIE | D26: 40000 | F26: =SUM(C26:E26) -> 40000
A27: AS201656 | B27: =VLOOKUP(A27,[5]LISTADHERENT!A$5:H$39,3,0) -> NOUBE ETIENNE | D27: 65000 | F27: =SUM(C27:E27) -> 65000
A28: AS201633 | B28: =VLOOKUP(A28,[5]LISTADHERENT!A$5:H$39,3,0) -> PATEGO NJOSSU GUSTAVE | C28: 115000 | F28: =SUM(C28:E28) -> 115000
A29: AS201657 | B29: =VLOOKUP(A29,[5]LISTADHERENT!A$5:H$39,3,0) -> SEUMO POLYCARPE | D29: 65000 | F29: =SUM(C29:E29) -> 65000
A30: AS201653 | B30: =VLOOKUP(A30,[5]LISTADHERENT!A$5:H$39,3,0) -> SIME BRICE | D30: 115000 | F30: =SUM(C30:E30) -> 115000
A31: AS201638 | B31: =VLOOKUP(A31,[5]LISTADHERENT!A$5:H$39,3,0) -> SIMO PIERRE | C31: 250000 | F31: =SUM(C31:E31) -> 250000
A32: AS201641 | B32: =VLOOKUP(A32,[5]LISTADHERENT!A$5:H$39,3,0) -> TCHOUAMOU MATHIEU | C32: 115000 | F32: =SUM(C32:E32) -> 115000
A33: AS201643 | B33: =VLOOKUP(A33,[5]LISTADHERENT!A$5:H$39,3,0) -> TCHOUTOU NANA CLAUDE | D33: 40000 | F33: =SUM(C33:E33) -> 40000
A34: AS201658 | B34: =VLOOKUP(A34,[5]LISTADHERENT!A$5:H$39,3,0) -> YANTCHOU GERVAIS | D34: 100000 | F34: =SUM(C34:E34) -> 100000
A35: AS201646 | B35: =VLOOKUP(A35,[5]LISTADHERENT!A$5:H$39,3,0) -> YEPMOU JEAN JACQUES | C35: 40000 | F35: =SUM(C35:E35) -> 40000
A36: AS201647 | B36: =VLOOKUP(A36,[5]LISTADHERENT!A$5:H$39,3,0) -> YOUMBI EMMANUEL | C36: 290000 | F36: =SUM(C36:E36) -> 290000
B38: TOTAUX | C38: =SUM(C7:C37) -> 3465000 | D38: =SUM(D7:D37) -> 589000 | E38: =SUM(E7:E37) -> 0 | F38: =SUM(F7:F37) -> 4054000 | G38: =SUM(G7:G37) -> 2705000 | H38: =SUM(H8:H37) -> 0

Sheet HISTOBQUEFEV23
A1: ASSOCIATION | B1: ASELBY | C1: MOIS DE FEVRIER
A2: ANNEE | B2: 2023
A3: 1 | B3: 2 | C3: 4 | D3: 5 | E3: 6 | F3: 21
B4: HISTORIQUE BANCAIRE
A5: MATRICULE | B5: NOM ET PRENOM | C5: HISTORIQUE BANQUE | D5: HITORIQUE ESPECES | E5: HITORIQUE TONTINE | F5: MONTANT ENGAGEMENT | G5: VERIFICATION | H5: AGIO
A6: AS201648 | B6: =VLOOKUP(A6,[5]LISTADHERENT!A$5:H$39,3,0) -> ASELBY | C6: 175000 | F6: =SUM(C6:E6) -> 175000
A7: AS201601 | B7: =VLOOKUP(A7,[5]LISTADHERENT!A$5:H$39,3,0) -> BAKOP ACHILLE | D7: 40000 | F7: =SUM(C7:E7) -> 40000
A8: AS201602 | B8: =VLOOKUP(A8,[5]LISTADHERENT!A$5:H$39,3,0) -> BOUTCHOUANG WILLIAM | C8: =115000+500000 -> 615000 | F8: =SUM(C8:E8) -> 615000
A9: AS201604 | B9: =VLOOKUP(A9,[5]LISTADHERENT!A$5:H$39,3,0) -> DJOMO JEAN PAUL | C9: 120000 | D9: 80000 | F9: =SUM(C9:E9) -> 200000
A10: AS201654 | B10: =VLOOKUP(A10,[5]LISTADHERENT!A$5:H$39,3,0) -> DJOMOU TCHAPDA | C10: =40000+63000 -> 103000 | F10: =SUM(C10:E10) -> 103000
A11: AS201605 | B11: =VLOOKUP(A11,[5]LISTADHERENT!A$5:H$39,3,0) -> DJOUKWE NANGUEN GUY BLAISE | C11: =115000+62000 -> 177000 | F11: =SUM(C11:E11) -> 177000
A12: AS201608 | B12: =VLOOKUP(A12,[5]LISTADHERENT!A$5:H$39,3,0) -> DJUOMBESSY ANTOINE | C12: 320000 | F12: =SUM(C12:E12) -> 320000
A13: AS201651 | B13: =VLOOKUP(A13,[5]LISTADHERENT!A$5:H$39,3,0) -> DOMOU FABIEN | D13: 40000 | F13: =SUM(C13:E13) -> 40000
A14: AS201609 | B14: =VLOOKUP(A14,[5]LISTADHERENT!A$5:H$39,3,0) -> DONHOU DAVID | C14: 40000 | F14: =SUM(C14:E14) -> 40000
A15: AS201611 | B15: =VLOOKUP(A15,[5]LISTADHERENT!A$5:H$39,3,0) -> HENGUE PAUL OMER | C15: 115000 | F15: =SUM(C15:E15) -> 115000
A16: AS201613 | B16: =VLOOKUP(A16,[5]LISTADHERENT!A$5:H$39,3,0) -> HOTCHO BENJAMIN | C16: 250000 | E16: 1000000 | F16: =SUM(C16:E16) -> 1250000
A17: AS201617 | B17: =VLOOKUP(A17,[5]LISTADHERENT!A$5:H$39,3,0) -> KOUAMOU MOISE | C17: 140000 | F17: =SUM(C17:E17) -> 140000
A18: AS201619 | B18: =VLOOKUP(A18,[5]LISTADHERENT!A$5:H$39,3,0) -> KOUATCHO MESSACK | C18: 51000 | D18: =100000+75000+40000+51000 -> 266000 | F18: =SUM(C18:E18) -> 317000
A19: AS201620 | B19: =VLOOKUP(A19,[5]LISTADHERENT!A$5:H$39,3,0) -> LOWE JEAN | D19: 40000 | F19: =SUM(C19:E19) -> 40000
A20: AS201649 | B20: =VLOOKUP(A20,[5]LISTADHERENT!A$5:H$39,3,0) -> MBOGNING TUGMA GUY | C20: 107000 | D20: 215000 | F20: =SUM(C20:E20) -> 322000
A21: AS201639 | B21: =VLOOKUP(A21,[5]LISTADHERENT!A$5:H$39,3,0) -> NANGUEN MARTIN | C21: 40000 | F21: =SUM(C21:E21) -> 40000
A22: AS201621 | B22: =VLOOKUP(A22,[5]LISTADHERENT!A$5:H$39,3,0) -> NANKAM APPOLINAIRE | C22: 115000 | F22: =SUM(C22:E22) -> 115000
A23: AS201622 | B23: =VLOOKUP(A23,[5]LISTADHERENT!A$5:H$39,3,0) -> NDJOMO ETIENNE | C23: 250000 | F23: =SUM(C23:E23) -> 250000
A24: AS201624 | B24: =VLOOKUP(A24,[5]LISTADHERENT!A$5:H$39,3,0) -> NGONDIEP CLAUDE | C24: =365000+134000+52000 -> 551000 | F24: =SUM(C24:E24) -> 551000
A25: AS201626 | B25: =VLOOKUP(A25,[5]LISTADHERENT!A$5:H$39,3,0) -> NGUIEMEGNI MATHIEU BLAISE | C25: =430000+21000 -> 451000 | D25: 50000 | E25: 70000 | F25: =SUM(C25:E25) -> 571000
A26: AS201628 | B26: =VLOOKUP(A26,[5]LISTADHERENT!A$5:H$39,3,0) -> NKAMGANG JUSTIN DEJOLIE | D26: =40000+62000 -> 102000 | E26: 70000 | F26: =SUM(C26:E26) -> 172000
A27: AS201656 | B27: =VLOOKUP(A27,[5]LISTADHERENT!A$5:H$39,3,0) -> NOUBE ETIENNE | C27: 40000 | F27: =SUM(C27:E27) -> 40000
A28: AS201633 | B28: =VLOOKUP(A28,[5]LISTADHERENT!A$5:H$39,3,0) -> PATEGO NJOSSU GUSTAVE | C28: 115000 | F28: =SUM(C28:E28) -> 115000
A29: AS201657 | B29: =VLOOKUP(A29,[5]LISTADHERENT!A$5:H$39,3,0) -> SEUMO POLYCARPE | C29: 40000 | F29: =SUM(C29:E29) -> 40000
A30: AS201653 | B30: =VLOOKUP(A30,[5]LISTADHERENT!A$5:H$39,3,0) -> SIME BRICE | C30: 115000 | F30: =SUM(C30:E30) -> 115000
A31: AS201638 | B31: =VLOOKUP(A31,[5]LISTADHERENT!A$5:H$39,3,0) -> SIMO PIERRE | D31: 140000 | F31: =SUM(C31:E31) -> 140000
A32: AS201641 | B32: =VLOOKUP(A32,[5]LISTADHERENT!A$5:H$39,3,0) -> TCHOUAMOU MATHIEU | C32: 115000 | F32: =SUM(C32:E32) -> 115000
A33: AS201643 | B33: =VLOOKUP(A33,[5]LISTADHERENT!A$5:H$39,3,0) -> TCHOUTOU NANA CLAUDE | D33: 40000 | F33: =SUM(C33:E33) -> 40000
A34: AS201658 | B34: =VLOOKUP(A34,[5]LISTADHERENT!A$5:H$39,3,0) -> YANTCHOU GERVAIS | C34: 100000 | F34: =SUM(C34:E34) -> 100000
A35: AS201646 | B35: =VLOOKUP(A35,[5]LISTADHERENT!A$5:H$39,3,0) -> YEPMOU JEAN JACQUES | C35: 40000 | F35: =SUM(C35:E35) -> 40000
A36: AS201647 | B36: =VLOOKUP(A36,[5]LISTADHERENT!A$5:H$39,3,0) -> YOUMBI EMMANUEL | C36: 290000 | F36: =SUM(C36:E36) -> 290000
B38: TOTAUX | C38: =SUM(C7:C37) -> 4300000 | D38: =SUM(D7:D37) -> 1013000 | E38: =SUM(E7:E37) -> 1140000 | F38: =SUM(F7:F37) -> 6453000 | G38: =SUM(G7:G37) -> 0 | H38: =SUM(H8:H37) -> 0
E40: 422000
E41: 201000
E42: 390000

Sheet HISTOBQUEMARS23
A1: ASSOCIATION | B1: ASELBY | C1: MOIS DE MARS
A2: ANNEE | B2: 2023
A3: 1 | B3: 2 | C3: 4 | D3: 5 | E3: 6 | F3: 21
B4: HISTORIQUE BANCAIRE
A5: MATRICULE | B5: NOM ET PRENOM | C5: HISTORIQUE BANQUE | D5: HITORIQUE ESPECES | E5: HITORIQUE TONTINE | F5: MONTANT ENGAGEMENT | G5: VERIFICATION | H5: AGIO
A6: AS201648 | B6: =VLOOKUP(A6,[5]LISTADHERENT!A$5:H$39,3,0) -> ASELBY | C6: 175000 | F6: =SUM(C6:E6) -> 175000
A7: AS201601 | B7: =VLOOKUP(A7,[5]LISTADHERENT!A$5:H$39,3,0) -> BAKOP ACHILLE | C7: 40000 | F7: =SUM(C7:E7) -> 40000 | G7: 40000
A8: AS201602 | B8: =VLOOKUP(A8,[5]LISTADHERENT!A$5:H$39,3,0) -> BOUTCHOUANG WILLIAM | C8: 115000 | F8: =SUM(C8:E8) -> 115000 | G8: 20000
A9: AS201604 | B9: =VLOOKUP(A9,[5]LISTADHERENT!A$5:H$39,3,0) -> DJOMO JEAN PAUL | C9: 140000 | F9: =SUM(C9:E9) -> 140000 | G9: 140000
A10: AS201654 | B10: =VLOOKUP(A10,[5]LISTADHERENT!A$5:H$39,3,0) -> DJOMOU TCHAPDA | C10: 82000 | F10: =SUM(C10:E10) -> 82000 | G10: 115000
A11: AS201605 | B11: =VLOOKUP(A11,[5]LISTADHERENT!A$5:H$39,3,0) -> DJOUKWE NANGUEN GUY BLAISE | C11: 20000 | F11: =SUM(C11:E11) -> 20000 | G11: 320000
A12: AS201608 | B12: =VLOOKUP(A12,[5]LISTADHERENT!A$5:H$39,3,0) -> DJUOMBESSY ANTOINE | C12: 320000 | F12: =SUM(C12:E12) -> 320000 | G12: 140000
A13: AS201651 | B13: =VLOOKUP(A13,[5]LISTADHERENT!A$5:H$39,3,0) -> DOMOU FABIEN | C13: 40000 | F13: =SUM(C13:E13) -> 40000 | G13: 115000
A14: AS201609 | B14: =VLOOKUP(A14,[5]LISTADHERENT!A$5:H$39,3,0) -> DONHOU DAVID | C14: 40000 | F14: =SUM(C14:E14) -> 40000 | G14: 40000
A15: AS201611 | B15: =VLOOKUP(A15,[5]LISTADHERENT!A$5:H$39,3,0) -> HENGUE PAUL OMER | C15: 115000 | F15: =SUM(C15:E15) -> 115000 | G15: 250000
A16: AS201613 | B16: =VLOOKUP(A16,[5]LISTADHERENT!A$5:H$39,3,0) -> HOTCHO BENJAMIN | C16: 250000 | F16: =SUM(C16:E16) -> 250000 | G16: 100000
A17: AS201617 | B17: =VLOOKUP(A17,[5]LISTADHERENT!A$5:H$39,3,0) -> KOUAMOU MOISE | C17: 140000 | F17: =SUM(C17:E17) -> 140000 | G17: 72500
A18: AS201619 | B18: =VLOOKUP(A18,[5]LISTADHERENT!A$5:H$39,3,0) -> KOUATCHO MESSACK | C18: =267000-52000 -> 215000 | F18: =SUM(C18:E18) -> 215000 | G18: 250000
A19: AS201620 | B19: =VLOOKUP(A19,[5]LISTADHERENT!A$5:H$39,3,0) -> LOWE JEAN | C19: 40000 | F19: =SUM(C19:E19) -> 40000 | G19: 267000
A20: AS201649 | B20: =VLOOKUP(A20,[5]LISTADHERENT!A$5:H$39,3,0) -> MBOGNING TUGMA GUY | C20: =319000+32500+52000 -> 403500 | F20: =SUM(C20:E20) -> 403500 | G20: 319000
A21: AS201639 | B21: =VLOOKUP(A21,[5]LISTADHERENT!A$5:H$39,3,0) -> NANGUEN MARTIN | C21: 40000 | F21: =SUM(C21:E21) -> 40000 | G21: 40000
A22: AS201621 | B22: =VLOOKUP(A22,[5]LISTADHERENT!A$5:H$39,3,0) -> NANKAM APPOLINAIRE | C22: 115000 | F22: =SUM(C22:E22) -> 115000 | G22: 40000
A23: AS201622 | B23: =VLOOKUP(A23,[5]LISTADHERENT!A$5:H$39,3,0) -> NDJOMO ETIENNE | C23: 250000 | F23: =SUM(C23:E23) -> 250000 | G23: 115000
A24: AS201624 | B24: =VLOOKUP(A24,[5]LISTADHERENT!A$5:H$39,3,0) -> NGONDIEP CLAUDE | D24: 215000 | F24: =SUM(C24:E24) -> 215000 | G24: 290000
A25: AS201626 | B25: =VLOOKUP(A25,[5]LISTADHERENT!A$5:H$39,3,0) -> NGUIEMEGNI MATHIEU BLAISE | C25: 280000 | F25: =SUM(C25:E25) -> 280000 | G25: 50000
A26: AS201628 | B26: =VLOOKUP(A26,[5]LISTADHERENT!A$5:H$39,3,0) -> NKAMGANG JUSTIN DEJOLIE | D26: 84000 | F26: =SUM(C26:E26) -> 84000 | G26: 280000
A27: AS201656 | B27: =VLOOKUP(A27,[5]LISTADHERENT!A$5:H$39,3,0) -> NOUBE ETIENNE | C27: 50000 | F27: =SUM(C27:E27) -> 50000 | G27: 140000
A28: AS201633 | B28: =VLOOKUP(A28,[5]LISTADHERENT!A$5:H$39,3,0) -> PATEGO NJOSSU GUSTAVE | C28: 115000 | F28: =SUM(C28:E28) -> 115000 | G28: 115000
A29: AS201657 | B29: =VLOOKUP(A29,[5]LISTADHERENT!A$5:H$39,3,0) -> SEUMO POLYCARPE | C29: =72500-32500 -> 40000 | F29: =SUM(C29:E29) -> 40000 | G29: 115000
A30: AS201653 | B30: =VLOOKUP(A30,[5]LISTADHERENT!A$5:H$39,3,0) -> SIME BRICE | C30: 115000 | F30: =SUM(C30:E30) -> 115000 | G30: 82000
A31: AS201638 | B31: =VLOOKUP(A31,[5]LISTADHERENT!A$5:H$39,3,0) -> SIMO PIERRE | C31: 140000 | F31: =SUM(C31:E31) -> 140000 | G31: 40000
A32: AS201641 | B32: =VLOOKUP(A32,[5]LISTADHERENT!A$5:H$39,3,0) -> TCHOUAMOU MATHIEU | C32: 115000 | F32: =SUM(C32:E32) -> 115000 | G32: 34000
A33: AS201643 | B33: =VLOOKUP(A33,[5]LISTADHERENT!A$5:H$39,3,0) -> TCHOUTOU NANA CLAUDE | C33: 40000 | F33: =SUM(C33:E33) -> 40000 | G33: 115000
A34: AS201658 | B34: =VLOOKUP(A34,[5]LISTADHERENT!A$5:H$39,3,0) -> YANTCHOU GERVAIS | C34: 100000 | F34: =SUM(C34:E34) -> 100000 | G34: 40000
A35: AS201646 | B35: =VLOOKUP(A35,[5]LISTADHERENT!A$5:H$39,3,0) -> YEPMOU JEAN JACQUES | C35: 34000 | F35: =SUM(C35:E35) -> 34000
A36: AS201647 | B36: =VLOOKUP(A36,[5]LISTADHERENT!A$5:H$39,3,0) -> YOUMBI EMMANUEL | C36: 290000 | F36: =SUM(C36:E36) -> 290000
B38: TOTAUX | C38: =SUM(C7:C37) -> 3684500 | D38: =SUM(D7:D37) -> 299000 | E38: =SUM(E7:E37) -> 0 | F38: =SUM(F7:F37) -> 3983500 | G38: =SUM(G7:G37) -> 3684500 | H38: =SUM(H8:H37) -> 0

Sheet HISTOBQUEAVRIL23
A1: ASSOCIATION | B1: ASELBY | C1: MOIS DEAVRIL
A2: ANNEE | B2: 2023
A3: 1 | B3: 2 | C3: 4 | D3: 5 | E3: 6 | F3: 21
B4: HISTORIQUE BANCAIRE
A5: MATRICULE | B5: NOM ET PRENOM | C5: HISTORIQUE BANQUE | D5: HITORIQUE ESPECES | E5: HITORIQUE TONTINE | F5: MONTANT ENGAGEMENT | G5: VERIFICATION | H5: AGIO
A6: AS201648 | B6: =VLOOKUP(A6,[5]LISTADHERENT!A$5:H$39,3,0) -> ASELBY | C6: 175000 | F6: =SUM(C6:E6) -> 175000
A7: AS201601 | B7: =VLOOKUP(A7,[5]LISTADHERENT!A$5:H$39,3,0) -> BAKOP ACHILLE | C7: 40000 | F7: =SUM(C7:E7) -> 40000 | G7: 115000
A8: AS201602 | B8: =VLOOKUP(A8,[5]LISTADHERENT!A$5:H$39,3,0) -> BOUTCHOUANG WILLIAM | C8: 115000 | F8: =SUM(C8:E8) -> 115000 | G8: 115000
A9: AS201604 | B9: =VLOOKUP(A9,[5]LISTADHERENT!A$5:H$39,3,0) -> DJOMO JEAN PAUL | C9: 145000 | F9: =SUM(C9:E9) -> 145000 | G9: 40000
A10: AS201654 | B10: =VLOOKUP(A10,[5]LISTADHERENT!A$5:H$39,3,0) -> DJOMOU TCHAPDA | D10: 43000 | F10: =SUM(C10:E10) -> 43000 | G10: 115000
A11: AS201605 | B11: =VLOOKUP(A11,[5]LISTADHERENT!A$5:H$39,3,0) -> DJOUKWE NANGUEN GUY BLAISE | C11: 115000 | F11: =SUM(C11:E11) -> 115000 | G11: 241000
A12: AS201608 | B12: =VLOOKUP(A12,[5]LISTADHERENT!A$5:H$39,3,0) -> DJUOMBESSY ANTOINE | C12: =100000+220000 -> 320000 | F12: =SUM(C12:E12) -> 320000 | G12: 140000
A13: AS201651 | B13: =VLOOKUP(A13,[5]LISTADHERENT!A$5:H$39,3,0) -> DOMOU FABIEN | C13: 40000 | F13: =SUM(C13:E13) -> 40000 | G13: 115000
A14: AS201609 | B14: =VLOOKUP(A14,[5]LISTADHERENT!A$5:H$39,3,0) -> DONHOU DAVID | C14: 40000 | F14: =SUM(C14:E14) -> 40000 | G14: 50000
A15: AS201611 | B15: =VLOOKUP(A15,[5]LISTADHERENT!A$5:H$39,3,0) -> HENGUE PAUL OMER | C15: 115000 | F15: =SUM(C15:E15) -> 115000 | G15: 516000
A16: AS201613 | B16: =VLOOKUP(A16,[5]LISTADHERENT!A$5:H$39,3,0) -> HOTCHO BENJAMIN | C16: =351000+165000 -> 516000 | F16: =SUM(C16:E16) -> 516000 | G16: 160000
A17: AS201617 | B17: =VLOOKUP(A17,[5]LISTADHERENT!A$5:H$39,3,0) -> KOUAMOU MOISE | C17: 241000 | F17: =SUM(C17:E17) -> 241000 | G17: 422000
A18: AS201619 | B18: =VLOOKUP(A18,[5]LISTADHERENT!A$5:H$39,3,0) -> KOUATCHO MESSACK | C18: =419000 -> 419000 | F18: =SUM(C18:E18) -> 419000 | G18: 452000
A19: AS201620 | B19: =VLOOKUP(A19,[5]LISTADHERENT!A$5:H$39,3,0) -> LOWE JEAN | C19: 40000 | F19: =SUM(C19:E19) -> 40000 | G19: 320000
A20: AS201649 | B20: =VLOOKUP(A20,[5]LISTADHERENT!A$5:H$39,3,0) -> MBOGNING TUGMA GUY | C20: =220000+202000 -> 422000 | F20: =SUM(C20:E20) -> 422000 | G20: 115000
A21: AS201639 | B21: =VLOOKUP(A21,[5]LISTADHERENT!A$5:H$39,3,0) -> NANGUEN MARTIN | C21: 40000 | F21: =SUM(C21:E21) -> 40000 | G21: 40000
A22: AS201621 | B22: =VLOOKUP(A22,[5]LISTADHERENT!A$5:H$39,3,0) -> NANKAM APPOLINAIRE | C22: 115000 | F22: =SUM(C22:E22) -> 115000 | G22: 40000
A23: AS201622 | B23: =VLOOKUP(A23,[5]LISTADHERENT!A$5:H$39,3,0) -> NDJOMO ETIENNE | C23: =250000+101000+101000 -> 452000 | F23: =SUM(C23:E23) -> 452000 | G23: 280000
A24: AS201624 | B24: =VLOOKUP(A24,[5]LISTADHERENT!A$5:H$39,3,0) -> NGONDIEP CLAUDE | C24: 220000 | F24: =SUM(C24:E24) -> 220000 | G24: 145000
A25: AS201626 | B25: =VLOOKUP(A25,[5]LISTADHERENT!A$5:H$39,3,0) -> NGUIEMEGNI MATHIEU BLAISE | C25: 280000 | F25: =SUM(C25:E25) -> 280000 | G25: 220000
A26: AS201628 | B26: =VLOOKUP(A26,[5]LISTADHERENT!A$5:H$39,3,0) -> NKAMGANG JUSTIN DEJOLIE | D26: 43000 | F26: =SUM(C26:E26) -> 43000 | G26: 419000
A27: AS201656 | B27: =VLOOKUP(A27,[5]LISTADHERENT!A$5:H$39,3,0) -> NOUBE ETIENNE | C27: 50000 | F27: =SUM(C27:E27) -> 50000 | G27: 40000
A28: AS201633 | B28: =VLOOKUP(A28,[5]LISTADHERENT!A$5:H$39,3,0) -> PATEGO NJOSSU GUSTAVE | C28: 115000 | F28: =SUM(C28:E28) -> 115000 | G28: 115000
A29: AS201657 | B29: =VLOOKUP(A29,[5]LISTADHERENT!A$5:H$39,3,0) -> SEUMO POLYCARPE | C29: 160000 | F29: =SUM(C29:E29) -> 160000 | G29: 40000
A30: AS201653 | B30: =VLOOKUP(A30,[5]LISTADHERENT!A$5:H$39,3,0) -> SIME BRICE | C30: 115000 | F30: =SUM(C30:E30) -> 115000 | G30: 290000
A31: AS201638 | B31: =VLOOKUP(A31,[5]LISTADHERENT!A$5:H$39,3,0) -> SIMO PIERRE | C31: 140000 | F31: =SUM(C31:E31) -> 140000 | G31: 115000
A32: AS201641 | B32: =VLOOKUP(A32,[5]LISTADHERENT!A$5:H$39,3,0) -> TCHOUAMOU MATHIEU | C32: 115000 | F32: =SUM(C32:E32) -> 115000
A33: AS201643 | B33: =VLOOKUP(A33,[5]LISTADHERENT!A$5:H$39,3,0) -> TCHOUTOU NANA CLAUDE | D33: 43000 | F33: =SUM(C33:E33) -> 43000
A34: AS201658 | B34: =VLOOKUP(A34,[5]LISTADHERENT!A$5:H$39,3,0) -> YANTCHOU GERVAIS | D34: 100000 | F34: =SUM(C34:E34) -> 100000
A35: AS201646 | B35: =VLOOKUP(A35,[5]LISTADHERENT!A$5:H$39,3,0) -> YEPMOU JEAN JACQUES | F35: =SUM(C35:E35) -> 0
A36: AS201647 | B36: =VLOOKUP(A36,[5]LISTADHERENT!A$5:H$39,3,0) -> YOUMBI EMMANUEL | C36: 290000 | F36: =SUM(C36:E36) -> 290000
B38: TOTAUX | C38: =SUM(C7:C37) -> 4660000 | D38: =SUM(D7:D37) -> 229000 | E38: =SUM(E7:E37) -> 0 | F38: =SUM(F7:F37) -> 4889000 | G38: =SUM(G7:G37) -> 4660000 | H38: =SUM(H8:H37) -> 0
G41: =+C38-G38 -> 0

Sheet HISTOBQUEMAI23
A1: ASSOCIATION | B1: ASELBY | C1: MOIS DE MAI
A2: ANNEE | B2: 2023
A3: 1 | B3: 2 | C3: 4 | D3: 5 | E3: 6 | F3: 21
B4: HISTORIQUE BANCAIRE
A5: MATRICULE | B5: NOM ET PRENOM | C5: HISTORIQUE BANQUE | D5: HITORIQUE ESPECES | E5: HITORIQUE TONTINE | F5: MONTANT ENGAGEMENT | G5: VERIFICATION | H5: AGIO
A6: AS201648 | B6: =VLOOKUP(A6,[5]LISTADHERENT!A$5:H$39,3,0) -> ASELBY | C6: 175000 | F6: =SUM(C6:E6) -> 175000
A7: AS201601 | B7: =VLOOKUP(A7,[5]LISTADHERENT!A$5:H$39,3,0) -> BAKOP ACHILLE | C7: 40000 | F7: =SUM(C7:E7) -> 40000 | G7: 255000
A8: AS201602 | B8: =VLOOKUP(A8,[5]LISTADHERENT!A$5:H$39,3,0) -> BOUTCHOUANG WILLIAM | C8: 115000 | F8: =SUM(C8:E8) -> 115000 | G8: 115000
A9: AS201604 | B9: =VLOOKUP(A9,[5]LISTADHERENT!A$5:H$39,3,0) -> DJOMO JEAN PAUL | C9: 145000 | D9: 23000 | F9: =SUM(C9:E9) -> 168000 | G9: 115000
A10: AS201654 | B10: =VLOOKUP(A10,[5]LISTADHERENT!A$5:H$39,3,0) -> DJOMOU TCHAPDA | D10: 105000 | F10: =SUM(C10:E10) -> 105000 | G10: 40000
A11: AS201605 | B11: =VLOOKUP(A11,[5]LISTADHERENT!A$5:H$39,3,0) -> DJOUKWE NANGUEN GUY BLAISE | C11: =115000+152000 -> 267000 | F11: =SUM(C11:E11) -> 267000 | G11: 140000
A12: AS201608 | B12: =VLOOKUP(A12,[5]LISTADHERENT!A$5:H$39,3,0) -> DJUOMBESSY ANTOINE | C12: 420000 | E12: 70000 | F12: =SUM(C12:E12) -> 490000 | G12: 380000
A13: AS201651 | B13: =VLOOKUP(A13,[5]LISTADHERENT!A$5:H$39,3,0) -> DOMOU FABIEN | C13: 40000 | F13: =SUM(C13:E13) -> 40000 | G13: 560000
A14: AS201609 | B14: =VLOOKUP(A14,[5]LISTADHERENT!A$5:H$39,3,0) -> DONHOU DAVID | C14: 40000 | F14: =SUM(C14:E14) -> 40000 | G14: 420000
A15: AS201611 | B15: =VLOOKUP(A15,[5]LISTADHERENT!A$5:H$39,3,0) -> HENGUE PAUL OMER | D15: 118000 | F15: =SUM(C15:E15) -> 118000 | G15: 230000
A16: AS201613 | B16: =VLOOKUP(A16,[5]LISTADHERENT!A$5:H$39,3,0) -> HOTCHO BENJAMIN | C16: 230000 | E16: 70000 | F16: =SUM(C16:E16) -> 300000 | G16: 115000
A17: AS201617 | B17: =VLOOKUP(A17,[5]LISTADHERENT!A$5:H$39,3,0) -> KOUAMOU MOISE | C17: 140000 | F17: =SUM(C17:E17) -> 140000 | G17: 140000
A18: AS201619 | B18: =VLOOKUP(A18,[5]LISTADHERENT!A$5:H$39,3,0) -> KOUATCHO MESSACK | C18: 315000 | F18: =SUM(C18:E18) -> 315000 | G18: 40000
A19: AS201620 | B19: =VLOOKUP(A19,[5]LISTADHERENT!A$5:H$39,3,0) -> LOWE JEAN | C19: 40000 | E19: 70000 | F19: =SUM(C19:E19) -> 110000 | G19: 100000
A20: AS201649 | B20: =VLOOKUP(A20,[5]LISTADHERENT!A$5:H$39,3,0) -> MBOGNING TUGMA GUY | C20: =367000-152000 -> 215000 | F20: =SUM(C20:E20) -> 215000 | G20: 115000
A21: AS201639 | B21: =VLOOKUP(A21,[5]LISTADHERENT!A$5:H$39,3,0) -> NANGUEN MARTIN | C21: 40000 | F21: =SUM(C21:E21) -> 40000 | G21: 140000
A22: AS201621 | B22: =VLOOKUP(A22,[5]LISTADHERENT!A$5:H$39,3,0) -> NANKAM APPOLINAIRE | C22: 115000 | F22: =SUM(C22:E22) -> 115000 | G22: 40000
A23: AS201622 | B23: =VLOOKUP(A23,[5]LISTADHERENT!A$5:H$39,3,0) -> NDJOMO ETIENNE | C23: 250000 | F23: =SUM(C23:E23) -> 250000 | G23: 40000
A24: AS201624 | B24: =VLOOKUP(A24,[5]LISTADHERENT!A$5:H$39,3,0) -> NGONDIEP CLAUDE | C24: 210000 | F24: =SUM(C24:E24) -> 210000 | G24: 367000
A25: AS201626 | B25: =VLOOKUP(A25,[5]LISTADHERENT!A$5:H$39,3,0) -> NGUIEMEGNI MATHIEU BLAISE | C25: 380000 | F25: =SUM(C25:E25) -> 380000 | G25: 250000
A26: AS201628 | B26: =VLOOKUP(A26,[5]LISTADHERENT!A$5:H$39,3,0) -> NKAMGANG JUSTIN DEJOLIE | D26: 104000 | F26: =SUM(C26:E26) -> 104000 | G26: 40000
A27: AS201656 | B27: =VLOOKUP(A27,[5]LISTADHERENT!A$5:H$39,3,0) -> NOUBE ETIENNE | C27: 560000 | F27: =SUM(C27:E27) -> 560000 | G27: 40000
A28: AS201633 | B28: =VLOOKUP(A28,[5]LISTADHERENT!A$5:H$39,3,0) -> PATEGO NJOSSU GUSTAVE | C28: 115000 | F28: =SUM(C28:E28) -> 115000 | G28: 315000
A29: AS201657 | B29: =VLOOKUP(A29,[5]LISTADHERENT!A$5:H$39,3,0) -> SEUMO POLYCARPE | C29: 40000 | F29: =SUM(C29:E29) -> 40000 | G29: 210000
A30: AS201653 | B30: =VLOOKUP(A30,[5]LISTADHERENT!A$5:H$39,3,0) -> SIME BRICE | C30: 115000 | F30: =SUM(C30:E30) -> 115000
A31: AS201638 | B31: =VLOOKUP(A31,[5]LISTADHERENT!A$5:H$39,3,0) -> SIMO PIERRE | C31: 140000 | F31: =SUM(C31:E31) -> 140000
A32: AS201641 | B32: =VLOOKUP(A32,[5]LISTADHERENT!A$5:H$39,3,0) -> TCHOUAMOU MATHIEU | C32: 255000 | F32: =SUM(C32:E32) -> 255000
A33: AS201643 | B33: =VLOOKUP(A33,[5]LISTADHERENT!A$5:H$39,3,0) -> TCHOUTOU NANA CLAUDE | D33: 40000 | F33: =SUM(C33:E33) -> 40000
A34: AS201658 | B34: =VLOOKUP(A34,[5]LISTADHERENT!A$5:H$39,3,0) -> YANTCHOU GERVAIS | C34: 100000 | F34: =SUM(C34:E34) -> 100000
A35: AS201646 | B35: =VLOOKUP(A35,[5]LISTADHERENT!A$5:H$39,3,0) -> YEPMOU JEAN JACQUES | D35: =43000+43000 -> 86000 | F35: =SUM(C35:E35) -> 86000
A36: AS201647 | B36: =VLOOKUP(A36,[5]LISTADHERENT!A$5:H$39,3,0) -> YOUMBI EMMANUEL | C36: 290000 | F36: =SUM(C36:E36) -> 290000
B38: TOTAUX | C38: =SUM(C7:C37) -> 4617000 | D38: =SUM(D7:D37) -> 476000 | E38: =SUM(E7:E37) -> 210000 | F38: =SUM(F7:F37) -> 5303000 | G38: =SUM(G7:G37) -> 4207000 | H38: =SUM(H8:H37) -> 0

Sheet HISTOBQUEJUIN23
A1: ASSOCIATION | B1: ASELBY | C1: MOIS DE JUIN
A2: ANNEE | B2: 2023
A3: 1 | B3: 2 | C3: 4 | D3: 5 | E3: 6 | F3: 21
B4: HISTORIQUE BANCAIRE
A5: MATRICULE | B5: NOM ET PRENOM | C5: HISTORIQUE BANQUE | D5: HITORIQUE ESPECES | E5: HITORIQUE TONTINE | F5: MONTANT ENGAGEMENT | G5: VERIFICATION | H5: AGIO | I5: VALIDATION
A6: AS201648 | B6: =VLOOKUP(A6,[5]LISTADHERENT!A$5:H$39,3,0) -> ASELBY | C6: =IF(I6="OK",VLOOKUP(A6,[6]MONTVERST!A$5:F$39,3,0),0) -> 175000 | F6: =SUM(C6:E6) -> 175000 | I6: OK
A7: AS201601 | B7: =VLOOKUP(A7,[5]LISTADHERENT!A$5:H$39,3,0) -> BAKOP ACHILLE | C7: =IF(I7="OK",VLOOKUP(A7,[6]MONTVERST!A$5:F$39,3,0),0) -> 40000 | F7: =SUM(C7:E7) -> 40000 | G7: 115000 | I7: OK
A8: AS201602 | B8: =VLOOKUP(A8,[5]LISTADHERENT!A$5:H$39,3,0) -> BOUTCHOUANG WILLIAM | C8: =IF(I8="OK",VLOOKUP(A8,[6]MONTVERST!A$5:F$39,3,0),0) -> 115000 | F8: =SUM(C8:E8) -> 115000 | G8: 40000 | I8: OK
A9: AS201604 | B9: =VLOOKUP(A9,[5]LISTADHERENT!A$5:H$39,3,0) -> DJOMO JEAN PAUL | C9: =140000+51000 -> 191000 | F9: =SUM(C9:E9) -> 191000 | G9: 170000 | I9: OK
A10: AS201654 | B10: =VLOOKUP(A10,[5]LISTADHERENT!A$5:H$39,3,0) -> DJOMOU TCHAPDA | C10: =IF(I10="OK",VLOOKUP(A10,[6]MONTVERST!A$5:F$39,3,0),0) -> 0 | D10: =94000-51000 -> 43000 | F10: =SUM(C10:E10) -> 43000 | G10: 40000
A11: AS201605 | B11: =VLOOKUP(A11,[5]LISTADHERENT!A$5:H$39,3,0) -> DJOUKWE NANGUEN GUY BLAISE | C11: 170000 | F11: =SUM(C11:E11) -> 170000 | G11: 140000 | I11: OK
A12: AS201608 | B12: =VLOOKUP(A12,[5]LISTADHERENT!A$5:H$39,3,0) -> DJUOMBESSY ANTOINE | C12: 388000 | F12: =SUM(C12:E12) -> 388000 | G12: 350000 | I12: OK
A13: AS201651 | B13: =VLOOKUP(A13,[5]LISTADHERENT!A$5:H$39,3,0) -> DOMOU FABIEN | C13: =IF(I13="OK",VLOOKUP(A13,[6]MONTVERST!A$5:F$39,3,0),0) -> 40000 | F13: =SUM(C13:E13) -> 40000 | G13: 140000 | I13: OK
A14: AS201609 | B14: =VLOOKUP(A14,[5]LISTADHERENT!A$5:H$39,3,0) -> DONHOU DAVID | C14: =IF(I14="OK",VLOOKUP(A14,[6]MONTVERST!A$5:F$39,3,0),0) -> 40000 | F14: =SUM(C14:E14) -> 40000 | G14: 1215000 | I14: OK
A15: AS201611 | B15: =VLOOKUP(A15,[5]LISTADHERENT!A$5:H$39,3,0) -> HENGUE PAUL OMER | C15: =IF(I15="OK",VLOOKUP(A15,[6]MONTVERST!A$5:F$39,3,0),0) -> 115000 | F15: =SUM(C15:E15) -> 115000 | G15: 40000 | I15: OK
A16: AS201613 | B16: =VLOOKUP(A16,[5]LISTADHERENT!A$5:H$39,3,0) -> HOTCHO BENJAMIN | C16: =IF(I16="OK",VLOOKUP(A16,[6]MONTVERST!A$5:F$39,3,0),0) -> 250000 | F16: =SUM(C16:E16) -> 250000 | G16: 100000 | I16: OK
A17: AS201617 | B17: =VLOOKUP(A17,[5]LISTADHERENT!A$5:H$39,3,0) -> KOUAMOU MOISE | C17: =IF(I17="OK",VLOOKUP(A17,[6]MONTVERST!A$5:F$39,3,0),0) -> 140000 | F17: =SUM(C17:E17) -> 140000 | G17: 290000 | I17: OK
A18: AS201619 | B18: =VLOOKUP(A18,[5]LISTADHERENT!A$5:H$39,3,0) -> KOUATCHO MESSACK | C18: 1215000 | F18: =SUM(C18:E18) -> 1215000 | G18: 115000 | I18: OK
A19: AS201620 | B19: =VLOOKUP(A19,[5]LISTADHERENT!A$5:H$39,3,0) -> LOWE JEAN | C19: =IF(I19="OK",VLOOKUP(A19,[6]MONTVERST!A$5:F$39,3,0),0) -> 40000 | F19: =SUM(C19:E19) -> 40000 | G19: 115000 | I19: OK
A20: AS201649 | B20: =VLOOKUP(A20,[5]LISTADHERENT!A$5:H$39,3,0) -> MBOGNING TUGMA GUY | C20: 998000 | F20: =SUM(C20:E20) -> 998000 | G20: 102000 | I20: OK
A21: AS201639 | B21: =VLOOKUP(A21,[5]LISTADHERENT!A$5:H$39,3,0) -> NANGUEN MARTIN | C21: =IF(I21="OK",VLOOKUP(A21,[6]MONTVERST!A$5:F$39,3,0),0) -> 40000 | F21: =SUM(C21:E21) -> 40000 | G21: 250000 | I21: OK
A22: AS201621 | B22: =VLOOKUP(A22,[5]LISTADHERENT!A$5:H$39,3,0) -> NANKAM APPOLINAIRE | C22: =IF(I22="OK",VLOOKUP(A22,[6]MONTVERST!A$5:F$39,3,0),0) -> 115000 | E22: 70000 | F22: =SUM(C22:E22) -> 185000 | G22: 115000 | I22: OK
A23: AS201622 | B23: =VLOOKUP(A23,[5]LISTADHERENT!A$5:H$39,3,0) -> NDJOMO ETIENNE | C23: 452000 | F23: =SUM(C23:E23) -> 452000 | G23: 115000 | I23: OK
A24: AS201624 | B24: =VLOOKUP(A24,[5]LISTADHERENT!A$5:H$39,3,0) -> NGONDIEP CLAUDE | C24: =IF(I24="OK",VLOOKUP(A24,[6]MONTVERST!A$5:F$39,3,0),0) -> 215000 | F24: =SUM(C24:E24) -> 215000 | G24: 350000 | I24: OK
A25: AS201626 | B25: =VLOOKUP(A25,[5]LISTADHERENT!A$5:H$39,3,0) -> NGUIEMEGNI MATHIEU BLAISE | C25: 350000 | F25: =SUM(C25:E25) -> 350000 | G25: 38500 | I25: OK
A26: AS201628 | B26: =VLOOKUP(A26,[5]LISTADHERENT!A$5:H$39,3,0) -> NKAMGANG JUSTIN DEJOLIE | C26: =IF(I26="OK",VLOOKUP(A26,[6]MONTVERST!A$5:F$39,3,0),0) -> 40000 | F26: =SUM(C26:E26) -> 40000 | G26: 250000 | I26: OK
A27: AS201656 | B27: =VLOOKUP(A27,[5]LISTADHERENT!A$5:H$39,3,0) -> NOUBE ETIENNE | C27: 45000 | F27: =SUM(C27:E27) -> 45000 | G27: 202000 | I27: OK
A28: AS201633 | B28: =VLOOKUP(A28,[5]LISTADHERENT!A$5:H$39,3,0) -> PATEGO NJOSSU GUSTAVE | C28: =IF(I28="OK",VLOOKUP(A28,[6]MONTVERST!A$5:F$39,3,0),0) -> 115000 | F28: =SUM(C28:E28) -> 115000 | G28: 998000 | I28: OK
A29: AS201657 | B29: =VLOOKUP(A29,[5]LISTADHERENT!A$5:H$39,3,0) -> SEUMO POLYCARPE | C29: =IF(I29="OK",VLOOKUP(A29,[6]MONTVERST!A$5:F$39,3,0),0) -> 40000 | F29: =SUM(C29:E29) -> 40000 | G29: 40000 | I29: OK
A30: AS201653 | B30: =VLOOKUP(A30,[5]LISTADHERENT!A$5:H$39,3,0) -> SIME BRICE | C30: =IF(I30="OK",VLOOKUP(A30,[6]MONTVERST!A$5:F$39,3,0),0) -> 115000 | F30: =SUM(C30:E30) -> 115000 | G30: 40000 | I30: OK
A31: AS201638 | B31: =VLOOKUP(A31,[5]LISTADHERENT!A$5:H$39,3,0) -> SIMO PIERRE | C31: =IF(I31="OK",VLOOKUP(A31,[6]MONTVERST!A$5:F$39,3,0),0) -> 140000 | F31: =SUM(C31:E31) -> 140000 | G31: 45000 | I31: OK
A32: AS201641 | B32: =VLOOKUP(A32,[5]LISTADHERENT!A$5:H$39,3,0) -> TCHOUAMOU MATHIEU | C32: 217000 | F32: =SUM(C32:E32) -> 217000 | G32: 40000 | I32: OK
A33: AS201643 | B33: =VLOOKUP(A33,[5]LISTADHERENT!A$5:H$39,3,0) -> TCHOUTOU NANA CLAUDE | C33: =IF(I33="OK",VLOOKUP(A33,[6]MONTVERST!A$5:F$39,3,0),0) -> 40000 | F33: =SUM(C33:E33) -> 40000 | G33: 40000 | I33: OK
A34: AS201658 | B34: =VLOOKUP(A34,[5]LISTADHERENT!A$5:H$39,3,0) -> YANTCHOU GERVAIS | C34: =IF(I34="OK",VLOOKUP(A34,[6]MONTVERST!A$5:F$39,3,0),0) -> 100000 | F34: =SUM(C34:E34) -> 100000 | G34: 40000 | I34: OK
A35: AS201646 | B35: =VLOOKUP(A35,[5]LISTADHERENT!A$5:H$39,3,0) -> YEPMOU JEAN JACQUES | C35: =IF(I35="OK",VLOOKUP(A35,[6]MONTVERST!A$5:F$39,3,0),0) -> 40000 | F35: =SUM(C35:E35) -> 40000 | G35: 40000 | I35: OK
A36: AS201647 | B36: =VLOOKUP(A36,[5]LISTADHERENT!A$5:H$39,3,0) -> YOUMBI EMMANUEL | C36: =IF(I36="OK",VLOOKUP(A36,[6]MONTVERST!A$5:F$39,3,0),0) -> 290000 | F36: =SUM(C36:E36) -> 290000 | G36: =255000+215000 -> 470000 | I36: OK
B38: TOTAUX | C38: =SUM(C7:C37) -> 6096000 | D38: =SUM(D7:D37) -> 43000 | E38: =SUM(E7:E37) -> 70000 | F38: =SUM(F7:F37) -> 6209000 | G38: =SUM(G7:G37) -> 6045500 | H38: =SUM(H8:H37) -> 0

Sheet HISTOBQUEJUIL23
A1: ASSOCIATION | B1: ASELBY | C1: MOIS DE JUILLET
A2: ANNEE | B2: 2023
A3: 1 | B3: 2 | C3: 4 | D3: 5 | E3: 6 | F3: 21
B4: HISTORIQUE BANCAIRE
A5: MATRICULE | B5: NOM ET PRENOM | C5: HISTORIQUE BANQUE | D5: HITORIQUE ESPECES | E5: HITORIQUE TONTINE | F5: MONTANT ENGAGEMENT | G5: VERIFICATION | H5: AGIO | I5: VALIDATION
A6: AS201648 | B6: =VLOOKUP(A6,[5]LISTADHERENT!A$5:H$39,3,0) -> ASELBY | C6: =IF(I6="OK",VLOOKUP(A6,[6]MONTVERST!A$5:F$39,3,0),0) -> 175000 | F6: =SUM(C6:E6) -> 175000 | I6: OK
A7: AS201601 | B7: =VLOOKUP(A7,[5]LISTADHERENT!A$5:H$39,3,0) -> BAKOP ACHILLE | C7: =IF(I7="OK",VLOOKUP(A7,[6]MONTVERST!A$5:F$39,3,0),0) -> 40000 | D7: 33500 | E7: 140000 | F7: =SUM(C7:E7) -> 213500 | I7: OK
A8: AS201602 | B8: =VLOOKUP(A8,[5]LISTADHERENT!A$5:H$39,3,0) -> BOUTCHOUANG WILLIAM | C8: =IF(I8="OK",VLOOKUP(A8,[6]MONTVERST!A$5:F$39,3,0),0) -> 115000 | F8: =SUM(C8:E8) -> 115000 | I8: OK
A9: AS201604 | B9: =VLOOKUP(A9,[5]LISTADHERENT!A$5:H$39,3,0) -> DJOMO JEAN PAUL | C9: 241000 | D9: 87500 | F9: =SUM(C9:E9) -> 328500 | I9: OK
A10: AS201654 | B10: =VLOOKUP(A10,[5]LISTADHERENT!A$5:H$39,3,0) -> DJOMOU TCHAPDA | C10: =IF(I10="OK",VLOOKUP(A10,[6]MONTVERST!A$5:F$39,3,0),0) -> 0 | D10: 40000 | F10: =SUM(C10:E10) -> 40000
A11: AS201605 | B11: =VLOOKUP(A11,[5]LISTADHERENT!A$5:H$39,3,0) -> DJOUKWE NANGUEN GUY BLAISE | C11: =IF(I11="OK",VLOOKUP(A11,[6]MONTVERST!A$5:F$39,3,0),0) -> 115000 | D11: =50000+35500 -> 85500 | F11: =SUM(C11:E11) -> 200500 | I11: OK
A12: AS201608 | B12: =VLOOKUP(A12,[5]LISTADHERENT!A$5:H$39,3,0) -> DJUOMBESSY ANTOINE | C12: =IF(I12="OK",VLOOKUP(A12,[6]MONTVERST!A$5:F$39,3,0),0)+40000 -> 360000 | F12: =SUM(C12:E12) -> 360000 | I12: OK
A13: AS201651 | B13: =VLOOKUP(A13,[5]LISTADHERENT!A$5:H$39,3,0) -> DOMOU FABIEN | C13: =IF(I13="OK",VLOOKUP(A13,[6]MONTVERST!A$5:F$39,3,0),0) -> 40000 | F13: =SUM(C13:E13) -> 40000 | I13: OK
A14: AS201609 | B14: =VLOOKUP(A14,[5]LISTADHERENT!A$5:H$39,3,0) -> DONHOU DAVID | C14: =IF(I14="OK",VLOOKUP(A14,[6]MONTVERST!A$5:F$39,3,0),0) -> 40000 | F14: =SUM(C14:E14) -> 40000 | I14: OK
A15: AS201611 | B15: =VLOOKUP(A15,[5]LISTADHERENT!A$5:H$39,3,0) -> HENGUE PAUL OMER | C15: =IF(I15="OK",VLOOKUP(A15,[6]MONTVERST!A$5:F$39,3,0),0) -> 115000 | E15: 70000 | F15: =SUM(C15:E15) -> 185000 | I15: OK
A16: AS201613 | B16: =VLOOKUP(A16,[5]LISTADHERENT!A$5:H$39,3,0) -> HOTCHO BENJAMIN | C16: =IF(I16="OK",VLOOKUP(A16,[6]MONTVERST!A$5:F$39,3,0),0) -> 250000 | F16: =SUM(C16:E16) -> 250000 | I16: OK
A17: AS201617 | B17: =VLOOKUP(A17,[5]LISTADHERENT!A$5:H$39,3,0) -> KOUAMOU MOISE | C17: =IF(I17="OK",VLOOKUP(A17,[6]MONTVERST!A$5:F$39,3,0),0) -> 140000 | F17: =SUM(C17:E17) -> 140000 | I17: OK
A18: AS201619 | B18: =VLOOKUP(A18,[5]LISTADHERENT!A$5:H$39,3,0) -> KOUATCHO MESSACK | C18: =IF(I18="OK",VLOOKUP(A18,[6]MONTVERST!A$5:F$39,3,0),0) -> 215000 | F18: =SUM(C18:E18) -> 215000 | I18: OK
A19: AS201620 | B19: =VLOOKUP(A19,[5]LISTADHERENT!A$5:H$39,3,0) -> LOWE JEAN | C19: =IF(I19="OK",VLOOKUP(A19,[6]MONTVERST!A$5:F$39,3,0),0) -> 40000 | F19: =SUM(C19:E19) -> 40000 | I19: OK
A20: AS201649 | B20: =VLOOKUP(A20,[5]LISTADHERENT!A$5:H$39,3,0) -> MBOGNING TUGMA GUY | C20: 1021000 | F20: =SUM(C20:E20) -> 1021000 | I20: OK
A21: AS201639 | B21: =VLOOKUP(A21,[5]LISTADHERENT!A$5:H$39,3,0) -> NANGUEN MARTIN | C21: =IF(I21="OK",VLOOKUP(A21,[6]MONTVERST!A$5:F$39,3,0),0) -> 40000 | F21: =SUM(C21:E21) -> 40000 | I21: OK
A22: AS201621 | B22: =VLOOKUP(A22,[5]LISTADHERENT!A$5:H$39,3,0) -> NANKAM APPOLINAIRE | C22: =IF(I22="OK",VLOOKUP(A22,[6]MONTVERST!A$5:F$39,3,0),0) -> 115000 | F22: =SUM(C22:E22) -> 115000 | I22: OK
A23: AS201622 | B23: =VLOOKUP(A23,[5]LISTADHERENT!A$5:H$39,3,0) -> NDJOMO ETIENNE | C23: =IF(I23="OK",VLOOKUP(A23,[6]MONTVERST!A$5:F$39,3,0),0) -> 250000 | F23: =SUM(C23:E23) -> 250000 | I23: OK
A24: AS201624 | B24: =VLOOKUP(A24,[5]LISTADHERENT!A$5:H$39,3,0) -> NGONDIEP CLAUDE | C24: 220000 | F24: =SUM(C24:E24) -> 220000 | I24: OK
A25: AS201626 | B25: =VLOOKUP(A25,[5]LISTADHERENT!A$5:H$39,3,0) -> NGUIEMEGNI MATHIEU BLAISE | C25: 400000 | F25: =SUM(C25:E25) -> 400000 | I25: OK
A26: AS201628 | B26: =VLOOKUP(A26,[5]LISTADHERENT!A$5:H$39,3,0) -> NKAMGANG JUSTIN DEJOLIE | C26: =IF(I26="OK",VLOOKUP(A26,[6]MONTVERST!A$5:F$39,3,0),0) -> 0 | D26: =43000 -> 43000 | F26: =SUM(C26:E26) -> 43000
A27: AS201656 | B27: =VLOOKUP(A27,[5]LISTADHERENT!A$5:H$39,3,0) -> NOUBE ETIENNE | C27: =IF(I27="OK",VLOOKUP(A27,[6]MONTVERST!A$5:F$39,3,0),0) -> 50000 | F27: =SUM(C27:E27) -> 50000 | I27: OK
A28: AS201633 | B28: =VLOOKUP(A28,[5]LISTADHERENT!A$5:H$39,3,0) -> PATEGO NJOSSU GUSTAVE | C28: =IF(I28="OK",VLOOKUP(A28,[6]MONTVERST!A$5:F$39,3,0),0) -> 115000 | F28: =SUM(C28:E28) -> 115000 | I28: OK
A29: AS201657 | B29: =VLOOKUP(A29,[5]LISTADHERENT!A$5:H$39,3,0) -> SEUMO POLYCARPE | C29: =IF(I29="OK",VLOOKUP(A29,[6]MONTVERST!A$5:F$39,3,0),0) -> 40000 | F29: =SUM(C29:E29) -> 40000 | I29: OK
A30: AS201653 | B30: =VLOOKUP(A30,[5]LISTADHERENT!A$5:H$39,3,0) -> SIME BRICE | C30: =IF(I30="OK",VLOOKUP(A30,[6]MONTVERST!A$5:F$39,3,0),0) -> 115000 | F30: =SUM(C30:E30) -> 115000 | I30: OK
A31: AS201638 | B31: =VLOOKUP(A31,[5]LISTADHERENT!A$5:H$39,3,0) -> SIMO PIERRE | C31: =IF(I31="OK",VLOOKUP(A31,[6]MONTVERST!A$5:F$39,3,0),0) -> 140000 | F31: =SUM(C31:E31) -> 140000 | I31: OK
A32: AS201641 | B32: =VLOOKUP(A32,[5]LISTADHERENT!A$5:H$39,3,0) -> TCHOUAMOU MATHIEU | C32: =IF(I32="OK",VLOOKUP(A32,[6]MONTVERST!A$5:F$39,3,0),0) -> 115000 | D32: 102000 | E32: =70000 -> 70000 | F32: =SUM(C32:E32) -> 287000 | I32: OK
A33: AS201643 | B33: =VLOOKUP(A33,[5]LISTADHERENT!A$5:H$39,3,0) -> TCHOUTOU NANA CLAUDE | C33: =IF(I33="OK",VLOOKUP(A33,[6]MONTVERST!A$5:F$39,3,0),0) -> 40000 | F33: =SUM(C33:E33) -> 40000 | I33: OK
A34: AS201658 | B34: =VLOOKUP(A34,[5]LISTADHERENT!A$5:H$39,3,0) -> YANTCHOU GERVAIS | C34: =IF(I34="OK",VLOOKUP(A34,[6]MONTVERST!A$5:F$39,3,0),0) -> 100000 | F34: =SUM(C34:E34) -> 100000 | I34: OK
A35: AS201646 | B35: =VLOOKUP(A35,[5]LISTADHERENT!A$5:H$39,3,0) -> YEPMOU JEAN JACQUES | C35: =IF(I35="OK",VLOOKUP(A35,[6]MONTVERST!A$5:F$39,3,0),0) -> 40000 | F35: =SUM(C35:E35) -> 40000 | I35: OK
A36: AS201647 | B36: =VLOOKUP(A36,[5]LISTADHERENT!A$5:H$39,3,0) -> YOUMBI EMMANUEL | C36: =IF(I36="OK",VLOOKUP(A36,[6]MONTVERST!A$5:F$39,3,0),0) -> 290000 | F36: =SUM(C36:E36) -> 290000 | I36: OK
B38: TOTAUX | C38: =SUM(C7:C37) -> 4802000 | D38: =SUM(D7:D37) -> 391500 | E38: =SUM(E7:E37) -> 280000 | F38: =SUM(F7:F37) -> 5473500 | G38: =SUM(G7:G37) -> 0 | H38: =SUM(H8:H37) -> 0

Sheet HISTOBQUEAOUT23
A1: ASSOCIATION | B1: ASELBY | C1: MOIS DE AOUT
A2: ANNEE | B2: 2023
A3: 1 | B3: 2 | C3: 4 | D3: 5 | E3: 6 | F3: 21
B4: HISTORIQUE BANCAIRE
A5: MATRICULE | B5: NOM ET PRENOM | C5: HISTORIQUE BANQUE | D5: HITORIQUE ESPECES | E5: HITORIQUE TONTINE | F5: MONTANT ENGAGEMENT | G5: VERIFICATION | H5: AGIO | I5: VALIDATION
A6: AS201648 | B6: =VLOOKUP(A6,[5]LISTADHERENT!A$5:H$39,3,0) -> ASELBY | C6: =IF(I6="OK",VLOOKUP(A6,[6]MONTVERST!A$5:F$39,3,0),0) -> 175000 | F6: =SUM(C6:E6) -> 175000 | I6: OK
A7: AS201601 | B7: =VLOOKUP(A7,[5]LISTADHERENT!A$5:H$39,3,0) -> BAKOP ACHILLE | C7: =IF(I7="OK",VLOOKUP(A7,[6]MONTVERST!A$5:F$39,3,0),0) -> 40000 | F7: =SUM(C7:E7) -> 40000 | I7: OK
A8: AS201602 | B8: =VLOOKUP(A8,[5]LISTADHERENT!A$5:H$39,3,0) -> BOUTCHOUANG WILLIAM | C8: =IF(I8="OK",VLOOKUP(A8,[6]MONTVERST!A$5:F$39,3,0),0) -> 115000 | F8: =SUM(C8:E8) -> 115000 | I8: OK
A9: AS201604 | B9: =VLOOKUP(A9,[5]LISTADHERENT!A$5:H$39,3,0) -> DJOMO JEAN PAUL | C9: =IF(I9="OK",VLOOKUP(A9,[6]MONTVERST!A$5:F$39,3,0),0) -> 140000 | D9: 202000 | F9: =SUM(C9:E9) -> 342000 | I9: OK
A10: AS201654 | B10: =VLOOKUP(A10,[5]LISTADHERENT!A$5:H$39,3,0) -> DJOMOU TCHAPDA | C10: =IF(I10="OK",VLOOKUP(A10,[6]MONTVERST!A$5:F$39,3,0),0) -> 0 | D10: 43000 | F10: =SUM(C10:E10) -> 43000
A11: AS201605 | B11: =VLOOKUP(A11,[5]LISTADHERENT!A$5:H$39,3,0) -> DJOUKWE NANGUEN GUY BLAISE | C11: =IF(I11="OK",VLOOKUP(A11,[6]MONTVERST!A$5:F$39,3,0),0) -> 115000 | F11: =SUM(C11:E11) -> 115000 | I11: OK
A12: AS201608 | B12: =VLOOKUP(A12,[5]LISTADHERENT!A$5:H$39,3,0) -> DJUOMBESSY ANTOINE | C12: =IF(I12="OK",VLOOKUP(A12,[6]MONTVERST!A$5:F$39,3,0),0) -> 320000 | F12: =SUM(C12:E12) -> 320000 | I12: OK
A13: AS201651 | B13: =VLOOKUP(A13,[5]LISTADHERENT!A$5:H$39,3,0) -> DOMOU FABIEN | C13: =IF(I13="OK",VLOOKUP(A13,[6]MONTVERST!A$5:F$39,3,0),0) -> 40000 | F13: =SUM(C13:E13) -> 40000 | I13: OK
A14: AS201609 | B14: =VLOOKUP(A14,[5]LISTADHERENT!A$5:H$39,3,0) -> DONHOU DAVID | C14: =IF(I14="OK",VLOOKUP(A14,[6]MONTVERST!A$5:F$39,3,0),0) -> 40000 | F14: =SUM(C14:E14) -> 40000 | I14: OK
A15: AS201611 | B15: =VLOOKUP(A15,[5]LISTADHERENT!A$5:H$39,3,0) -> HENGUE PAUL OMER | C15: =IF(I15="OK",VLOOKUP(A15,[6]MONTVERST!A$5:F$39,3,0),0) -> 115000 | F15: =SUM(C15:E15) -> 115000 | I15: OK
A16: AS201613 | B16: =VLOOKUP(A16,[5]LISTADHERENT!A$5:H$39,3,0) -> HOTCHO BENJAMIN | C16: =IF(I16="OK",VLOOKUP(A16,[6]MONTVERST!A$5:F$39,3,0),0) -> 250000 | F16: =SUM(C16:E16) -> 250000 | I16: OK
A17: AS201617 | B17: =VLOOKUP(A17,[5]LISTADHERENT!A$5:H$39,3,0) -> KOUAMOU MOISE | C17: 241000 | F17: =SUM(C17:E17) -> 241000 | I17: OK
A18: AS201619 | B18: =VLOOKUP(A18,[5]LISTADHERENT!A$5:H$39,3,0) -> KOUATCHO MESSACK | C18: =IF(I18="OK",VLOOKUP(A18,[6]MONTVERST!A$5:F$39,3,0),0) -> 215000 | F18: =SUM(C18:E18) -> 215000 | I18: OK
A19: AS201620 | B19: =VLOOKUP(A19,[5]LISTADHERENT!A$5:H$39,3,0) -> LOWE JEAN | C19: 340000 | F19: =SUM(C19:E19) -> 340000 | I19: OK
A20: AS201649 | B20: =VLOOKUP(A20,[5]LISTADHERENT!A$5:H$39,3,0) -> MBOGNING TUGMA GUY | C20: 586500 | F20: =SUM(C20:E20) -> 586500 | I20: OK
A21: AS201639 | B21: =VLOOKUP(A21,[5]LISTADHERENT!A$5:H$39,3,0) -> NANGUEN MARTIN | C21: =IF(I21="OK",VLOOKUP(A21,[6]MONTVERST!A$5:F$39,3,0),0) -> 40000 | E21: 70000 | F21: =SUM(C21:E21) -> 110000 | I21: OK
A22: AS201621 | B22: =VLOOKUP(A22,[5]LISTADHERENT!A$5:H$39,3,0) -> NANKAM APPOLINAIRE | C22: =IF(I22="OK",VLOOKUP(A22,[6]MONTVERST!A$5:F$39,3,0),0) -> 115000 | F22: =SUM(C22:E22) -> 115000 | I22: OK
A23: AS201622 | B23: =VLOOKUP(A23,[5]LISTADHERENT!A$5:H$39,3,0) -> NDJOMO ETIENNE | C23: 270000 | F23: =SUM(C23:E23) -> 270000 | I23: OK
A24: AS201624 | B24: =VLOOKUP(A24,[5]LISTADHERENT!A$5:H$39,3,0) -> NGONDIEP CLAUDE | C24: 320000 | F24: =SUM(C24:E24) -> 320000 | I24: OK
A25: AS201626 | B25: =VLOOKUP(A25,[5]LISTADHERENT!A$5:H$39,3,0) -> NGUIEMEGNI MATHIEU BLAISE | C25: 400000 | F25: =SUM(C25:E25) -> 400000 | I25: OK
A26: AS201628 | B26: =VLOOKUP(A26,[5]LISTADHERENT!A$5:H$39,3,0) -> NKAMGANG JUSTIN DEJOLIE | C26: 116000 | F26: =SUM(C26:E26) -> 116000 | I26: OK
A27: AS201656 | B27: =VLOOKUP(A27,[5]LISTADHERENT!A$5:H$39,3,0) -> NOUBE ETIENNE | C27: =IF(I27="OK",VLOOKUP(A27,[6]MONTVERST!A$5:F$39,3,0),0) -> 50000 | F27: =SUM(C27:E27) -> 50000 | I27: OK
A28: AS201633 | B28: =VLOOKUP(A28,[5]LISTADHERENT!A$5:H$39,3,0) -> PATEGO NJOSSU GUSTAVE | C28: =IF(I28="OK",VLOOKUP(A28,[6]MONTVERST!A$5:F$39,3,0),0) -> 115000 | F28: =SUM(C28:E28) -> 115000 | I28: OK
A29: AS201657 | B29: =VLOOKUP(A29,[5]LISTADHERENT!A$5:H$39,3,0) -> SEUMO POLYCARPE | C29: =IF(I29="OK",VLOOKUP(A29,[6]MONTVERST!A$5:F$39,3,0),0) -> 40000 | F29: =SUM(C29:E29) -> 40000 | I29: OK
A30: AS201653 | B30: =VLOOKUP(A30,[5]LISTADHERENT!A$5:H$39,3,0) -> SIME BRICE | C30: =IF(I30="OK",VLOOKUP(A30,[6]MONTVERST!A$5:F$39,3,0),0) -> 115000 | E30: 70000 | F30: =SUM(C30:E30) -> 185000 | I30: OK
A31: AS201638 | B31: =VLOOKUP(A31,[5]LISTADHERENT!A$5:H$39,3,0) -> SIMO PIERRE | C31: =IF(I31="OK",VLOOKUP(A31,[6]MONTVERST!A$5:F$39,3,0),0) -> 140000 | F31: =SUM(C31:E31) -> 140000 | I31: OK
A32: AS201641 | B32: =VLOOKUP(A32,[5]LISTADHERENT!A$5:H$39,3,0) -> TCHOUAMOU MATHIEU | C32: =115000+250000 -> 365000 | F32: =SUM(C32:E32) -> 365000 | I32: OK
A33: AS201643 | B33: =VLOOKUP(A33,[5]LISTADHERENT!A$5:H$39,3,0) -> TCHOUTOU NANA CLAUDE | C33: =IF(I33="OK",VLOOKUP(A33,[6]MONTVERST!A$5:F$39,3,0),0) -> 0 | F33: =SUM(C33:E33) -> 0
A34: AS201658 | B34: =VLOOKUP(A34,[5]LISTADHERENT!A$5:H$39,3,0) -> YANTCHOU GERVAIS | C34: =IF(I34="OK",VLOOKUP(A34,[6]MONTVERST!A$5:F$39,3,0),0) -> 100000 | F34: =SUM(C34:E34) -> 100000 | I34: OK
A35: AS201646 | B35: =VLOOKUP(A35,[5]LISTADHERENT!A$5:H$39,3,0) -> YEPMOU JEAN JACQUES | C35: =IF(I35="OK",VLOOKUP(A35,[6]MONTVERST!A$5:F$39,3,0),0) -> 40000 | F35: =SUM(C35:E35) -> 40000 | I35: OK
A36: AS201647 | B36: =VLOOKUP(A36,[5]LISTADHERENT!A$5:H$39,3,0) -> YOUMBI EMMANUEL | C36: =IF(I36="OK",VLOOKUP(A36,[6]MONTVERST!A$5:F$39,3,0),0) -> 290000 | F36: =SUM(C36:E36) -> 290000 | I36: OK
B38: TOTAUX | C38: =SUM(C7:C37) -> 5073500 | D38: =SUM(D7:D37) -> 245000 | E38: =SUM(E7:E37) -> 140000 | F38: =SUM(F7:F37) -> 5458500 | G38: =SUM(G7:G37) -> 0 | H38: =SUM(H8:H37) -> 0

Sheet HISTOBQUESEPT23
A1: ASSOCIATION | B1: ASELBY | C1: MOIS DE SEPTEMBRE
A2: ANNEE | B2: 2023
A3: 1 | B3: 2 | C3: 4 | D3: 5 | E3: 6 | F3: 21
B4: HISTORIQUE BANCAIRE
A5: MATRICULE | B5: NOM ET PRENOM | C5: HISTORIQUE BANQUE | D5: HITORIQUE ESPECES | E5: HITORIQUE TONTINE | F5: MONTANT ENGAGEMENT | G5: VERIFICATION | H5: AGIO | I5: VALIDATION
A6: AS201648 | B6: =VLOOKUP(A6,[5]LISTADHERENT!A$5:H$39,3,0) -> ASELBY | C6: =IF(I6="OK",VLOOKUP(A6,[6]MONTVERST!A$5:F$39,3,0),0) -> 175000 | F6: =SUM(C6:E6) -> 175000 | I6: OK
A7: AS201601 | B7: =VLOOKUP(A7,[5]LISTADHERENT!A$5:H$39,3,0) -> BAKOP ACHILLE | C7: =IF(I7="OK",VLOOKUP(A7,[6]MONTVERST!A$5:F$39,3,0),0) -> 40000 | F7: =SUM(C7:E7) -> 40000 | I7: OK
A8: AS201602 | B8: =VLOOKUP(A8,[5]LISTADHERENT!A$5:H$39,3,0) -> BOUTCHOUANG WILLIAM | C8: =IF(I8="OK",VLOOKUP(A8,[6]MONTVERST!A$5:F$39,3,0),0) -> 115000 | F8: =SUM(C8:E8) -> 115000 | I8: OK
A9: AS201604 | B9: =VLOOKUP(A9,[5]LISTADHERENT!A$5:H$39,3,0) -> DJOMO JEAN PAUL | C9: 340000 | F9: =SUM(C9:E9) -> 340000 | I9: OK
A10: AS201654 | B10: =VLOOKUP(A10,[5]LISTADHERENT!A$5:H$39,3,0) -> DJOMOU TCHAPDA | C10: 141000 | F10: =SUM(C10:E10) -> 141000 | I10: OK
A11: AS201605 | B11: =VLOOKUP(A11,[5]LISTADHERENT!A$5:H$39,3,0) -> DJOUKWE NANGUEN GUY BLAISE | C11: =315000+32000 -> 347000 | F11: =SUM(C11:E11) -> 347000 | I11: OK
A12: AS201608 | B12: =VLOOKUP(A12,[5]LISTADHERENT!A$5:H$39,3,0) -> DJUOMBESSY ANTOINE | C12: =IF(I12="OK",VLOOKUP(A12,[6]MONTVERST!A$5:F$39,3,0),0) -> 320000 | F12: =SUM(C12:E12) -> 320000 | I12: OK
A13: AS201651 | B13: =VLOOKUP(A13,[5]LISTADHERENT!A$5:H$39,3,0) -> DOMOU FABIEN | C13: =IF(I13="OK",VLOOKUP(A13,[6]MONTVERST!A$5:F$39,3,0),0) -> 40000 | F13: =SUM(C13:E13) -> 40000 | I13: OK
A14: AS201609 | B14: =VLOOKUP(A14,[5]LISTADHERENT!A$5:H$39,3,0) -> DONHOU DAVID | C14: =IF(I14="OK",VLOOKUP(A14,[6]MONTVERST!A$5:F$39,3,0),0) -> 40000 | F14: =SUM(C14:E14) -> 40000 | I14: OK
A15: AS201611 | B15: =VLOOKUP(A15,[5]LISTADHERENT!A$5:H$39,3,0) -> HENGUE PAUL OMER | C15: =IF(I15="OK",VLOOKUP(A15,[6]MONTVERST!A$5:F$39,3,0),0) -> 115000 | F15: =SUM(C15:E15) -> 115000 | I15: OK
A16: AS201613 | B16: =VLOOKUP(A16,[5]LISTADHERENT!A$5:H$39,3,0) -> HOTCHO BENJAMIN | C16: =IF(I16="OK",VLOOKUP(A16,[6]MONTVERST!A$5:F$39,3,0),0) -> 250000 | F16: =SUM(C16:E16) -> 250000 | I16: OK
A17: AS201617 | B17: =VLOOKUP(A17,[5]LISTADHERENT!A$5:H$39,3,0) -> KOUAMOU MOISE | C17: =IF(I17="OK",VLOOKUP(A17,[6]MONTVERST!A$5:F$39,3,0),0) -> 140000 | F17: =SUM(C17:E17) -> 140000 | I17: OK
A18: AS201619 | B18: =VLOOKUP(A18,[5]LISTADHERENT!A$5:H$39,3,0) -> KOUATCHO MESSACK | C18: =IF(I18="OK",VLOOKUP(A18,[6]MONTVERST!A$5:F$39,3,0),0) -> 215000 | D18: 100000 | F18: =SUM(C18:E18) -> 315000 | I18: OK
A19: AS201620 | B19: =VLOOKUP(A19,[5]LISTADHERENT!A$5:H$39,3,0) -> LOWE JEAN | C19: =IF(I19="OK",VLOOKUP(A19,[6]MONTVERST!A$5:F$39,3,0),0) -> 40000 | F19: =SUM(C19:E19) -> 40000 | I19: OK
A20: AS201649 | B20: =VLOOKUP(A20,[5]LISTADHERENT!A$5:H$39,3,0) -> MBOGNING TUGMA GUY | C20: =498000+30500 -> 528500 | F20: =SUM(C20:E20) -> 528500 | I20: OK
A21: AS201639 | B21: =VLOOKUP(A21,[5]LISTADHERENT!A$5:H$39,3,0) -> NANGUEN MARTIN | C21: =IF(I21="OK",VLOOKUP(A21,[6]MONTVERST!A$5:F$39,3,0),0) -> 40000 | F21: =SUM(C21:E21) -> 40000 | I21: OK
A22: AS201621 | B22: =VLOOKUP(A22,[5]LISTADHERENT!A$5:H$39,3,0) -> NANKAM APPOLINAIRE | C22: =IF(I22="OK",VLOOKUP(A22,[6]MONTVERST!A$5:F$39,3,0),0) -> 115000 | F22: =SUM(C22:E22) -> 115000 | I22: OK
A23: AS201622 | B23: =VLOOKUP(A23,[5]LISTADHERENT!A$5:H$39,3,0) -> NDJOMO ETIENNE | C23: =IF(I23="OK",VLOOKUP(A23,[6]MONTVERST!A$5:F$39,3,0),0) -> 250000 | F23: =SUM(C23:E23) -> 250000 | I23: OK
A24: AS201624 | B24: =VLOOKUP(A24,[5]LISTADHERENT!A$5:H$39,3,0) -> NGONDIEP CLAUDE | C24: =IF(I24="OK",VLOOKUP(A24,[6]MONTVERST!A$5:F$39,3,0),0) -> 215000 | F24: =SUM(C24:E24) -> 215000 | I24: OK
A25: AS201626 | B25: =VLOOKUP(A25,[5]LISTADHERENT!A$5:H$39,3,0) -> NGUIEMEGNI MATHIEU BLAISE | C25: =400000+40000 -> 440000 | F25: =SUM(C25:E25) -> 440000 | I25: OK
A26: AS201628 | B26: =VLOOKUP(A26,[5]LISTADHERENT!A$5:H$39,3,0) -> NKAMGANG JUSTIN DEJOLIE | C26: 50000 | D26: 94000 | F26: =SUM(C26:E26) -> 144000 | I26: OK
A27: AS201656 | B27: =VLOOKUP(A27,[5]LISTADHERENT!A$5:H$39,3,0) -> NOUBE ETIENNE | C27: =IF(I27="OK",VLOOKUP(A27,[6]MONTVERST!A$5:F$39,3,0),0) -> 50000 | F27: =SUM(C27:E27) -> 50000 | I27: OK
A28: AS201633 | B28: =VLOOKUP(A28,[5]LISTADHERENT!A$5:H$39,3,0) -> PATEGO NJOSSU GUSTAVE | C28: =IF(I28="OK",VLOOKUP(A28,[6]MONTVERST!A$5:F$39,3,0),0) -> 115000 | F28: =SUM(C28:E28) -> 115000 | I28: OK
A29: AS201657 | B29: =VLOOKUP(A29,[5]LISTADHERENT!A$5:H$39,3,0) -> SEUMO POLYCARPE | C29: =IF(I29="OK",VLOOKUP(A29,[6]MONTVERST!A$5:F$39,3,0),0) -> 40000 | F29: =SUM(C29:E29) -> 40000 | I29: OK
A30: AS201653 | B30: =VLOOKUP(A30,[5]LISTADHERENT!A$5:H$39,3,0) -> SIME BRICE | C30: =IF(I30="OK",VLOOKUP(A30,[6]MONTVERST!A$5:F$39,3,0),0) -> 115000 | F30: =SUM(C30:E30) -> 115000 | I30: OK
A31: AS201638 | B31: =VLOOKUP(A31,[5]LISTADHERENT!A$5:H$39,3,0) -> SIMO PIERRE | C31: =IF(I31="OK",VLOOKUP(A31,[6]MONTVERST!A$5:F$39,3,0),0) -> 140000 | F31: =SUM(C31:E31) -> 140000 | I31: OK
A32: AS201641 | B32: =VLOOKUP(A32,[5]LISTADHERENT!A$5:H$39,3,0) -> TCHOUAMOU MATHIEU | C32: 191000 | F32: =SUM(C32:E32) -> 191000 | I32: OK
A33: AS201643 | B33: =VLOOKUP(A33,[5]LISTADHERENT!A$5:H$39,3,0) -> TCHOUTOU NANA CLAUDE | C33: =IF(I33="OK",VLOOKUP(A33,[6]MONTVERST!A$5:F$39,3,0),0) -> 0 | F33: =SUM(C33:E33) -> 0
A34: AS201658 | B34: =VLOOKUP(A34,[5]LISTADHERENT!A$5:H$39,3,0) -> YANTCHOU GERVAIS | C34: 40000 | F34: =SUM(C34:E34) -> 40000 | I34: OK
A35: AS201646 | B35: =VLOOKUP(A35,[5]LISTADHERENT!A$5:H$39,3,0) -> YEPMOU JEAN JACQUES | C35: =IF(I35="OK",VLOOKUP(A35,[6]MONTVERST!A$5:F$39,3,0),0) -> 40000 | F35: =SUM(C35:E35) -> 40000 | I35: OK
A36: AS201647 | B36: =VLOOKUP(A36,[5]LISTADHERENT!A$5:H$39,3,0) -> YOUMBI EMMANUEL | C36: 400000 | F36: =SUM(C36:E36) -> 400000 | I36: OK
B38: TOTAUX | C38: =SUM(C7:C37) -> 4912500 | D38: =SUM(D7:D37) -> 194000 | E38: =SUM(E7:E37) -> 0 | F38: =SUM(F7:F37) -> 5106500 | G38: =SUM(G7:G37) -> 0 | H38: =SUM(H8:H37) -> 0

Sheet HISTOBQUEOCT23
A1: ASSOCIATION | B1: ASELBY | C1: MOIS DE OCTOBRE
A2: ANNEE | B2: 2023
A3: 1 | B3: 2 | C3: 4 | D3: 5 | E3: 6 | F3: 21
B4: HISTORIQUE BANCAIRE
A5: MATRICULE | B5: NOM ET PRENOM | C5: HISTORIQUE BANQUE | D5: HITORIQUE ESPECES | E5: HITORIQUE TONTINE | F5: MONTANT ENGAGEMENT | G5: VERIFICATION | H5: AGIO | I5: VALIDATION
A6: AS201648 | B6: =VLOOKUP(A6,[5]LISTADHERENT!A$5:H$39,3,0) -> ASELBY | C6: =IF(I6="OK",VLOOKUP(A6,[6]MONTVERST!A$5:F$39,3,0),0) -> 175000 | F6: =SUM(C6:E6) -> 175000 | I6: OK
A7: AS201601 | B7: =VLOOKUP(A7,[5]LISTADHERENT!A$5:H$39,3,0) -> BAKOP ACHILLE | C7: =IF(I7="OK",VLOOKUP(A7,[6]MONTVERST!A$5:F$39,3,0),0) -> 40000 | F7: =SUM(C7:E7) -> 40000 | I7: OK
A8: AS201602 | B8: =VLOOKUP(A8,[5]LISTADHERENT!A$5:H$39,3,0) -> BOUTCHOUANG WILLIAM | C8: =IF(I8="OK",VLOOKUP(A8,[6]MONTVERST!A$5:F$39,3,0),0) -> 0 | D8: 115000 | F8: =SUM(C8:E8) -> 115000
A9: AS201604 | B9: =VLOOKUP(A9,[5]LISTADHERENT!A$5:H$39,3,0) -> DJOMO JEAN PAUL | C9: =IF(I9="OK",VLOOKUP(A9,[6]MONTVERST!A$5:F$39,3,0),0) -> 140000 | F9: =SUM(C9:E9) -> 140000 | I9: OK
A10: AS201654 | B10: =VLOOKUP(A10,[5]LISTADHERENT!A$5:H$39,3,0) -> DJOMOU TCHAPDA | C10: 343000 | F10: =SUM(C10:E10) -> 343000 | I10: OK
A11: AS201605 | B11: =VLOOKUP(A11,[5]LISTADHERENT!A$5:H$39,3,0) -> DJOUKWE NANGUEN GUY BLAISE | C11: =IF(I11="OK",VLOOKUP(A11,[6]MONTVERST!A$5:F$39,3,0),0) -> 115000 | D11: 59000 | F11: =SUM(C11:E11) -> 174000 | I11: OK
A12: AS201608 | B12: =VLOOKUP(A12,[5]LISTADHERENT!A$5:H$39,3,0) -> DJUOMBESSY ANTOINE | C12: =320000+202000 -> 522000 | F12: =SUM(C12:E12) -> 522000 | I12: OK
A13: AS201651 | B13: =VLOOKUP(A13,[5]LISTADHERENT!A$5:H$39,3,0) -> DOMOU FABIEN | C13: =IF(I13="OK",VLOOKUP(A13,[6]MONTVERST!A$5:F$39,3,0),0) -> 40000 | F13: =SUM(C13:E13) -> 40000 | I13: OK
A14: AS201609 | B14: =VLOOKUP(A14,[5]LISTADHERENT!A$5:H$39,3,0) -> DONHOU DAVID | C14: =IF(I14="OK",VLOOKUP(A14,[6]MONTVERST!A$5:F$39,3,0),0) -> 40000 | F14: =SUM(C14:E14) -> 40000 | I14: OK
A15: AS201611 | B15: =VLOOKUP(A15,[5]LISTADHERENT!A$5:H$39,3,0) -> HENGUE PAUL OMER | C15: =IF(I15="OK",VLOOKUP(A15,[6]MONTVERST!A$5:F$39,3,0),0) -> 115000 | F15: =SUM(C15:E15) -> 115000 | I15: OK
A16: AS201613 | B16: =VLOOKUP(A16,[5]LISTADHERENT!A$5:H$39,3,0) -> HOTCHO BENJAMIN | C16: =250000+202000 -> 452000 | D16: 136500 | F16: =SUM(C16:E16) -> 588500 | I16: OK
A17: AS201617 | B17: =VLOOKUP(A17,[5]LISTADHERENT!A$5:H$39,3,0) -> KOUAMOU MOISE | C17: =IF(I17="OK",VLOOKUP(A17,[6]MONTVERST!A$5:F$39,3,0),0) -> 140000 | F17: =SUM(C17:E17) -> 140000 | I17: OK
A18: AS201619 | B18: =VLOOKUP(A18,[5]LISTADHERENT!A$5:H$39,3,0) -> KOUATCHO MESSACK | C18: 355000 | F18: =SUM(C18:E18) -> 355000 | I18: OK
A19: AS201620 | B19: =VLOOKUP(A19,[5]LISTADHERENT!A$5:H$39,3,0) -> LOWE JEAN | C19: =IF(I19="OK",VLOOKUP(A19,[6]MONTVERST!A$5:F$39,3,0),0) -> 40000 | F19: =SUM(C19:E19) -> 40000 | I19: OK
A20: AS201649 | B20: =VLOOKUP(A20,[5]LISTADHERENT!A$5:H$39,3,0) -> MBOGNING TUGMA GUY | C20: 417000 | F20: =SUM(C20:E20) -> 417000 | I20: OK
A21: AS201639 | B21: =VLOOKUP(A21,[5]LISTADHERENT!A$5:H$39,3,0) -> NANGUEN MARTIN | C21: =IF(I21="OK",VLOOKUP(A21,[6]MONTVERST!A$5:F$39,3,0),0) -> 40000 | F21: =SUM(C21:E21) -> 40000 | I21: OK
A22: AS201621 | B22: =VLOOKUP(A22,[5]LISTADHERENT!A$5:H$39,3,0) -> NANKAM APPOLINAIRE | C22: =IF(I22="OK",VLOOKUP(A22,[6]MONTVERST!A$5:F$39,3,0),0) -> 115000 | F22: =SUM(C22:E22) -> 115000 | I22: OK
A23: AS201622 | B23: =VLOOKUP(A23,[5]LISTADHERENT!A$5:H$39,3,0) -> NDJOMO ETIENNE | C23: =IF(I23="OK",VLOOKUP(A23,[6]MONTVERST!A$5:F$39,3,0),0) -> 250000 | F23: =SUM(C23:E23) -> 250000 | I23: OK
A24: AS201624 | B24: =VLOOKUP(A24,[5]LISTADHERENT!A$5:H$39,3,0) -> NGONDIEP CLAUDE | C24: 400000 | D24: 17000 | F24: =SUM(C24:E24) -> 417000 | I24: OK
A25: AS201626 | B25: =VLOOKUP(A25,[5]LISTADHERENT!A$5:H$39,3,0) -> NGUIEMEGNI MATHIEU BLAISE | C25: 500000 | F25: =SUM(C25:E25) -> 500000 | I25: OK
A26: AS201628 | B26: =VLOOKUP(A26,[5]LISTADHERENT!A$5:H$39,3,0) -> NKAMGANG JUSTIN DEJOLIE | C26: =IF(I26="OK",VLOOKUP(A26,[6]MONTVERST!A$5:F$39,3,0),0) -> 0 | D26: =40000+101000+17500 -> 158500 | F26: =SUM(C26:E26) -> 158500
A27: AS201656 | B27: =VLOOKUP(A27,[5]LISTADHERENT!A$5:H$39,3,0) -> NOUBE ETIENNE | C27: =IF(I27="OK",VLOOKUP(A27,[6]MONTVERST!A$5:F$39,3,0),0) -> 50000 | F27: =SUM(C27:E27) -> 50000 | I27: OK
A28: AS201633 | B28: =VLOOKUP(A28,[5]LISTADHERENT!A$5:H$39,3,0) -> PATEGO NJOSSU GUSTAVE | C28: =IF(I28="OK",VLOOKUP(A28,[6]MONTVERST!A$5:F$39,3,0),0) -> 115000 | F28: =SUM(C28:E28) -> 115000 | I28: OK
A29: AS201657 | B29: =VLOOKUP(A29,[5]LISTADHERENT!A$5:H$39,3,0) -> SEUMO POLYCARPE | C29: =IF(I29="OK",VLOOKUP(A29,[6]MONTVERST!A$5:F$39,3,0),0) -> 40000 | F29: =SUM(C29:E29) -> 40000 | I29: OK
A30: AS201653 | B30: =VLOOKUP(A30,[5]LISTADHERENT!A$5:H$39,3,0) -> SIME BRICE | C30: =IF(I30="OK",VLOOKUP(A30,[6]MONTVERST!A$5:F$39,3,0),0) -> 115000 | F30: =SUM(C30:E30) -> 115000 | I30: OK
A31: AS201638 | B31: =VLOOKUP(A31,[5]LISTADHERENT!A$5:H$39,3,0) -> SIMO PIERRE | C31: 171000 | F31: =SUM(C31:E31) -> 171000 | I31: OK
A32: AS201641 | B32: =VLOOKUP(A32,[5]LISTADHERENT!A$5:H$39,3,0) -> TCHOUAMOU MATHIEU | C32: =IF(I32="OK",VLOOKUP(A32,[6]MONTVERST!A$5:F$39,3,0),0) -> 115000 | F32: =SUM(C32:E32) -> 115000 | I32: OK
A33: AS201643 | B33: =VLOOKUP(A33,[5]LISTADHERENT!A$5:H$39,3,0) -> TCHOUTOU NANA CLAUDE | C33: =IF(I33="OK",VLOOKUP(A33,[6]MONTVERST!A$5:F$39,3,0),0) -> 40000 | F33: =SUM(C33:E33) -> 40000 | I33: OK
A34: AS201658 | B34: =VLOOKUP(A34,[5]LISTADHERENT!A$5:H$39,3,0) -> YANTCHOU GERVAIS | C34: 80000 | F34: =SUM(C34:E34) -> 80000 | I34: OK
A35: AS201646 | B35: =VLOOKUP(A35,[5]LISTADHERENT!A$5:H$39,3,0) -> YEPMOU JEAN JACQUES | C35: =IF(I35="OK",VLOOKUP(A35,[6]MONTVERST!A$5:F$39,3,0),0) -> 0 | D35: 40000 | F35: =SUM(C35:E35) -> 40000
A36: AS201647 | B36: =VLOOKUP(A36,[5]LISTADHERENT!A$5:H$39,3,0) -> YOUMBI EMMANUEL | C36: =580000+300000 -> 880000 | F36: =SUM(C36:E36) -> 880000 | I36: OK
B38: TOTAUX | C38: =SUM(C7:C37) -> 5670000 | D38: =SUM(D7:D37) -> 526000 | E38: =SUM(E7:E37) -> 0 | F38: =SUM(F7:F37) -> 6196000 | G38: =SUM(G7:G37) -> 0 | H38: =SUM(H8:H37) -> 0

Sheet HISTOBQUENOV23
A1: ASSOCIATION | B1: ASELBY | C1: MOIS DE NOVEMBRE | F1: =70000+91000+225000-221000 -> 165000
A2: ANNEE | B2: 2023
A3: 1 | B3: 2 | C3: 4 | D3: 5 | E3: 6 | F3: 21
B4: HISTORIQUE BANCAIRE
A5: MATRICULE | B5: NOM ET PRENOM | C5: HISTORIQUE BANQUE | D5: HITORIQUE ESPECES | E5: HITORIQUE TONTINE | F5: MONTANT ENGAGEMENT | G5: VERIFICATION | H5: AGIO | I5: VALIDATION
A6: AS201648 | B6: =VLOOKUP(A6,[5]LISTADHERENT!A$5:H$39,3,0) -> ASELBY | C6: =IF(I6="OK",VLOOKUP(A6,[6]MONTVERST!A$5:F$39,3,0),0) -> 175000 | F6: =SUM(C6:E6) -> 175000 | I6: OK
A7: AS201601 | B7: =VLOOKUP(A7,[5]LISTADHERENT!A$5:H$39,3,0) -> BAKOP ACHILLE | C7: =IF(I7="OK",VLOOKUP(A7,[6]MONTVERST!A$5:F$39,3,0),0) -> 40000 | F7: =SUM(C7:E7) -> 40000 | I7: OK
A8: AS201602 | B8: =VLOOKUP(A8,[5]LISTADHERENT!A$5:H$39,3,0) -> BOUTCHOUANG WILLIAM | C8: =IF(I8="OK",VLOOKUP(A8,[6]MONTVERST!A$5:F$39,3,0),0) -> 115000 | F8: =SUM(C8:E8) -> 115000 | I8: OK
A9: AS201604 | B9: =VLOOKUP(A9,[5]LISTADHERENT!A$5:H$39,3,0) -> DJOMO JEAN PAUL | C9: =101000+20000+221000 -> 342000 | F9: =SUM(C9:E9) -> 342000 | I9: OK
A10: AS201654 | B10: =VLOOKUP(A10,[5]LISTADHERENT!A$5:H$39,3,0) -> DJOMOU TCHAPDA | C10: =IF(I10="OK",VLOOKUP(A10,[6]MONTVERST!A$5:F$39,3,0),0) -> 40000 | F10: =SUM(C10:E10) -> 40000 | I10: OK
A11: AS201605 | B11: =VLOOKUP(A11,[5]LISTADHERENT!A$5:H$39,3,0) -> DJOUKWE NANGUEN GUY BLAISE | C11: =IF(I11="OK",VLOOKUP(A11,[6]MONTVERST!A$5:F$39,3,0),0) -> 115000 | F11: =SUM(C11:E11) -> 115000 | I11: OK
