Workbook
Name BANQUE: #REF!
Name BANQUE: #REF!
Name BANQUE: #REF!
Name BANQUE: #REF!
Name BANQUE: #REF!
Name BANQUE: #REF!
Name BANQUE: #REF!
Name BANQUE: #REF!
Name BANQUE: #REF!
Name BANQUE: #REF!
Name BANQUE: #REF!
Name BANQUE: #REF!
Name BANQUE: #REF!
Name BANQUE: #REF!
Name MODEPAID: MODEPAID!$A$1:$A$3
Name MODEPAID: [1]Feuil2!$A$1:$A$3
Name MODEPAID: [1]Feuil2!$A$1:$A$3
Name MODEPAID: [1]Feuil2!$A$1:$A$3
Name MODEPAID: [1]Feuil2!$A$1:$A$3
Name MODEPAID: [1]Feuil2!$A$1:$A$3
Name MODEPAID: [1]Feuil2!$A$1:$A$3
Name MODEPAID: [1]Feuil2!$A$1:$A$3
Name MODEPAID: [1]Feuil2!$A$1:$A$3
Name MODEPAID: [1]Feuil2!$A$1:$A$3
Name MODEPAID: [1]Feuil2!$A$1:$A$3
Name MODEPAID: [1]Feuil2!$A$1:$A$3
Name MODEPAID: [1]Feuil2!$A$1:$A$3
Name MODEPAID: [1]Feuil2!$A$1:$A$3
Name MODEPAID: #REF!
Name MODET25000: [2]MODEVERSEMENT!$A$1:$A$3
Name MODEVERSEMENT: #REF!
Name MODEVERSEMENT: #REF!
Name MODEVERSEMENT: #REF!
Name MODEVERSEMENT: #REF!
Name MODEVERSEMENT: #REF!
Name MODEVERSEMENT: #REF!
Name MODEVERSEMENT: #REF!
Name MODEVERSEMENT: #REF!
Name MODEVERSEMENT: #REF!
Name MODEVERSEMENT: #REF!
Name MODEVERSEMENT: #REF!
Name MODEVERSEMENT: #REF!
Name MODEVERSEMENT: #REF!
Name MODEVERSEMENT: #REF!
Name MODEVERSEMENTS: [3]MODEVERSEMENT!$A$1:$A$3
Name MODEVERSEMENTS: [3]MODEVERSEMENT!$A$1:$A$3
Name MODEVERSEMENTS: [3]MODEVERSEMENT!$A$1:$A$3
Name MODEVERSEMENTS: [3]MODEVERSEMENT!$A$1:$A$3
Name MODEVERSEMENTS: [3]MODEVERSEMENT!$A$1:$A$3
Name MODEVERSEMENTS: [3]MODEVERSEMENT!$A$1:$A$3
Name MODEVERSEMENTS: [3]MODEVERSEMENT!$A$1:$A$3
Name MODEVERSEMENTS: [3]MODEVERSEMENT!$A$1:$A$3
Name MODEVERSEMENTS: [3]MODEVERSEMENT!$A$1:$A$3
Name MODEVERSEMENTS: [3]MODEVERSEMENT!$A$1:$A$3
Name MODEVERSEMENTS: [3]MODEVERSEMENT!$A$1:$A$3
Name MODEVERSEMENTS: [3]MODEVERSEMENT!$A$1:$A$3
Name MODEVERSEMENTS: [3]MODEVERSEMENT!$A$1:$A$3
Name MODEVERSEMENTS: [4]MODEVERSEMENT!$A$1:$A$3
Name MODPAID: TONTAOUT23!#REF!
Name MODPAID: TONTAVRIL23!#REF!

Sheet MODEPAID
A1: BANQUE
A2: ESPECES
A3: ECHEC

Sheet TONTJANV23
A1: ASSOCIATION | B1: ASELBY
A2: ANNEE | B2: 2023 | C2: TONIINE | D2: NBRE PART
A3: TAUX TONTINE | B3: 100000 | C3: =B3*12 -> 1200000 | D3: =ROUNDDOWN(L22/C3,0) -> 3
C4: 44939
A5: MATRICULE | B5: NBREPART | C5: NOM ET PRENOM | D5: MONTANT TONTINE | E5: MODE VERSEMENT | F5: VENTE PETIT LOT | G5: INTERET PETIT LOT | H5: MODE VERSEMENT VENTE PETIT LOT | I5: NUMERO CHEQUE | J5: MONTANT A REMBOURSER PETIT LOT | K5: REMBOURSEMENT PETIT LOT | L5: MODE VERSEMENT REMBOURSEMENT | M5: MODE VERSEMENTLOT PRINCIPAL | N5: NUMERO CHEQUE | O5: MONTANT LOT PRINCIPAL | P5: INTERET LOT PRINCIPAL
A6: AS201648 | B6: =IF(D6=0,0,VLOOKUP($A6,[6]HISTOJANV23!$A$6:$BQ$45,14,0)) -> 1 | C6: =VLOOKUP(A6,[7]LISTADHERENT!A$5:H$60,3,0) -> ASELBY | D6: =IF(E6="ECHEC",0,VLOOKUP($A6,[6]HISTOJANV23!$A$6:$BB$45,15,0)) -> 100000 | E6: =VLOOKUP($A6,[6]HISTOJANV23!$A$6:$BB$45,8,0) -> BANQUE | F6: =VLOOKUP($A6,[6]HISTOJANV23!$A$6:$BB$45,37,0) -> 0 | G6: =VLOOKUP($A6,[6]HISTOJANV23!$A$6:$BB$45,40,0) -> 0 | H6: =IF(F6<>0,VLOOKUP($A6,[6]HISTOJANV23!$A$6:$BB$45,42,0),"ECHEC") -> ECHEC | I6: =VLOOKUP($A6,[6]HISTOJANV23!$A$6:$BB$45,41,0) -> 0 | K6: =VLOOKUP($A6,[6]HISTOJANV23!$A$6:$BB$45,18,0) -> 0 | L6: =IF(K6<>0,VLOOKUP($A6,[6]HISTOJANV23!$A$6:$BB$45,42,0),"ECHEC") -> ECHEC | M6: =IF(P6<>0,VLOOKUP($A6,[6]HISTOJANV23!$A$6:$BB$45,32,0),"ECHEC") -> ECHEC | N6: =VLOOKUP($A6,[6]HISTOJANV23!$A$6:$BB$45,33,0) -> 0 | O6: =IF(P6=0,0,($C$3-P6)) -> 0 | P6: =VLOOKUP($A6,[6]HISTOJANV23!$A$6:$BB$45,31,0) -> 0
A7: AS201604 | B7: =IF(D7=0,0,VLOOKUP($A7,[6]HISTOJANV23!$A$6:$BQ$45,14,0)) -> 1 | C7: =VLOOKUP(A7,[7]LISTADHERENT!A$5:H$60,3,0) -> DJOMO JEAN PAUL | D7: =IF(E7="ECHEC",0,VLOOKUP($A7,[6]HISTOJANV23!$A$6:$BB$45,15,0)) -> 100000 | E7: =VLOOKUP($A7,[6]HISTOJANV23!$A$6:$BB$45,8,0) -> BANQUE | F7: =VLOOKUP($A7,[6]HISTOJANV23!$A$6:$BB$45,37,0) -> 50000 | G7: =VLOOKUP($A7,[6]HISTOJANV23!$A$6:$BB$45,40,0) -> 2000 | H7: =IF(F7<>0,VLOOKUP($A7,[6]HISTOJANV23!$A$6:$BB$45,42,0),"ECHEC") -> BANQUE | I7: =VLOOKUP($A7,[6]HISTOJANV23!$A$6:$BB$45,41,0) -> 0 | K7: =VLOOKUP($A7,[6]HISTOJANV23!$A$6:$BB$45,18,0) -> 0 | L7: =IF(K7<>0,VLOOKUP($A7,[6]HISTOJANV23!$A$6:$BB$45,42,0),"ECHEC") -> ECHEC | M7: =IF(P7<>0,VLOOKUP($A7,[6]HISTOJANV23!$A$6:$BB$45,32,0),"ECHEC") -> ECHEC | N7: =VLOOKUP($A7,[6]HISTOJANV23!$A$6:$BB$45,33,0) -> 0 | O7: =IF(P7=0,0,($C$3-P7)) -> 0 | P7: =VLOOKUP($A7,[6]HISTOJANV23!$A$6:$BB$45,31,0) -> 0
A8: AS201608 | B8: =IF(D8=0,0,VLOOKUP($A8,[6]HISTOJANV23!$A$6:$BQ$45,14,0)) -> 2 | C8: =VLOOKUP(A8,[7]LISTADHERENT!A$5:H$60,3,0) -> DJUOMBESSY ANTOINE | D8: =IF(E8="ECHEC",0,VLOOKUP($A8,[6]HISTOJANV23!$A$6:$BB$45,15,0)) -> 200000 | E8: =VLOOKUP($A8,[6]HISTOJANV23!$A$6:$BB$45,8,0) -> BANQUE | F8: =VLOOKUP($A8,[6]HISTOJANV23!$A$6:$BB$45,37,0) -> 0 | G8: =VLOOKUP($A8,[6]HISTOJANV23!$A$6:$BB$45,40,0) -> 0 | H8: =IF(F8<>0,VLOOKUP($A8,[6]HISTOJANV23!$A$6:$BB$45,42,0),"ECHEC") -> ECHEC | I8: =VLOOKUP($A8,[6]HISTOJANV23!$A$6:$BB$45,41,0) -> 0 | K8: =VLOOKUP($A8,[6]HISTOJANV23!$A$6:$BB$45,18,0) -> 0 | L8: =IF(K8<>0,VLOOKUP($A8,[6]HISTOJANV23!$A$6:$BB$45,42,0),"ECHEC") -> ECHEC | M8: =IF(P8<>0,VLOOKUP($A8,[6]HISTOJANV23!$A$6:$BB$45,32,0),"ECHEC") -> ECHEC | N8: =VLOOKUP($A8,[6]HISTOJANV23!$A$6:$BB$45,33,0) -> 0 | O8: =IF(P8=0,0,($C$3-P8)) -> 0 | P8: =VLOOKUP($A8,[6]HISTOJANV23!$A$6:$BB$45,31,0) -> 0
A9: AS201613 | B9: =IF(D9=0,0,VLOOKUP($A9,[6]HISTOJANV23!$A$6:$BQ$45,14,0)) -> 1 | C9: =VLOOKUP(A9,[7]LISTADHERENT!A$5:H$60,3,0) -> HOTCHO BENJAMIN | D9: =IF(E9="ECHEC",0,VLOOKUP($A9,[6]HISTOJANV23!$A$6:$BB$45,15,0)) -> 100000 | E9: =VLOOKUP($A9,[6]HISTOJANV23!$A$6:$BB$45,8,0) -> BANQUE | F9: =VLOOKUP($A9,[6]HISTOJANV23!$A$6:$BB$45,37,0) -> 0 | G9: =VLOOKUP($A9,[6]HISTOJANV23!$A$6:$BB$45,40,0) -> 0 | H9: =IF(F9<>0,VLOOKUP($A9,[6]HISTOJANV23!$A$6:$BB$45,42,0),"ECHEC") -> ECHEC | I9: =VLOOKUP($A9,[6]HISTOJANV23!$A$6:$BB$45,41,0) -> 0 | K9: =VLOOKUP($A9,[6]HISTOJANV23!$A$6:$BB$45,18,0) -> 0 | L9: =IF(K9<>0,VLOOKUP($A9,[6]HISTOJANV23!$A$6:$BB$45,42,0),"ECHEC") -> ECHEC | M9: =IF(P9<>0,VLOOKUP($A9,[6]HISTOJANV23!$A$6:$BB$45,32,0),"ECHEC") -> ECHEC | N9: =VLOOKUP($A9,[6]HISTOJANV23!$A$6:$BB$45,33,0) -> 0 | O9: =IF(P9=0,0,($C$3-P9)) -> 0 | P9: =VLOOKUP($A9,[6]HISTOJANV23!$A$6:$BB$45,31,0) -> 0
A10: AS201617 | B10: =IF(D10=0,0,VLOOKUP($A10,[6]HISTOJANV23!$A$6:$BQ$45,14,0)) -> 1 | C10: =VLOOKUP(A10,[7]LISTADHERENT!A$5:H$60,3,0) -> KOUAMOU MOISE | D10: =IF(E10="ECHEC",0,VLOOKUP($A10,[6]HISTOJANV23!$A$6:$BB$45,15,0)) -> 100000 | E10: =VLOOKUP($A10,[6]HISTOJANV23!$A$6:$BB$45,8,0) -> BANQUE | F10: =VLOOKUP($A10,[6]HISTOJANV23!$A$6:$BB$45,37,0) -> 0 | G10: =VLOOKUP($A10,[6]HISTOJANV23!$A$6:$BB$45,40,0) -> 0 | H10: =IF(F10<>0,VLOOKUP($A10,[6]HISTOJANV23!$A$6:$BB$45,42,0),"ECHEC") -> ECHEC | I10: =VLOOKUP($A10,[6]HISTOJANV23!$A$6:$BB$45,41,0) -> 0 | K10: =VLOOKUP($A10,[6]HISTOJANV23!$A$6:$BB$45,18,0) -> 0 | L10: =IF(K10<>0,VLOOKUP($A10,[6]HISTOJANV23!$A$6:$BB$45,42,0),"ECHEC") -> ECHEC | M10: =IF(P10<>0,VLOOKUP($A10,[6]HISTOJANV23!$A$6:$BB$45,32,0),"ECHEC") -> ECHEC | N10: =VLOOKUP($A10,[6]HISTOJANV23!$A$6:$BB$45,33,0) -> 0 | O10: =IF(P10=0,0,($C$3-P10)) -> 0 | P10: =VLOOKUP($A10,[6]HISTOJANV23!$A$6:$BB$45,31,0) -> 0
A11: AS201619 | B11: =IF(D11=0,0,VLOOKUP($A11,[6]HISTOJANV23!$A$6:$BQ$45,14,0)) -> 1 | C11: =VLOOKUP(A11,[7]LISTADHERENT!A$5:H$60,3,0) -> KOUATCHO MESSACK | D11: =IF(E11="ECHEC",0,VLOOKUP($A11,[6]HISTOJANV23!$A$6:$BB$45,15,0)) -> 100000 | E11: =VLOOKUP($A11,[6]HISTOJANV23!$A$6:$BB$45,8,0) -> BANQUE | F11: =VLOOKUP($A11,[6]HISTOJANV23!$A$6:$BB$45,37,0) -> 0 | G11: =VLOOKUP($A11,[6]HISTOJANV23!$A$6:$BB$45,40,0) -> 0 | H11: =IF(F11<>0,VLOOKUP($A11,[6]HISTOJANV23!$A$6:$BB$45,42,0),"ECHEC") -> ECHEC | I11: =VLOOKUP($A11,[6]HISTOJANV23!$A$6:$BB$45,41,0) -> 0 | K11: =VLOOKUP($A11,[6]HISTOJANV23!$A$6:$BB$45,18,0) -> 0 | L11: =IF(K11<>0,VLOOKUP($A11,[6]HISTOJANV23!$A$6:$BB$45,42,0),"ECHEC") -> ECHEC | M11: =IF(P11<>0,VLOOKUP($A11,[6]HISTOJANV23!$A$6:$BB$45,32,0),"ECHEC") -> BANQUE | N11: =VLOOKUP($A11,[6]HISTOJANV23!$A$6:$BB$45,33,0) -> 0 | O11: =IF(P11=0,0,($C$3-P11)) -> 1075000 | P11: =VLOOKUP($A11,[6]HISTOJANV23!$A$6:$BB$45,31,0) -> 125000
A12: AS201649 | B12: =IF(D12=0,0,VLOOKUP($A12,[6]HISTOJANV23!$A$6:$BQ$45,14,0)) -> 1 | C12: =VLOOKUP(A12,[7]LISTADHERENT!A$5:H$60,3,0) -> MBOGNING TUGMA GUY | D12: =IF(E12="ECHEC",0,VLOOKUP($A12,[6]HISTOJANV23!$A$6:$BB$45,15,0)) -> 100000 | E12: =VLOOKUP($A12,[6]HISTOJANV23!$A$6:$BB$45,8,0) -> BANQUE | F12: =VLOOKUP($A12,[6]HISTOJANV23!$A$6:$BB$45,37,0) -> 0 | G12: =VLOOKUP($A12,[6]HISTOJANV23!$A$6:$BB$45,40,0) -> 0 | H12: =IF(F12<>0,VLOOKUP($A12,[6]HISTOJANV23!$A$6:$BB$45,42,0),"ECHEC") -> ECHEC | I12: =VLOOKUP($A12,[6]HISTOJANV23!$A$6:$BB$45,41,0) -> 0 | K12: =VLOOKUP($A12,[6]HISTOJANV23!$A$6:$BB$45,18,0) -> 0 | L12: =IF(K12<>0,VLOOKUP($A12,[6]HISTOJANV23!$A$6:$BB$45,42,0),"ECHEC") -> ECHEC | M12: =IF(P12<>0,VLOOKUP($A12,[6]HISTOJANV23!$A$6:$BB$45,32,0),"ECHEC") -> BANQUE | N12: =VLOOKUP($A12,[6]HISTOJANV23!$A$6:$BB$45,33,0) -> 0 | O12: =IF(P12=0,0,($C$3-P12)) -> 1075000 | P12: =VLOOKUP($A12,[6]HISTOJANV23!$A$6:$BB$45,31,0) -> 125000
A13: AS201622 | B13: =IF(D13=0,0,VLOOKUP($A13,[6]HISTOJANV23!$A$6:$BQ$45,14,0)) -> 2 | C13: =VLOOKUP(A13,[7]LISTADHERENT!A$5:H$60,3,0) -> NDJOMO ETIENNE | D13: =IF(E13="ECHEC",0,VLOOKUP($A13,[6]HISTOJANV23!$A$6:$BB$45,15,0)) -> 200000 | E13: =VLOOKUP($A13,[6]HISTOJANV23!$A$6:$BB$45,8,0) -> BANQUE | F13: =VLOOKUP($A13,[6]HISTOJANV23!$A$6:$BB$45,37,0) -> 0 | G13: =VLOOKUP($A13,[6]HISTOJANV23!$A$6:$BB$45,40,0) -> 0 | H13: =IF(F13<>0,VLOOKUP($A13,[6]HISTOJANV23!$A$6:$BB$45,42,0),"ECHEC") -> ECHEC | I13: =VLOOKUP($A13,[6]HISTOJANV23!$A$6:$BB$45,41,0) -> 0 | K13: =VLOOKUP($A13,[6]HISTOJANV23!$A$6:$BB$45,18,0) -> 0 | L13: =IF(K13<>0,VLOOKUP($A13,[6]HISTOJANV23!$A$6:$BB$45,42,0),"ECHEC") -> ECHEC | M13: =IF(P13<>0,VLOOKUP($A13,[6]HISTOJANV23!$A$6:$BB$45,32,0),"ECHEC") -> ECHEC | N13: =VLOOKUP($A13,[6]HISTOJANV23!$A$6:$BB$45,33,0) -> 0 | O13: =IF(P13=0,0,($C$3-P13)) -> 0 | P13: =VLOOKUP($A13,[6]HISTOJANV23!$A$6:$BB$45,31,0) -> 0
A14: AS201624 | B14: =IF(D14=0,0,VLOOKUP($A14,[6]HISTOJANV23!$A$6:$BQ$45,14,0)) -> 1 | C14: =VLOOKUP(A14,[7]LISTADHERENT!A$5:H$60,3,0) -> NGONDIEP CLAUDE | D14: =IF(E14="ECHEC",0,VLOOKUP($A14,[6]HISTOJANV23!$A$6:$BB$45,15,0)) -> 100000 | E14: =VLOOKUP($A14,[6]HISTOJANV23!$A$6:$BB$45,8,0) -> BANQUE | F14: =VLOOKUP($A14,[6]HISTOJANV23!$A$6:$BB$45,37,0) -> 200000 | G14: =VLOOKUP($A14,[6]HISTOJANV23!$A$6:$BB$45,40,0) -> 8000 | H14: =IF(F14<>0,VLOOKUP($A14,[6]HISTOJANV23!$A$6:$BB$45,42,0),"ECHEC") -> BANQUE | I14: =VLOOKUP($A14,[6]HISTOJANV23!$A$6:$BB$45,41,0) -> 0 | K14: =VLOOKUP($A14,[6]HISTOJANV23!$A$6:$BB$45,18,0) -> 0 | L14: =IF(K14<>0,VLOOKUP($A14,[6]HISTOJANV23!$A$6:$BB$45,42,0),"ECHEC") -> ECHEC | M14: =IF(P14<>0,VLOOKUP($A14,[6]HISTOJANV23!$A$6:$BB$45,32,0),"ECHEC") -> BANQUE | N14: =VLOOKUP($A14,[6]HISTOJANV23!$A$6:$BB$45,33,0) -> 0 | O14: =IF(P14=0,0,($C$3-P14)) -> 1075000 | P14: =VLOOKUP($A14,[6]HISTOJANV23!$A$6:$BB$45,31,0) -> 125000
A15: AS201626 | B15: =IF(D15=0,0,VLOOKUP($A15,[6]HISTOJANV23!$A$6:$BQ$45,14,0)) -> 1 | C15: =VLOOKUP(A15,[7]LISTADHERENT!A$5:H$60,3,0) -> NGUIEMEGNI MATHIEU BLAISE | D15: =IF(E15="ECHEC",0,VLOOKUP($A15,[6]HISTOJANV23!$A$6:$BB$45,15,0)) -> 100000 | E15: =VLOOKUP($A15,[6]HISTOJANV23!$A$6:$BB$45,8,0) -> BANQUE | F15: =VLOOKUP($A15,[6]HISTOJANV23!$A$6:$BB$45,37,0) -> 75000 | G15: =VLOOKUP($A15,[6]HISTOJANV23!$A$6:$BB$45,40,0) -> 3000 | H15: =IF(F15<>0,VLOOKUP($A15,[6]HISTOJANV23!$A$6:$BB$45,42,0),"ECHEC") -> BANQUE | I15: =VLOOKUP($A15,[6]HISTOJANV23!$A$6:$BB$45,41,0) -> 0 | K15: =VLOOKUP($A15,[6]HISTOJANV23!$A$6:$BB$45,18,0) -> 0 | L15: =IF(K15<>0,VLOOKUP($A15,[6]HISTOJANV23!$A$6:$BB$45,42,0),"ECHEC") -> ECHEC | M15: =IF(P15<>0,VLOOKUP($A15,[6]HISTOJANV23!$A$6:$BB$45,32,0),"ECHEC") -> ECHEC | N15: =VLOOKUP($A15,[6]HISTOJANV23!$A$6:$BB$45,33,0) -> 0 | O15: =IF(P15=0,0,($C$3-P15)) -> 0 | P15: =VLOOKUP($A15,[6]HISTOJANV23!$A$6:$BB$45,31,0) -> 0
A16: AS201638 | B16: =IF(D16=0,0,VLOOKUP($A16,[6]HISTOJANV23!$A$6:$BQ$45,14,0)) -> 1 | C16: =VLOOKUP(A16,[7]LISTADHERENT!A$5:H$60,3,0) -> SIMO PIERRE | D16: =IF(E16="ECHEC",0,VLOOKUP($A16,[6]HISTOJANV23!$A$6:$BB$45,15,0)) -> 100000 | E16: =VLOOKUP($A16,[6]HISTOJANV23!$A$6:$BB$45,8,0) -> BANQUE | F16: =VLOOKUP($A16,[6]HISTOJANV23!$A$6:$BB$45,37,0) -> 0 | G16: =VLOOKUP($A16,[6]HISTOJANV23!$A$6:$BB$45,40,0) -> 0 | H16: =IF(F16<>0,VLOOKUP($A16,[6]HISTOJANV23!$A$6:$BB$45,42,0),"ECHEC") -> ECHEC | I16: =VLOOKUP($A16,[6]HISTOJANV23!$A$6:$BB$45,41,0) -> 0 | K16: =VLOOKUP($A16,[6]HISTOJANV23!$A$6:$BB$45,18,0) -> 0 | L16: =IF(K16<>0,VLOOKUP($A16,[6]HISTOJANV23!$A$6:$BB$45,42,0),"ECHEC") -> ECHEC | M16: =IF(P16<>0,VLOOKUP($A16,[6]HISTOJANV23!$A$6:$BB$45,32,0),"ECHEC") -> ECHEC | N16: =VLOOKUP($A16,[6]HISTOJANV23!$A$6:$BB$45,33,0) -> 0 | O16: =IF(P16=0,0,($C$3-P16)) -> 0 | P16: =VLOOKUP($A16,[6]HISTOJANV23!$A$6:$BB$45,31,0) -> 0
A17: AS201647 | B17: =IF(D17=0,0,VLOOKUP($A17,[6]HISTOJANV23!$A$6:$BQ$45,14,0)) -> 1 | C17: =VLOOKUP(A17,[7]LISTADHERENT!A$5:H$60,3,0) -> YOUMBI EMMANUEL | D17: =IF(E17="ECHEC",0,VLOOKUP($A17,[6]HISTOJANV23!$A$6:$BB$45,15,0)) -> 100000 | E17: =VLOOKUP($A17,[6]HISTOJANV23!$A$6:$BB$45,8,0) -> BANQUE | F17: =VLOOKUP($A17,[6]HISTOJANV23!$A$6:$BB$45,37,0) -> 0 | G17: =VLOOKUP($A17,[6]HISTOJANV23!$A$6:$BB$45,40,0) -> 0 | H17: =IF(F17<>0,VLOOKUP($A17,[6]HISTOJANV23!$A$6:$BB$45,42,0),"ECHEC") -> ECHEC | I17: =VLOOKUP($A17,[6]HISTOJANV23!$A$6:$BB$45,41,0) -> 0 | K17: =VLOOKUP($A17,[6]HISTOJANV23!$A$6:$BB$45,18,0) -> 0 | L17: =IF(K17<>0,VLOOKUP($A17,[6]HISTOJANV23!$A$6:$BB$45,42,0),"ECHEC") -> ECHEC | M17: =IF(P17<>0,VLOOKUP($A17,[6]HISTOJANV23!$A$6:$BB$45,32,0),"ECHEC") -> ECHEC | N17: =VLOOKUP($A17,[6]HISTOJANV23!$A$6:$BB$45,33,0) -> 0 | O17: =IF(P17=0,0,($C$3-P17)) -> 0 | P17: =VLOOKUP($A17,[6]HISTOJANV23!$A$6:$BB$45,31,0) -> 0
A19: TOTAL PART | B19: =SUM(B6:B18) -> 14
A20: NBRE ADHERENT | B20: =+COUNT(D6:D18) -> 12 | D20: =SUM(D6:D18) -> 1400000 | E20: =SUM(E6:E18) -> 0 | F20: =SUM(F6:F18) -> 325000 | G20: =SUM(G6:G18) -> 13000 | H20: =SUM(H6:H18) -> 0 | I20: =SUM(I6:I18) -> 0 | J20: =SUM(J6:J18) -> 0 | K20: =SUM(K6:K18) -> 0 | ... P20: =SUM(P6:P18) -> 375000
M21: NBRE PART | N21: PART VENDUE
D22: MONTANT TONTINE | E22: REMBOURSEMENT PETIT LOT | F22: VENTE PETIT LOT | G22: VENTE LOT PRINCIPAL | H22: SOLDE EN CAISSE | K22: TONTINE + REMB + INTERET VENTE | L22: =D26+E26+P20 -> 4175000
C23: ESPECES | D23: =SUMIFS(D6:D18,E6:E18,"ESPECES") -> 0 | E23: =SUMIFS(K6:K18,L6:L18,"ESPECES") -> 0 | F23: =SUMIFS(F6:F18,H6:H18,"ESPECES") -> 0 | G23: =SUMIFS(O6:O18,M6:M18,"ESPECES") -> 0 | H23: =D23+E23-F23-G23 -> 0 | K23: LOT PRINCIPAL | L23: =C3*COUNTIF(O6:O18,">0") -> 3600000 | M23: =D3 -> 3 | N23: =COUNTIF(O8:O17,">0") -> 3
C24: BANQUE | D24: =SUMIFS(D6:D18,E6:E18,"BANQUE")+2400000 -> 3800000 | E24: =SUMIFS(K6:K18,L6:L18,"BANQUE") -> 0 | F24: =SUMIFS(F6:F18,H6:H18,"BANQUE") -> 325000 | G24: =SUMIFS(O6:O18,M6:M18,"BANQUE") -> 3225000 | H24: =D24+E24-F24-G24 -> 250000
K25: PETIT LOT | L25: =L22-L23 -> 575000
C26: TOTAL | D26: =D23+D24 -> 3800000 | E26: =E23+E24 -> 0 | F26: =F23+F24 -> 325000 | G26: =G23+G24 -> 3225000 | H26: =H23+H24 -> 250000
K27: RELIQUAT | L27: =L25-F20 -> 250000 | N27: =L27 -> 250000 | O27: CUMUL
K29: ECHEC TONTINE MOIS | L29: =COUNTIFS(E6:E24,"ECHEC")*100000 -> 0 | N29: =L29 -> 0 | O29: CUMUL
K30: ECHEC REMBOURSEMENT MOIS | L30: =J20-E26 -> 0 | N30: =L30 -> 0 | O30: CUMUL

Sheet TONTFEV23
A1: ASSOCIATION | B1: ASELBY
A2: ANNEE | B2: 2023 | C2: TONIINE | D2: NBRE PART
A3: TAUX TONTINE | B3: 100000 | C3: =B3*12 -> 1200000 | D3: =ROUNDDOWN(L22/C3,0) -> 2
C4: 44970
A5: MATRICULE | B5: NBREPART | C5: NOM ET PRENOM | D5: MONTANT TONTINE | E5: MODE VERSEMENT | F5: VENTE PETIT LOT | G5: INTERET PETIT LOT | H5: MODE VERSEMENT VENTE PETIT LOT | I5: NUMERO CHEQUE | J5: MONTANT A REMBOURSER PETIT LOT | K5: REMBOURSEMENT PETIT LOT | L5: MODE VERSEMENT REMBOURSEMENT | M5: MODE VERSEMENTLOT PRINCIPAL | N5: NUMERO CHEQUE | O5: MONTANT LOT PRINCIPAL | P5: INTERET LOT PRINCIPAL
A6: AS201648 | B6: =IF(D6=0,0,VLOOKUP($A6,[6]HISTOFEV23!$A$6:$BQ$45,14,0)) -> 1 | C6: =VLOOKUP(A6,[7]LISTADHERENT!A$5:H$60,3,0) -> ASELBY | D6: =IF(E6="ECHEC",0,VLOOKUP($A6,[6]HISTOFEV23!$A$6:$BB$45,15,0)) -> 100000 | E6: =VLOOKUP($A6,[6]HISTOFEV23!$A$6:$BB$45,8,0) -> BANQUE | F6: =VLOOKUP($A6,[6]HISTOFEV23!$A$6:$BB$45,37,0) -> 0 | G6: =VLOOKUP($A6,[6]HISTOFEV23!$A$6:$BB$45,40,0) -> 0 | H6: =IF(F6<>0,VLOOKUP($A6,[6]HISTOFEV23!$A$6:$BB$45,42,0),"ECHEC") -> ECHEC | I6: =VLOOKUP($A6,[6]HISTOFEV23!$A$6:$BB$45,41,0) -> 0 | J6: =TONTJANV23!F6+TONTJANV23!G6 -> 0 | K6: =VLOOKUP($A6,[6]HISTOFEV23!$A$6:$BB$45,18,0) -> 0 | L6: =IF(K6<>0,VLOOKUP($A6,[6]HISTOFEV23!$A$6:$BB$45,42,0),"ECHEC") -> ECHEC | M6: =IF(P6<>0,VLOOKUP($A6,[6]HISTOFEV23!$A$6:$BB$45,32,0),"ECHEC") -> ECHEC | N6: =VLOOKUP($A6,[6]HISTOFEV23!$A$6:$BB$45,33,0) -> 0 | O6: =IF(P6=0,0,($C$3-P6)) -> 0 | P6: =VLOOKUP($A6,[6]HISTOFEV23!$A$6:$BB$45,31,0) -> 0
A7: AS201604 | B7: =IF(D7=0,0,VLOOKUP($A7,[6]HISTOFEV23!$A$6:$BQ$45,14,0)) -> 1 | C7: =VLOOKUP(A7,[7]LISTADHERENT!A$5:H$60,3,0) -> DJOMO JEAN PAUL | D7: =IF(E7="ECHEC",0,VLOOKUP($A7,[6]HISTOFEV23!$A$6:$BB$45,15,0)) -> 100000 | E7: =VLOOKUP($A7,[6]HISTOFEV23!$A$6:$BB$45,8,0) -> BANQUE | F7: =VLOOKUP($A7,[6]HISTOFEV23!$A$6:$BB$45,37,0) -> 0 | G7: =VLOOKUP($A7,[6]HISTOFEV23!$A$6:$BB$45,40,0) -> 0 | H7: =IF(F7<>0,VLOOKUP($A7,[6]HISTOFEV23!$A$6:$BB$45,42,0),"ECHEC") -> ECHEC | I7: =VLOOKUP($A7,[6]HISTOFEV23!$A$6:$BB$45,41,0) -> 0 | J7: =TONTJANV23!F7+TONTJANV23!G7 -> 52000 | K7: =VLOOKUP($A7,[6]HISTOFEV23!$A$6:$BB$45,18,0) -> 52000 | L7: =IF(K7<>0,VLOOKUP($A7,[6]HISTOFEV23!$A$6:$BB$45,42,0),"ECHEC") -> BANQUE | M7: =IF(P7<>0,VLOOKUP($A7,[6]HISTOFEV23!$A$6:$BB$45,32,0),"ECHEC") -> ECHEC | N7: =VLOOKUP($A7,[6]HISTOFEV23!$A$6:$BB$45,33,0) -> 0 | O7: =IF(P7=0,0,($C$3-P7)) -> 0 | P7: =VLOOKUP($A7,[6]HISTOFEV23!$A$6:$BB$45,31,0) -> 0
A8: AS201608 | B8: =IF(D8=0,0,VLOOKUP($A8,[6]HISTOFEV23!$A$6:$BQ$45,14,0)) -> 2 | C8: =VLOOKUP(A8,[7]LISTADHERENT!A$5:H$60,3,0) -> DJUOMBESSY ANTOINE | D8: =IF(E8="ECHEC",0,VLOOKUP($A8,[6]HISTOFEV23!$A$6:$BB$45,15,0)) -> 200000 | E8: =VLOOKUP($A8,[6]HISTOFEV23!$A$6:$BB$45,8,0) -> BANQUE | F8: =VLOOKUP($A8,[6]HISTOFEV23!$A$6:$BB$45,37,0) -> 0 | G8: =VLOOKUP($A8,[6]HISTOFEV23!$A$6:$BB$45,40,0) -> 0 | H8: =IF(F8<>0,VLOOKUP($A8,[6]HISTOFEV23!$A$6:$BB$45,42,0),"ECHEC") -> ECHEC | I8: =VLOOKUP($A8,[6]HISTOFEV23!$A$6:$BB$45,41,0) -> 0 | J8: =TONTJANV23!F8+TONTJANV23!G8 -> 0 | K8: =VLOOKUP($A8,[6]HISTOFEV23!$A$6:$BB$45,18,0) -> 0 | L8: =IF(K8<>0,VLOOKUP($A8,[6]HISTOFEV23!$A$6:$BB$45,42,0),"ECHEC") -> ECHEC | M8: =IF(P8<>0,VLOOKUP($A8,[6]HISTOFEV23!$A$6:$BB$45,32,0),"ECHEC") -> ECHEC | N8: =VLOOKUP($A8,[6]HISTOFEV23!$A$6:$BB$45,33,0) -> 0 | O8: =IF(P8=0,0,($C$3-P8)) -> 0 | P8: =VLOOKUP($A8,[6]HISTOFEV23!$A$6:$BB$45,31,0) -> 0
A9: AS201613 | B9: =IF(D9=0,0,VLOOKUP($A9,[6]HISTOFEV23!$A$6:$BQ$45,14,0)) -> 1 | C9: =VLOOKUP(A9,[7]LISTADHERENT!A$5:H$60,3,0) -> HOTCHO BENJAMIN | D9: =IF(E9="ECHEC",0,VLOOKUP($A9,[6]HISTOFEV23!$A$6:$BB$45,15,0)) -> 100000 | E9: =VLOOKUP($A9,[6]HISTOFEV23!$A$6:$BB$45,8,0) -> BANQUE | F9: =VLOOKUP($A9,[6]HISTOFEV23!$A$6:$BB$45,37,0) -> 0 | G9: =VLOOKUP($A9,[6]HISTOFEV23!$A$6:$BB$45,40,0) -> 0 | H9: =IF(F9<>0,VLOOKUP($A9,[6]HISTOFEV23!$A$6:$BB$45,42,0),"ECHEC") -> ECHEC | I9: =VLOOKUP($A9,[6]HISTOFEV23!$A$6:$BB$45,41,0) -> 0 | J9: =TONTJANV23!F9+TONTJANV23!G9 -> 0 | K9: =VLOOKUP($A9,[6]HISTOFEV23!$A$6:$BB$45,18,0) -> 0 | L9: =IF(K9<>0,VLOOKUP($A9,[6]HISTOFEV23!$A$6:$BB$45,42,0),"ECHEC") -> ECHEC | M9: =IF(P9<>0,VLOOKUP($A9,[6]HISTOFEV23!$A$6:$BB$45,32,0),"ECHEC") -> BANQUE | N9: =VLOOKUP($A9,[6]HISTOFEV23!$A$6:$BB$45,33,0) -> 0 | O9: =IF(P9=0,0,($C$3-P9)) -> 1172000 | P9: =VLOOKUP($A9,[6]HISTOFEV23!$A$6:$BB$45,31,0) -> 28000
A10: AS201617 | B10: =IF(D10=0,0,VLOOKUP($A10,[6]HISTOFEV23!$A$6:$BQ$45,14,0)) -> 1 | C10: =VLOOKUP(A10,[7]LISTADHERENT!A$5:H$60,3,0) -> KOUAMOU MOISE | D10: =IF(E10="ECHEC",0,VLOOKUP($A10,[6]HISTOFEV23!$A$6:$BB$45,15,0)) -> 100000 | E10: =VLOOKUP($A10,[6]HISTOFEV23!$A$6:$BB$45,8,0) -> BANQUE | F10: =VLOOKUP($A10,[6]HISTOFEV23!$A$6:$BB$45,37,0) -> 0 | G10: =VLOOKUP($A10,[6]HISTOFEV23!$A$6:$BB$45,40,0) -> 0 | H10: =IF(F10<>0,VLOOKUP($A10,[6]HISTOFEV23!$A$6:$BB$45,42,0),"ECHEC") -> ECHEC | I10: =VLOOKUP($A10,[6]HISTOFEV23!$A$6:$BB$45,41,0) -> 0 | J10: =TONTJANV23!F10+TONTJANV23!G10 -> 0 | K10: =VLOOKUP($A10,[6]HISTOFEV23!$A$6:$BB$45,18,0) -> 0 | L10: =IF(K10<>0,VLOOKUP($A10,[6]HISTOFEV23!$A$6:$BB$45,42,0),"ECHEC") -> ECHEC | M10: =IF(P10<>0,VLOOKUP($A10,[6]HISTOFEV23!$A$6:$BB$45,32,0),"ECHEC") -> BANQUE | N10: =VLOOKUP($A10,[6]HISTOFEV23!$A$6:$BB$45,33,0) -> 0 | O10: =IF(P10=0,0,($C$3-P10)) -> 1172000 | P10: =VLOOKUP($A10,[6]HISTOFEV23!$A$6:$BB$45,31,0) -> 28000
A11: AS201619 | B11: =IF(D11=0,0,VLOOKUP($A11,[6]HISTOFEV23!$A$6:$BQ$45,14,0)) -> 1 | C11: =VLOOKUP(A11,[7]LISTADHERENT!A$5:H$60,3,0) -> KOUATCHO MESSACK | D11: =IF(E11="ECHEC",0,VLOOKUP($A11,[6]HISTOFEV23!$A$6:$BB$45,15,0)) -> 100000 | E11: =VLOOKUP($A11,[6]HISTOFEV23!$A$6:$BB$45,8,0) -> BANQUE | F11: =VLOOKUP($A11,[6]HISTOFEV23!$A$6:$BB$45,37,0) -> 0 | G11: =VLOOKUP($A11,[6]HISTOFEV23!$A$6:$BB$45,40,0) -> 0 | H11: =IF(F11<>0,VLOOKUP($A11,[6]HISTOFEV23!$A$6:$BB$45,42,0),"ECHEC") -> ECHEC | I11: =VLOOKUP($A11,[6]HISTOFEV23!$A$6:$BB$45,41,0) -> 0 | J11: =TONTJANV23!F11+TONTJANV23!G11 -> 0 | K11: =VLOOKUP($A11,[6]HISTOFEV23!$A$6:$BB$45,18,0) -> 0 | L11: =IF(K11<>0,VLOOKUP($A11,[6]HISTOFEV23!$A$6:$BB$45,42,0),"ECHEC") -> ECHEC | M11: =IF(P11<>0,VLOOKUP($A11,[6]HISTOFEV23!$A$6:$BB$45,32,0),"ECHEC") -> ECHEC | N11: =VLOOKUP($A11,[6]HISTOFEV23!$A$6:$BB$45,33,0) -> 0 | O11: =IF(P11=0,0,($C$3-P11)) -> 0 | P11: =VLOOKUP($A11,[6]HISTOFEV23!$A$6:$BB$45,31,0) -> 0
A12: AS201649 | B12: =IF(D12=0,0,VLOOKUP($A12,[6]HISTOFEV23!$A$6:$BQ$45,14,0)) -> 1 | C12: =VLOOKUP(A12,[7]LISTADHERENT!A$5:H$60,3,0) -> MBOGNING TUGMA GUY | D12: =IF(E12="ECHEC",0,VLOOKUP($A12,[6]HISTOFEV23!$A$6:$BB$45,15,0)) -> 100000 | E12: =VLOOKUP($A12,[6]HISTOFEV23!$A$6:$BB$45,8,0) -> BANQUE | F12: =VLOOKUP($A12,[6]HISTOFEV23!$A$6:$BB$45,37,0) -> 0 | G12: =VLOOKUP($A12,[6]HISTOFEV23!$A$6:$BB$45,40,0) -> 0 | H12: =IF(F12<>0,VLOOKUP($A12,[6]HISTOFEV23!$A$6:$BB$45,42,0),"ECHEC") -> ECHEC | I12: =VLOOKUP($A12,[6]HISTOFEV23!$A$6:$BB$45,41,0) -> 0 | J12: =TONTJANV23!F12+TONTJANV23!G12 -> 0 | K12: =VLOOKUP($A12,[6]HISTOFEV23!$A$6:$BB$45,18,0) -> 0 | L12: =IF(K12<>0,VLOOKUP($A12,[6]HISTOFEV23!$A$6:$BB$45,42,0),"ECHEC") -> ECHEC | M12: =IF(P12<>0,VLOOKUP($A12,[6]HISTOFEV23!$A$6:$BB$45,32,0),"ECHEC") -> ECHEC | N12: =VLOOKUP($A12,[6]HISTOFEV23!$A$6:$BB$45,33,0) -> 0 | O12: =IF(P12=0,0,($C$3-P12)) -> 0 | P12: =VLOOKUP($A12,[6]HISTOFEV23!$A$6:$BB$45,31,0) -> 0
A13: AS201622 | B13: =IF(D13=0,0,VLOOKUP($A13,[6]HISTOFEV23!$A$6:$BQ$45,14,0)) -> 2 | C13: =VLOOKUP(A13,[7]LISTADHERENT!A$5:H$60,3,0) -> NDJOMO ETIENNE | D13: =IF(E13="ECHEC",0,VLOOKUP($A13,[6]HISTOFEV23!$A$6:$BB$45,15,0)) -> 200000 | E13: =VLOOKUP($A13,[6]HISTOFEV23!$A$6:$BB$45,8,0) -> BANQUE | F13: =VLOOKUP($A13,[6]HISTOFEV23!$A$6:$BB$45,37,0) -> 0 | G13: =VLOOKUP($A13,[6]HISTOFEV23!$A$6:$BB$45,40,0) -> 0 | H13: =IF(F13<>0,VLOOKUP($A13,[6]HISTOFEV23!$A$6:$BB$45,42,0),"ECHEC") -> ECHEC | I13: =VLOOKUP($A13,[6]HISTOFEV23!$A$6:$BB$45,41,0) -> 0 | J13: =TONTJANV23!F13+TONTJANV23!G13 -> 0 | K13: =VLOOKUP($A13,[6]HISTOFEV23!$A$6:$BB$45,18,0) -> 0 | L13: =IF(K13<>0,VLOOKUP($A13,[6]HISTOFEV23!$A$6:$BB$45,42,0),"ECHEC") -> ECHEC | M13: =IF(P13<>0,VLOOKUP($A13,[6]HISTOFEV23!$A$6:$BB$45,32,0),"ECHEC") -> ECHEC | N13: =VLOOKUP($A13,[6]HISTOFEV23!$A$6:$BB$45,33,0) -> 0 | O13: =IF(P13=0,0,($C$3-P13)) -> 0 | P13: =VLOOKUP($A13,[6]HISTOFEV23!$A$6:$BB$45,31,0) -> 0
A14: AS201624 | B14: =IF(D14=0,0,VLOOKUP($A14,[6]HISTOFEV23!$A$6:$BQ$45,14,0)) -> 1 | C14: =VLOOKUP(A14,[7]LISTADHERENT!A$5:H$60,3,0) -> NGONDIEP CLAUDE | D14: =IF(E14="ECHEC",0,VLOOKUP($A14,[6]HISTOFEV23!$A$6:$BB$45,15,0)) -> 100000 | E14: =VLOOKUP($A14,[6]HISTOFEV23!$A$6:$BB$45,8,0) -> BANQUE | F14: =VLOOKUP($A14,[6]HISTOFEV23!$A$6:$BB$45,37,0) -> 0 | G14: =VLOOKUP($A14,[6]HISTOFEV23!$A$6:$BB$45,40,0) -> 0 | H14: =IF(F14<>0,VLOOKUP($A14,[6]HISTOFEV23!$A$6:$BB$45,42,0),"ECHEC") -> ECHEC | I14: =VLOOKUP($A14,[6]HISTOFEV23!$A$6:$BB$45,41,0) -> 0 | J14: =TONTJANV23!F14+TONTJANV23!G14 -> 208000 | K14: =VLOOKUP($A14,[6]HISTOFEV23!$A$6:$BB$45,18,0) -> 208000 | L14: =IF(K14<>0,VLOOKUP($A14,[6]HISTOFEV23!$A$6:$BB$45,42,0),"ECHEC") -> BANQUE | M14: =IF(P14<>0,VLOOKUP($A14,[6]HISTOFEV23!$A$6:$BB$45,32,0),"ECHEC") -> ECHEC | N14: =VLOOKUP($A14,[6]HISTOFEV23!$A$6:$BB$45,33,0) -> 0 | O14: =IF(P14=0,0,($C$3-P14)) -> 0 | P14: =VLOOKUP($A14,[6]HISTOFEV23!$A$6:$BB$45,31,0) -> 0
A15: AS201626 | B15: =IF(D15=0,0,VLOOKUP($A15,[6]HISTOFEV23!$A$6:$BQ$45,14,0)) -> 1 | C15: =VLOOKUP(A15,[7]LISTADHERENT!A$5:H$60,3,0) -> NGUIEMEGNI MATHIEU BLAISE | D15: =IF(E15="ECHEC",0,VLOOKUP($A15,[6]HISTOFEV23!$A$6:$BB$45,15,0)) -> 100000 | E15: =VLOOKUP($A15,[6]HISTOFEV23!$A$6:$BB$45,8,0) -> BANQUE | F15: =VLOOKUP($A15,[6]HISTOFEV23!$A$6:$BB$45,37,0) -> 0 | G15: =VLOOKUP($A15,[6]HISTOFEV23!$A$6:$BB$45,40,0) -> 0 | H15: =IF(F15<>0,VLOOKUP($A15,[6]HISTOFEV23!$A$6:$BB$45,42,0),"ECHEC") -> ECHEC | I15: =VLOOKUP($A15,[6]HISTOFEV23!$A$6:$BB$45,41,0) -> 0 | J15: =TONTJANV23!F15+TONTJANV23!G15 -> 78000 | K15: =VLOOKUP($A15,[6]HISTOFEV23!$A$6:$BB$45,18,0) -> 78000 | L15: =IF(K15<>0,VLOOKUP($A15,[6]HISTOFEV23!$A$6:$BB$45,42,0),"ECHEC") -> BANQUE | M15: =IF(P15<>0,VLOOKUP($A15,[6]HISTOFEV23!$A$6:$BB$45,32,0),"ECHEC") -> ECHEC | N15: =VLOOKUP($A15,[6]HISTOFEV23!$A$6:$BB$45,33,0) -> 0 | O15: =IF(P15=0,0,($C$3-P15)) -> 0 | P15: =VLOOKUP($A15,[6]HISTOFEV23!$A$6:$BB$45,31,0) -> 0
A16: AS201638 | B16: =IF(D16=0,0,VLOOKUP($A16,[6]HISTOFEV23!$A$6:$BQ$45,14,0)) -> 1 | C16: =VLOOKUP(A16,[7]LISTADHERENT!A$5:H$60,3,0) -> SIMO PIERRE | D16: =IF(E16="ECHEC",0,VLOOKUP($A16,[6]HISTOFEV23!$A$6:$BB$45,15,0)) -> 100000 | E16: =VLOOKUP($A16,[6]HISTOFEV23!$A$6:$BB$45,8,0) -> ESPECES | F16: =VLOOKUP($A16,[6]HISTOFEV23!$A$6:$BB$45,37,0) -> 0 | G16: =VLOOKUP($A16,[6]HISTOFEV23!$A$6:$BB$45,40,0) -> 0 | H16: =IF(F16<>0,VLOOKUP($A16,[6]HISTOFEV23!$A$6:$BB$45,42,0),"ECHEC") -> ECHEC | I16: =VLOOKUP($A16,[6]HISTOFEV23!$A$6:$BB$45,41,0) -> 0 | J16: =TONTJANV23!F16+TONTJANV23!G16 -> 0 | K16: =VLOOKUP($A16,[6]HISTOFEV23!$A$6:$BB$45,18,0) -> 0 | L16: =IF(K16<>0,VLOOKUP($A16,[6]HISTOFEV23!$A$6:$BB$45,42,0),"ECHEC") -> ECHEC | M16: =IF(P16<>0,VLOOKUP($A16,[6]HISTOFEV23!$A$6:$BB$45,32,0),"ECHEC") -> ECHEC | N16: =VLOOKUP($A16,[6]HISTOFEV23!$A$6:$BB$45,33,0) -> 0 | O16: =IF(P16=0,0,($C$3-P16)) -> 0 | P16: =VLOOKUP($A16,[6]HISTOFEV23!$A$6:$BB$45,31,0) -> 0
A17: AS201647 | B17: =IF(D17=0,0,VLOOKUP($A17,[6]HISTOFEV23!$A$6:$BQ$45,14,0)) -> 1 | C17: =VLOOKUP(A17,[7]LISTADHERENT!A$5:H$60,3,0) -> YOUMBI EMMANUEL | D17: =IF(E17="ECHEC",0,VLOOKUP($A17,[6]HISTOFEV23!$A$6:$BB$45,15,0)) -> 100000 | E17: =VLOOKUP($A17,[6]HISTOFEV23!$A$6:$BB$45,8,0) -> BANQUE | F17: =VLOOKUP($A17,[6]HISTOFEV23!$A$6:$BB$45,37,0) -> 0 | G17: =VLOOKUP($A17,[6]HISTOFEV23!$A$6:$BB$45,40,0) -> 0 | H17: =IF(F17<>0,VLOOKUP($A17,[6]HISTOFEV23!$A$6:$BB$45,42,0),"ECHEC") -> ECHEC | I17: =VLOOKUP($A17,[6]HISTOFEV23!$A$6:$BB$45,41,0) -> 0 | J17: =TONTJANV23!F17+TONTJANV23!G17 -> 0 | K17: =VLOOKUP($A17,[6]HISTOFEV23!$A$6:$BB$45,18,0) -> 0 | L17: =IF(K17<>0,VLOOKUP($A17,[6]HISTOFEV23!$A$6:$BB$45,42,0),"ECHEC") -> ECHEC | M17: =IF(P17<>0,VLOOKUP($A17,[6]HISTOFEV23!$A$6:$BB$45,32,0),"ECHEC") -> ECHEC | N17: =VLOOKUP($A17,[6]HISTOFEV23!$A$6:$BB$45,33,0) -> 0 | O17: =IF(P17=0,0,($C$3-P17)) -> 0 | P17: =VLOOKUP($A17,[6]HISTOFEV23!$A$6:$BB$45,31,0) -> 0
A19: TOTAL PART | B19: =SUM(B6:B18) -> 14
A20: NBRE ADHERENT | B20: =+COUNT(D6:D18) -> 12 | D20: =SUM(D6:D18) -> 1400000 | F20: =SUM(F6:F18) -> 0 | G20: =SUM(G6:G18) -> 0 | I20: =SUM(I6:I18) -> 0 | J20: =SUM(J6:J18) -> 338000 | K20: =SUM(K6:K18) -> 338000 | N20: =SUM(N6:N18) -> 0 | O20: =SUM(O6:O18) -> 2344000 | P20: =SUM(P6:P18) -> 56000
M21: NBRE PART | N21: PART VENDUE
D22: MONTANT TONTINE | E22: REMBOURSEMENT PETIT LOT | F22: VENTE PETIT LOT | G22: VENTE LOT PRINCIPAL | H22: SOLDE EN CAISSE | K22: TONTINE + REMB + INTERET VENTE | L22: =D26+E26+P20+TONTJANV23!N27 -> 3244000
C23: ESPECES | D23: =SUMIFS(D6:D18,E6:E18,"ESPECES") -> 100000 | E23: =SUMIFS(K6:K18,L6:L18,"ESPECES") -> 0 | F23: =SUMIFS(F6:F18,H6:H18,"ESPECES") -> 0 | G23: =SUMIFS(O6:O18,M6:M18,"ESPECES") -> 0 | H23: =D23+E23-F23-G23 -> 100000 | K23: LOT PRINCIPAL | L23: =C3*COUNTIF(O6:O18,">0") -> 2400000 | M23: =D3 -> 2 | N23: =COUNTIF(O8:O17,">0") -> 2
C24: BANQUE | D24: =SUMIFS(D6:D18,E6:E18,"BANQUE")+1200000 -> 2500000 | E24: =SUMIFS(K6:K18,L6:L18,"BANQUE") -> 338000 | F24: =SUMIFS(F6:F18,H6:H18,"BANQUE") -> 0 | G24: =SUMIFS(O6:O18,M6:M18,"BANQUE") -> 2344000 | H24: =D24+E24-F24-G24 -> 494000
K25: PETIT LOT | L25: =L22-L23 -> 844000 | M25: 816000 | N25: 28000 | O25: ACHAT HOTCHO
C26: TOTAL | D26: =D23+D24 -> 2600000 | E26: =E23+E24 -> 338000 | F26: =F23+F24 -> 0 | G26: =G23+G24 -> 2344000 | H26: =H23+H24 -> 594000
K27: RELIQUAT | L27: =L25-F20 -> 844000 | N27: =TONTFEV23!L27 -> 844000 | O27: CUMUL
K29: ECHEC TONTINE MOIS | L29: =COUNTIFS(E6:E24,"ECHEC")*100000 -> 0 | N29: =TONTJANV23!N29+TONTFEV23!L29 -> 0 | O29: CUMUL
K30: ECHEC REMBOURSEMENT MOIS | L30: =J20-E26 -> 0 | N30: =TONTJANV23!N30+TONTFEV23!L30 -> 0 | O30: CUMUL

Sheet TONTMARS23
A1: ASSOCIATION | B1: ASELBY
A2: ANNEE | B2: 2023 | C2: TONIINE | D2: NBRE PART
A3: TAUX TONTINE | B3: 100000 | C3: =B3*12 -> 1200000 | D3: =ROUNDDOWN(L22/C3,0) -> 2
C4: 44998
A5: MATRICULE | B5: NBREPART | C5: NOM ET PRENOM | D5: MONTANT TONTINE | E5: MODE VERSEMENT | F5: VENTE PETIT LOT | G5: INTERET PETIT LOT | H5: MODE VERSEMENT VENTE PETIT LOT | I5: NUMERO CHEQUE | J5: MONTANT A REMBOURSER PETIT LOT | K5: REMBOURSEMENT PETIT LOT | L5: MODE VERSEMENT REMBOURSEMENT | M5: MODE VERSEMENTLOT PRINCIPAL | N5: NUMERO CHEQUE | O5: MONTANT LOT PRINCIPAL | P5: INTERET LOT PRINCIPAL
A6: AS201648 | B6: =IF(D6=0,0,VLOOKUP($A6,[6]HISTOMARS23!$A$6:$BQ$45,14,0)) -> 1 | C6: =VLOOKUP(A6,[7]LISTADHERENT!A$5:H$60,3,0) -> ASELBY | D6: =IF(E6="ECHEC",0,VLOOKUP($A6,[6]HISTOMARS23!$A$6:$BB$45,15,0)) -> 100000 | E6: =VLOOKUP($A6,[6]HISTOMARS23!$A$6:$BB$45,8,0) -> BANQUE | F6: =VLOOKUP($A6,[6]HISTOMARS23!$A$6:$BB$45,37,0) -> 0 | G6: =VLOOKUP($A6,[6]HISTOMARS23!$A$6:$BB$45,40,0) -> 0 | H6: =IF(F6<>0,VLOOKUP($A6,[6]HISTOMARS23!$A$6:$BB$45,42,0),"ECHEC") -> ECHEC | I6: =VLOOKUP($A6,[6]HISTOMARS23!$A$6:$BB$45,41,0) -> 0 | J6: =TONTFEV23!F6+TONTFEV23!G6 -> 0 | K6: =VLOOKUP($A6,[6]HISTOMARS23!$A$6:$BB$45,18,0) -> 0 | L6: =IF(K6<>0,VLOOKUP($A6,[6]HISTOMARS23!$A$6:$BB$45,42,0),"ECHEC") -> ECHEC | M6: =IF(P6<>0,VLOOKUP($A6,[6]HISTOMARS23!$A$6:$BB$45,32,0),"ECHEC") -> ECHEC | N6: =VLOOKUP($A6,[6]HISTOMARS23!$A$6:$BB$45,33,0) -> 0 | O6: =IF(P6=0,0,($C$3-P6)) -> 0 | P6: =VLOOKUP($A6,[6]HISTOMARS23!$A$6:$BB$45,31,0) -> 0
A7: AS201604 | B7: =IF(D7=0,0,VLOOKUP($A7,[6]HISTOMARS23!$A$6:$BQ$45,14,0)) -> 1 | C7: =VLOOKUP(A7,[7]LISTADHERENT!A$5:H$60,3,0) -> DJOMO JEAN PAUL | D7: =IF(E7="ECHEC",0,VLOOKUP($A7,[6]HISTOMARS23!$A$6:$BB$45,15,0)) -> 100000 | E7: =VLOOKUP($A7,[6]HISTOMARS23!$A$6:$BB$45,8,0) -> BANQUE | F7: =VLOOKUP($A7,[6]HISTOMARS23!$A$6:$BB$45,37,0) -> 0 | G7: =VLOOKUP($A7,[6]HISTOMARS23!$A$6:$BB$45,40,0) -> 0 | H7: =IF(F7<>0,VLOOKUP($A7,[6]HISTOMARS23!$A$6:$BB$45,42,0),"ECHEC") -> ECHEC | I7: =VLOOKUP($A7,[6]HISTOMARS23!$A$6:$BB$45,41,0) -> 0 | J7: =TONTFEV23!F7+TONTFEV23!G7 -> 0 | K7: =VLOOKUP($A7,[6]HISTOMARS23!$A$6:$BB$45,18,0) -> 0 | L7: =IF(K7<>0,VLOOKUP($A7,[6]HISTOMARS23!$A$6:$BB$45,42,0),"ECHEC") -> ECHEC | M7: =IF(P7<>0,VLOOKUP($A7,[6]HISTOMARS23!$A$6:$BB$45,32,0),"ECHEC") -> 0 | N7: =VLOOKUP($A7,[6]HISTOMARS23!$A$6:$BB$45,33,0) -> 0 | O7: =IF(P7=0,0,($C$3-P7)) -> 1190000 | P7: =VLOOKUP($A7,[6]HISTOMARS23!$A$6:$BB$45,31,0) -> 10000
A8: AS201608 | B8: =IF(D8=0,0,VLOOKUP($A8,[6]HISTOMARS23!$A$6:$BQ$45,14,0)) -> 2 | C8: =VLOOKUP(A8,[7]LISTADHERENT!A$5:H$60,3,0) -> DJUOMBESSY ANTOINE | D8: =IF(E8="ECHEC",0,VLOOKUP($A8,[6]HISTOMARS23!$A$6:$BB$45,15,0)) -> 200000 | E8: =VLOOKUP($A8,[6]HISTOMARS23!$A$6:$BB$45,8,0) -> BANQUE | F8: =VLOOKUP($A8,[6]HISTOMARS23!$A$6:$BB$45,37,0) -> 0 | G8: =VLOOKUP($A8,[6]HISTOMARS23!$A$6:$BB$45,40,0) -> 0 | H8: =IF(F8<>0,VLOOKUP($A8,[6]HISTOMARS23!$A$6:$BB$45,42,0),"ECHEC") -> ECHEC | I8: =VLOOKUP($A8,[6]HISTOMARS23!$A$6:$BB$45,41,0) -> 0 | J8: =TONTFEV23!F8+TONTFEV23!G8 -> 0 | K8: =VLOOKUP($A8,[6]HISTOMARS23!$A$6:$BB$45,18,0) -> 0 | L8: =IF(K8<>0,VLOOKUP($A8,[6]HISTOMARS23!$A$6:$BB$45,42,0),"ECHEC") -> ECHEC | M8: =IF(P8<>0,VLOOKUP($A8,[6]HISTOMARS23!$A$6:$BB$45,32,0),"ECHEC") -> 0 | N8: =VLOOKUP($A8,[6]HISTOMARS23!$A$6:$BB$45,33,0) -> 0 | O8: =IF(P8=0,0,($C$3-P8)) -> 1190000 | P8: =VLOOKUP($A8,[6]HISTOMARS23!$A$6:$BB$45,31,0) -> 10000
A9: AS201613 | B9: =IF(D9=0,0,VLOOKUP($A9,[6]HISTOMARS23!$A$6:$BQ$45,14,0)) -> 1 | C9: =VLOOKUP(A9,[7]LISTADHERENT!A$5:H$60,3,0) -> HOTCHO BENJAMIN | D9: =IF(E9="ECHEC",0,VLOOKUP($A9,[6]HISTOMARS23!$A$6:$BB$45,15,0)) -> 100000 | E9: =VLOOKUP($A9,[6]HISTOMARS23!$A$6:$BB$45,8,0) -> BANQUE | F9: =VLOOKUP($A9,[6]HISTOMARS23!$A$6:$BB$45,37,0) -> 164000 | G9: =VLOOKUP($A9,[6]HISTOMARS23!$A$6:$BB$45,40,0) -> 1000 | H9: =IF(F9<>0,VLOOKUP($A9,[6]HISTOMARS23!$A$6:$BB$45,42,0),"ECHEC") -> 0 | I9: =VLOOKUP($A9,[6]HISTOMARS23!$A$6:$BB$45,41,0) -> 0 | J9: =TONTFEV23!F9+TONTFEV23!G9 -> 0 | K9: =VLOOKUP($A9,[6]HISTOMARS23!$A$6:$BB$45,18,0) -> 0 | L9: =IF(K9<>0,VLOOKUP($A9,[6]HISTOMARS23!$A$6:$BB$45,42,0),"ECHEC") -> ECHEC | M9: =IF(P9<>0,VLOOKUP($A9,[6]HISTOMARS23!$A$6:$BB$45,32,0),"ECHEC") -> ECHEC | N9: =VLOOKUP($A9,[6]HISTOMARS23!$A$6:$BB$45,33,0) -> 0 | O9: =IF(P9=0,0,($C$3-P9)) -> 0 | P9: =VLOOKUP($A9,[6]HISTOMARS23!$A$6:$BB$45,31,0) -> 0
A10: AS201617 | B10: =IF(D10=0,0,VLOOKUP($A10,[6]HISTOMARS23!$A$6:$BQ$45,14,0)) -> 1 | C10: =VLOOKUP(A10,[7]LISTADHERENT!A$5:H$60,3,0) -> KOUAMOU MOISE | D10: =IF(E10="ECHEC",0,VLOOKUP($A10,[6]HISTOMARS23!$A$6:$BB$45,15,0)) -> 100000 | E10: =VLOOKUP($A10,[6]HISTOMARS23!$A$6:$BB$45,8,0) -> BANQUE | F10: =VLOOKUP($A10,[6]HISTOMARS23!$A$6:$BB$45,37,0) -> 200000 | G10: =VLOOKUP($A10,[6]HISTOMARS23!$A$6:$BB$45,40,0) -> 2000 | H10: =IF(F10<>0,VLOOKUP($A10,[6]HISTOMARS23!$A$6:$BB$45,42,0),"ECHEC") -> 0 | I10: =VLOOKUP($A10,[6]HISTOMARS23!$A$6:$BB$45,41,0) -> 0 | J10: =TONTFEV23!F10+TONTFEV23!G10 -> 0 | K10: =VLOOKUP($A10,[6]HISTOMARS23!$A$6:$BB$45,18,0) -> 0 | L10: =IF(K10<>0,VLOOKUP($A10,[6]HISTOMARS23!$A$6:$BB$45,42,0),"ECHEC") -> ECHEC | M10: =IF(P10<>0,VLOOKUP($A10,[6]HISTOMARS23!$A$6:$BB$45,32,0),"ECHEC") -> ECHEC | N10: =VLOOKUP($A10,[6]HISTOMARS23!$A$6:$BB$45,33,0) -> 0 | O10: =IF(P10=0,0,($C$3-P10)) -> 0 | P10: =VLOOKUP($A10,[6]HISTOMARS23!$A$6:$BB$45,31,0) -> 0
A11: AS201619 | B11: =IF(D11=0,0,VLOOKUP($A11,[6]HISTOMARS23!$A$6:$BQ$45,14,0)) -> 1 | C11: =VLOOKUP(A11,[7]LISTADHERENT!A$5:H$60,3,0) -> KOUATCHO MESSACK | D11: =IF(E11="ECHEC",0,VLOOKUP($A11,[6]HISTOMARS23!$A$6:$BB$45,15,0)) -> 100000 | E11: =VLOOKUP($A11,[6]HISTOMARS23!$A$6:$BB$45,8,0) -> BANQUE | F11: =VLOOKUP($A11,[6]HISTOMARS23!$A$6:$BB$45,37,0) -> 200000 | G11: =VLOOKUP($A11,[6]HISTOMARS23!$A$6:$BB$45,40,0) -> 2000 | H11: =IF(F11<>0,VLOOKUP($A11,[6]HISTOMARS23!$A$6:$BB$45,42,0),"ECHEC") -> 0 | I11: =VLOOKUP($A11,[6]HISTOMARS23!$A$6:$BB$45,41,0) -> 0 | J11: =TONTFEV23!F11+TONTFEV23!G11 -> 0 | K11: =VLOOKUP($A11,[6]HISTOMARS23!$A$6:$BB$45,18,0) -> 0 | L11: =IF(K11<>0,VLOOKUP($A11,[6]HISTOMARS23!$A$6:$BB$45,42,0),"ECHEC") -> ECHEC | M11: =IF(P11<>0,VLOOKUP($A11,[6]HISTOMARS23!$A$6:$BB$45,32,0),"ECHEC") -> ECHEC | N11: =VLOOKUP($A11,[6]HISTOMARS23!$A$6:$BB$45,33,0) -> 0 | O11: =IF(P11=0,0,($C$3-P11)) -> 0 | P11: =VLOOKUP($A11,[6]HISTOMARS23!$A$6:$BB$45,31,0) -> 0
A12: AS201649 | B12: =IF(D12=0,0,VLOOKUP($A12,[6]HISTOMARS23!$A$6:$BQ$45,14,0)) -> 1 | C12: =VLOOKUP(A12,[7]LISTADHERENT!A$5:H$60,3,0) -> MBOGNING TUGMA GUY | D12: =IF(E12="ECHEC",0,VLOOKUP($A12,[6]HISTOMARS23!$A$6:$BB$45,15,0)) -> 100000 | E12: =VLOOKUP($A12,[6]HISTOMARS23!$A$6:$BB$45,8,0) -> BANQUE | F12: =VLOOKUP($A12,[6]HISTOMARS23!$A$6:$BB$45,37,0) -> 200000 | G12: =VLOOKUP($A12,[6]HISTOMARS23!$A$6:$BB$45,40,0) -> 2000 | H12: =IF(F12<>0,VLOOKUP($A12,[6]HISTOMARS23!$A$6:$BB$45,42,0),"ECHEC") -> 0 | I12: =VLOOKUP($A12,[6]HISTOMARS23!$A$6:$BB$45,41,0) -> 0 | J12: =TONTFEV23!F12+TONTFEV23!G12 -> 0 | K12: =VLOOKUP($A12,[6]HISTOMARS23!$A$6:$BB$45,18,0) -> 0 | L12: =IF(K12<>0,VLOOKUP($A12,[6]HISTOMARS23!$A$6:$BB$45,42,0),"ECHEC") -> ECHEC | M12: =IF(P12<>0,VLOOKUP($A12,[6]HISTOMARS23!$A$6:$BB$45,32,0),"ECHEC") -> ECHEC | N12: =VLOOKUP($A12,[6]HISTOMARS23!$A$6:$BB$45,33,0) -> 0 | O12: =IF(P12=0,0,($C$3-P12)) -> 0 | P12: =VLOOKUP($A12,[6]HISTOMARS23!$A$6:$BB$45,31,0) -> 0
A13: AS201622 | B13: =IF(D13=0,0,VLOOKUP($A13,[6]HISTOMARS23!$A$6:$BQ$45,14,0)) -> 2 | C13: =VLOOKUP(A13,[7]LISTADHERENT!A$5:H$60,3,0) -> NDJOMO ETIENNE | D13: =IF(E13="ECHEC",0,VLOOKUP($A13,[6]HISTOMARS23!$A$6:$BB$45,15,0)) -> 200000 | E13: =VLOOKUP($A13,[6]HISTOMARS23!$A$6:$BB$45,8,0) -> BANQUE | F13: =VLOOKUP($A13,[6]HISTOMARS23!$A$6:$BB$45,37,0) -> 200000 | G13: =VLOOKUP($A13,[6]HISTOMARS23!$A$6:$BB$45,40,0) -> 2000 | H13: =IF(F13<>0,VLOOKUP($A13,[6]HISTOMARS23!$A$6:$BB$45,42,0),"ECHEC") -> 0 | I13: =VLOOKUP($A13,[6]HISTOMARS23!$A$6:$BB$45,41,0) -> 0 | J13: =TONTFEV23!F13+TONTFEV23!G13 -> 0 | K13: =VLOOKUP($A13,[6]HISTOMARS23!$A$6:$BB$45,18,0) -> 0 | L13: =IF(K13<>0,VLOOKUP($A13,[6]HISTOMARS23!$A$6:$BB$45,42,0),"ECHEC") -> ECHEC | M13: =IF(P13<>0,VLOOKUP($A13,[6]HISTOMARS23!$A$6:$BB$45,32,0),"ECHEC") -> ECHEC | N13: =VLOOKUP($A13,[6]HISTOMARS23!$A$6:$BB$45,33,0) -> 0 | O13: =IF(P13=0,0,($C$3-P13)) -> 0 | P13: =VLOOKUP($A13,[6]HISTOMARS23!$A$6:$BB$45,31,0) -> 0
A14: AS201624 | B14: =IF(D14=0,0,VLOOKUP($A14,[6]HISTOMARS23!$A$6:$BQ$45,14,0)) -> 1 | C14: =VLOOKUP(A14,[7]LISTADHERENT!A$5:H$60,3,0) -> NGONDIEP CLAUDE | D14: =IF(E14="ECHEC",0,VLOOKUP($A14,[6]HISTOMARS23!$A$6:$BB$45,15,0)) -> 100000 | E14: =VLOOKUP($A14,[6]HISTOMARS23!$A$6:$BB$45,8,0) -> ESPECES | F14: =VLOOKUP($A14,[6]HISTOMARS23!$A$6:$BB$45,37,0) -> 0 | G14: =VLOOKUP($A14,[6]HISTOMARS23!$A$6:$BB$45,40,0) -> 0 | H14: =IF(F14<>0,VLOOKUP($A14,[6]HISTOMARS23!$A$6:$BB$45,42,0),"ECHEC") -> ECHEC | I14: =VLOOKUP($A14,[6]HISTOMARS23!$A$6:$BB$45,41,0) -> 0 | J14: =TONTFEV23!F14+TONTFEV23!G14 -> 0 | K14: =VLOOKUP($A14,[6]HISTOMARS23!$A$6:$BB$45,18,0) -> 0 | L14: =IF(K14<>0,VLOOKUP($A14,[6]HISTOMARS23!$A$6:$BB$45,42,0),"ECHEC") -> ECHEC | M14: =IF(P14<>0,VLOOKUP($A14,[6]HISTOMARS23!$A$6:$BB$45,32,0),"ECHEC") -> ECHEC | N14: =VLOOKUP($A14,[6]HISTOMARS23!$A$6:$BB$45,33,0) -> 0 | O14: =IF(P14=0,0,($C$3-P14)) -> 0 | P14: =VLOOKUP($A14,[6]HISTOMARS23!$A$6:$BB$45,31,0) -> 0
A15: AS201626 | B15: =IF(D15=0,0,VLOOKUP($A15,[6]HISTOMARS23!$A$6:$BQ$45,14,0)) -> 1 | C15: =VLOOKUP(A15,[7]LISTADHERENT!A$5:H$60,3,0) -> NGUIEMEGNI MATHIEU BLAISE | D15: =IF(E15="ECHEC",0,VLOOKUP($A15,[6]HISTOMARS23!$A$6:$BB$45,15,0)) -> 100000 | E15: =VLOOKUP($A15,[6]HISTOMARS23!$A$6:$BB$45,8,0) -> BANQUE | F15: =VLOOKUP($A15,[6]HISTOMARS23!$A$6:$BB$45,37,0) -> 0 | G15: =VLOOKUP($A15,[6]HISTOMARS23!$A$6:$BB$45,40,0) -> 0 | H15: =IF(F15<>0,VLOOKUP($A15,[6]HISTOMARS23!$A$6:$BB$45,42,0),"ECHEC") -> ECHEC | I15: =VLOOKUP($A15,[6]HISTOMARS23!$A$6:$BB$45,41,0) -> 0 | J15: =TONTFEV23!F15+TONTFEV23!G15 -> 0 | K15: =VLOOKUP($A15,[6]HISTOMARS23!$A$6:$BB$45,18,0) -> 0 | L15: =IF(K15<>0,VLOOKUP($A15,[6]HISTOMARS23!$A$6:$BB$45,42,0),"ECHEC") -> ECHEC | M15: =IF(P15<>0,VLOOKUP($A15,[6]HISTOMARS23!$A$6:$BB$45,32,0),"ECHEC") -> ECHEC | N15: =VLOOKUP($A15,[6]HISTOMARS23!$A$6:$BB$45,33,0) -> 0 | O15: =IF(P15=0,0,($C$3-P15)) -> 0 | P15: =VLOOKUP($A15,[6]HISTOMARS23!$A$6:$BB$45,31,0) -> 0
A16: AS201638 | B16: =IF(D16=0,0,VLOOKUP($A16,[6]HISTOMARS23!$A$6:$BQ$45,14,0)) -> 1 | C16: =VLOOKUP(A16,[7]LISTADHERENT!A$5:H$60,3,0) -> SIMO PIERRE | D16: =IF(E16="ECHEC",0,VLOOKUP($A16,[6]HISTOMARS23!$A$6:$BB$45,15,0)) -> 100000 | E16: =VLOOKUP($A16,[6]HISTOMARS23!$A$6:$BB$45,8,0) -> BANQUE | F16: =VLOOKUP($A16,[6]HISTOMARS23!$A$6:$BB$45,37,0) -> 0 | G16: =VLOOKUP($A16,[6]HISTOMARS23!$A$6:$BB$45,40,0) -> 0 | H16: =IF(F16<>0,VLOOKUP($A16,[6]HISTOMARS23!$A$6:$BB$45,42,0),"ECHEC") -> ECHEC | I16: =VLOOKUP($A16,[6]HISTOMARS23!$A$6:$BB$45,41,0) -> 0 | J16: =TONTFEV23!F16+TONTFEV23!G16 -> 0 | K16: =VLOOKUP($A16,[6]HISTOMARS23!$A$6:$BB$45,18,0) -> 0 | L16: =IF(K16<>0,VLOOKUP($A16,[6]HISTOMARS23!$A$6:$BB$45,42,0),"ECHEC") -> ECHEC | M16: =IF(P16<>0,VLOOKUP($A16,[6]HISTOMARS23!$A$6:$BB$45,32,0),"ECHEC") -> ECHEC | N16: =VLOOKUP($A16,[6]HISTOMARS23!$A$6:$BB$45,33,0) -> 0 | O16: =IF(P16=0,0,($C$3-P16)) -> 0 | P16: =VLOOKUP($A16,[6]HISTOMARS23!$A$6:$BB$45,31,0) -> 0
A17: AS201647 | B17: =IF(D17=0,0,VLOOKUP($A17,[6]HISTOMARS23!$A$6:$BQ$45,14,0)) -> 1 | C17: =VLOOKUP(A17,[7]LISTADHERENT!A$5:H$60,3,0) -> YOUMBI EMMANUEL | D17: =IF(E17="ECHEC",0,VLOOKUP($A17,[6]HISTOMARS23!$A$6:$BB$45,15,0)) -> 100000 | E17: =VLOOKUP($A17,[6]HISTOMARS23!$A$6:$BB$45,8,0) -> BANQUE | F17: =VLOOKUP($A17,[6]HISTOMARS23!$A$6:$BB$45,37,0) -> 0 | G17: =VLOOKUP($A17,[6]HISTOMARS23!$A$6:$BB$45,40,0) -> 0 | H17: =IF(F17<>0,VLOOKUP($A17,[6]HISTOMARS23!$A$6:$BB$45,42,0),"ECHEC") -> ECHEC | I17: =VLOOKUP($A17,[6]HISTOMARS23!$A$6:$BB$45,41,0) -> 0 | J17: =TONTFEV23!F17+TONTFEV23!G17 -> 0 | K17: =VLOOKUP($A17,[6]HISTOMARS23!$A$6:$BB$45,18,0) -> 0 | L17: =IF(K17<>0,VLOOKUP($A17,[6]HISTOMARS23!$A$6:$BB$45,42,0),"ECHEC") -> ECHEC | M17: =IF(P17<>0,VLOOKUP($A17,[6]HISTOMARS23!$A$6:$BB$45,32,0),"ECHEC") -> ECHEC | N17: =VLOOKUP($A17,[6]HISTOMARS23!$A$6:$BB$45,33,0) -> 0 | O17: =IF(P17=0,0,($C$3-P17)) -> 0 | P17: =VLOOKUP($A17,[6]HISTOMARS23!$A$6:$BB$45,31,0) -> 0
A19: TOTAL PART | B19: =SUM(B6:B18) -> 14
A20: NBRE ADHERENT | B20: =+COUNT(D6:D18) -> 12 | D20: =SUM(D6:D18) -> 1400000 | F20: =SUM(F6:F18) -> 964000 | G20: =SUM(G6:G18) -> 9000 | I20: =SUM(I6:I18) -> 0 | J20: =SUM(J6:J18) -> 0 | K20: =SUM(K6:K18) -> 0 | N20: =SUM(N6:N18) -> 0 | O20: =SUM(O6:O18) -> 2380000 | P20: =SUM(P6:P18) -> 20000
M21: NBRE PART | N21: PART VENDUE
D22: MONTANT TONTINE | E22: REMBOURSEMENT PETIT LOT | F22: VENTE PETIT LOT | G22: VENTE LOT PRINCIPAL | H22: SOLDE EN CAISSE | K22: TONTINE + REMB + INTERET VENTE | L22: =D26+E26+P20+TONTFEV23!N27 -> 3464000
C23: ESPECES | D23: =SUMIFS(D6:D18,E6:E18,"ESPECES") -> 100000 | E23: =SUMIFS(K6:K18,L6:L18,"ESPECES") -> 0 | F23: =SUMIFS(F6:F18,H6:H18,"ESPECES") -> 0 | G23: =SUMIFS(O6:O18,M6:M18,"ESPECES") -> 0 | H23: =D23+E23-F23-G23 -> 100000 | K23: LOT PRINCIPAL | L23: =C3*COUNTIF(O6:O18,">0") -> 2400000 | M23: =D3 -> 2 | N23: =COUNTIF(O8:O17,">0") -> 1
C24: BANQUE | D24: =SUMIFS(D6:D18,E6:E18,"BANQUE")+1200000 -> 2500000 | E24: =SUMIFS(K6:K18,L6:L18,"BANQUE") -> 0 | F24: =SUMIFS(F6:F18,H6:H18,"BANQUE") -> 0 | G24: =SUMIFS(O6:O18,M6:M18,"BANQUE") -> 0 | H24: =D24+E24-F24-G24 -> 2500000
K25: PETIT LOT | L25: =L22-L23 -> 1064000
C26: TOTAL | D26: =D23+D24 -> 2600000 | E26: =E23+E24 -> 0 | F26: =F23+F24 -> 0 | G26: =G23+G24 -> 0 | H26: =H23+H24 -> 2600000
K27: RELIQUAT | L27: =L25-F20 -> 100000 | N27: =TONTMARS23!L27 -> 100000 | O27: CUMUL
K29: ECHEC TONTINE MOIS | L29: =COUNTIFS(E6:E24,"ECHEC")*100000 -> 0 | N29: =TONTFEV23!N29+TONTMARS23!L29 -> 0 | O29: CUMUL
K30: ECHEC REMBOURSEMENT MOIS | L30: =J20-E26 -> 0 | N30: =TONTFEV23!N30+TONTMARS23!L30 -> 0 | O30: CUMUL

Sheet TONTAVRIL23
A1: ASSOCIATION | B1: ASELBY
A2: ANNEE | B2: 2023 | C2: TONIINE | D2: NBRE PART
A3: TAUX TONTINE | B3: 100000 | C3: =B3*12 -> 1200000 | D3: =ROUNDDOWN(L22/C3,0) -> 2
C4: 45029
A5: MATRICULE | B5: NBREPART | C5: NOM ET PRENOM | D5: MONTANT TONTINE | E5: MODE VERSEMENT | F5: VENTE PETIT LOT | G5: INTERET PETIT LOT | H5: MODE VERSEMENT VENTE PETIT LOT | I5: NUMERO CHEQUE | J5: MONTANT A REMBOURSER PETIT LOT | K5: REMBOURSEMENT PETIT LOT | L5: MODE VERSEMENT REMBOURSEMENT | M5: MODE VERSEMENTLOT PRINCIPAL | N5: NUMERO CHEQUE | O5: MONTANT LOT PRINCIPAL | P5: INTERET LOT PRINCIPAL
A6: AS201648 | B6: =IF(D6=0,0,VLOOKUP($A6,[6]HISTOAVRIL23!$A$6:$BQ$45,14,0)) -> 1 | C6: =VLOOKUP(A6,[7]LISTADHERENT!A$5:H$60,3,0) -> ASELBY | D6: =IF(E6="ECHEC",0,VLOOKUP($A6,[6]HISTOAVRIL23!$A$6:$BB$45,15,0)) -> 100000 | E6: =VLOOKUP($A6,[6]HISTOAVRIL23!$A$6:$BB$45,8,0) -> BANQUE | F6: =VLOOKUP($A6,[6]HISTOAVRIL23!$A$6:$BB$45,37,0) -> 0 | G6: =VLOOKUP($A6,[6]HISTOAVRIL23!$A$6:$BB$45,40,0) -> 0 | H6: =IF(F6<>0,VLOOKUP($A6,[6]HISTOAVRIL23!$A$6:$BB$45,42,0),"ECHEC") -> ECHEC | I6: =VLOOKUP($A6,[6]HISTOAVRIL23!$A$6:$BB$45,41,0) -> 0 | J6: =TONTMARS23!F6+TONTMARS23!G6 -> 0 | K6: =VLOOKUP($A6,[6]HISTOAVRIL23!$A$6:$BB$45,18,0) -> 0 | L6: =IF(K6<>0,VLOOKUP($A6,[6]HISTOAVRIL23!$A$6:$BB$45,42,0),"ECHEC") -> ECHEC | M6: =IF(P6<>0,VLOOKUP($A6,[6]HISTOAVRIL23!$A$6:$BB$45,32,0),"ECHEC") -> ECHEC | N6: =VLOOKUP($A6,[6]HISTOAVRIL23!$A$6:$BB$45,33,0) -> 0 | O6: =IF(P6=0,0,($C$3-P6)) -> 0 | P6: =VLOOKUP($A6,[6]HISTOAVRIL23!$A$6:$BB$45,31,0) -> 0
A7: AS201604 | B7: =IF(D7=0,0,VLOOKUP($A7,[6]HISTOAVRIL23!$A$6:$BQ$45,14,0)) -> 1 | C7: =VLOOKUP(A7,[7]LISTADHERENT!A$5:H$60,3,0) -> DJOMO JEAN PAUL | D7: =IF(E7="ECHEC",0,VLOOKUP($A7,[6]HISTOAVRIL23!$A$6:$BB$45,15,0)) -> 100000 | E7: =VLOOKUP($A7,[6]HISTOAVRIL23!$A$6:$BB$45,8,0) -> BANQUE | F7: =VLOOKUP($A7,[6]HISTOAVRIL23!$A$6:$BB$45,37,0) -> 0 | G7: =VLOOKUP($A7,[6]HISTOAVRIL23!$A$6:$BB$45,40,0) -> 0 | H7: =IF(F7<>0,VLOOKUP($A7,[6]HISTOAVRIL23!$A$6:$BB$45,42,0),"ECHEC") -> ECHEC | I7: =VLOOKUP($A7,[6]HISTOAVRIL23!$A$6:$BB$45,41,0) -> 0 | J7: =TONTMARS23!F7+TONTMARS23!G7 -> 0 | K7: =VLOOKUP($A7,[6]HISTOAVRIL23!$A$6:$BB$45,18,0) -> 0 | L7: =IF(K7<>0,VLOOKUP($A7,[6]HISTOAVRIL23!$A$6:$BB$45,42,0),"ECHEC") -> ECHEC | M7: =IF(P7<>0,VLOOKUP($A7,[6]HISTOAVRIL23!$A$6:$BB$45,32,0),"ECHEC") -> ECHEC | N7: =VLOOKUP($A7,[6]HISTOAVRIL23!$A$6:$BB$45,33,0) -> 0 | O7: =IF(P7=0,0,($C$3-P7)) -> 0 | P7: =VLOOKUP($A7,[6]HISTOAVRIL23!$A$6:$BB$45,31,0) -> 0
A8: AS201608 | B8: =IF(D8=0,0,VLOOKUP($A8,[6]HISTOAVRIL23!$A$6:$BQ$45,14,0)) -> 2 | C8: =VLOOKUP(A8,[7]LISTADHERENT!A$5:H$60,3,0) -> DJUOMBESSY ANTOINE | D8: =IF(E8="ECHEC",0,VLOOKUP($A8,[6]HISTOAVRIL23!$A$6:$BB$45,15,0)) -> 200000 | E8: =VLOOKUP($A8,[6]HISTOAVRIL23!$A$6:$BB$45,8,0) -> BANQUE | F8: =VLOOKUP($A8,[6]HISTOAVRIL23!$A$6:$BB$45,37,0) -> 0 | G8: =VLOOKUP($A8,[6]HISTOAVRIL23!$A$6:$BB$45,40,0) -> 0 | H8: =IF(F8<>0,VLOOKUP($A8,[6]HISTOAVRIL23!$A$6:$BB$45,42,0),"ECHEC") -> ECHEC | I8: =VLOOKUP($A8,[6]HISTOAVRIL23!$A$6:$BB$45,41,0) -> 0 | J8: =TONTMARS23!F8+TONTMARS23!G8 -> 0 | K8: =VLOOKUP($A8,[6]HISTOAVRIL23!$A$6:$BB$45,18,0) -> 0 | L8: =IF(K8<>0,VLOOKUP($A8,[6]HISTOAVRIL23!$A$6:$BB$45,42,0),"ECHEC") -> ECHEC | M8: =IF(P8<>0,VLOOKUP($A8,[6]HISTOAVRIL23!$A$6:$BB$45,32,0),"ECHEC") -> ECHEC | N8: =VLOOKUP($A8,[6]HISTOAVRIL23!$A$6:$BB$45,33,0) -> 0 | O8: =IF(P8=0,0,($C$3-P8)) -> 0 | P8: =VLOOKUP($A8,[6]HISTOAVRIL23!$A$6:$BB$45,31,0) -> 0
A9: AS201613 | B9: =IF(D9=0,0,VLOOKUP($A9,[6]HISTOAVRIL23!$A$6:$BQ$45,14,0)) -> 1 | C9: =VLOOKUP(A9,[7]LISTADHERENT!A$5:H$60,3,0) -> HOTCHO BENJAMIN | D9: =IF(E9="ECHEC",0,VLOOKUP($A9,[6]HISTOAVRIL23!$A$6:$BB$45,15,0)) -> 100000 | E9: =VLOOKUP($A9,[6]HISTOAVRIL23!$A$6:$BB$45,8,0) -> BANQUE | F9: =VLOOKUP($A9,[6]HISTOAVRIL23!$A$6:$BB$45,37,0) -> 0 | G9: =VLOOKUP($A9,[6]HISTOAVRIL23!$A$6:$BB$45,40,0) -> 0 | H9: =IF(F9<>0,VLOOKUP($A9,[6]HISTOAVRIL23!$A$6:$BB$45,42,0),"ECHEC") -> ECHEC | I9: =VLOOKUP($A9,[6]HISTOAVRIL23!$A$6:$BB$45,41,0) -> 0 | J9: =TONTMARS23!F9+TONTMARS23!G9 -> 165000 | K9: =VLOOKUP($A9,[6]HISTOAVRIL23!$A$6:$BB$45,18,0) -> 165000 | L9: =IF(K9<>0,VLOOKUP($A9,[6]HISTOAVRIL23!$A$6:$BB$45,42,0),"ECHEC") -> BANQUE | M9: =IF(P9<>0,VLOOKUP($A9,[6]HISTOAVRIL23!$A$6:$BB$45,32,0),"ECHEC") -> ECHEC | N9: =VLOOKUP($A9,[6]HISTOAVRIL23!$A$6:$BB$45,33,0) -> 0 | O9: =IF(P9=0,0,($C$3-P9)) -> 0 | P9: =VLOOKUP($A9,[6]HISTOAVRIL23!$A$6:$BB$45,31,0) -> 0
A10: AS201617 | B10: =IF(D10=0,0,VLOOKUP($A10,[6]HISTOAVRIL23!$A$6:$BQ$45,14,0)) -> 1 | C10: =VLOOKUP(A10,[7]LISTADHERENT!A$5:H$60,3,0) -> KOUAMOU MOISE | D10: =IF(E10="ECHEC",0,VLOOKUP($A10,[6]HISTOAVRIL23!$A$6:$BB$45,15,0)) -> 100000 | E10: =VLOOKUP($A10,[6]HISTOAVRIL23!$A$6:$BB$45,8,0) -> BANQUE | F10: =VLOOKUP($A10,[6]HISTOAVRIL23!$A$6:$BB$45,37,0) -> 0 | G10: =VLOOKUP($A10,[6]HISTOAVRIL23!$A$6:$BB$45,40,0) -> 0 | H10: =IF(F10<>0,VLOOKUP($A10,[6]HISTOAVRIL23!$A$6:$BB$45,42,0),"ECHEC") -> ECHEC | I10: =VLOOKUP($A10,[6]HISTOAVRIL23!$A$6:$BB$45,41,0) -> 0 | J10: =TONTMARS23!F10+TONTMARS23!G10 -> 202000 | K10: =VLOOKUP($A10,[6]HISTOAVRIL23!$A$6:$BB$45,18,0) -> 202000 | L10: =IF(K10<>0,VLOOKUP($A10,[6]HISTOAVRIL23!$A$6:$BB$45,42,0),"ECHEC") -> BANQUE | M10: =IF(P10<>0,VLOOKUP($A10,[6]HISTOAVRIL23!$A$6:$BB$45,32,0),"ECHEC") -> ECHEC | N10: =VLOOKUP($A10,[6]HISTOAVRIL23!$A$6:$BB$45,33,0) -> 0 | O10: =IF(P10=0,0,($C$3-P10)) -> 0 | P10: =VLOOKUP($A10,[6]HISTOAVRIL23!$A$6:$BB$45,31,0) -> 0
A11: AS201619 | B11: =IF(D11=0,0,VLOOKUP($A11,[6]HISTOAVRIL23!$A$6:$BQ$45,14,0)) -> 1 | C11: =VLOOKUP(A11,[7]LISTADHERENT!A$5:H$60,3,0) -> KOUATCHO MESSACK | D11: =IF(E11="ECHEC",0,VLOOKUP($A11,[6]HISTOAVRIL23!$A$6:$BB$45,15,0)) -> 100000 | E11: =VLOOKUP($A11,[6]HISTOAVRIL23!$A$6:$BB$45,8,0) -> BANQUE | F11: =VLOOKUP($A11,[6]HISTOAVRIL23!$A$6:$BB$45,37,0) -> 0 | G11: =VLOOKUP($A11,[6]HISTOAVRIL23!$A$6:$BB$45,40,0) -> 0 | H11: =IF(F11<>0,VLOOKUP($A11,[6]HISTOAVRIL23!$A$6:$BB$45,42,0),"ECHEC") -> ECHEC | I11: =VLOOKUP($A11,[6]HISTOAVRIL23!$A$6:$BB$45,41,0) -> 0 | J11: =TONTMARS23!F11+TONTMARS23!G11 -> 202000 | K11: =VLOOKUP($A11,[6]HISTOAVRIL23!$A$6:$BB$45,18,0) -> 202000 | L11: =IF(K11<>0,VLOOKUP($A11,[6]HISTOAVRIL23!$A$6:$BB$45,42,0),"ECHEC") -> BANQUE | M11: =IF(P11<>0,VLOOKUP($A11,[6]HISTOAVRIL23!$A$6:$BB$45,32,0),"ECHEC") -> ECHEC | N11: =VLOOKUP($A11,[6]HISTOAVRIL23!$A$6:$BB$45,33,0) -> 0 | O11: =IF(P11=0,0,($C$3-P11)) -> 0 | P11: =VLOOKUP($A11,[6]HISTOAVRIL23!$A$6:$BB$45,31,0) -> 0
A12: AS201649 | B12: =IF(D12=0,0,VLOOKUP($A12,[6]HISTOAVRIL23!$A$6:$BQ$45,14,0)) -> 1 | C12: =VLOOKUP(A12,[7]LISTADHERENT!A$5:H$60,3,0) -> MBOGNING TUGMA GUY | D12: =IF(E12="ECHEC",0,VLOOKUP($A12,[6]HISTOAVRIL23!$A$6:$BB$45,15,0)) -> 100000 | E12: =VLOOKUP($A12,[6]HISTOAVRIL23!$A$6:$BB$45,8,0) -> BANQUE | F12: =VLOOKUP($A12,[6]HISTOAVRIL23!$A$6:$BB$45,37,0) -> 0 | G12: =VLOOKUP($A12,[6]HISTOAVRIL23!$A$6:$BB$45,40,0) -> 0 | H12: =IF(F12<>0,VLOOKUP($A12,[6]HISTOAVRIL23!$A$6:$BB$45,42,0),"ECHEC") -> ECHEC | I12: =VLOOKUP($A12,[6]HISTOAVRIL23!$A$6:$BB$45,41,0) -> 0 | J12: =TONTMARS23!F12+TONTMARS23!G12 -> 202000 | K12: =VLOOKUP($A12,[6]HISTOAVRIL23!$A$6:$BB$45,18,0) -> 202000 | L12: =IF(K12<>0,VLOOKUP($A12,[6]HISTOAVRIL23!$A$6:$BB$45,42,0),"ECHEC") -> BANQUE | M12: =IF(P12<>0,VLOOKUP($A12,[6]HISTOAVRIL23!$A$6:$BB$45,32,0),"ECHEC") -> ECHEC | N12: =VLOOKUP($A12,[6]HISTOAVRIL23!$A$6:$BB$45,33,0) -> 0 | O12: =IF(P12=0,0,($C$3-P12)) -> 0 | P12: =VLOOKUP($A12,[6]HISTOAVRIL23!$A$6:$BB$45,31,0) -> 0
A13: AS201622 | B13: =IF(D13=0,0,VLOOKUP($A13,[6]HISTOAVRIL23!$A$6:$BQ$45,14,0)) -> 2 | C13: =VLOOKUP(A13,[7]LISTADHERENT!A$5:H$60,3,0) -> NDJOMO ETIENNE | D13: =IF(E13="ECHEC",0,VLOOKUP($A13,[6]HISTOAVRIL23!$A$6:$BB$45,15,0)) -> 200000 | E13: =VLOOKUP($A13,[6]HISTOAVRIL23!$A$6:$BB$45,8,0) -> BANQUE | F13: =VLOOKUP($A13,[6]HISTOAVRIL23!$A$6:$BB$45,37,0) -> 0 | G13: =VLOOKUP($A13,[6]HISTOAVRIL23!$A$6:$BB$45,40,0) -> 0 | H13: =IF(F13<>0,VLOOKUP($A13,[6]HISTOAVRIL23!$A$6:$BB$45,42,0),"ECHEC") -> ECHEC | I13: =VLOOKUP($A13,[6]HISTOAVRIL23!$A$6:$BB$45,41,0) -> 0 | J13: =TONTMARS23!F13+TONTMARS23!G13 -> 202000 | K13: =VLOOKUP($A13,[6]HISTOAVRIL23!$A$6:$BB$45,18,0) -> 202000 | L13: =IF(K13<>0,VLOOKUP($A13,[6]HISTOAVRIL23!$A$6:$BB$45,42,0),"ECHEC") -> BANQUE | M13: =IF(P13<>0,VLOOKUP($A13,[6]HISTOAVRIL23!$A$6:$BB$45,32,0),"ECHEC") -> ECHEC | N13: =VLOOKUP($A13,[6]HISTOAVRIL23!$A$6:$BB$45,33,0) -> 0 | O13: =IF(P13=0,0,($C$3-P13)) -> 0 | P13: =VLOOKUP($A13,[6]HISTOAVRIL23!$A$6:$BB$45,31,0) -> 0
A14: AS201624 | B14: =IF(D14=0,0,VLOOKUP($A14,[6]HISTOAVRIL23!$A$6:$BQ$45,14,0)) -> 1 | C14: =VLOOKUP(A14,[7]LISTADHERENT!A$5:H$60,3,0) -> NGONDIEP CLAUDE | D14: =IF(E14="ECHEC",0,VLOOKUP($A14,[6]HISTOAVRIL23!$A$6:$BB$45,15,0)) -> 100000 | E14: =VLOOKUP($A14,[6]HISTOAVRIL23!$A$6:$BB$45,8,0) -> BANQUE | F14: =VLOOKUP($A14,[6]HISTOAVRIL23!$A$6:$BB$45,37,0) -> 0 | G14: =VLOOKUP($A14,[6]HISTOAVRIL23!$A$6:$BB$45,40,0) -> 0 | H14: =IF(F14<>0,VLOOKUP($A14,[6]HISTOAVRIL23!$A$6:$BB$45,42,0),"ECHEC") -> ECHEC | I14: =VLOOKUP($A14,[6]HISTOAVRIL23!$A$6:$BB$45,41,0) -> 0 | J14: =TONTMARS23!F14+TONTMARS23!G14 -> 0 | K14: =VLOOKUP($A14,[6]HISTOAVRIL23!$A$6:$BB$45,18,0) -> 0 | L14: =IF(K14<>0,VLOOKUP($A14,[6]HISTOAVRIL23!$A$6:$BB$45,42,0),"ECHEC") -> ECHEC | M14: =IF(P14<>0,VLOOKUP($A14,[6]HISTOAVRIL23!$A$6:$BB$45,32,0),"ECHEC") -> ECHEC | N14: =VLOOKUP($A14,[6]HISTOAVRIL23!$A$6:$BB$45,33,0) -> 0 | O14: =IF(P14=0,0,($C$3-P14)) -> 0 | P14: =VLOOKUP($A14,[6]HISTOAVRIL23!$A$6:$BB$45,31,0) -> 0
A15: AS201626 | B15: =IF(D15=0,0,VLOOKUP($A15,[6]HISTOAVRIL23!$A$6:$BQ$45,14,0)) -> 1 | C15: =VLOOKUP(A15,[7]LISTADHERENT!A$5:H$60,3,0) -> NGUIEMEGNI MATHIEU BLAISE | D15: =IF(E15="ECHEC",0,VLOOKUP($A15,[6]HISTOAVRIL23!$A$6:$BB$45,15,0)) -> 100000 | E15: =VLOOKUP($A15,[6]HISTOAVRIL23!$A$6:$BB$45,8,0) -> BANQUE | F15: =VLOOKUP($A15,[6]HISTOAVRIL23!$A$6:$BB$45,37,0) -> 93000 | G15: =VLOOKUP($A15,[6]HISTOAVRIL23!$A$6:$BB$45,40,0) -> 6000 | H15: =IF(F15<>0,VLOOKUP($A15,[6]HISTOAVRIL23!$A$6:$BB$45,42,0),"ECHEC") -> BANQUE | I15: =VLOOKUP($A15,[6]HISTOAVRIL23!$A$6:$BB$45,41,0) -> 0 | J15: =TONTMARS23!F15+TONTMARS23!G15 -> 0 | K15: =VLOOKUP($A15,[6]HISTOAVRIL23!$A$6:$BB$45,18,0) -> 0 | L15: =IF(K15<>0,VLOOKUP($A15,[6]HISTOAVRIL23!$A$6:$BB$45,42,0),"ECHEC") -> ECHEC | M15: =IF(P15<>0,VLOOKUP($A15,[6]HISTOAVRIL23!$A$6:$BB$45,32,0),"ECHEC") -> BANQUE | N15: =VLOOKUP($A15,[6]HISTOAVRIL23!$A$6:$BB$45,33,0) -> 0 | O15: =IF(P15=0,0,($C$3-P15)) -> 1180000 | P15: =VLOOKUP($A15,[6]HISTOAVRIL23!$A$6:$BB$45,31,0) -> 20000
A16: AS201638 | B16: =IF(D16=0,0,VLOOKUP($A16,[6]HISTOAVRIL23!$A$6:$BQ$45,14,0)) -> 1 | C16: =VLOOKUP(A16,[7]LISTADHERENT!A$5:H$60,3,0) -> SIMO PIERRE | D16: =IF(E16="ECHEC",0,VLOOKUP($A16,[6]HISTOAVRIL23!$A$6:$BB$45,15,0)) -> 100000 | E16: =VLOOKUP($A16,[6]HISTOAVRIL23!$A$6:$BB$45,8,0) -> BANQUE | F16: =VLOOKUP($A16,[6]HISTOAVRIL23!$A$6:$BB$45,37,0) -> 0 | G16: =VLOOKUP($A16,[6]HISTOAVRIL23!$A$6:$BB$45,40,0) -> 0 | H16: =IF(F16<>0,VLOOKUP($A16,[6]HISTOAVRIL23!$A$6:$BB$45,42,0),"ECHEC") -> ECHEC | I16: =VLOOKUP($A16,[6]HISTOAVRIL23!$A$6:$BB$45,41,0) -> 0 | J16: =TONTMARS23!F16+TONTMARS23!G16 -> 0 | K16: =VLOOKUP($A16,[6]HISTOAVRIL23!$A$6:$BB$45,18,0) -> 0 | L16: =IF(K16<>0,VLOOKUP($A16,[6]HISTOAVRIL23!$A$6:$BB$45,42,0),"ECHEC") -> ECHEC | M16: =IF(P16<>0,VLOOKUP($A16,[6]HISTOAVRIL23!$A$6:$BB$45,32,0),"ECHEC") -> ECHEC | N16: =VLOOKUP($A16,[6]HISTOAVRIL23!$A$6:$BB$45,33,0) -> 0 | O16: =IF(P16=0,0,($C$3-P16)) -> 0 | P16: =VLOOKUP($A16,[6]HISTOAVRIL23!$A$6:$BB$45,31,0) -> 0
A17: AS201647 | B17: =IF(D17=0,0,VLOOKUP($A17,[6]HISTOAVRIL23!$A$6:$BQ$45,14,0)) -> 1 | C17: =VLOOKUP(A17,[7]LISTADHERENT!A$5:H$60,3,0) -> YOUMBI EMMANUEL | D17: =IF(E17="ECHEC",0,VLOOKUP($A17,[6]HISTOAVRIL23!$A$6:$BB$45,15,0)) -> 100000 | E17: =VLOOKUP($A17,[6]HISTOAVRIL23!$A$6:$BB$45,8,0) -> BANQUE | F17: =VLOOKUP($A17,[6]HISTOAVRIL23!$A$6:$BB$45,37,0) -> 0 | G17: =VLOOKUP($A17,[6]HISTOAVRIL23!$A$6:$BB$45,40,0) -> 0 | H17: =IF(F17<>0,VLOOKUP($A17,[6]HISTOAVRIL23!$A$6:$BB$45,42,0),"ECHEC") -> ECHEC | I17: =VLOOKUP($A17,[6]HISTOAVRIL23!$A$6:$BB$45,41,0) -> 0 | J17: =TONTMARS23!F17+TONTMARS23!G17 -> 0 | K17: =VLOOKUP($A17,[6]HISTOAVRIL23!$A$6:$BB$45,18,0) -> 0 | L17: =IF(K17<>0,VLOOKUP($A17,[6]HISTOAVRIL23!$A$6:$BB$45,42,0),"ECHEC") -> ECHEC | M17: =IF(P17<>0,VLOOKUP($A17,[6]HISTOAVRIL23!$A$6:$BB$45,32,0),"ECHEC") -> ECHEC | N17: =VLOOKUP($A17,[6]HISTOAVRIL23!$A$6:$BB$45,33,0) -> 0 | O17: =IF(P17=0,0,($C$3-P17)) -> 0 | P17: =VLOOKUP($A17,[6]HISTOAVRIL23!$A$6:$BB$45,31,0) -> 0
A19: TOTAL PART | B19: =SUM(B6:B18) -> 14
A20: NBRE ADHERENT | B20: =+COUNT(D6:D18) -> 12 | D20: =SUM(D6:D18) -> 1400000 | F20: =SUM(F6:F18) -> 93000 | G20: =SUM(G6:G18) -> 6000 | I20: =SUM(I6:I18) -> 0 | J20: =SUM(J6:J18) -> 973000 | K20: =SUM(K6:K18) -> 973000 | N20: =SUM(N6:N18) -> 0 | O20: =SUM(O6:O18) -> 1180000 | P20: =SUM(P6:P18) -> 20000
M21: NBRE PART | N21: PART VENDUE
D22: MONTANT TONTINE | E22: REMBOURSEMENT PETIT LOT | F22: VENTE PETIT LOT | G22: VENTE LOT PRINCIPAL | H22: SOLDE EN CAISSE | K22: TONTINE + REMB + INTERET VENTE | L22: =D26+E26+P20+TONTMARS23!N27 -> 2493000
C23: ESPECES | D23: =SUMIFS(D6:D18,E6:E18,"ESPECES") -> 0 | E23: =SUMIFS(K6:K18,L6:L18,"ESPECES") -> 0 | F23: =SUMIFS(F6:F18,H6:H18,"ESPECES") -> 0 | G23: =SUMIFS(O6:O18,M6:M18,"ESPECES") -> 0 | H23: =D23+E23-F23-G23 -> 0 | K23: LOT PRINCIPAL | L23: =C3*COUNTIF(O6:O18,">0") -> 1200000 | M23: =D3 -> 2 | N23: =COUNTIF(O8:O17,">0") -> 1
C24: BANQUE | D24: =SUMIFS(D6:D18,E6:E18,"BANQUE") -> 1400000 | E24: =SUMIFS(K6:K18,L6:L18,"BANQUE") -> 973000 | F24: =SUMIFS(F6:F18,H6:H18,"BANQUE") -> 93000 | G24: =SUMIFS(O6:O18,M6:M18,"BANQUE") -> 1180000 | H24: =D24+E24-F24-G24 -> 1100000
K25: PETIT LOT | L25: =L22-L23 -> 1293000
C26: TOTAL | D26: =D23+D24 -> 1400000 | E26: =E23+E24 -> 973000 | F26: =F23+F24 -> 93000 | G26: =G23+G24 -> 1180000 | H26: =H23+H24 -> 1100000
K27: RELIQUAT | L27: =L25-F20 -> 1200000 | N27: =TONTAVRIL23!L27 -> 1200000 | O27: CUMUL
K29: ECHEC TONTINE MOIS | L29: =COUNTIFS(E6:E24,"ECHEC")*100000 -> 0 | N29: =TONTMARS23!N29+TONTAVRIL23!L29 -> 0 | O29: CUMUL
K30: ECHEC REMBOURSEMENT MOIS | L30: =J20-E26 -> 0 | N30: =TONTMARS23!N30+TONTAVRIL23!L30 -> 0 | O30: CUMUL

Sheet TONTMAI23
A1: ASSOCIATION | B1: ASELBY
A2: ANNEE | B2: 2023 | C2: TONIINE | D2: NBRE PART
A3: TAUX TONTINE | B3: 100000 | C3: =B3*12 -> 1200000 | D3: =ROUNDDOWN(L22/C3,0) -> 2
C4: 45059
A5: MATRICULE | B5: NBREPART | C5: NOM ET PRENOM | D5: MONTANT TONTINE | E5: MODE VERSEMENT | F5: VENTE PETIT LOT | G5: INTERET PETIT LOT | H5: MODE VERSEMENT VENTE PETIT LOT | I5: NUMERO CHEQUE | J5: MONTANT A REMBOURSER PETIT LOT | K5: REMBOURSEMENT PETIT LOT | L5: MODE VERSEMENT REMBOURSEMENT | M5: MODE VERSEMENTLOT PRINCIPAL | N5: NUMERO CHEQUE | O5: MONTANT LOT PRINCIPAL | P5: INTERET LOT PRINCIPAL
A6: AS201648 | B6: =IF(D6=0,0,VLOOKUP($A6,[6]HISTOMAI23!$A$6:$BQ$45,14,0)) -> 1 | C6: =VLOOKUP(A6,[7]LISTADHERENT!A$5:H$60,3,0) -> ASELBY | D6: =IF(E6="ECHEC",0,VLOOKUP($A6,[6]HISTOMAI23!$A$6:$BB$45,15,0)) -> 100000 | E6: =VLOOKUP($A6,[6]HISTOMAI23!$A$6:$BB$45,8,0) -> BANQUE | F6: =VLOOKUP($A6,[6]HISTOMAI23!$A$6:$BB$45,37,0) -> 0 | G6: =VLOOKUP($A6,[6]HISTOMAI23!$A$6:$BB$45,40,0) -> 0 | H6: =IF(F6<>0,VLOOKUP($A6,[6]HISTOMAI23!$A$6:$BB$45,42,0),"ECHEC") -> ECHEC | I6: =VLOOKUP($A6,[6]HISTOMAI23!$A$6:$BB$45,41,0) -> 0 | J6: =TONTAVRIL23!F6+TONTAVRIL23!G6 -> 0 | K6: =VLOOKUP($A6,[6]HISTOMAI23!$A$6:$BB$45,18,0) -> 0 | L6: =IF(K6<>0,VLOOKUP($A6,[6]HISTOMAI23!$A$6:$BB$45,42,0),"ECHEC") -> ECHEC | M6: =IF(P6<>0,VLOOKUP($A6,[6]HISTOMAI23!$A$6:$BB$45,32,0),"ECHEC") -> ECHEC | N6: =VLOOKUP($A6,[6]HISTOMAI23!$A$6:$BB$45,33,0) -> 0 | O6: =IF(P6=0,0,($C$3-P6)) -> 0 | P6: =VLOOKUP($A6,[6]HISTOMAI23!$A$6:$BB$45,31,0) -> 0
A7: AS201604 | B7: =IF(D7=0,0,VLOOKUP($A7,[6]HISTOMAI23!$A$6:$BQ$45,14,0)) -> 1 | C7: =VLOOKUP(A7,[7]LISTADHERENT!A$5:H$60,3,0) -> DJOMO JEAN PAUL | D7: =IF(E7="ECHEC",0,VLOOKUP($A7,[6]HISTOMAI23!$A$6:$BB$45,15,0)) -> 100000 | E7: =VLOOKUP($A7,[6]HISTOMAI23!$A$6:$BB$45,8,0) -> BANQUE | F7: =VLOOKUP($A7,[6]HISTOMAI23!$A$6:$BB$45,37,0) -> 50000 | G7: =VLOOKUP($A7,[6]HISTOMAI23!$A$6:$BB$45,40,0) -> 1000 | H7: =IF(F7<>0,VLOOKUP($A7,[6]HISTOMAI23!$A$6:$BB$45,42,0),"ECHEC") -> BANQUE | I7: =VLOOKUP($A7,[6]HISTOMAI23!$A$6:$BB$45,41,0) -> 0 | J7: =TONTAVRIL23!F7+TONTAVRIL23!G7 -> 0 | K7: =VLOOKUP($A7,[6]HISTOMAI23!$A$6:$BB$45,18,0) -> 0 | L7: =IF(K7<>0,VLOOKUP($A7,[6]HISTOMAI23!$A$6:$BB$45,42,0),"ECHEC") -> ECHEC | M7: =IF(P7<>0,VLOOKUP($A7,[6]HISTOMAI23!$A$6:$BB$45,32,0),"ECHEC") -> ECHEC | N7: =VLOOKUP($A7,[6]HISTOMAI23!$A$6:$BB$45,33,0) -> 0 | O7: =IF(P7=0,0,($C$3-P7)) -> 0 | P7: =VLOOKUP($A7,[6]HISTOMAI23!$A$6:$BB$45,31,0) -> 0
