Workbook
Name BANQUE: #REF!
Name BANQUE: #REF!
Name BANQUE: #REF!
Name BANQUE: #REF!
Name BANQUE: #REF!
Name BANQUE: #REF!
Name BANQUE: #REF!
Name BANQUE: #REF!
Name BANQUE: #REF!
Name BANQUE: #REF!
Name BANQUE: #REF!
Name BANQUE: #REF!
Name BANQUE: #REF!
Name BANQUE: #REF!
Name BANQUE: #REF!
Name BANQUE: #REF!
Name BANQUE: #REF!
Name MODEPAID: [1]Feuil2!$A$1:$A$3
Name MODET25000: [2]MODEVERSEMENT!$A$1:$A$3
Name MODEVERSEMENT: #REF!
Name MODEVERSEMENT: #REF!
Name MODEVERSEMENT: #REF!
Name MODEVERSEMENT: #REF!
Name MODEVERSEMENT: #REF!
Name MODEVERSEMENT: #REF!
Name MODEVERSEMENT: #REF!
Name MODEVERSEMENT: #REF!
Name MODEVERSEMENT: #REF!
Name MODEVERSEMENT: #REF!
Name MODEVERSEMENT: #REF!
Name MODEVERSEMENT: #REF!
Name MODEVERSEMENT: #REF!
Name MODEVERSEMENT: #REF!
Name MODEVERSEMENT: #REF!
Name MODEVERSEMENT: #REF!
Name MODEVERSEMENT: #REF!
Name MODEVERSEMENTS: [3]MODEVERSEMENT!$A$1:$A$3
Name MODEVERSEMENTS: MODEVERSEMENT!$A$1:$A$3
Name VALMODEPAID: [4]MODEPAID!$A$1:$A$3

Sheet MODEVERSEMENT
A1: Taux
A2: Montant

Sheet HISTOMVTDEPENSE
A1: TCHUIDJASSI | B1: Observation
A2: RECONSTITUTION | B2: 2022
A3: 1 | B3: 2 | D3: 3 | E3: 4 | F3: 5 | G3: 6 | H3: 7 | I3: 8 | J3: 9 | K3: 10 | L3: 11 | M3: 12 | N3: 13 | O3: 14 | P3: 15 | Q3: 16 | R3: 17 | S3: 18
B4: PRÊT ASSURANCE
A5: DIBONJI | B5: MONTANT | D5: LIBELLES | M5: Taxi Trésorier | P5: Frais de taxi pour comité spéciale bureau | R5: F. AIDE | T5: A- RECAPITULATIF DES ENTREES
C6: AGIOS BANCAIRE | D6: OBSERVATIONS | E6: Frais Communication SG | F6: Frais Communication CC | G6: EpargneAssurance Déces | H6: Frais Communication Trésorier | I6: Frais Communication SGA | J6: Taxi Président | K6: Commissions diverses | L6: Banque et commissions diverses | M6: Achats Envelloppes | N6: Pour interet tontine | O6: EMOLUMENTS DES MEMBRES DU BUREAU | P6: Frais de taxi pour comité spéciale bureau | Q6: Confection rapport Annuel | R6: WASO Georges | S6: NDEFO PP
A7: Taux 100 KF | B7: =VLOOKUP(A7,[5]LISTADHERENT!A$5:H$60,3,0) -> ASELBY | T7: =SUM(D7:S7) -> 0
A8: Mai | B8: =VLOOKUP(A8,[5]LISTADHERENT!A$5:H$60,3,0) -> BOUTCHOUANG WILLIAM | T8: =SUM(D8:S8) -> 0
A9: NOMS | B9: =VLOOKUP(A9,[5]LISTADHERENT!A$5:H$60,3,0) -> DJOMO JEAN PAUL | T9: =SUM(D9:S9) -> 0
A10: JUIN | B10: =VLOOKUP(A10,[5]LISTADHERENT!A$5:H$60,3,0) -> DJOMOU TCHANDA | T10: =SUM(D10:S10) -> 0
A11: JUILLET | B11: =VLOOKUP(A11,[5]LISTADHERENT!A$5:H$60,3,0) -> DJOUKWE NANGUEN GUY BLAISE | T11: =SUM(D11:S11) -> 0
A12: AOUT | B12: =VLOOKUP(A12,[5]LISTADHERENT!A$5:H$60,3,0) -> DJUOMBESSY ANTOINE | T12: =SUM(D12:S12) -> 0
A13: KAMNO | B13: =VLOOKUP(A13,[5]LISTADHERENT!A$5:H$60,3,0) -> DOMOU FABIEN | T13: =SUM(D13:S13) -> 0
A14: NJIKI AZARIA | B14: =VLOOKUP(A14,[5]LISTADHERENT!A$5:H$60,3,0) -> DONHOU DAVID | T14: =SUM(D14:S14) -> 0
A15: Evénement | B15: =VLOOKUP(A15,[5]LISTADHERENT!A$5:H$60,3,0) -> FOTSO THOMAS | T15: =SUM(D15:S15) -> 0
A16: TOTAL | B16: =VLOOKUP(A16,[5]LISTADHERENT!A$5:H$60,3,0) -> HENGUE PAUL OMER | T16: =SUM(D16:S16) -> 0
A17: SOKAMTE | B17: =VLOOKUP(A17,[5]LISTADHERENT!A$5:H$60,3,0) -> HOTCHO BENJAMIN | T17: =SUM(D17:S17) -> 0
A18: N° | B18: =VLOOKUP(A18,[5]LISTADHERENT!A$5:H$60,3,0) -> KOUAMOU MOISE | T18: =SUM(D18:S18) -> 0
... A37: Compte Principal | B37: =VLOOKUP(A37,[5]LISTADHERENT!A$5:H$60,3,0) -> YOUMBI EMMANUEL | T37: =SUM(D37:S37) -> 0
B39: A- RECAPITULATIF DES ENTREES | C39: =SUM(C8:C38) -> 0 | D39: =SUM(D8:D38) -> 0 | E39: =SUM(E8:E38) -> 0 | F39: =SUM(F8:F38) -> 0 | G39: =SUM(G8:G38) -> 0 | H39: =SUM(H8:H38) -> 0 | J39: =SUM(J8:J38) -> 0 | K39: =SUM(K8:K38) -> 0 | L39: =SUM(L8:L38) -> 0 | M39: =SUM(M8:M38) -> 0 | N39: =SUM(N8:N38) -> 0 | O39: =SUM(O8:O38) -> 0 | P39: =SUM(P8:P38) -> 0 | Q39: =SUM(Q8:Q38) -> 0 | ... T39: =SUM(T8:T38) -> 0

Sheet COMPTE BANQUE
C1: SAPE MAURICE | H1: Taux 150 KF
A2: RECONSTITUTION | C2: 2022 | H2: 2022
A4: TCHIO ANDRE | B4: TCHOUTIO LEOPOLD | C4: TCHUIDJASSI MANFRED | D4: DIBONJI PAUL | E4: EWOUDOU EDITH | G4: Interet / Membre | H4: DIBONJI PAUL | I4: DONSTOP CATHERINE | J4: EWOUDOU EDITH
A5: TCHUENTE PHILOTEE | E5: =14283661-6017000 -> 8266661
A6: TENKAM NICOLAS | C6: =#REF!+HISTOMVTDEPENSE!T39 -> #REF! | D6: =#REF! -> #REF! | E6: =IF(D6=0,0,E5+D6-C6) -> #REF!
A7: TOMFEU JEAN PIERRE | C7: =#REF! -> #REF! | D7: =#REF! -> #REF! | E7: =IF(D7=0,0,E6+D7-C7) -> #REF!
A8: TSEMEU JOEL | C8: =#REF! -> #REF! | D8: =#REF! -> #REF! | E8: =IF(D8=0,0,E7+D8-C8) -> #REF!
A9: WETOUMDU ERNEST | C9: =#REF! -> #REF! | D9: =#REF! -> #REF! | E9: =IF(D9=0,0,E8+D9-C9) -> #REF!
A10: WATA BLAISE | C10: =#REF! -> #REF! | D10: =#REF! -> #REF! | E10: =IF(D10=0,0,E9+D10-C10) -> #REF!
A11: NANA RAYMOND | C11: =#REF! -> #REF! | D11: =#REF! -> #REF! | E11: =IF(D11=0,0,E10+D11-C11) -> #REF!
A12: NGANDIMOUN IDRISSOU | C12: =#REF! -> #REF! | D12: =#REF! -> #REF! | E12: =IF(D12=0,0,E11+D12-C12) -> #REF!
A13: NOVEMBRE | C13: =#REF! -> #REF! | D13: =#REF! -> #REF! | E13: =IF(D13=0,0,E12+D13-C13) -> #REF!
A14: Total Parts | C14: =#REF! -> #REF! | D14: =#REF! -> #REF! | E14: =IF(D14=0,0,E13+D14-C14) -> #REF!
A15: 5% Arouest | C15: =#REF! -> #REF! | D15: =#REF! -> #REF! | E15: =IF(D15=0,0,E14+D15-C15) -> #REF!
A16: 12% Bureau | C16: =#REF! -> #REF! | D16: =#REF! -> #REF! | E16: =IF(D16=0,0,E15+D16-C16) -> #REF!
A17: Montant A distribuer | C17: =#REF! -> #REF! | D17: =#REF! -> #REF! | E17: =IF(D17=0,0,E16+D17-C17) -> #REF!
A19: Nbre Part

Sheet HISTODEC21

Sheet HISTOJANV23
A1: TCHUIDJASSI | B1: Observation
A2: RECONSTITUTION | B2: 2024
A3: 1 | B3: 2 | C3: 3 | D3: 4 | E3: 5 | F3: 6 | G3: 7 | H3: 8 | I3: 9 | J3: 10 | K3: 11 | L3: 12 | M3: 13 | N3: 14 | O3: 15 | P3: 16 | Q3: 17 | R3: 18 | S3: 19 | T3: 20 | U3: 21 | V3: 22 | W3: 23 | X3: 24 | Y3: 25 | Z3: 26 | AA3: 27 | AB3: 28 | AC3: 29 | AD3: 30 | AE3: 31 | AF3: 32 | AG3: 33 | AH3: 34 | AI3: 35 | AJ3: 36 | AK3: 37 | AL3: 38 | AM3: 39 | AN3: 40 | AO3: 41 | AP3: 42 | AQ3: 43 | AR3: 44 | AS3: 45 | AT3: 46 | AU3: 47 | AV3: 48 | AW3: 49 | AX3: 50 | AY3: 51 | AZ3: 52 | BA3: 53 | BB3: 54 | BC3: 55 | BD3: 56 | BE3: 57 | BF3: 58 | BG3: 59 | BH3: 60 | BI3: 61 | BJ3: 62 | BK3: 63 | BL3: 64 | BM3: 65 | BN3: 66 | BO3: 67 | BP3: 68
B4: TOTAL AGIOS BANQUE
A5: DIBONJI | B5: MONTANT | C5: CONSTRUCTION | D5: NOMS ET PRENOMS | E5: INTERET /PART | F5: Date versement | G5: Contribution Retraite | H5: ASSURANCE | I5: SOH HENRI | J5: TONTINES | K5: REPARTITION DU SOLDE THEORIQUE EN CAISSE | L5: TONTINES | M5: JANVIER | N5: TONTINES | O5: FEVRIER | P5: aide mariage cheizing | Q5: AVRIL | R5: MARS | S5: NDEFO PIERRE PAUL | T5: NDANGA MATHIEU | U5: NGOUNOU MICHEL | V5: DJUOMBESSY | W5: INSCRIPTION | X5: TCHUENTE INGRID | Y5: MEGAPTCHE | Z5: F. FIXE | AA5: KAMGA JOSEPH | AB5: Ancienneté supérieur à 10 ans et membre de bureau | AC5: PAYEMENT ASSURANCE / EPARGNE | AD5: Compte secondaire | AE5: TCHI ROBERT | AF5: ACHAT TERRAIN | AG5: Ancienneté supérieur à 10 ans et membre de bureau | AH5: Contribution Retraite | AI5: Délégation (fumba et takougoum) | AJ5: REPAS | AK5: SANCTIONS | AL5: NGOUNOU | AM5: PRETS ASS NON REMBOURSES | AN5: Autres dettes | AO5: Ancienneté supérieur à 10 ans et membre de bureau | AP5: KOLOKO | AQ5: NDANGA | AR5: FOUTE | AS5: TCHUENTE LEOPOLD | AT5: F. AIDE | AU5: RECAPITULATIF DES AVOIRS EPARGNE ASSURANCE | AV5: NGATAT JEAN MARIE | AW5: MONTANT INITIAL PAYE | AX5: MONKAM VINCENT | AY5: KANKEU CHRETIEN | AZ5: MGBORON ISSIAKA | BA5: NOMBO SAKIO | BB5: Taux 50 KF | BC5: Interet Epargne Assurance Deces | BD5: Versement Fond Aide Nouveau membre | BE5: TCHOUTIO LEOPOLD | BF5: Fond Fixe Arouest Issue Tontines Arouest | BG5: Repartition des Entrées | BH5: Agios Bancaire | BI5: Répartition des Sorties | BJ5: Payement des Primes Fixe au Membre Arouest | BK5: TOTAL DES SORTIES | BL5: FOND AROUEST | BM5: SITUATION DE CAISSE DE AROUEST | BN5: BELL MARTINE | BO5: Frais de Fonctionnement Annuel Arouest | BP5: MASSE MONETAIRE
A6: Taux 100 KF | B6: =VLOOKUP(A6,[11]LISTADHERENT!A$5:H$50,3,0) -> ASELBY | C6: =D6+E6+F6-U6-BB6 -> 0 | D6: =VLOOKUP(A6,[12]HISTOBQUEJANV24!$A$6:$G$46,3,0) -> 175000 | E6: =VLOOKUP(A6,[12]HISTOBQUEJANV24!$A$6:$G$41,4,0) -> 0 | F6: =VLOOKUP(A6,[12]HISTOBQUEJANV24!$A$6:$G$41,5,0) -> 0 | G6: =IF(H6="ESPECES",3000,0) -> 0 | H6: =IF($D6<>0,"BANQUE",IF($E6<>0,"ESPECES","ECHEC")) -> BANQUE | K6: =IF($D6<>0,J6*50000,IF($E6<>0,J6*50000,0)) -> 0 | L6: 1 | M6: =IF($D6<>0,L6*75000,IF($E6<>0,L6*75000,0)) -> 75000 | N6: 1 | O6: =IF($D6<>0,N6*100000,IF($E6<>0,N6*100000,0)) -> 100000 | U6: =G6+S6++R6+P6+O6+M6+I6+K6+Q6+V6+W6 -> 175000 | AQ6: =IF(H6="ECHEC",((K6+M6+O6)*20/100),0) -> 0 | AR6: =IF(H6="ECHEC",((K6+M6+O6)*20/100),0) -> 0 | AW6: =IF(AC6=0,AI6,(1*25000*12)+AI6-AC6) -> 0 | AX6: =IF(AD6=0,AJ6,(1*75000*12)+(AJ6)-AD6) -> 0 | AY6: =IF(AE6=0,AK6,(1*100000*12)+(AK6)-AE6) -> 0 | AZ6: =SUM(AV6:AY6)-BF6+Z6-F6+BH6+BI6+BJ6+BK6+BL6+BM6 -> 627000 | BA6: 27000 | BD6: =IF(AZ6=0,(AZ6-BA6-BC6),(AZ6-BA6-BB6-BC6)) -> 600000 | BF6: =Z6*1/100*BG6 -> 0 | BG6: 11 | BH6: =BP16 -> 27000 | BI6: =BP28 -> 500000 | BJ6: =BP33 -> 0 | BK6: =+BP40 -> 100000 | BM6: =BP22 -> 0 | BN6: OBSERVATIONS | BO6: LIBELLES | BP6: 8500
A7: RUBRIQUE AIDE | B7: =VLOOKUP(A7,[11]LISTADHERENT!A$5:H$50,3,0) -> BAKOP ACHILLE | C7: =D7+E7+F7-U7-BB7 -> 6000 | D7: =VLOOKUP(A7,[12]HISTOBQUEJANV24!$A$6:$G$46,3,0) -> 56000 | E7: =VLOOKUP(A7,[12]HISTOBQUEJANV24!$A$6:$G$41,4,0) -> 0 | F7: =VLOOKUP(A7,[12]HISTOBQUEJANV24!$A$6:$G$41,5,0) -> 0 | G7: =IF(H7="ESPECES",3000,0) -> 0 | H7: =IF($D7<>0,"BANQUE",IF($E7<>0,"ESPECES","ECHEC")) -> BANQUE | J7: 1 | K7: =IF($D7<>0,J7*50000,IF($E7<>0,J7*50000,0)) -> 50000 | M7: =IF($D7<>0,L7*75000,IF($E7<>0,L7*75000,0)) -> 0 | O7: =IF($D7<>0,N7*100000,IF($E7<>0,N7*100000,0)) -> 0 | U7: =G7+S7++R7+P7+O7+M7+I7+K7+Q7+V7+W7 -> 50000 | AQ7: =IF(H7="ECHEC",((K7+M7+O7)*20/100),0) -> 0 | AR7: =IF(H7="ECHEC",((K7+M7+O7)*20/100),0) -> 0 | AS7: =IF(H7="ECHEC",0,(K7+I7-25000)) -> 25000 | AW7: =IF(AC7=0,AI7,(1*25000*12)+AI7-AC7) -> 0 | AX7: =IF(AD7=0,AJ7,(1*75000*12)+(AJ7)-AD7) -> 0 | AY7: =IF(AE7=0,AK7,(1*100000*12)+(AK7)-AE7) -> 0 | AZ7: =SUM(AV7:AY7)-BF7+Z7-F7+BH7+BI7+BJ7+BK7+BL7+BM7+6000 -> 0 | BD7: =IF(AZ7=0,(AZ7-BA7-BC7),(AZ7-BA7-BB7-BC7))+F7 -> 0 | BF7: =Z7*1/100*BG7+6000 -> 6000 | BG7: 11 | BN7: Frais Communication SG | BO7: LIBELLES
A8: Mai | B8: =VLOOKUP(A8,[11]LISTADHERENT!A$5:H$50,3,0) -> BOUTCHOUANG WILLIAM | C8: =D8+E8+F8-U8-BB8 -> 0 | D8: =VLOOKUP(A8,[12]HISTOBQUEJANV24!$A$6:$G$46,3,0) -> 125000 | E8: =VLOOKUP(A8,[12]HISTOBQUEJANV24!$A$6:$G$41,4,0) -> 0 | F8: =VLOOKUP(A8,[12]HISTOBQUEJANV24!$A$6:$G$41,5,0) -> 0 | G8: =IF(H8="ESPECES",3000,0) -> 0 | H8: =IF($D8<>0,"BANQUE",IF($E8<>0,"ESPECES","ECHEC")) -> BANQUE | J8: 1 | K8: =IF($D8<>0,J8*50000,IF($E8<>0,J8*50000,0)) -> 50000 | L8: 1 | M8: =IF($D8<>0,L8*75000,IF($E8<>0,L8*75000,0)) -> 75000 | O8: =IF($D8<>0,N8*100000,IF($E8<>0,N8*100000,0)) -> 0 | Q8: =VLOOKUP(A8,[13]TONTJANV23!$A$7:$P$20,10,0) -> 0 | U8: =G8+S8++R8+P8+O8+M8+I8+K8+Q8+V8+W8 -> 125000 | AQ8: =IF(H8="ECHEC",((K8+M8+O8)*20/100),0) -> 0 | AR8: =IF(H8="ECHEC",((K8+M8+O8)*20/100),0) -> 0 | AS8: =IF(H8="ECHEC",0,(K8+I8-25000)) -> 25000 | AW8: =IF(AC8=0,AI8,(1*25000*12)+AI8-AC8) -> 0 | AX8: =IF(AD8=0,AJ8,(1*75000*12)+(AJ8)-AD8) -> 0 | AY8: =IF(AE8=0,AK8,(1*100000*12)+(AK8)-AE8) -> 0 | AZ8: =SUM(AV8:AY8)-BF8+Z8-F8+BH8+BI8+BJ8+BK8+BL8+BM8 -> 0 | BD8: =IF(AZ8=0,(AZ8-BA8-BC8),(AZ8-BA8-BB8-BC8))+F8 -> 0 | BF8: =Z8*1/100*BG8 -> 0 | BG8: 11 | BN8: Frais Communication CC | BO8: LIBELLES
A9: NOMS | B9: =VLOOKUP(A9,[11]LISTADHERENT!A$5:H$50,3,0) -> DJOMO JEAN PAUL | C9: =D9+E9+F9-U9-BB9 -> 0 | D9: =VLOOKUP(A9,[12]HISTOBQUEJANV24!$A$6:$G$46,3,0) -> 250000 | E9: =VLOOKUP(A9,[12]HISTOBQUEJANV24!$A$6:$G$41,4,0) -> 0 | F9: =VLOOKUP(A9,[12]HISTOBQUEJANV24!$A$6:$G$41,5,0) -> 0 | G9: =IF(H9="ESPECES",3000,0) -> 0 | H9: =IF($D9<>0,"BANQUE",IF($E9<>0,"ESPECES","ECHEC")) -> BANQUE | J9: 1 | K9: =IF($D9<>0,J9*50000,IF($E9<>0,J9*50000,0)) -> 50000 | M9: =IF($D9<>0,L9*75000,IF($E9<>0,L9*75000,0)) -> 0 | N9: 2 | O9: =IF($D9<>0,N9*100000,IF($E9<>0,N9*100000,0)) -> 200000 | U9: =G9+S9++R9+P9+O9+M9+I9+K9+Q9+V9+W9 -> 250000 | AE9: 115000 | AF9: Taux | AQ9: =IF(H9="ECHEC",((K9+M9+O9)*20/100),0) -> 0 | AR9: =IF(H9="ECHEC",((K9+M9+O9)*20/100),0) -> 0 | AS9: =IF(H9="ECHEC",0,(K9+I9-25000)) -> 25000 | AW9: =IF(AC9=0,AI9,(1*25000*12)+AI9-AC9) -> 0 | AX9: =IF(AD9=0,AJ9,(1*75000*12)+(AJ9)-AD9) -> 0 | AY9: =IF(AE9=0,AK9,(1*100000*12)+(AK9)-AE9) -> 1085000 | AZ9: =SUM(AV9:AY9)-BF9+Z9-F9+BH9+BI9+BJ9+BK9+BL9+BM9 -> 1085000 | BA9: 500000 | BD9: =IF(AZ9=0,(AZ9-BA9-BC9),(AZ9-BA9-BB9-BC9))+F9 -> 585000 | BF9: =Z9*1/100*BG9 -> 0 | BG9: 11 | BN9: TONGA | BO9: LIBELLES | BP9: 18500
A10: JUIN | B10: =VLOOKUP(A10,[11]LISTADHERENT!A$5:H$50,3,0) -> DJOMOU TCHAPDA | C10: =D10+E10+F10-U10-BB10 -> 0 | D10: =VLOOKUP(A10,[12]HISTOBQUEJANV24!$A$6:$G$46,3,0) -> 125000 | E10: =VLOOKUP(A10,[12]HISTOBQUEJANV24!$A$6:$G$41,4,0) -> 0 | F10: =VLOOKUP(A10,[12]HISTOBQUEJANV24!$A$6:$G$41,5,0) -> 0 | G10: =IF(H10="ESPECES",3000,0) -> 0 | H10: =IF($D10<>0,"BANQUE",IF($E10<>0,"ESPECES","ECHEC")) -> BANQUE | J10: 1 | K10: =IF($D10<>0,J10*50000,IF($E10<>0,J10*50000,0)) -> 50000 | L10: 1 | M10: =IF($D10<>0,L10*75000,IF($E10<>0,L10*75000,0)) -> 75000 | O10: =IF($D10<>0,N10*100000,IF($E10<>0,N10*100000,0)) -> 0 | U10: =G10+S10++R10+P10+O10+M10+I10+K10+Q10+V10+W10 -> 125000 | AJ10: =50000+50000 -> 100000 | AM10: 2000 | AQ10: =IF(H10="ECHEC",((K10+M10+O10)*20/100),0) -> 0 | AR10: =IF(H10="ECHEC",((K10+M10+O10)*20/100),0) -> 0 | AS10: =IF(H10="ECHEC",0,(K10+I10-25000)) -> 25000 | AW10: =IF(AC10=0,AI10,(1*25000*12)+AI10-AC10) -> 0 | AX10: =IF(AD10=0,AJ10,(1*75000*12)+(AJ10)-AD10) -> 100000 | AY10: =IF(AE10=0,AK10,(1*100000*12)+(AK10)-AE10) -> 0 | AZ10: =SUM(AV10:AY10)-BF10+Z10-F10+BH10+BI10+BJ10+BK10+BL10+BM10 -> 100000 | BD10: =IF(AZ10=0,(AZ10-BA10-BC10),(AZ10-BA10-BB10-BC10))+F10 -> 100000 | BF10: =Z10*1/100*BG10 -> 0 | BG10: 11 | BN10: Frais Communication Trésorier | BO10: LIBELLES
A11: JUILLET | B11: =VLOOKUP(A11,[11]LISTADHERENT!A$5:H$50,3,0) -> DJOUKWE NANGUEN GUY BLAISE | C11: =D11+E11+F11-U11-BB11 -> 0 | D11: =VLOOKUP(A11,[12]HISTOBQUEJANV24!$A$6:$G$46,3,0) -> 125000 | E11: =VLOOKUP(A11,[12]HISTOBQUEJANV24!$A$6:$G$41,4,0) -> 0 | F11: =VLOOKUP(A11,[12]HISTOBQUEJANV24!$A$6:$G$41,5,0) -> 0 | G11: =IF(H11="ESPECES",3000,0) -> 0 | H11: =IF($D11<>0,"BANQUE",IF($E11<>0,"ESPECES","ECHEC")) -> BANQUE | J11: 1 | K11: =IF($D11<>0,J11*50000,IF($E11<>0,J11*50000,0)) -> 50000 | L11: 1 | M11: =IF($D11<>0,L11*75000,IF($E11<>0,L11*75000,0)) -> 75000 | O11: =IF($D11<>0,N11*100000,IF($E11<>0,N11*100000,0)) -> 0 | Q11: =VLOOKUP(A11,[13]TONTJANV23!$A$7:$P$20,10,0) -> 0 | U11: =G11+S11++R11+P11+O11+M11+I11+K11+Q11+V11+W11 -> 125000 | AJ11: =50000+50000 -> 100000 | AM11: 2000 | AQ11: =IF(H11="ECHEC",((K11+M11+O11)*20/100),0) -> 0 | AR11: =IF(H11="ECHEC",((K11+M11+O11)*20/100),0) -> 0 | AS11: =IF(H11="ECHEC",0,(K11+I11-25000)) -> 25000 | AW11: =IF(AC11=0,AI11,(1*25000*12)+AI11-AC11) -> 0 | AX11: =IF(AD11=0,AJ11,(1*75000*12)+(AJ11)-AD11) -> 100000 | AY11: =IF(AE11=0,AK11,(1*100000*12)+(AK11)-AE11) -> 0 | AZ11: =SUM(AV11:AY11)-BF11+Z11-F11+BH11+BI11+BJ11+BK11+BL11+BM11 -> 100000 | BA11: 100000 | BD11: =IF(AZ11=0,(AZ11-BA11-BC11),(AZ11-BA11-BB11-BC11))+F11 -> 0 | BF11: =Z11*1/100*BG11 -> 0 | BG11: 11 | BN11: Frais Communication SGA | BO11: LIBELLES
A12: AOUT | B12: =VLOOKUP(A12,[11]LISTADHERENT!A$5:H$50,3,0) -> DJUOMBESSY ANTOINE | C12: =D12+E12+F12-U12-BB12 -> 0 | D12: =VLOOKUP(A12,[12]HISTOBQUEJANV24!$A$6:$G$46,3,0) -> 330000 | E12: =VLOOKUP(A12,[12]HISTOBQUEJANV24!$A$6:$G$41,4,0) -> 0 | F12: =VLOOKUP(A12,[12]HISTOBQUEJANV24!$A$6:$G$41,5,0) -> 0 | G12: =IF(H12="ESPECES",3000,0) -> 0 | H12: =IF($D12<>0,"BANQUE",IF($E12<>0,"ESPECES","ECHEC")) -> BANQUE | I12: 5000 | J12: 1 | K12: =IF($D12<>0,J12*50000,IF($E12<>0,J12*50000,0)) -> 50000 | L12: 1 | M12: =IF($D12<>0,L12*75000,IF($E12<>0,L12*75000,0)) -> 75000 | N12: 2 | O12: =IF($D12<>0,N12*100000,IF($E12<>0,N12*100000,0)) -> 200000 | Q12: =VLOOKUP(A12,[13]TONTJANV23!$A$7:$P$20,10,0) -> 0 | U12: =G12+S12++R12+P12+O12+M12+I12+K12+Q12+V12+W12 -> 330000 | AD12: 60000 | AF12: Taux | AQ12: =IF(H12="ECHEC",((K12+M12+O12)*20/100),0) -> 0 | AR12: =IF(H12="ECHEC",((K12+M12+O12)*20/100),0) -> 0 | AS12: =IF(H12="ECHEC",0,(K12+I12-25000)) -> 30000 | AW12: =IF(AC12=0,AI12,(1*25000*12)+AI12-AC12) -> 0 | AX12: =IF(AD12=0,AJ12,(1*75000*12)+(AJ12)-AD12) -> 840000 | AY12: =IF(AE12=0,AK12,(1*100000*12)+(AK12)-AE12) -> 0 | AZ12: =SUM(AV12:AY12)-BF12+Z12-F12+BH12+BI12+BJ12+BK12+BL12+BM12 -> 840000 | BD12: =IF(AZ12=0,(AZ12-BA12-BC12),(AZ12-BA12-BB12-BC12))+F12 -> 840000 | BF12: =Z12*1/100*BG12 -> 0 | BG12: 11 | BN12: Taxi Président | BO12: LIBELLES
A13: KAMNO | B13: =VLOOKUP(A13,[11]LISTADHERENT!A$5:H$50,3,0) -> DOMOU FABIEN | C13: =D13+E13+F13-U13-BB13 -> 0 | D13: =VLOOKUP(A13,[12]HISTOBQUEJANV24!$A$6:$G$46,3,0) -> 50000 | E13: =VLOOKUP(A13,[12]HISTOBQUEJANV24!$A$6:$G$41,4,0) -> 0 | F13: =VLOOKUP(A13,[12]HISTOBQUEJANV24!$A$6:$G$41,5,0) -> 0 | G13: =IF(H13="ESPECES",3000,0) -> 0 | H13: =IF($D13<>0,"BANQUE",IF($E13<>0,"ESPECES","ECHEC")) -> BANQUE | J13: 1 | K13: =IF($D13<>0,J13*50000,IF($E13<>0,J13*50000,0)) -> 50000 | M13: =IF($D13<>0,L13*75000,IF($E13<>0,L13*75000,0)) -> 0 | O13: =IF($D13<>0,N13*100000,IF($E13<>0,N13*100000,0)) -> 0 | U13: =G13+S13++R13+P13+O13+M13+I13+K13+Q13+V13+W13 -> 50000 | AQ13: =IF(H13="ECHEC",((K13+M13+O13)*20/100),0) -> 0 | AR13: =IF(H13="ECHEC",((K13+M13+O13)*20/100),0) -> 0 | AS13: =IF(H13="ECHEC",0,(K13+I13-25000)) -> 25000 | AW13: =IF(AC13=0,AI13,(1*25000*12)+AI13-AC13) -> 0 | AX13: =IF(AD13=0,AJ13,(1*75000*12)+(AJ13)-AD13) -> 0 | AY13: =IF(AE13=0,AK13,(1*100000*12)+(AK13)-AE13) -> 0 | AZ13: =SUM(AV13:AY13)-BF13+Z13-F13+BH13+BI13+BJ13+BK13+BL13+BM13 -> 0 | BD13: =IF(AZ13=0,(AZ13-BA13-BC13),(AZ13-BA13-BB13-BC13))+F13 -> 0 | BF13: =Z13*1/100*BG13 -> 0 | BG13: 11 | BN13: Retrait Epargne Assurance | BO13: LIBELLES
A14: NJIKI AZARIA | B14: =VLOOKUP(A14,[11]LISTADHERENT!A$5:H$50,3,0) -> DONHOU DAVID | C14: =D14+E14+F14-U14-BB14 -> 0 | D14: =VLOOKUP(A14,[12]HISTOBQUEJANV24!$A$6:$G$46,3,0) -> 0 | E14: =VLOOKUP(A14,[12]HISTOBQUEJANV24!$A$6:$G$41,4,0) -> 50000 | F14: =VLOOKUP(A14,[12]HISTOBQUEJANV24!$A$6:$G$41,5,0) -> 0 | G14: =IF(H14="ESPECES",3000,0)-3000 -> 0 | H14: =IF($D14<>0,"BANQUE",IF($E14<>0,"ESPECES","ECHEC")) -> ESPECES | J14: 1 | K14: =IF($D14<>0,J14*50000,IF($E14<>0,J14*50000,0)) -> 50000 | M14: =IF($D14<>0,L14*75000,IF($E14<>0,L14*75000,0)) -> 0 | O14: =IF($D14<>0,N14*100000,IF($E14<>0,N14*100000,0)) -> 0 | U14: =G14+S14++R14+P14+O14+M14+I14+K14+Q14+V14+W14 -> 50000 | AQ14: =IF(H14="ECHEC",((K14+M14+O14)*20/100),0) -> 0 | AR14: =IF(H14="ECHEC",((K14+M14+O14)*20/100),0) -> 0 | AS14: =IF(H14="ECHEC",0,(K14+I14-25000)) -> 25000 | AW14: =IF(AC14=0,AI14,(1*25000*12)+AI14-AC14) -> 0 | AX14: =IF(AD14=0,AJ14,(1*75000*12)+(AJ14)-AD14) -> 0 | AY14: =IF(AE14=0,AK14,(1*100000*12)+(AK14)-AE14) -> 0 | AZ14: =SUM(AV14:AY14)-BF14+Z14-F14+BH14+BI14+BJ14+BK14+BL14+BM14 -> 0 | BD14: =IF(AZ14=0,(AZ14-BA14-BC14),(AZ14-BA14-BB14-BC14))+F14 -> 0 | BF14: =Z14*1/100*BG14 -> 0 | BG14: 11 | BN14: Banque et commissions diverses | BO14: LIBELLES
A15: TOTAL | B15: =VLOOKUP(A15,[11]LISTADHERENT!A$5:H$50,3,0) -> HENGUE PAUL OMER | C15: =D15+E15+F15-U15-BB15 -> 0 | D15: =VLOOKUP(A15,[12]HISTOBQUEJANV24!$A$6:$G$46,3,0) -> 125000 | E15: =VLOOKUP(A15,[12]HISTOBQUEJANV24!$A$6:$G$41,4,0) -> 0 | F15: =VLOOKUP(A15,[12]HISTOBQUEJANV24!$A$6:$G$41,5,0) -> 0 | G15: =IF(H15="ESPECES",3000,0) -> 0 | H15: =IF($D15<>0,"BANQUE",IF($E15<>0,"ESPECES","ECHEC")) -> BANQUE | J15: 1 | K15: =IF($D15<>0,J15*50000,IF($E15<>0,J15*50000,0)) -> 50000 | L15: 1 | M15: =IF($D15<>0,L15*75000,IF($E15<>0,L15*75000,0)) -> 75000 | O15: =IF($D15<>0,N15*100000,IF($E15<>0,N15*100000,0)) -> 0 | Q15: =VLOOKUP(A15,[13]TONTJANV23!$A$7:$P$20,10,0) -> 0 | U15: =G15+S15++R15+P15+O15+M15+I15+K15+Q15+V15+W15 -> 125000 | AQ15: =IF(H15="ECHEC",((K15+M15+O15)*20/100),0) -> 0 | AR15: =IF(H15="ECHEC",((K15+M15+O15)*20/100),0) -> 0 | AS15: =IF(H15="ECHEC",0,(K15+I15-25000)) -> 25000 | AW15: =IF(AC15=0,AI15,(1*25000*12)+AI15-AC15) -> 0 | AX15: =IF(AD15=0,AJ15,(1*75000*12)+(AJ15)-AD15) -> 0 | AY15: =IF(AE15=0,AK15,(1*100000*12)+(AK15)-AE15) -> 0 | AZ15: =SUM(AV15:AY15)-BF15+Z15-F15+BH15+BI15+BJ15+BK15+BL15+BM15 -> 0 | BD15: =IF(AZ15=0,(AZ15-BA15-BC15),(AZ15-BA15-BB15-BC15))+F15 -> 0 | BF15: =Z15*1/100*BG15 -> 0 | BG15: 11
A16: SOKAMTE | B16: =VLOOKUP(A16,[11]LISTADHERENT!A$5:H$50,3,0) -> HOTCHO BENJAMIN | C16: =D16+E16+F16-U16-BB16 -> 0 | D16: =VLOOKUP(A16,[12]HISTOBQUEJANV24!$A$6:$G$46,3,0) -> 260000 | E16: =VLOOKUP(A16,[12]HISTOBQUEJANV24!$A$6:$G$41,4,0) -> 0 | F16: =VLOOKUP(A16,[12]HISTOBQUEJANV24!$A$6:$G$41,5,0) -> 0 | G16: =IF(H16="ESPECES",3000,0) -> 0 | H16: =IF($D16<>0,"BANQUE",IF($E16<>0,"ESPECES","ECHEC")) -> BANQUE | I16: 35000 | J16: 1 | K16: =IF($D16<>0,J16*50000,IF($E16<>0,J16*50000,0)) -> 50000 | L16: 1 | M16: =IF($D16<>0,L16*75000,IF($E16<>0,L16*75000,0)) -> 75000 | N16: 1 | O16: =IF($D16<>0,N16*100000,IF($E16<>0,N16*100000,0)) -> 100000 | Q16: =VLOOKUP(A16,[13]TONTJANV23!$A$7:$P$20,10,0) -> 0 | U16: =G16+S16++R16+P16+O16+M16+I16+K16+Q16+V16+W16 -> 260000 | AC16: 12000 | AF16: Taux | AQ16: =IF(H16="ECHEC",((K16+M16+O16)*20/100),0) -> 0 | AR16: =IF(H16="ECHEC",((K16+M16+O16)*20/100),0) -> 0 | AS16: =IF(H16="ECHEC",0,(K16+I16-25000)) -> 60000 | AW16: =IF(AC16=0,AI16,(1*25000*12)+AI16-AC16) -> 288000 | AX16: =IF(AD16=0,AJ16,(1*75000*12)+(AJ16)-AD16) -> 0 | AY16: =IF(AE16=0,AK16,(1*100000*12)+(AK16)-AE16) -> 0 | AZ16: =SUM(AV16:AY16)-BF16+Z16-F16+BH16+BI16+BJ16+BK16+BL16+BM16 -> 288000 | BD16: =IF(AZ16=0,(AZ16-BA16-BC16),(AZ16-BA16-BB16-BC16))+F16 -> 288000 | BF16: =Z16*1/100*BG16 -> 0 | BG16: 11 | BN16: EPARGNE ASSURANCE DECES | BP16: =SUM(BP6:BP15) -> 27000
A17: N° | B17: =VLOOKUP(A17,[11]LISTADHERENT!A$5:H$50,3,0) -> KOUAMOU MOISE | C17: =D17+E17+F17-U17-BB17 -> 0 | D17: =VLOOKUP(A17,[12]HISTOBQUEJANV24!$A$6:$G$46,3,0) -> 150000 | E17: =VLOOKUP(A17,[12]HISTOBQUEJANV24!$A$6:$G$41,4,0) -> 0 | F17: =VLOOKUP(A17,[12]HISTOBQUEJANV24!$A$6:$G$41,5,0) -> 0 | G17: =IF(H17="ESPECES",3000,0) -> 0 | H17: =IF($D17<>0,"BANQUE",IF($E17<>0,"ESPECES","ECHEC")) -> BANQUE | J17: 1 | K17: =IF($D17<>0,J17*50000,IF($E17<>0,J17*50000,0)) -> 50000 | M17: =IF($D17<>0,L17*75000,IF($E17<>0,L17*75000,0)) -> 0 | N17: 1 | O17: =IF($D17<>0,N17*100000,IF($E17<>0,N17*100000,0)) -> 100000 | U17: =G17+S17++R17+P17+O17+M17+I17+K17+Q17+V17+W17 -> 150000 | Z17: 1000000 | AK17: 100000 | AN17: 1000 | AQ17: =IF(H17="ECHEC",((K17+M17+O17)*20/100),0) -> 0 | AR17: =IF(H17="ECHEC",((K17+M17+O17)*20/100),0) -> 0 | AS17: =IF(H17="ECHEC",0,(K17+I17-25000)) -> 25000 | AW17: =IF(AC17=0,AI17,(1*25000*12)+AI17-AC17) -> 0 | AX17: =IF(AD17=0,AJ17,(1*75000*12)+(AJ17)-AD17) -> 0 | AY17: =IF(AE17=0,AK17,(1*100000*12)+(AK17)-AE17) -> 100000 | AZ17: =SUM(AV17:AY17)-BF17+Z17-F17+BH17+BI17+BJ17+BK17+BL17+BM17+60000 -> 1150000 | BA17: 100000 | BD17: =IF(AZ17=0,(AZ17-BA17-BC17),(AZ17-BA17-BB17-BC17))+F17 -> 1050000 | BF17: =Z17*1/100*BG17 -> 110000 | BG17: 11 | BK17: 100000
A18: NOM et PRENOM | B18: =VLOOKUP(A18,[11]LISTADHERENT!A$5:H$50,3,0) -> KOUATCHO MESSACK | C18: =D18+E18+F18-U18-BB18 -> 0 | D18: =VLOOKUP(A18,[12]HISTOBQUEJANV24!$A$6:$G$46,3,0) -> 150000 | E18: =VLOOKUP(A18,[12]HISTOBQUEJANV24!$A$6:$G$41,4,0) -> 0 | F18: =VLOOKUP(A18,[12]HISTOBQUEJANV24!$A$6:$G$41,5,0) -> 0 | G18: =IF(H18="ESPECES",3000,0) -> 0 | H18: =IF($D18<>0,"BANQUE",IF($E18<>0,"ESPECES","ECHEC")) -> BANQUE | J18: 1 | K18: =IF($D18<>0,J18*50000,IF($E18<>0,J18*50000,0)) -> 50000 | M18: =IF($D18<>0,L18*75000,IF($E18<>0,L18*75000,0)) -> 0 | N18: 1 | O18: =IF($D18<>0,N18*100000,IF($E18<>0,N18*100000,0)) -> 100000 | U18: =G18+S18++R18+P18+O18+M18+I18+K18+Q18+V18+W18 -> 150000 | AC18: 13000 | AF18: Taux | AQ18: =IF(H18="ECHEC",((K18+M18+O18)*20/100),0) -> 0 | AR18: =IF(H18="ECHEC",((K18+M18+O18)*20/100),0) -> 0 | AS18: =IF(H18="ECHEC",0,(K18+I18-25000)) -> 25000 | AW18: =IF(AC18=0,AI18,(1*25000*12)+AI18-AC18) -> 287000 | AX18: =IF(AD18=0,AJ18,(1*75000*12)+(AJ18)-AD18) -> 0 | AY18: =IF(AE18=0,AK18,(1*100000*12)+(AK18)-AE18) -> 0 | AZ18: =SUM(AV18:AY18)-BF18+Z18-F18+BH18+BI18+BJ18+BK18+BL18+BM18 -> 287000 | BD18: =IF(AZ18=0,(AZ18-BA18-BC18),(AZ18-BA18-BB18-BC18))+F18 -> 287000 | BF18: =Z18*1/100*BG18 -> 0 | BG18: 11 | BN18: AGIOS BANCAIRES | BO18: Contribution Retraite
A19: TCHAPCHET DESIRE | B19: =VLOOKUP(A19,[11]LISTADHERENT!A$5:H$50,3,0) -> MASSEUNGOUE DAGOBERT | C19: =D19+E19+F19-U19-BB19 -> 0 | D19: =VLOOKUP(A19,[12]HISTOBQUEJANV24!$A$6:$G$46,3,0) -> 50000 | E19: =VLOOKUP(A19,[12]HISTOBQUEJANV24!$A$6:$G$41,4,0) -> 25000 | F19: =VLOOKUP(A19,[12]HISTOBQUEJANV24!$A$6:$G$41,5,0) -> 0 | G19: =IF(H19="ESPECES",3000,0) -> 0 | H19: =IF($D19<>0,"BANQUE",IF($E19<>0,"ESPECES","ECHEC")) -> BANQUE | J19: 1 | K19: =IF($D19<>0,J19*50000,IF($E19<>0,J19*50000,0)) -> 50000 | M19: =IF($D19<>0,L19*75000,IF($E19<>0,L19*75000,0)) -> 0 | O19: =IF($D19<>0,N19*100000,IF($E19<>0,N19*100000,0)) -> 0 | U19: =G19+S19++R19+P19+O19+M19+I19+K19+Q19+V19+W19 -> 75000 | W19: 25000 | AQ19: =IF(H19="ECHEC",((K19+M19+O19)*20/100),0) -> 0 | AR19: =IF(H19="ECHEC",((K19+M19+O19)*20/100),0) -> 0 | AS19: =IF(H19="ECHEC",0,(K19+I19-25000)) -> 25000 | AW19: =IF(AC19=0,AI19,(1*25000*12)+AI19-AC19) -> 0 | AX19: =IF(AD19=0,AJ19,(1*75000*12)+(AJ19)-AD19) -> 0 | AY19: =IF(AE19=0,AK19,(1*100000*12)+(AK19)-AE19) -> 0 | AZ19: =SUM(AV19:AY19)-BF19+Z19-F19+BH19+BI19+BJ19+BK19+BL19+BM19 -> 0 | BD19: =IF(AZ19=0,(AZ19-BA19-BC19),(AZ19-BA19-BB19-BC19))+F19 -> 0 | BF19: =Z19*1/100*BG19 -> 0 | BG19: 11
A20: SOH Henri | B20: =VLOOKUP(A20,[11]LISTADHERENT!A$5:H$50,3,0) -> MBOGNING TUGMA GUY | C20: =D20+E20+F20-U20-BB20 -> 0 | D20: =VLOOKUP(A20,[12]HISTOBQUEJANV24!$A$6:$G$46,3,0) -> 225000 | E20: =VLOOKUP(A20,[12]HISTOBQUEJANV24!$A$6:$G$41,4,0) -> 0 | F20: =VLOOKUP(A20,[12]HISTOBQUEJANV24!$A$6:$G$41,5,0) -> 0 | G20: =IF(H20="ESPECES",3000,0) -> 0 | H20: =IF($D20<>0,"BANQUE",IF($E20<>0,"ESPECES","ECHEC")) -> BANQUE | J20: 1 | K20: =IF($D20<>0,J20*50000,IF($E20<>0,J20*50000,0)) -> 50000 | L20: 1 | M20: =IF($D20<>0,L20*75000,IF($E20<>0,L20*75000,0)) -> 75000 | N20: 1 | O20: =IF($D20<>0,N20*100000,IF($E20<>0,N20*100000,0)) -> 100000 | Q20: =VLOOKUP(A20,[13]TONTJANV23!$A$7:$P$20,10,0) -> 0 | U20: =G20+S20++R20+P20+O20+M20+I20+K20+Q20+V20+W20 -> 225000 | AE20: 115000 | AF20: Taux | AQ20: =IF(H20="ECHEC",((K20+M20+O20)*20/100),0) -> 0 | AR20: =IF(H20="ECHEC",((K20+M20+O20)*20/100),0) -> 0 | AS20: =IF(H20="ECHEC",0,(K20+I20-25000)) -> 25000 | AW20: =IF(AC20=0,AI20,(1*25000*12)+AI20-AC20) -> 0 | AX20: =IF(AD20=0,AJ20,(1*75000*12)+(AJ20)-AD20) -> 0 | AY20: =IF(AE20=0,AK20,(1*100000*12)+(AK20)-AE20) -> 1085000 | AZ20: =SUM(AV20:AY20)-BF20+Z20-F20+BH20+BI20+BJ20+BK20+BL20+BM20 -> 1085000 | BD20: =IF(AZ20=0,(AZ20-BA20-BC20),(AZ20-BA20-BB20-BC20))+F20 -> 1085000 | BF20: =Z20*1/100*BG20 -> 0 | BG20: 11
A21: SEPTEMBRE | B21: =VLOOKUP(A21,[11]LISTADHERENT!A$5:H$50,3,0) -> NANGUEN MARTIN | C21: =D21+E21+F21-U21-BB21 -> 0 | D21: =VLOOKUP(A21,[12]HISTOBQUEJANV24!$A$6:$G$46,3,0) -> 50000 | E21: =VLOOKUP(A21,[12]HISTOBQUEJANV24!$A$6:$G$41,4,0) -> 0 | F21: =VLOOKUP(A21,[12]HISTOBQUEJANV24!$A$6:$G$41,5,0) -> 0 | G21: =IF(H21="ESPECES",3000,0) -> 0 | H21: =IF($D21<>0,"BANQUE",IF($E21<>0,"ESPECES","ECHEC")) -> BANQUE | J21: 1 | K21: =IF($D21<>0,J21*50000,IF($E21<>0,J21*50000,0)) -> 50000 | M21: =IF($D21<>0,L21*75000,IF($E21<>0,L21*75000,0)) -> 0 | O21: =IF($D21<>0,N21*100000,IF($E21<>0,N21*100000,0)) -> 0 | U21: =G21+S21++R21+P21+O21+M21+I21+K21+Q21+V21+W21 -> 50000 | AQ21: =IF(H21="ECHEC",((K21+M21+O21)*20/100),0) -> 0 | AR21: =IF(H21="ECHEC",((K21+M21+O21)*20/100),0) -> 0 | AS21: =IF(H21="ECHEC",0,(K21+I21-25000)) -> 25000 | AW21: =IF(AC21=0,AI21,(1*25000*12)+AI21-AC21) -> 0 | AX21: =IF(AD21=0,AJ21,(1*75000*12)+(AJ21)-AD21) -> 0 | AY21: =IF(AE21=0,AK21,(1*100000*12)+(AK21)-AE21) -> 0 | AZ21: =SUM(AV21:AY21)-BF21+Z21-F21+BH21+BI21+BJ21+BK21+BL21+BM21 -> 0 | BD21: =IF(AZ21=0,(AZ21-BA21-BC21),(AZ21-BA21-BB21-BC21))+F21 -> 0 | BF21: =Z21*1/100*BG21 -> 0 | BG21: 11
A22: OCTOBRE | B22: =VLOOKUP(A22,[11]LISTADHERENT!A$5:H$50,3,0) -> NANKAM APPOLINAIRE | C22: =D22+E22+F22-U22-BB22 -> 0 | D22: =VLOOKUP(A22,[12]HISTOBQUEJANV24!$A$6:$G$46,3,0) -> 125000 | E22: =VLOOKUP(A22,[12]HISTOBQUEJANV24!$A$6:$G$41,4,0) -> 0 | F22: =VLOOKUP(A22,[12]HISTOBQUEJANV24!$A$6:$G$41,5,0) -> 0 | G22: =IF(H22="ESPECES",3000,0) -> 0 | H22: =IF($D22<>0,"BANQUE",IF($E22<>0,"ESPECES","ECHEC")) -> BANQUE | J22: 1 | K22: =IF($D22<>0,J22*50000,IF($E22<>0,J22*50000,0)) -> 50000 | L22: 1 | M22: =IF($D22<>0,L22*75000,IF($E22<>0,L22*75000,0)) -> 75000 | O22: =IF($D22<>0,N22*100000,IF($E22<>0,N22*100000,0)) -> 0 | Q22: =VLOOKUP(A22,[13]TONTJANV23!$A$7:$P$20,10,0) -> 0 | U22: =G22+S22++R22+P22+O22+M22+I22+K22+Q22+V22+W22 -> 125000 | AQ22: =IF(H22="ECHEC",((K22+M22+O22)*20/100),0) -> 0 | AR22: =IF(H22="ECHEC",((K22+M22+O22)*20/100),0) -> 0 | AS22: =IF(H22="ECHEC",0,(K22+I22-25000)) -> 25000 | AW22: =IF(AC22=0,AI22,(1*25000*12)+AI22-AC22) -> 0 | AX22: =IF(AD22=0,AJ22,(1*75000*12)+(AJ22)-AD22) -> 0 | AY22: =IF(AE22=0,AK22,(1*100000*12)+(AK22)-AE22) -> 0 | AZ22: =SUM(AV22:AY22)-BF22+Z22-F22+BH22+BI22+BJ22+BK22+BL22+BM22 -> 0 | BD22: =IF(AZ22=0,(AZ22-BA22-BC22),(AZ22-BA22-BB22-BC22))+F22 -> 0 | BF22: =Z22*1/100*BG22 -> 0 | BG22: 11 | BN22: EPARGNE ASSURANCE DECES | BP22: =SUM(BP18:BP21) -> 0
A23: Total | B23: =VLOOKUP(A23,[11]LISTADHERENT!A$5:H$50,3,0) -> NDJOMO ETIENNE | C23: =D23+E23+F23-U23-BB23 -> 0 | D23: =VLOOKUP(A23,[12]HISTOBQUEJANV24!$A$6:$G$46,3,0) -> 260000 | E23: =VLOOKUP(A23,[12]HISTOBQUEJANV24!$A$6:$G$41,4,0) -> 0 | F23: =VLOOKUP(A23,[12]HISTOBQUEJANV24!$A$6:$G$41,5,0) -> 0 | G23: =IF(H23="ESPECES",3000,0) -> 0 | H23: =IF($D23<>0,"BANQUE",IF($E23<>0,"ESPECES","ECHEC")) -> BANQUE | I23: 10000 | J23: 1 | K23: =IF($D23<>0,J23*50000,IF($E23<>0,J23*50000,0)) -> 50000 | M23: =IF($D23<>0,L23*75000,IF($E23<>0,L23*75000,0)) -> 0 | N23: 2 | O23: =IF($D23<>0,N23*100000,IF($E23<>0,N23*100000,0)) -> 200000 | U23: =G23+S23++R23+P23+O23+M23+I23+K23+Q23+V23+W23 -> 260000 | AQ23: =IF(H23="ECHEC",((K23+M23+O23)*20/100),0) -> 0 | AR23: =IF(H23="ECHEC",((K23+M23+O23)*20/100),0) -> 0 | AS23: =IF(H23="ECHEC",0,(K23+I23-25000)) -> 35000 | AW23: =IF(AC23=0,AI23,(1*25000*12)+AI23-AC23) -> 0 | AX23: =IF(AD23=0,AJ23,(1*75000*12)+(AJ23)-AD23) -> 0 | AY23: =IF(AE23=0,AK23,(1*100000*12)+(AK23)-AE23) -> 0 | AZ23: =SUM(AV23:AY23)-BF23+Z23-F23+BH23+BI23+BJ23+BK23+BL23+BM23 -> 0 | BA23: 56000 | BD23: =IF(AZ23=0,(AZ23-BA23-BC23),(AZ23-BA23-BB23-BC23))+F23+56000 -> 0 | BF23: =Z23*1/100*BG23 -> 0 | BG23: 11
A24: TATUE FOPA | B24: =VLOOKUP(A24,[11]LISTADHERENT!A$5:H$50,3,0) -> NGONDIEP CLAUDE | C24: =D24+E24+F24-U24-BB24 -> 0 | D24: =VLOOKUP(A24,[12]HISTOBQUEJANV24!$A$6:$G$46,3,0) -> 225000 | E24: =VLOOKUP(A24,[12]HISTOBQUEJANV24!$A$6:$G$41,4,0) -> 0 | F24: =VLOOKUP(A24,[12]HISTOBQUEJANV24!$A$6:$G$41,5,0) -> 0 | G24: =IF(H24="ESPECES",3000,0) -> 0 | H24: =IF($D24<>0,"BANQUE",IF($E24<>0,"ESPECES","ECHEC")) -> BANQUE | J24: 1 | K24: =IF($D24<>0,J24*50000,IF($E24<>0,J24*50000,0)) -> 50000 | L24: 1 | M24: =IF($D24<>0,L24*75000,IF($E24<>0,L24*75000,0)) -> 75000 | N24: 1 | O24: =IF($D24<>0,N24*100000,IF($E24<>0,N24*100000,0)) -> 100000 | Q24: =VLOOKUP(A24,[13]TONTJANV23!$A$7:$P$20,10,0) -> 0 | U24: =G24+S24++R24+P24+O24+M24+I24+K24+Q24+V24+W24 -> 225000 | AQ24: =IF(H24="ECHEC",((K24+M24+O24)*20/100),0) -> 0 | AR24: =IF(H24="ECHEC",((K24+M24+O24)*20/100),0) -> 0 | AS24: =IF(H24="ECHEC",0,(K24+I24-25000)) -> 25000 | AW24: =IF(AC24=0,AI24,(1*25000*12)+AI24-AC24) -> 0 | AX24: =IF(AD24=0,AJ24,(1*75000*12)+(AJ24)-AD24) -> 0 | AY24: =IF(AE24=0,AK24,(1*100000*12)+(AK24)-AE24) -> 0 | AZ24: =SUM(AV24:AY24)-BF24+Z24-F24+BH24+BI24+BJ24+BK24+BL24+BM24 -> 0 | BD24: =IF(AZ24=0,(AZ24-BA24-BC24),(AZ24-BA24-BB24-BC24))+F24 -> 0 | BF24: =Z24*1/100*BG24 -> 0 | BG24: 11 | BN24: KAMGUEM LISE | BO24: FOND AIDE | BP24: 200000
A25: A | B25: =VLOOKUP(A25,[11]LISTADHERENT!A$5:H$50,3,0) -> NGUIEMEGNI MATHIEU BLAISE | C25: =D25+E25+F25-U25-BB25 -> 0 | D25: =VLOOKUP(A25,[12]HISTOBQUEJANV24!$A$6:$G$46,3,0) -> 375000 | E25: =VLOOKUP(A25,[12]HISTOBQUEJANV24!$A$6:$G$41,4,0) -> 0 | F25: =VLOOKUP(A25,[12]HISTOBQUEJANV24!$A$6:$G$41,5,0) -> 0 | G25: =IF(H25="ESPECES",3000,0) -> 0 | H25: =IF($D25<>0,"BANQUE",IF($E25<>0,"ESPECES","ECHEC")) -> BANQUE | J25: 1 | K25: =IF($D25<>0,J25*50000,IF($E25<>0,J25*50000,0)) -> 50000 | L25: 3 | M25: =IF($D25<>0,L25*75000,IF($E25<>0,L25*75000,0)) -> 225000 | N25: 1 | O25: =IF($D25<>0,N25*100000,IF($E25<>0,N25*100000,0)) -> 100000 | Q25: =VLOOKUP(A25,[13]TONTJANV23!$A$7:$P$20,10,0) -> 0 | U25: =G25+S25++R25+P25+O25+M25+I25+K25+Q25+V25+W25 -> 375000 | AD25: 65000 | AE25: 125000 | AF25: Taux | AQ25: =IF(H25="ECHEC",((K25+M25+O25)*20/100),0) -> 0 | AR25: =IF(H25="ECHEC",((K25+M25+O25)*20/100),0) -> 0 | AS25: =IF(H25="ECHEC",0,(K25+I25-25000)) -> 25000 | AW25: =IF(AC25=0,AI25,(1*25000*12)+AI25-AC25) -> 0 | AX25: =IF(AD25=0,AJ25,(1*75000*12)+(AJ25)-AD25) -> 835000 | AY25: =IF(AE25=0,AK25,(1*100000*12)+(AK25)-AE25) -> 1075000 | AZ25: =SUM(AV25:AY25)-BF25+Z25-F25+BH25+BI25+BJ25+BK25+BL25+BM25 -> 1910000 | BD25: =IF(AZ25=0,(AZ25-BA25-BC25),(AZ25-BA25-BB25-BC25))+F25 -> 1910000 | BF25: =Z25*1/100*BG25 -> 0 | BG25: 11 | BN25: NANA | BO25: FOND AIDE | BP25: 300000
A26: B | B26: =VLOOKUP(A26,[11]LISTADHERENT!A$5:H$50,3,0) -> NKAMGANG JUSTIN DEJOLIE | C26: =D26+E26+F26-U26-BB26 -> 0 | D26: =VLOOKUP(A26,[12]HISTOBQUEJANV24!$A$6:$G$46,3,0) -> 0 | E26: =VLOOKUP(A26,[12]HISTOBQUEJANV24!$A$6:$G$41,4,0) -> 50000 | F26: =VLOOKUP(A26,[12]HISTOBQUEJANV24!$A$6:$G$41,5,0) -> 0 | G26: =IF(H26="ESPECES",3000,0)-3000 -> 0 | H26: =IF($D26<>0,"BANQUE",IF($E26<>0,"ESPECES","ECHEC")) -> ESPECES | J26: 1 | K26: =IF($D26<>0,J26*50000,IF($E26<>0,J26*50000,0)) -> 50000 | M26: =IF($D26<>0,L26*75000,IF($E26<>0,L26*75000,0)) -> 0 | O26: =IF($D26<>0,N26*100000,IF($E26<>0,N26*100000,0)) -> 0 | U26: =G26+S26++R26+P26+O26+M26+I26+K26+Q26+V26+W26 -> 50000 | AC26: 13000 | AF26: Taux | AQ26: =IF(H26="ECHEC",((K26+M26+O26)*20/100),0) -> 0 | AR26: =IF(H26="ECHEC",((K26+M26+O26)*20/100),0) -> 0 | AS26: =IF(H26="ECHEC",0,(K26+I26-25000)) -> 25000 | AW26: =IF(AC26=0,AI26,(1*25000*12)+AI26-AC26) -> 287000 | AX26: =IF(AD26=0,AJ26,(1*75000*12)+(AJ26)-AD26) -> 0 | AY26: =IF(AE26=0,AK26,(1*100000*12)+(AK26)-AE26) -> 0 | AZ26: =SUM(AV26:AY26)-BF26+Z26-F26+BH26+BI26+BJ26+BK26+BL26+BM26 -> 287000 | BA26: 7000 | BD26: =IF(AZ26=0,(AZ26-BA26-BC26),(AZ26-BA26-BB26-BC26))+F26 -> 280000 | BF26: =Z26*1/100*BG26 -> 0 | BG26: 11 | BN26: Aide Suite différents Evenements | BO26: FOND AIDE
A27: COTISATION RETRAITE | B27: =VLOOKUP(A27,[11]LISTADHERENT!A$5:H$50,3,0) -> NOUBE ETIENNE | C27: =D27+E27+F27-U27-BB27 -> 0 | D27: =VLOOKUP(A27,[12]HISTOBQUEJANV24!$A$6:$G$46,3,0) -> 50000 | E27: =VLOOKUP(A27,[12]HISTOBQUEJANV24!$A$6:$G$41,4,0) -> 0 | F27: =VLOOKUP(A27,[12]HISTOBQUEJANV24!$A$6:$G$41,5,0) -> 0 | G27: =IF(H27="ESPECES",3000,0) -> 0 | H27: =IF($D27<>0,"BANQUE",IF($E27<>0,"ESPECES","ECHEC")) -> BANQUE | J27: 1 | K27: =IF($D27<>0,J27*50000,IF($E27<>0,J27*50000,0)) -> 50000 | M27: =IF($D27<>0,L27*75000,IF($E27<>0,L27*75000,0)) -> 0 | O27: =IF($D27<>0,N27*100000,IF($E27<>0,N27*100000,0)) -> 0 | U27: =G27+S27++R27+P27+O27+M27+I27+K27+Q27+V27+W27 -> 50000 | AQ27: =IF(H27="ECHEC",((K27+M27+O27)*20/100),0) -> 0 | AR27: =IF(H27="ECHEC",((K27+M27+O27)*20/100),0) -> 0 | AS27: =IF(H27="ECHEC",0,(K27+I27-25000)) -> 25000 | AW27: =IF(AC27=0,AI27,(1*25000*12)+AI27-AC27) -> 0 | AX27: =IF(AD27=0,AJ27,(1*75000*12)+(AJ27)-AD27) -> 0 | AY27: =IF(AE27=0,AK27,(1*100000*12)+(AK27)-AE27) -> 0 | AZ27: =SUM(AV27:AY27)-BF27+Z27-F27+BH27+BI27+BJ27+BK27+BL27+BM27 -> 0 | BD27: =IF(AZ27=0,(AZ27-BA27-BC27),(AZ27-BA27-BB27-BC27))+F27 -> 0 | BF27: =Z27*1/100*BG27 -> 0 | BG27: 11
A28: Ancienneté inférieure à 5 ans | B28: =VLOOKUP(A28,[11]LISTADHERENT!A$5:H$50,3,0) -> PATEGO NJOSSU GUSTAVE | C28: =D28+E28+F28-U28-BB28 -> 0 | D28: =VLOOKUP(A28,[12]HISTOBQUEJANV24!$A$6:$G$46,3,0) -> 125000 | E28: =VLOOKUP(A28,[12]HISTOBQUEJANV24!$A$6:$G$41,4,0) -> 0 | F28: =VLOOKUP(A28,[12]HISTOBQUEJANV24!$A$6:$G$41,5,0) -> 0 | G28: =IF(H28="ESPECES",3000,0) -> 0 | H28: =IF($D28<>0,"BANQUE",IF($E28<>0,"ESPECES","ECHEC")) -> BANQUE | J28: 1 | K28: =IF($D28<>0,J28*50000,IF($E28<>0,J28*50000,0)) -> 50000 | L28: 1 | M28: =IF($D28<>0,L28*75000,IF($E28<>0,L28*75000,0)) -> 75000 | O28: =IF($D28<>0,N28*100000,IF($E28<>0,N28*100000,0)) -> 0 | Q28: =VLOOKUP(A28,[13]TONTJANV23!$A$7:$P$20,10,0) -> 0 | U28: =G28+S28++R28+P28+O28+M28+I28+K28+Q28+V28+W28 -> 125000 | AQ28: =IF(H28="ECHEC",((K28+M28+O28)*20/100),0) -> 0 | AR28: =IF(H28="ECHEC",((K28+M28+O28)*20/100),0) -> 0 | AS28: =IF(H28="ECHEC",0,(K28+I28-25000)) -> 25000 | AW28: =IF(AC28=0,AI28,(1*25000*12)+AI28-AC28) -> 0 | AX28: =IF(AD28=0,AJ28,(1*75000*12)+(AJ28)-AD28) -> 0 | AY28: =IF(AE28=0,AK28,(1*100000*12)+(AK28)-AE28) -> 0 | AZ28: =SUM(AV28:AY28)-BF28+Z28-F28+BH28+BI28+BJ28+BK28+BL28+BM28 -> 0 | BD28: =IF(AZ28=0,(AZ28-BA28-BC28),(AZ28-BA28-BB28-BC28))+F28 -> 0 | BF28: =Z28*1/100*BG28 -> 0 | BG28: 11 | BN28: EPARGNE ASSURANCE DECES | BP28: =SUM(BP24:BP26) -> 500000
A29: B- RECAPITULATIF DES SORTIES | B29: =VLOOKUP(A29,[11]LISTADHERENT!A$5:H$50,3,0) -> SEUMO POLYCARPE | C29: =D29+E29+F29-U29-BB29 -> 0 | D29: =VLOOKUP(A29,[12]HISTOBQUEJANV24!$A$6:$G$46,3,0) -> 500000 | E29: =VLOOKUP(A29,[12]HISTOBQUEJANV24!$A$6:$G$41,4,0) -> 0 | F29: =VLOOKUP(A29,[12]HISTOBQUEJANV24!$A$6:$G$41,5,0) -> 0 | G29: =IF(H29="ESPECES",3000,0) -> 0 | H29: =IF($D29<>0,"BANQUE",IF($E29<>0,"ESPECES","ECHEC")) -> BANQUE | I29: 450000 | J29: 1 | K29: =IF($D29<>0,J29*50000,IF($E29<>0,J29*50000,0)) -> 50000 | M29: =IF($D29<>0,L29*75000,IF($E29<>0,L29*75000,0)) -> 0 | O29: =IF($D29<>0,N29*100000,IF($E29<>0,N29*100000,0)) -> 0 | U29: =G29+S29++R29+P29+O29+M29+I29+K29+Q29+V29+W29 -> 500000 | AQ29: =IF(H29="ECHEC",((K29+M29+O29)*20/100),0) -> 0 | AR29: =IF(H29="ECHEC",((K29+M29+O29)*20/100),0) -> 0 | AS29: =IF(H29="ECHEC",0,(K29+I29-25000)) -> 475000 | AW29: =IF(AC29=0,AI29,(1*25000*12)+AI29-AC29) -> 0 | AX29: =IF(AD29=0,AJ29,(1*75000*12)+(AJ29)-AD29) -> 0 | AY29: =IF(AE29=0,AK29,(1*100000*12)+(AK29)-AE29) -> 0 | AZ29: =SUM(AV29:AY29)-BF29+Z29-F29+BH29+BI29+BJ29+BK29+BL29+BM29 -> 0 | BD29: =IF(AZ29=0,(AZ29-BA29-BC29),(AZ29-BA29-BB29-BC29))+F29 -> 0 | BF29: =Z29*1/100*BG29 -> 0 | BG29: 11
A30: CALCUL DE LA PRIME AROUEST A PAYER A CERTAINS RETRAITE | B30: =VLOOKUP(A30,[11]LISTADHERENT!A$5:H$50,3,0) -> SIME BRICE | C30: =D30+E30+F30-U30-BB30 -> 0 | D30: =VLOOKUP(A30,[12]HISTOBQUEJANV24!$A$6:$G$46,3,0) -> 250000 | E30: =VLOOKUP(A30,[12]HISTOBQUEJANV24!$A$6:$G$41,4,0) -> 0 | F30: =VLOOKUP(A30,[12]HISTOBQUEJANV24!$A$6:$G$41,5,0) -> 0 | G30: =IF(H30="ESPECES",3000,0) -> 0 | H30: =IF($D30<>0,"BANQUE",IF($E30<>0,"ESPECES","ECHEC")) -> BANQUE | J30: 1 | K30: =IF($D30<>0,J30*50000,IF($E30<>0,J30*50000,0)) -> 50000 | M30: =IF($D30<>0,L30*75000,IF($E30<>0,L30*75000,0)) -> 0 | N30: 2 | O30: =IF($D30<>0,N30*100000,IF($E30<>0,N30*100000,0)) -> 200000 | U30: =G30+S30++R30+P30+O30+M30+I30+K30+Q30+V30+W30 -> 250000 | AQ30: =IF(H30="ECHEC",((K30+M30+O30)*20/100),0) -> 0 | AR30: =IF(H30="ECHEC",((K30+M30+O30)*20/100),0) -> 0 | AS30: =IF(H30="ECHEC",0,(K30+I30-25000)) -> 25000 | AW30: =IF(AC30=0,AI30,(1*25000*12)+AI30-AC30) -> 0 | AX30: =IF(AD30=0,AJ30,(1*75000*12)+(AJ30)-AD30) -> 0 | AY30: =IF(AE30=0,AK30,(1*100000*12)+(AK30)-AE30) -> 0 | AZ30: =SUM(AV30:AY30)-BF30+Z30-F30+BH30+BI30+BJ30+BK30+BL30+BM30 -> 0 | BD30: =IF(AZ30=0,(AZ30-BA30-BC30),(AZ30-BA30-BB30-BC30))+F30 -> 0 | BF30: =Z30*1/100*BG30 -> 0 | BG30: 11 | BN30: WASO Georges | BO30: F. AIDE
A31: Montant à rembouser par chaque membre | B31: =VLOOKUP(A31,[11]LISTADHERENT!A$5:H$50,3,0) -> SIMO PIERRE | C31: =D31+E31+F31-U31-BB31 -> 0 | D31: =VLOOKUP(A31,[12]HISTOBQUEJANV24!$A$6:$G$46,3,0) -> 150000 | E31: =VLOOKUP(A31,[12]HISTOBQUEJANV24!$A$6:$G$41,4,0) -> 0 | F31: =VLOOKUP(A31,[12]HISTOBQUEJANV24!$A$6:$G$41,5,0) -> 0 | G31: =IF(H31="ESPECES",3000,0) -> 0 | H31: =IF($D31<>0,"BANQUE",IF($E31<>0,"ESPECES","ECHEC")) -> BANQUE | J31: 1 | K31: =IF($D31<>0,J31*50000,IF($E31<>0,J31*50000,0)) -> 50000 | M31: =IF($D31<>0,L31*75000,IF($E31<>0,L31*75000,0)) -> 0 | N31: 1 | O31: =IF($D31<>0,N31*100000,IF($E31<>0,N31*100000,0)) -> 100000 | U31: =G31+S31++R31+P31+O31+M31+I31+K31+Q31+V31+W31 -> 150000 | AQ31: =IF(H31="ECHEC",((K31+M31+O31)*20/100),0) -> 0 | AR31: =IF(H31="ECHEC",((K31+M31+O31)*20/100),0) -> 0 | AS31: =IF(H31="ECHEC",0,(K31+I31-25000)) -> 25000 | AW31: =IF(AC31=0,AI31,(1*25000*12)+AI31-AC31) -> 0 | AX31: =IF(AD31=0,AJ31,(1*75000*12)+(AJ31)-AD31) -> 0 | AY31: =IF(AE31=0,AK31,(1*100000*12)+(AK31)-AE31) -> 0 | AZ31: =SUM(AV31:AY31)-BF31+Z31-F31+BH31+BI31+BJ31+BK31+BL31+BM31 -> 0 | BD31: =IF(AZ31=0,(AZ31-BA31-BC31),(AZ31-BA31-BB31-BC31))+F31 -> 0 | BF31: =Z31*1/100*BG31 -> 0 | BG31: 11 | BN31: NDEFO PP | BO31: F. AIDE
A32: COMPTE CHEQUE TONTINE | B32: =VLOOKUP(A32,[11]LISTADHERENT!A$5:H$50,3,0) -> TCHOUAMOU MATHIEU | C32: =D32+E32+F32-U32-BB32 -> 0 | D32: =VLOOKUP(A32,[12]HISTOBQUEJANV24!$A$6:$G$46,3,0) -> 125000 | E32: =VLOOKUP(A32,[12]HISTOBQUEJANV24!$A$6:$G$41,4,0) -> 0 | F32: =VLOOKUP(A32,[12]HISTOBQUEJANV24!$A$6:$G$41,5,0) -> 0 | G32: =IF(H32="ESPECES",3000,0) -> 0 | H32: =IF($D32<>0,"BANQUE",IF($E32<>0,"ESPECES","ECHEC")) -> BANQUE | J32: 1 | K32: =IF($D32<>0,J32*50000,IF($E32<>0,J32*50000,0)) -> 50000 | L32: 1 | M32: =IF($D32<>0,L32*75000,IF($E32<>0,L32*75000,0)) -> 75000 | O32: =IF($D32<>0,N32*100000,IF($E32<>0,N32*100000,0)) -> 0 | U32: =G32+S32++R32+P32+O32+M32+I32+K32+Q32+V32+W32 -> 125000 | Z32: 1000000 | AQ32: =IF(H32="ECHEC",((K32+M32+O32)*20/100),0) -> 0 | AR32: =IF(H32="ECHEC",((K32+M32+O32)*20/100),0) -> 0 | AS32: =IF(H32="ECHEC",0,(K32+I32-25000)) -> 25000 | AW32: =IF(AC32=0,AI32,(1*25000*12)+AI32-AC32) -> 0 | AX32: =IF(AD32=0,AJ32,(1*75000*12)+(AJ32)-AD32) -> 0 | AY32: =IF(AE32=0,AK32,(1*100000*12)+(AK32)-AE32) -> 0 | AZ32: =SUM(AV32:AY32)-BF32+Z32-F32+BH32+BI32+BJ32+BK32+BL32+BM32 -> 940000 | BD32: =IF(AZ32=0,(AZ32-BA32-BC32),(AZ32-BA32-BB32-BC32))+F32 -> 940000 | BF32: =Z32*1/100*BG32 -> 60000 | BG32: 6
A33: Versement en banque janvier | B33: =VLOOKUP(A33,[11]LISTADHERENT!A$5:H$50,3,0) -> TCHOUATEU AUGUSTIN | C33: =D33+E33+F33-U33-BB33 -> 120000 | D33: =VLOOKUP(A33,[12]HISTOBQUEJANV24!$A$6:$G$46,3,0) -> 540000 | E33: =VLOOKUP(A33,[12]HISTOBQUEJANV24!$A$6:$G$41,4,0) -> 0 | F33: =VLOOKUP(A33,[12]HISTOBQUEJANV24!$A$6:$G$41,5,0) -> 0 | G33: =IF(H33="ESPECES",3000,0) -> 0 | H33: =IF($D33<>0,"BANQUE",IF($E33<>0,"ESPECES","ECHEC")) -> BANQUE | I33: 245000 | J33: 1 | K33: =IF($D33<>0,J33*50000,IF($E33<>0,J33*50000,0)) -> 50000 | M33: =IF($D33<>0,L33*75000,IF($E33<>0,L33*75000,0)) -> 0 | N33: 1 | O33: =IF($D33<>0,N33*100000,IF($E33<>0,N33*100000,0)) -> 100000 | U33: =G33+S33++R33+P33+O33+M33+I33+K33+Q33+V33+W33 -> 420000 | W33: 25000 | AQ33: =IF(H33="ECHEC",((K33+M33+O33)*20/100),0) -> 0 | AR33: =IF(H33="ECHEC",((K33+M33+O33)*20/100),0) -> 0 | AS33: =IF(H33="ECHEC",0,(K33+I33-25000)) -> 270000 | AT33: 120000 | AW33: =IF(AC33=0,AI33,(1*25000*12)+AI33-AC33) -> 0 | AX33: =IF(AD33=0,AJ33,(1*75000*12)+(AJ33)-AD33) -> 0 | AY33: =IF(AE33=0,AK33,(1*100000*12)+(AK33)-AE33) -> 0 | AZ33: =SUM(AV33:AY33)-BF33+Z33-F33+BH33+BI33+BJ33+BK33+BL33+BM33 -> 0 | BD33: =IF(AZ33=0,(AZ33-BA33-BC33),(AZ33-BA33-BB33-BC33))+F33 -> 0 | BF33: =Z33*1/100*BG33 -> 0 | BG33: 11 | BN33: EPARGNE ASSURANCE DECES | BP33: =SUM(BP30:BP32) -> 0
A34: ASSURANCE DECES | B34: =VLOOKUP(A34,[11]LISTADHERENT!A$5:H$50,3,0) -> TCHOUTOU NANA CLAUDE | C34: =D34+E34+F34-U34-BB34 -> 0 | D34: =VLOOKUP(A34,[12]HISTOBQUEJANV24!$A$6:$G$46,3,0) -> 50000 | E34: =VLOOKUP(A34,[12]HISTOBQUEJANV24!$A$6:$G$41,4,0) -> 0 | F34: =VLOOKUP(A34,[12]HISTOBQUEJANV24!$A$6:$G$41,5,0) -> 0 | G34: =IF(H34="ESPECES",3000,0) -> 0 | H34: =IF($D34<>0,"BANQUE",IF($E34<>0,"ESPECES","ECHEC")) -> BANQUE | J34: 1 | K34: =IF($D34<>0,J34*50000,IF($E34<>0,J34*50000,0)) -> 50000 | M34: =IF($D34<>0,L34*75000,IF($E34<>0,L34*75000,0)) -> 0 | O34: =IF($D34<>0,N34*100000,IF($E34<>0,N34*100000,0)) -> 0 | U34: =G34+S34++R34+P34+O34+M34+I34+K34+Q34+V34+W34 -> 50000 | AQ34: =IF(H34="ECHEC",((K34+M34+O34)*20/100),0) -> 0 | AR34: =IF(H34="ECHEC",((K34+M34+O34)*20/100),0) -> 0 | AS34: =IF(H34="ECHEC",0,(K34+I34-25000)) -> 25000 | AW34: =IF(AC34=0,AI34,(1*25000*12)+AI34-AC34) -> 0 | AX34: =IF(AD34=0,AJ34,(1*75000*12)+(AJ34)-AD34) -> 0 | AY34: =IF(AE34=0,AK34,(1*100000*12)+(AK34)-AE34) -> 0 | AZ34: =SUM(AV34:AY34)-BF34+Z34-F34+BH34+BI34+BJ34+BK34+BL34+BM34 -> 0 | BD34: =IF(AZ34=0,(AZ34-BA34-BC34),(AZ34-BA34-BB34-BC34))+F34 -> 0 | BF34: =Z34*1/100*BG34 -> 0 | BG34: 11 | BN34: EPARGNE ASSURANCE DECES | BP34: =SUM(BP31:BP33) -> 0
A35: RETRAIT DE FONDS DANS L'ASSURANCE PAR LES MEMBRES | B35: =VLOOKUP(A35,[11]LISTADHERENT!A$5:H$50,3,0) -> YANTCHOU GERVAIS | C35: =D35+E35+F35-U35-BB35 -> 0 | D35: =VLOOKUP(A35,[12]HISTOBQUEJANV24!$A$6:$G$46,3,0) -> 60000 | E35: =VLOOKUP(A35,[12]HISTOBQUEJANV24!$A$6:$G$41,4,0) -> 0 | F35: =VLOOKUP(A35,[12]HISTOBQUEJANV24!$A$6:$G$41,5,0) -> 0 | G35: =IF(H35="ESPECES",3000,0) -> 0 | H35: =IF($D35<>0,"BANQUE",IF($E35<>0,"ESPECES","ECHEC")) -> BANQUE | I35: 10000 | J35: 1 | K35: =IF($D35<>0,J35*50000,IF($E35<>0,J35*50000,0)) -> 50000 | M35: =IF($D35<>0,L35*75000,IF($E35<>0,L35*75000,0)) -> 0 | O35: =IF($D35<>0,N35*100000,IF($E35<>0,N35*100000,0)) -> 0 | U35: =G35+S35++R35+P35+O35+M35+I35+K35+Q35+V35+W35 -> 60000 | AQ35: =IF(H35="ECHEC",((K35+M35+O35)*20/100),0) -> 0 | AR35: =IF(H35="ECHEC",((K35+M35+O35)*20/100),0) -> 0 | AS35: =IF(H35="ECHEC",0,(K35+I35-25000)) -> 35000 | AW35: =IF(AC35=0,AI35,(1*25000*12)+AI35-AC35) -> 0 | AX35: =IF(AD35=0,AJ35,(1*75000*12)+(AJ35)-AD35) -> 0 | AY35: =IF(AE35=0,AK35,(1*100000*12)+(AK35)-AE35) -> 0 | AZ35: =SUM(AV35:AY35)-BF35+Z35-F35+BH35+BI35+BJ35+BK35+BL35+BM35 -> 0 | BD35: =IF(AZ35=0,(AZ35-BA35-BC35),(AZ35-BA35-BB35-BC35))+F35 -> 0 | BF35: =Z35*1/100*BG35 -> 0 | BG35: 11
A36: COMPTES EPARGNE | B36: =VLOOKUP(A36,[11]LISTADHERENT!A$5:H$50,3,0) -> YEPMOU JEAN JACQUES | C36: =D36+E36+F36-U36-BB36 -> 0 | D36: =VLOOKUP(A36,[12]HISTOBQUEJANV24!$A$6:$G$46,3,0) -> 0 | E36: =VLOOKUP(A36,[12]HISTOBQUEJANV24!$A$6:$G$41,4,0) -> 50000 | F36: =VLOOKUP(A36,[12]HISTOBQUEJANV24!$A$6:$G$41,5,0) -> 0 | G36: =IF(H36="ESPECES",3000,0)-3000 -> 0 | H36: =IF($D36<>0,"BANQUE",IF($E36<>0,"ESPECES","ECHEC")) -> ESPECES | J36: 1 | K36: =IF($D36<>0,J36*50000,IF($E36<>0,J36*50000,0)) -> 50000 | M36: =IF($D36<>0,L36*75000,IF($E36<>0,L36*75000,0)) -> 0 | O36: =IF($D36<>0,N36*100000,IF($E36<>0,N36*100000,0)) -> 0 | U36: =G36+S36++R36+P36+O36+M36+I36+K36+Q36+V36+W36 -> 50000 | AQ36: =IF(H36="ECHEC",((K36+M36+O36)*20/100),0) -> 0 | AR36: =IF(H36="ECHEC",((K36+M36+O36)*20/100),0) -> 0 | AS36: =IF(H36="ECHEC",0,(K36+I36-25000)) -> 25000 | AW36: =IF(AC36=0,AI36,(1*25000*12)+AI36-AC36) -> 0 | AX36: =IF(AD36=0,AJ36,(1*75000*12)+(AJ36)-AD36) -> 0 | AY36: =IF(AE36=0,AK36,(1*100000*12)+(AK36)-AE36) -> 0 | AZ36: =SUM(AV36:AY36)-BF36+Z36-F36+BH36+BI36+BJ36+BK36+BL36+BM36 -> 0 | BD36: =IF(AZ36=0,(AZ36-BA36-BC36),(AZ36-BA36-BB36-BC36))+F36 -> 0 | BF36: =Z36*1/100*BG36 -> 0 | BG36: 11 | BN36: Frais de taxi pour comité spéciale bureau | BO36: Frais de taxi pour comité spéciale bureau | BP36: 100000
A37: TAKOUGOUM | B37: =VLOOKUP(A37,[11]LISTADHERENT!A$5:H$50,3,0) -> YIALA ALAIN OSCAR | C37: =D37+E37+F37-U37-BB37 -> 0 | D37: =VLOOKUP(A37,[12]HISTOBQUEJANV24!$A$6:$G$46,3,0) -> 150000 | E37: =VLOOKUP(A37,[12]HISTOBQUEJANV24!$A$6:$G$41,4,0) -> 25000 | F37: =VLOOKUP(A37,[12]HISTOBQUEJANV24!$A$6:$G$41,5,0) -> 0 | G37: =IF(H37="ESPECES",3000,0) -> 0 | H37: =IF($D37<>0,"BANQUE",IF($E37<>0,"ESPECES","ECHEC")) -> BANQUE | J37: 1 | K37: =IF($D37<>0,J37*50000,IF($E37<>0,J37*50000,0)) -> 50000 | M37: =IF($D37<>0,L37*75000,IF($E37<>0,L37*75000,0)) -> 0 | N37: 1 | O37: =IF($D37<>0,N37*100000,IF($E37<>0,N37*100000,0)) -> 100000 | U37: =G37+S37++R37+P37+O37+M37+I37+K37+Q37+V37+W37 -> 175000 | W37: 25000 | AQ37: =IF(H37="ECHEC",((K37+M37+O37)*20/100),0) -> 0 | AR37: =IF(H37="ECHEC",((K37+M37+O37)*20/100),0) -> 0 | AS37: =IF(H37="ECHEC",0,(K37+I37-25000)) -> 25000 | AW37: =IF(AC37=0,AI37,(1*25000*12)+AI37-AC37) -> 0 | AX37: =IF(AD37=0,AJ37,(1*75000*12)+(AJ37)-AD37) -> 0 | AY37: =IF(AE37=0,AK37,(1*100000*12)+(AK37)-AE37) -> 0 | AZ37: =SUM(AV37:AY37)-BF37+Z37-F37+BH37+BI37+BJ37+BK37+BL37+BM37 -> 0 | BD37: =IF(AZ37=0,(AZ37-BA37-BC37),(AZ37-BA37-BB37-BC37))+F37 -> 0 | BF37: =Z37*1/100*BG37 -> 0 | BG37: 11 | BN37: Confection rapport Annuel | BO37: Frais de taxi pour comité spéciale bureau
A38: Compte Principal | B38: =VLOOKUP(A38,[11]LISTADHERENT!A$5:H$50,3,0) -> YOUMBI EMMANUEL | C38: =D38+E38+F38-U38-BB38 -> 0 | D38: =VLOOKUP(A38,[12]HISTOBQUEJANV24!$A$6:$G$46,3,0) -> 125000 | E38: =VLOOKUP(A38,[12]HISTOBQUEJANV24!$A$6:$G$41,4,0) -> 0 | F38: =VLOOKUP(A38,[12]HISTOBQUEJANV24!$A$6:$G$41,5,0) -> 0 | G38: =IF(H38="ESPECES",3000,0) -> 0 | H38: =IF($D38<>0,"BANQUE",IF($E38<>0,"ESPECES","ECHEC")) -> BANQUE | J38: 1 | K38: =IF($D38<>0,J38*50000,IF($E38<>0,J38*50000,0)) -> 50000 | L38: 1 | M38: =IF($D38<>0,L38*75000,IF($E38<>0,L38*75000,0)) -> 75000 | O38: =IF($D38<>0,N38*100000,IF($E38<>0,N38*100000,0)) -> 0 | Q38: =VLOOKUP(A38,[13]TONTJANV23!$A$7:$P$20,10,0) -> 0 | U38: =G38+S38++R38+P38+O38+M38+I38+K38+Q38+V38+W38 -> 125000 | AQ38: =IF(H38="ECHEC",((K38+M38+O38)*20/100),0) -> 0 | AR38: =IF(H38="ECHEC",((K38+M38+O38)*20/100),0) -> 0 | AS38: =IF(H38="ECHEC",0,(K38+I38-25000)) -> 25000 | AW38: =IF(AC38=0,AI38,(1*25000*12)+AI38-AC38) -> 0 | AX38: =IF(AD38=0,AJ38,(1*75000*12)+(AJ38)-AD38) -> 0 | AY38: =IF(AE38=0,AK38,(1*100000*12)+(AK38)-AE38) -> 0 | AZ38: =SUM(AV38:AY38)-BF38+Z38-F38+BH38+BI38+BJ38+BK38+BL38+BM38 -> 0 | BD38: =IF(AZ38=0,(AZ38-BA38-BC38),(AZ38-BA38-BB38-BC38))+F38 -> 0 | BF38: =Z38*1/100*BG38 -> 0 | BG38: 11 | BN38: Confection rapport Annuel | BO38: Frais de taxi pour comité spéciale bureau
B40: A- RECAPITULATIF DES ENTREES | C40: =SUM(C6:C39) -> 126000 | D40: =SUM(D6:D39) -> 5356000 | E40: =SUM(E6:E39) -> 200000 | F40: =SUM(F6:F39) -> 0 | G40: =SUM(G6:G39) -> 0 | H40: =SUM(H6:H39) -> 0 | I40: =SUM(I6:I39) -> 755000 | J40: =SUM(J6:J39) -> 32 | ... S40: =SUM(S6:S39) -> 0 | U40: =SUM(U6:U39) -> 5430000 | V40: =SUM(V6:V39) -> 0 | W40: =SUM(W6:W39) -> 75000 | X40: =SUM(X6:X39) -> 0 | Y40: =SUM(Y6:Y39) -> 0 | Z40: =SUM(Z6:Z39) -> 2000000 | AA40: =SUM(AA6:AA39) -> 0 | AC40: =SUM(AC6:AC39) -> 38000 | AD40: =SUM(AD6:AD39) -> 125000 | AE40: =SUM(AE6:AE39) -> 355000 | AF40: =SUM(AF6:AF39) -> 0 | AG40: =SUM(AG6:AG39) -> 0 | AI40: =SUM(AI6:AI39) -> 0 | AJ40: =SUM(AJ6:AJ39) -> 200000 | AK40: =SUM(AK6:AK39) -> 100000 | AL40: =SUM(AL6:AL39) -> 0 | AM40: =SUM(AM6:AM39) -> 4000 | AN40: =SUM(AN6:AN39) -> 1000 | AO40: =SUM(AO6:AO39) -> 0 | AP40: =SUM(AP6:AP39) -> 0 | ... BF40: =SUM(BF6:BF39) -> 176000 | BH40: =SUM(BH6:BH39) -> 27000 | BI40: =SUM(BI6:BI39) -> 500000 | BJ40: =SUM(BJ6:BJ39) -> 0 | BK40: =SUM(BK6:BK39) -> 200000 | BL40: =SUM(BL6:BL39) -> 0 | BM40: =SUM(BM6:BM39) -> 0 | BN40: EPARGNE ASSURANCE DECES | BP40: =SUM(BP36:BP38) -> 100000
B43: ASSURANCE DECES | BN43: NDEFO PP | BO43: F. AIDE
...

Sheet HISTOFEV23
A1: TCHUIDJASSI | B1: Observation
A2: RECONSTITUTION | B2: 2024
A3: 1 | B3: 2 | C3: 3 | D3: 4 | E3: 5 | F3: 6 | G3: 7 | H3: 8 | I3: 9 | J3: 10 | K3: 11 | L3: 12 | M3: 13 | N3: 14 | O3: 15 | P3: 16 | Q3: 17 | R3: 18 | S3: 19 | T3: 20 | U3: 21 | V3: 22 | W3: 23 | X3: 24 | Y3: 25 | Z3: 26 | AA3: 27 | AB3: 28 | AC3: 29 | AD3: 30 | AE3: 31 | AF3: 32 | AG3: 33 | AH3: 34 | AI3: 35 | AJ3: 36 | AK3: 37 | AL3: 38 | AM3: 39 | AN3: 40 | AO3: 41 | AP3: 42 | AQ3: 43 | AR3: 44 | AS3: 45 | AT3: 46 | AU3: 47 | AV3: 48 | AW3: 49 | AX3: 50 | AY3: 51 | AZ3: 52 | BA3: 53 | BB3: 54 | BC3: 55 | BD3: 56 | BE3: 57 | BF3: 58 | BG3: 59 | BH3: 60 | BI3: 61 | BJ3: 62 | BK3: 63 | BL3: 64 | BM3: 65 | BN3: 66 | BO3: 67 | BP3: 68
B4: TOTAL AGIOS BANQUE
A5: DIBONJI | B5: MONTANT | C5: CONSTRUCTION | D5: NOMS ET PRENOMS | E5: INTERET /PART | F5: Date versement | G5: Contribution Retraite | H5: ASSURANCE | I5: SOH HENRI | J5: TONTINES | K5: REPARTITION DU SOLDE THEORIQUE EN CAISSE | L5: TONTINES | M5: JANVIER | N5: TONTINES | O5: FEVRIER | P5: aide mariage cheizing | Q5: AVRIL | R5: MARS | S5: NDEFO PIERRE PAUL | T5: NDANGA MATHIEU | U5: NGOUNOU MICHEL | V5: DJUOMBESSY | W5: INSCRIPTION | X5: TCHUENTE INGRID | Y5: MEGAPTCHE | Z5: F. FIXE | AA5: KAMGA JOSEPH | AB5: Ancienneté supérieur à 10 ans et membre de bureau | AC5: MVOLA | AD5: Compte secondaire | AE5: TCHI ROBERT | AF5: ACHAT TERRAIN | AG5: Ancienneté supérieur à 10 ans et membre de bureau | AH5: Contribution Retraite | AI5: Délégation (fumba et takougoum) | AJ5: REPAS | AK5: SANCTIONS | AL5: NGOUNOU | AM5: PRETS ASS NON REMBOURSES | AN5: Autres dettes | AO5: Ancienneté supérieur à 10 ans et membre de bureau | AP5: KOLOKO | AQ5: NDANGA | AR5: FOUTE | AS5: TCHUENTE LEOPOLD | AT5: F. AIDE | AU5: RECAPITULATIF DES AVOIRS EPARGNE ASSURANCE | AV5: NGATAT JEAN MARIE | AW5: WASO GEORGES | AX5: MONKAM VINCENT | AY5: KANKEU CHRETIEN | AZ5: MGBORON ISSIAKA | BA5: NOMBO SAKIO | BB5: Taux 50 KF | BC5: Interet Epargne Assurance Deces | BD5: Versement Fond Aide Nouveau membre | BE5: TCHOUTIO LEOPOLD | BF5: Fond Fixe Arouest Issue Tontines Arouest | BG5: Repartition des Entrées | BH5: Agios Bancaire | BI5: Répartition des Sorties | BJ5: Payement des Primes Fixe au Membre Arouest | BK5: TOTAL DES SORTIES | BL5: FOND AROUEST | BM5: SITUATION DE CAISSE DE AROUEST | BN5: BELL MARTINE | BO5: Frais de Fonctionnement Annuel Arouest | BP5: MASSE MONETAIRE
A6: Taux 100 KF | B6: =VLOOKUP(A6,[11]LISTADHERENT!A$5:H$50,3,0) -> ASELBY | C6: =D6+E6+F6-U6-BB6 -> 0 | D6: =VLOOKUP(A6,[12]HISTOBQUEFEV24!$A$6:$G$46,3,0) -> 175000 | E6: =VLOOKUP(A6,[12]HISTOBQUEFEV24!$A$6:$G$41,4,0) -> 0 | F6: =VLOOKUP(A6,[12]HISTOBQUEFEV24!$A$6:$G$41,5,0) -> 0 | G6: =IF(H6="ESPECES",3000,0) -> 0 | H6: =IF($D6<>0,"BANQUE",IF($E6<>0,"ESPECES","ECHEC")) -> BANQUE | K6: =IF($D6<>0,J6*50000,IF($E6<>0,J6*50000,0)) -> 0 | L6: 1 | M6: =IF($D6<>0,L6*75000,IF($E6<>0,L6*75000,0)) -> 75000 | N6: 1 | O6: =IF($D6<>0,N6*100000,IF($E6<>0,N6*100000,0)) -> 100000 | U6: =G6+S6++R6+P6+O6+M6+I6+K6+Q6+V6+W6 -> 175000 | AQ6: =IF(H6="ECHEC",((K6+M6+O6)*20/100),0) -> 0 | AR6: =IF(H6="ECHEC",((K6+M6+O6)*20/100),0) -> 0 | AW6: =IF(AC6=0,AI6,(1*25000*12)+AI6-AC6) -> 0 | AX6: =IF(AD6=0,AJ6,(1*75000*12)+(AJ6)-AD6) -> 0 | AY6: =IF(AE6=0,AK6,(1*100000*12)+(AK6)-AE6) -> 0 | AZ6: =SUM(AV6:AY6)-BF6+Z6-F6+BH6+BI6+BJ6+BK6+BL6+BM6 -> 227000 | BD6: =IF(AZ6=0,(AZ6-BA6-BC6),(AZ6-BA6-BB6-BC6)) -> 227000 | BF6: =Z6*1/100*BG6 -> 0 | BG6: 10 | BH6: =BP16 -> 27000 | BI6: =BP28 -> 0 | BJ6: =BP33 -> 100000 | BK6: =+BP40 -> 100000 | BM6: =BP22 -> 0 | BN6: OBSERVATIONS | BO6: LIBELLES | BP6: 3000
A7: RUBRIQUE AIDE | B7: =VLOOKUP(A7,[11]LISTADHERENT!A$5:H$50,3,0) -> BAKOP ACHILLE | C7: =D7+E7+F7-U7-BB7 -> 6000 | D7: =VLOOKUP(A7,[12]HISTOBQUEFEV24!$A$6:$G$46,3,0) -> 78000 | E7: =VLOOKUP(A7,[12]HISTOBQUEFEV24!$A$6:$G$41,4,0) -> 0 | F7: =VLOOKUP(A7,[12]HISTOBQUEFEV24!$A$6:$G$41,5,0) -> 0 | G7: =IF(H7="ESPECES",3000,0) -> 0 | H7: =IF($D7<>0,"BANQUE",IF($E7<>0,"ESPECES","ECHEC")) -> BANQUE | I7: 22000 | J7: 1 | K7: =IF($D7<>0,J7*50000,IF($E7<>0,J7*50000,0)) -> 50000 | M7: =IF($D7<>0,L7*75000,IF($E7<>0,L7*75000,0)) -> 0 | O7: =IF($D7<>0,N7*100000,IF($E7<>0,N7*100000,0)) -> 0 | P7: =VLOOKUP(A7,[14]TONTFEV24!$A$6:$R$39,12,0) -> 0 | U7: =G7+S7++R7+P7+O7+M7+I7+K7+Q7+V7+W7 -> 72000 | AI7: 60000 | AL7: 1000 | AQ7: =IF(H7="ECHEC",((K7+M7+O7)*20/100),0) -> 0 | AR7: =IF(H7="ECHEC",((K7+M7+O7)*20/100),0) -> 0 | AS7: =IF(H7="ECHEC",0,(K7+I7-25000)) -> 47000 | AW7: =IF(AC7=0,AI7,(1*25000*12)+AI7-AC7) -> 60000 | AX7: =IF(AD7=0,AJ7,(1*75000*12)+(AJ7)-AD7) -> 0 | AY7: =IF(AE7=0,AK7,(1*100000*12)+(AK7)-AE7) -> 0 | AZ7: =SUM(AV7:AY7)-BF7+Z7-F7+BH7+BI7+BJ7+BK7+BL7+BM7+6000 -> 60000 | BD7: =IF(AZ7=0,(AZ7-BA7-BC7),(AZ7-BA7-BB7-BC7)) -> 60000 | BF7: =Z7*1/100*BG7+6000 -> 6000 | BG7: 10 | BN7: Frais Communication SG | BO7: LIBELLES
A8: Mai | B8: =VLOOKUP(A8,[11]LISTADHERENT!A$5:H$50,3,0) -> BOUTCHOUANG WILLIAM | C8: =D8+E8+F8-U8-BB8 -> 3000 | D8: =VLOOKUP(A8,[12]HISTOBQUEFEV24!$A$6:$G$46,3,0) -> 100000 | E8: =VLOOKUP(A8,[12]HISTOBQUEFEV24!$A$6:$G$41,4,0) -> 25000 | F8: =VLOOKUP(A8,[12]HISTOBQUEFEV24!$A$6:$G$41,5,0) -> 0 | G8: =IF(H8="ESPECES",3000,0) -> 0 | H8: =IF($D8<>0,"BANQUE",IF($E8<>0,"ESPECES","ECHEC")) -> BANQUE | I8: -3000 | J8: 1 | K8: =IF($D8<>0,J8*50000,IF($E8<>0,J8*50000,0)) -> 50000 | L8: 1 | M8: =IF($D8<>0,L8*75000,IF($E8<>0,L8*75000,0)) -> 75000 | O8: =IF($D8<>0,N8*100000,IF($E8<>0,N8*100000,0)) -> 0 | P8: =VLOOKUP(A8,[14]TONTFEV24!$A$6:$R$39,12,0) -> 0 | Q8: =VLOOKUP(A8,[15]TONTFEV24!$A$7:$P$23,10,0) -> 0 | U8: =G8+S8++R8+P8+O8+M8+I8+K8+Q8+V8+W8 -> 122000 | AQ8: =IF(H8="ECHEC",((K8+M8+O8)*20/100),0) -> 0 | AR8: =IF(H8="ECHEC",((K8+M8+O8)*20/100),0) -> 0 | AS8: =IF(H8="ECHEC",0,(K8+I8-25000)) -> 22000 | AW8: =IF(AC8=0,AI8,(1*25000*12)+AI8-AC8) -> 0 | AX8: =IF(AD8=0,AJ8,(1*75000*12)+(AJ8)-AD8) -> 0 | AY8: =IF(AE8=0,AK8,(1*100000*12)+(AK8)-AE8) -> 0 | AZ8: =SUM(AV8:AY8)-BF8+Z8-F8+BH8+BI8+BJ8+BK8+BL8+BM8 -> 0 | BD8: =IF(AZ8=0,(AZ8-BA8-BC8),(AZ8-BA8-BB8-BC8)) -> 0 | BF8: =Z8*1/100*BG8 -> 0 | BG8: 10 | BN8: Frais Communication CC | BO8: LIBELLES | BP8: 12000
A9: NOMS | B9: =VLOOKUP(A9,[11]LISTADHERENT!A$5:H$50,3,0) -> DJOMO JEAN PAUL | C9: =D9+E9+F9-U9-BB9 -> 0 | D9: =VLOOKUP(A9,[12]HISTOBQUEFEV24!$A$6:$G$46,3,0) -> 250000 | E9: =VLOOKUP(A9,[12]HISTOBQUEFEV24!$A$6:$G$41,4,0) -> 0 | F9: =VLOOKUP(A9,[12]HISTOBQUEFEV24!$A$6:$G$41,5,0) -> 0 | G9: =IF(H9="ESPECES",3000,0) -> 0 | H9: =IF($D9<>0,"BANQUE",IF($E9<>0,"ESPECES","ECHEC")) -> BANQUE | J9: 1 | K9: =IF($D9<>0,J9*50000,IF($E9<>0,J9*50000,0)) -> 50000 | M9: =IF($D9<>0,L9*75000,IF($E9<>0,L9*75000,0)) -> 0 | N9: 2 | O9: =IF($D9<>0,N9*100000,IF($E9<>0,N9*100000,0)) -> 200000 | P9: =VLOOKUP(A9,[14]TONTFEV24!$A$6:$R$39,12,0) -> 0 | R9: =VLOOKUP(A9,[16]TONTFEV24!$A$7:$P$20,10,0) -> 0 | U9: =G9+S9++R9+P9+O9+M9+I9+K9+Q9+V9+W9 -> 250000 | AQ9: =IF(H9="ECHEC",((K9+M9+O9)*20/100),0) -> 0 | AR9: =IF(H9="ECHEC",((K9+M9+O9)*20/100),0) -> 0 | AS9: =IF(H9="ECHEC",0,(K9+I9-25000)) -> 25000 | AW9: =IF(AC9=0,AI9,(1*25000*12)+AI9-AC9) -> 0 | AX9: =IF(AD9=0,AJ9,(1*75000*12)+(AJ9)-AD9) -> 0 | AY9: =IF(AE9=0,AK9,(1*100000*12)+(AK9)-AE9) -> 0 | AZ9: =SUM(AV9:AY9)-BF9+Z9-F9+BH9+BI9+BJ9+BK9+BL9+BM9 -> 0 | BD9: =IF(AZ9=0,(AZ9-BA9-BC9),(AZ9-BA9-BB9-BC9)) -> 0 | BF9: =Z9*1/100*BG9 -> 0 | BG9: 10 | BN9: TONGA | BO9: LIBELLES
A10: JUIN | B10: =VLOOKUP(A10,[11]LISTADHERENT!A$5:H$50,3,0) -> DJOMOU TCHAPDA | C10: =D10+E10+F10-U10-BB10 -> 0 | D10: =VLOOKUP(A10,[12]HISTOBQUEFEV24!$A$6:$G$46,3,0) -> 125000 | E10: =VLOOKUP(A10,[12]HISTOBQUEFEV24!$A$6:$G$41,4,0) -> 105000 | F10: =VLOOKUP(A10,[12]HISTOBQUEFEV24!$A$6:$G$41,5,0) -> 0 | G10: =IF(H10="ESPECES",3000,0)+3000 -> 3000 | H10: =IF($D10<>0,"BANQUE",IF($E10<>0,"ESPECES","ECHEC")) -> BANQUE | J10: 1 | K10: =IF($D10<>0,J10*50000,IF($E10<>0,J10*50000,0)) -> 50000 | L10: 1 | M10: =IF($D10<>0,L10*75000,IF($E10<>0,L10*75000,0)) -> 75000 | O10: =IF($D10<>0,N10*100000,IF($E10<>0,N10*100000,0)) -> 0 | P10: =VLOOKUP(A10,[14]TONTFEV24!$A$6:$R$39,12,0) -> 0 | Q10: =VLOOKUP(A10,[15]TONTFEV24!$A$7:$P$23,10,0) -> 102000 | U10: =G10+S10++R10+P10+O10+M10+I10+K10+Q10+V10+W10 -> 230000 | AI10: 60000 | AL10: 1000 | AP10: Taux | AQ10: =IF(H10="ECHEC",((K10+M10+O10)*20/100),0) -> 0 | AR10: =IF(H10="ECHEC",((K10+M10+O10)*20/100),0) -> 0 | AS10: =IF(H10="ECHEC",0,(K10+I10-25000)) -> 25000 | AW10: =IF(AC10=0,AI10,(1*25000*12)+AI10-AC10) -> 60000 | AX10: =IF(AD10=0,AJ10,(1*75000*12)+(AJ10)-AD10) -> 0 | AY10: =IF(AE10=0,AK10,(1*100000*12)+(AK10)-AE10) -> 0 | AZ10: =SUM(AV10:AY10)-BF10+Z10-F10+BH10+BI10+BJ10+BK10+BL10+BM10 -> 60000 | BD10: =IF(AZ10=0,(AZ10-BA10-BC10),(AZ10-BA10-BB10-BC10)) -> 60000 | BF10: =Z10*1/100*BG10 -> 0 | BG10: 10 | BN10: Frais Communication Trésorier | BO10: LIBELLES
