Workbook
Name BANQUE: #REF!
Name BANQUE: #REF!
Name BANQUE: #REF!
Name BANQUE: #REF!
Name BANQUE: #REF!
Name BANQUE: #REF!
Name BANQUE: #REF!
Name BANQUE: #REF!
Name BANQUE: #REF!
Name BANQUE: #REF!
Name BANQUE: #REF!
Name BANQUE: #REF!
Name BANQUE: #REF!
Name BANQUE: #REF!
Name MODEPAID: MODEPAID!$A$1:$A$3
Name MODEPAID: [1]Feuil2!$A$1:$A$3
Name MODEPAID: [1]Feuil2!$A$1:$A$3
Name MODEPAID: [1]Feuil2!$A$1:$A$3
Name MODEPAID: [1]Feuil2!$A$1:$A$3
Name MODEPAID: [1]Feuil2!$A$1:$A$3
Name MODEPAID: [1]Feuil2!$A$1:$A$3
Name MODEPAID: [1]Feuil2!$A$1:$A$3
Name MODEPAID: [1]Feuil2!$A$1:$A$3
Name MODEPAID: [1]Feuil2!$A$1:$A$3
Name MODEPAID: [1]Feuil2!$A$1:$A$3
Name MODEPAID: [1]Feuil2!$A$1:$A$3
Name MODEPAID: [1]Feuil2!$A$1:$A$3
Name MODEPAID: [1]Feuil2!$A$1:$A$3
Name MODEPAID: #REF!
Name MODET25000: [2]MODEVERSEMENT!$A$1:$A$3
Name MODEVERSEMENT: #REF!
Name MODEVERSEMENT: #REF!
Name MODEVERSEMENT: #REF!
Name MODEVERSEMENT: #REF!
Name MODEVERSEMENT: #REF!
Name MODEVERSEMENT: #REF!
Name MODEVERSEMENT: #REF!
Name MODEVERSEMENT: #REF!
Name MODEVERSEMENT: #REF!
Name MODEVERSEMENT: #REF!
Name MODEVERSEMENT: #REF!
Name MODEVERSEMENT: #REF!
Name MODEVERSEMENT: #REF!
Name MODEVERSEMENT: #REF!
Name MODEVERSEMENTS: [3]MODEVERSEMENT!$A$1:$A$3
Name MODEVERSEMENTS: [3]MODEVERSEMENT!$A$1:$A$3
Name MODEVERSEMENTS: [3]MODEVERSEMENT!$A$1:$A$3
Name MODEVERSEMENTS: [3]MODEVERSEMENT!$A$1:$A$3
Name MODEVERSEMENTS: [3]MODEVERSEMENT!$A$1:$A$3
Name MODEVERSEMENTS: [3]MODEVERSEMENT!$A$1:$A$3
Name MODEVERSEMENTS: [3]MODEVERSEMENT!$A$1:$A$3
Name MODEVERSEMENTS: [3]MODEVERSEMENT!$A$1:$A$3
Name MODEVERSEMENTS: [3]MODEVERSEMENT!$A$1:$A$3
Name MODEVERSEMENTS: [3]MODEVERSEMENT!$A$1:$A$3
Name MODEVERSEMENTS: [3]MODEVERSEMENT!$A$1:$A$3
Name MODEVERSEMENTS: [3]MODEVERSEMENT!$A$1:$A$3
Name MODEVERSEMENTS: [3]MODEVERSEMENT!$A$1:$A$3
Name MODEVERSEMENTS: [4]MODEVERSEMENT!$A$1:$A$3
Name MODPAID: TONTAOUT23!#REF!
Name MODPAID: TONTAVRIL23!#REF!

Sheet MODEPAID
A1: BANQUE
A2: ESPECES
A3: ECHEC

Sheet TONTJANV23
A1: ASSOCIATION | B1: ASELBY
A2: ANNEE | B2: 2023 | C2: TONIINE | D2: NBRE PART
A3: TAUX TONTINE | B3: 75000 | C3: =B3*12 -> 900000 | D3: =ROUNDDOWN(K25/C3,0) -> 1
C4: 44939
A5: MATRICULE | B5: NBREPART | C5: NOM ET PRENOM | D5: MONTANT TONTINE | E5: MODE VERSEMENT | F5: VENTE PETIT LOT | G5: INTERET PETIT LOT | H5: MODE VERSEMENT VENTE PETIT LOT | I5: NUMERO CHEQUE | J5: MONTANT A REMBOURSER PETIT LOT | K5: REMBOURSEMENT PETIT LOT | L5: MODE VERSEMENT REMBOURSEMENT | M5: MODE VERSEMENTLOT PRINCIPAL | N5: NUMERO CHEQUE | O5: MONTANT LOT PRINCIPAL | P5: INTERET LOT PRINCIPAL
A6: AS201648 | B6: =IF(D6=0,0,VLOOKUP($A6,[6]HISTOJANV23!$A$6:$BB$45,12,0)) -> 1 | C6: =VLOOKUP(A6,[7]LISTADHERENT!A$5:H$60,3,0) -> ASELBY | D6: =IF(E6="ECHEC",0,VLOOKUP($A6,[6]HISTOJANV23!$A$6:$AR$45,13,0)) -> 75000 | E6: =VLOOKUP($A6,[6]HISTOJANV23!$A$6:$AV$45,8,0) -> BANQUE | F6: =VLOOKUP($A6,[6]HISTOJANV23!$A$6:$AV$45,36,0) -> 0 | G6: =VLOOKUP($A6,[6]HISTOJANV23!$A$6:$AV$45,39,0) -> 0 | H6: =IF(G6=0,0,VLOOKUP($A6,[6]HISTOJANV23!$A$6:$AV$45,42,0)) -> 0 | I6: =VLOOKUP($A6,[6]HISTOJANV23!$A$6:$AV$45,41,0) -> 0 | K6: =VLOOKUP($A6,[6]HISTOJANV23!$A$6:$AV$45,17,0) -> 0 | L6: =IF(K6<>0,VLOOKUP($A6,[6]HISTOJANV23!$A$6:$BB$45,8,0),"ECHEC") -> ECHEC | M6: =IF(P6=0,0,VLOOKUP($A6,[6]HISTOJANV23!$A$6:$AV$45,32,0)) -> 0 | N6: =VLOOKUP($A6,[6]HISTOJANV23!$A$6:$AV$45,33,0) -> 0 | O6: =IF(P6=0,0,($C$3-P6)) -> 0 | P6: =VLOOKUP($A6,[6]HISTOJANV23!$A$6:$AV$45,30,0) -> 0
A7: AS201602 | B7: =IF(D7=0,0,VLOOKUP($A7,[6]HISTOJANV23!$A$6:$BB$45,12,0)) -> 1 | C7: =VLOOKUP(A7,[7]LISTADHERENT!A$5:H$60,3,0) -> BOUTCHOUANG WILLIAM | D7: =IF(E7="ECHEC",0,VLOOKUP($A7,[6]HISTOJANV23!$A$6:$AR$45,13,0)) -> 75000 | E7: =VLOOKUP($A7,[6]HISTOJANV23!$A$6:$AV$45,8,0) -> BANQUE | F7: =VLOOKUP($A7,[6]HISTOJANV23!$A$6:$AV$45,36,0) -> 0 | G7: =VLOOKUP($A7,[6]HISTOJANV23!$A$6:$AV$45,39,0) -> 0 | H7: =IF(G7=0,0,VLOOKUP($A7,[6]HISTOJANV23!$A$6:$AV$45,42,0)) -> 0 | I7: =VLOOKUP($A7,[6]HISTOJANV23!$A$6:$AV$45,41,0) -> 0 | K7: =VLOOKUP($A7,[6]HISTOJANV23!$A$6:$AV$45,17,0) -> 0 | L7: =IF(K7<>0,VLOOKUP($A7,[6]HISTOJANV23!$A$6:$BB$45,8,0),"ECHEC") -> ECHEC | M7: =IF(P7=0,0,VLOOKUP($A7,[6]HISTOJANV23!$A$6:$AV$45,32,0)) -> 0 | N7: =VLOOKUP($A7,[6]HISTOJANV23!$A$6:$AV$45,33,0) -> 0 | O7: =IF(P7=0,0,($C$3-P7)) -> 0 | P7: =VLOOKUP($A7,[6]HISTOJANV23!$A$6:$AV$45,30,0) -> 0
A8: AS201605 | B8: =IF(D8=0,0,VLOOKUP($A8,[6]HISTOJANV23!$A$6:$BB$45,12,0)) -> 1 | C8: =VLOOKUP(A8,[7]LISTADHERENT!A$5:H$60,3,0) -> DJOUKWE NANGUEN GUY BLAISE | D8: =IF(E8="ECHEC",0,VLOOKUP($A8,[6]HISTOJANV23!$A$7:$AR$45,13,0)) -> 75000 | E8: =VLOOKUP($A8,[6]HISTOJANV23!$A$7:$AV$45,8,0) -> BANQUE | F8: =VLOOKUP($A8,[6]HISTOJANV23!$A$6:$AV$45,36,0) -> 0 | G8: =VLOOKUP($A8,[6]HISTOJANV23!$A$6:$AV$45,39,0) -> 0 | H8: =IF(G8=0,0,VLOOKUP($A8,[6]HISTOJANV23!$A$6:$AV$45,42,0)) -> 0 | I8: =VLOOKUP($A8,[6]HISTOJANV23!$A$6:$AV$45,41,0) -> 0 | K8: =VLOOKUP($A8,[6]HISTOJANV23!$A$6:$AV$45,17,0) -> 0 | L8: =IF(K8<>0,VLOOKUP($A8,[6]HISTOJANV23!$A$6:$BB$45,8,0),"ECHEC") -> ECHEC | M8: =IF(P8=0,0,VLOOKUP($A8,[6]HISTOJANV23!$A$6:$AV$45,32,0)) -> 0 | N8: =VLOOKUP($A8,[6]HISTOJANV23!$A$6:$AV$45,33,0) -> 0 | O8: =IF(P8=0,0,($C$3-P8)) -> 0 | P8: =VLOOKUP($A8,[6]HISTOJANV23!$A$6:$AV$45,30,0) -> 0
A9: AS201608 | B9: =IF(D9=0,0,VLOOKUP($A9,[6]HISTOJANV23!$A$6:$BB$45,12,0)) -> 1 | C9: =VLOOKUP(A9,[7]LISTADHERENT!A$5:H$60,3,0) -> DJUOMBESSY ANTOINE | D9: =IF(E9="ECHEC",0,VLOOKUP($A9,[6]HISTOJANV23!$A$7:$AR$45,13,0)) -> 75000 | E9: =VLOOKUP($A9,[6]HISTOJANV23!$A$7:$AV$45,8,0) -> BANQUE | F9: =VLOOKUP($A9,[6]HISTOJANV23!$A$6:$AV$45,36,0) -> 0 | G9: =VLOOKUP($A9,[6]HISTOJANV23!$A$6:$AV$45,39,0) -> 0 | H9: =IF(G9=0,0,VLOOKUP($A9,[6]HISTOJANV23!$A$6:$AV$45,42,0)) -> 0 | I9: =VLOOKUP($A9,[6]HISTOJANV23!$A$6:$AV$45,41,0) -> 0 | K9: =VLOOKUP($A9,[6]HISTOJANV23!$A$6:$AV$45,17,0) -> 0 | L9: =IF(K9<>0,VLOOKUP($A9,[6]HISTOJANV23!$A$6:$BB$45,8,0),"ECHEC") -> ECHEC | M9: =IF(P9=0,0,VLOOKUP($A9,[6]HISTOJANV23!$A$6:$AV$45,32,0)) -> 0 | N9: =VLOOKUP($A9,[6]HISTOJANV23!$A$6:$AV$45,33,0) -> 0 | O9: =IF(P9=0,0,($C$3-P9)) -> 0 | P9: =VLOOKUP($A9,[6]HISTOJANV23!$A$6:$AV$45,30,0) -> 0
A10: AS201613 | B10: =IF(D10=0,0,VLOOKUP($A10,[6]HISTOJANV23!$A$6:$BB$45,12,0)) -> 1 | C10: =VLOOKUP(A10,[7]LISTADHERENT!A$5:H$60,3,0) -> HOTCHO BENJAMIN | D10: =IF(E10="ECHEC",0,VLOOKUP($A10,[6]HISTOJANV23!$A$7:$AR$45,13,0)) -> 75000 | E10: =VLOOKUP($A10,[6]HISTOJANV23!$A$7:$AV$45,8,0) -> BANQUE | F10: =VLOOKUP($A10,[6]HISTOJANV23!$A$6:$AV$45,36,0) -> 0 | G10: =VLOOKUP($A10,[6]HISTOJANV23!$A$6:$AV$45,39,0) -> 0 | H10: =IF(G10=0,0,VLOOKUP($A10,[6]HISTOJANV23!$A$6:$AV$45,42,0)) -> 0 | I10: =VLOOKUP($A10,[6]HISTOJANV23!$A$6:$AV$45,41,0) -> 0 | K10: =VLOOKUP($A10,[6]HISTOJANV23!$A$6:$AV$45,17,0) -> 0 | L10: =IF(K10<>0,VLOOKUP($A10,[6]HISTOJANV23!$A$6:$BB$45,8,0),"ECHEC") -> ECHEC | M10: =IF(P10=0,0,VLOOKUP($A10,[6]HISTOJANV23!$A$6:$AV$45,32,0)) -> 0 | N10: =VLOOKUP($A10,[6]HISTOJANV23!$A$6:$AV$45,33,0) -> 0 | O10: =IF(P10=0,0,($C$3-P10)) -> 0 | P10: =VLOOKUP($A10,[6]HISTOJANV23!$A$6:$AV$45,30,0) -> 0
A11: AS201611 | B11: =IF(D11=0,0,VLOOKUP($A11,[6]HISTOJANV23!$A$6:$BB$45,12,0)) -> 1 | C11: =VLOOKUP(A11,[7]LISTADHERENT!A$5:H$60,3,0) -> HENGUE PAUL OMER | D11: =IF(E11="ECHEC",0,VLOOKUP($A11,[6]HISTOJANV23!$A$7:$AR$45,13,0)) -> 75000 | E11: =VLOOKUP($A11,[6]HISTOJANV23!$A$7:$AV$45,8,0) -> BANQUE | F11: =VLOOKUP($A11,[6]HISTOJANV23!$A$6:$AV$45,36,0) -> 0 | G11: =VLOOKUP($A11,[6]HISTOJANV23!$A$6:$AV$45,39,0) -> 0 | H11: =IF(G11=0,0,VLOOKUP($A11,[6]HISTOJANV23!$A$6:$AV$45,42,0)) -> 0 | I11: =VLOOKUP($A11,[6]HISTOJANV23!$A$6:$AV$45,41,0) -> 0 | K11: =VLOOKUP($A11,[6]HISTOJANV23!$A$6:$AV$45,17,0) -> 0 | L11: =IF(K11<>0,VLOOKUP($A11,[6]HISTOJANV23!$A$6:$BB$45,8,0),"ECHEC") -> ECHEC | M11: =IF(P11=0,0,VLOOKUP($A11,[6]HISTOJANV23!$A$6:$AV$45,32,0)) -> 0 | N11: =VLOOKUP($A11,[6]HISTOJANV23!$A$6:$AV$45,33,0) -> 0 | O11: =IF(P11=0,0,($C$3-P11)) -> 0 | P11: =VLOOKUP($A11,[6]HISTOJANV23!$A$6:$AV$45,30,0) -> 0
A12: AS201619 | B12: =IF(D12=0,0,VLOOKUP($A12,[6]HISTOJANV23!$A$6:$BB$45,12,0)) -> 1 | C12: =VLOOKUP(A12,[7]LISTADHERENT!A$5:H$60,3,0) -> KOUATCHO MESSACK | D12: =IF(E12="ECHEC",0,VLOOKUP($A12,[6]HISTOJANV23!$A$7:$AR$45,13,0)) -> 75000 | E12: =VLOOKUP($A12,[6]HISTOJANV23!$A$7:$AV$45,8,0) -> BANQUE | F12: =VLOOKUP($A12,[6]HISTOJANV23!$A$6:$AV$45,36,0) -> 100000 | G12: =VLOOKUP($A12,[6]HISTOJANV23!$A$6:$AV$45,39,0) -> 2000 | H12: =IF(G12=0,0,VLOOKUP($A12,[6]HISTOJANV23!$A$6:$AV$45,42,0)) -> BANQUE | I12: =VLOOKUP($A12,[6]HISTOJANV23!$A$6:$AV$45,41,0) -> 0 | K12: =VLOOKUP($A12,[6]HISTOJANV23!$A$6:$AV$45,17,0) -> 0 | L12: =IF(K12<>0,VLOOKUP($A12,[6]HISTOJANV23!$A$6:$BB$45,8,0),"ECHEC") -> ECHEC | M12: =IF(P12=0,0,VLOOKUP($A12,[6]HISTOJANV23!$A$6:$AV$45,32,0)) -> 0 | N12: =VLOOKUP($A12,[6]HISTOJANV23!$A$6:$AV$45,33,0) -> 0 | O12: =IF(P12=0,0,($C$3-P12)) -> 0 | P12: =VLOOKUP($A12,[6]HISTOJANV23!$A$6:$AV$45,30,0) -> 0
A13: AS201649 | B13: =IF(D13=0,0,VLOOKUP($A13,[6]HISTOJANV23!$A$6:$BB$45,12,0)) -> 1 | C13: =VLOOKUP(A13,[7]LISTADHERENT!A$5:H$60,3,0) -> MBOGNING TUGMA GUY | D13: =IF(E13="ECHEC",0,VLOOKUP($A13,[6]HISTOJANV23!$A$7:$AR$45,13,0)) -> 75000 | E13: =VLOOKUP($A13,[6]HISTOJANV23!$A$7:$AV$45,8,0) -> BANQUE | F13: =VLOOKUP($A13,[6]HISTOJANV23!$A$6:$AV$45,36,0) -> 105000 | G13: =VLOOKUP($A13,[6]HISTOJANV23!$A$6:$AV$45,39,0) -> 2000 | H13: =IF(G13=0,0,VLOOKUP($A13,[6]HISTOJANV23!$A$6:$AV$45,42,0)) -> BANQUE | I13: =VLOOKUP($A13,[6]HISTOJANV23!$A$6:$AV$45,41,0) -> 0 | K13: =VLOOKUP($A13,[6]HISTOJANV23!$A$6:$AV$45,17,0) -> 0 | L13: =IF(K13<>0,VLOOKUP($A13,[6]HISTOJANV23!$A$6:$BB$45,8,0),"ECHEC") -> ECHEC | M13: =IF(P13=0,0,VLOOKUP($A13,[6]HISTOJANV23!$A$6:$AV$45,32,0)) -> 0 | N13: =VLOOKUP($A13,[6]HISTOJANV23!$A$6:$AV$45,33,0) -> 0 | O13: =IF(P13=0,0,($C$3-P13)) -> 0 | P13: =VLOOKUP($A13,[6]HISTOJANV23!$A$6:$AV$45,30,0) -> 0
A14: AS201621 | B14: =IF(D14=0,0,VLOOKUP($A14,[6]HISTOJANV23!$A$6:$BB$45,12,0)) -> 1 | C14: =VLOOKUP(A14,[7]LISTADHERENT!A$5:H$60,3,0) -> NANKAM APPOLINAIRE | D14: =IF(E14="ECHEC",0,VLOOKUP($A14,[6]HISTOJANV23!$A$7:$AR$45,13,0)) -> 75000 | E14: =VLOOKUP($A14,[6]HISTOJANV23!$A$7:$AV$45,8,0) -> BANQUE | F14: =VLOOKUP($A14,[6]HISTOJANV23!$A$6:$AV$45,36,0) -> 0 | G14: =VLOOKUP($A14,[6]HISTOJANV23!$A$6:$AV$45,39,0) -> 0 | H14: =IF(G14=0,0,VLOOKUP($A14,[6]HISTOJANV23!$A$6:$AV$45,42,0)) -> 0 | I14: =VLOOKUP($A14,[6]HISTOJANV23!$A$6:$AV$45,41,0) -> 0 | K14: =VLOOKUP($A14,[6]HISTOJANV23!$A$6:$AV$45,17,0) -> 0 | L14: =IF(K14<>0,VLOOKUP($A14,[6]HISTOJANV23!$A$6:$BB$45,8,0),"ECHEC") -> ECHEC | M14: =IF(P14=0,0,VLOOKUP($A14,[6]HISTOJANV23!$A$6:$AV$45,32,0)) -> 0 | N14: =VLOOKUP($A14,[6]HISTOJANV23!$A$6:$AV$45,33,0) -> 0 | O14: =IF(P14=0,0,($C$3-P14)) -> 0 | P14: =VLOOKUP($A14,[6]HISTOJANV23!$A$6:$AV$45,30,0) -> 0
A15: AS201624 | B15: =IF(D15=0,0,VLOOKUP($A15,[6]HISTOJANV23!$A$6:$BB$45,12,0)) -> 1 | C15: =VLOOKUP(A15,[7]LISTADHERENT!A$5:H$60,3,0) -> NGONDIEP CLAUDE | D15: =IF(E15="ECHEC",0,VLOOKUP($A15,[6]HISTOJANV23!$A$7:$AR$45,13,0)) -> 75000 | E15: =VLOOKUP($A15,[6]HISTOJANV23!$A$7:$AV$45,8,0) -> BANQUE | F15: =VLOOKUP($A15,[6]HISTOJANV23!$A$6:$AV$45,36,0) -> 100000 | G15: =VLOOKUP($A15,[6]HISTOJANV23!$A$6:$AV$45,39,0) -> 2000 | H15: =IF(G15=0,0,VLOOKUP($A15,[6]HISTOJANV23!$A$6:$AV$45,42,0)) -> BANQUE | I15: =VLOOKUP($A15,[6]HISTOJANV23!$A$6:$AV$45,41,0) -> 0 | K15: =VLOOKUP($A15,[6]HISTOJANV23!$A$6:$AV$45,17,0) -> 0 | L15: =IF(K15<>0,VLOOKUP($A15,[6]HISTOJANV23!$A$6:$BB$45,8,0),"ECHEC") -> ECHEC | M15: =IF(P15=0,0,VLOOKUP($A15,[6]HISTOJANV23!$A$6:$AV$45,32,0)) -> BANQUE | N15: =VLOOKUP($A15,[6]HISTOJANV23!$A$6:$AV$45,33,0) -> 0 | O15: =IF(P15=0,0,($C$3-P15)) -> 795000 | P15: =VLOOKUP($A15,[6]HISTOJANV23!$A$6:$AV$45,30,0) -> 105000
A16: AS201626 | B16: =IF(D16=0,0,VLOOKUP($A16,[6]HISTOJANV23!$A$6:$BB$45,12,0)) -> 2 | C16: =VLOOKUP(A16,[7]LISTADHERENT!A$5:H$60,3,0) -> NGUIEMEGNI MATHIEU BLAISE | D16: =IF(E16="ECHEC",0,VLOOKUP($A16,[6]HISTOJANV23!$A$7:$AR$45,13,0)) -> 150000 | E16: =VLOOKUP($A16,[6]HISTOJANV23!$A$7:$AV$45,8,0) -> BANQUE | F16: =VLOOKUP($A16,[6]HISTOJANV23!$A$6:$AV$45,36,0) -> 100000 | G16: =VLOOKUP($A16,[6]HISTOJANV23!$A$6:$AV$45,39,0) -> 2000 | H16: =IF(G16=0,0,VLOOKUP($A16,[6]HISTOJANV23!$A$6:$AV$45,42,0)) -> BANQUE | I16: =VLOOKUP($A16,[6]HISTOJANV23!$A$6:$AV$45,41,0) -> 0 | K16: =VLOOKUP($A16,[6]HISTOJANV23!$A$6:$AV$45,17,0) -> 0 | L16: =IF(K16<>0,VLOOKUP($A16,[6]HISTOJANV23!$A$6:$BB$45,8,0),"ECHEC") -> ECHEC | M16: =IF(P16=0,0,VLOOKUP($A16,[6]HISTOJANV23!$A$6:$AV$45,32,0)) -> 0 | N16: =VLOOKUP($A16,[6]HISTOJANV23!$A$6:$AV$45,33,0) -> 0 | O16: =IF(P16=0,0,($C$3-P16)) -> 0 | P16: =VLOOKUP($A16,[6]HISTOJANV23!$A$6:$AV$45,30,0) -> 0
A17: AS201633 | B17: =IF(D17=0,0,VLOOKUP($A17,[6]HISTOJANV23!$A$6:$BB$45,12,0)) -> 1 | C17: =VLOOKUP(A17,[7]LISTADHERENT!A$5:H$60,3,0) -> PATEGO NJOSSU GUSTAVE | D17: =IF(E17="ECHEC",0,VLOOKUP($A17,[6]HISTOJANV23!$A$7:$AR$45,13,0)) -> 75000 | E17: =VLOOKUP($A17,[6]HISTOJANV23!$A$7:$AV$45,8,0) -> BANQUE | F17: =VLOOKUP($A17,[6]HISTOJANV23!$A$6:$AV$45,36,0) -> 0 | G17: =VLOOKUP($A17,[6]HISTOJANV23!$A$6:$AV$45,39,0) -> 0 | H17: =IF(G17=0,0,VLOOKUP($A17,[6]HISTOJANV23!$A$6:$AV$45,42,0)) -> 0 | I17: =VLOOKUP($A17,[6]HISTOJANV23!$A$6:$AV$45,41,0) -> 0 | K17: =VLOOKUP($A17,[6]HISTOJANV23!$A$6:$AV$45,17,0) -> 0 | L17: =IF(K17<>0,VLOOKUP($A17,[6]HISTOJANV23!$A$6:$BB$45,8,0),"ECHEC") -> ECHEC | M17: =IF(P17=0,0,VLOOKUP($A17,[6]HISTOJANV23!$A$6:$AV$45,32,0)) -> 0 | N17: =VLOOKUP($A17,[6]HISTOJANV23!$A$6:$AV$45,33,0) -> 0 | O17: =IF(P17=0,0,($C$3-P17)) -> 0 | P17: =VLOOKUP($A17,[6]HISTOJANV23!$A$6:$AV$45,30,0) -> 0
A18: AS201653 | B18: =IF(D18=0,0,VLOOKUP($A18,[6]HISTOJANV23!$A$6:$BB$45,12,0)) -> 1 | C18: =VLOOKUP(A18,[7]LISTADHERENT!A$5:H$60,3,0) -> SIME BRICE | D18: =IF(E18="ECHEC",0,VLOOKUP($A18,[6]HISTOJANV23!$A$7:$AR$45,13,0)) -> 75000 | E18: =VLOOKUP($A18,[6]HISTOJANV23!$A$7:$AV$45,8,0) -> ESPECES | F18: =VLOOKUP($A18,[6]HISTOJANV23!$A$6:$AV$45,36,0) -> 0 | G18: =VLOOKUP($A18,[6]HISTOJANV23!$A$6:$AV$45,39,0) -> 0 | H18: =IF(G18=0,0,VLOOKUP($A18,[6]HISTOJANV23!$A$6:$AV$45,42,0)) -> 0 | I18: =VLOOKUP($A18,[6]HISTOJANV23!$A$6:$AV$45,41,0) -> 0 | K18: =VLOOKUP($A18,[6]HISTOJANV23!$A$6:$AV$45,17,0) -> 0 | L18: =IF(K18<>0,VLOOKUP($A18,[6]HISTOJANV23!$A$6:$BB$45,8,0),"ECHEC") -> ECHEC | M18: =IF(P18=0,0,VLOOKUP($A18,[6]HISTOJANV23!$A$6:$AV$45,32,0)) -> 0 | N18: =VLOOKUP($A18,[6]HISTOJANV23!$A$6:$AV$45,33,0) -> 0 | O18: =IF(P18=0,0,($C$3-P18)) -> 0 | P18: =VLOOKUP($A18,[6]HISTOJANV23!$A$6:$AV$45,30,0) -> 0
A19: AS201641 | B19: =IF(D19=0,0,VLOOKUP($A19,[6]HISTOJANV23!$A$6:$BB$45,12,0)) -> 1 | C19: =VLOOKUP(A19,[7]LISTADHERENT!A$5:H$60,3,0) -> TCHOUAMOU MATHIEU | D19: =IF(E19="ECHEC",0,VLOOKUP($A19,[6]HISTOJANV23!$A$7:$AR$45,13,0)) -> 75000 | E19: =VLOOKUP($A19,[6]HISTOJANV23!$A$7:$AV$45,8,0) -> BANQUE | F19: =VLOOKUP($A19,[6]HISTOJANV23!$A$6:$AV$45,36,0) -> 0 | G19: =VLOOKUP($A19,[6]HISTOJANV23!$A$6:$AV$45,39,0) -> 0 | H19: =IF(G19=0,0,VLOOKUP($A19,[6]HISTOJANV23!$A$6:$AV$45,42,0)) -> 0 | I19: =VLOOKUP($A19,[6]HISTOJANV23!$A$6:$AV$45,41,0) -> 0 | K19: =VLOOKUP($A19,[6]HISTOJANV23!$A$6:$AV$45,17,0) -> 0 | L19: =IF(K19<>0,VLOOKUP($A19,[6]HISTOJANV23!$A$6:$BB$45,8,0),"ECHEC") -> ECHEC | M19: =IF(P19=0,0,VLOOKUP($A19,[6]HISTOJANV23!$A$6:$AV$45,32,0)) -> 0 | N19: =VLOOKUP($A19,[6]HISTOJANV23!$A$6:$AV$45,33,0) -> 0 | O19: =IF(P19=0,0,($C$3-P19)) -> 0 | P19: =VLOOKUP($A19,[6]HISTOJANV23!$A$6:$AV$45,30,0) -> 0
A20: AS201647 | B20: =IF(D20=0,0,VLOOKUP($A20,[6]HISTOJANV23!$A$6:$BB$45,12,0)) -> 2 | C20: =VLOOKUP(A20,[7]LISTADHERENT!A$5:H$60,3,0) -> YOUMBI EMMANUEL | D20: =IF(E20="ECHEC",0,VLOOKUP($A20,[6]HISTOJANV23!$A$7:$AR$45,13,0)) -> 150000 | E20: =VLOOKUP($A20,[6]HISTOJANV23!$A$7:$AV$45,8,0) -> BANQUE | F20: =VLOOKUP($A20,[6]HISTOJANV23!$A$6:$AV$45,36,0) -> 0 | G20: =VLOOKUP($A20,[6]HISTOJANV23!$A$6:$AV$45,39,0) -> 0 | H20: =IF(G20=0,0,VLOOKUP($A20,[6]HISTOJANV23!$A$6:$AV$45,42,0)) -> 0 | I20: =VLOOKUP($A20,[6]HISTOJANV23!$A$6:$AV$45,41,0) -> 0 | K20: =VLOOKUP($A20,[6]HISTOJANV23!$A$6:$AV$45,17,0) -> 0 | L20: =IF(K20<>0,VLOOKUP($A20,[6]HISTOJANV23!$A$6:$BB$45,8,0),"ECHEC") -> ECHEC | M20: =IF(P20=0,0,VLOOKUP($A20,[6]HISTOJANV23!$A$6:$AV$45,32,0)) -> 0 | N20: =VLOOKUP($A20,[6]HISTOJANV23!$A$6:$AV$45,33,0) -> 0 | O20: =IF(P20=0,0,($C$3-P20)) -> 0 | P20: =VLOOKUP($A20,[6]HISTOJANV23!$A$6:$AV$45,30,0) -> 0
A22: TOTAL PART | B22: =SUM(B6:B21) -> 17
A23: NBRE ADHERENT | B23: =COUNT(D6:D21) -> 15 | D23: =SUM(D6:D22) -> 1275000 | E23: =SUM(E6:E22) -> 0 | F23: =SUM(F6:F22) -> 405000 | G23: =SUM(G6:G22) -> 8000 | H23: =SUM(H6:H22) -> 0 | I23: =SUM(I6:I22) -> 0 | J23: =SUM(J6:J22) -> 0 | K23: =SUM(K6:K22) -> 0 | ... P23: =SUM(P6:P22) -> 105000
L24: NBRE PART | M24: PART VENDUE
D25: MONTANT TONTINE | E25: REMBOURSEMENT PETIT LOT | F25: VENTE PETIT LOT | G25: VENTE LOT PRINCIPAL | H25: SOLDE EN CAISSE | J25: TONTINE + REMB + INTERET VENTE+RELIQUAT | K25: =D29+E29+P23 -> 1380000
D26: =SUMIFS(D6:D22,E6:E22,"ESPECES") -> 75000 | E26: =SUMIFS(K7:K17,L7:L17,"ESPECES") -> 0 | F26: =SUMIFS(F7:F22,H7:H22,"ESPECES") -> 0 | G26: =SUMIFS(O7:O22,M7:M22,"ESPECES") -> 0 | H26: =D26+E26-F26-G26 -> 75000 | J26: LOT PRINCIPAL | K26: =C3*COUNTIF(O7:O22,">0") -> 900000 | L26: =D3 -> 1 | M26: =COUNTIF(O7:O17,">0") -> 1
D27: =SUMIFS(D6:D22,E6:E22,"BANQUE") -> 1200000 | E27: =SUMIFS(K7:K17,L7:L17,"BANQUE") -> 0 | F27: =SUMIFS(F7:F22,H7:H22,"BANQUE") -> 405000 | G27: =SUMIFS(O7:O22,M7:M22,"BANQUE") -> 795000 | H27: =D27+E27-F27-G27 -> 0
J28: PETIT LOT | K28: =K25-K26 -> 480000
D29: =D26+D27 -> 1275000 | E29: =E26+E27 -> 0 | F29: =F26+F27 -> 405000 | G29: =G26+G27 -> 795000 | H29: =H26+H27 -> 75000
J30: RELIQUAT | K30: =K28-F23 -> 75000 | M30: =K30 -> 75000 | N30: CUMUL
J32: ECHEC TONTINE MOIS | K32: =COUNTIFS(E7:E21,"ECHEC")*75000 -> 0 | M32: =+K32 -> 0 | N32: CUMUL
J33: ECHEC REMBOURSEMENT MOIS | K33: =J23-E29 -> 0 | M33: =+K33 -> 0 | N33: CUMUL

Sheet TONTFEV23
A1: ASSOCIATION | B1: ASELBY
A2: ANNEE | B2: 2023 | C2: TONIINE | D2: NBRE PART
A3: TAUX TONTINE | B3: 75000 | C3: =B3*12 -> 900000 | D3: =ROUNDDOWN(K25/C3,0) -> 2
C4: 44970
A5: MATRICULE | B5: NBREPART | C5: NOM ET PRENOM | D5: MONTANT TONTINE | E5: MODE VERSEMENT | F5: VENTE PETIT LOT | G5: INTERET PETIT LOT | H5: MODE VERSEMENT VENTE PETIT LOT | I5: NUMERO CHEQUE | J5: MONTANT A REMBOURSER PETIT LOT | K5: REMBOURSEMENT PETIT LOT | L5: MODE VERSEMENT REMBOURSEMENT | M5: MODE VERSEMENTLOT PRINCIPAL | N5: NUMERO CHEQUE | O5: MONTANT LOT PRINCIPAL | P5: INTERET LOT PRINCIPAL
A6: AS201648 | B6: =IF(D6=0,0,VLOOKUP($A6,[6]HISTOFEV23!$A$6:$BB$45,12,0)) -> 1 | C6: =VLOOKUP(A6,[7]LISTADHERENT!A$5:H$60,3,0) -> ASELBY | D6: =IF(E6="ECHEC",0,VLOOKUP($A6,[6]HISTOFEV23!$A$6:$AR$45,13,0)) -> 75000 | E6: =VLOOKUP($A6,[6]HISTOFEV23!$A$6:$AV$45,8,0) -> BANQUE | F6: =VLOOKUP($A6,[6]HISTOFEV23!$A$6:$AV$45,36,0) -> 0 | G6: =VLOOKUP($A6,[6]HISTOFEV23!$A$6:$AV$45,39,0) -> 0 | H6: =IF(G6=0,0,VLOOKUP($A6,[6]HISTOFEV23!$A$6:$AV$45,42,0)) -> 0 | I6: =VLOOKUP($A6,[6]HISTOFEV23!$A$6:$AV$45,41,0) -> 0 | J6: =TONTJANV23!F6+TONTJANV23!G6 -> 0 | K6: =VLOOKUP($A6,[6]HISTOFEV23!$A$6:$AV$45,17,0) -> 0 | L6: =IF(K6<>0,VLOOKUP($A6,[6]HISTOFEV23!$A$6:$BB$45,8,0),"ECHEC") -> ECHEC | M6: =IF(P6=0,0,VLOOKUP($A6,[6]HISTOFEV23!$A$6:$AV$45,32,0)) -> 0 | N6: =VLOOKUP($A6,[6]HISTOFEV23!$A$6:$AV$45,33,0) -> 0 | O6: =IF(P6=0,0,($C$3-P6)) -> 0 | P6: =VLOOKUP($A6,[6]HISTOFEV23!$A$6:$AV$45,30,0) -> 0
A7: AS201602 | B7: =IF(D7=0,0,VLOOKUP($A7,[6]HISTOFEV23!$A$6:$BB$45,12,0)) -> 1 | C7: =VLOOKUP(A7,[7]LISTADHERENT!A$5:H$60,3,0) -> BOUTCHOUANG WILLIAM | D7: =IF(E7="ECHEC",0,VLOOKUP($A7,[6]HISTOFEV23!$A$6:$AR$45,13,0)) -> 75000 | E7: =VLOOKUP($A7,[6]HISTOFEV23!$A$6:$AV$45,8,0) -> BANQUE | F7: =VLOOKUP($A7,[6]HISTOFEV23!$A$6:$AV$45,36,0) -> 0 | G7: =VLOOKUP($A7,[6]HISTOFEV23!$A$6:$AV$45,39,0) -> 0 | H7: =IF(G7=0,0,VLOOKUP($A7,[6]HISTOFEV23!$A$6:$AV$45,42,0)) -> 0 | I7: =VLOOKUP($A7,[6]HISTOFEV23!$A$6:$AV$45,41,0) -> 0 | J7: =TONTJANV23!F7+TONTJANV23!G7 -> 0 | K7: =VLOOKUP($A7,[6]HISTOFEV23!$A$6:$AV$45,17,0) -> 0 | L7: =IF(K7<>0,VLOOKUP($A7,[6]HISTOFEV23!$A$6:$BB$45,8,0),"ECHEC") -> ECHEC | M7: =IF(P7=0,0,VLOOKUP($A7,[6]HISTOFEV23!$A$6:$AV$45,32,0)) -> 0 | N7: =VLOOKUP($A7,[6]HISTOFEV23!$A$6:$AV$45,33,0) -> 0 | O7: =IF(P7=0,0,($C$3-P7)) -> 0 | P7: =VLOOKUP($A7,[6]HISTOFEV23!$A$6:$AV$45,30,0) -> 0
A8: AS201605 | B8: =IF(D8=0,0,VLOOKUP($A8,[6]HISTOFEV23!$A$6:$BB$45,12,0)) -> 1 | C8: =VLOOKUP(A8,[7]LISTADHERENT!A$5:H$60,3,0) -> DJOUKWE NANGUEN GUY BLAISE | D8: =IF(E8="ECHEC",0,VLOOKUP($A8,[6]HISTOFEV23!$A$7:$AR$45,13,0)) -> 75000 | E8: =VLOOKUP($A8,[6]HISTOFEV23!$A$7:$AV$45,8,0) -> BANQUE | F8: =VLOOKUP($A8,[6]HISTOFEV23!$A$6:$AV$45,36,0) -> 0 | G8: =VLOOKUP($A8,[6]HISTOFEV23!$A$6:$AV$45,39,0) -> 0 | H8: =IF(G8=0,0,VLOOKUP($A8,[6]HISTOFEV23!$A$6:$AV$45,42,0)) -> 0 | I8: =VLOOKUP($A8,[6]HISTOFEV23!$A$6:$AV$45,41,0) -> 0 | J8: =TONTJANV23!F8+TONTJANV23!G8 -> 0 | K8: =VLOOKUP($A8,[6]HISTOFEV23!$A$6:$AV$45,17,0) -> 0 | L8: =IF(K8<>0,VLOOKUP($A8,[6]HISTOFEV23!$A$6:$BB$45,8,0),"ECHEC") -> ECHEC | M8: =IF(P8=0,0,VLOOKUP($A8,[6]HISTOFEV23!$A$6:$AV$45,32,0)) -> 0 | N8: =VLOOKUP($A8,[6]HISTOFEV23!$A$6:$AV$45,33,0) -> 0 | O8: =IF(P8=0,0,($C$3-P8)) -> 0 | P8: =VLOOKUP($A8,[6]HISTOFEV23!$A$6:$AV$45,30,0) -> 0
A9: AS201608 | B9: =IF(D9=0,0,VLOOKUP($A9,[6]HISTOFEV23!$A$6:$BB$45,12,0)) -> 1 | C9: =VLOOKUP(A9,[7]LISTADHERENT!A$5:H$60,3,0) -> DJUOMBESSY ANTOINE | D9: =IF(E9="ECHEC",0,VLOOKUP($A9,[6]HISTOFEV23!$A$7:$AR$45,13,0)) -> 75000 | E9: =VLOOKUP($A9,[6]HISTOFEV23!$A$7:$AV$45,8,0) -> BANQUE | F9: =VLOOKUP($A9,[6]HISTOFEV23!$A$6:$AV$45,36,0) -> 0 | G9: =VLOOKUP($A9,[6]HISTOFEV23!$A$6:$AV$45,39,0) -> 0 | H9: =IF(G9=0,0,VLOOKUP($A9,[6]HISTOFEV23!$A$6:$AV$45,42,0)) -> 0 | I9: =VLOOKUP($A9,[6]HISTOFEV23!$A$6:$AV$45,41,0) -> 0 | J9: =TONTJANV23!F9+TONTJANV23!G9 -> 0 | K9: =VLOOKUP($A9,[6]HISTOFEV23!$A$6:$AV$45,17,0) -> 0 | L9: =IF(K9<>0,VLOOKUP($A9,[6]HISTOFEV23!$A$6:$BB$45,8,0),"ECHEC") -> ECHEC | M9: =IF(P9=0,0,VLOOKUP($A9,[6]HISTOFEV23!$A$6:$AV$45,32,0)) -> 0 | N9: =VLOOKUP($A9,[6]HISTOFEV23!$A$6:$AV$45,33,0) -> 0 | O9: =IF(P9=0,0,($C$3-P9)) -> 0 | P9: =VLOOKUP($A9,[6]HISTOFEV23!$A$6:$AV$45,30,0) -> 0
A10: AS201613 | B10: =IF(D10=0,0,VLOOKUP($A10,[6]HISTOFEV23!$A$6:$BB$45,12,0)) -> 1 | C10: =VLOOKUP(A10,[7]LISTADHERENT!A$5:H$60,3,0) -> HOTCHO BENJAMIN | D10: =IF(E10="ECHEC",0,VLOOKUP($A10,[6]HISTOFEV23!$A$7:$AR$45,13,0)) -> 75000 | E10: =VLOOKUP($A10,[6]HISTOFEV23!$A$7:$AV$45,8,0) -> BANQUE | F10: =VLOOKUP($A10,[6]HISTOFEV23!$A$6:$AV$45,36,0) -> 0 | G10: =VLOOKUP($A10,[6]HISTOFEV23!$A$6:$AV$45,39,0) -> 0 | H10: =IF(G10=0,0,VLOOKUP($A10,[6]HISTOFEV23!$A$6:$AV$45,42,0)) -> 0 | I10: =VLOOKUP($A10,[6]HISTOFEV23!$A$6:$AV$45,41,0) -> 0 | J10: =TONTJANV23!F10+TONTJANV23!G10 -> 0 | K10: =VLOOKUP($A10,[6]HISTOFEV23!$A$6:$AV$45,17,0) -> 0 | L10: =IF(K10<>0,VLOOKUP($A10,[6]HISTOFEV23!$A$6:$BB$45,8,0),"ECHEC") -> ECHEC | M10: =IF(P10=0,0,VLOOKUP($A10,[6]HISTOFEV23!$A$6:$AV$45,32,0)) -> BANQUE | N10: =VLOOKUP($A10,[6]HISTOFEV23!$A$6:$AV$45,33,0) -> 0 | O10: =IF(P10=0,0,($C$3-P10)) -> 880000 | P10: =VLOOKUP($A10,[6]HISTOFEV23!$A$6:$AV$45,30,0) -> 20000
A11: AS201611 | B11: =IF(D11=0,0,VLOOKUP($A11,[6]HISTOFEV23!$A$6:$BB$45,12,0)) -> 1 | C11: =VLOOKUP(A11,[7]LISTADHERENT!A$5:H$60,3,0) -> HENGUE PAUL OMER | D11: =IF(E11="ECHEC",0,VLOOKUP($A11,[6]HISTOFEV23!$A$7:$AR$45,13,0)) -> 75000 | E11: =VLOOKUP($A11,[6]HISTOFEV23!$A$7:$AV$45,8,0) -> BANQUE | F11: =VLOOKUP($A11,[6]HISTOFEV23!$A$6:$AV$45,36,0) -> 0 | G11: =VLOOKUP($A11,[6]HISTOFEV23!$A$6:$AV$45,39,0) -> 0 | H11: =IF(G11=0,0,VLOOKUP($A11,[6]HISTOFEV23!$A$6:$AV$45,42,0)) -> 0 | I11: =VLOOKUP($A11,[6]HISTOFEV23!$A$6:$AV$45,41,0) -> 0 | J11: =TONTJANV23!F11+TONTJANV23!G11 -> 0 | K11: =VLOOKUP($A11,[6]HISTOFEV23!$A$6:$AV$45,17,0) -> 0 | L11: =IF(K11<>0,VLOOKUP($A11,[6]HISTOFEV23!$A$6:$BB$45,8,0),"ECHEC") -> ECHEC | M11: =IF(P11=0,0,VLOOKUP($A11,[6]HISTOFEV23!$A$6:$AV$45,32,0)) -> 0 | N11: =VLOOKUP($A11,[6]HISTOFEV23!$A$6:$AV$45,33,0) -> 0 | O11: =IF(P11=0,0,($C$3-P11)) -> 0 | P11: =VLOOKUP($A11,[6]HISTOFEV23!$A$6:$AV$45,30,0) -> 0
A12: AS201619 | B12: =IF(D12=0,0,VLOOKUP($A12,[6]HISTOFEV23!$A$6:$BB$45,12,0)) -> 1 | C12: =VLOOKUP(A12,[7]LISTADHERENT!A$5:H$60,3,0) -> KOUATCHO MESSACK | D12: =IF(E12="ECHEC",0,VLOOKUP($A12,[6]HISTOFEV23!$A$7:$AR$45,13,0)) -> 75000 | E12: =VLOOKUP($A12,[6]HISTOFEV23!$A$7:$AV$45,8,0) -> BANQUE | F12: =VLOOKUP($A12,[6]HISTOFEV23!$A$6:$AV$45,36,0) -> 0 | G12: =VLOOKUP($A12,[6]HISTOFEV23!$A$6:$AV$45,39,0) -> 0 | H12: =IF(G12=0,0,VLOOKUP($A12,[6]HISTOFEV23!$A$6:$AV$45,42,0)) -> 0 | I12: =VLOOKUP($A12,[6]HISTOFEV23!$A$6:$AV$45,41,0) -> 0 | J12: =TONTJANV23!F12+TONTJANV23!G12 -> 102000 | K12: =VLOOKUP($A12,[6]HISTOFEV23!$A$6:$AV$45,17,0) -> 102000 | L12: =IF(K12<>0,VLOOKUP($A12,[6]HISTOFEV23!$A$6:$BB$45,8,0),"ECHEC") -> BANQUE | M12: =IF(P12=0,0,VLOOKUP($A12,[6]HISTOFEV23!$A$6:$AV$45,32,0)) -> 0 | N12: =VLOOKUP($A12,[6]HISTOFEV23!$A$6:$AV$45,33,0) -> 0 | O12: =IF(P12=0,0,($C$3-P12)) -> 0 | P12: =VLOOKUP($A12,[6]HISTOFEV23!$A$6:$AV$45,30,0) -> 0
A13: AS201649 | B13: =IF(D13=0,0,VLOOKUP($A13,[6]HISTOFEV23!$A$6:$BB$45,12,0)) -> 1 | C13: =VLOOKUP(A13,[7]LISTADHERENT!A$5:H$60,3,0) -> MBOGNING TUGMA GUY | D13: =IF(E13="ECHEC",0,VLOOKUP($A13,[6]HISTOFEV23!$A$7:$AR$45,13,0)) -> 75000 | E13: =VLOOKUP($A13,[6]HISTOFEV23!$A$7:$AV$45,8,0) -> BANQUE | F13: =VLOOKUP($A13,[6]HISTOFEV23!$A$6:$AV$45,36,0) -> 0 | G13: =VLOOKUP($A13,[6]HISTOFEV23!$A$6:$AV$45,39,0) -> 0 | H13: =IF(G13=0,0,VLOOKUP($A13,[6]HISTOFEV23!$A$6:$AV$45,42,0)) -> 0 | I13: =VLOOKUP($A13,[6]HISTOFEV23!$A$6:$AV$45,41,0) -> 0 | J13: =TONTJANV23!F13+TONTJANV23!G13 -> 107000 | K13: =VLOOKUP($A13,[6]HISTOFEV23!$A$6:$AV$45,17,0) -> 107000 | L13: =IF(K13<>0,VLOOKUP($A13,[6]HISTOFEV23!$A$6:$BB$45,8,0),"ECHEC") -> BANQUE | M13: =IF(P13=0,0,VLOOKUP($A13,[6]HISTOFEV23!$A$6:$AV$45,32,0)) -> BANQUE | N13: =VLOOKUP($A13,[6]HISTOFEV23!$A$6:$AV$45,33,0) -> 0 | O13: =IF(P13=0,0,($C$3-P13)) -> 878000 | P13: =VLOOKUP($A13,[6]HISTOFEV23!$A$6:$AV$45,30,0) -> 22000
A14: AS201621 | B14: =IF(D14=0,0,VLOOKUP($A14,[6]HISTOFEV23!$A$6:$BB$45,12,0)) -> 1 | C14: =VLOOKUP(A14,[7]LISTADHERENT!A$5:H$60,3,0) -> NANKAM APPOLINAIRE | D14: =IF(E14="ECHEC",0,VLOOKUP($A14,[6]HISTOFEV23!$A$7:$AR$45,13,0)) -> 75000 | E14: =VLOOKUP($A14,[6]HISTOFEV23!$A$7:$AV$45,8,0) -> BANQUE | F14: =VLOOKUP($A14,[6]HISTOFEV23!$A$6:$AV$45,36,0) -> 0 | G14: =VLOOKUP($A14,[6]HISTOFEV23!$A$6:$AV$45,39,0) -> 0 | H14: =IF(G14=0,0,VLOOKUP($A14,[6]HISTOFEV23!$A$6:$AV$45,42,0)) -> 0 | I14: =VLOOKUP($A14,[6]HISTOFEV23!$A$6:$AV$45,41,0) -> 0 | J14: =TONTJANV23!F14+TONTJANV23!G14 -> 0 | K14: =VLOOKUP($A14,[6]HISTOFEV23!$A$6:$AV$45,17,0) -> 0 | L14: =IF(K14<>0,VLOOKUP($A14,[6]HISTOFEV23!$A$6:$BB$45,8,0),"ECHEC") -> ECHEC | M14: =IF(P14=0,0,VLOOKUP($A14,[6]HISTOFEV23!$A$6:$AV$45,32,0)) -> 0 | N14: =VLOOKUP($A14,[6]HISTOFEV23!$A$6:$AV$45,33,0) -> 0 | O14: =IF(P14=0,0,($C$3-P14)) -> 0 | P14: =VLOOKUP($A14,[6]HISTOFEV23!$A$6:$AV$45,30,0) -> 0
A15: AS201624 | B15: =IF(D15=0,0,VLOOKUP($A15,[6]HISTOFEV23!$A$6:$BB$45,12,0)) -> 1 | C15: =VLOOKUP(A15,[7]LISTADHERENT!A$5:H$60,3,0) -> NGONDIEP CLAUDE | D15: =IF(E15="ECHEC",0,VLOOKUP($A15,[6]HISTOFEV23!$A$7:$AR$45,13,0)) -> 75000 | E15: =VLOOKUP($A15,[6]HISTOFEV23!$A$7:$AV$45,8,0) -> BANQUE | F15: =VLOOKUP($A15,[6]HISTOFEV23!$A$6:$AV$45,36,0) -> 0 | G15: =VLOOKUP($A15,[6]HISTOFEV23!$A$6:$AV$45,39,0) -> 0 | H15: =IF(G15=0,0,VLOOKUP($A15,[6]HISTOFEV23!$A$6:$AV$45,42,0)) -> 0 | I15: =VLOOKUP($A15,[6]HISTOFEV23!$A$6:$AV$45,41,0) -> 0 | J15: =TONTJANV23!F15+TONTJANV23!G15 -> 102000 | K15: =VLOOKUP($A15,[6]HISTOFEV23!$A$6:$AV$45,17,0) -> 102000 | L15: =IF(K15<>0,VLOOKUP($A15,[6]HISTOFEV23!$A$6:$BB$45,8,0),"ECHEC") -> BANQUE | M15: =IF(P15=0,0,VLOOKUP($A15,[6]HISTOFEV23!$A$6:$AV$45,32,0)) -> 0 | N15: =VLOOKUP($A15,[6]HISTOFEV23!$A$6:$AV$45,33,0) -> 0 | O15: =IF(P15=0,0,($C$3-P15)) -> 0 | P15: =VLOOKUP($A15,[6]HISTOFEV23!$A$6:$AV$45,30,0) -> 0
A16: AS201626 | B16: =IF(D16=0,0,VLOOKUP($A16,[6]HISTOFEV23!$A$6:$BB$45,12,0)) -> 2 | C16: =VLOOKUP(A16,[7]LISTADHERENT!A$5:H$60,3,0) -> NGUIEMEGNI MATHIEU BLAISE | D16: =IF(E16="ECHEC",0,VLOOKUP($A16,[6]HISTOFEV23!$A$7:$AR$45,13,0)) -> 150000 | E16: =VLOOKUP($A16,[6]HISTOFEV23!$A$7:$AV$45,8,0) -> BANQUE | F16: =VLOOKUP($A16,[6]HISTOFEV23!$A$6:$AV$45,36,0) -> 0 | G16: =VLOOKUP($A16,[6]HISTOFEV23!$A$6:$AV$45,39,0) -> 0 | H16: =IF(G16=0,0,VLOOKUP($A16,[6]HISTOFEV23!$A$6:$AV$45,42,0)) -> 0 | I16: =VLOOKUP($A16,[6]HISTOFEV23!$A$6:$AV$45,41,0) -> 0 | J16: =TONTJANV23!F16+TONTJANV23!G16 -> 102000 | K16: =VLOOKUP($A16,[6]HISTOFEV23!$A$6:$AV$45,17,0) -> 102000 | L16: =IF(K16<>0,VLOOKUP($A16,[6]HISTOFEV23!$A$6:$BB$45,8,0),"ECHEC") -> BANQUE | M16: =IF(P16=0,0,VLOOKUP($A16,[6]HISTOFEV23!$A$6:$AV$45,32,0)) -> 0 | N16: =VLOOKUP($A16,[6]HISTOFEV23!$A$6:$AV$45,33,0) -> 0 | O16: =IF(P16=0,0,($C$3-P16)) -> 0 | P16: =VLOOKUP($A16,[6]HISTOFEV23!$A$6:$AV$45,30,0) -> 0
A17: AS201633 | B17: =IF(D17=0,0,VLOOKUP($A17,[6]HISTOFEV23!$A$6:$BB$45,12,0)) -> 1 | C17: =VLOOKUP(A17,[7]LISTADHERENT!A$5:H$60,3,0) -> PATEGO NJOSSU GUSTAVE | D17: =IF(E17="ECHEC",0,VLOOKUP($A17,[6]HISTOFEV23!$A$7:$AR$45,13,0)) -> 75000 | E17: =VLOOKUP($A17,[6]HISTOFEV23!$A$7:$AV$45,8,0) -> BANQUE | F17: =VLOOKUP($A17,[6]HISTOFEV23!$A$6:$AV$45,36,0) -> 0 | G17: =VLOOKUP($A17,[6]HISTOFEV23!$A$6:$AV$45,39,0) -> 0 | H17: =IF(G17=0,0,VLOOKUP($A17,[6]HISTOFEV23!$A$6:$AV$45,42,0)) -> 0 | I17: =VLOOKUP($A17,[6]HISTOFEV23!$A$6:$AV$45,41,0) -> 0 | J17: =TONTJANV23!F17+TONTJANV23!G17 -> 0 | K17: =VLOOKUP($A17,[6]HISTOFEV23!$A$6:$AV$45,17,0) -> 0 | L17: =IF(K17<>0,VLOOKUP($A17,[6]HISTOFEV23!$A$6:$BB$45,8,0),"ECHEC") -> ECHEC | M17: =IF(P17=0,0,VLOOKUP($A17,[6]HISTOFEV23!$A$6:$AV$45,32,0)) -> 0 | N17: =VLOOKUP($A17,[6]HISTOFEV23!$A$6:$AV$45,33,0) -> 0 | O17: =IF(P17=0,0,($C$3-P17)) -> 0 | P17: =VLOOKUP($A17,[6]HISTOFEV23!$A$6:$AV$45,30,0) -> 0
A18: AS201653 | B18: =IF(D18=0,0,VLOOKUP($A18,[6]HISTOFEV23!$A$6:$BB$45,12,0)) -> 1 | C18: =VLOOKUP(A18,[7]LISTADHERENT!A$5:H$60,3,0) -> SIME BRICE | D18: =IF(E18="ECHEC",0,VLOOKUP($A18,[6]HISTOFEV23!$A$7:$AR$45,13,0)) -> 75000 | E18: =VLOOKUP($A18,[6]HISTOFEV23!$A$7:$AV$45,8,0) -> BANQUE | F18: =VLOOKUP($A18,[6]HISTOFEV23!$A$6:$AV$45,36,0) -> 0 | G18: =VLOOKUP($A18,[6]HISTOFEV23!$A$6:$AV$45,39,0) -> 0 | H18: =IF(G18=0,0,VLOOKUP($A18,[6]HISTOFEV23!$A$6:$AV$45,42,0)) -> 0 | I18: =VLOOKUP($A18,[6]HISTOFEV23!$A$6:$AV$45,41,0) -> 0 | J18: =TONTJANV23!F18+TONTJANV23!G18 -> 0 | K18: =VLOOKUP($A18,[6]HISTOFEV23!$A$6:$AV$45,17,0) -> 0 | L18: =IF(K18<>0,VLOOKUP($A18,[6]HISTOFEV23!$A$6:$BB$45,8,0),"ECHEC") -> ECHEC | M18: =IF(P18=0,0,VLOOKUP($A18,[6]HISTOFEV23!$A$6:$AV$45,32,0)) -> 0 | N18: =VLOOKUP($A18,[6]HISTOFEV23!$A$6:$AV$45,33,0) -> 0 | O18: =IF(P18=0,0,($C$3-P18)) -> 0 | P18: =VLOOKUP($A18,[6]HISTOFEV23!$A$6:$AV$45,30,0) -> 0
A19: AS201641 | B19: =IF(D19=0,0,VLOOKUP($A19,[6]HISTOFEV23!$A$6:$BB$45,12,0)) -> 1 | C19: =VLOOKUP(A19,[7]LISTADHERENT!A$5:H$60,3,0) -> TCHOUAMOU MATHIEU | D19: =IF(E19="ECHEC",0,VLOOKUP($A19,[6]HISTOFEV23!$A$7:$AR$45,13,0)) -> 75000 | E19: =VLOOKUP($A19,[6]HISTOFEV23!$A$7:$AV$45,8,0) -> BANQUE | F19: =VLOOKUP($A19,[6]HISTOFEV23!$A$6:$AV$45,36,0) -> 0 | G19: =VLOOKUP($A19,[6]HISTOFEV23!$A$6:$AV$45,39,0) -> 0 | H19: =IF(G19=0,0,VLOOKUP($A19,[6]HISTOFEV23!$A$6:$AV$45,42,0)) -> 0 | I19: =VLOOKUP($A19,[6]HISTOFEV23!$A$6:$AV$45,41,0) -> 0 | J19: =TONTJANV23!F19+TONTJANV23!G19 -> 0 | K19: =VLOOKUP($A19,[6]HISTOFEV23!$A$6:$AV$45,17,0) -> 0 | L19: =IF(K19<>0,VLOOKUP($A19,[6]HISTOFEV23!$A$6:$BB$45,8,0),"ECHEC") -> ECHEC | M19: =IF(P19=0,0,VLOOKUP($A19,[6]HISTOFEV23!$A$6:$AV$45,32,0)) -> 0 | N19: =VLOOKUP($A19,[6]HISTOFEV23!$A$6:$AV$45,33,0) -> 0 | O19: =IF(P19=0,0,($C$3-P19)) -> 0 | P19: =VLOOKUP($A19,[6]HISTOFEV23!$A$6:$AV$45,30,0) -> 0
A20: AS201647 | B20: =IF(D20=0,0,VLOOKUP($A20,[6]HISTOFEV23!$A$6:$BB$45,12,0)) -> 2 | C20: =VLOOKUP(A20,[7]LISTADHERENT!A$5:H$60,3,0) -> YOUMBI EMMANUEL | D20: =IF(E20="ECHEC",0,VLOOKUP($A20,[6]HISTOFEV23!$A$7:$AR$45,13,0)) -> 150000 | E20: =VLOOKUP($A20,[6]HISTOFEV23!$A$7:$AV$45,8,0) -> BANQUE | F20: =VLOOKUP($A20,[6]HISTOFEV23!$A$6:$AV$45,36,0) -> 0 | G20: =VLOOKUP($A20,[6]HISTOFEV23!$A$6:$AV$45,39,0) -> 0 | H20: =IF(G20=0,0,VLOOKUP($A20,[6]HISTOFEV23!$A$6:$AV$45,42,0)) -> 0 | I20: =VLOOKUP($A20,[6]HISTOFEV23!$A$6:$AV$45,41,0) -> 0 | J20: =TONTJANV23!F20+TONTJANV23!G20 -> 0 | K20: =VLOOKUP($A20,[6]HISTOFEV23!$A$6:$AV$45,17,0) -> 0 | L20: =IF(K20<>0,VLOOKUP($A20,[6]HISTOFEV23!$A$6:$BB$45,8,0),"ECHEC") -> ECHEC | M20: =IF(P20=0,0,VLOOKUP($A20,[6]HISTOFEV23!$A$6:$AV$45,32,0)) -> 0 | N20: =VLOOKUP($A20,[6]HISTOFEV23!$A$6:$AV$45,33,0) -> 0 | O20: =IF(P20=0,0,($C$3-P20)) -> 0 | P20: =VLOOKUP($A20,[6]HISTOFEV23!$A$6:$AV$45,30,0) -> 0
A22: TOTAL PART | B22: =SUM(B6:B21) -> 17
A23: NBRE ADHERENT | B23: =COUNT(D6:D21) -> 15 | D23: =SUM(D6:D22) -> 1275000 | E23: =SUM(E6:E22) -> 0 | F23: =SUM(F6:F22) -> 0 | G23: =SUM(G6:G22) -> 0 | H23: =SUM(H6:H22) -> 0 | I23: =SUM(I6:I22) -> 0 | J23: =SUM(J6:J22) -> 413000 | K23: =SUM(K6:K22) -> 413000 | ... P23: =SUM(P6:P22) -> 42000
L24: NBRE PART | M24: PART VENDUE
D25: MONTANT TONTINE | E25: REMBOURSEMENT PETIT LOT | F25: VENTE PETIT LOT | G25: VENTE LOT PRINCIPAL | H25: SOLDE EN CAISSE | J25: TONTINE + REMB + INTERET VENTE+RELIQUAT | K25: =D29+E29+P23+TONTJANV23!M30 -> 1805000
D26: =SUMIFS(D6:D22,E6:E22,"ESPECES") -> 0 | E26: =SUMIFS(K7:K17,L7:L17,"ESPECES") -> 0 | F26: =SUMIFS(F7:F22,H7:H22,"ESPECES") -> 0 | G26: =SUMIFS(O7:O22,M7:M22,"ESPECES") -> 0 | H26: =D26+E26-F26-G26 -> 0 | J26: LOT PRINCIPAL | K26: =C3*COUNTIF(O7:O22,">0") -> 1800000 | L26: =D3 -> 2 | M26: =COUNTIF(O7:O17,">0") -> 2
D27: =SUMIFS(D6:D22,E6:E22,"BANQUE") -> 1275000 | E27: =SUMIFS(K7:K17,L7:L17,"BANQUE") -> 413000 | F27: =SUMIFS(F7:F22,H7:H22,"BANQUE") -> 0 | G27: =SUMIFS(O7:O22,M7:M22,"BANQUE") -> 1758000 | H27: =D27+E27-F27-G27 -> -70000
J28: PETIT LOT | K28: =K25-K26 -> 5000
D29: =D26+D27 -> 1275000 | E29: =E26+E27 -> 413000 | F29: =F26+F27 -> 0 | G29: =G26+G27 -> 1758000 | H29: =H26+H27 -> -70000
J30: RELIQUAT | K30: =K28-F23 -> 5000 | M30: =K30 -> 5000 | N30: CUMUL
J32: ECHEC TONTINE MOIS | K32: =COUNTIFS(E7:E21,"ECHEC")*75000 -> 0 | M32: =TONTJANV23!M32+TONTFEV23!K32 -> 0 | N32: CUMUL
J33: ECHEC REMBOURSEMENT MOIS | K33: =J23-E29 -> 0 | M33: =TONTJANV23!M33+TONTFEV23!K33 -> 0 | N33: CUMUL

Sheet TONTMARS23
A1: ASSOCIATION | B1: ASELBY
A2: ANNEE | B2: 2023 | C2: TONIINE | D2: NBRE PART
A3: TAUX TONTINE | B3: 75000 | C3: =B3*12 -> 900000 | D3: =ROUNDDOWN(K25/C3,0) -> 2
C4: 44998
A5: MATRICULE | B5: NBREPART | C5: NOM ET PRENOM | D5: MONTANT TONTINE | E5: MODE VERSEMENT | F5: VENTE PETIT LOT | G5: INTERET PETIT LOT | H5: MODE VERSEMENT VENTE PETIT LOT | I5: NUMERO CHEQUE | J5: MONTANT A REMBOURSER PETIT LOT | K5: REMBOURSEMENT PETIT LOT | L5: MODE VERSEMENT REMBOURSEMENT | M5: MODE VERSEMENTLOT PRINCIPAL | N5: NUMERO CHEQUE | O5: MONTANT LOT PRINCIPAL | P5: INTERET LOT PRINCIPAL
A6: AS201648 | B6: =IF(D6=0,0,VLOOKUP($A6,[6]HISTOMARS23!$A$6:$BB$45,12,0)) -> 1 | C6: =VLOOKUP(A6,[7]LISTADHERENT!A$5:H$60,3,0) -> ASELBY | D6: =IF(E6="ECHEC",0,VLOOKUP($A6,[6]HISTOMARS23!$A$6:$AR$45,13,0)) -> 75000 | E6: =VLOOKUP($A6,[6]HISTOMARS23!$A$6:$AV$45,8,0) -> BANQUE | F6: =VLOOKUP($A6,[6]HISTOMARS23!$A$6:$AV$45,36,0) -> 0 | G6: =VLOOKUP($A6,[6]HISTOMARS23!$A$6:$AV$45,39,0) -> 0 | H6: =IF(G6=0,0,VLOOKUP($A6,[6]HISTOMARS23!$A$6:$AV$45,42,0)) -> 0 | I6: =VLOOKUP($A6,[6]HISTOMARS23!$A$6:$AV$45,41,0) -> 0 | J6: =TONTFEV23!F6+TONTFEV23!G6 -> 0 | K6: =VLOOKUP($A6,[6]HISTOMARS23!$A$6:$AV$45,17,0) -> 0 | L6: =IF(K6<>0,VLOOKUP($A6,[6]HISTOMARS23!$A$6:$BB$45,8,0),"ECHEC") -> ECHEC | M6: =IF(P6=0,0,VLOOKUP($A6,[6]HISTOMARS23!$A$6:$AV$45,32,0)) -> 0 | N6: =VLOOKUP($A6,[6]HISTOMARS23!$A$6:$AV$45,33,0) -> 0 | O6: =IF(P6=0,0,($C$3-P6)) -> 0 | P6: =VLOOKUP($A6,[6]HISTOMARS23!$A$6:$AV$45,30,0) -> 0
A7: AS201602 | B7: =IF(D7=0,0,VLOOKUP($A7,[6]HISTOMARS23!$A$6:$BB$45,12,0)) -> 1 | C7: =VLOOKUP(A7,[7]LISTADHERENT!A$5:H$60,3,0) -> BOUTCHOUANG WILLIAM | D7: =IF(E7="ECHEC",0,VLOOKUP($A7,[6]HISTOMARS23!$A$6:$AR$45,13,0)) -> 75000 | E7: =VLOOKUP($A7,[6]HISTOMARS23!$A$6:$AV$45,8,0) -> BANQUE | F7: =VLOOKUP($A7,[6]HISTOMARS23!$A$6:$AV$45,36,0) -> 0 | G7: =VLOOKUP($A7,[6]HISTOMARS23!$A$6:$AV$45,39,0) -> 0 | H7: =IF(G7=0,0,VLOOKUP($A7,[6]HISTOMARS23!$A$6:$AV$45,42,0)) -> 0 | I7: =VLOOKUP($A7,[6]HISTOMARS23!$A$6:$AV$45,41,0) -> 0 | J7: =TONTFEV23!F7+TONTFEV23!G7 -> 0 | K7: =VLOOKUP($A7,[6]HISTOMARS23!$A$6:$AV$45,17,0) -> 0 | L7: =IF(K7<>0,VLOOKUP($A7,[6]HISTOMARS23!$A$6:$BB$45,8,0),"ECHEC") -> ECHEC | M7: =IF(P7=0,0,VLOOKUP($A7,[6]HISTOMARS23!$A$6:$AV$45,32,0)) -> 0 | N7: =VLOOKUP($A7,[6]HISTOMARS23!$A$6:$AV$45,33,0) -> 0 | O7: =IF(P7=0,0,($C$3-P7)) -> 0 | P7: =VLOOKUP($A7,[6]HISTOMARS23!$A$6:$AV$45,30,0) -> 0
A8: AS201605 | B8: =IF(D8=0,0,VLOOKUP($A8,[6]HISTOMARS23!$A$6:$BB$45,12,0)) -> 1 | C8: =VLOOKUP(A8,[7]LISTADHERENT!A$5:H$60,3,0) -> DJOUKWE NANGUEN GUY BLAISE | D8: =IF(E8="ECHEC",0,VLOOKUP($A8,[6]HISTOMARS23!$A$7:$AR$45,13,0)) -> 75000 | E8: =VLOOKUP($A8,[6]HISTOMARS23!$A$7:$AV$45,8,0) -> BANQUE | F8: =VLOOKUP($A8,[6]HISTOMARS23!$A$6:$AV$45,36,0) -> 0 | G8: =VLOOKUP($A8,[6]HISTOMARS23!$A$6:$AV$45,39,0) -> 0 | H8: =IF(G8=0,0,VLOOKUP($A8,[6]HISTOMARS23!$A$6:$AV$45,42,0)) -> 0 | I8: =VLOOKUP($A8,[6]HISTOMARS23!$A$6:$AV$45,41,0) -> 0 | J8: =TONTFEV23!F8+TONTFEV23!G8 -> 0 | K8: =VLOOKUP($A8,[6]HISTOMARS23!$A$6:$AV$45,17,0) -> 0 | L8: =IF(K8<>0,VLOOKUP($A8,[6]HISTOMARS23!$A$6:$BB$45,8,0),"ECHEC") -> ECHEC | M8: =IF(P8=0,0,VLOOKUP($A8,[6]HISTOMARS23!$A$6:$AV$45,32,0)) -> 0 | N8: =VLOOKUP($A8,[6]HISTOMARS23!$A$6:$AV$45,33,0) -> 0 | O8: =IF(P8=0,0,($C$3-P8)) -> 892500 | P8: =VLOOKUP($A8,[6]HISTOMARS23!$A$6:$AV$45,30,0) -> 7500
A9: AS201608 | B9: =IF(D9=0,0,VLOOKUP($A9,[6]HISTOMARS23!$A$6:$BB$45,12,0)) -> 1 | C9: =VLOOKUP(A9,[7]LISTADHERENT!A$5:H$60,3,0) -> DJUOMBESSY ANTOINE | D9: =IF(E9="ECHEC",0,VLOOKUP($A9,[6]HISTOMARS23!$A$7:$AR$45,13,0)) -> 75000 | E9: =VLOOKUP($A9,[6]HISTOMARS23!$A$7:$AV$45,8,0) -> BANQUE | F9: =VLOOKUP($A9,[6]HISTOMARS23!$A$6:$AV$45,36,0) -> 0 | G9: =VLOOKUP($A9,[6]HISTOMARS23!$A$6:$AV$45,39,0) -> 0 | H9: =IF(G9=0,0,VLOOKUP($A9,[6]HISTOMARS23!$A$6:$AV$45,42,0)) -> 0 | I9: =VLOOKUP($A9,[6]HISTOMARS23!$A$6:$AV$45,41,0) -> 0 | J9: =TONTFEV23!F9+TONTFEV23!G9 -> 0 | K9: =VLOOKUP($A9,[6]HISTOMARS23!$A$6:$AV$45,17,0) -> 0 | L9: =IF(K9<>0,VLOOKUP($A9,[6]HISTOMARS23!$A$6:$BB$45,8,0),"ECHEC") -> ECHEC | M9: =IF(P9=0,0,VLOOKUP($A9,[6]HISTOMARS23!$A$6:$AV$45,32,0)) -> 0 | N9: =VLOOKUP($A9,[6]HISTOMARS23!$A$6:$AV$45,33,0) -> 0 | O9: =IF(P9=0,0,($C$3-P9)) -> 0 | P9: =VLOOKUP($A9,[6]HISTOMARS23!$A$6:$AV$45,30,0) -> 0
A10: AS201613 | B10: =IF(D10=0,0,VLOOKUP($A10,[6]HISTOMARS23!$A$6:$BB$45,12,0)) -> 1 | C10: =VLOOKUP(A10,[7]LISTADHERENT!A$5:H$60,3,0) -> HOTCHO BENJAMIN | D10: =IF(E10="ECHEC",0,VLOOKUP($A10,[6]HISTOMARS23!$A$7:$AR$45,13,0)) -> 75000 | E10: =VLOOKUP($A10,[6]HISTOMARS23!$A$7:$AV$45,8,0) -> BANQUE | F10: =VLOOKUP($A10,[6]HISTOMARS23!$A$6:$AV$45,36,0) -> 0 | G10: =VLOOKUP($A10,[6]HISTOMARS23!$A$6:$AV$45,39,0) -> 0 | H10: =IF(G10=0,0,VLOOKUP($A10,[6]HISTOMARS23!$A$6:$AV$45,42,0)) -> 0 | I10: =VLOOKUP($A10,[6]HISTOMARS23!$A$6:$AV$45,41,0) -> 0 | J10: =TONTFEV23!F10+TONTFEV23!G10 -> 0 | K10: =VLOOKUP($A10,[6]HISTOMARS23!$A$6:$AV$45,17,0) -> 0 | L10: =IF(K10<>0,VLOOKUP($A10,[6]HISTOMARS23!$A$6:$BB$45,8,0),"ECHEC") -> ECHEC | M10: =IF(P10=0,0,VLOOKUP($A10,[6]HISTOMARS23!$A$6:$AV$45,32,0)) -> 0 | N10: =VLOOKUP($A10,[6]HISTOMARS23!$A$6:$AV$45,33,0) -> 0 | O10: =IF(P10=0,0,($C$3-P10)) -> 0 | P10: =VLOOKUP($A10,[6]HISTOMARS23!$A$6:$AV$45,30,0) -> 0
A11: AS201611 | B11: =IF(D11=0,0,VLOOKUP($A11,[6]HISTOMARS23!$A$6:$BB$45,12,0)) -> 1 | C11: =VLOOKUP(A11,[7]LISTADHERENT!A$5:H$60,3,0) -> HENGUE PAUL OMER | D11: =IF(E11="ECHEC",0,VLOOKUP($A11,[6]HISTOMARS23!$A$7:$AR$45,13,0)) -> 75000 | E11: =VLOOKUP($A11,[6]HISTOMARS23!$A$7:$AV$45,8,0) -> BANQUE | F11: =VLOOKUP($A11,[6]HISTOMARS23!$A$6:$AV$45,36,0) -> 0 | G11: =VLOOKUP($A11,[6]HISTOMARS23!$A$6:$AV$45,39,0) -> 0 | H11: =IF(G11=0,0,VLOOKUP($A11,[6]HISTOMARS23!$A$6:$AV$45,42,0)) -> 0 | I11: =VLOOKUP($A11,[6]HISTOMARS23!$A$6:$AV$45,41,0) -> 0 | J11: =TONTFEV23!F11+TONTFEV23!G11 -> 0 | K11: =VLOOKUP($A11,[6]HISTOMARS23!$A$6:$AV$45,17,0) -> 0 | L11: =IF(K11<>0,VLOOKUP($A11,[6]HISTOMARS23!$A$6:$BB$45,8,0),"ECHEC") -> ECHEC | M11: =IF(P11=0,0,VLOOKUP($A11,[6]HISTOMARS23!$A$6:$AV$45,32,0)) -> 0 | N11: =VLOOKUP($A11,[6]HISTOMARS23!$A$6:$AV$45,33,0) -> 0 | O11: =IF(P11=0,0,($C$3-P11)) -> 0 | P11: =VLOOKUP($A11,[6]HISTOMARS23!$A$6:$AV$45,30,0) -> 0
A12: AS201619 | B12: =IF(D12=0,0,VLOOKUP($A12,[6]HISTOMARS23!$A$6:$BB$45,12,0)) -> 1 | C12: =VLOOKUP(A12,[7]LISTADHERENT!A$5:H$60,3,0) -> KOUATCHO MESSACK | D12: =IF(E12="ECHEC",0,VLOOKUP($A12,[6]HISTOMARS23!$A$7:$AR$45,13,0)) -> 75000 | E12: =VLOOKUP($A12,[6]HISTOMARS23!$A$7:$AV$45,8,0) -> BANQUE | F12: =VLOOKUP($A12,[6]HISTOMARS23!$A$6:$AV$45,36,0) -> 0 | G12: =VLOOKUP($A12,[6]HISTOMARS23!$A$6:$AV$45,39,0) -> 0 | H12: =IF(G12=0,0,VLOOKUP($A12,[6]HISTOMARS23!$A$6:$AV$45,42,0)) -> 0 | I12: =VLOOKUP($A12,[6]HISTOMARS23!$A$6:$AV$45,41,0) -> 0 | J12: =TONTFEV23!F12+TONTFEV23!G12 -> 0 | K12: =VLOOKUP($A12,[6]HISTOMARS23!$A$6:$AV$45,17,0) -> 0 | L12: =IF(K12<>0,VLOOKUP($A12,[6]HISTOMARS23!$A$6:$BB$45,8,0),"ECHEC") -> ECHEC | M12: =IF(P12=0,0,VLOOKUP($A12,[6]HISTOMARS23!$A$6:$AV$45,32,0)) -> 0 | N12: =VLOOKUP($A12,[6]HISTOMARS23!$A$6:$AV$45,33,0) -> 0 | O12: =IF(P12=0,0,($C$3-P12)) -> 0 | P12: =VLOOKUP($A12,[6]HISTOMARS23!$A$6:$AV$45,30,0) -> 0
A13: AS201649 | B13: =IF(D13=0,0,VLOOKUP($A13,[6]HISTOMARS23!$A$6:$BB$45,12,0)) -> 1 | C13: =VLOOKUP(A13,[7]LISTADHERENT!A$5:H$60,3,0) -> MBOGNING TUGMA GUY | D13: =IF(E13="ECHEC",0,VLOOKUP($A13,[6]HISTOMARS23!$A$7:$AR$45,13,0)) -> 75000 | E13: =VLOOKUP($A13,[6]HISTOMARS23!$A$7:$AV$45,8,0) -> BANQUE | F13: =VLOOKUP($A13,[6]HISTOMARS23!$A$6:$AV$45,36,0) -> 0 | G13: =VLOOKUP($A13,[6]HISTOMARS23!$A$6:$AV$45,39,0) -> 0 | H13: =IF(G13=0,0,VLOOKUP($A13,[6]HISTOMARS23!$A$6:$AV$45,42,0)) -> 0 | I13: =VLOOKUP($A13,[6]HISTOMARS23!$A$6:$AV$45,41,0) -> 0 | J13: =TONTFEV23!F13+TONTFEV23!G13 -> 0 | K13: =VLOOKUP($A13,[6]HISTOMARS23!$A$6:$AV$45,17,0) -> 0 | L13: =IF(K13<>0,VLOOKUP($A13,[6]HISTOMARS23!$A$6:$BB$45,8,0),"ECHEC") -> ECHEC | M13: =IF(P13=0,0,VLOOKUP($A13,[6]HISTOMARS23!$A$6:$AV$45,32,0)) -> 0 | N13: =VLOOKUP($A13,[6]HISTOMARS23!$A$6:$AV$45,33,0) -> 0 | O13: =IF(P13=0,0,($C$3-P13)) -> 0 | P13: =VLOOKUP($A13,[6]HISTOMARS23!$A$6:$AV$45,30,0) -> 0
A14: AS201621 | B14: =IF(D14=0,0,VLOOKUP($A14,[6]HISTOMARS23!$A$6:$BB$45,12,0)) -> 1 | C14: =VLOOKUP(A14,[7]LISTADHERENT!A$5:H$60,3,0) -> NANKAM APPOLINAIRE | D14: =IF(E14="ECHEC",0,VLOOKUP($A14,[6]HISTOMARS23!$A$7:$AR$45,13,0)) -> 75000 | E14: =VLOOKUP($A14,[6]HISTOMARS23!$A$7:$AV$45,8,0) -> BANQUE | F14: =VLOOKUP($A14,[6]HISTOMARS23!$A$6:$AV$45,36,0) -> 0 | G14: =VLOOKUP($A14,[6]HISTOMARS23!$A$6:$AV$45,39,0) -> 0 | H14: =IF(G14=0,0,VLOOKUP($A14,[6]HISTOMARS23!$A$6:$AV$45,42,0)) -> 0 | I14: =VLOOKUP($A14,[6]HISTOMARS23!$A$6:$AV$45,41,0) -> 0 | J14: =TONTFEV23!F14+TONTFEV23!G14 -> 0 | K14: =VLOOKUP($A14,[6]HISTOMARS23!$A$6:$AV$45,17,0) -> 0 | L14: =IF(K14<>0,VLOOKUP($A14,[6]HISTOMARS23!$A$6:$BB$45,8,0),"ECHEC") -> ECHEC | M14: =IF(P14=0,0,VLOOKUP($A14,[6]HISTOMARS23!$A$6:$AV$45,32,0)) -> 0 | N14: =VLOOKUP($A14,[6]HISTOMARS23!$A$6:$AV$45,33,0) -> 0 | O14: =IF(P14=0,0,($C$3-P14)) -> 0 | P14: =VLOOKUP($A14,[6]HISTOMARS23!$A$6:$AV$45,30,0) -> 0
A15: AS201624 | B15: =IF(D15=0,0,VLOOKUP($A15,[6]HISTOMARS23!$A$6:$BB$45,12,0)) -> 1 | C15: =VLOOKUP(A15,[7]LISTADHERENT!A$5:H$60,3,0) -> NGONDIEP CLAUDE | D15: =IF(E15="ECHEC",0,VLOOKUP($A15,[6]HISTOMARS23!$A$7:$AR$45,13,0)) -> 75000 | E15: =VLOOKUP($A15,[6]HISTOMARS23!$A$7:$AV$45,8,0) -> ESPECES | F15: =VLOOKUP($A15,[6]HISTOMARS23!$A$6:$AV$45,36,0) -> 0 | G15: =VLOOKUP($A15,[6]HISTOMARS23!$A$6:$AV$45,39,0) -> 0 | H15: =IF(G15=0,0,VLOOKUP($A15,[6]HISTOMARS23!$A$6:$AV$45,42,0)) -> 0 | I15: =VLOOKUP($A15,[6]HISTOMARS23!$A$6:$AV$45,41,0) -> 0 | J15: =TONTFEV23!F15+TONTFEV23!G15 -> 0 | K15: =VLOOKUP($A15,[6]HISTOMARS23!$A$6:$AV$45,17,0) -> 0 | L15: =IF(K15<>0,VLOOKUP($A15,[6]HISTOMARS23!$A$6:$BB$45,8,0),"ECHEC") -> ECHEC | M15: =IF(P15=0,0,VLOOKUP($A15,[6]HISTOMARS23!$A$6:$AV$45,32,0)) -> 0 | N15: =VLOOKUP($A15,[6]HISTOMARS23!$A$6:$AV$45,33,0) -> 0 | O15: =IF(P15=0,0,($C$3-P15)) -> 0 | P15: =VLOOKUP($A15,[6]HISTOMARS23!$A$6:$AV$45,30,0) -> 0
A16: AS201626 | B16: =IF(D16=0,0,VLOOKUP($A16,[6]HISTOMARS23!$A$6:$BB$45,12,0)) -> 2 | C16: =VLOOKUP(A16,[7]LISTADHERENT!A$5:H$60,3,0) -> NGUIEMEGNI MATHIEU BLAISE | D16: =IF(E16="ECHEC",0,VLOOKUP($A16,[6]HISTOMARS23!$A$7:$AR$45,13,0)) -> 150000 | E16: =VLOOKUP($A16,[6]HISTOMARS23!$A$7:$AV$45,8,0) -> BANQUE | F16: =VLOOKUP($A16,[6]HISTOMARS23!$A$6:$AV$45,36,0) -> 0 | G16: =VLOOKUP($A16,[6]HISTOMARS23!$A$6:$AV$45,39,0) -> 0 | H16: =IF(G16=0,0,VLOOKUP($A16,[6]HISTOMARS23!$A$6:$AV$45,42,0)) -> 0 | I16: =VLOOKUP($A16,[6]HISTOMARS23!$A$6:$AV$45,41,0) -> 0 | J16: =TONTFEV23!F16+TONTFEV23!G16 -> 0 | K16: =VLOOKUP($A16,[6]HISTOMARS23!$A$6:$AV$45,17,0) -> 0 | L16: =IF(K16<>0,VLOOKUP($A16,[6]HISTOMARS23!$A$6:$BB$45,8,0),"ECHEC") -> ECHEC | M16: =IF(P16=0,0,VLOOKUP($A16,[6]HISTOMARS23!$A$6:$AV$45,32,0)) -> 0 | N16: =VLOOKUP($A16,[6]HISTOMARS23!$A$6:$AV$45,33,0) -> 0 | O16: =IF(P16=0,0,($C$3-P16)) -> 0 | P16: =VLOOKUP($A16,[6]HISTOMARS23!$A$6:$AV$45,30,0) -> 0
A17: AS201633 | B17: =IF(D17=0,0,VLOOKUP($A17,[6]HISTOMARS23!$A$6:$BB$45,12,0)) -> 1 | C17: =VLOOKUP(A17,[7]LISTADHERENT!A$5:H$60,3,0) -> PATEGO NJOSSU GUSTAVE | D17: =IF(E17="ECHEC",0,VLOOKUP($A17,[6]HISTOMARS23!$A$7:$AR$45,13,0)) -> 75000 | E17: =VLOOKUP($A17,[6]HISTOMARS23!$A$7:$AV$45,8,0) -> BANQUE | F17: =VLOOKUP($A17,[6]HISTOMARS23!$A$6:$AV$45,36,0) -> 0 | G17: =VLOOKUP($A17,[6]HISTOMARS23!$A$6:$AV$45,39,0) -> 0 | H17: =IF(G17=0,0,VLOOKUP($A17,[6]HISTOMARS23!$A$6:$AV$45,42,0)) -> 0 | I17: =VLOOKUP($A17,[6]HISTOMARS23!$A$6:$AV$45,41,0) -> 0 | J17: =TONTFEV23!F17+TONTFEV23!G17 -> 0 | K17: =VLOOKUP($A17,[6]HISTOMARS23!$A$6:$AV$45,17,0) -> 0 | L17: =IF(K17<>0,VLOOKUP($A17,[6]HISTOMARS23!$A$6:$BB$45,8,0),"ECHEC") -> ECHEC | M17: =IF(P17=0,0,VLOOKUP($A17,[6]HISTOMARS23!$A$6:$AV$45,32,0)) -> 0 | N17: =VLOOKUP($A17,[6]HISTOMARS23!$A$6:$AV$45,33,0) -> 0 | O17: =IF(P17=0,0,($C$3-P17)) -> 0 | P17: =VLOOKUP($A17,[6]HISTOMARS23!$A$6:$AV$45,30,0) -> 0
A18: AS201653 | B18: =IF(D18=0,0,VLOOKUP($A18,[6]HISTOMARS23!$A$6:$BB$45,12,0)) -> 1 | C18: =VLOOKUP(A18,[7]LISTADHERENT!A$5:H$60,3,0) -> SIME BRICE | D18: =IF(E18="ECHEC",0,VLOOKUP($A18,[6]HISTOMARS23!$A$7:$AR$45,13,0)) -> 75000 | E18: =VLOOKUP($A18,[6]HISTOMARS23!$A$7:$AV$45,8,0) -> BANQUE | F18: =VLOOKUP($A18,[6]HISTOMARS23!$A$6:$AV$45,36,0) -> 0 | G18: =VLOOKUP($A18,[6]HISTOMARS23!$A$6:$AV$45,39,0) -> 0 | H18: =IF(G18=0,0,VLOOKUP($A18,[6]HISTOMARS23!$A$6:$AV$45,42,0)) -> 0 | I18: =VLOOKUP($A18,[6]HISTOMARS23!$A$6:$AV$45,41,0) -> 0 | J18: =TONTFEV23!F18+TONTFEV23!G18 -> 0 | K18: =VLOOKUP($A18,[6]HISTOMARS23!$A$6:$AV$45,17,0) -> 0 | L18: =IF(K18<>0,VLOOKUP($A18,[6]HISTOMARS23!$A$6:$BB$45,8,0),"ECHEC") -> ECHEC | M18: =IF(P18=0,0,VLOOKUP($A18,[6]HISTOMARS23!$A$6:$AV$45,32,0)) -> 0 | N18: =VLOOKUP($A18,[6]HISTOMARS23!$A$6:$AV$45,33,0) -> 0 | O18: =IF(P18=0,0,($C$3-P18)) -> 0 | P18: =VLOOKUP($A18,[6]HISTOMARS23!$A$6:$AV$45,30,0) -> 0
A19: AS201641 | B19: =IF(D19=0,0,VLOOKUP($A19,[6]HISTOMARS23!$A$6:$BB$45,12,0)) -> 1 | C19: =VLOOKUP(A19,[7]LISTADHERENT!A$5:H$60,3,0) -> TCHOUAMOU MATHIEU | D19: =IF(E19="ECHEC",0,VLOOKUP($A19,[6]HISTOMARS23!$A$7:$AR$45,13,0)) -> 75000 | E19: =VLOOKUP($A19,[6]HISTOMARS23!$A$7:$AV$45,8,0) -> BANQUE | F19: =VLOOKUP($A19,[6]HISTOMARS23!$A$6:$AV$45,36,0) -> 0 | G19: =VLOOKUP($A19,[6]HISTOMARS23!$A$6:$AV$45,39,0) -> 0 | H19: =IF(G19=0,0,VLOOKUP($A19,[6]HISTOMARS23!$A$6:$AV$45,42,0)) -> 0 | I19: =VLOOKUP($A19,[6]HISTOMARS23!$A$6:$AV$45,41,0) -> 0 | J19: =TONTFEV23!F19+TONTFEV23!G19 -> 0 | K19: =VLOOKUP($A19,[6]HISTOMARS23!$A$6:$AV$45,17,0) -> 0 | L19: =IF(K19<>0,VLOOKUP($A19,[6]HISTOMARS23!$A$6:$BB$45,8,0),"ECHEC") -> ECHEC | M19: =IF(P19=0,0,VLOOKUP($A19,[6]HISTOMARS23!$A$6:$AV$45,32,0)) -> 0 | N19: =VLOOKUP($A19,[6]HISTOMARS23!$A$6:$AV$45,33,0) -> 0 | O19: =IF(P19=0,0,($C$3-P19)) -> 892500 | P19: =VLOOKUP($A19,[6]HISTOMARS23!$A$6:$AV$45,30,0) -> 7500
A20: AS201647 | B20: =IF(D20=0,0,VLOOKUP($A20,[6]HISTOMARS23!$A$6:$BB$45,12,0)) -> 2 | C20: =VLOOKUP(A20,[7]LISTADHERENT!A$5:H$60,3,0) -> YOUMBI EMMANUEL | D20: =IF(E20="ECHEC",0,VLOOKUP($A20,[6]HISTOMARS23!$A$7:$AR$45,13,0)) -> 150000 | E20: =VLOOKUP($A20,[6]HISTOMARS23!$A$7:$AV$45,8,0) -> BANQUE | F20: =VLOOKUP($A20,[6]HISTOMARS23!$A$6:$AV$45,36,0) -> 0 | G20: =VLOOKUP($A20,[6]HISTOMARS23!$A$6:$AV$45,39,0) -> 0 | H20: =IF(G20=0,0,VLOOKUP($A20,[6]HISTOMARS23!$A$6:$AV$45,42,0)) -> 0 | I20: =VLOOKUP($A20,[6]HISTOMARS23!$A$6:$AV$45,41,0) -> 0 | J20: =TONTFEV23!F20+TONTFEV23!G20 -> 0 | K20: =VLOOKUP($A20,[6]HISTOMARS23!$A$6:$AV$45,17,0) -> 0 | L20: =IF(K20<>0,VLOOKUP($A20,[6]HISTOMARS23!$A$6:$BB$45,8,0),"ECHEC") -> ECHEC | M20: =IF(P20=0,0,VLOOKUP($A20,[6]HISTOMARS23!$A$6:$AV$45,32,0)) -> 0 | N20: =VLOOKUP($A20,[6]HISTOMARS23!$A$6:$AV$45,33,0) -> 0 | O20: =IF(P20=0,0,($C$3-P20)) -> 0 | P20: =VLOOKUP($A20,[6]HISTOMARS23!$A$6:$AV$45,30,0) -> 0
A22: TOTAL PART | B22: =SUM(B6:B21) -> 17
A23: NBRE ADHERENT | B23: =COUNT(D6:D21) -> 15 | D23: =SUM(D6:D22) -> 1275000 | E23: =SUM(E6:E22) -> 0 | F23: =SUM(F6:F22) -> 0 | G23: =SUM(G6:G22) -> 0 | H23: =SUM(H6:H22) -> 0 | I23: =SUM(I6:I22) -> 0 | J23: =SUM(J6:J22) -> 0 | K23: =SUM(K6:K22) -> 0 | ... P23: =SUM(P6:P22) -> 15000
L24: NBRE PART | M24: PART VENDUE
D25: MONTANT TONTINE | E25: REMBOURSEMENT PETIT LOT | F25: VENTE PETIT LOT | G25: VENTE LOT PRINCIPAL | H25: SOLDE EN CAISSE | J25: TONTINE + REMB + INTERET VENTE+RELIQUAT | K25: =D29+E29+P23+TONTFEV23!M30 -> 2195000
D26: =SUMIFS(D6:D22,E6:E22,"ESPECES") -> 75000 | E26: =SUMIFS(K7:K17,L7:L17,"ESPECES") -> 0 | F26: =SUMIFS(F7:F22,H7:H22,"ESPECES") -> 0 | G26: =SUMIFS(O7:O22,M7:M22,"ESPECES") -> 0 | H26: =D26+E26-F26-G26 -> 75000 | J26: LOT PRINCIPAL | K26: =C3*COUNTIF(O7:O22,">0") -> 1800000 | L26: =D3 -> 2 | M26: =COUNTIF(O7:O17,">0") -> 1
D27: =SUMIFS(D6:D22,E6:E22,"BANQUE")+900000 -> 2100000 | E27: =SUMIFS(K7:K17,L7:L17,"BANQUE") -> 0 | F27: =SUMIFS(F7:F22,H7:H22,"BANQUE") -> 0 | G27: =SUMIFS(O7:O22,M7:M22,"BANQUE") -> 0 | H27: =D27+E27-F27-G27 -> 2100000
J28: PETIT LOT | K28: =K25-K26 -> 395000
D29: =D26+D27 -> 2175000 | E29: =E26+E27 -> 0 | F29: =F26+F27 -> 0 | G29: =G26+G27 -> 0 | H29: =H26+H27 -> 2175000
J30: RELIQUAT | K30: =K28-F23 -> 395000 | M30: =K30 -> 395000 | N30: CUMUL
J32: ECHEC TONTINE MOIS | K32: =COUNTIFS(E7:E21,"ECHEC")*75000 -> 0 | M32: =TONTFEV23!M32+TONTMARS23!K32 -> 0 | N32: CUMUL
J33: ECHEC REMBOURSEMENT MOIS | K33: =J23-E29 -> 0 | M33: =TONTFEV23!M33+TONTMARS23!K33 -> 0 | N33: CUMUL

Sheet TONTAVRIL23
A1: ASSOCIATION | B1: ASELBY
A2: ANNEE | B2: 2023 | C2: TONIINE | D2: NBRE PART
A3: TAUX TONTINE | B3: 75000 | C3: =B3*12 -> 900000 | D3: =ROUNDDOWN(K25/C3,0) -> 1
C4: 45029
A5: MATRICULE | B5: NBREPART | C5: NOM ET PRENOM | D5: MONTANT TONTINE | E5: MODE VERSEMENT | F5: VENTE PETIT LOT | G5: INTERET PETIT LOT | H5: MODE VERSEMENT VENTE PETIT LOT | I5: NUMERO CHEQUE | J5: MONTANT A REMBOURSER PETIT LOT | K5: REMBOURSEMENT PETIT LOT | L5: MODE VERSEMENT REMBOURSEMENT | M5: MODE VERSEMENTLOT PRINCIPAL | N5: NUMERO CHEQUE | O5: MONTANT LOT PRINCIPAL | P5: INTERET LOT PRINCIPAL
A6: AS201648 | B6: =IF(D6=0,0,VLOOKUP($A6,[6]HISTOAVRIL23!$A$6:$BB$45,12,0)) -> 1 | C6: =VLOOKUP(A6,[7]LISTADHERENT!A$5:H$60,3,0) -> ASELBY | D6: =IF(E6="ECHEC",0,VLOOKUP($A6,[6]HISTOAVRIL23!$A$6:$AR$45,13,0)) -> 75000 | E6: =VLOOKUP($A6,[6]HISTOAVRIL23!$A$6:$AV$45,8,0) -> BANQUE | F6: =VLOOKUP($A6,[6]HISTOAVRIL23!$A$6:$AV$45,36,0) -> 0 | G6: =VLOOKUP($A6,[6]HISTOAVRIL23!$A$6:$AV$45,39,0) -> 0 | H6: =IF(G6=0,0,VLOOKUP($A6,[6]HISTOAVRIL23!$A$6:$AV$45,42,0)) -> 0 | I6: =VLOOKUP($A6,[6]HISTOAVRIL23!$A$6:$AV$45,41,0) -> 0 | J6: =TONTMARS23!F6+TONTMARS23!G6 -> 0 | K6: =VLOOKUP($A6,[6]HISTOAVRIL23!$A$6:$AV$45,17,0) -> 0 | L6: =IF(K6<>0,VLOOKUP($A6,[6]HISTOAVRIL23!$A$6:$BB$45,8,0),"ECHEC") -> ECHEC | M6: =IF(P6=0,0,VLOOKUP($A6,[6]HISTOAVRIL23!$A$6:$AV$45,32,0)) -> 0 | N6: =VLOOKUP($A6,[6]HISTOAVRIL23!$A$6:$AV$45,33,0) -> 0 | O6: =IF(P6=0,0,($C$3-P6)) -> 0 | P6: =VLOOKUP($A6,[6]HISTOAVRIL23!$A$6:$AV$45,30,0) -> 0
A7: AS201602 | B7: =IF(D7=0,0,VLOOKUP($A7,[6]HISTOAVRIL23!$A$6:$BB$45,12,0)) -> 1 | C7: =VLOOKUP(A7,[7]LISTADHERENT!A$5:H$60,3,0) -> BOUTCHOUANG WILLIAM | D7: =IF(E7="ECHEC",0,VLOOKUP($A7,[6]HISTOAVRIL23!$A$6:$AR$45,13,0)) -> 75000 | E7: =VLOOKUP($A7,[6]HISTOAVRIL23!$A$6:$AV$45,8,0) -> BANQUE | F7: =VLOOKUP($A7,[6]HISTOAVRIL23!$A$6:$AV$45,36,0) -> 0 | G7: =VLOOKUP($A7,[6]HISTOAVRIL23!$A$6:$AV$45,39,0) -> 0 | H7: =IF(G7=0,0,VLOOKUP($A7,[6]HISTOAVRIL23!$A$6:$AV$45,42,0)) -> 0 | I7: =VLOOKUP($A7,[6]HISTOAVRIL23!$A$6:$AV$45,41,0) -> 0 | J7: =TONTMARS23!F7+TONTMARS23!G7 -> 0 | K7: =VLOOKUP($A7,[6]HISTOAVRIL23!$A$6:$AV$45,17,0) -> 0 | L7: =IF(K7<>0,VLOOKUP($A7,[6]HISTOAVRIL23!$A$6:$BB$45,8,0),"ECHEC") -> ECHEC | M7: =IF(P7=0,0,VLOOKUP($A7,[6]HISTOAVRIL23!$A$6:$AV$45,32,0)) -> 0 | N7: =VLOOKUP($A7,[6]HISTOAVRIL23!$A$6:$AV$45,33,0) -> 0 | O7: =IF(P7=0,0,($C$3-P7)) -> 0 | P7: =VLOOKUP($A7,[6]HISTOAVRIL23!$A$6:$AV$45,30,0) -> 0
A8: AS201605 | B8: =IF(D8=0,0,VLOOKUP($A8,[6]HISTOAVRIL23!$A$6:$BB$45,12,0)) -> 1 | C8: =VLOOKUP(A8,[7]LISTADHERENT!A$5:H$60,3,0) -> DJOUKWE NANGUEN GUY BLAISE | D8: =IF(E8="ECHEC",0,VLOOKUP($A8,[6]HISTOAVRIL23!$A$7:$AR$45,13,0)) -> 75000 | E8: =VLOOKUP($A8,[6]HISTOAVRIL23!$A$7:$AV$45,8,0) -> BANQUE | F8: =VLOOKUP($A8,[6]HISTOAVRIL23!$A$6:$AV$45,36,0) -> 150000 | G8: =VLOOKUP($A8,[6]HISTOAVRIL23!$A$6:$AV$45,39,0) -> 2000 | H8: =IF(G8=0,0,VLOOKUP($A8,[6]HISTOAVRIL23!$A$6:$AV$45,42,0)) -> 0 | I8: =VLOOKUP($A8,[6]HISTOAVRIL23!$A$6:$AV$45,41,0) -> 0 | J8: =TONTMARS23!F8+TONTMARS23!G8 -> 0 | K8: =VLOOKUP($A8,[6]HISTOAVRIL23!$A$6:$AV$45,17,0) -> 0 | L8: =IF(K8<>0,VLOOKUP($A8,[6]HISTOAVRIL23!$A$6:$BB$45,8,0),"ECHEC") -> ECHEC | M8: =IF(P8=0,0,VLOOKUP($A8,[6]HISTOAVRIL23!$A$6:$AV$45,32,0)) -> 0 | N8: =VLOOKUP($A8,[6]HISTOAVRIL23!$A$6:$AV$45,33,0) -> 0 | O8: =IF(P8=0,0,($C$3-P8)) -> 0 | P8: =VLOOKUP($A8,[6]HISTOAVRIL23!$A$6:$AV$45,30,0) -> 0
A9: AS201608 | B9: =IF(D9=0,0,VLOOKUP($A9,[6]HISTOAVRIL23!$A$6:$BB$45,12,0)) -> 1 | C9: =VLOOKUP(A9,[7]LISTADHERENT!A$5:H$60,3,0) -> DJUOMBESSY ANTOINE | D9: =IF(E9="ECHEC",0,VLOOKUP($A9,[6]HISTOAVRIL23!$A$7:$AR$45,13,0)) -> 75000 | E9: =VLOOKUP($A9,[6]HISTOAVRIL23!$A$7:$AV$45,8,0) -> BANQUE | F9: =VLOOKUP($A9,[6]HISTOAVRIL23!$A$6:$AV$45,36,0) -> 0 | G9: =VLOOKUP($A9,[6]HISTOAVRIL23!$A$6:$AV$45,39,0) -> 0 | H9: =IF(G9=0,0,VLOOKUP($A9,[6]HISTOAVRIL23!$A$6:$AV$45,42,0)) -> 0 | I9: =VLOOKUP($A9,[6]HISTOAVRIL23!$A$6:$AV$45,41,0) -> 0 | J9: =TONTMARS23!F9+TONTMARS23!G9 -> 0 | K9: =VLOOKUP($A9,[6]HISTOAVRIL23!$A$6:$AV$45,17,0) -> 0 | L9: =IF(K9<>0,VLOOKUP($A9,[6]HISTOAVRIL23!$A$6:$BB$45,8,0),"ECHEC") -> ECHEC | M9: =IF(P9=0,0,VLOOKUP($A9,[6]HISTOAVRIL23!$A$6:$AV$45,32,0)) -> 0 | N9: =VLOOKUP($A9,[6]HISTOAVRIL23!$A$6:$AV$45,33,0) -> 0 | O9: =IF(P9=0,0,($C$3-P9)) -> 0 | P9: =VLOOKUP($A9,[6]HISTOAVRIL23!$A$6:$AV$45,30,0) -> 0
A10: AS201613 | B10: =IF(D10=0,0,VLOOKUP($A10,[6]HISTOAVRIL23!$A$6:$BB$45,12,0)) -> 1 | C10: =VLOOKUP(A10,[7]LISTADHERENT!A$5:H$60,3,0) -> HOTCHO BENJAMIN | D10: =IF(E10="ECHEC",0,VLOOKUP($A10,[6]HISTOAVRIL23!$A$7:$AR$45,13,0)) -> 75000 | E10: =VLOOKUP($A10,[6]HISTOAVRIL23!$A$7:$AV$45,8,0) -> BANQUE | F10: =VLOOKUP($A10,[6]HISTOAVRIL23!$A$6:$AV$45,36,0) -> 0 | G10: =VLOOKUP($A10,[6]HISTOAVRIL23!$A$6:$AV$45,39,0) -> 0 | H10: =IF(G10=0,0,VLOOKUP($A10,[6]HISTOAVRIL23!$A$6:$AV$45,42,0)) -> 0 | I10: =VLOOKUP($A10,[6]HISTOAVRIL23!$A$6:$AV$45,41,0) -> 0 | J10: =TONTMARS23!F10+TONTMARS23!G10 -> 0 | K10: =VLOOKUP($A10,[6]HISTOAVRIL23!$A$6:$AV$45,17,0) -> 0 | L10: =IF(K10<>0,VLOOKUP($A10,[6]HISTOAVRIL23!$A$6:$BB$45,8,0),"ECHEC") -> ECHEC | M10: =IF(P10=0,0,VLOOKUP($A10,[6]HISTOAVRIL23!$A$6:$AV$45,32,0)) -> 0 | N10: =VLOOKUP($A10,[6]HISTOAVRIL23!$A$6:$AV$45,33,0) -> 0 | O10: =IF(P10=0,0,($C$3-P10)) -> 0 | P10: =VLOOKUP($A10,[6]HISTOAVRIL23!$A$6:$AV$45,30,0) -> 0
A11: AS201611 | B11: =IF(D11=0,0,VLOOKUP($A11,[6]HISTOAVRIL23!$A$6:$BB$45,12,0)) -> 1 | C11: =VLOOKUP(A11,[7]LISTADHERENT!A$5:H$60,3,0) -> HENGUE PAUL OMER | D11: =IF(E11="ECHEC",0,VLOOKUP($A11,[6]HISTOAVRIL23!$A$7:$AR$45,13,0)) -> 75000 | E11: =VLOOKUP($A11,[6]HISTOAVRIL23!$A$7:$AV$45,8,0) -> BANQUE | F11: =VLOOKUP($A11,[6]HISTOAVRIL23!$A$6:$AV$45,36,0) -> 0 | G11: =VLOOKUP($A11,[6]HISTOAVRIL23!$A$6:$AV$45,39,0) -> 0 | H11: =IF(G11=0,0,VLOOKUP($A11,[6]HISTOAVRIL23!$A$6:$AV$45,42,0)) -> 0 | I11: =VLOOKUP($A11,[6]HISTOAVRIL23!$A$6:$AV$45,41,0) -> 0 | J11: =TONTMARS23!F11+TONTMARS23!G11 -> 0 | K11: =VLOOKUP($A11,[6]HISTOAVRIL23!$A$6:$AV$45,17,0) -> 0 | L11: =IF(K11<>0,VLOOKUP($A11,[6]HISTOAVRIL23!$A$6:$BB$45,8,0),"ECHEC") -> ECHEC | M11: =IF(P11=0,0,VLOOKUP($A11,[6]HISTOAVRIL23!$A$6:$AV$45,32,0)) -> 0 | N11: =VLOOKUP($A11,[6]HISTOAVRIL23!$A$6:$AV$45,33,0) -> 0 | O11: =IF(P11=0,0,($C$3-P11)) -> 0 | P11: =VLOOKUP($A11,[6]HISTOAVRIL23!$A$6:$AV$45,30,0) -> 0
A12: AS201619 | B12: =IF(D12=0,0,VLOOKUP($A12,[6]HISTOAVRIL23!$A$6:$BB$45,12,0)) -> 1 | C12: =VLOOKUP(A12,[7]LISTADHERENT!A$5:H$60,3,0) -> KOUATCHO MESSACK | D12: =IF(E12="ECHEC",0,VLOOKUP($A12,[6]HISTOAVRIL23!$A$7:$AR$45,13,0)) -> 75000 | E12: =VLOOKUP($A12,[6]HISTOAVRIL23!$A$7:$AV$45,8,0) -> BANQUE | F12: =VLOOKUP($A12,[6]HISTOAVRIL23!$A$6:$AV$45,36,0) -> 100000 | G12: =VLOOKUP($A12,[6]HISTOAVRIL23!$A$6:$AV$45,39,0) -> 1000 | H12: =IF(G12=0,0,VLOOKUP($A12,[6]HISTOAVRIL23!$A$6:$AV$45,42,0)) -> BANQUE | I12: =VLOOKUP($A12,[6]HISTOAVRIL23!$A$6:$AV$45,41,0) -> 0 | J12: =TONTMARS23!F12+TONTMARS23!G12 -> 0 | K12: =VLOOKUP($A12,[6]HISTOAVRIL23!$A$6:$AV$45,17,0) -> 0 | L12: =IF(K12<>0,VLOOKUP($A12,[6]HISTOAVRIL23!$A$6:$BB$45,8,0),"ECHEC") -> ECHEC | M12: =IF(P12=0,0,VLOOKUP($A12,[6]HISTOAVRIL23!$A$6:$AV$45,32,0)) -> 0 | N12: =VLOOKUP($A12,[6]HISTOAVRIL23!$A$6:$AV$45,33,0) -> 0 | O12: =IF(P12=0,0,($C$3-P12)) -> 887000 | P12: =VLOOKUP($A12,[6]HISTOAVRIL23!$A$6:$AV$45,30,0) -> 13000
A13: AS201649 | B13: =IF(D13=0,0,VLOOKUP($A13,[6]HISTOAVRIL23!$A$6:$BB$45,12,0)) -> 1 | C13: =VLOOKUP(A13,[7]LISTADHERENT!A$5:H$60,3,0) -> MBOGNING TUGMA GUY | D13: =IF(E13="ECHEC",0,VLOOKUP($A13,[6]HISTOAVRIL23!$A$7:$AR$45,13,0)) -> 75000 | E13: =VLOOKUP($A13,[6]HISTOAVRIL23!$A$7:$AV$45,8,0) -> BANQUE | F13: =VLOOKUP($A13,[6]HISTOAVRIL23!$A$6:$AV$45,36,0) -> 0 | G13: =VLOOKUP($A13,[6]HISTOAVRIL23!$A$6:$AV$45,39,0) -> 0 | H13: =IF(G13=0,0,VLOOKUP($A13,[6]HISTOAVRIL23!$A$6:$AV$45,42,0)) -> 0 | I13: =VLOOKUP($A13,[6]HISTOAVRIL23!$A$6:$AV$45,41,0) -> 0 | J13: =TONTMARS23!F13+TONTMARS23!G13 -> 0 | K13: =VLOOKUP($A13,[6]HISTOAVRIL23!$A$6:$AV$45,17,0) -> 0 | L13: =IF(K13<>0,VLOOKUP($A13,[6]HISTOAVRIL23!$A$6:$BB$45,8,0),"ECHEC") -> ECHEC | M13: =IF(P13=0,0,VLOOKUP($A13,[6]HISTOAVRIL23!$A$6:$AV$45,32,0)) -> 0 | N13: =VLOOKUP($A13,[6]HISTOAVRIL23!$A$6:$AV$45,33,0) -> 0 | O13: =IF(P13=0,0,($C$3-P13)) -> 0 | P13: =VLOOKUP($A13,[6]HISTOAVRIL23!$A$6:$AV$45,30,0) -> 0
A14: AS201621 | B14: =IF(D14=0,0,VLOOKUP($A14,[6]HISTOAVRIL23!$A$6:$BB$45,12,0)) -> 1 | C14: =VLOOKUP(A14,[7]LISTADHERENT!A$5:H$60,3,0) -> NANKAM APPOLINAIRE | D14: =IF(E14="ECHEC",0,VLOOKUP($A14,[6]HISTOAVRIL23!$A$7:$AR$45,13,0)) -> 75000 | E14: =VLOOKUP($A14,[6]HISTOAVRIL23!$A$7:$AV$45,8,0) -> BANQUE | F14: =VLOOKUP($A14,[6]HISTOAVRIL23!$A$6:$AV$45,36,0) -> 0 | G14: =VLOOKUP($A14,[6]HISTOAVRIL23!$A$6:$AV$45,39,0) -> 0 | H14: =IF(G14=0,0,VLOOKUP($A14,[6]HISTOAVRIL23!$A$6:$AV$45,42,0)) -> 0 | I14: =VLOOKUP($A14,[6]HISTOAVRIL23!$A$6:$AV$45,41,0) -> 0 | J14: =TONTMARS23!F14+TONTMARS23!G14 -> 0 | K14: =VLOOKUP($A14,[6]HISTOAVRIL23!$A$6:$AV$45,17,0) -> 0 | L14: =IF(K14<>0,VLOOKUP($A14,[6]HISTOAVRIL23!$A$6:$BB$45,8,0),"ECHEC") -> ECHEC | M14: =IF(P14=0,0,VLOOKUP($A14,[6]HISTOAVRIL23!$A$6:$AV$45,32,0)) -> 0 | N14: =VLOOKUP($A14,[6]HISTOAVRIL23!$A$6:$AV$45,33,0) -> 0 | O14: =IF(P14=0,0,($C$3-P14)) -> 0 | P14: =VLOOKUP($A14,[6]HISTOAVRIL23!$A$6:$AV$45,30,0) -> 0
