Workbook
Name BANQUE: #REF!
Name BANQUE: #REF!
Name BANQUE: #REF!
Name BANQUE: #REF!
Name BANQUE: #REF!
Name BANQUE: #REF!
Name BANQUE: #REF!
Name BANQUE: #REF!
Name BANQUE: #REF!
Name BANQUE: #REF!
Name BANQUE: #REF!
Name BANQUE: #REF!
Name BANQUE: #REF!
Name BANQUE: #REF!
Name BANQUE: #REF!
Name MODEPAID: #REF!
Name MODEPAID: [1]Feuil2!$A$1:$A$3
Name MODET25000: [2]MODEVERSEMENT!$A$1:$A$3
Name MODEVERSEMENT: #REF!
Name MODEVERSEMENT: #REF!
Name MODEVERSEMENT: #REF!
Name MODEVERSEMENT: #REF!
Name MODEVERSEMENT: #REF!
Name MODEVERSEMENT: #REF!
Name MODEVERSEMENT: #REF!
Name MODEVERSEMENT: #REF!
Name MODEVERSEMENT: #REF!
Name MODEVERSEMENT: #REF!
Name MODEVERSEMENT: #REF!
Name MODEVERSEMENT: #REF!
Name MODEVERSEMENT: #REF!
Name MODEVERSEMENT: #REF!
Name MODEVERSEMENT: #REF!
Name MODEVERSEMENTS: [3]MODEVERSEMENT!$A$1:$A$3
Name MODEVERSEMENTS: [3]MODEVERSEMENT!$A$1:$A$3
Name MODEVERSEMENTS: [3]MODEVERSEMENT!$A$1:$A$3
Name MODEVERSEMENTS: [3]MODEVERSEMENT!$A$1:$A$3
Name MODEVERSEMENTS: [3]MODEVERSEMENT!$A$1:$A$3
Name MODEVERSEMENTS: [3]MODEVERSEMENT!$A$1:$A$3
Name MODEVERSEMENTS: [3]MODEVERSEMENT!$A$1:$A$3
Name MODEVERSEMENTS: [3]MODEVERSEMENT!$A$1:$A$3
Name MODEVERSEMENTS: [3]MODEVERSEMENT!$A$1:$A$3
Name MODEVERSEMENTS: [3]MODEVERSEMENT!$A$1:$A$3
Name MODEVERSEMENTS: [3]MODEVERSEMENT!$A$1:$A$3
Name MODEVERSEMENTS: [3]MODEVERSEMENT!$A$1:$A$3
Name MODEVERSEMENTS: [3]MODEVERSEMENT!$A$1:$A$3
Name MODEVERSEMENTS: MODEVERSEMENT!$A$1:$A$3
Name MODPAID: TONTAOUT23!#REF!
Name MODPAID: TONTAVRIL23!#REF!
Name MODPAID: TONTDEC23!#REF!
Name MODPAID: TONTFEV23!#REF!
Name MODPAID: TONTJANV23!#REF!
Name MODPAID: TONTJUIL23!#REF!
Name MODPAID: TONTJUIN23!#REF!
Name MODPAID: TONTMAI23!#REF!
Name MODPAID: TONTMARS23!#REF!
Name MODPAID: TONTNOV23!#REF!
Name MODPAID: TONTOCT23!#REF!
Name MODPAID: TONTRESUME23!#REF!
Name MODPAID: TONTSEPT23!#REF!

Sheet MODEVERSEMENT
A1: BANQUE
A2: ESPECES
A3: ECHEC

Sheet TONTJANV23
A1: ASSOCIATION | B1: ASELBY
A2: ANNEE | B2: 2023 | C2: TONIINE | D2: NBRE PART
A3: TAUX TONTINE | B3: 25000 | C3: =B3*12 -> 300000 | D3: =ROUNDDOWN(M40/C3,0) -> 2
C4: 44939
A5: MATRICULE | B5: NBREPART | C5: NOM ET PRENOM | D5: MONTANT TONTINE | E5: MONTANT VERSE | F5: PENALITE VERSEMENT ESPECES | G5: MODE VERSEMENT | H5: VENTE PETIT LOT | I5: INTERET PETIT LOT | J5: MODE VERSEMENT VENTE PETIT LOT | K5: NUMERO CHEQUE | L5: MONTANT A REMBOURSER PETIT LOT | M5: REMBOURSEMENT PETIT LOT | N5: MODE VERSEMENT REMBOURSEMENT | O5: MODE VERSEMENTLOT PRINCIPAL | P5: NUMERO CHEQUE | Q5: MONTANT LOT PRINCIPAL | R5: INTERET LOT PRINCIPAL
A6: AS201601 | B6: =IF(D6=0,0,VLOOKUP($A6,[6]HISTOJANV23!$A$6:$BP$42,10,0)) -> 1 | C6: =VLOOKUP(A6,[7]LISTADHERENT!A$5:H$60,3,0) -> BAKOP ACHILLE | D6: =IF(G6="ECHEC",0,B$3) -> 25000 | E6: =D6+VLOOKUP($A6,[6]HISTOJANV23!$A$7:$AU$40,45,0)+F6 -> 104000 | F6: =VLOOKUP($A6,[6]HISTOJANV23!$A$6:$AV$47,7,0) -> 0 | G6: =VLOOKUP($A6,[6]HISTOJANV23!$A$6:$AV$47,8,0) -> ESPECES | H6: =VLOOKUP($A6,[6]HISTOJANV23!$A$6:$AV$47,35,0) -> 0 | I6: =VLOOKUP($A6,[6]HISTOJANV23!$A$6:$AV$47,38,0) -> 0 | J6: =IF(H6=0,0,VLOOKUP($A6,[6]HISTOJANV23!$A$6:$AV$47,42,0)) -> 0 | K6: =VLOOKUP($A6,[6]HISTOJANV23!$A$6:$AV$47,41,0) -> 0 | M6: =VLOOKUP($A6,[6]HISTOJANV23!$A$6:$AV$47,16,0) -> 0 | N6: =IF(M6<>0,VLOOKUP($A6,[6]HISTOJANV23!$A$6:$AV$47,8,0),"ECHEC") -> ECHEC | O6: =IF(R6=0,0,VLOOKUP($A6,[6]HISTOJANV23!$A$6:$AV$47,32,0)) -> 0 | P6: =VLOOKUP($A6,[6]HISTOJANV23!$A$6:$AV$47,33,0) -> 0 | Q6: =IF(R6=0,0,($C$3-R6)) -> 0 | R6: =VLOOKUP($A6,[6]HISTOJANV23!$A$6:$AV$47,29,0) -> 0
A7: AS201602 | B7: =IF(D7=0,0,VLOOKUP($A7,[6]HISTOJANV23!$A$6:$BP$42,10,0)) -> 1 | C7: =VLOOKUP(A7,[7]LISTADHERENT!A$5:H$60,3,0) -> BOUTCHOUANG WILLIAM | D7: =IF(G7="ECHEC",0,B$3) -> 25000 | E7: =D7+VLOOKUP($A7,[6]HISTOJANV23!$A$7:$AU$40,45,0)+F7 -> 40000 | F7: =VLOOKUP($A7,[6]HISTOJANV23!$A$6:$AV$47,7,0) -> 0 | G7: =VLOOKUP($A7,[6]HISTOJANV23!$A$6:$AV$47,8,0) -> BANQUE | H7: =VLOOKUP($A7,[6]HISTOJANV23!$A$6:$AV$47,35,0) -> 0 | I7: =VLOOKUP($A7,[6]HISTOJANV23!$A$6:$AV$47,38,0) -> 0 | J7: =IF(H7=0,0,VLOOKUP($A7,[6]HISTOJANV23!$A$6:$AV$47,42,0)) -> 0 | K7: =VLOOKUP($A7,[6]HISTOJANV23!$A$6:$AV$47,41,0) -> 0 | M7: =VLOOKUP($A7,[6]HISTOJANV23!$A$6:$AV$47,16,0) -> 0 | N7: =IF(M7<>0,VLOOKUP($A7,[6]HISTOJANV23!$A$6:$AV$47,8,0),"ECHEC") -> ECHEC | O7: =IF(R7=0,0,VLOOKUP($A7,[6]HISTOJANV23!$A$6:$AV$47,32,0)) -> 0 | P7: =VLOOKUP($A7,[6]HISTOJANV23!$A$6:$AV$47,33,0) -> 0 | Q7: =IF(R7=0,0,($C$3-R7)) -> 0 | R7: =VLOOKUP($A7,[6]HISTOJANV23!$A$6:$AV$47,29,0) -> 0
A8: AS201604 | B8: =IF(D8=0,0,VLOOKUP($A8,[6]HISTOJANV23!$A$6:$BP$42,10,0)) -> 1 | C8: =VLOOKUP(A8,[7]LISTADHERENT!A$5:H$60,3,0) -> DJOMO JEAN PAUL | D8: =IF(G8="ECHEC",0,B$3) -> 25000 | E8: =D8+VLOOKUP($A8,[6]HISTOJANV23!$A$7:$AU$40,45,0)+F8 -> 60000 | F8: =VLOOKUP($A8,[6]HISTOJANV23!$A$6:$AV$47,7,0) -> 0 | G8: =VLOOKUP($A8,[6]HISTOJANV23!$A$6:$AV$47,8,0) -> BANQUE | H8: =VLOOKUP($A8,[6]HISTOJANV23!$A$6:$AV$47,35,0) -> 0 | I8: =VLOOKUP($A8,[6]HISTOJANV23!$A$6:$AV$47,38,0) -> 0 | J8: =IF(H8=0,0,VLOOKUP($A8,[6]HISTOJANV23!$A$6:$AV$47,42,0)) -> 0 | K8: =VLOOKUP($A8,[6]HISTOJANV23!$A$6:$AV$47,41,0) -> 0 | M8: =VLOOKUP($A8,[6]HISTOJANV23!$A$6:$AV$47,16,0) -> 0 | N8: =IF(M8<>0,VLOOKUP($A8,[6]HISTOJANV23!$A$6:$AV$47,8,0),"ECHEC") -> ECHEC | O8: =IF(R8=0,0,VLOOKUP($A8,[6]HISTOJANV23!$A$6:$AV$47,32,0)) -> BANQUE | P8: =VLOOKUP($A8,[6]HISTOJANV23!$A$6:$AV$47,33,0) -> 0 | Q8: =IF(R8=0,0,($C$3-R8)) -> 255000 | R8: =VLOOKUP($A8,[6]HISTOJANV23!$A$6:$AV$47,29,0) -> 45000
A9: AS201654 | B9: =IF(D9=0,0,VLOOKUP($A9,[6]HISTOJANV23!$A$6:$BP$42,10,0)) -> 1 | C9: =VLOOKUP(A9,[7]LISTADHERENT!A$5:H$60,3,0) -> DJOMOU TCHAPDA | D9: =IF(G9="ECHEC",0,B$3) -> 25000 | E9: =D9+VLOOKUP($A9,[6]HISTOJANV23!$A$7:$AU$40,45,0)+F9 -> 40000 | F9: =VLOOKUP($A9,[6]HISTOJANV23!$A$6:$AV$47,7,0) -> 0 | G9: =VLOOKUP($A9,[6]HISTOJANV23!$A$6:$AV$47,8,0) -> BANQUE | H9: =VLOOKUP($A9,[6]HISTOJANV23!$A$6:$AV$47,35,0) -> 60000 | I9: =VLOOKUP($A9,[6]HISTOJANV23!$A$6:$AV$47,38,0) -> 3000 | J9: =IF(H9=0,0,VLOOKUP($A9,[6]HISTOJANV23!$A$6:$AV$47,42,0)) -> BANQUE | K9: =VLOOKUP($A9,[6]HISTOJANV23!$A$6:$AV$47,41,0) -> 0 | M9: =VLOOKUP($A9,[6]HISTOJANV23!$A$6:$AV$47,16,0) -> 0 | N9: =IF(M9<>0,VLOOKUP($A9,[6]HISTOJANV23!$A$6:$AV$47,8,0),"ECHEC") -> ECHEC | O9: =IF(R9=0,0,VLOOKUP($A9,[6]HISTOJANV23!$A$6:$AV$47,32,0)) -> 0 | P9: =VLOOKUP($A9,[6]HISTOJANV23!$A$6:$AV$47,33,0) -> 0 | Q9: =IF(R9=0,0,($C$3-R9)) -> 0 | R9: =VLOOKUP($A9,[6]HISTOJANV23!$A$6:$AV$47,29,0) -> 0
A10: AS201605 | B10: =IF(D10=0,0,VLOOKUP($A10,[6]HISTOJANV23!$A$6:$BP$42,10,0)) -> 1 | C10: =VLOOKUP(A10,[7]LISTADHERENT!A$5:H$60,3,0) -> DJOUKWE NANGUEN GUY BLAISE | D10: =IF(G10="ECHEC",0,B$3) -> 25000 | E10: =D10+VLOOKUP($A10,[6]HISTOJANV23!$A$7:$AU$40,45,0)+F10 -> 40000 | F10: =VLOOKUP($A10,[6]HISTOJANV23!$A$6:$AV$47,7,0) -> 0 | G10: =VLOOKUP($A10,[6]HISTOJANV23!$A$6:$AV$47,8,0) -> BANQUE | H10: =VLOOKUP($A10,[6]HISTOJANV23!$A$6:$AV$47,35,0) -> 60000 | I10: =VLOOKUP($A10,[6]HISTOJANV23!$A$6:$AV$47,38,0) -> 2000 | J10: =IF(H10=0,0,VLOOKUP($A10,[6]HISTOJANV23!$A$6:$AV$47,42,0)) -> BANQUE | K10: =VLOOKUP($A10,[6]HISTOJANV23!$A$6:$AV$47,41,0) -> 0 | M10: =VLOOKUP($A10,[6]HISTOJANV23!$A$6:$AV$47,16,0) -> 0 | N10: =IF(M10<>0,VLOOKUP($A10,[6]HISTOJANV23!$A$6:$AV$47,8,0),"ECHEC") -> ECHEC | O10: =IF(R10=0,0,VLOOKUP($A10,[6]HISTOJANV23!$A$6:$AV$47,32,0)) -> 0 | P10: =VLOOKUP($A10,[6]HISTOJANV23!$A$6:$AV$47,33,0) -> 0 | Q10: =IF(R10=0,0,($C$3-R10)) -> 0 | R10: =VLOOKUP($A10,[6]HISTOJANV23!$A$6:$AV$47,29,0) -> 0
A11: AS201608 | B11: =IF(D11=0,0,VLOOKUP($A11,[6]HISTOJANV23!$A$6:$BP$42,10,0)) -> 1 | C11: =VLOOKUP(A11,[7]LISTADHERENT!A$5:H$60,3,0) -> DJUOMBESSY ANTOINE | D11: =IF(G11="ECHEC",0,B$3) -> 25000 | E11: =D11+VLOOKUP($A11,[6]HISTOJANV23!$A$7:$AU$40,45,0)+F11 -> 45000 | F11: =VLOOKUP($A11,[6]HISTOJANV23!$A$6:$AV$47,7,0) -> 0 | G11: =VLOOKUP($A11,[6]HISTOJANV23!$A$6:$AV$47,8,0) -> BANQUE | H11: =VLOOKUP($A11,[6]HISTOJANV23!$A$6:$AV$47,35,0) -> 0 | I11: =VLOOKUP($A11,[6]HISTOJANV23!$A$6:$AV$47,38,0) -> 0 | J11: =IF(H11=0,0,VLOOKUP($A11,[6]HISTOJANV23!$A$6:$AV$47,42,0)) -> 0 | K11: =VLOOKUP($A11,[6]HISTOJANV23!$A$6:$AV$47,41,0) -> 0 | M11: =VLOOKUP($A11,[6]HISTOJANV23!$A$6:$AV$47,16,0) -> 0 | N11: =IF(M11<>0,VLOOKUP($A11,[6]HISTOJANV23!$A$6:$AV$47,8,0),"ECHEC") -> ECHEC | O11: =IF(R11=0,0,VLOOKUP($A11,[6]HISTOJANV23!$A$6:$AV$47,32,0)) -> 0 | P11: =VLOOKUP($A11,[6]HISTOJANV23!$A$6:$AV$47,33,0) -> 0 | Q11: =IF(R11=0,0,($C$3-R11)) -> 0 | R11: =VLOOKUP($A11,[6]HISTOJANV23!$A$6:$AV$47,29,0) -> 0
A12: AS201651 | B12: =IF(D12=0,0,VLOOKUP($A12,[6]HISTOJANV23!$A$6:$BP$42,10,0)) -> 1 | C12: =VLOOKUP(A12,[7]LISTADHERENT!A$5:H$60,3,0) -> DOMOU FABIEN | D12: =IF(G12="ECHEC",0,B$3) -> 25000 | E12: =D12+VLOOKUP($A12,[6]HISTOJANV23!$A$7:$AU$40,45,0)+F12 -> 40000 | F12: =VLOOKUP($A12,[6]HISTOJANV23!$A$6:$AV$47,7,0) -> 0 | G12: =VLOOKUP($A12,[6]HISTOJANV23!$A$6:$AV$47,8,0) -> BANQUE | H12: =VLOOKUP($A12,[6]HISTOJANV23!$A$6:$AV$47,35,0) -> 0 | I12: =VLOOKUP($A12,[6]HISTOJANV23!$A$6:$AV$47,38,0) -> 0 | J12: =IF(H12=0,0,VLOOKUP($A12,[6]HISTOJANV23!$A$6:$AV$47,42,0)) -> 0 | K12: =VLOOKUP($A12,[6]HISTOJANV23!$A$6:$AV$47,41,0) -> 0 | M12: =VLOOKUP($A12,[6]HISTOJANV23!$A$6:$AV$47,16,0) -> 0 | N12: =IF(M12<>0,VLOOKUP($A12,[6]HISTOJANV23!$A$6:$AV$47,8,0),"ECHEC") -> ECHEC | O12: =IF(R12=0,0,VLOOKUP($A12,[6]HISTOJANV23!$A$6:$AV$47,32,0)) -> 0 | P12: =VLOOKUP($A12,[6]HISTOJANV23!$A$6:$AV$47,33,0) -> 0 | Q12: =IF(R12=0,0,($C$3-R12)) -> 0 | R12: =VLOOKUP($A12,[6]HISTOJANV23!$A$6:$AV$47,29,0) -> 0
A13: AS201609 | B13: =IF(D13=0,0,VLOOKUP($A13,[6]HISTOJANV23!$A$6:$BP$42,10,0)) -> 1 | C13: =VLOOKUP(A13,[7]LISTADHERENT!A$5:H$60,3,0) -> DONHOU DAVID | D13: =IF(G13="ECHEC",0,B$3) -> 25000 | E13: =D13+VLOOKUP($A13,[6]HISTOJANV23!$A$7:$AU$40,45,0)+F13 -> 40000 | F13: =VLOOKUP($A13,[6]HISTOJANV23!$A$6:$AV$47,7,0) -> 0 | G13: =VLOOKUP($A13,[6]HISTOJANV23!$A$6:$AV$47,8,0) -> BANQUE | H13: =VLOOKUP($A13,[6]HISTOJANV23!$A$6:$AV$47,35,0) -> 0 | I13: =VLOOKUP($A13,[6]HISTOJANV23!$A$6:$AV$47,38,0) -> 0 | J13: =IF(H13=0,0,VLOOKUP($A13,[6]HISTOJANV23!$A$6:$AV$47,42,0)) -> 0 | K13: =VLOOKUP($A13,[6]HISTOJANV23!$A$6:$AV$47,41,0) -> 0 | M13: =VLOOKUP($A13,[6]HISTOJANV23!$A$6:$AV$47,16,0) -> 0 | N13: =IF(M13<>0,VLOOKUP($A13,[6]HISTOJANV23!$A$6:$AV$47,8,0),"ECHEC") -> ECHEC | O13: =IF(R13=0,0,VLOOKUP($A13,[6]HISTOJANV23!$A$6:$AV$47,32,0)) -> 0 | P13: =VLOOKUP($A13,[6]HISTOJANV23!$A$6:$AV$47,33,0) -> 0 | Q13: =IF(R13=0,0,($C$3-R13)) -> 0 | R13: =VLOOKUP($A13,[6]HISTOJANV23!$A$6:$AV$47,29,0) -> 0
A14: AS201611 | B14: =IF(D14=0,0,VLOOKUP($A14,[6]HISTOJANV23!$A$6:$BP$42,10,0)) -> 1 | C14: =VLOOKUP(A14,[7]LISTADHERENT!A$5:H$60,3,0) -> HENGUE PAUL OMER | D14: =IF(G14="ECHEC",0,B$3) -> 25000 | E14: =D14+VLOOKUP($A14,[6]HISTOJANV23!$A$7:$AU$40,45,0)+F14 -> 40000 | F14: =VLOOKUP($A14,[6]HISTOJANV23!$A$6:$AV$47,7,0) -> 0 | G14: =VLOOKUP($A14,[6]HISTOJANV23!$A$6:$AV$47,8,0) -> BANQUE | H14: =VLOOKUP($A14,[6]HISTOJANV23!$A$6:$AV$47,35,0) -> 0 | I14: =VLOOKUP($A14,[6]HISTOJANV23!$A$6:$AV$47,38,0) -> 0 | J14: =IF(H14=0,0,VLOOKUP($A14,[6]HISTOJANV23!$A$6:$AV$47,42,0)) -> 0 | K14: =VLOOKUP($A14,[6]HISTOJANV23!$A$6:$AV$47,41,0) -> 0 | M14: =VLOOKUP($A14,[6]HISTOJANV23!$A$6:$AV$47,16,0) -> 0 | N14: =IF(M14<>0,VLOOKUP($A14,[6]HISTOJANV23!$A$6:$AV$47,8,0),"ECHEC") -> ECHEC | O14: =IF(R14=0,0,VLOOKUP($A14,[6]HISTOJANV23!$A$6:$AV$47,32,0)) -> 0 | P14: =VLOOKUP($A14,[6]HISTOJANV23!$A$6:$AV$47,33,0) -> 0 | Q14: =IF(R14=0,0,($C$3-R14)) -> 0 | R14: =VLOOKUP($A14,[6]HISTOJANV23!$A$6:$AV$47,29,0) -> 0
A15: AS201613 | B15: =IF(D15=0,0,VLOOKUP($A15,[6]HISTOJANV23!$A$6:$BP$42,10,0)) -> 1 | C15: =VLOOKUP(A15,[7]LISTADHERENT!A$5:H$60,3,0) -> HOTCHO BENJAMIN | D15: =IF(G15="ECHEC",0,B$3) -> 25000 | E15: =D15+VLOOKUP($A15,[6]HISTOJANV23!$A$7:$AU$40,45,0)+F15 -> 75000 | F15: =VLOOKUP($A15,[6]HISTOJANV23!$A$6:$AV$47,7,0) -> 0 | G15: =VLOOKUP($A15,[6]HISTOJANV23!$A$6:$AV$47,8,0) -> BANQUE | H15: =VLOOKUP($A15,[6]HISTOJANV23!$A$6:$AV$47,35,0) -> 0 | I15: =VLOOKUP($A15,[6]HISTOJANV23!$A$6:$AV$47,38,0) -> 0 | J15: =IF(H15=0,0,VLOOKUP($A15,[6]HISTOJANV23!$A$6:$AV$47,42,0)) -> 0 | K15: =VLOOKUP($A15,[6]HISTOJANV23!$A$6:$AV$47,41,0) -> 0 | M15: =VLOOKUP($A15,[6]HISTOJANV23!$A$6:$AV$47,16,0) -> 0 | N15: =IF(M15<>0,VLOOKUP($A15,[6]HISTOJANV23!$A$6:$AV$47,8,0),"ECHEC") -> ECHEC | O15: =IF(R15=0,0,VLOOKUP($A15,[6]HISTOJANV23!$A$6:$AV$47,32,0)) -> 0 | P15: =VLOOKUP($A15,[6]HISTOJANV23!$A$6:$AV$47,33,0) -> 0 | Q15: =IF(R15=0,0,($C$3-R15)) -> 0 | R15: =VLOOKUP($A15,[6]HISTOJANV23!$A$6:$AV$47,29,0) -> 0
A16: AS201617 | B16: =IF(D16=0,0,VLOOKUP($A16,[6]HISTOJANV23!$A$6:$BP$42,10,0)) -> 1 | C16: =VLOOKUP(A16,[7]LISTADHERENT!A$5:H$60,3,0) -> KOUAMOU MOISE | D16: =IF(G16="ECHEC",0,B$3) -> 25000 | E16: =D16+VLOOKUP($A16,[6]HISTOJANV23!$A$7:$AU$40,45,0)+F16 -> 40000 | F16: =VLOOKUP($A16,[6]HISTOJANV23!$A$6:$AV$47,7,0) -> 0 | G16: =VLOOKUP($A16,[6]HISTOJANV23!$A$6:$AV$47,8,0) -> BANQUE | H16: =VLOOKUP($A16,[6]HISTOJANV23!$A$6:$AV$47,35,0) -> 0 | I16: =VLOOKUP($A16,[6]HISTOJANV23!$A$6:$AV$47,38,0) -> 0 | J16: =IF(H16=0,0,VLOOKUP($A16,[6]HISTOJANV23!$A$6:$AV$47,42,0)) -> 0 | K16: =VLOOKUP($A16,[6]HISTOJANV23!$A$6:$AV$47,41,0) -> 0 | M16: =VLOOKUP($A16,[6]HISTOJANV23!$A$6:$AV$47,16,0) -> 0 | N16: =IF(M16<>0,VLOOKUP($A16,[6]HISTOJANV23!$A$6:$AV$47,8,0),"ECHEC") -> ECHEC | O16: =IF(R16=0,0,VLOOKUP($A16,[6]HISTOJANV23!$A$6:$AV$47,32,0)) -> 0 | P16: =VLOOKUP($A16,[6]HISTOJANV23!$A$6:$AV$47,33,0) -> 0 | Q16: =IF(R16=0,0,($C$3-R16)) -> 0 | R16: =VLOOKUP($A16,[6]HISTOJANV23!$A$6:$AV$47,29,0) -> 0
A17: AS201619 | B17: =IF(D17=0,0,VLOOKUP($A17,[6]HISTOJANV23!$A$6:$BP$42,10,0)) -> 1 | C17: =VLOOKUP(A17,[7]LISTADHERENT!A$5:H$60,3,0) -> KOUATCHO MESSACK | D17: =IF(G17="ECHEC",0,B$3) -> 25000 | E17: =D17+VLOOKUP($A17,[6]HISTOJANV23!$A$7:$AU$40,45,0)+F17 -> 40000 | F17: =VLOOKUP($A17,[6]HISTOJANV23!$A$6:$AV$47,7,0) -> 0 | G17: =VLOOKUP($A17,[6]HISTOJANV23!$A$6:$AV$47,8,0) -> BANQUE | H17: =VLOOKUP($A17,[6]HISTOJANV23!$A$6:$AV$47,35,0) -> 0 | I17: =VLOOKUP($A17,[6]HISTOJANV23!$A$6:$AV$47,38,0) -> 0 | J17: =IF(H17=0,0,VLOOKUP($A17,[6]HISTOJANV23!$A$6:$AV$47,42,0)) -> 0 | K17: =VLOOKUP($A17,[6]HISTOJANV23!$A$6:$AV$47,41,0) -> 0 | M17: =VLOOKUP($A17,[6]HISTOJANV23!$A$6:$AV$47,16,0) -> 0 | N17: =IF(M17<>0,VLOOKUP($A17,[6]HISTOJANV23!$A$6:$AV$47,8,0),"ECHEC") -> ECHEC | O17: =IF(R17=0,0,VLOOKUP($A17,[6]HISTOJANV23!$A$6:$AV$47,32,0)) -> BANQUE | P17: =VLOOKUP($A17,[6]HISTOJANV23!$A$6:$AV$47,33,0) -> 0 | Q17: =IF(R17=0,0,($C$3-R17)) -> 260000 | R17: =VLOOKUP($A17,[6]HISTOJANV23!$A$6:$AV$47,29,0) -> 40000
... A35: AS201647 | B35: =IF(D35=0,0,VLOOKUP($A35,[6]HISTOJANV23!$A$6:$BP$42,10,0)) -> 1 | C35: =VLOOKUP(A35,[7]LISTADHERENT!A$5:H$60,3,0) -> YOUMBI EMMANUEL | D35: =IF(G35="ECHEC",0,B$3) -> 25000 | E35: =D35+VLOOKUP($A35,[6]HISTOJANV23!$A$7:$AU$40,45,0)+F35 -> 40000 | F35: =VLOOKUP($A35,[6]HISTOJANV23!$A$6:$AV$47,7,0) -> 0 | G35: =VLOOKUP($A35,[6]HISTOJANV23!$A$6:$AV$47,8,0) -> BANQUE | H35: =VLOOKUP($A35,[6]HISTOJANV23!$A$6:$AV$47,35,0) -> 0 | I35: =VLOOKUP($A35,[6]HISTOJANV23!$A$6:$AV$47,38,0) -> 0 | J35: =IF(H35=0,0,VLOOKUP($A35,[6]HISTOJANV23!$A$6:$AV$47,42,0)) -> 0 | K35: =VLOOKUP($A35,[6]HISTOJANV23!$A$6:$AV$47,41,0) -> 0 | M35: =VLOOKUP($A35,[6]HISTOJANV23!$A$6:$AV$47,16,0) -> 0 | N35: =IF(M35<>0,VLOOKUP($A35,[6]HISTOJANV23!$A$6:$AV$47,8,0),"ECHEC") -> ECHEC | O35: =IF(R35=0,0,VLOOKUP($A35,[6]HISTOJANV23!$A$6:$AV$47,32,0)) -> 0 | P35: =VLOOKUP($A35,[6]HISTOJANV23!$A$6:$AV$47,33,0) -> 0 | Q35: =IF(R35=0,0,($C$3-R35)) -> 0 | R35: =VLOOKUP($A35,[6]HISTOJANV23!$A$6:$AV$47,29,0) -> 0
A37: TOTAL PART | B37: =SUM(B6:B36) -> 30
A38: NBRE ADHERENT | B38: =COUNT(D6:D36) -> 30 | D38: =SUM(D6:D37) -> 750000 | F38: =SUM(F6:F37) -> 0 | G38: =SUM(G6:G37) -> 0 | H38: =SUM(H6:H37) -> 235000 | I38: =SUM(I6:I37) -> 9000 | J38: =SUM(J6:J37) -> 0 | K38: =SUM(K6:K37) -> 0 | L38: =SUM(L6:L37) -> 0 | M38: =SUM(M6:M37) -> 0 | ... R38: =SUM(R6:R37) -> 85000
N39: NBRE PART | O39: PART VENDUE
D40: MONTANT TONTINE | G40: REMBOURSEMENT PETIT LOT | H40: VENTE PETIT LOT | I40: VENTE LOT PRINCIPAL | J40: SOLDE EN CAISSE | L40: TONTINE + REMB + INTERET VENTE | M40: =D44+G44+R38 -> 835000
D41: =SUMIFS(D6:D37,G6:G37,"ESPECES") -> 125000 | F41: ESPECES | G41: =SUMIFS(M6:M32,N6:N32,"ESPECES") -> 0 | H41: =SUMIFS(H6:H37,J6:J37,"ESPECES") -> 0 | I41: =SUMIFS(Q6:Q37,O6:O37,"ESPECES") -> 0 | J41: =D41+G41-H41-I41 -> 125000 | L41: LOT PRINCIPAL | M41: =C3*COUNTIF(Q7:Q37,">0") -> 600000 | N41: =D3 -> 2 | O41: =COUNTIF(Q7:Q32,">0") -> 2
D42: =SUMIFS(D6:D37,G6:G37,"BANQUE") -> 625000 | F42: BANQUE | G42: =SUMIFS(M6:M32,N6:N32,"BANQUE") -> 0 | H42: =SUMIFS(H6:H37,J6:J37,"BANQUE") -> 235000 | I42: =SUMIFS(Q6:Q37,O6:O37,"BANQUE") -> 515000 | J42: =D42+G42-H42-I42 -> -125000
L43: PETIT LOT | M43: =M40-M41 -> 235000
D44: =D41+D42 -> 750000 | F44: TOTAL | G44: =G41+G42 -> 0 | H44: =H41+H42 -> 235000 | I44: =I41+I42 -> 515000 | J44: =J41+J42 -> 0
F45: TOTAL+DEPOT | L45: RELIQUAT | M45: =M43-H38 -> 0 | O45: =M45 -> 0 | P45: CUMUL
L47: ECHEC TONTINE MOIS | M47: =COUNTIFS(G7:G36,"ECHEC")*23000 -> 0 | P47: CUMUL
L48: ECHEC REMBOURSEMENT MOIS | M48: =L38-G44 -> 0 | P48: CUMUL

Sheet TONTFEV23
A1: ASSOCIATION | B1: ASELBY
A2: ANNEE | B2: 2023 | C2: TONIINE | D2: NBRE PART
A3: TAUX TONTINE | B3: 25000 | C3: =B3*12 -> 300000 | D3: =ROUNDDOWN(M40/C3,0) -> 3
C4: 44970
A5: MATRICULE | B5: NBREPART | C5: NOM ET PRENOM | D5: MONTANT TONTINE | E5: MONTANT VERSE | F5: PENALITE VERSEMENT ESPECES | G5: MODE VERSEMENT | H5: VENTE PETIT LOT | I5: INTERET PETIT LOT | J5: MODE VERSEMENT VENTE PETIT LOT | K5: NUMERO CHEQUE | L5: MONTANT A REMBOURSER PETIT LOT | M5: REMBOURSEMENT PETIT LOT | N5: MODE VERSEMENT REMBOURSEMENT | O5: MODE VERSEMENTLOT PRINCIPAL | P5: NUMERO CHEQUE | Q5: MONTANT LOT PRINCIPAL | R5: INTERET LOT PRINCIPAL
A6: AS201601 | B6: =IF(D6=0,0,VLOOKUP($A6,[6]HISTOFEV23!$A$6:$BO$40,10,0)) -> 1 | C6: =VLOOKUP(A6,[7]LISTADHERENT!A$5:H$60,3,0) -> BAKOP ACHILLE | D6: =IF(G6="ECHEC",0,B$3) -> 25000 | E6: =D6+VLOOKUP($A6,[6]HISTOFEV23!$A$7:$AU$40,45,0)+F6 -> 40000 | F6: =VLOOKUP($A6,[6]HISTOFEV23!$A$7:$AU$45,7,0) -> 0 | G6: =VLOOKUP($A6,[6]HISTOFEV23!$A$7:$AU$45,8,0) -> ESPECES | H6: =VLOOKUP($A6,[6]HISTOFEV23!$A$6:$AU$45,35,0) -> 0 | I6: =VLOOKUP($A6,[6]HISTOFEV23!$A$7:$AU$45,38,0) -> 0 | J6: =IF(I6=0,0,VLOOKUP($A6,[6]HISTOFEV23!$A$7:$AU$45,42,0)) -> 0 | K6: =VLOOKUP($A6,[6]HISTOFEV23!$A$7:$AU$45,41,0) -> 0 | L6: =TONTJANV23!H6+TONTJANV23!I6 -> 0 | M6: =VLOOKUP($A6,[6]HISTOFEV23!$A$7:$AU$45,16,0) -> 0 | N6: =IF(M6<>0,VLOOKUP($A6,[6]HISTOFEV23!$A$7:$AU$45,8,0),"ECHEC") -> ECHEC | O6: =IF(R6=0,0,VLOOKUP($A6,[6]HISTOFEV23!$A$7:$AU$45,32,0)) -> 0 | P6: =VLOOKUP($A6,[6]HISTOFEV23!$A$7:$AU$45,33,0) -> 0 | Q6: =IF(R6=0,0,($C$3-R6)) -> 0 | R6: =VLOOKUP($A6,[6]HISTOFEV23!$A$7:$AU$45,29,0) -> 0
A7: AS201602 | B7: =IF(D7=0,0,VLOOKUP($A7,[6]HISTOFEV23!$A$6:$BO$40,10,0)) -> 1 | C7: =VLOOKUP(A7,[7]LISTADHERENT!A$5:H$60,3,0) -> BOUTCHOUANG WILLIAM | D7: =IF(G7="ECHEC",0,B$3) -> 25000 | E7: =D7+VLOOKUP($A7,[6]HISTOFEV23!$A$7:$AU$40,45,0)+F7 -> 40000 | F7: =VLOOKUP($A7,[6]HISTOFEV23!$A$7:$AU$45,7,0) -> 0 | G7: =VLOOKUP($A7,[6]HISTOFEV23!$A$7:$AU$45,8,0) -> BANQUE | H7: =VLOOKUP($A7,[6]HISTOFEV23!$A$6:$AU$45,35,0) -> 0 | I7: =VLOOKUP($A7,[6]HISTOFEV23!$A$7:$AU$45,38,0) -> 0 | J7: =IF(I7=0,0,VLOOKUP($A7,[6]HISTOFEV23!$A$7:$AU$45,42,0)) -> 0 | K7: =VLOOKUP($A7,[6]HISTOFEV23!$A$7:$AU$45,41,0) -> 0 | L7: =TONTJANV23!H7+TONTJANV23!I7 -> 0 | M7: =VLOOKUP($A7,[6]HISTOFEV23!$A$7:$AU$45,16,0) -> 0 | N7: =IF(M7<>0,VLOOKUP($A7,[6]HISTOFEV23!$A$7:$AU$45,8,0),"ECHEC") -> ECHEC | O7: =IF(R7=0,0,VLOOKUP($A7,[6]HISTOFEV23!$A$7:$AU$45,32,0)) -> 0 | P7: =VLOOKUP($A7,[6]HISTOFEV23!$A$7:$AU$45,33,0) -> 0 | Q7: =IF(R7=0,0,($C$3-R7)) -> 0 | R7: =VLOOKUP($A7,[6]HISTOFEV23!$A$7:$AU$45,29,0) -> 0
A8: AS201604 | B8: =IF(D8=0,0,VLOOKUP($A8,[6]HISTOFEV23!$A$6:$BO$40,10,0)) -> 1 | C8: =VLOOKUP(A8,[7]LISTADHERENT!A$5:H$60,3,0) -> DJOMO JEAN PAUL | D8: =IF(G8="ECHEC",0,B$3) -> 25000 | E8: =D8+VLOOKUP($A8,[6]HISTOFEV23!$A$7:$AU$40,45,0)+F8 -> 48000 | F8: =VLOOKUP($A8,[6]HISTOFEV23!$A$7:$AU$45,7,0) -> 0 | G8: =VLOOKUP($A8,[6]HISTOFEV23!$A$7:$AU$45,8,0) -> BANQUE | H8: =VLOOKUP($A8,[6]HISTOFEV23!$A$6:$AU$45,35,0) -> 0 | I8: =VLOOKUP($A8,[6]HISTOFEV23!$A$7:$AU$45,38,0) -> 0 | J8: =IF(I8=0,0,VLOOKUP($A8,[6]HISTOFEV23!$A$7:$AU$45,42,0)) -> 0 | K8: =VLOOKUP($A8,[6]HISTOFEV23!$A$7:$AU$45,41,0) -> 0 | L8: =TONTJANV23!H8+TONTJANV23!I8 -> 0 | M8: =VLOOKUP($A8,[6]HISTOFEV23!$A$7:$AU$45,16,0) -> 0 | N8: =IF(M8<>0,VLOOKUP($A8,[6]HISTOFEV23!$A$7:$AU$45,8,0),"ECHEC") -> ECHEC | O8: =IF(R8=0,0,VLOOKUP($A8,[6]HISTOFEV23!$A$7:$AU$45,32,0)) -> 0 | P8: =VLOOKUP($A8,[6]HISTOFEV23!$A$7:$AU$45,33,0) -> 0 | Q8: =IF(R8=0,0,($C$3-R8)) -> 0 | R8: =VLOOKUP($A8,[6]HISTOFEV23!$A$7:$AU$45,29,0) -> 0
A9: AS201654 | B9: =IF(D9=0,0,VLOOKUP($A9,[6]HISTOFEV23!$A$6:$BO$40,10,0)) -> 1 | C9: =VLOOKUP(A9,[7]LISTADHERENT!A$5:H$60,3,0) -> DJOMOU TCHAPDA | D9: =IF(G9="ECHEC",0,B$3) -> 25000 | E9: =D9+VLOOKUP($A9,[6]HISTOFEV23!$A$7:$AU$40,45,0)+F9 -> 40000 | F9: =VLOOKUP($A9,[6]HISTOFEV23!$A$7:$AU$45,7,0) -> 0 | G9: =VLOOKUP($A9,[6]HISTOFEV23!$A$7:$AU$45,8,0) -> BANQUE | H9: =VLOOKUP($A9,[6]HISTOFEV23!$A$6:$AU$45,35,0) -> 40000 | I9: =VLOOKUP($A9,[6]HISTOFEV23!$A$7:$AU$45,38,0) -> 1000 | J9: =IF(I9=0,0,VLOOKUP($A9,[6]HISTOFEV23!$A$7:$AU$45,42,0)) -> BANQUE | K9: =VLOOKUP($A9,[6]HISTOFEV23!$A$7:$AU$45,41,0) -> 0 | L9: =TONTJANV23!H9+TONTJANV23!I9 -> 63000 | M9: =VLOOKUP($A9,[6]HISTOFEV23!$A$7:$AU$45,16,0) -> 63000 | N9: =IF(M9<>0,VLOOKUP($A9,[6]HISTOFEV23!$A$7:$AU$45,8,0),"ECHEC") -> BANQUE | O9: =IF(R9=0,0,VLOOKUP($A9,[6]HISTOFEV23!$A$7:$AU$45,32,0)) -> 0 | P9: =VLOOKUP($A9,[6]HISTOFEV23!$A$7:$AU$45,33,0) -> 0 | Q9: =IF(R9=0,0,($C$3-R9)) -> 0 | R9: =VLOOKUP($A9,[6]HISTOFEV23!$A$7:$AU$45,29,0) -> 0
A10: AS201605 | B10: =IF(D10=0,0,VLOOKUP($A10,[6]HISTOFEV23!$A$6:$BO$40,10,0)) -> 1 | C10: =VLOOKUP(A10,[7]LISTADHERENT!A$5:H$60,3,0) -> DJOUKWE NANGUEN GUY BLAISE | D10: =IF(G10="ECHEC",0,B$3) -> 25000 | E10: =D10+VLOOKUP($A10,[6]HISTOFEV23!$A$7:$AU$40,45,0)+F10 -> 40000 | F10: =VLOOKUP($A10,[6]HISTOFEV23!$A$7:$AU$45,7,0) -> 0 | G10: =VLOOKUP($A10,[6]HISTOFEV23!$A$7:$AU$45,8,0) -> BANQUE | H10: =VLOOKUP($A10,[6]HISTOFEV23!$A$6:$AU$45,35,0) -> 0 | I10: =VLOOKUP($A10,[6]HISTOFEV23!$A$7:$AU$45,38,0) -> 0 | J10: =IF(I10=0,0,VLOOKUP($A10,[6]HISTOFEV23!$A$7:$AU$45,42,0)) -> 0 | K10: =VLOOKUP($A10,[6]HISTOFEV23!$A$7:$AU$45,41,0) -> 0 | L10: =TONTJANV23!H10+TONTJANV23!I10 -> 62000 | M10: =VLOOKUP($A10,[6]HISTOFEV23!$A$7:$AU$45,16,0) -> 62000 | N10: =IF(M10<>0,VLOOKUP($A10,[6]HISTOFEV23!$A$7:$AU$45,8,0),"ECHEC") -> BANQUE | O10: =IF(R10=0,0,VLOOKUP($A10,[6]HISTOFEV23!$A$7:$AU$45,32,0)) -> 0 | P10: =VLOOKUP($A10,[6]HISTOFEV23!$A$7:$AU$45,33,0) -> 0 | Q10: =IF(R10=0,0,($C$3-R10)) -> 0 | R10: =VLOOKUP($A10,[6]HISTOFEV23!$A$7:$AU$45,29,0) -> 0
A11: AS201608 | B11: =IF(D11=0,0,VLOOKUP($A11,[6]HISTOFEV23!$A$6:$BO$40,10,0)) -> 1 | C11: =VLOOKUP(A11,[7]LISTADHERENT!A$5:H$60,3,0) -> DJUOMBESSY ANTOINE | D11: =IF(G11="ECHEC",0,B$3) -> 25000 | E11: =D11+VLOOKUP($A11,[6]HISTOFEV23!$A$7:$AU$40,45,0)+F11 -> 45000 | F11: =VLOOKUP($A11,[6]HISTOFEV23!$A$7:$AU$45,7,0) -> 0 | G11: =VLOOKUP($A11,[6]HISTOFEV23!$A$7:$AU$45,8,0) -> BANQUE | H11: =VLOOKUP($A11,[6]HISTOFEV23!$A$6:$AU$45,35,0) -> 0 | I11: =VLOOKUP($A11,[6]HISTOFEV23!$A$7:$AU$45,38,0) -> 0 | J11: =IF(I11=0,0,VLOOKUP($A11,[6]HISTOFEV23!$A$7:$AU$45,42,0)) -> 0 | K11: =VLOOKUP($A11,[6]HISTOFEV23!$A$7:$AU$45,41,0) -> 0 | L11: =TONTJANV23!H11+TONTJANV23!I11 -> 0 | M11: =VLOOKUP($A11,[6]HISTOFEV23!$A$7:$AU$45,16,0) -> 0 | N11: =IF(M11<>0,VLOOKUP($A11,[6]HISTOFEV23!$A$7:$AU$45,8,0),"ECHEC") -> ECHEC | O11: =IF(R11=0,0,VLOOKUP($A11,[6]HISTOFEV23!$A$7:$AU$45,32,0)) -> 0 | P11: =VLOOKUP($A11,[6]HISTOFEV23!$A$7:$AU$45,33,0) -> 0 | Q11: =IF(R11=0,0,($C$3-R11)) -> 0 | R11: =VLOOKUP($A11,[6]HISTOFEV23!$A$7:$AU$45,29,0) -> 0
A12: AS201651 | B12: =IF(D12=0,0,VLOOKUP($A12,[6]HISTOFEV23!$A$6:$BO$40,10,0)) -> 1 | C12: =VLOOKUP(A12,[7]LISTADHERENT!A$5:H$60,3,0) -> DOMOU FABIEN | D12: =IF(G12="ECHEC",0,B$3) -> 25000 | E12: =D12+VLOOKUP($A12,[6]HISTOFEV23!$A$7:$AU$40,45,0)+F12 -> 40000 | F12: =VLOOKUP($A12,[6]HISTOFEV23!$A$7:$AU$45,7,0) -> 0 | G12: =VLOOKUP($A12,[6]HISTOFEV23!$A$7:$AU$45,8,0) -> ESPECES | H12: =VLOOKUP($A12,[6]HISTOFEV23!$A$6:$AU$45,35,0) -> 0 | I12: =VLOOKUP($A12,[6]HISTOFEV23!$A$7:$AU$45,38,0) -> 0 | J12: =IF(I12=0,0,VLOOKUP($A12,[6]HISTOFEV23!$A$7:$AU$45,42,0)) -> 0 | K12: =VLOOKUP($A12,[6]HISTOFEV23!$A$7:$AU$45,41,0) -> 0 | L12: =TONTJANV23!H12+TONTJANV23!I12 -> 0 | M12: =VLOOKUP($A12,[6]HISTOFEV23!$A$7:$AU$45,16,0) -> 0 | N12: =IF(M12<>0,VLOOKUP($A12,[6]HISTOFEV23!$A$7:$AU$45,8,0),"ECHEC") -> ECHEC | O12: =IF(R12=0,0,VLOOKUP($A12,[6]HISTOFEV23!$A$7:$AU$45,32,0)) -> 0 | P12: =VLOOKUP($A12,[6]HISTOFEV23!$A$7:$AU$45,33,0) -> 0 | Q12: =IF(R12=0,0,($C$3-R12)) -> 0 | R12: =VLOOKUP($A12,[6]HISTOFEV23!$A$7:$AU$45,29,0) -> 0
A13: AS201609 | B13: =IF(D13=0,0,VLOOKUP($A13,[6]HISTOFEV23!$A$6:$BO$40,10,0)) -> 1 | C13: =VLOOKUP(A13,[7]LISTADHERENT!A$5:H$60,3,0) -> DONHOU DAVID | D13: =IF(G13="ECHEC",0,B$3) -> 25000 | E13: =D13+VLOOKUP($A13,[6]HISTOFEV23!$A$7:$AU$40,45,0)+F13 -> 40000 | F13: =VLOOKUP($A13,[6]HISTOFEV23!$A$7:$AU$45,7,0) -> 0 | G13: =VLOOKUP($A13,[6]HISTOFEV23!$A$7:$AU$45,8,0) -> BANQUE | H13: =VLOOKUP($A13,[6]HISTOFEV23!$A$6:$AU$45,35,0) -> 0 | I13: =VLOOKUP($A13,[6]HISTOFEV23!$A$7:$AU$45,38,0) -> 0 | J13: =IF(I13=0,0,VLOOKUP($A13,[6]HISTOFEV23!$A$7:$AU$45,42,0)) -> 0 | K13: =VLOOKUP($A13,[6]HISTOFEV23!$A$7:$AU$45,41,0) -> 0 | L13: =TONTJANV23!H13+TONTJANV23!I13 -> 0 | M13: =VLOOKUP($A13,[6]HISTOFEV23!$A$7:$AU$45,16,0) -> 0 | N13: =IF(M13<>0,VLOOKUP($A13,[6]HISTOFEV23!$A$7:$AU$45,8,0),"ECHEC") -> ECHEC | O13: =IF(R13=0,0,VLOOKUP($A13,[6]HISTOFEV23!$A$7:$AU$45,32,0)) -> 0 | P13: =VLOOKUP($A13,[6]HISTOFEV23!$A$7:$AU$45,33,0) -> 0 | Q13: =IF(R13=0,0,($C$3-R13)) -> 0 | R13: =VLOOKUP($A13,[6]HISTOFEV23!$A$7:$AU$45,29,0) -> 0
A14: AS201611 | B14: =IF(D14=0,0,VLOOKUP($A14,[6]HISTOFEV23!$A$6:$BO$40,10,0)) -> 1 | C14: =VLOOKUP(A14,[7]LISTADHERENT!A$5:H$60,3,0) -> HENGUE PAUL OMER | D14: =IF(G14="ECHEC",0,B$3) -> 25000 | E14: =D14+VLOOKUP($A14,[6]HISTOFEV23!$A$7:$AU$40,45,0)+F14 -> 40000 | F14: =VLOOKUP($A14,[6]HISTOFEV23!$A$7:$AU$45,7,0) -> 0 | G14: =VLOOKUP($A14,[6]HISTOFEV23!$A$7:$AU$45,8,0) -> BANQUE | H14: =VLOOKUP($A14,[6]HISTOFEV23!$A$6:$AU$45,35,0) -> 0 | I14: =VLOOKUP($A14,[6]HISTOFEV23!$A$7:$AU$45,38,0) -> 0 | J14: =IF(I14=0,0,VLOOKUP($A14,[6]HISTOFEV23!$A$7:$AU$45,42,0)) -> 0 | K14: =VLOOKUP($A14,[6]HISTOFEV23!$A$7:$AU$45,41,0) -> 0 | L14: =TONTJANV23!H14+TONTJANV23!I14 -> 0 | M14: =VLOOKUP($A14,[6]HISTOFEV23!$A$7:$AU$45,16,0) -> 0 | N14: =IF(M14<>0,VLOOKUP($A14,[6]HISTOFEV23!$A$7:$AU$45,8,0),"ECHEC") -> ECHEC | O14: =IF(R14=0,0,VLOOKUP($A14,[6]HISTOFEV23!$A$7:$AU$45,32,0)) -> 0 | P14: =VLOOKUP($A14,[6]HISTOFEV23!$A$7:$AU$45,33,0) -> 0 | Q14: =IF(R14=0,0,($C$3-R14)) -> 0 | R14: =VLOOKUP($A14,[6]HISTOFEV23!$A$7:$AU$45,29,0) -> 0
A15: AS201613 | B15: =IF(D15=0,0,VLOOKUP($A15,[6]HISTOFEV23!$A$6:$BO$40,10,0)) -> 1 | C15: =VLOOKUP(A15,[7]LISTADHERENT!A$5:H$60,3,0) -> HOTCHO BENJAMIN | D15: =IF(G15="ECHEC",0,B$3) -> 25000 | E15: =D15+VLOOKUP($A15,[6]HISTOFEV23!$A$7:$AU$40,45,0)+F15 -> 75000 | F15: =VLOOKUP($A15,[6]HISTOFEV23!$A$7:$AU$45,7,0) -> 0 | G15: =VLOOKUP($A15,[6]HISTOFEV23!$A$7:$AU$45,8,0) -> BANQUE | H15: =VLOOKUP($A15,[6]HISTOFEV23!$A$6:$AU$45,35,0) -> 0 | I15: =VLOOKUP($A15,[6]HISTOFEV23!$A$7:$AU$45,38,0) -> 0 | J15: =IF(I15=0,0,VLOOKUP($A15,[6]HISTOFEV23!$A$7:$AU$45,42,0)) -> 0 | K15: =VLOOKUP($A15,[6]HISTOFEV23!$A$7:$AU$45,41,0) -> 0 | L15: =TONTJANV23!H15+TONTJANV23!I15 -> 0 | M15: =VLOOKUP($A15,[6]HISTOFEV23!$A$7:$AU$45,16,0) -> 0 | N15: =IF(M15<>0,VLOOKUP($A15,[6]HISTOFEV23!$A$7:$AU$45,8,0),"ECHEC") -> ECHEC | O15: =IF(R15=0,0,VLOOKUP($A15,[6]HISTOFEV23!$A$7:$AU$45,32,0)) -> 0 | P15: =VLOOKUP($A15,[6]HISTOFEV23!$A$7:$AU$45,33,0) -> 0 | Q15: =IF(R15=0,0,($C$3-R15)) -> 0 | R15: =VLOOKUP($A15,[6]HISTOFEV23!$A$7:$AU$45,29,0) -> 0
A16: AS201617 | B16: =IF(D16=0,0,VLOOKUP($A16,[6]HISTOFEV23!$A$6:$BO$40,10,0)) -> 1 | C16: =VLOOKUP(A16,[7]LISTADHERENT!A$5:H$60,3,0) -> KOUAMOU MOISE | D16: =IF(G16="ECHEC",0,B$3) -> 25000 | E16: =D16+VLOOKUP($A16,[6]HISTOFEV23!$A$7:$AU$40,45,0)+F16 -> 40000 | F16: =VLOOKUP($A16,[6]HISTOFEV23!$A$7:$AU$45,7,0) -> 0 | G16: =VLOOKUP($A16,[6]HISTOFEV23!$A$7:$AU$45,8,0) -> BANQUE | H16: =VLOOKUP($A16,[6]HISTOFEV23!$A$6:$AU$45,35,0) -> 0 | I16: =VLOOKUP($A16,[6]HISTOFEV23!$A$7:$AU$45,38,0) -> 0 | J16: =IF(I16=0,0,VLOOKUP($A16,[6]HISTOFEV23!$A$7:$AU$45,42,0)) -> 0 | K16: =VLOOKUP($A16,[6]HISTOFEV23!$A$7:$AU$45,41,0) -> 0 | L16: =TONTJANV23!H16+TONTJANV23!I16 -> 0 | M16: =VLOOKUP($A16,[6]HISTOFEV23!$A$7:$AU$45,16,0) -> 0 | N16: =IF(M16<>0,VLOOKUP($A16,[6]HISTOFEV23!$A$7:$AU$45,8,0),"ECHEC") -> ECHEC | O16: =IF(R16=0,0,VLOOKUP($A16,[6]HISTOFEV23!$A$7:$AU$45,32,0)) -> BANQUE | P16: =VLOOKUP($A16,[6]HISTOFEV23!$A$7:$AU$45,33,0) -> 0 | Q16: =IF(R16=0,0,($C$3-R16)) -> 293500 | R16: =VLOOKUP($A16,[6]HISTOFEV23!$A$7:$AU$45,29,0) -> 6500
A17: AS201619 | B17: =IF(D17=0,0,VLOOKUP($A17,[6]HISTOFEV23!$A$6:$BO$40,10,0)) -> 1 | C17: =VLOOKUP(A17,[7]LISTADHERENT!A$5:H$60,3,0) -> KOUATCHO MESSACK | D17: =IF(G17="ECHEC",0,B$3) -> 25000 | E17: =D17+VLOOKUP($A17,[6]HISTOFEV23!$A$7:$AU$40,45,0)+F17 -> 40000 | F17: =VLOOKUP($A17,[6]HISTOFEV23!$A$7:$AU$45,7,0) -> 0 | G17: =VLOOKUP($A17,[6]HISTOFEV23!$A$7:$AU$45,8,0) -> BANQUE | H17: =VLOOKUP($A17,[6]HISTOFEV23!$A$6:$AU$45,35,0) -> 0 | I17: =VLOOKUP($A17,[6]HISTOFEV23!$A$7:$AU$45,38,0) -> 0 | J17: =IF(I17=0,0,VLOOKUP($A17,[6]HISTOFEV23!$A$7:$AU$45,42,0)) -> 0 | K17: =VLOOKUP($A17,[6]HISTOFEV23!$A$7:$AU$45,41,0) -> 0 | L17: =TONTJANV23!H17+TONTJANV23!I17 -> 0 | M17: =VLOOKUP($A17,[6]HISTOFEV23!$A$7:$AU$45,16,0) -> 0 | N17: =IF(M17<>0,VLOOKUP($A17,[6]HISTOFEV23!$A$7:$AU$45,8,0),"ECHEC") -> ECHEC | O17: =IF(R17=0,0,VLOOKUP($A17,[6]HISTOFEV23!$A$7:$AU$45,32,0)) -> 0 | P17: =VLOOKUP($A17,[6]HISTOFEV23!$A$7:$AU$45,33,0) -> 0 | Q17: =IF(R17=0,0,($C$3-R17)) -> 0 | R17: =VLOOKUP($A17,[6]HISTOFEV23!$A$7:$AU$45,29,0) -> 0
... A35: AS201647 | B35: =IF(D35=0,0,VLOOKUP($A35,[6]HISTOFEV23!$A$6:$BO$40,10,0)) -> 1 | C35: =VLOOKUP(A35,[7]LISTADHERENT!A$5:H$60,3,0) -> YOUMBI EMMANUEL | D35: =IF(G35="ECHEC",0,B$3) -> 25000 | E35: =D35+VLOOKUP($A35,[6]HISTOFEV23!$A$7:$AU$40,45,0)+F35 -> 40000 | F35: =VLOOKUP($A35,[6]HISTOFEV23!$A$7:$AU$45,7,0) -> 0 | G35: =VLOOKUP($A35,[6]HISTOFEV23!$A$7:$AU$45,8,0) -> BANQUE | H35: =VLOOKUP($A35,[6]HISTOFEV23!$A$6:$AU$45,35,0) -> 0 | I35: =VLOOKUP($A35,[6]HISTOFEV23!$A$7:$AU$45,38,0) -> 0 | J35: =IF(I35=0,0,VLOOKUP($A35,[6]HISTOFEV23!$A$7:$AU$45,42,0)) -> 0 | K35: =VLOOKUP($A35,[6]HISTOFEV23!$A$7:$AU$45,41,0) -> 0 | L35: =TONTJANV23!H35+TONTJANV23!I35 -> 0 | M35: =VLOOKUP($A35,[6]HISTOFEV23!$A$7:$AU$45,16,0) -> 0 | N35: =IF(M35<>0,VLOOKUP($A35,[6]HISTOFEV23!$A$7:$AU$45,8,0),"ECHEC") -> ECHEC | O35: =IF(R35=0,0,VLOOKUP($A35,[6]HISTOFEV23!$A$7:$AU$45,32,0)) -> 0 | P35: =VLOOKUP($A35,[6]HISTOFEV23!$A$7:$AU$45,33,0) -> 0 | Q35: =IF(R35=0,0,($C$3-R35)) -> 0 | R35: =VLOOKUP($A35,[6]HISTOFEV23!$A$7:$AU$45,29,0) -> 0
A37: TOTAL PART | B37: =SUM(B6:B36) -> 30
A38: NBRE ADHERENT | B38: =COUNT(D6:D35) -> 30 | D38: =SUM(D6:D37) -> 750000 | E38: =SUM(E6:E37) -> 1258000 | F38: =SUM(F6:F37) -> 0 | H38: =SUM(H6:H37) -> 111500 | I38: =SUM(I6:I37) -> 3000 | L38: =SUM(L6:L37) -> 244000 | M38: =SUM(M6:M37) -> 244000 | N38: =SUM(N6:N37) -> 0 | O38: =SUM(O6:O37) -> 0 | P38: =SUM(P6:P37) -> 0 | Q38: =SUM(Q6:Q37) -> 882500 | R38: =SUM(R6:R37) -> 17500
N39: NBRE PART | O39: PART VENDUE
D40: MONTANT TONTINE | E40: MONTANT VERSE | G40: REMBOURSEMENT PETIT LOT | H40: VENTE PETIT LOT | I40: VENTE LOT PRINCIPAL | J40: SOLDE EN CAISSE | L40: TONTINE + REMB + INTERET VENTE | M40: =D44+G44+R38+TONTJANV23!O45 -> 1011500
D41: =SUMIFS(D6:D37,G6:G37,"ESPECES") -> 150000 | E41: =SUMIFS(E6:E37,G6:G37,"ESPECES") -> 240000 | F41: ESPECES | G41: =SUMIFS(M6:M35,N6:N35,"ESPECES") -> 62000 | H41: =SUMIFS(H6:H37,J6:J37,"ESPECES") -> 0 | I41: =SUMIFS(Q6:Q37,O6:O37,"ESPECES") -> 0 | J41: =D41+G41-H41-I41 -> 212000 | L41: LOT PRINCIPAL | M41: =C3*COUNTIF(Q6:Q37,">0") -> 900000 | N41: =D3 -> 3 | O41: =COUNTIF(Q6:Q35,">0") -> 3
D42: =SUMIFS(D6:D37,G6:G37,"BANQUE") -> 600000 | E42: =SUMIFS(E6:E38,G6:G38,"BANQUE") -> 1018000 | F42: BANQUE | G42: =SUMIFS(M6:M35,N6:N35,"BANQUE") -> 182000 | H42: =SUMIFS(H6:H37,J6:J37,"BANQUE") -> 111500 | I42: =SUMIFS(Q6:Q37,O6:O37,"BANQUE") -> 882500 | J42: =D42+G42-H42-I42 -> -212000
L43: PETIT LOT | M43: =M40-M41 -> 111500
D44: =D41+D42 -> 750000 | E44: =E41+E42 -> 1258000 | F44: TOTAL | G44: =G41+G42 -> 244000 | H44: =H41+H42 -> 111500 | I44: =I41+I42 -> 882500 | J44: =J41+J42 -> 0
F45: TOTAL+DEPOT | L45: RELIQUAT | M45: =M43-H38 -> 0 | O45: =TONTFEV23!M45 -> 0 | P45: CUMUL
L47: ECHEC TONTINE MOIS | M47: =COUNTIFS(G6:G36,"ECHEC")*25000 -> 0 | O47: =TONTFEV23!M47 -> 0 | P47: CUMUL
L48: ECHEC REMBOURSEMENT MOIS | M48: =L38-G44 -> 0 | O48: =TONTFEV23!M48 -> 0 | P48: CUMUL

Sheet TONTMARS23
A1: ASSOCIATION | B1: ASELBY
A2: ANNEE | B2: 2023 | C2: TONIINE | D2: NBRE PART
A3: TAUX TONTINE | B3: 25000 | C3: =B3*12 -> 300000 | D3: =ROUNDDOWN(M40/C3,0) -> 2
C4: 44998
A5: MATRICULE | B5: NBREPART | C5: NOM ET PRENOM | D5: MONTANT TONTINE | E5: MONTANT VERSE | F5: PENALITE VERSEMENT ESPECES | G5: MODE VERSEMENT | H5: VENTE PETIT LOT | I5: INTERET PETIT LOT | J5: MODE VERSEMENT VENTE PETIT LOT | K5: NUMERO CHEQUE | L5: MONTANT A REMBOURSER PETIT LOT | M5: REMBOURSEMENT PETIT LOT | N5: MODE VERSEMENT REMBOURSEMENT | O5: MODE VERSEMENTLOT PRINCIPAL | P5: NUMERO CHEQUE | Q5: MONTANT LOT PRINCIPAL | R5: INTERET LOT PRINCIPAL
A6: AS201601 | B6: =IF(D6=0,0,VLOOKUP($A6,[6]HISTOMARS23!$A$6:$BO$40,10,0)) -> 1 | C6: =VLOOKUP(A6,[7]LISTADHERENT!A$5:H$60,3,0) -> BAKOP ACHILLE | D6: =IF(G6="ECHEC",0,B$3) -> 25000 | E6: =D6+VLOOKUP($A6,[6]HISTOMARS23!$A$7:$AU$40,45,0)+F6 -> 40000 | F6: =VLOOKUP($A6,[6]HISTOMARS23!$A$7:$AU$45,7,0) -> 0 | G6: =VLOOKUP($A6,[6]HISTOMARS23!$A$7:$AU$45,8,0) -> BANQUE | H6: =VLOOKUP($A6,[6]HISTOMARS23!$A$6:$AU$45,35,0) -> 0 | I6: =VLOOKUP($A6,[6]HISTOMARS23!$A$7:$AU$45,38,0) -> 0 | J6: =IF(I6=0,0,VLOOKUP($A6,[6]HISTOMARS23!$A$7:$AU$45,42,0)) -> 0 | K6: =VLOOKUP($A6,[6]HISTOMARS23!$A$7:$AU$45,41,0) -> 0 | L6: =TONTFEV23!H6+TONTFEV23!I6 -> 0 | M6: =VLOOKUP($A6,[6]HISTOMARS23!$A$7:$AU$45,16,0) -> 0 | N6: =IF(M6<>0,VLOOKUP($A6,[6]HISTOMARS23!$A$7:$AU$45,8,0),"ECHEC") -> ECHEC | O6: =IF(R6=0,0,VLOOKUP($A6,[6]HISTOMARS23!$A$7:$AU$45,32,0)) -> 0 | P6: =VLOOKUP($A6,[6]HISTOMARS23!$A$7:$AU$45,33,0) -> 0 | Q6: =IF(R6=0,0,($C$3-R6)) -> 0 | R6: =VLOOKUP($A6,[6]HISTOMARS23!$A$7:$AU$45,29,0) -> 0
A7: AS201602 | B7: =IF(D7=0,0,VLOOKUP($A7,[6]HISTOMARS23!$A$6:$BO$40,10,0)) -> 1 | C7: =VLOOKUP(A7,[7]LISTADHERENT!A$5:H$60,3,0) -> BOUTCHOUANG WILLIAM | D7: =IF(G7="ECHEC",0,B$3) -> 25000 | E7: =D7+VLOOKUP($A7,[6]HISTOMARS23!$A$7:$AU$40,45,0)+F7 -> 40000 | F7: =VLOOKUP($A7,[6]HISTOMARS23!$A$7:$AU$45,7,0) -> 0 | G7: =VLOOKUP($A7,[6]HISTOMARS23!$A$7:$AU$45,8,0) -> BANQUE | H7: =VLOOKUP($A7,[6]HISTOMARS23!$A$6:$AU$45,35,0) -> 0 | I7: =VLOOKUP($A7,[6]HISTOMARS23!$A$7:$AU$45,38,0) -> 0 | J7: =IF(I7=0,0,VLOOKUP($A7,[6]HISTOMARS23!$A$7:$AU$45,42,0)) -> 0 | K7: =VLOOKUP($A7,[6]HISTOMARS23!$A$7:$AU$45,41,0) -> 0 | L7: =TONTFEV23!H7+TONTFEV23!I7 -> 0 | M7: =VLOOKUP($A7,[6]HISTOMARS23!$A$7:$AU$45,16,0) -> 0 | N7: =IF(M7<>0,VLOOKUP($A7,[6]HISTOMARS23!$A$7:$AU$45,8,0),"ECHEC") -> ECHEC | O7: =IF(R7=0,0,VLOOKUP($A7,[6]HISTOMARS23!$A$7:$AU$45,32,0)) -> 0 | P7: =VLOOKUP($A7,[6]HISTOMARS23!$A$7:$AU$45,33,0) -> 0 | Q7: =IF(R7=0,0,($C$3-R7)) -> 0 | R7: =VLOOKUP($A7,[6]HISTOMARS23!$A$7:$AU$45,29,0) -> 0
A8: AS201604 | B8: =IF(D8=0,0,VLOOKUP($A8,[6]HISTOMARS23!$A$6:$BO$40,10,0)) -> 1 | C8: =VLOOKUP(A8,[7]LISTADHERENT!A$5:H$60,3,0) -> DJOMO JEAN PAUL | D8: =IF(G8="ECHEC",0,B$3) -> 25000 | E8: =D8+VLOOKUP($A8,[6]HISTOMARS23!$A$7:$AU$40,45,0)+F8 -> 40000 | F8: =VLOOKUP($A8,[6]HISTOMARS23!$A$7:$AU$45,7,0) -> 0 | G8: =VLOOKUP($A8,[6]HISTOMARS23!$A$7:$AU$45,8,0) -> BANQUE | H8: =VLOOKUP($A8,[6]HISTOMARS23!$A$6:$AU$45,35,0) -> 0 | I8: =VLOOKUP($A8,[6]HISTOMARS23!$A$7:$AU$45,38,0) -> 0 | J8: =IF(I8=0,0,VLOOKUP($A8,[6]HISTOMARS23!$A$7:$AU$45,42,0)) -> 0 | K8: =VLOOKUP($A8,[6]HISTOMARS23!$A$7:$AU$45,41,0) -> 0 | L8: =TONTFEV23!H8+TONTFEV23!I8 -> 0 | M8: =VLOOKUP($A8,[6]HISTOMARS23!$A$7:$AU$45,16,0) -> 0 | N8: =IF(M8<>0,VLOOKUP($A8,[6]HISTOMARS23!$A$7:$AU$45,8,0),"ECHEC") -> ECHEC | O8: =IF(R8=0,0,VLOOKUP($A8,[6]HISTOMARS23!$A$7:$AU$45,32,0)) -> 0 | P8: =VLOOKUP($A8,[6]HISTOMARS23!$A$7:$AU$45,33,0) -> 0 | Q8: =IF(R8=0,0,($C$3-R8)) -> 0 | R8: =VLOOKUP($A8,[6]HISTOMARS23!$A$7:$AU$45,29,0) -> 0
A9: AS201654 | B9: =IF(D9=0,0,VLOOKUP($A9,[6]HISTOMARS23!$A$6:$BO$40,10,0)) -> 1 | C9: =VLOOKUP(A9,[7]LISTADHERENT!A$5:H$60,3,0) -> DJOMOU TCHAPDA | D9: =IF(G9="ECHEC",0,B$3) -> 25000 | E9: =D9+VLOOKUP($A9,[6]HISTOMARS23!$A$7:$AU$40,45,0)+F9 -> 41000 | F9: =VLOOKUP($A9,[6]HISTOMARS23!$A$7:$AU$45,7,0) -> 0 | G9: =VLOOKUP($A9,[6]HISTOMARS23!$A$7:$AU$45,8,0) -> BANQUE | H9: =VLOOKUP($A9,[6]HISTOMARS23!$A$6:$AU$45,35,0) -> 0 | I9: =VLOOKUP($A9,[6]HISTOMARS23!$A$7:$AU$45,38,0) -> 0 | J9: =IF(I9=0,0,VLOOKUP($A9,[6]HISTOMARS23!$A$7:$AU$45,42,0)) -> 0 | K9: =VLOOKUP($A9,[6]HISTOMARS23!$A$7:$AU$45,41,0) -> 0 | L9: =TONTFEV23!H9+TONTFEV23!I9 -> 41000 | M9: =VLOOKUP($A9,[6]HISTOMARS23!$A$7:$AU$45,16,0) -> 41000 | N9: =IF(M9<>0,VLOOKUP($A9,[6]HISTOMARS23!$A$7:$AU$45,8,0),"ECHEC") -> BANQUE | O9: =IF(R9=0,0,VLOOKUP($A9,[6]HISTOMARS23!$A$7:$AU$45,32,0)) -> 0 | P9: =VLOOKUP($A9,[6]HISTOMARS23!$A$7:$AU$45,33,0) -> 0 | Q9: =IF(R9=0,0,($C$3-R9)) -> 0 | R9: =VLOOKUP($A9,[6]HISTOMARS23!$A$7:$AU$45,29,0) -> 0
A10: AS201605 | B10: =IF(D10=0,0,VLOOKUP($A10,[6]HISTOMARS23!$A$6:$BO$40,10,0)) -> 1 | C10: =VLOOKUP(A10,[7]LISTADHERENT!A$5:H$60,3,0) -> DJOUKWE NANGUEN GUY BLAISE | D10: =IF(G10="ECHEC",0,B$3) -> 25000 | E10: =D10+VLOOKUP($A10,[6]HISTOMARS23!$A$7:$AU$40,45,0)+F10 -> 45000 | F10: =VLOOKUP($A10,[6]HISTOMARS23!$A$7:$AU$45,7,0) -> 0 | G10: =VLOOKUP($A10,[6]HISTOMARS23!$A$7:$AU$45,8,0) -> BANQUE | H10: =VLOOKUP($A10,[6]HISTOMARS23!$A$6:$AU$45,35,0) -> 0 | I10: =VLOOKUP($A10,[6]HISTOMARS23!$A$7:$AU$45,38,0) -> 0 | J10: =IF(I10=0,0,VLOOKUP($A10,[6]HISTOMARS23!$A$7:$AU$45,42,0)) -> 0 | K10: =VLOOKUP($A10,[6]HISTOMARS23!$A$7:$AU$45,41,0) -> 0 | L10: =TONTFEV23!H10+TONTFEV23!I10 -> 0 | M10: =VLOOKUP($A10,[6]HISTOMARS23!$A$7:$AU$45,16,0) -> 0 | N10: =IF(M10<>0,VLOOKUP($A10,[6]HISTOMARS23!$A$7:$AU$45,8,0),"ECHEC") -> ECHEC | O10: =IF(R10=0,0,VLOOKUP($A10,[6]HISTOMARS23!$A$7:$AU$45,32,0)) -> 0 | P10: =VLOOKUP($A10,[6]HISTOMARS23!$A$7:$AU$45,33,0) -> 0 | Q10: =IF(R10=0,0,($C$3-R10)) -> 0 | R10: =VLOOKUP($A10,[6]HISTOMARS23!$A$7:$AU$45,29,0) -> 0
A11: AS201608 | B11: =IF(D11=0,0,VLOOKUP($A11,[6]HISTOMARS23!$A$6:$BO$40,10,0)) -> 1 | C11: =VLOOKUP(A11,[7]LISTADHERENT!A$5:H$60,3,0) -> DJUOMBESSY ANTOINE | D11: =IF(G11="ECHEC",0,B$3) -> 25000 | E11: =D11+VLOOKUP($A11,[6]HISTOMARS23!$A$7:$AU$40,45,0)+F11 -> 45000 | F11: =VLOOKUP($A11,[6]HISTOMARS23!$A$7:$AU$45,7,0) -> 0 | G11: =VLOOKUP($A11,[6]HISTOMARS23!$A$7:$AU$45,8,0) -> BANQUE | H11: =VLOOKUP($A11,[6]HISTOMARS23!$A$6:$AU$45,35,0) -> 0 | I11: =VLOOKUP($A11,[6]HISTOMARS23!$A$7:$AU$45,38,0) -> 0 | J11: =IF(I11=0,0,VLOOKUP($A11,[6]HISTOMARS23!$A$7:$AU$45,42,0)) -> 0 | K11: =VLOOKUP($A11,[6]HISTOMARS23!$A$7:$AU$45,41,0) -> 0 | L11: =TONTFEV23!H11+TONTFEV23!I11 -> 0 | M11: =VLOOKUP($A11,[6]HISTOMARS23!$A$7:$AU$45,16,0) -> 0 | N11: =IF(M11<>0,VLOOKUP($A11,[6]HISTOMARS23!$A$7:$AU$45,8,0),"ECHEC") -> ECHEC | O11: =IF(R11=0,0,VLOOKUP($A11,[6]HISTOMARS23!$A$7:$AU$45,32,0)) -> 0 | P11: =VLOOKUP($A11,[6]HISTOMARS23!$A$7:$AU$45,33,0) -> 0 | Q11: =IF(R11=0,0,($C$3-R11)) -> 0 | R11: =VLOOKUP($A11,[6]HISTOMARS23!$A$7:$AU$45,29,0) -> 0
A12: AS201651 | B12: =IF(D12=0,0,VLOOKUP($A12,[6]HISTOMARS23!$A$6:$BO$40,10,0)) -> 1 | C12: =VLOOKUP(A12,[7]LISTADHERENT!A$5:H$60,3,0) -> DOMOU FABIEN | D12: =IF(G12="ECHEC",0,B$3) -> 25000 | E12: =D12+VLOOKUP($A12,[6]HISTOMARS23!$A$7:$AU$40,45,0)+F12 -> 40000 | F12: =VLOOKUP($A12,[6]HISTOMARS23!$A$7:$AU$45,7,0) -> 0 | G12: =VLOOKUP($A12,[6]HISTOMARS23!$A$7:$AU$45,8,0) -> BANQUE | H12: =VLOOKUP($A12,[6]HISTOMARS23!$A$6:$AU$45,35,0) -> 0 | I12: =VLOOKUP($A12,[6]HISTOMARS23!$A$7:$AU$45,38,0) -> 0 | J12: =IF(I12=0,0,VLOOKUP($A12,[6]HISTOMARS23!$A$7:$AU$45,42,0)) -> 0 | K12: =VLOOKUP($A12,[6]HISTOMARS23!$A$7:$AU$45,41,0) -> 0 | L12: =TONTFEV23!H12+TONTFEV23!I12 -> 0 | M12: =VLOOKUP($A12,[6]HISTOMARS23!$A$7:$AU$45,16,0) -> 0 | N12: =IF(M12<>0,VLOOKUP($A12,[6]HISTOMARS23!$A$7:$AU$45,8,0),"ECHEC") -> ECHEC | O12: =IF(R12=0,0,VLOOKUP($A12,[6]HISTOMARS23!$A$7:$AU$45,32,0)) -> 0 | P12: =VLOOKUP($A12,[6]HISTOMARS23!$A$7:$AU$45,33,0) -> 0 | Q12: =IF(R12=0,0,($C$3-R12)) -> 290000 | R12: =VLOOKUP($A12,[6]HISTOMARS23!$A$7:$AU$45,29,0) -> 10000
A13: AS201609 | B13: =IF(D13=0,0,VLOOKUP($A13,[6]HISTOMARS23!$A$6:$BO$40,10,0)) -> 1 | C13: =VLOOKUP(A13,[7]LISTADHERENT!A$5:H$60,3,0) -> DONHOU DAVID | D13: =IF(G13="ECHEC",0,B$3) -> 25000 | E13: =D13+VLOOKUP($A13,[6]HISTOMARS23!$A$7:$AU$40,45,0)+F13 -> 40000 | F13: =VLOOKUP($A13,[6]HISTOMARS23!$A$7:$AU$45,7,0) -> 0 | G13: =VLOOKUP($A13,[6]HISTOMARS23!$A$7:$AU$45,8,0) -> BANQUE | H13: =VLOOKUP($A13,[6]HISTOMARS23!$A$6:$AU$45,35,0) -> 0 | I13: =VLOOKUP($A13,[6]HISTOMARS23!$A$7:$AU$45,38,0) -> 0 | J13: =IF(I13=0,0,VLOOKUP($A13,[6]HISTOMARS23!$A$7:$AU$45,42,0)) -> 0 | K13: =VLOOKUP($A13,[6]HISTOMARS23!$A$7:$AU$45,41,0) -> 0 | L13: =TONTFEV23!H13+TONTFEV23!I13 -> 0 | M13: =VLOOKUP($A13,[6]HISTOMARS23!$A$7:$AU$45,16,0) -> 0 | N13: =IF(M13<>0,VLOOKUP($A13,[6]HISTOMARS23!$A$7:$AU$45,8,0),"ECHEC") -> ECHEC | O13: =IF(R13=0,0,VLOOKUP($A13,[6]HISTOMARS23!$A$7:$AU$45,32,0)) -> 0 | P13: =VLOOKUP($A13,[6]HISTOMARS23!$A$7:$AU$45,33,0) -> 0 | Q13: =IF(R13=0,0,($C$3-R13)) -> 0 | R13: =VLOOKUP($A13,[6]HISTOMARS23!$A$7:$AU$45,29,0) -> 0
A14: AS201611 | B14: =IF(D14=0,0,VLOOKUP($A14,[6]HISTOMARS23!$A$6:$BO$40,10,0)) -> 1 | C14: =VLOOKUP(A14,[7]LISTADHERENT!A$5:H$60,3,0) -> HENGUE PAUL OMER | D14: =IF(G14="ECHEC",0,B$3) -> 25000 | E14: =D14+VLOOKUP($A14,[6]HISTOMARS23!$A$7:$AU$40,45,0)+F14 -> 40000 | F14: =VLOOKUP($A14,[6]HISTOMARS23!$A$7:$AU$45,7,0) -> 0 | G14: =VLOOKUP($A14,[6]HISTOMARS23!$A$7:$AU$45,8,0) -> BANQUE | H14: =VLOOKUP($A14,[6]HISTOMARS23!$A$6:$AU$45,35,0) -> 0 | I14: =VLOOKUP($A14,[6]HISTOMARS23!$A$7:$AU$45,38,0) -> 0 | J14: =IF(I14=0,0,VLOOKUP($A14,[6]HISTOMARS23!$A$7:$AU$45,42,0)) -> 0 | K14: =VLOOKUP($A14,[6]HISTOMARS23!$A$7:$AU$45,41,0) -> 0 | L14: =TONTFEV23!H14+TONTFEV23!I14 -> 0 | M14: =VLOOKUP($A14,[6]HISTOMARS23!$A$7:$AU$45,16,0) -> 0 | N14: =IF(M14<>0,VLOOKUP($A14,[6]HISTOMARS23!$A$7:$AU$45,8,0),"ECHEC") -> ECHEC | O14: =IF(R14=0,0,VLOOKUP($A14,[6]HISTOMARS23!$A$7:$AU$45,32,0)) -> 0 | P14: =VLOOKUP($A14,[6]HISTOMARS23!$A$7:$AU$45,33,0) -> 0 | Q14: =IF(R14=0,0,($C$3-R14)) -> 0 | R14: =VLOOKUP($A14,[6]HISTOMARS23!$A$7:$AU$45,29,0) -> 0
A15: AS201613 | B15: =IF(D15=0,0,VLOOKUP($A15,[6]HISTOMARS23!$A$6:$BO$40,10,0)) -> 1 | C15: =VLOOKUP(A15,[7]LISTADHERENT!A$5:H$60,3,0) -> HOTCHO BENJAMIN | D15: =IF(G15="ECHEC",0,B$3) -> 25000 | E15: =D15+VLOOKUP($A15,[6]HISTOMARS23!$A$7:$AU$40,45,0)+F15 -> 75000 | F15: =VLOOKUP($A15,[6]HISTOMARS23!$A$7:$AU$45,7,0) -> 0 | G15: =VLOOKUP($A15,[6]HISTOMARS23!$A$7:$AU$45,8,0) -> BANQUE | H15: =VLOOKUP($A15,[6]HISTOMARS23!$A$6:$AU$45,35,0) -> 0 | I15: =VLOOKUP($A15,[6]HISTOMARS23!$A$7:$AU$45,38,0) -> 0 | J15: =IF(I15=0,0,VLOOKUP($A15,[6]HISTOMARS23!$A$7:$AU$45,42,0)) -> 0 | K15: =VLOOKUP($A15,[6]HISTOMARS23!$A$7:$AU$45,41,0) -> 0 | L15: =TONTFEV23!H15+TONTFEV23!I15 -> 0 | M15: =VLOOKUP($A15,[6]HISTOMARS23!$A$7:$AU$45,16,0) -> 0 | N15: =IF(M15<>0,VLOOKUP($A15,[6]HISTOMARS23!$A$7:$AU$45,8,0),"ECHEC") -> ECHEC | O15: =IF(R15=0,0,VLOOKUP($A15,[6]HISTOMARS23!$A$7:$AU$45,32,0)) -> 0 | P15: =VLOOKUP($A15,[6]HISTOMARS23!$A$7:$AU$45,33,0) -> 0 | Q15: =IF(R15=0,0,($C$3-R15)) -> 0 | R15: =VLOOKUP($A15,[6]HISTOMARS23!$A$7:$AU$45,29,0) -> 0
A16: AS201617 | B16: =IF(D16=0,0,VLOOKUP($A16,[6]HISTOMARS23!$A$6:$BO$40,10,0)) -> 1 | C16: =VLOOKUP(A16,[7]LISTADHERENT!A$5:H$60,3,0) -> KOUAMOU MOISE | D16: =IF(G16="ECHEC",0,B$3) -> 25000 | E16: =D16+VLOOKUP($A16,[6]HISTOMARS23!$A$7:$AU$40,45,0)+F16 -> 40000 | F16: =VLOOKUP($A16,[6]HISTOMARS23!$A$7:$AU$45,7,0) -> 0 | G16: =VLOOKUP($A16,[6]HISTOMARS23!$A$7:$AU$45,8,0) -> BANQUE | H16: =VLOOKUP($A16,[6]HISTOMARS23!$A$6:$AU$45,35,0) -> 0 | I16: =VLOOKUP($A16,[6]HISTOMARS23!$A$7:$AU$45,38,0) -> 0 | J16: =IF(I16=0,0,VLOOKUP($A16,[6]HISTOMARS23!$A$7:$AU$45,42,0)) -> 0 | K16: =VLOOKUP($A16,[6]HISTOMARS23!$A$7:$AU$45,41,0) -> 0 | L16: =TONTFEV23!H16+TONTFEV23!I16 -> 0 | M16: =VLOOKUP($A16,[6]HISTOMARS23!$A$7:$AU$45,16,0) -> 0 | N16: =IF(M16<>0,VLOOKUP($A16,[6]HISTOMARS23!$A$7:$AU$45,8,0),"ECHEC") -> ECHEC | O16: =IF(R16=0,0,VLOOKUP($A16,[6]HISTOMARS23!$A$7:$AU$45,32,0)) -> 0 | P16: =VLOOKUP($A16,[6]HISTOMARS23!$A$7:$AU$45,33,0) -> 0 | Q16: =IF(R16=0,0,($C$3-R16)) -> 0 | R16: =VLOOKUP($A16,[6]HISTOMARS23!$A$7:$AU$45,29,0) -> 0
A17: AS201619 | B17: =IF(D17=0,0,VLOOKUP($A17,[6]HISTOMARS23!$A$6:$BO$40,10,0)) -> 1 | C17: =VLOOKUP(A17,[7]LISTADHERENT!A$5:H$60,3,0) -> KOUATCHO MESSACK | D17: =IF(G17="ECHEC",0,B$3) -> 25000 | E17: =D17+VLOOKUP($A17,[6]HISTOMARS23!$A$7:$AU$40,45,0)+F17 -> 39000 | F17: =VLOOKUP($A17,[6]HISTOMARS23!$A$7:$AU$45,7,0) -> 0 | G17: =VLOOKUP($A17,[6]HISTOMARS23!$A$7:$AU$45,8,0) -> BANQUE | H17: =VLOOKUP($A17,[6]HISTOMARS23!$A$6:$AU$45,35,0) -> 0 | I17: =VLOOKUP($A17,[6]HISTOMARS23!$A$7:$AU$45,38,0) -> 0 | J17: =IF(I17=0,0,VLOOKUP($A17,[6]HISTOMARS23!$A$7:$AU$45,42,0)) -> 0 | K17: =VLOOKUP($A17,[6]HISTOMARS23!$A$7:$AU$45,41,0) -> 0 | L17: =TONTFEV23!H17+TONTFEV23!I17 -> 0 | M17: =VLOOKUP($A17,[6]HISTOMARS23!$A$7:$AU$45,16,0) -> 0 | N17: =IF(M17<>0,VLOOKUP($A17,[6]HISTOMARS23!$A$7:$AU$45,8,0),"ECHEC") -> ECHEC | O17: =IF(R17=0,0,VLOOKUP($A17,[6]HISTOMARS23!$A$7:$AU$45,32,0)) -> 0 | P17: =VLOOKUP($A17,[6]HISTOMARS23!$A$7:$AU$45,33,0) -> 0 | Q17: =IF(R17=0,0,($C$3-R17)) -> 0 | R17: =VLOOKUP($A17,[6]HISTOMARS23!$A$7:$AU$45,29,0) -> 0
... A35: AS201647 | B35: =IF(D35=0,0,VLOOKUP($A35,[6]HISTOMARS23!$A$6:$BO$40,10,0)) -> 1 | C35: =VLOOKUP(A35,[7]LISTADHERENT!A$5:H$60,3,0) -> YOUMBI EMMANUEL | D35: =IF(G35="ECHEC",0,B$3) -> 25000 | E35: =D35+VLOOKUP($A35,[6]HISTOMARS23!$A$7:$AU$40,45,0)+F35 -> 40000 | F35: =VLOOKUP($A35,[6]HISTOMARS23!$A$7:$AU$45,7,0) -> 0 | G35: =VLOOKUP($A35,[6]HISTOMARS23!$A$7:$AU$45,8,0) -> BANQUE | H35: =VLOOKUP($A35,[6]HISTOMARS23!$A$6:$AU$45,35,0) -> 0 | I35: =VLOOKUP($A35,[6]HISTOMARS23!$A$7:$AU$45,38,0) -> 0 | J35: =IF(I35=0,0,VLOOKUP($A35,[6]HISTOMARS23!$A$7:$AU$45,42,0)) -> 0 | K35: =VLOOKUP($A35,[6]HISTOMARS23!$A$7:$AU$45,41,0) -> 0 | L35: =TONTFEV23!H35+TONTFEV23!I35 -> 0 | M35: =VLOOKUP($A35,[6]HISTOMARS23!$A$7:$AU$45,16,0) -> 0 | N35: =IF(M35<>0,VLOOKUP($A35,[6]HISTOMARS23!$A$7:$AU$45,8,0),"ECHEC") -> ECHEC | O35: =IF(R35=0,0,VLOOKUP($A35,[6]HISTOMARS23!$A$7:$AU$45,32,0)) -> 0 | P35: =VLOOKUP($A35,[6]HISTOMARS23!$A$7:$AU$45,33,0) -> 0 | Q35: =IF(R35=0,0,($C$3-R35)) -> 0 | R35: =VLOOKUP($A35,[6]HISTOMARS23!$A$7:$AU$45,29,0) -> 0
A37: TOTAL PART | B37: =SUM(B6:B36) -> 30
A38: NBRE ADHERENT | B38: =COUNT(D6:D35) -> 30 | D38: =SUM(D6:D37) -> 750000 | E38: =SUM(E6:E37) -> 1283000 | F38: =SUM(F6:F37) -> 6000 | H38: =SUM(H6:H37) -> 0 | I38: =SUM(I6:I37) -> 0 | L38: =SUM(L6:L37) -> 114500 | M38: =SUM(M6:M37) -> 114500 | N38: =SUM(N6:N37) -> 0 | O38: =SUM(O6:O37) -> 0 | P38: =SUM(P6:P37) -> 0 | Q38: =SUM(Q6:Q37) -> 868000 | R38: =SUM(R6:R37) -> 32000
N39: NBRE PART | O39: PART VENDUE
D40: MONTANT TONTINE | E40: MONTANT VERSE | G40: REMBOURSEMENT PETIT LOT | H40: VENTE PETIT LOT | I40: VENTE LOT PRINCIPAL | J40: SOLDE EN CAISSE | L40: TONTINE + REMB + INTERET VENTE | M40: =D44+G44+R38+TONTFEV23!O45 -> 896500
D41: =SUMIFS(D6:D37,G6:G37,"ESPECES") -> 50000 | E41: =SUMIFS(E6:E37,G6:G37,"ESPECES") -> 86000 | F41: ESPECES | G41: =SUMIFS(M6:M35,N6:N35,"ESPECES") -> 41000 | H41: =SUMIFS(H6:H37,J6:J37,"ESPECES") -> 0 | I41: =SUMIFS(Q6:Q37,O6:O37,"ESPECES") -> 0 | J41: =D41+G41-H41-I41 -> 91000 | L41: LOT PRINCIPAL | M41: =C3*COUNTIF(Q6:Q37,">0") -> 900000 | N41: =D3 -> 2 | O41: =COUNTIF(Q6:Q35,">0") -> 3
D42: =SUMIFS(D6:D37,G6:G37,"BANQUE") -> 700000 | E42: =SUMIFS(E6:E38,G6:G38,"BANQUE") -> 1197000 | F42: BANQUE | G42: =SUMIFS(M6:M35,N6:N35,"BANQUE") -> 73500 | H42: =SUMIFS(H6:H37,J6:J37,"BANQUE") -> 0 | I42: =SUMIFS(Q6:Q37,O6:O37,"BANQUE") -> 0 | J42: =D42+G42-H42-I42 -> 773500
L43: PETIT LOT | M43: =M40-M41 -> -3500
D44: =D41+D42 -> 750000 | E44: =E41+E42 -> 1283000 | F44: TOTAL | G44: =G41+G42 -> 114500 | H44: =H41+H42 -> 0 | I44: =I41+I42 -> 0 | J44: =J41+J42 -> 864500
F45: TOTAL+DEPOT | L45: RELIQUAT | M45: =M43-H38 -> -3500 | O45: =TONTMARS23!M45 -> -3500 | P45: CUMUL
L47: ECHEC TONTINE MOIS | M47: =COUNTIFS(G6:G36,"ECHEC")*25000 -> 0 | O47: =TONTFEV23!O47+TONTMARS23!M47 -> 0 | P47: CUMUL
L48: ECHEC REMBOURSEMENT MOIS | M48: =L38-G44 -> 0 | O48: =TONTFEV23!O48+TONTMARS23!M48 -> 0 | P48: CUMUL

Sheet TONTAVRIL23
A1: ASSOCIATION | B1: ASELBY
A2: ANNEE | B2: 2023 | C2: TONIINE | D2: NBRE PART
A3: TAUX TONTINE | B3: 25000 | C3: =B3*12 -> 300000 | D3: =ROUNDDOWN(M40/C3,0) -> 2
C4: 45029
A5: MATRICULE | B5: NBREPART | C5: NOM ET PRENOM | D5: MONTANT TONTINE | E5: MONTANT VERSE | F5: PENALITE VERSEMENT ESPECES | G5: MODE VERSEMENT | H5: VENTE PETIT LOT | I5: INTERET PETIT LOT | J5: MODE VERSEMENT VENTE PETIT LOT | K5: NUMERO CHEQUE | L5: MONTANT A REMBOURSER PETIT LOT | M5: REMBOURSEMENT PETIT LOT | N5: MODE VERSEMENT REMBOURSEMENT | O5: MODE VERSEMENTLOT PRINCIPAL | P5: NUMERO CHEQUE | Q5: MONTANT LOT PRINCIPAL | R5: INTERET LOT PRINCIPAL
A6: AS201601 | B6: =IF(D6=0,0,VLOOKUP($A6,[6]HISTOAVRIL23!$A$6:$BO$40,10,0)) -> 1 | C6: =VLOOKUP(A6,[7]LISTADHERENT!A$5:H$60,3,0) -> BAKOP ACHILLE | D6: =IF(G6="ECHEC",0,B$3) -> 25000 | E6: =D6+VLOOKUP($A6,[6]HISTOAVRIL23!$A$7:$AU$40,45,0)+F6 -> 40000 | F6: =VLOOKUP($A6,[6]HISTOAVRIL23!$A$7:$AU$45,7,0) -> 0 | G6: =VLOOKUP($A6,[6]HISTOAVRIL23!$A$7:$AU$45,8,0) -> BANQUE | H6: =VLOOKUP($A6,[6]HISTOAVRIL23!$A$6:$AU$45,35,0) -> 0 | I6: =VLOOKUP($A6,[6]HISTOAVRIL23!$A$7:$AU$45,38,0) -> 0 | J6: =IF(I6=0,0,VLOOKUP($A6,[6]HISTOAVRIL23!$A$7:$AU$45,42,0)) -> 0 | K6: =VLOOKUP($A6,[6]HISTOAVRIL23!$A$7:$AU$45,41,0) -> 0 | L6: =TONTMARS23!H6+TONTMARS23!I6 -> 0 | M6: =VLOOKUP($A6,[6]HISTOAVRIL23!$A$7:$AU$45,16,0) -> 0 | N6: =IF(M6<>0,VLOOKUP($A6,[6]HISTOAVRIL23!$A$7:$AU$45,8,0),"ECHEC") -> ECHEC | O6: =IF(R6=0,0,VLOOKUP($A6,[6]HISTOAVRIL23!$A$7:$AU$45,32,0)) -> 0 | P6: =VLOOKUP($A6,[6]HISTOAVRIL23!$A$7:$AU$45,33,0) -> 0 | Q6: =IF(R6=0,0,($C$3-R6)) -> 0 | R6: =VLOOKUP($A6,[6]HISTOAVRIL23!$A$7:$AU$45,29,0) -> 0
A7: AS201602 | B7: =IF(D7=0,0,VLOOKUP($A7,[6]HISTOAVRIL23!$A$6:$BO$40,10,0)) -> 1 | C7: =VLOOKUP(A7,[7]LISTADHERENT!A$5:H$60,3,0) -> BOUTCHOUANG WILLIAM | D7: =IF(G7="ECHEC",0,B$3) -> 25000 | E7: =D7+VLOOKUP($A7,[6]HISTOAVRIL23!$A$7:$AU$40,45,0)+F7 -> 40000 | F7: =VLOOKUP($A7,[6]HISTOAVRIL23!$A$7:$AU$45,7,0) -> 0 | G7: =VLOOKUP($A7,[6]HISTOAVRIL23!$A$7:$AU$45,8,0) -> BANQUE | H7: =VLOOKUP($A7,[6]HISTOAVRIL23!$A$6:$AU$45,35,0) -> 0 | I7: =VLOOKUP($A7,[6]HISTOAVRIL23!$A$7:$AU$45,38,0) -> 0 | J7: =IF(I7=0,0,VLOOKUP($A7,[6]HISTOAVRIL23!$A$7:$AU$45,42,0)) -> 0 | K7: =VLOOKUP($A7,[6]HISTOAVRIL23!$A$7:$AU$45,41,0) -> 0 | L7: =TONTMARS23!H7+TONTMARS23!I7 -> 0 | M7: =VLOOKUP($A7,[6]HISTOAVRIL23!$A$7:$AU$45,16,0) -> 0 | N7: =IF(M7<>0,VLOOKUP($A7,[6]HISTOAVRIL23!$A$7:$AU$45,8,0),"ECHEC") -> ECHEC | O7: =IF(R7=0,0,VLOOKUP($A7,[6]HISTOAVRIL23!$A$7:$AU$45,32,0)) -> 0 | P7: =VLOOKUP($A7,[6]HISTOAVRIL23!$A$7:$AU$45,33,0) -> 0 | Q7: =IF(R7=0,0,($C$3-R7)) -> 0 | R7: =VLOOKUP($A7,[6]HISTOAVRIL23!$A$7:$AU$45,29,0) -> 0
A8: AS201604 | B8: =IF(D8=0,0,VLOOKUP($A8,[6]HISTOAVRIL23!$A$6:$BO$40,10,0)) -> 1 | C8: =VLOOKUP(A8,[7]LISTADHERENT!A$5:H$60,3,0) -> DJOMO JEAN PAUL | D8: =IF(G8="ECHEC",0,B$3) -> 25000 | E8: =D8+VLOOKUP($A8,[6]HISTOAVRIL23!$A$7:$AU$40,45,0)+F8 -> 45000 | F8: =VLOOKUP($A8,[6]HISTOAVRIL23!$A$7:$AU$45,7,0) -> 0 | G8: =VLOOKUP($A8,[6]HISTOAVRIL23!$A$7:$AU$45,8,0) -> BANQUE | H8: =VLOOKUP($A8,[6]HISTOAVRIL23!$A$6:$AU$45,35,0) -> 22500 | I8: =VLOOKUP($A8,[6]HISTOAVRIL23!$A$7:$AU$45,38,0) -> 500 | J8: =IF(I8=0,0,VLOOKUP($A8,[6]HISTOAVRIL23!$A$7:$AU$45,42,0)) -> 0 | K8: =VLOOKUP($A8,[6]HISTOAVRIL23!$A$7:$AU$45,41,0) -> 0 | L8: =TONTMARS23!H8+TONTMARS23!I8 -> 0 | M8: =VLOOKUP($A8,[6]HISTOAVRIL23!$A$7:$AU$45,16,0) -> 0 | N8: =IF(M8<>0,VLOOKUP($A8,[6]HISTOAVRIL23!$A$7:$AU$45,8,0),"ECHEC") -> ECHEC | O8: =IF(R8=0,0,VLOOKUP($A8,[6]HISTOAVRIL23!$A$7:$AU$45,32,0)) -> 0 | P8: =VLOOKUP($A8,[6]HISTOAVRIL23!$A$7:$AU$45,33,0) -> 0 | Q8: =IF(R8=0,0,($C$3-R8)) -> 0 | R8: =VLOOKUP($A8,[6]HISTOAVRIL23!$A$7:$AU$45,29,0) -> 0
A9: AS201654 | B9: =IF(D9=0,0,VLOOKUP($A9,[6]HISTOAVRIL23!$A$6:$BO$40,10,0)) -> 1 | C9: =VLOOKUP(A9,[7]LISTADHERENT!A$5:H$60,3,0) -> DJOMOU TCHAPDA | D9: =IF(G9="ECHEC",0,B$3) -> 25000 | E9: =D9+VLOOKUP($A9,[6]HISTOAVRIL23!$A$7:$AU$40,45,0)+F9 -> 43000 | F9: =VLOOKUP($A9,[6]HISTOAVRIL23!$A$7:$AU$45,7,0) -> 3000 | G9: =VLOOKUP($A9,[6]HISTOAVRIL23!$A$7:$AU$45,8,0) -> ESPECES | H9: =VLOOKUP($A9,[6]HISTOAVRIL23!$A$6:$AU$45,35,0) -> 60000 | I9: =VLOOKUP($A9,[6]HISTOAVRIL23!$A$7:$AU$45,38,0) -> 2000 | J9: =IF(I9=0,0,VLOOKUP($A9,[6]HISTOAVRIL23!$A$7:$AU$45,42,0)) -> 0 | K9: =VLOOKUP($A9,[6]HISTOAVRIL23!$A$7:$AU$45,41,0) -> 0 | L9: =TONTMARS23!H9+TONTMARS23!I9 -> 0 | M9: =VLOOKUP($A9,[6]HISTOAVRIL23!$A$7:$AU$45,16,0) -> 0 | N9: =IF(M9<>0,VLOOKUP($A9,[6]HISTOAVRIL23!$A$7:$AU$45,8,0),"ECHEC") -> ECHEC | O9: =IF(R9=0,0,VLOOKUP($A9,[6]HISTOAVRIL23!$A$7:$AU$45,32,0)) -> 0 | P9: =VLOOKUP($A9,[6]HISTOAVRIL23!$A$7:$AU$45,33,0) -> 0 | Q9: =IF(R9=0,0,($C$3-R9)) -> 289000 | R9: =VLOOKUP($A9,[6]HISTOAVRIL23!$A$7:$AU$45,29,0) -> 11000
A10: AS201605 | B10: =IF(D10=0,0,VLOOKUP($A10,[6]HISTOAVRIL23!$A$6:$BO$40,10,0)) -> 1 | C10: =VLOOKUP(A10,[7]LISTADHERENT!A$5:H$60,3,0) -> DJOUKWE NANGUEN GUY BLAISE | D10: =IF(G10="ECHEC",0,B$3) -> 25000 | E10: =D10+VLOOKUP($A10,[6]HISTOAVRIL23!$A$7:$AU$40,45,0)+F10 -> 40000 | F10: =VLOOKUP($A10,[6]HISTOAVRIL23!$A$7:$AU$45,7,0) -> 0 | G10: =VLOOKUP($A10,[6]HISTOAVRIL23!$A$7:$AU$45,8,0) -> BANQUE | H10: =VLOOKUP($A10,[6]HISTOAVRIL23!$A$6:$AU$45,35,0) -> 0 | I10: =VLOOKUP($A10,[6]HISTOAVRIL23!$A$7:$AU$45,38,0) -> 0 | J10: =IF(I10=0,0,VLOOKUP($A10,[6]HISTOAVRIL23!$A$7:$AU$45,42,0)) -> 0 | K10: =VLOOKUP($A10,[6]HISTOAVRIL23!$A$7:$AU$45,41,0) -> 0 | L10: =TONTMARS23!H10+TONTMARS23!I10 -> 0 | M10: =VLOOKUP($A10,[6]HISTOAVRIL23!$A$7:$AU$45,16,0) -> 0 | N10: =IF(M10<>0,VLOOKUP($A10,[6]HISTOAVRIL23!$A$7:$AU$45,8,0),"ECHEC") -> ECHEC | O10: =IF(R10=0,0,VLOOKUP($A10,[6]HISTOAVRIL23!$A$7:$AU$45,32,0)) -> 0 | P10: =VLOOKUP($A10,[6]HISTOAVRIL23!$A$7:$AU$45,33,0) -> 0 | Q10: =IF(R10=0,0,($C$3-R10)) -> 290000 | R10: =VLOOKUP($A10,[6]HISTOAVRIL23!$A$7:$AU$45,29,0) -> 10000
A11: AS201608 | B11: =IF(D11=0,0,VLOOKUP($A11,[6]HISTOAVRIL23!$A$6:$BO$40,10,0)) -> 1 | C11: =VLOOKUP(A11,[7]LISTADHERENT!A$5:H$60,3,0) -> DJUOMBESSY ANTOINE | D11: =IF(G11="ECHEC",0,B$3) -> 25000 | E11: =D11+VLOOKUP($A11,[6]HISTOAVRIL23!$A$7:$AU$40,45,0)+F11 -> 45000 | F11: =VLOOKUP($A11,[6]HISTOAVRIL23!$A$7:$AU$45,7,0) -> 0 | G11: =VLOOKUP($A11,[6]HISTOAVRIL23!$A$7:$AU$45,8,0) -> BANQUE | H11: =VLOOKUP($A11,[6]HISTOAVRIL23!$A$6:$AU$45,35,0) -> 0 | I11: =VLOOKUP($A11,[6]HISTOAVRIL23!$A$7:$AU$45,38,0) -> 0 | J11: =IF(I11=0,0,VLOOKUP($A11,[6]HISTOAVRIL23!$A$7:$AU$45,42,0)) -> 0 | K11: =VLOOKUP($A11,[6]HISTOAVRIL23!$A$7:$AU$45,41,0) -> 0 | L11: =TONTMARS23!H11+TONTMARS23!I11 -> 0 | M11: =VLOOKUP($A11,[6]HISTOAVRIL23!$A$7:$AU$45,16,0) -> 0 | N11: =IF(M11<>0,VLOOKUP($A11,[6]HISTOAVRIL23!$A$7:$AU$45,8,0),"ECHEC") -> ECHEC | O11: =IF(R11=0,0,VLOOKUP($A11,[6]HISTOAVRIL23!$A$7:$AU$45,32,0)) -> 0 | P11: =VLOOKUP($A11,[6]HISTOAVRIL23!$A$7:$AU$45,33,0) -> 0 | Q11: =IF(R11=0,0,($C$3-R11)) -> 0 | R11: =VLOOKUP($A11,[6]HISTOAVRIL23!$A$7:$AU$45,29,0) -> 0
A12: AS201651 | B12: =IF(D12=0,0,VLOOKUP($A12,[6]HISTOAVRIL23!$A$6:$BO$40,10,0)) -> 1 | C12: =VLOOKUP(A12,[7]LISTADHERENT!A$5:H$60,3,0) -> DOMOU FABIEN | D12: =IF(G12="ECHEC",0,B$3) -> 25000 | E12: =D12+VLOOKUP($A12,[6]HISTOAVRIL23!$A$7:$AU$40,45,0)+F12 -> 40000 | F12: =VLOOKUP($A12,[6]HISTOAVRIL23!$A$7:$AU$45,7,0) -> 0 | G12: =VLOOKUP($A12,[6]HISTOAVRIL23!$A$7:$AU$45,8,0) -> BANQUE | H12: =VLOOKUP($A12,[6]HISTOAVRIL23!$A$6:$AU$45,35,0) -> 0 | I12: =VLOOKUP($A12,[6]HISTOAVRIL23!$A$7:$AU$45,38,0) -> 0 | J12: =IF(I12=0,0,VLOOKUP($A12,[6]HISTOAVRIL23!$A$7:$AU$45,42,0)) -> 0 | K12: =VLOOKUP($A12,[6]HISTOAVRIL23!$A$7:$AU$45,41,0) -> 0 | L12: =TONTMARS23!H12+TONTMARS23!I12 -> 0 | M12: =VLOOKUP($A12,[6]HISTOAVRIL23!$A$7:$AU$45,16,0) -> 0 | N12: =IF(M12<>0,VLOOKUP($A12,[6]HISTOAVRIL23!$A$7:$AU$45,8,0),"ECHEC") -> ECHEC | O12: =IF(R12=0,0,VLOOKUP($A12,[6]HISTOAVRIL23!$A$7:$AU$45,32,0)) -> 0 | P12: =VLOOKUP($A12,[6]HISTOAVRIL23!$A$7:$AU$45,33,0) -> 0 | Q12: =IF(R12=0,0,($C$3-R12)) -> 0 | R12: =VLOOKUP($A12,[6]HISTOAVRIL23!$A$7:$AU$45,29,0) -> 0
A13: AS201609 | B13: =IF(D13=0,0,VLOOKUP($A13,[6]HISTOAVRIL23!$A$6:$BO$40,10,0)) -> 1 | C13: =VLOOKUP(A13,[7]LISTADHERENT!A$5:H$60,3,0) -> DONHOU DAVID | D13: =IF(G13="ECHEC",0,B$3) -> 25000 | E13: =D13+VLOOKUP($A13,[6]HISTOAVRIL23!$A$7:$AU$40,45,0)+F13 -> 40000 | F13: =VLOOKUP($A13,[6]HISTOAVRIL23!$A$7:$AU$45,7,0) -> 0 | G13: =VLOOKUP($A13,[6]HISTOAVRIL23!$A$7:$AU$45,8,0) -> BANQUE | H13: =VLOOKUP($A13,[6]HISTOAVRIL23!$A$6:$AU$45,35,0) -> 0 | I13: =VLOOKUP($A13,[6]HISTOAVRIL23!$A$7:$AU$45,38,0) -> 0 | J13: =IF(I13=0,0,VLOOKUP($A13,[6]HISTOAVRIL23!$A$7:$AU$45,42,0)) -> 0 | K13: =VLOOKUP($A13,[6]HISTOAVRIL23!$A$7:$AU$45,41,0) -> 0 | L13: =TONTMARS23!H13+TONTMARS23!I13 -> 0 | M13: =VLOOKUP($A13,[6]HISTOAVRIL23!$A$7:$AU$45,16,0) -> 0 | N13: =IF(M13<>0,VLOOKUP($A13,[6]HISTOAVRIL23!$A$7:$AU$45,8,0),"ECHEC") -> ECHEC | O13: =IF(R13=0,0,VLOOKUP($A13,[6]HISTOAVRIL23!$A$7:$AU$45,32,0)) -> 0 | P13: =VLOOKUP($A13,[6]HISTOAVRIL23!$A$7:$AU$45,33,0) -> 0 | Q13: =IF(R13=0,0,($C$3-R13)) -> 0 | R13: =VLOOKUP($A13,[6]HISTOAVRIL23!$A$7:$AU$45,29,0) -> 0
A14: AS201611 | B14: =IF(D14=0,0,VLOOKUP($A14,[6]HISTOAVRIL23!$A$6:$BO$40,10,0)) -> 1 | C14: =VLOOKUP(A14,[7]LISTADHERENT!A$5:H$60,3,0) -> HENGUE PAUL OMER | D14: =IF(G14="ECHEC",0,B$3) -> 25000 | E14: =D14+VLOOKUP($A14,[6]HISTOAVRIL23!$A$7:$AU$40,45,0)+F14 -> 40000 | F14: =VLOOKUP($A14,[6]HISTOAVRIL23!$A$7:$AU$45,7,0) -> 0 | G14: =VLOOKUP($A14,[6]HISTOAVRIL23!$A$7:$AU$45,8,0) -> BANQUE | H14: =VLOOKUP($A14,[6]HISTOAVRIL23!$A$6:$AU$45,35,0) -> 0 | I14: =VLOOKUP($A14,[6]HISTOAVRIL23!$A$7:$AU$45,38,0) -> 0 | J14: =IF(I14=0,0,VLOOKUP($A14,[6]HISTOAVRIL23!$A$7:$AU$45,42,0)) -> 0 | K14: =VLOOKUP($A14,[6]HISTOAVRIL23!$A$7:$AU$45,41,0) -> 0 | L14: =TONTMARS23!H14+TONTMARS23!I14 -> 0 | M14: =VLOOKUP($A14,[6]HISTOAVRIL23!$A$7:$AU$45,16,0) -> 0 | N14: =IF(M14<>0,VLOOKUP($A14,[6]HISTOAVRIL23!$A$7:$AU$45,8,0),"ECHEC") -> ECHEC | O14: =IF(R14=0,0,VLOOKUP($A14,[6]HISTOAVRIL23!$A$7:$AU$45,32,0)) -> 0 | P14: =VLOOKUP($A14,[6]HISTOAVRIL23!$A$7:$AU$45,33,0) -> 0 | Q14: =IF(R14=0,0,($C$3-R14)) -> 0 | R14: =VLOOKUP($A14,[6]HISTOAVRIL23!$A$7:$AU$45,29,0) -> 0
A15: AS201613 | B15: =IF(D15=0,0,VLOOKUP($A15,[6]HISTOAVRIL23!$A$6:$BO$40,10,0)) -> 1 | C15: =VLOOKUP(A15,[7]LISTADHERENT!A$5:H$60,3,0) -> HOTCHO BENJAMIN | D15: =IF(G15="ECHEC",0,B$3) -> 25000 | E15: =D15+VLOOKUP($A15,[6]HISTOAVRIL23!$A$7:$AU$40,45,0)+F15 -> 75000 | F15: =VLOOKUP($A15,[6]HISTOAVRIL23!$A$7:$AU$45,7,0) -> 0 | G15: =VLOOKUP($A15,[6]HISTOAVRIL23!$A$7:$AU$45,8,0) -> BANQUE | H15: =VLOOKUP($A15,[6]HISTOAVRIL23!$A$6:$AU$45,35,0) -> 0 | I15: =VLOOKUP($A15,[6]HISTOAVRIL23!$A$7:$AU$45,38,0) -> 0 | J15: =IF(I15=0,0,VLOOKUP($A15,[6]HISTOAVRIL23!$A$7:$AU$45,42,0)) -> 0 | K15: =VLOOKUP($A15,[6]HISTOAVRIL23!$A$7:$AU$45,41,0) -> 0 | L15: =TONTMARS23!H15+TONTMARS23!I15 -> 0 | M15: =VLOOKUP($A15,[6]HISTOAVRIL23!$A$7:$AU$45,16,0) -> 0 | N15: =IF(M15<>0,VLOOKUP($A15,[6]HISTOAVRIL23!$A$7:$AU$45,8,0),"ECHEC") -> ECHEC | O15: =IF(R15=0,0,VLOOKUP($A15,[6]HISTOAVRIL23!$A$7:$AU$45,32,0)) -> 0 | P15: =VLOOKUP($A15,[6]HISTOAVRIL23!$A$7:$AU$45,33,0) -> 0 | Q15: =IF(R15=0,0,($C$3-R15)) -> 0 | R15: =VLOOKUP($A15,[6]HISTOAVRIL23!$A$7:$AU$45,29,0) -> 0
