Workbook
Name BANQUE: #REF!
Name BANQUE: #REF!
Name BANQUE: #REF!
Name BANQUE: #REF!
Name BANQUE: #REF!
Name BANQUE: #REF!
Name BANQUE: #REF!
Name BANQUE: #REF!
Name BANQUE: #REF!
Name BANQUE: #REF!
Name BANQUE: #REF!
Name BANQUE: #REF!
Name BANQUE: #REF!
Name BANQUE: #REF!
Name BANQUE: #REF!
Name BANQUE: #REF!
Name BANQUE: #REF!
Name MODEPAID: [1]Feuil2!$A$1:$A$3
Name MODET25000: [2]MODEVERSEMENT!$A$1:$A$3
Name MODEVERSEMENT: #REF!
Name MODEVERSEMENT: #REF!
Name MODEVERSEMENT: #REF!
Name MODEVERSEMENT: #REF!
Name MODEVERSEMENT: #REF!
Name MODEVERSEMENT: #REF!
Name MODEVERSEMENT: #REF!
Name MODEVERSEMENT: #REF!
Name MODEVERSEMENT: #REF!
Name MODEVERSEMENT: #REF!
Name MODEVERSEMENT: #REF!
Name MODEVERSEMENT: #REF!
Name MODEVERSEMENT: #REF!
Name MODEVERSEMENT: #REF!
Name MODEVERSEMENT: #REF!
Name MODEVERSEMENT: #REF!
Name MODEVERSEMENT: #REF!
Name MODEVERSEMENTS: [3]MODEVERSEMENT!$A$1:$A$3
Name MODEVERSEMENTS: [3]MODEVERSEMENT!$A$1:$A$3
Name MODEVERSEMENTS: [3]MODEVERSEMENT!$A$1:$A$3
Name MODEVERSEMENTS: [3]MODEVERSEMENT!$A$1:$A$3
Name MODEVERSEMENTS: [3]MODEVERSEMENT!$A$1:$A$3
Name MODEVERSEMENTS: [3]MODEVERSEMENT!$A$1:$A$3
Name MODEVERSEMENTS: [3]MODEVERSEMENT!$A$1:$A$3
Name MODEVERSEMENTS: [3]MODEVERSEMENT!$A$1:$A$3
Name MODEVERSEMENTS: [3]MODEVERSEMENT!$A$1:$A$3
Name MODEVERSEMENTS: [3]MODEVERSEMENT!$A$1:$A$3
Name MODEVERSEMENTS: [3]MODEVERSEMENT!$A$1:$A$3
Name MODEVERSEMENTS: [3]MODEVERSEMENT!$A$1:$A$3
Name MODEVERSEMENTS: [3]MODEVERSEMENT!$A$1:$A$3
Name MODEVERSEMENTS: [3]MODEVERSEMENT!$A$1:$A$3
Name MODEVERSEMENTS: [3]MODEVERSEMENT!$A$1:$A$3
Name MODEVERSEMENTS: MODEVERSEMENT!$A$1:$A$3
Name VALMODEPAID: [4]MODEPAID!$A$1:$A$3

Sheet MODEVERSEMENT
A1: BANQUE
A2: ESPECES
A3: ECHEC

Sheet COMPTE BANQUE
C1: COMPTE BANQUE | H1: COMPTE CAISSE
A2: ANNEE | C2: 2021 | H2: 2021
A4: MOIS | B4: NUMERO CHEQUE | C4: SORTIE | D4: ENTREE | E4: SOLDE | G4: NUMERO PIECE | H4: ENTREE | I4: SORTIE | J4: SOLDE
A5: REPORT A NOUVEAU | E5: =14283661-6017000 -> 8266661
A6: JANVIER | C6: =HISTOBQUEJANV22!#REF! -> #REF! | D6: =HISTOBQUEJANV22!#REF! -> #REF! | E6: =IF(D6=0,0,E5+D6-C6) -> #REF!
A7: FÉVRIER | C7: =#REF! -> #REF! | D7: =#REF! -> #REF! | E7: =IF(D7=0,0,E6+D7-C7) -> #REF!
A8: MARS | C8: =#REF! -> #REF! | D8: =#REF! -> #REF! | E8: =IF(D8=0,0,E7+D8-C8) -> #REF!
A9: AVRIL | C9: =#REF! -> #REF! | D9: =#REF! -> #REF! | E9: =IF(D9=0,0,E8+D9-C9) -> #REF!
A10: MAI | C10: =#REF! -> #REF! | D10: =#REF! -> #REF! | E10: =IF(D10=0,0,E9+D10-C10) -> #REF!
A11: JUIN | C11: =#REF! -> #REF! | D11: =#REF! -> #REF! | E11: =IF(D11=0,0,E10+D11-C11) -> #REF!
A12: JUILLET | C12: =#REF! -> #REF! | D12: =#REF! -> #REF! | E12: =IF(D12=0,0,E11+D12-C12) -> #REF!
A13: AOÛT | C13: =#REF! -> #REF! | D13: =#REF! -> #REF! | E13: =IF(D13=0,0,E12+D13-C13) -> #REF!
A14: SEPTEMBRE | C14: =#REF! -> #REF! | D14: =#REF! -> #REF! | E14: =IF(D14=0,0,E13+D14-C14) -> #REF!
A15: OCTOBRE | C15: =#REF! -> #REF! | D15: =#REF! -> #REF! | E15: =IF(D15=0,0,E14+D15-C15) -> #REF!
A16: NOVEMBRE | C16: =#REF! -> #REF! | D16: =#REF! -> #REF! | E16: =IF(D16=0,0,E15+D16-C16) -> #REF!
A17: DÉCEMBRE | C17: =#REF! -> #REF! | D17: =#REF! -> #REF! | E17: =IF(D17=0,0,E16+D17-C17) -> #REF!
A19: TOTAL

Sheet HISTOBQUEJANV23
A1: ASSOCIATION | B1: ASELBY
A2: ANNEE | B2: 2023
A3: 1 | B3: 2 | C3: 4 | D3: 5 | E3: 6 | F3: 21
B4: HISTORIQUE BANCAIRE
A5: MATRICULE | B5: NOM ET PRENOM | C5: HISTORIQUE BANQUE | D5: HITORIQUE ESPECES | E5: HITORIQUE TONTINE | F5: MONTANT ENGAGEMENT | G5: VERIFICATION | H5: AGIO
A6: AS201648 | B6: =VLOOKUP(A6,[5]LISTADHERENT!A$5:H$60,3,0) -> ASELBY | F6: =SUM(C6:E6) -> 0
A7: AS201602 | B7: =VLOOKUP(A7,[5]LISTADHERENT!A$5:H$60,3,0) -> BOUTCHOUANG WILLIAM | C7: 105000 | F7: =SUM(C7:E7) -> 105000 | G7: 40000
A8: AS201604 | B8: =VLOOKUP(A8,[5]LISTADHERENT!A$5:H$60,3,0) -> DJOMO JEAN PAUL | C8: 160000 | F8: =SUM(C8:E8) -> 160000 | G8: 115000
A9: AS201654 | B9: =VLOOKUP(A9,[5]LISTADHERENT!A$5:H$60,3,0) -> DJOMOU TCHANDA | C9: 40000 | F9: =SUM(C9:E9) -> 40000 | G9: 250000
A10: AS201605 | B10: =VLOOKUP(A10,[5]LISTADHERENT!A$5:H$60,3,0) -> DJOUKWE NANGUEN GUY BLAISE | C10: 115000 | F10: =SUM(C10:E10) -> 115000 | G10: 115000
A11: AS201608 | B11: =VLOOKUP(A11,[5]LISTADHERENT!A$5:H$60,3,0) -> DJUOMBESSY ANTOINE | C11: 320000 | F11: =SUM(C11:E11) -> 320000 | G11: 280000
A12: AS201651 | B12: =VLOOKUP(A12,[5]LISTADHERENT!A$5:H$60,3,0) -> DOMOU FABIEN | C12: 40000 | F12: =SUM(C12:E12) -> 40000 | G12: 115000
A13: AS201609 | B13: =VLOOKUP(A13,[5]LISTADHERENT!A$5:H$60,3,0) -> DONHOU DAVID | F13: =SUM(C13:E13) -> 0 | G13: 140000
A14: AS201610 | B14: =VLOOKUP(A14,[5]LISTADHERENT!A$5:H$60,3,0) -> FOTSO THOMAS | F14: =SUM(C14:E14) -> 0 | G14: 250000
A15: AS201611 | B15: =VLOOKUP(A15,[5]LISTADHERENT!A$5:H$60,3,0) -> HENGUE PAUL OMER | C15: 115000 | F15: =SUM(C15:E15) -> 115000 | G15: 105000
A16: AS201613 | B16: =VLOOKUP(A16,[5]LISTADHERENT!A$5:H$60,3,0) -> HOTCHO BENJAMIN | C16: 250000 | F16: =SUM(C16:E16) -> 250000 | G16: 320000
A17: AS201617 | B17: =VLOOKUP(A17,[5]LISTADHERENT!A$5:H$60,3,0) -> KOUAMOU MOISE | C17: 140000 | F17: =SUM(C17:E17) -> 140000 | G17: 290000
A18: AS201619 | B18: =VLOOKUP(A18,[5]LISTADHERENT!A$5:H$60,3,0) -> KOUATCHO MESSACK | F18: =SUM(C18:E18) -> 0 | G18: 250000
A19: AS201620 | B19: =VLOOKUP(A19,[5]LISTADHERENT!A$5:H$60,3,0) -> LOWE JEAN | F19: =SUM(C19:E19) -> 0 | G19: 40000
A20: AS201649 | B20: =VLOOKUP(A20,[5]LISTADHERENT!A$5:H$60,3,0) -> MBOGNING TUGMA GUY | C20: 215000 | F20: =SUM(C20:E20) -> 215000 | G20: 215000
A21: AS201639 | B21: =VLOOKUP(A21,[5]LISTADHERENT!A$5:H$60,3,0) -> NANGUEN MARTIN | C21: 40000 | F21: =SUM(C21:E21) -> 40000 | G21: 160000
A22: AS201621 | B22: =VLOOKUP(A22,[5]LISTADHERENT!A$5:H$60,3,0) -> NANKAM APPOLINAIRE | C22: 115000 | F22: =SUM(C22:E22) -> 115000 | G22: 115000
A23: AS201622 | B23: =VLOOKUP(A23,[5]LISTADHERENT!A$5:H$60,3,0) -> NDJOMO ETIENNE | C23: 250000 | F23: =SUM(C23:E23) -> 250000 | G23: 40000
A24: AS201624 | B24: =VLOOKUP(A24,[5]LISTADHERENT!A$5:H$60,3,0) -> NGONDIEP CLAUDE | F24: =SUM(C24:E24) -> 0 | G24: 115000
A25: AS201626 | B25: =VLOOKUP(A25,[5]LISTADHERENT!A$5:H$60,3,0) -> NGUIEMEGNI MATHIEU BLAISE | C25: 280000 | F25: =SUM(C25:E25) -> 280000
A26: AS201628 | B26: =VLOOKUP(A26,[5]LISTADHERENT!A$5:H$60,3,0) -> NKAMGANG JUSTIN DEJOLIE | F26: =SUM(C26:E26) -> 0
A27: AS201614 | B27: =VLOOKUP(A27,[5]LISTADHERENT!A$5:H$60,3,0) -> NKEHE DAVID | F27: =SUM(C27:E27) -> 0
A28: AS201629 | B28: =VLOOKUP(A28,[5]LISTADHERENT!A$5:H$60,3,0) -> NKEPSEU DIEUDONNE | F28: =SUM(C28:E28) -> 0
A29: AS201633 | B29: =VLOOKUP(A29,[5]LISTADHERENT!A$5:H$60,3,0) -> PATEGO NJOSSU GUSTAVE | C29: 115000 | F29: =SUM(C29:E29) -> 115000
A30: AS201653 | B30: =VLOOKUP(A30,[5]LISTADHERENT!A$5:H$60,3,0) -> SIME BRICE | F30: =SUM(C30:E30) -> 0
A31: AS201636 | B31: =VLOOKUP(A31,[5]LISTADHERENT!A$5:H$60,3,0) -> SIMO FONGANG ERIC | F31: =SUM(C31:E31) -> 0
A32: AS201638 | B32: =VLOOKUP(A32,[5]LISTADHERENT!A$5:H$60,3,0) -> SIMO PIERRE | C32: 250000 | F32: =SUM(C32:E32) -> 250000
A33: AS201641 | B33: =VLOOKUP(A33,[5]LISTADHERENT!A$5:H$60,3,0) -> TCHOUAMOU MATHIEU | C33: 115000 | F33: =SUM(C33:E33) -> 115000
A34: AS201644 | B34: =VLOOKUP(A34,[5]LISTADHERENT!A$5:H$60,3,0) -> TIEYAM ERNEST | F34: =SUM(C34:E34) -> 0
A35: AS201646 | B35: =VLOOKUP(A35,[5]LISTADHERENT!A$5:H$60,3,0) -> YEPMOU JEAN JACQUES | F35: =SUM(C35:E35) -> 0
A36: AS201647 | B36: =VLOOKUP(A36,[5]LISTADHERENT!A$5:H$60,3,0) -> YOUMBI EMMANUEL | C36: 290000 | F36: =SUM(C36:E36) -> 290000
B38: TOTAUX | C38: =SUM(C7:C37) -> 2955000 | D38: =SUM(D7:D37) -> 0 | E38: =SUM(E7:E37) -> 0 | F38: =SUM(F7:F37) -> 2955000 | G38: =SUM(G7:G37) -> 2955000 | H38: =SUM(H7:H37) -> 0

Sheet HISTOBQUEJANV22
A1: ASSOCIATION | B1: ASELBY
A2: ANNEE | B2: 2022
A3: 1 | B3: 2 | C3: 4 | D3: 5 | E3: 6 | F3: 21
B4: HISTORIQUE BANCAIRE
A5: MATRICULE | B5: NOM ET PRENOM | C5: HISTORIQUE BANQUE | D5: HITORIQUE ESPECES | E5: HITORIQUE TONTINE | F5: MONTANT ENGAGEMENT | G5: VERIFICATION | H5: AGIO
A6: AS201648 | B6: =VLOOKUP(A6,[5]LISTADHERENT!A$5:H$60,3,0) -> ASELBY | C6: 100000 | F6: =SUM(C6:E6) -> 100000 | G6: 30000
A7: AS201602 | B7: =VLOOKUP(A7,[5]LISTADHERENT!A$5:H$60,3,0) -> BOUTCHOUANG WILLIAM | C7: 105000 | F7: =SUM(C7:E7) -> 105000 | G7: 30000
A8: AS201604 | B8: =VLOOKUP(A8,[5]LISTADHERENT!A$5:H$60,3,0) -> DJOMO JEAN PAUL | C8: 150000 | F8: =SUM(C8:E8) -> 150000 | G8: 150000
A9: AS201654 | B9: =VLOOKUP(A9,[5]LISTADHERENT!A$5:H$60,3,0) -> DJOMOU TCHANDA | C9: 30000 | F9: =SUM(C9:E9) -> 30000 | G9: 105000
A10: AS201605 | B10: =VLOOKUP(A10,[5]LISTADHERENT!A$5:H$60,3,0) -> DJOUKWE NANGUEN GUY BLAISE | C10: 35000 | F10: =SUM(C10:E10) -> 35000 | G10: 420000
A11: AS201608 | B11: =VLOOKUP(A11,[5]LISTADHERENT!A$5:H$60,3,0) -> DJUOMBESSY ANTOINE | C11: 205000 | E11: =1029000+61000 -> 1090000 | F11: =SUM(C11:E11) -> 1295000 | G11: 150000
A12: AS201651 | B12: =VLOOKUP(A12,[5]LISTADHERENT!A$5:H$60,3,0) -> DOMOU FABIEN | C12: 35000 | F12: =SUM(C12:E12) -> 35000 | G12: 1029000
A13: AS201609 | B13: =VLOOKUP(A13,[5]LISTADHERENT!A$5:H$60,3,0) -> DONHOU DAVID | C13: 30000 | F13: =SUM(C13:E13) -> 30000 | G13: 120000
A14: AS201610 | B14: =VLOOKUP(A14,[5]LISTADHERENT!A$5:H$60,3,0) -> FOTSO THOMAS | F14: =SUM(C14:E14) -> 0 | G14: 330000
A15: AS201611 | B15: =VLOOKUP(A15,[5]LISTADHERENT!A$5:H$60,3,0) -> HENGUE PAUL OMER | C15: 105000 | F15: =SUM(C15:E15) -> 105000 | G15: 210000
A16: AS201613 | B16: =VLOOKUP(A16,[5]LISTADHERENT!A$5:H$60,3,0) -> HOTCHO BENJAMIN | C16: 150000 | F16: =SUM(C16:E16) -> 150000 | G16: 105000
A17: AS201617 | B17: =VLOOKUP(A17,[5]LISTADHERENT!A$5:H$60,3,0) -> KOUAMOU MOISE | C17: 330000 | F17: =SUM(C17:E17) -> 330000 | G17: 105000
A18: AS201619 | B18: =VLOOKUP(A18,[5]LISTADHERENT!A$5:H$60,3,0) -> KOUATCHO MESSACK | C18: 411000 | F18: =SUM(C18:E18) -> 411000 | G18: 105000
A19: AS201620 | B19: =VLOOKUP(A19,[5]LISTADHERENT!A$5:H$60,3,0) -> LOWE JEAN | C19: 30000 | F19: =SUM(C19:E19) -> 30000 | G19: 280000
A20: AS201649 | B20: =VLOOKUP(A20,[5]LISTADHERENT!A$5:H$60,3,0) -> MBOGNING TUGMA GUY | C20: 455000 | F20: =SUM(C20:E20) -> 455000 | G20: 35000
A21: AS201639 | B21: =VLOOKUP(A21,[5]LISTADHERENT!A$5:H$60,3,0) -> NANGUEN MARTIN | C21: 30000 | F21: =SUM(C21:E21) -> 30000 | G21: 140000
A22: AS201621 | B22: =VLOOKUP(A22,[5]LISTADHERENT!A$5:H$60,3,0) -> NANKAM APPOLINAIRE | C22: 1029000 | F22: =SUM(C22:E22) -> 1029000 | G22: 105000
A23: AS201622 | B23: =VLOOKUP(A23,[5]LISTADHERENT!A$5:H$60,3,0) -> NDJOMO ETIENNE | C23: 140000 | F23: =SUM(C23:E23) -> 140000 | G23: 455000
A24: AS201624 | B24: =VLOOKUP(A24,[5]LISTADHERENT!A$5:H$60,3,0) -> NGONDIEP CLAUDE | C24: 210000 | F24: =SUM(C24:E24) -> 210000 | G24: 205000
A25: AS201626 | B25: =VLOOKUP(A25,[5]LISTADHERENT!A$5:H$60,3,0) -> NGUIEMEGNI MATHIEU BLAISE | C25: =420000-140000 -> 280000 | F25: =SUM(C25:E25) -> 280000 | G25: 40000
A26: AS201628 | B26: =VLOOKUP(A26,[5]LISTADHERENT!A$5:H$60,3,0) -> NKAMGANG JUSTIN DEJOLIE | C26: 105000 | D26: 29500 | F26: =SUM(C26:E26) -> 134500 | G26: 30000
A27: AS201614 | B27: =VLOOKUP(A27,[5]LISTADHERENT!A$5:H$60,3,0) -> NKEHE DAVID | C27: 30000 | F27: =SUM(C27:E27) -> 30000 | G27: 60000
A28: AS201629 | B28: =VLOOKUP(A28,[5]LISTADHERENT!A$5:H$60,3,0) -> NKEPSEU DIEUDONNE | C28: 140000 | F28: =SUM(C28:E28) -> 140000 | G28: 35000
A29: AS201633 | B29: =VLOOKUP(A29,[5]LISTADHERENT!A$5:H$60,3,0) -> PATEGO NJOSSU GUSTAVE | C29: 105000 | F29: =SUM(C29:E29) -> 105000 | G29: 411000
A30: AS201653 | B30: =VLOOKUP(A30,[5]LISTADHERENT!A$5:H$60,3,0) -> SIME BRICE | C30: 105000 | F30: =SUM(C30:E30) -> 105000 | G30: 105000
A31: AS201636 | B31: =VLOOKUP(A31,[5]LISTADHERENT!A$5:H$60,3,0) -> SIMO FONGANG ERIC | F31: =SUM(C31:E31) -> 0 | G31: 30000
A32: AS201638 | B32: =VLOOKUP(A32,[5]LISTADHERENT!A$5:H$60,3,0) -> SIMO PIERRE | C32: 120000 | F32: =SUM(C32:E32) -> 120000 | G32: 30000
A33: AS201641 | B33: =VLOOKUP(A33,[5]LISTADHERENT!A$5:H$60,3,0) -> TCHOUAMOU MATHIEU | C33: 105000 | F33: =SUM(C33:E33) -> 105000
A34: AS201644 | B34: =VLOOKUP(A34,[5]LISTADHERENT!A$5:H$60,3,0) -> TIEYAM ERNEST | C34: 30000 | F34: =SUM(C34:E34) -> 30000
A35: AS201646 | B35: =VLOOKUP(A35,[5]LISTADHERENT!A$5:H$60,3,0) -> YEPMOU JEAN JACQUES | D35: 33000 | F35: =SUM(C35:E35) -> 33000
A36: AS201647 | B36: =VLOOKUP(A36,[5]LISTADHERENT!A$5:H$60,3,0) -> YOUMBI EMMANUEL | C36: 280000 | F36: =SUM(C36:E36) -> 280000
B38: TOTAUX | C38: =SUM(C7:C37) -> 4780000 | D38: =SUM(D7:D37) -> 62500 | E38: =SUM(E7:E37) -> 1090000 | F38: =SUM(F7:F37) -> 5932500 | G38: =SUM(G7:G37) -> 4820000 | H38: =SUM(H7:H37) -> 0

Sheet HISTOBQUEFEV22
A1: ASSOCIATION | B1: ASELBY
A2: ANNEE | B2: 2022
A3: 1 | B3: 2 | C3: 4 | D3: 5 | E3: 6 | F3: 21
B4: HISTORIQUE BANCAIRE
A5: MATRICULE | B5: NOM ET PRENOM | C5: HISTORIQUE BANQUE | D5: HITORIQUE ESPECES | E5: HITORIQUE TONTINE | F5: MONTANT ENGAGEMENT | G5: VERIFICATION | H5: AGIO
A6: AS201648 | B6: =VLOOKUP(A6,[5]LISTADHERENT!A$5:H$60,3,0) -> ASELBY | C6: 100000 | F6: =SUM(C6:E6) -> 100000 | G6: 30000
A7: AS201602 | B7: =VLOOKUP(A7,[5]LISTADHERENT!A$5:H$60,3,0) -> BOUTCHOUANG WILLIAM | C7: 105000 | F7: =SUM(C7:E7) -> 105000 | G7: 30000
A8: AS201604 | B8: =VLOOKUP(A8,[5]LISTADHERENT!A$5:H$60,3,0) -> DJOMO JEAN PAUL | C8: =25000 -> 25000 | D8: 135000 | F8: =SUM(C8:E8) -> 160000 | G8: 150000
A9: AS201654 | B9: =VLOOKUP(A9,[5]LISTADHERENT!A$5:H$60,3,0) -> DJOMOU TCHANDA | C9: 30000 | F9: =SUM(C9:E9) -> 30000 | G9: 105000
A10: AS201605 | B10: =VLOOKUP(A10,[5]LISTADHERENT!A$5:H$60,3,0) -> DJOUKWE NANGUEN GUY BLAISE | C10: 60000 | F10: =SUM(C10:E10) -> 60000 | G10: 420000
A11: AS201608 | B11: =VLOOKUP(A11,[5]LISTADHERENT!A$5:H$60,3,0) -> DJUOMBESSY ANTOINE | C11: 205000 | F11: =SUM(C11:E11) -> 205000 | G11: 150000
A12: AS201651 | B12: =VLOOKUP(A12,[5]LISTADHERENT!A$5:H$60,3,0) -> DOMOU FABIEN | C12: 35000 | F12: =SUM(C12:E12) -> 35000 | G12: 1029000
A13: AS201609 | B13: =VLOOKUP(A13,[5]LISTADHERENT!A$5:H$60,3,0) -> DONHOU DAVID | C13: 35000 | F13: =SUM(C13:E13) -> 35000 | G13: 120000
A14: AS201610 | B14: =VLOOKUP(A14,[5]LISTADHERENT!A$5:H$60,3,0) -> FOTSO THOMAS | F14: =SUM(C14:E14) -> 0 | G14: 330000
A15: AS201611 | B15: =VLOOKUP(A15,[5]LISTADHERENT!A$5:H$60,3,0) -> HENGUE PAUL OMER | C15: 105000 | F15: =SUM(C15:E15) -> 105000 | G15: 210000
A16: AS201613 | B16: =VLOOKUP(A16,[5]LISTADHERENT!A$5:H$60,3,0) -> HOTCHO BENJAMIN | C16: 150000 | F16: =SUM(C16:E16) -> 150000 | G16: 105000
A17: AS201617 | B17: =VLOOKUP(A17,[5]LISTADHERENT!A$5:H$60,3,0) -> KOUAMOU MOISE | C17: 330000 | F17: =SUM(C17:E17) -> 330000 | G17: 105000
A18: AS201619 | B18: =VLOOKUP(A18,[5]LISTADHERENT!A$5:H$60,3,0) -> KOUATCHO MESSACK | C18: 293500 | D18: =101000+148000 -> 249000 | F18: =SUM(C18:E18) -> 542500 | G18: 105000
A19: AS201620 | B19: =VLOOKUP(A19,[5]LISTADHERENT!A$5:H$60,3,0) -> LOWE JEAN | C19: 30000 | F19: =SUM(C19:E19) -> 30000 | G19: 280000
A20: AS201649 | B20: =VLOOKUP(A20,[5]LISTADHERENT!A$5:H$60,3,0) -> MBOGNING TUGMA GUY | C20: 557000 | E20: =1155000+595000 -> 1750000 | F20: =SUM(C20:E20) -> 2307000 | G20: 35000
A21: AS201639 | B21: =VLOOKUP(A21,[5]LISTADHERENT!A$5:H$60,3,0) -> NANGUEN MARTIN | C21: 30000 | F21: =SUM(C21:E21) -> 30000 | G21: 140000
A22: AS201621 | B22: =VLOOKUP(A22,[5]LISTADHERENT!A$5:H$60,3,0) -> NANKAM APPOLINAIRE | C22: 105000 | E22: 71000 | F22: =SUM(C22:E22) -> 176000 | G22: 105000
A23: AS201622 | B23: =VLOOKUP(A23,[5]LISTADHERENT!A$5:H$60,3,0) -> NDJOMO ETIENNE | C23: 150000 | F23: =SUM(C23:E23) -> 150000 | G23: 455000
A24: AS201624 | B24: =VLOOKUP(A24,[5]LISTADHERENT!A$5:H$60,3,0) -> NGONDIEP CLAUDE | C24: 220000 | F24: =SUM(C24:E24) -> 220000 | G24: 205000
A25: AS201626 | B25: =VLOOKUP(A25,[5]LISTADHERENT!A$5:H$60,3,0) -> NGUIEMEGNI MATHIEU BLAISE | C25: 180000 | F25: =SUM(C25:E25) -> 180000 | G25: 40000
A26: AS201628 | B26: =VLOOKUP(A26,[5]LISTADHERENT!A$5:H$60,3,0) -> NKAMGANG JUSTIN DEJOLIE | C26: 105000 | F26: =SUM(C26:E26) -> 105000 | G26: 30000
A27: AS201614 | B27: =VLOOKUP(A27,[5]LISTADHERENT!A$5:H$60,3,0) -> NKEHE DAVID | F27: =SUM(C27:E27) -> 0 | G27: 60000
A28: AS201629 | B28: =VLOOKUP(A28,[5]LISTADHERENT!A$5:H$60,3,0) -> NKEPSEU DIEUDONNE | C28: 130000 | F28: =SUM(C28:E28) -> 130000 | G28: 35000
A29: AS201633 | B29: =VLOOKUP(A29,[5]LISTADHERENT!A$5:H$60,3,0) -> PATEGO NJOSSU GUSTAVE | C29: 105000 | F29: =SUM(C29:E29) -> 105000 | G29: 411000
A30: AS201653 | B30: =VLOOKUP(A30,[5]LISTADHERENT!A$5:H$60,3,0) -> SIME BRICE | C30: 105000 | F30: =SUM(C30:E30) -> 105000 | G30: 105000
A31: AS201636 | B31: =VLOOKUP(A31,[5]LISTADHERENT!A$5:H$60,3,0) -> SIMO FONGANG ERIC | F31: =SUM(C31:E31) -> 0 | G31: 30000
A32: AS201638 | B32: =VLOOKUP(A32,[5]LISTADHERENT!A$5:H$60,3,0) -> SIMO PIERRE | C32: 130000 | F32: =SUM(C32:E32) -> 130000 | G32: 30000
A33: AS201641 | B33: =VLOOKUP(A33,[5]LISTADHERENT!A$5:H$60,3,0) -> TCHOUAMOU MATHIEU | C33: 156000 | F33: =SUM(C33:E33) -> 156000
A34: AS201644 | B34: =VLOOKUP(A34,[5]LISTADHERENT!A$5:H$60,3,0) -> TIEYAM ERNEST | F34: =SUM(C34:E34) -> 0
A35: AS201646 | B35: =VLOOKUP(A35,[5]LISTADHERENT!A$5:H$60,3,0) -> YEPMOU JEAN JACQUES | C35: 30000 | F35: =SUM(C35:E35) -> 30000
A36: AS201647 | B36: =VLOOKUP(A36,[5]LISTADHERENT!A$5:H$60,3,0) -> YOUMBI EMMANUEL | C36: 280000 | F36: =SUM(C36:E36) -> 280000
B38: TOTAUX | C38: =SUM(C7:C37) -> 3686500 | D38: =SUM(D7:D37) -> 384000 | E38: =SUM(E7:E37) -> 1821000 | F38: =SUM(F7:F37) -> 5891500 | G38: =SUM(G7:G37) -> 4820000 | H38: =SUM(H7:H37) -> 0

Sheet HISTOBQUEMARS22
A1: ASSOCIATION | B1: ASELBY
A2: ANNEE | B2: 2022
A3: 1 | B3: 2 | C3: 4 | D3: 5 | E3: 6 | F3: 21
B4: HISTORIQUE BANCAIRE
A5: MATRICULE | B5: NOM ET PRENOM | C5: HISTORIQUE BANQUE | D5: HITORIQUE ESPECES | E5: HITORIQUE TONTINE | F5: MONTANT ENGAGEMENT | G5: VERIFICATION | H5: AGIO
A6: AS201648 | B6: =VLOOKUP(A6,[5]LISTADHERENT!A$5:H$60,3,0) -> ASELBY | C6: 100000 | F6: =SUM(C6:E6) -> 100000
A7: AS201602 | B7: =VLOOKUP(A7,[5]LISTADHERENT!A$5:H$60,3,0) -> BOUTCHOUANG WILLIAM | C7: 105000 | F7: =SUM(C7:E7) -> 105000
A8: AS201604 | B8: =VLOOKUP(A8,[5]LISTADHERENT!A$5:H$60,3,0) -> DJOMO JEAN PAUL | D8: =105000+3000 -> 108000 | F8: =SUM(C8:E8) -> 108000
A9: AS201654 | B9: =VLOOKUP(A9,[5]LISTADHERENT!A$5:H$60,3,0) -> DJOMOU TCHANDA | D9: =30000+3000 -> 33000 | F9: =SUM(C9:E9) -> 33000
A10: AS201605 | B10: =VLOOKUP(A10,[5]LISTADHERENT!A$5:H$60,3,0) -> DJOUKWE NANGUEN GUY BLAISE | C10: 81000 | F10: =SUM(C10:E10) -> 81000
A11: AS201608 | B11: =VLOOKUP(A11,[5]LISTADHERENT!A$5:H$60,3,0) -> DJUOMBESSY ANTOINE | C11: 205000 | F11: =SUM(C11:E11) -> 205000
A12: AS201651 | B12: =VLOOKUP(A12,[5]LISTADHERENT!A$5:H$60,3,0) -> DOMOU FABIEN | C12: 35000 | F12: =SUM(C12:E12) -> 35000
A13: AS201609 | B13: =VLOOKUP(A13,[5]LISTADHERENT!A$5:H$60,3,0) -> DONHOU DAVID | D13: =30000+3000 -> 33000 | F13: =SUM(C13:E13) -> 33000
A14: AS201610 | B14: =VLOOKUP(A14,[5]LISTADHERENT!A$5:H$60,3,0) -> FOTSO THOMAS | F14: =SUM(C14:E14) -> 0
A15: AS201611 | B15: =VLOOKUP(A15,[5]LISTADHERENT!A$5:H$60,3,0) -> HENGUE PAUL OMER | C15: 105000 | F15: =SUM(C15:E15) -> 105000
A16: AS201613 | B16: =VLOOKUP(A16,[5]LISTADHERENT!A$5:H$60,3,0) -> HOTCHO BENJAMIN | C16: 150000 | F16: =SUM(C16:E16) -> 150000
A17: AS201617 | B17: =VLOOKUP(A17,[5]LISTADHERENT!A$5:H$60,3,0) -> KOUAMOU MOISE | C17: 330000 | F17: =SUM(C17:E17) -> 330000
A18: AS201619 | B18: =VLOOKUP(A18,[5]LISTADHERENT!A$5:H$60,3,0) -> KOUATCHO MESSACK | C18: 205000 | F18: =SUM(C18:E18) -> 205000 | G18: 150000
A19: AS201620 | B19: =VLOOKUP(A19,[5]LISTADHERENT!A$5:H$60,3,0) -> LOWE JEAN | C19: =30000+500000 -> 530000 | F19: =SUM(C19:E19) -> 530000 | G19: 30000
A20: AS201649 | B20: =VLOOKUP(A20,[5]LISTADHERENT!A$5:H$60,3,0) -> MBOGNING TUGMA GUY | C20: 455000 | F20: =SUM(C20:E20) -> 455000 | G20: 81000
A21: AS201639 | B21: =VLOOKUP(A21,[5]LISTADHERENT!A$5:H$60,3,0) -> NANGUEN MARTIN | C21: 30000 | F21: =SUM(C21:E21) -> 30000 | G21: 105000
A22: AS201621 | B22: =VLOOKUP(A22,[5]LISTADHERENT!A$5:H$60,3,0) -> NANKAM APPOLINAIRE | C22: 105000 | F22: =SUM(C22:E22) -> 105000 | G22: 340000
A23: AS201622 | B23: =VLOOKUP(A23,[5]LISTADHERENT!A$5:H$60,3,0) -> NDJOMO ETIENNE | C23: 150000 | F23: =SUM(C23:E23) -> 150000 | G23: 330000
A24: AS201624 | B24: =VLOOKUP(A24,[5]LISTADHERENT!A$5:H$60,3,0) -> NGONDIEP CLAUDE | C24: 205000 | F24: =SUM(C24:E24) -> 205000 | G24: 105000
A25: AS201626 | B25: =VLOOKUP(A25,[5]LISTADHERENT!A$5:H$60,3,0) -> NGUIEMEGNI MATHIEU BLAISE | C25: 340000 | F25: =SUM(C25:E25) -> 340000 | G25: 180000
A26: AS201628 | B26: =VLOOKUP(A26,[5]LISTADHERENT!A$5:H$60,3,0) -> NKAMGANG JUSTIN DEJOLIE | C26: 105000 | F26: =SUM(C26:E26) -> 105000 | G26: 105000
A27: AS201614 | B27: =VLOOKUP(A27,[5]LISTADHERENT!A$5:H$60,3,0) -> NKEHE DAVID | F27: =SUM(C27:E27) -> 0 | G27: 150000
A28: AS201629 | B28: =VLOOKUP(A28,[5]LISTADHERENT!A$5:H$60,3,0) -> NKEPSEU DIEUDONNE | C28: 180000 | F28: =SUM(C28:E28) -> 180000 | G28: 280000
A29: AS201633 | B29: =VLOOKUP(A29,[5]LISTADHERENT!A$5:H$60,3,0) -> PATEGO NJOSSU GUSTAVE | C29: 105000 | F29: =SUM(C29:E29) -> 105000 | G29: 205000
A30: AS201653 | B30: =VLOOKUP(A30,[5]LISTADHERENT!A$5:H$60,3,0) -> SIME BRICE | D30: =105000+3000 -> 108000 | F30: =SUM(C30:E30) -> 108000 | G30: 105000
A31: AS201636 | B31: =VLOOKUP(A31,[5]LISTADHERENT!A$5:H$60,3,0) -> SIMO FONGANG ERIC | F31: =SUM(C31:E31) -> 0 | G31: 455000
A32: AS201638 | B32: =VLOOKUP(A32,[5]LISTADHERENT!A$5:H$60,3,0) -> SIMO PIERRE | C32: 150000 | F32: =SUM(C32:E32) -> 150000 | G32: 205000
A33: AS201641 | B33: =VLOOKUP(A33,[5]LISTADHERENT!A$5:H$60,3,0) -> TCHOUAMOU MATHIEU | C33: 105000 | F33: =SUM(C33:E33) -> 105000 | G33: 150000
A34: AS201644 | B34: =VLOOKUP(A34,[5]LISTADHERENT!A$5:H$60,3,0) -> TIEYAM ERNEST | F34: =SUM(C34:E34) -> 0 | G34: 105000
A35: AS201646 | B35: =VLOOKUP(A35,[5]LISTADHERENT!A$5:H$60,3,0) -> YEPMOU JEAN JACQUES | C35: 30000 | F35: =SUM(C35:E35) -> 30000 | G35: 105000
A36: AS201647 | B36: =VLOOKUP(A36,[5]LISTADHERENT!A$5:H$60,3,0) -> YOUMBI EMMANUEL | C36: 280000 | F36: =SUM(C36:E36) -> 280000
B38: TOTAUX | C38: =SUM(C7:C37) -> 3986000 | D38: =SUM(D7:D37) -> 282000 | E38: =SUM(E7:E37) -> 0 | F38: =SUM(F7:F37) -> 4268000 | G38: =SUM(G7:G37) -> 3186000 | H38: =SUM(H7:H37) -> 0

Sheet HISTOBQUEAVRIL22
A1: ASSOCIATION | B1: ASELBY
A2: ANNEE | B2: 2022
A3: 1 | B3: 2 | C3: 4 | D3: 5 | E3: 6 | F3: 21
B4: HISTORIQUE BANCAIRE
A5: MATRICULE | B5: NOM ET PRENOM | C5: HISTORIQUE BANQUE | D5: HITORIQUE ESPECES | E5: HITORIQUE TONTINE | F5: MONTANT ENGAGEMENT | G5: VERIFICATION | H5: AGIO
A6: AS201648 | B6: =VLOOKUP(A6,[5]LISTADHERENT!A$5:H$60,3,0) -> ASELBY | C6: 100000 | F6: =SUM(C6:E6) -> 100000
A7: AS201602 | B7: =VLOOKUP(A7,[5]LISTADHERENT!A$5:H$60,3,0) -> BOUTCHOUANG WILLIAM | C7: 105000 | F7: =SUM(C7:E7) -> 105000 | G7: 430000
A8: AS201604 | B8: =VLOOKUP(A8,[5]LISTADHERENT!A$5:H$60,3,0) -> DJOMO JEAN PAUL | C8: 132000 | F8: =SUM(C8:E8) -> 132000 | G8: 105000
A9: AS201654 | B9: =VLOOKUP(A9,[5]LISTADHERENT!A$5:H$60,3,0) -> DJOMOU TCHANDA | C9: 35000 | F9: =SUM(C9:E9) -> 35000 | G9: 30000
A10: AS201605 | B10: =VLOOKUP(A10,[5]LISTADHERENT!A$5:H$60,3,0) -> DJOUKWE NANGUEN GUY BLAISE | C10: 81000 | F10: =SUM(C10:E10) -> 81000 | G10: 81000
A11: AS201608 | B11: =VLOOKUP(A11,[5]LISTADHERENT!A$5:H$60,3,0) -> DJUOMBESSY ANTOINE | C11: 105000 | D11: 100000 | F11: =SUM(C11:E11) -> 205000 | G11: 241000
A12: AS201651 | B12: =VLOOKUP(A12,[5]LISTADHERENT!A$5:H$60,3,0) -> DOMOU FABIEN | C12: 35000 | F12: =SUM(C12:E12) -> 35000 | G12: 105000
A13: AS201609 | B13: =VLOOKUP(A13,[5]LISTADHERENT!A$5:H$60,3,0) -> DONHOU DAVID | C13: 35000 | F13: =SUM(C13:E13) -> 35000 | G13: 280000
A14: AS201610 | B14: =VLOOKUP(A14,[5]LISTADHERENT!A$5:H$60,3,0) -> FOTSO THOMAS | F14: =SUM(C14:E14) -> 0 | G14: 105000
A15: AS201611 | B15: =VLOOKUP(A15,[5]LISTADHERENT!A$5:H$60,3,0) -> HENGUE PAUL OMER | C15: 105000 | F15: =SUM(C15:E15) -> 105000
A16: AS201613 | B16: =VLOOKUP(A16,[5]LISTADHERENT!A$5:H$60,3,0) -> HOTCHO BENJAMIN | C16: 150000 | F16: =SUM(C16:E16) -> 150000 | G16: 455000
A17: AS201617 | B17: =VLOOKUP(A17,[5]LISTADHERENT!A$5:H$60,3,0) -> KOUAMOU MOISE | C17: 430000 | F17: =SUM(C17:E17) -> 430000 | G17: 105000
A18: AS201619 | B18: =VLOOKUP(A18,[5]LISTADHERENT!A$5:H$60,3,0) -> KOUATCHO MESSACK | C18: 410000 | F18: =SUM(C18:E18) -> 410000 | G18: 35000
A19: AS201620 | B19: =VLOOKUP(A19,[5]LISTADHERENT!A$5:H$60,3,0) -> LOWE JEAN | C19: 30000 | F19: =SUM(C19:E19) -> 30000 | G19: 150000
A20: AS201649 | B20: =VLOOKUP(A20,[5]LISTADHERENT!A$5:H$60,3,0) -> MBOGNING TUGMA GUY | C20: 455000 | F20: =SUM(C20:E20) -> 455000 | G20: 105000
A21: AS201639 | B21: =VLOOKUP(A21,[5]LISTADHERENT!A$5:H$60,3,0) -> NANGUEN MARTIN | C21: 30000 | F21: =SUM(C21:E21) -> 30000 | G21: 132000
A22: AS201621 | B22: =VLOOKUP(A22,[5]LISTADHERENT!A$5:H$60,3,0) -> NANKAM APPOLINAIRE | C22: 105000 | F22: =SUM(C22:E22) -> 105000
A23: AS201622 | B23: =VLOOKUP(A23,[5]LISTADHERENT!A$5:H$60,3,0) -> NDJOMO ETIENNE | C23: 150000 | F23: =SUM(C23:E23) -> 150000 | G23: 161000
A24: AS201624 | B24: =VLOOKUP(A24,[5]LISTADHERENT!A$5:H$60,3,0) -> NGONDIEP CLAUDE | C24: 315000 | F24: =SUM(C24:E24) -> 315000 | G24: 105000
A25: AS201626 | B25: =VLOOKUP(A25,[5]LISTADHERENT!A$5:H$60,3,0) -> NGUIEMEGNI MATHIEU BLAISE | C25: 280000 | F25: =SUM(C25:E25) -> 280000 | G25: 280000
A26: AS201628 | B26: =VLOOKUP(A26,[5]LISTADHERENT!A$5:H$60,3,0) -> NKAMGANG JUSTIN DEJOLIE | C26: 105000 | F26: =SUM(C26:E26) -> 105000 | G26: 105000
A27: AS201614 | B27: =VLOOKUP(A27,[5]LISTADHERENT!A$5:H$60,3,0) -> NKEHE DAVID | F27: =SUM(C27:E27) -> 0 | G27: 35000
A28: AS201629 | B28: =VLOOKUP(A28,[5]LISTADHERENT!A$5:H$60,3,0) -> NKEPSEU DIEUDONNE | C28: 241000 | F28: =SUM(C28:E28) -> 241000 | G28: 410000
A29: AS201633 | B29: =VLOOKUP(A29,[5]LISTADHERENT!A$5:H$60,3,0) -> PATEGO NJOSSU GUSTAVE | C29: 105000 | F29: =SUM(C29:E29) -> 105000 | G29: 105000
A30: AS201653 | B30: =VLOOKUP(A30,[5]LISTADHERENT!A$5:H$60,3,0) -> SIME BRICE | C30: 105000 | F30: =SUM(C30:E30) -> 105000 | G30: 35000
A31: AS201636 | B31: =VLOOKUP(A31,[5]LISTADHERENT!A$5:H$60,3,0) -> SIMO FONGANG ERIC | F31: =SUM(C31:E31) -> 0 | G31: 30000
A32: AS201638 | B32: =VLOOKUP(A32,[5]LISTADHERENT!A$5:H$60,3,0) -> SIMO PIERRE | C32: 261000 | F32: =SUM(C32:E32) -> 261000 | G32: 315000
A33: AS201641 | B33: =VLOOKUP(A33,[5]LISTADHERENT!A$5:H$60,3,0) -> TCHOUAMOU MATHIEU | C33: 105000 | F33: =SUM(C33:E33) -> 105000 | G33: 150000
A34: AS201644 | B34: =VLOOKUP(A34,[5]LISTADHERENT!A$5:H$60,3,0) -> TIEYAM ERNEST | F34: =SUM(C34:E34) -> 0
A35: AS201646 | B35: =VLOOKUP(A35,[5]LISTADHERENT!A$5:H$60,3,0) -> YEPMOU JEAN JACQUES | D35: 30000 | F35: =SUM(C35:E35) -> 30000
A36: AS201647 | B36: =VLOOKUP(A36,[5]LISTADHERENT!A$5:H$60,3,0) -> YOUMBI EMMANUEL | C36: 280000 | F36: =SUM(C36:E36) -> 280000
B38: TOTAUX | C38: =SUM(C7:C37) -> 4190000 | D38: =SUM(D7:D37) -> 130000 | E38: =SUM(E7:E37) -> 0 | F38: =SUM(F7:F37) -> 4320000 | G38: =SUM(G7:G37) -> 4090000 | H38: =SUM(H7:H37) -> 0
D40: =+C38-G38 -> 100000

Sheet HISTOBQUEMAI22
A1: ASSOCIATION | B1: ASELBY
A2: ANNEE | B2: 2022
A3: 1 | B3: 2 | C3: 4 | D3: 5 | E3: 6 | F3: 21
B4: HISTORIQUE BANCAIRE
A5: MATRICULE | B5: NOM ET PRENOM | C5: HISTORIQUE BANQUE | D5: HITORIQUE ESPECES | E5: HITORIQUE TONTINE | F5: MONTANT ENGAGEMENT | G5: VERIFICATION | H5: AGIO
A6: AS201648 | B6: =VLOOKUP(A6,[5]LISTADHERENT!A$5:H$60,3,0) -> ASELBY | C6: 100000 | F6: =SUM(C6:E6) -> 100000
A7: AS201602 | B7: =VLOOKUP(A7,[5]LISTADHERENT!A$5:H$60,3,0) -> BOUTCHOUANG WILLIAM | D7: 105000 | F7: =SUM(C7:E7) -> 105000 | G7: 105000
A8: AS201604 | B8: =VLOOKUP(A8,[5]LISTADHERENT!A$5:H$60,3,0) -> DJOMO JEAN PAUL | C8: 120000 | F8: =SUM(C8:E8) -> 120000 | G8: 150000
A9: AS201654 | B9: =VLOOKUP(A9,[5]LISTADHERENT!A$5:H$60,3,0) -> DJOMOU TCHANDA | C9: 30000 | F9: =SUM(C9:E9) -> 30000 | G9: 150000
A10: AS201605 | B10: =VLOOKUP(A10,[5]LISTADHERENT!A$5:H$60,3,0) -> DJOUKWE NANGUEN GUY BLAISE | C10: 30000 | F10: =SUM(C10:E10) -> 30000 | G10: 210000
A11: AS201608 | B11: =VLOOKUP(A11,[5]LISTADHERENT!A$5:H$60,3,0) -> DJUOMBESSY ANTOINE | C11: 205000 | F11: =SUM(C11:E11) -> 205000 | G11: 341000
A12: AS201651 | B12: =VLOOKUP(A12,[5]LISTADHERENT!A$5:H$60,3,0) -> DOMOU FABIEN | C12: 35000 | F12: =SUM(C12:E12) -> 35000 | G12: 280000
A13: AS201609 | B13: =VLOOKUP(A13,[5]LISTADHERENT!A$5:H$60,3,0) -> DONHOU DAVID | C13: 35000 | F13: =SUM(C13:E13) -> 35000 | G13: 35000
A14: AS201610 | B14: =VLOOKUP(A14,[5]LISTADHERENT!A$5:H$60,3,0) -> FOTSO THOMAS | F14: =SUM(C14:E14) -> 0 | G14: 30000
A15: AS201611 | B15: =VLOOKUP(A15,[5]LISTADHERENT!A$5:H$60,3,0) -> HENGUE PAUL OMER | C15: 105000 | F15: =SUM(C15:E15) -> 105000 | G15: 105000
A16: AS201613 | B16: =VLOOKUP(A16,[5]LISTADHERENT!A$5:H$60,3,0) -> HOTCHO BENJAMIN | C16: 150000 | F16: =SUM(C16:E16) -> 150000 | G16: 105000
A17: AS201617 | B17: =VLOOKUP(A17,[5]LISTADHERENT!A$5:H$60,3,0) -> KOUAMOU MOISE | C17: 330000 | F17: =SUM(C17:E17) -> 330000 | G17: 205000
A18: AS201619 | B18: =VLOOKUP(A18,[5]LISTADHERENT!A$5:H$60,3,0) -> KOUATCHO MESSACK | C18: 205000 | F18: =SUM(C18:E18) -> 205000 | G18: 205000
A19: AS201620 | B19: =VLOOKUP(A19,[5]LISTADHERENT!A$5:H$60,3,0) -> LOWE JEAN | C19: 30000 | F19: =SUM(C19:E19) -> 30000 | G19: 330000
A20: AS201649 | B20: =VLOOKUP(A20,[5]LISTADHERENT!A$5:H$60,3,0) -> MBOGNING TUGMA GUY | C20: =556000+50500 -> 606500 | F20: =SUM(C20:E20) -> 606500 | G20: 35000
A21: AS201639 | B21: =VLOOKUP(A21,[5]LISTADHERENT!A$5:H$60,3,0) -> NANGUEN MARTIN | C21: 30000 | F21: =SUM(C21:E21) -> 30000 | G21: 105000
A22: AS201621 | B22: =VLOOKUP(A22,[5]LISTADHERENT!A$5:H$60,3,0) -> NANKAM APPOLINAIRE | C22: 105000 | E22: 1000000 | F22: =SUM(C22:E22) -> 1105000 | G22: 30000
A23: AS201622 | B23: =VLOOKUP(A23,[5]LISTADHERENT!A$5:H$60,3,0) -> NDJOMO ETIENNE | C23: 150000 | F23: =SUM(C23:E23) -> 150000 | G23: =556000+50500 -> 606500
A24: AS201624 | B24: =VLOOKUP(A24,[5]LISTADHERENT!A$5:H$60,3,0) -> NGONDIEP CLAUDE | D24: 205000 | F24: =SUM(C24:E24) -> 205000 | G24: 30000
A25: AS201626 | B25: =VLOOKUP(A25,[5]LISTADHERENT!A$5:H$60,3,0) -> NGUIEMEGNI MATHIEU BLAISE | C25: =400000+80000 -> 480000 | F25: =SUM(C25:E25) -> 480000 | G25: 120000
A26: AS201628 | B26: =VLOOKUP(A26,[5]LISTADHERENT!A$5:H$60,3,0) -> NKAMGANG JUSTIN DEJOLIE | C26: 105000 | F26: =SUM(C26:E26) -> 105000
A27: AS201614 | B27: =VLOOKUP(A27,[5]LISTADHERENT!A$5:H$60,3,0) -> NKEHE DAVID | F27: =SUM(C27:E27) -> 0 | G27: 105000
A28: AS201629 | B28: =VLOOKUP(A28,[5]LISTADHERENT!A$5:H$60,3,0) -> NKEPSEU DIEUDONNE | C28: 341000 | F28: =SUM(C28:E28) -> 341000 | G28: 30000
A29: AS201633 | B29: =VLOOKUP(A29,[5]LISTADHERENT!A$5:H$60,3,0) -> PATEGO NJOSSU GUSTAVE | C29: 105000 | F29: =SUM(C29:E29) -> 105000 | G29: 30000
A30: AS201653 | B30: =VLOOKUP(A30,[5]LISTADHERENT!A$5:H$60,3,0) -> SIME BRICE | D30: 105000 | F30: =SUM(C30:E30) -> 105000
A31: AS201636 | B31: =VLOOKUP(A31,[5]LISTADHERENT!A$5:H$60,3,0) -> SIMO FONGANG ERIC | F31: =SUM(C31:E31) -> 0
A32: AS201638 | B32: =VLOOKUP(A32,[5]LISTADHERENT!A$5:H$60,3,0) -> SIMO PIERRE | C32: 210000 | F32: =SUM(C32:E32) -> 210000
A33: AS201641 | B33: =VLOOKUP(A33,[5]LISTADHERENT!A$5:H$60,3,0) -> TCHOUAMOU MATHIEU | C33: 105000 | F33: =SUM(C33:E33) -> 105000 | G33: 480000
A34: AS201644 | B34: =VLOOKUP(A34,[5]LISTADHERENT!A$5:H$60,3,0) -> TIEYAM ERNEST | F34: =SUM(C34:E34) -> 0
A35: AS201646 | B35: =VLOOKUP(A35,[5]LISTADHERENT!A$5:H$60,3,0) -> YEPMOU JEAN JACQUES | C35: 30000 | F35: =SUM(C35:E35) -> 30000
A36: AS201647 | B36: =VLOOKUP(A36,[5]LISTADHERENT!A$5:H$60,3,0) -> YOUMBI EMMANUEL | C36: 280000 | F36: =SUM(C36:E36) -> 280000
B38: TOTAUX | C38: =SUM(C7:C37) -> 3822500 | D38: =SUM(D7:D37) -> 415000 | E38: =SUM(E7:E37) -> 1000000 | F38: =SUM(F7:F37) -> 5237500 | G38: =SUM(G7:G37) -> 3822500 | H38: =SUM(H7:H37) -> 0
E41: =C38-G38 -> 0

Sheet HISTOBQUEJUIN22
A1: ASSOCIATION | B1: ASELBY
A2: ANNEE | B2: 2022
A3: 1 | B3: 2 | C3: 4 | D3: 5 | E3: 6 | F3: 21
B4: HISTORIQUE BANCAIRE
A5: MATRICULE | B5: NOM ET PRENOM | C5: HISTORIQUE BANQUE | D5: HITORIQUE ESPECES | E5: HITORIQUE TONTINE | F5: MONTANT ENGAGEMENT | G5: VERIFICATION | H5: AGIO
A6: AS201648 | B6: =VLOOKUP(A6,[5]LISTADHERENT!A$5:H$60,3,0) -> ASELBY | C6: 100000 | F6: =SUM(C6:E6) -> 100000
A7: AS201602 | B7: =VLOOKUP(A7,[5]LISTADHERENT!A$5:H$60,3,0) -> BOUTCHOUANG WILLIAM | C7: 105000 | F7: =SUM(C7:E7) -> 105000 | G7: 385000
A8: AS201604 | B8: =VLOOKUP(A8,[5]LISTADHERENT!A$5:H$60,3,0) -> DJOMO JEAN PAUL | C8: 110000 | F8: =SUM(C8:E8) -> 110000 | G8: 105000
A9: AS201654 | B9: =VLOOKUP(A9,[5]LISTADHERENT!A$5:H$60,3,0) -> DJOMOU TCHANDA | C9: 30000 | F9: =SUM(C9:E9) -> 30000 | G9: 533000
A10: AS201605 | B10: =VLOOKUP(A10,[5]LISTADHERENT!A$5:H$60,3,0) -> DJOUKWE NANGUEN GUY BLAISE | C10: 30000 | F10: =SUM(C10:E10) -> 30000 | G10: 859000
A11: AS201608 | B11: =VLOOKUP(A11,[5]LISTADHERENT!A$5:H$60,3,0) -> DJUOMBESSY ANTOINE | C11: 205000 | F11: =SUM(C11:E11) -> 205000 | G11: 30000
A12: AS201651 | B12: =VLOOKUP(A12,[5]LISTADHERENT!A$5:H$60,3,0) -> DOMOU FABIEN | C12: 35000 | F12: =SUM(C12:E12) -> 35000 | G12: 105000
A13: AS201609 | B13: =VLOOKUP(A13,[5]LISTADHERENT!A$5:H$60,3,0) -> DONHOU DAVID | C13: 35000 | F13: =SUM(C13:E13) -> 35000 | G13: 430000
A14: AS201610 | B14: =VLOOKUP(A14,[5]LISTADHERENT!A$5:H$60,3,0) -> FOTSO THOMAS | F14: =SUM(C14:E14) -> 0 | G14: 150000
A15: AS201611 | B15: =VLOOKUP(A15,[5]LISTADHERENT!A$5:H$60,3,0) -> HENGUE PAUL OMER | C15: 105000 | F15: =SUM(C15:E15) -> 105000 | G15: 310000
A16: AS201613 | B16: =VLOOKUP(A16,[5]LISTADHERENT!A$5:H$60,3,0) -> HOTCHO BENJAMIN | C16: 150000 | F16: =SUM(C16:E16) -> 150000 | G16: 150000
A17: AS201617 | B17: =VLOOKUP(A17,[5]LISTADHERENT!A$5:H$60,3,0) -> KOUAMOU MOISE | C17: 533000 | F17: =SUM(C17:E17) -> 533000 | G17: 110000
A18: AS201619 | B18: =VLOOKUP(A18,[5]LISTADHERENT!A$5:H$60,3,0) -> KOUATCHO MESSACK | C18: 380000 | F18: =SUM(C18:E18) -> 380000 | G18: 105000
A19: AS201620 | B19: =VLOOKUP(A19,[5]LISTADHERENT!A$5:H$60,3,0) -> LOWE JEAN | C19: 30000 | F19: =SUM(C19:E19) -> 30000 | G19: 280000
A20: AS201649 | B20: =VLOOKUP(A20,[5]LISTADHERENT!A$5:H$60,3,0) -> MBOGNING TUGMA GUY | C20: 859000 | F20: =SUM(C20:E20) -> 859000 | G20: 30000
A21: AS201639 | B21: =VLOOKUP(A21,[5]LISTADHERENT!A$5:H$60,3,0) -> NANGUEN MARTIN | C21: 30000 | F21: =SUM(C21:E21) -> 30000 | G21: 35000
A22: AS201621 | B22: =VLOOKUP(A22,[5]LISTADHERENT!A$5:H$60,3,0) -> NANKAM APPOLINAIRE | C22: 105000 | F22: =SUM(C22:E22) -> 105000 | G22: 341500
A23: AS201622 | B23: =VLOOKUP(A23,[5]LISTADHERENT!A$5:H$60,3,0) -> NDJOMO ETIENNE | C23: 150000 | F23: =SUM(C23:E23) -> 150000 | G23: 30000
A24: AS201624 | B24: =VLOOKUP(A24,[5]LISTADHERENT!A$5:H$60,3,0) -> NGONDIEP CLAUDE | C24: 740000 | D24: 17000 | F24: =SUM(C24:E24) -> 757000 | G24: 380000
A25: AS201626 | B25: =VLOOKUP(A25,[5]LISTADHERENT!A$5:H$60,3,0) -> NGUIEMEGNI MATHIEU BLAISE | C25: 385000 | F25: =SUM(C25:E25) -> 385000 | G25: 30000
A26: AS201628 | B26: =VLOOKUP(A26,[5]LISTADHERENT!A$5:H$60,3,0) -> NKAMGANG JUSTIN DEJOLIE | C26: 341500 | F26: =SUM(C26:E26) -> 341500 | G26: 206000
A27: AS201614 | B27: =VLOOKUP(A27,[5]LISTADHERENT!A$5:H$60,3,0) -> NKEHE DAVID | C27: 20000 | F27: =SUM(C27:E27) -> 20000 | G27: 105000
A28: AS201629 | B28: =VLOOKUP(A28,[5]LISTADHERENT!A$5:H$60,3,0) -> NKEPSEU DIEUDONNE | C28: 430000 | F28: =SUM(C28:E28) -> 430000 | G28: 205000
A29: AS201633 | B29: =VLOOKUP(A29,[5]LISTADHERENT!A$5:H$60,3,0) -> PATEGO NJOSSU GUSTAVE | C29: 105000 | F29: =SUM(C29:E29) -> 105000 | G29: 35000
A30: AS201653 | B30: =VLOOKUP(A30,[5]LISTADHERENT!A$5:H$60,3,0) -> SIME BRICE | C30: 105000 | F30: =SUM(C30:E30) -> 105000 | G30: 20000
A31: AS201636 | B31: =VLOOKUP(A31,[5]LISTADHERENT!A$5:H$60,3,0) -> SIMO FONGANG ERIC | F31: =SUM(C31:E31) -> 0 | G31: 740000
A32: AS201638 | B32: =VLOOKUP(A32,[5]LISTADHERENT!A$5:H$60,3,0) -> SIMO PIERRE | C32: 310000 | F32: =SUM(C32:E32) -> 310000 | G32: 30000
A33: AS201641 | B33: =VLOOKUP(A33,[5]LISTADHERENT!A$5:H$60,3,0) -> TCHOUAMOU MATHIEU | C33: 206000 | F33: =SUM(C33:E33) -> 206000 | G33: 105000
A34: AS201644 | B34: =VLOOKUP(A34,[5]LISTADHERENT!A$5:H$60,3,0) -> TIEYAM ERNEST | C34: 30000 | F34: =SUM(C34:E34) -> 30000
A35: AS201646 | B35: =VLOOKUP(A35,[5]LISTADHERENT!A$5:H$60,3,0) -> YEPMOU JEAN JACQUES | D35: 30000 | F35: =SUM(C35:E35) -> 30000
A36: AS201647 | B36: =VLOOKUP(A36,[5]LISTADHERENT!A$5:H$60,3,0) -> YOUMBI EMMANUEL | C36: 280000 | F36: =SUM(C36:E36) -> 280000
B38: TOTAUX | C38: =SUM(C7:C37) -> 5844500 | D38: =SUM(D7:D37) -> 47000 | E38: =SUM(E7:E37) -> 0 | F38: =SUM(F7:F37) -> 5891500 | G38: =SUM(G7:G37) -> 5844500 | H38: =SUM(H7:H37) -> 0
G40: =C38-G38 -> 0

Sheet HISTOBQUEJUIL22
A1: ASSOCIATION | B1: ASELBY
A2: ANNEE | B2: 2022
A3: 1 | B3: 2 | C3: 4 | D3: 5 | E3: 6 | F3: 21
B4: HISTORIQUE BANCAIRE
A5: MATRICULE | B5: NOM ET PRENOM | C5: HISTORIQUE BANQUE | D5: HITORIQUE ESPECES | E5: HITORIQUE TONTINE | F5: MONTANT ENGAGEMENT | G5: VERIFICATION | H5: AGIO
A6: AS201648 | B6: =VLOOKUP(A6,[5]LISTADHERENT!A$5:H$60,3,0) -> ASELBY | C6: 100000 | F6: =SUM(C6:E6) -> 100000
A7: AS201602 | B7: =VLOOKUP(A7,[5]LISTADHERENT!A$5:H$60,3,0) -> BOUTCHOUANG WILLIAM | C7: 105000 | E7: =70000+500000 -> 570000 | F7: =SUM(C7:E7) -> 675000
A8: AS201604 | B8: =VLOOKUP(A8,[5]LISTADHERENT!A$5:H$60,3,0) -> DJOMO JEAN PAUL | C8: 105000 | F8: =SUM(C8:E8) -> 105000
A9: AS201654 | B9: =VLOOKUP(A9,[5]LISTADHERENT!A$5:H$60,3,0) -> DJOMOU TCHANDA | D9: 34000 | F9: =SUM(C9:E9) -> 34000
A10: AS201605 | B10: =VLOOKUP(A10,[5]LISTADHERENT!A$5:H$60,3,0) -> DJOUKWE NANGUEN GUY BLAISE | C10: 30000 | F10: =SUM(C10:E10) -> 30000
A11: AS201608 | B11: =VLOOKUP(A11,[5]LISTADHERENT!A$5:H$60,3,0) -> DJUOMBESSY ANTOINE | D11: 259000 | E11: 700000 | F11: =SUM(C11:E11) -> 959000
A12: AS201651 | B12: =VLOOKUP(A12,[5]LISTADHERENT!A$5:H$60,3,0) -> DOMOU FABIEN | C12: 35000 | F12: =SUM(C12:E12) -> 35000
A13: AS201609 | B13: =VLOOKUP(A13,[5]LISTADHERENT!A$5:H$60,3,0) -> DONHOU DAVID | C13: 35000 | F13: =SUM(C13:E13) -> 35000
A14: AS201610 | B14: =VLOOKUP(A14,[5]LISTADHERENT!A$5:H$60,3,0) -> FOTSO THOMAS | F14: =SUM(C14:E14) -> 0
A15: AS201611 | B15: =VLOOKUP(A15,[5]LISTADHERENT!A$5:H$60,3,0) -> HENGUE PAUL OMER | C15: 105000 | F15: =SUM(C15:E15) -> 105000
A16: AS201613 | B16: =VLOOKUP(A16,[5]LISTADHERENT!A$5:H$60,3,0) -> HOTCHO BENJAMIN | C16: 150000 | F16: =SUM(C16:E16) -> 150000
A17: AS201617 | B17: =VLOOKUP(A17,[5]LISTADHERENT!A$5:H$60,3,0) -> KOUAMOU MOISE | C17: 330000 | F17: =SUM(C17:E17) -> 330000
A18: AS201619 | B18: =VLOOKUP(A18,[5]LISTADHERENT!A$5:H$60,3,0) -> KOUATCHO MESSACK | C18: 453000 | F18: =SUM(C18:E18) -> 453000
A19: AS201620 | B19: =VLOOKUP(A19,[5]LISTADHERENT!A$5:H$60,3,0) -> LOWE JEAN | C19: 30000 | F19: =SUM(C19:E19) -> 30000
A20: AS201649 | B20: =VLOOKUP(A20,[5]LISTADHERENT!A$5:H$60,3,0) -> MBOGNING TUGMA GUY | C20: 657000 | F20: =SUM(C20:E20) -> 657000
A21: AS201639 | B21: =VLOOKUP(A21,[5]LISTADHERENT!A$5:H$60,3,0) -> NANGUEN MARTIN | C21: 30000 | F21: =SUM(C21:E21) -> 30000
A22: AS201621 | B22: =VLOOKUP(A22,[5]LISTADHERENT!A$5:H$60,3,0) -> NANKAM APPOLINAIRE | C22: 105000 | F22: =SUM(C22:E22) -> 105000
A23: AS201622 | B23: =VLOOKUP(A23,[5]LISTADHERENT!A$5:H$60,3,0) -> NDJOMO ETIENNE | C23: 150000 | F23: =SUM(C23:E23) -> 150000
A24: AS201624 | B24: =VLOOKUP(A24,[5]LISTADHERENT!A$5:H$60,3,0) -> NGONDIEP CLAUDE | C24: 460000 | F24: =SUM(C24:E24) -> 460000
A25: AS201626 | B25: =VLOOKUP(A25,[5]LISTADHERENT!A$5:H$60,3,0) -> NGUIEMEGNI MATHIEU BLAISE | C25: 387000 | F25: =SUM(C25:E25) -> 387000
A26: AS201628 | B26: =VLOOKUP(A26,[5]LISTADHERENT!A$5:H$60,3,0) -> NKAMGANG JUSTIN DEJOLIE | C26: 105000 | D26: 84500 | F26: =SUM(C26:E26) -> 189500
A27: AS201614 | B27: =VLOOKUP(A27,[5]LISTADHERENT!A$5:H$60,3,0) -> NKEHE DAVID | C27: 20000 | F27: =SUM(C27:E27) -> 20000
A28: AS201629 | B28: =VLOOKUP(A28,[5]LISTADHERENT!A$5:H$60,3,0) -> NKEPSEU DIEUDONNE | C28: 200000 | F28: =SUM(C28:E28) -> 200000
A29: AS201633 | B29: =VLOOKUP(A29,[5]LISTADHERENT!A$5:H$60,3,0) -> PATEGO NJOSSU GUSTAVE | C29: 105000 | F29: =SUM(C29:E29) -> 105000
A30: AS201653 | B30: =VLOOKUP(A30,[5]LISTADHERENT!A$5:H$60,3,0) -> SIME BRICE | D30: 108000 | F30: =SUM(C30:E30) -> 108000
A31: AS201636 | B31: =VLOOKUP(A31,[5]LISTADHERENT!A$5:H$60,3,0) -> SIMO FONGANG ERIC | F31: =SUM(C31:E31) -> 0
A32: AS201638 | B32: =VLOOKUP(A32,[5]LISTADHERENT!A$5:H$60,3,0) -> SIMO PIERRE | C32: 110000 | F32: =SUM(C32:E32) -> 110000
A33: AS201641 | B33: =VLOOKUP(A33,[5]LISTADHERENT!A$5:H$60,3,0) -> TCHOUAMOU MATHIEU | C33: 156000 | E33: 560000 | F33: =SUM(C33:E33) -> 716000
A34: AS201644 | B34: =VLOOKUP(A34,[5]LISTADHERENT!A$5:H$60,3,0) -> TIEYAM ERNEST | C34: 30000 | F34: =SUM(C34:E34) -> 30000
A35: AS201646 | B35: =VLOOKUP(A35,[5]LISTADHERENT!A$5:H$60,3,0) -> YEPMOU JEAN JACQUES | D35: 33000 | F35: =SUM(C35:E35) -> 33000
A36: AS201647 | B36: =VLOOKUP(A36,[5]LISTADHERENT!A$5:H$60,3,0) -> YOUMBI EMMANUEL | D36: 283000 | F36: =SUM(C36:E36) -> 283000
B38: TOTAUX | C38: =SUM(C7:C37) -> 3893000 | D38: =SUM(D7:D37) -> 801500 | E38: =SUM(E7:E37) -> 1830000 | F38: =SUM(F7:F37) -> 6524500 | G38: =SUM(G7:G37) -> 0 | H38: =SUM(H7:H37) -> 0

Sheet HISTOBQUEAOUT22
A1: ASSOCIATION | B1: ASELBY
A2: ANNEE | B2: 2022
A3: 1 | B3: 2 | C3: 4 | D3: 5 | E3: 6 | F3: 21
B4: HISTORIQUE BANCAIRE
A5: MATRICULE | B5: NOM ET PRENOM | C5: HISTORIQUE BANQUE | D5: HITORIQUE ESPECES | E5: HITORIQUE TONTINE | F5: MONTANT ENGAGEMENT | G5: VERIFICATION | H5: AGIO
A6: AS201648 | B6: =VLOOKUP(A6,[5]LISTADHERENT!A$5:H$60,3,0) -> ASELBY | C6: 100000 | F6: =SUM(C6:E6) -> 100000
A7: AS201602 | B7: =VLOOKUP(A7,[5]LISTADHERENT!A$5:H$60,3,0) -> BOUTCHOUANG WILLIAM | C7: 105000 | F7: =SUM(C7:E7) -> 105000
A8: AS201604 | B8: =VLOOKUP(A8,[5]LISTADHERENT!A$5:H$60,3,0) -> DJOMO JEAN PAUL | C8: 260000 | F8: =SUM(C8:E8) -> 260000
A9: AS201654 | B9: =VLOOKUP(A9,[5]LISTADHERENT!A$5:H$60,3,0) -> DJOMOU TCHANDA | C9: 30000 | F9: =SUM(C9:E9) -> 30000
A10: AS201605 | B10: =VLOOKUP(A10,[5]LISTADHERENT!A$5:H$60,3,0) -> DJOUKWE NANGUEN GUY BLAISE | C10: 30000 | F10: =SUM(C10:E10) -> 30000
A11: AS201608 | B11: =VLOOKUP(A11,[5]LISTADHERENT!A$5:H$60,3,0) -> DJUOMBESSY ANTOINE | C11: 110000 | E11: 176000 | F11: =SUM(C11:E11) -> 286000
A12: AS201651 | B12: =VLOOKUP(A12,[5]LISTADHERENT!A$5:H$60,3,0) -> DOMOU FABIEN | C12: 35000 | F12: =SUM(C12:E12) -> 35000
A13: AS201609 | B13: =VLOOKUP(A13,[5]LISTADHERENT!A$5:H$60,3,0) -> DONHOU DAVID | C13: 35000 | F13: =SUM(C13:E13) -> 35000
A14: AS201610 | B14: =VLOOKUP(A14,[5]LISTADHERENT!A$5:H$60,3,0) -> FOTSO THOMAS | F14: =SUM(C14:E14) -> 0
A15: AS201611 | B15: =VLOOKUP(A15,[5]LISTADHERENT!A$5:H$60,3,0) -> HENGUE PAUL OMER | C15: 1050000 | E15: 70000 | F15: =SUM(C15:E15) -> 1120000
A16: AS201613 | B16: =VLOOKUP(A16,[5]LISTADHERENT!A$5:H$60,3,0) -> HOTCHO BENJAMIN | C16: 150000 | F16: =SUM(C16:E16) -> 150000
A17: AS201617 | B17: =VLOOKUP(A17,[5]LISTADHERENT!A$5:H$60,3,0) -> KOUAMOU MOISE | C17: 330000 | F17: =SUM(C17:E17) -> 330000
A18: AS201619 | B18: =VLOOKUP(A18,[5]LISTADHERENT!A$5:H$60,3,0) -> KOUATCHO MESSACK | C18: =130000-65000 -> 65000 | D18: =342000+3000 -> 345000 | F18: =SUM(C18:E18) -> 410000
A19: AS201620 | B19: =VLOOKUP(A19,[5]LISTADHERENT!A$5:H$60,3,0) -> LOWE JEAN | C19: 30000 | F19: =SUM(C19:E19) -> 30000
A20: AS201649 | B20: =VLOOKUP(A20,[5]LISTADHERENT!A$5:H$60,3,0) -> MBOGNING TUGMA GUY | C20: 618000 | F20: =SUM(C20:E20) -> 618000
A21: AS201639 | B21: =VLOOKUP(A21,[5]LISTADHERENT!A$5:H$60,3,0) -> NANGUEN MARTIN | C21: 30000 | F21: =SUM(C21:E21) -> 30000
A22: AS201621 | B22: =VLOOKUP(A22,[5]LISTADHERENT!A$5:H$60,3,0) -> NANKAM APPOLINAIRE | C22: 105000 | F22: =SUM(C22:E22) -> 105000
A23: AS201622 | B23: =VLOOKUP(A23,[5]LISTADHERENT!A$5:H$60,3,0) -> NDJOMO ETIENNE | C23: 251000 | F23: =SUM(C23:E23) -> 251000
A24: AS201624 | B24: =VLOOKUP(A24,[5]LISTADHERENT!A$5:H$60,3,0) -> NGONDIEP CLAUDE | C24: 240000 | F24: =SUM(C24:E24) -> 240000
A25: AS201626 | B25: =VLOOKUP(A25,[5]LISTADHERENT!A$5:H$60,3,0) -> NGUIEMEGNI MATHIEU BLAISE | C25: 280000 | F25: =SUM(C25:E25) -> 280000
A26: AS201628 | B26: =VLOOKUP(A26,[5]LISTADHERENT!A$5:H$60,3,0) -> NKAMGANG JUSTIN DEJOLIE | C26: 211000 | F26: =SUM(C26:E26) -> 211000
A27: AS201614 | B27: =VLOOKUP(A27,[5]LISTADHERENT!A$5:H$60,3,0) -> NKEHE DAVID | C27: 20000 | F27: =SUM(C27:E27) -> 20000
A28: AS201629 | B28: =VLOOKUP(A28,[5]LISTADHERENT!A$5:H$60,3,0) -> NKEPSEU DIEUDONNE | C28: 130000 | F28: =SUM(C28:E28) -> 130000
A29: AS201633 | B29: =VLOOKUP(A29,[5]LISTADHERENT!A$5:H$60,3,0) -> PATEGO NJOSSU GUSTAVE | C29: 105000 | F29: =SUM(C29:E29) -> 105000
A30: AS201653 | B30: =VLOOKUP(A30,[5]LISTADHERENT!A$5:H$60,3,0) -> SIME BRICE | C30: 105000 | F30: =SUM(C30:E30) -> 105000
A31: AS201636 | B31: =VLOOKUP(A31,[5]LISTADHERENT!A$5:H$60,3,0) -> SIMO FONGANG ERIC | F31: =SUM(C31:E31) -> 0
A32: AS201638 | B32: =VLOOKUP(A32,[5]LISTADHERENT!A$5:H$60,3,0) -> SIMO PIERRE | C32: 120000 | D32: 10000 | F32: =SUM(C32:E32) -> 130000
A33: AS201641 | B33: =VLOOKUP(A33,[5]LISTADHERENT!A$5:H$60,3,0) -> TCHOUAMOU MATHIEU | C33: 156000 | F33: =SUM(C33:E33) -> 156000
A34: AS201644 | B34: =VLOOKUP(A34,[5]LISTADHERENT!A$5:H$60,3,0) -> TIEYAM ERNEST | F34: =SUM(C34:E34) -> 0
A35: AS201646 | B35: =VLOOKUP(A35,[5]LISTADHERENT!A$5:H$60,3,0) -> YEPMOU JEAN JACQUES | E35: =70000+143750 -> 213750 | F35: =SUM(C35:E35) -> 213750
A36: AS201647 | B36: =VLOOKUP(A36,[5]LISTADHERENT!A$5:H$60,3,0) -> YOUMBI EMMANUEL | C36: 280000 | F36: =SUM(C36:E36) -> 280000
B38: TOTAUX | C38: =SUM(C7:C37) -> 4881000 | D38: =SUM(D7:D37) -> 355000 | E38: =SUM(E7:E37) -> 459750 | F38: =SUM(F7:F37) -> 5695750 | G38: =SUM(G7:G37) -> 0 | H38: =SUM(H7:H37) -> 0

Sheet HISTOBQUESEPT22
A1: ASSOCIATION | B1: ASELBY
A2: ANNEE | B2: 2022
A3: 1 | B3: 2 | C3: 4 | D3: 5 | E3: 6 | F3: 21
B4: HISTORIQUE BANCAIRE
A5: MATRICULE | B5: NOM ET PRENOM | C5: HISTORIQUE BANQUE | D5: HITORIQUE ESPECES | E5: HITORIQUE TONTINE | F5: MONTANT ENGAGEMENT | G5: VERIFICATION | H5: AGIO
A6: AS201648 | B6: =VLOOKUP(A6,[5]LISTADHERENT!A$5:H$60,3,0) -> ASELBY | C6: 100000 | F6: =SUM(C6:E6) -> 100000
A7: AS201602 | B7: =VLOOKUP(A7,[5]LISTADHERENT!A$5:H$60,3,0) -> BOUTCHOUANG WILLIAM | C7: 105000 | F7: =SUM(C7:E7) -> 105000
A8: AS201604 | B8: =VLOOKUP(A8,[5]LISTADHERENT!A$5:H$60,3,0) -> DJOMO JEAN PAUL | D8: 156000 | F8: =SUM(C8:E8) -> 156000
A9: AS201654 | B9: =VLOOKUP(A9,[5]LISTADHERENT!A$5:H$60,3,0) -> DJOMOU TCHANDA | C9: 30000 | E9: 113000 | F9: =SUM(C9:E9) -> 143000
A10: AS201605 | B10: =VLOOKUP(A10,[5]LISTADHERENT!A$5:H$60,3,0) -> DJOUKWE NANGUEN GUY BLAISE | C10: 131000 | E10: 51000 | F10: =SUM(C10:E10) -> 182000
A11: AS201608 | B11: =VLOOKUP(A11,[5]LISTADHERENT!A$5:H$60,3,0) -> DJUOMBESSY ANTOINE | C11: 350000 | F11: =SUM(C11:E11) -> 350000
A12: AS201651 | B12: =VLOOKUP(A12,[5]LISTADHERENT!A$5:H$60,3,0) -> DOMOU FABIEN | C12: 35000 | F12: =SUM(C12:E12) -> 35000
A13: AS201609 | B13: =VLOOKUP(A13,[5]LISTADHERENT!A$5:H$60,3,0) -> DONHOU DAVID | F13: =SUM(C13:E13) -> 0
A14: AS201610 | B14: =VLOOKUP(A14,[5]LISTADHERENT!A$5:H$60,3,0) -> FOTSO THOMAS | F14: =SUM(C14:E14) -> 0
A15: AS201611 | B15: =VLOOKUP(A15,[5]LISTADHERENT!A$5:H$60,3,0) -> HENGUE PAUL OMER | C15: 105000 | F15: =SUM(C15:E15) -> 105000
A16: AS201613 | B16: =VLOOKUP(A16,[5]LISTADHERENT!A$5:H$60,3,0) -> HOTCHO BENJAMIN | C16: 150000 | F16: =SUM(C16:E16) -> 150000
A17: AS201617 | B17: =VLOOKUP(A17,[5]LISTADHERENT!A$5:H$60,3,0) -> KOUAMOU MOISE | C17: 330000 | E17: 1070000 | F17: =SUM(C17:E17) -> 1400000
A18: AS201619 | B18: =VLOOKUP(A18,[5]LISTADHERENT!A$5:H$60,3,0) -> KOUATCHO MESSACK | C18: 577000 | F18: =SUM(C18:E18) -> 577000
A19: AS201620 | B19: =VLOOKUP(A19,[5]LISTADHERENT!A$5:H$60,3,0) -> LOWE JEAN | F19: =SUM(C19:E19) -> 0
A20: AS201649 | B20: =VLOOKUP(A20,[5]LISTADHERENT!A$5:H$60,3,0) -> MBOGNING TUGMA GUY | C20: 633000 | E20: 124000 | F20: =SUM(C20:E20) -> 757000
A21: AS201639 | B21: =VLOOKUP(A21,[5]LISTADHERENT!A$5:H$60,3,0) -> NANGUEN MARTIN | C21: 30000 | F21: =SUM(C21:E21) -> 30000
A22: AS201621 | B22: =VLOOKUP(A22,[5]LISTADHERENT!A$5:H$60,3,0) -> NANKAM APPOLINAIRE | C22: 105000 | F22: =SUM(C22:E22) -> 105000
A23: AS201622 | B23: =VLOOKUP(A23,[5]LISTADHERENT!A$5:H$60,3,0) -> NDJOMO ETIENNE | C23: 150000 | F23: =SUM(C23:E23) -> 150000
A24: AS201624 | B24: =VLOOKUP(A24,[5]LISTADHERENT!A$5:H$60,3,0) -> NGONDIEP CLAUDE | C24: 205000 | F24: =SUM(C24:E24) -> 205000
A25: AS201626 | B25: =VLOOKUP(A25,[5]LISTADHERENT!A$5:H$60,3,0) -> NGUIEMEGNI MATHIEU BLAISE | C25: 580000 | F25: =SUM(C25:E25) -> 580000
A26: AS201628 | B26: =VLOOKUP(A26,[5]LISTADHERENT!A$5:H$60,3,0) -> NKAMGANG JUSTIN DEJOLIE | D26: =202000+51000 -> 253000 | F26: =SUM(C26:E26) -> 253000
A27: AS201614 | B27: =VLOOKUP(A27,[5]LISTADHERENT!A$5:H$60,3,0) -> NKEHE DAVID | C27: 20000 | F27: =SUM(C27:E27) -> 20000
A28: AS201629 | B28: =VLOOKUP(A28,[5]LISTADHERENT!A$5:H$60,3,0) -> NKEPSEU DIEUDONNE | C28: 130000 | F28: =SUM(C28:E28) -> 130000
A29: AS201633 | B29: =VLOOKUP(A29,[5]LISTADHERENT!A$5:H$60,3,0) -> PATEGO NJOSSU GUSTAVE | C29: 105000 | F29: =SUM(C29:E29) -> 105000
A30: AS201653 | B30: =VLOOKUP(A30,[5]LISTADHERENT!A$5:H$60,3,0) -> SIME BRICE | C30: 105000 | E30: 70000 | F30: =SUM(C30:E30) -> 175000
A31: AS201636 | B31: =VLOOKUP(A31,[5]LISTADHERENT!A$5:H$60,3,0) -> SIMO FONGANG ERIC | F31: =SUM(C31:E31) -> 0
A32: AS201638 | B32: =VLOOKUP(A32,[5]LISTADHERENT!A$5:H$60,3,0) -> SIMO PIERRE | C32: 110000 | F32: =SUM(C32:E32) -> 110000
A33: AS201641 | B33: =VLOOKUP(A33,[5]LISTADHERENT!A$5:H$60,3,0) -> TCHOUAMOU MATHIEU | C33: 105000 | F33: =SUM(C33:E33) -> 105000
A34: AS201644 | B34: =VLOOKUP(A34,[5]LISTADHERENT!A$5:H$60,3,0) -> TIEYAM ERNEST | F34: =SUM(C34:E34) -> 0
A35: AS201646 | B35: =VLOOKUP(A35,[5]LISTADHERENT!A$5:H$60,3,0) -> YEPMOU JEAN JACQUES | C35: 30000 | F35: =SUM(C35:E35) -> 30000
A36: AS201647 | B36: =VLOOKUP(A36,[5]LISTADHERENT!A$5:H$60,3,0) -> YOUMBI EMMANUEL | C36: 280000 | F36: =SUM(C36:E36) -> 280000
B38: TOTAUX | C38: =SUM(C7:C37) -> 4401000 | D38: =SUM(D7:D37) -> 409000 | E38: =SUM(E7:E37) -> 1428000 | F38: =SUM(F7:F37) -> 6238000 | G38: =SUM(G7:G37) -> 0 | H38: =SUM(H7:H37) -> 0

Sheet HISTOBQUEOCT22
A1: ASSOCIATION | B1: ASELBY
A2: ANNEE | B2: 2022
A3: 1 | B3: 2 | C3: 4 | D3: 5 | E3: 6 | F3: 21
B4: HISTORIQUE BANCAIRE
A5: MATRICULE | B5: NOM ET PRENOM | C5: HISTORIQUE BANQUE | D5: HITORIQUE ESPECES | E5: HITORIQUE TONTINE | F5: MONTANT ENGAGEMENT | G5: VERIFICATION | H5: AGIO
A6: AS201648 | B6: =VLOOKUP(A6,[5]LISTADHERENT!A$5:H$60,3,0) -> ASELBY | C6: 100000 | F6: =SUM(C6:E6) -> 100000
A7: AS201602 | B7: =VLOOKUP(A7,[5]LISTADHERENT!A$5:H$60,3,0) -> BOUTCHOUANG WILLIAM | C7: 105000 | F7: =SUM(C7:E7) -> 105000 | G7: 250000
A8: AS201604 | B8: =VLOOKUP(A8,[5]LISTADHERENT!A$5:H$60,3,0) -> DJOMO JEAN PAUL | C8: 250000 | F8: =SUM(C8:E8) -> 250000 | G8: 30000
A9: AS201654 | B9: =VLOOKUP(A9,[5]LISTADHERENT!A$5:H$60,3,0) -> DJOMOU TCHANDA | C9: 30000 | F9: =SUM(C9:E9) -> 30000 | G9: 30000
A10: AS201605 | B10: =VLOOKUP(A10,[5]LISTADHERENT!A$5:H$60,3,0) -> DJOUKWE NANGUEN GUY BLAISE | C10: 30000 | F10: =SUM(C10:E10) -> 30000 | G10: 330000
A11: AS201608 | B11: =VLOOKUP(A11,[5]LISTADHERENT!A$5:H$60,3,0) -> DJUOMBESSY ANTOINE | C11: 205000 | F11: =SUM(C11:E11) -> 205000 | G11: 105000
A12: AS201651 | B12: =VLOOKUP(A12,[5]LISTADHERENT!A$5:H$60,3,0) -> DOMOU FABIEN | C12: 35000 | F12: =SUM(C12:E12) -> 35000 | G12: 120000
A13: AS201609 | B13: =VLOOKUP(A13,[5]LISTADHERENT!A$5:H$60,3,0) -> DONHOU DAVID | F13: =SUM(C13:E13) -> 0 | G13: 105000
A14: AS201610 | B14: =VLOOKUP(A14,[5]LISTADHERENT!A$5:H$60,3,0) -> FOTSO THOMAS | F14: =SUM(C14:E14) -> 0 | G14: 35000
A15: AS201611 | B15: =VLOOKUP(A15,[5]LISTADHERENT!A$5:H$60,3,0) -> HENGUE PAUL OMER | C15: 105000 | F15: =SUM(C15:E15) -> 105000 | G15: 205000
A16: AS201613 | B16: =VLOOKUP(A16,[5]LISTADHERENT!A$5:H$60,3,0) -> HOTCHO BENJAMIN | C16: 150000 | F16: =SUM(C16:E16) -> 150000 | G16: 130000
A17: AS201617 | B17: =VLOOKUP(A17,[5]LISTADHERENT!A$5:H$60,3,0) -> KOUAMOU MOISE | C17: 330000 | F17: =SUM(C17:E17) -> 330000 | G17: 205000
A18: AS201619 | B18: =VLOOKUP(A18,[5]LISTADHERENT!A$5:H$60,3,0) -> KOUATCHO MESSACK | C18: =205000+170000 -> 375000 | F18: =SUM(C18:E18) -> 375000 | G18: 150000
A19: AS201620 | B19: =VLOOKUP(A19,[5]LISTADHERENT!A$5:H$60,3,0) -> LOWE JEAN | F19: =SUM(C19:E19) -> 0 | G19: 105000
A20: AS201649 | B20: =VLOOKUP(A20,[5]LISTADHERENT!A$5:H$60,3,0) -> MBOGNING TUGMA GUY | C20: =385000+70000 -> 455000 | F20: =SUM(C20:E20) -> 455000 | G20: 280000
A21: AS201639 | B21: =VLOOKUP(A21,[5]LISTADHERENT!A$5:H$60,3,0) -> NANGUEN MARTIN | C21: 30000 | F21: =SUM(C21:E21) -> 30000 | G21: 105000
A22: AS201621 | B22: =VLOOKUP(A22,[5]LISTADHERENT!A$5:H$60,3,0) -> NANKAM APPOLINAIRE | C22: 105000 | F22: =SUM(C22:E22) -> 105000 | G22: 105000
A23: AS201622 | B23: =VLOOKUP(A23,[5]LISTADHERENT!A$5:H$60,3,0) -> NDJOMO ETIENNE | C23: 150000 | F23: =SUM(C23:E23) -> 150000 | G23: 30000
A24: AS201624 | B24: =VLOOKUP(A24,[5]LISTADHERENT!A$5:H$60,3,0) -> NGONDIEP CLAUDE | C24: =205000+66500 -> 271500 | F24: =SUM(C24:E24) -> 271500 | G24: 400000
A25: AS201626 | B25: =VLOOKUP(A25,[5]LISTADHERENT!A$5:H$60,3,0) -> NGUIEMEGNI MATHIEU BLAISE | C25: 400000 | F25: =SUM(C25:E25) -> 400000 | G25: 385000
A26: AS201628 | B26: =VLOOKUP(A26,[5]LISTADHERENT!A$5:H$60,3,0) -> NKAMGANG JUSTIN DEJOLIE | C26: 206000 | F26: =SUM(C26:E26) -> 206000 | G26: 150000
A27: AS201614 | B27: =VLOOKUP(A27,[5]LISTADHERENT!A$5:H$60,3,0) -> NKEHE DAVID | F27: =SUM(C27:E27) -> 0 | G27: 205000
A28: AS201629 | B28: =VLOOKUP(A28,[5]LISTADHERENT!A$5:H$60,3,0) -> NKEPSEU DIEUDONNE | C28: 130000 | F28: =SUM(C28:E28) -> 130000 | G28: 206000
A29: AS201633 | B29: =VLOOKUP(A29,[5]LISTADHERENT!A$5:H$60,3,0) -> PATEGO NJOSSU GUSTAVE | C29: 105000 | E29: 70000 | F29: =SUM(C29:E29) -> 175000 | G29: 30000
A30: AS201653 | B30: =VLOOKUP(A30,[5]LISTADHERENT!A$5:H$60,3,0) -> SIME BRICE | C30: 105000 | F30: =SUM(C30:E30) -> 105000
A31: AS201636 | B31: =VLOOKUP(A31,[5]LISTADHERENT!A$5:H$60,3,0) -> SIMO FONGANG ERIC | F31: =SUM(C31:E31) -> 0
A32: AS201638 | B32: =VLOOKUP(A32,[5]LISTADHERENT!A$5:H$60,3,0) -> SIMO PIERRE | C32: 120000 | F32: =SUM(C32:E32) -> 120000
A33: AS201641 | B33: =VLOOKUP(A33,[5]LISTADHERENT!A$5:H$60,3,0) -> TCHOUAMOU MATHIEU | C33: 105000 | F33: =SUM(C33:E33) -> 105000
A34: AS201644 | B34: =VLOOKUP(A34,[5]LISTADHERENT!A$5:H$60,3,0) -> TIEYAM ERNEST | F34: =SUM(C34:E34) -> 0
A35: AS201646 | B35: =VLOOKUP(A35,[5]LISTADHERENT!A$5:H$60,3,0) -> YEPMOU JEAN JACQUES | C35: 30000 | F35: =SUM(C35:E35) -> 30000
A36: AS201647 | B36: =VLOOKUP(A36,[5]LISTADHERENT!A$5:H$60,3,0) -> YOUMBI EMMANUEL | C36: 280000 | F36: =SUM(C36:E36) -> 280000
B38: TOTAUX | C38: =SUM(C7:C37) -> 4107500 | D38: =SUM(D7:D37) -> 0 | E38: =SUM(E7:E37) -> 70000 | F38: =SUM(F7:F37) -> 4177500 | G38: =SUM(G7:G37) -> 3696000 | H38: =SUM(H7:H37) -> 0

Sheet HISTOBQUENOV22
A1: ASSOCIATION | B1: ASELBY
A2: ANNEE | B2: 2022
A3: 1 | B3: 2 | C3: 4 | D3: 5 | E3: 6 | F3: 21
B4: HISTORIQUE BANCAIRE
A5: MATRICULE | B5: NOM ET PRENOM | C5: HISTORIQUE BANQUE | D5: HITORIQUE ESPECES | E5: HITORIQUE TONTINE | F5: MONTANT ENGAGEMENT | G5: VERIFICATION | H5: AGIO
A6: AS201648 | B6: =VLOOKUP(A6,[5]LISTADHERENT!A$5:H$60,3,0) -> ASELBY | C6: 100000 | F6: =SUM(C6:E6) -> 100000
A7: AS201602 | B7: =VLOOKUP(A7,[5]LISTADHERENT!A$5:H$60,3,0) -> BOUTCHOUANG WILLIAM | C7: 105000 | F7: =SUM(C7:E7) -> 105000 | G7: 105000
A8: AS201604 | B8: =VLOOKUP(A8,[5]LISTADHERENT!A$5:H$60,3,0) -> DJOMO JEAN PAUL | C8: =165000+40000 -> 205000 | F8: =SUM(C8:E8) -> 205000 | G8: 105000
A9: AS201654 | B9: =VLOOKUP(A9,[5]LISTADHERENT!A$5:H$60,3,0) -> DJOMOU TCHANDA | C9: 30000 | F9: =SUM(C9:E9) -> 30000 | G9: 30000
A10: AS201605 | B10: =VLOOKUP(A10,[5]LISTADHERENT!A$5:H$60,3,0) -> DJOUKWE NANGUEN GUY BLAISE | C10: =30000+75000 -> 105000 | F10: =SUM(C10:E10) -> 105000 | G10: 30000
A11: AS201608 | B11: =VLOOKUP(A11,[5]LISTADHERENT!A$5:H$60,3,0) -> DJUOMBESSY ANTOINE | C11: 205000 | F11: =SUM(C11:E11) -> 205000 | G11: 759000
A12: AS201651 | B12: =VLOOKUP(A12,[5]LISTADHERENT!A$5:H$60,3,0) -> DOMOU FABIEN | C12: 35000 | F12: =SUM(C12:E12) -> 35000 | G12: 150000
A13: AS201609 | B13: =VLOOKUP(A13,[5]LISTADHERENT!A$5:H$60,3,0) -> DONHOU DAVID | C13: 35000 | F13: =SUM(C13:E13) -> 35000 | G13: 370000
A14: AS201610 | B14: =VLOOKUP(A14,[5]LISTADHERENT!A$5:H$60,3,0) -> FOTSO THOMAS | F14: =SUM(C14:E14) -> 0 | G14: 105000
A15: AS201611 | B15: =VLOOKUP(A15,[5]LISTADHERENT!A$5:H$60,3,0) -> HENGUE PAUL OMER | C15: 105000 | F15: =SUM(C15:E15) -> 105000 | G15: 280000
A16: AS201613 | B16: =VLOOKUP(A16,[5]LISTADHERENT!A$5:H$60,3,0) -> HOTCHO BENJAMIN | C16: 150000 | F16: =SUM(C16:E16) -> 150000 | G16: 105000 | I16: 105000
A17: AS201617 | B17: =VLOOKUP(A17,[5]LISTADHERENT!A$5:H$60,3,0) -> KOUAMOU MOISE | C17: 330000 | F17: =SUM(C17:E17) -> 330000 | G17: 165000 | I17: 30000
A18: AS201619 | B18: =VLOOKUP(A18,[5]LISTADHERENT!A$5:H$60,3,0) -> KOUATCHO MESSACK | C18: =410000-1500 -> 408500 | F18: =SUM(C18:E18) -> 408500 | G18: 130000 | I18: 35000
A19: AS201620 | B19: =VLOOKUP(A19,[5]LISTADHERENT!A$5:H$60,3,0) -> LOWE JEAN | C19: 30000 | F19: =SUM(C19:E19) -> 30000 | G19: 110000 | I19: 179000
A20: AS201649 | B20: =VLOOKUP(A20,[5]LISTADHERENT!A$5:H$60,3,0) -> MBOGNING TUGMA GUY | C20: =455000+179000+1500 -> 635500 | F20: =SUM(C20:E20) -> 635500 | G20: 205000 | I20: =SUM(I16:I19) -> 349000
A21: AS201639 | B21: =VLOOKUP(A21,[5]LISTADHERENT!A$5:H$60,3,0) -> NANGUEN MARTIN | C21: 30000 | E21: 70000 | F21: =SUM(C21:E21) -> 100000 | G21: 330000
A22: AS201621 | B22: =VLOOKUP(A22,[5]LISTADHERENT!A$5:H$60,3,0) -> NANKAM APPOLINAIRE | C22: 105000 | F22: =SUM(C22:E22) -> 105000 | G22: 35000 | I22: 759000 | J22: =I22-I20 -> 410000
A23: AS201622 | B23: =VLOOKUP(A23,[5]LISTADHERENT!A$5:H$60,3,0) -> NDJOMO ETIENNE | C23: 140000 | F23: =SUM(C23:E23) -> 140000 | G23: 105000
A24: AS201624 | B24: =VLOOKUP(A24,[5]LISTADHERENT!A$5:H$60,3,0) -> NGONDIEP CLAUDE | C24: 205000 | D24: 87500 | F24: =SUM(C24:E24) -> 292500 | G24: 455000
A25: AS201626 | B25: =VLOOKUP(A25,[5]LISTADHERENT!A$5:H$60,3,0) -> NGUIEMEGNI MATHIEU BLAISE | C25: =370000+120000 -> 490000 | F25: =SUM(C25:E25) -> 490000 | G25: 140000
A26: AS201628 | B26: =VLOOKUP(A26,[5]LISTADHERENT!A$5:H$60,3,0) -> NKAMGANG JUSTIN DEJOLIE | C26: =105000+202000 -> 307000 | F26: =SUM(C26:E26) -> 307000 | G26: 105000
A27: AS201614 | B27: =VLOOKUP(A27,[5]LISTADHERENT!A$5:H$60,3,0) -> NKEHE DAVID | F27: =SUM(C27:E27) -> 0
A28: AS201629 | B28: =VLOOKUP(A28,[5]LISTADHERENT!A$5:H$60,3,0) -> NKEPSEU DIEUDONNE | C28: 130000 | F28: =SUM(C28:E28) -> 130000
A29: AS201633 | B29: =VLOOKUP(A29,[5]LISTADHERENT!A$5:H$60,3,0) -> PATEGO NJOSSU GUSTAVE | C29: 105000 | F29: =SUM(C29:E29) -> 105000
A30: AS201653 | B30: =VLOOKUP(A30,[5]LISTADHERENT!A$5:H$60,3,0) -> SIME BRICE | C30: 105000 | F30: =SUM(C30:E30) -> 105000
A31: AS201636 | B31: =VLOOKUP(A31,[5]LISTADHERENT!A$5:H$60,3,0) -> SIMO FONGANG ERIC | F31: =SUM(C31:E31) -> 0
A32: AS201638 | B32: =VLOOKUP(A32,[5]LISTADHERENT!A$5:H$60,3,0) -> SIMO PIERRE | C32: 110000 | F32: =SUM(C32:E32) -> 110000
A33: AS201641 | B33: =VLOOKUP(A33,[5]LISTADHERENT!A$5:H$60,3,0) -> TCHOUAMOU MATHIEU | C33: 30000 | F33: =SUM(C33:E33) -> 30000
A34: AS201644 | B34: =VLOOKUP(A34,[5]LISTADHERENT!A$5:H$60,3,0) -> TIEYAM ERNEST | F34: =SUM(C34:E34) -> 0
A35: AS201646 | B35: =VLOOKUP(A35,[5]LISTADHERENT!A$5:H$60,3,0) -> YEPMOU JEAN JACQUES | D35: 33000 | F35: =SUM(C35:E35) -> 33000
A36: AS201647 | B36: =VLOOKUP(A36,[5]LISTADHERENT!A$5:H$60,3,0) -> YOUMBI EMMANUEL | C36: 280000 | F36: =SUM(C36:E36) -> 280000
B38: TOTAUX | C38: =SUM(C7:C37) -> 4416000 | D38: =SUM(D7:D37) -> 120500 | E38: =SUM(E7:E37) -> 70000 | F38: =SUM(F7:F37) -> 4606500 | G38: =SUM(G7:G37) -> 3819000 | H38: =SUM(H7:H37) -> 0
G40: =C38-G38 -> 597000

Sheet HISTOBQUEDEC22
A1: ASSOCIATION | B1: ASELBY
A2: ANNEE | B2: 2022
A3: 1 | B3: 2 | C3: 4 | D3: 5 | E3: 6 | F3: 21
B4: HISTORIQUE BANCAIRE
A5: MATRICULE | B5: NOM ET PRENOM | C5: HISTORIQUE BANQUE | D5: HITORIQUE ESPECES | E5: HITORIQUE TONTINE | F5: MONTANT ENGAGEMENT | G5: VERIFICATION | H5: AGIO
A6: AS201648 | B6: =VLOOKUP(A6,[5]LISTADHERENT!A$5:H$60,3,0) -> ASELBY | C6: 100000 | F6: =SUM(C6:E6) -> 100000
A7: AS201602 | B7: =VLOOKUP(A7,[5]LISTADHERENT!A$5:H$60,3,0) -> BOUTCHOUANG WILLIAM | C7: 105000 | F7: =SUM(C7:E7) -> 105000
A8: AS201604 | B8: =VLOOKUP(A8,[5]LISTADHERENT!A$5:H$60,3,0) -> DJOMO JEAN PAUL | C8: =880000+130000+95000 -> 1105000 | F8: =SUM(C8:E8) -> 1105000
