Workbook
Name BANQUE: #REF!
Name BANQUE: #REF!
Name BANQUE: #REF!
Name BANQUE: #REF!
Name BANQUE: #REF!
Name BANQUE: #REF!
Name BANQUE: #REF!
Name BANQUE: #REF!
Name BANQUE: #REF!
Name BANQUE: #REF!
Name BANQUE: #REF!
Name BANQUE: #REF!
Name BANQUE: #REF!
Name BANQUE: #REF!
Name BANQUE: #REF!
Name BANQUE: #REF!
Name BANQUE: #REF!
Name BANQUE: #REF!
Name MODEPAID: #REF!
Name MODEPAID: [1]Feuil2!$A$1:$A$3
Name MODET25000: [2]MODEVERSEMENT!$A$1:$A$3
Name MODEVERSEMENT: #REF!
Name MODEVERSEMENT: #REF!
Name MODEVERSEMENT: #REF!
Name MODEVERSEMENT: #REF!
Name MODEVERSEMENT: #REF!
Name MODEVERSEMENT: #REF!
Name MODEVERSEMENT: #REF!
Name MODEVERSEMENT: #REF!
Name MODEVERSEMENT: #REF!
Name MODEVERSEMENT: #REF!
Name MODEVERSEMENT: #REF!
Name MODEVERSEMENT: #REF!
Name MODEVERSEMENT: #REF!
Name MODEVERSEMENT: #REF!
Name MODEVERSEMENT: #REF!
Name MODEVERSEMENT: #REF!
Name MODEVERSEMENT: #REF!
Name MODEVERSEMENT: #REF!
Name MODEVERSEMENTS: [3]MODEVERSEMENT!$A$1:$A$3
Name MODEVERSEMENTS: [3]MODEVERSEMENT!$A$1:$A$3
Name MODEVERSEMENTS: [3]MODEVERSEMENT!$A$1:$A$3
Name MODEVERSEMENTS: [3]MODEVERSEMENT!$A$1:$A$3
Name MODEVERSEMENTS: [3]MODEVERSEMENT!$A$1:$A$3
Name MODEVERSEMENTS: [3]MODEVERSEMENT!$A$1:$A$3
Name MODEVERSEMENTS: [3]MODEVERSEMENT!$A$1:$A$3
Name MODEVERSEMENTS: [3]MODEVERSEMENT!$A$1:$A$3
Name MODEVERSEMENTS: [3]MODEVERSEMENT!$A$1:$A$3
Name MODEVERSEMENTS: [3]MODEVERSEMENT!$A$1:$A$3
Name MODEVERSEMENTS: [3]MODEVERSEMENT!$A$1:$A$3
Name MODEVERSEMENTS: [3]MODEVERSEMENT!$A$1:$A$3
Name MODEVERSEMENTS: [3]MODEVERSEMENT!$A$1:$A$3
Name MODEVERSEMENTS: [3]MODEVERSEMENT!$A$1:$A$3
Name MODEVERSEMENTS: [3]MODEVERSEMENT!$A$1:$A$3
Name MODEVERSEMENTS: [3]MODEVERSEMENT!$A$1:$A$3
Name MODEVERSEMENTS: MODEVERSEMENT!$A$1:$A$3
Name MODPAID: TONTAOUT22!#REF!
Name MODPAID: TONTAVRIL22!#REF!
Name MODPAID: TONTDEC22!#REF!
Name MODPAID: TONTFEV22!#REF!

Sheet MODEVERSEMENT
A1: BANQUE
A2: ESPECES
A3: ECHEC

Sheet TONTJANV23
A1: ASSOCIATION | B1: ASELBY
A2: ANNEE | B2: 2023 | C2: TONIINE | D2: NBRE PART
A3: TAUX TONTINE | B3: 25000 | C3: =B3*13+1000 -> 326000 | D3: =ROUNDDOWN(M40/C3,0) -> 2
C4: 44939
A5: MATRICULE | B5: NBREPART | C5: NOM ET PRENOM | D5: MONTANT TONTINE | E5: MONTANT VERSE | F5: PENALITE VERSEMENT ESPECES | G5: MODE VERSEMENT | H5: VENTE PETIT LOT | I5: INTERET PETIT LOT | J5: MODE VERSEMENT VENTE PETIT LOT | K5: NUMERO CHEQUE | L5: MONTANT A REMBOURSER PETIT LOT | M5: REMBOURSEMENT PETIT LOT | N5: MODE VERSEMENT REMBOURSEMENT | O5: MODE VERSEMENTLOT PRINCIPAL | P5: NUMERO CHEQUE | Q5: MONTANT LOT PRINCIPAL | R5: INTERET LOT PRINCIPAL
A6: AS201601 | B6: =IF(D6=0,0,VLOOKUP($A6,[6]HISTOJANV23!$A$6:$BO$40,10,0)) -> 1 | C6: =VLOOKUP(A6,[7]LISTADHERENT!A$5:H$60,3,0) -> BAKOP ACHILLE | D6: =IF(G6="ECHEC",0,B$3) -> 25000 | E6: =D6+VLOOKUP($A6,[6]HISTOJANV23!$A$7:$AU$40,45,0)+F6 -> 104000 | F6: =VLOOKUP($A6,[6]HISTOJANV23!$A$7:$AU$45,7,0) -> 0 | G6: =VLOOKUP($A6,[6]HISTOJANV23!$A$7:$AU$45,8,0) -> ESPECES | H6: =VLOOKUP($A6,[6]HISTOJANV23!$A$6:$AU$45,35,0) -> 0 | I6: =VLOOKUP($A6,[6]HISTOJANV23!$A$7:$AU$45,38,0) -> 0 | J6: =IF(I6=0,0,VLOOKUP($A6,[6]HISTOJANV23!$A$7:$AU$45,42,0)) -> 0 | K6: =VLOOKUP($A6,[6]HISTOJANV23!$A$7:$AU$45,41,0) -> 0 | M6: =VLOOKUP($A6,[6]HISTOJANV23!$A$7:$AU$45,16,0) -> 0 | N6: =IF(M6<>0,VLOOKUP($A6,[6]HISTOJANV23!$A$7:$AU$45,8,0),"ECHEC") -> ECHEC | O6: =IF(R6=0,0,VLOOKUP($A6,[6]HISTOJANV23!$A$7:$AU$45,32,0)) -> 0 | P6: =VLOOKUP($A6,[6]HISTOJANV23!$A$7:$AU$45,33,0) -> 0 | Q6: =IF(R6=0,0,($C$3-R6)) -> 0 | R6: =VLOOKUP($A6,[6]HISTOJANV23!$A$7:$AU$45,29,0) -> 0
A7: AS201602 | B7: =IF(D7=0,0,VLOOKUP($A7,[6]HISTOJANV23!$A$6:$BO$40,10,0)) -> 1 | C7: =VLOOKUP(A7,[7]LISTADHERENT!A$5:H$60,3,0) -> BOUTCHOUANG WILLIAM | D7: =IF(G7="ECHEC",0,B$3) -> 25000 | E7: =D7+VLOOKUP($A7,[6]HISTOJANV23!$A$7:$AU$40,45,0)+F7 -> 40000 | F7: =VLOOKUP($A7,[6]HISTOJANV23!$A$7:$AU$45,7,0) -> 0 | G7: =VLOOKUP($A7,[6]HISTOJANV23!$A$7:$AU$45,8,0) -> BANQUE | H7: =VLOOKUP($A7,[6]HISTOJANV23!$A$6:$AU$45,35,0) -> 0 | I7: =VLOOKUP($A7,[6]HISTOJANV23!$A$7:$AU$45,38,0) -> 0 | J7: =IF(I7=0,0,VLOOKUP($A7,[6]HISTOJANV23!$A$7:$AU$45,42,0)) -> 0 | K7: =VLOOKUP($A7,[6]HISTOJANV23!$A$7:$AU$45,41,0) -> 0 | M7: =VLOOKUP($A7,[6]HISTOJANV23!$A$7:$AU$45,16,0) -> 0 | N7: =IF(M7<>0,VLOOKUP($A7,[6]HISTOJANV23!$A$7:$AU$45,8,0),"ECHEC") -> ECHEC | O7: =IF(R7=0,0,VLOOKUP($A7,[6]HISTOJANV23!$A$7:$AU$45,32,0)) -> 0 | P7: =VLOOKUP($A7,[6]HISTOJANV23!$A$7:$AU$45,33,0) -> 0 | Q7: =IF(R7=0,0,($C$3-R7)) -> 0 | R7: =VLOOKUP($A7,[6]HISTOJANV23!$A$7:$AU$45,29,0) -> 0
A8: AS201604 | B8: =IF(D8=0,0,VLOOKUP($A8,[6]HISTOJANV23!$A$6:$BO$40,10,0)) -> 1 | C8: =VLOOKUP(A8,[7]LISTADHERENT!A$5:H$60,3,0) -> DJOMO JEAN PAUL | D8: =IF(G8="ECHEC",0,B$3) -> 25000 | E8: =D8+VLOOKUP($A8,[6]HISTOJANV23!$A$7:$AU$40,45,0)+F8 -> 60000 | F8: =VLOOKUP($A8,[6]HISTOJANV23!$A$7:$AU$45,7,0) -> 0 | G8: =VLOOKUP($A8,[6]HISTOJANV23!$A$7:$AU$45,8,0) -> BANQUE | H8: =VLOOKUP($A8,[6]HISTOJANV23!$A$6:$AU$45,35,0) -> 0 | I8: =VLOOKUP($A8,[6]HISTOJANV23!$A$7:$AU$45,38,0) -> 0 | J8: =IF(I8=0,0,VLOOKUP($A8,[6]HISTOJANV23!$A$7:$AU$45,42,0)) -> 0 | K8: =VLOOKUP($A8,[6]HISTOJANV23!$A$7:$AU$45,41,0) -> 0 | M8: =VLOOKUP($A8,[6]HISTOJANV23!$A$7:$AU$45,16,0) -> 0 | N8: =IF(M8<>0,VLOOKUP($A8,[6]HISTOJANV23!$A$7:$AU$45,8,0),"ECHEC") -> ECHEC | O8: =IF(R8=0,0,VLOOKUP($A8,[6]HISTOJANV23!$A$7:$AU$45,32,0)) -> BANQUE | P8: =VLOOKUP($A8,[6]HISTOJANV23!$A$7:$AU$45,33,0) -> 0 | Q8: =IF(R8=0,0,($C$3-R8)) -> 281000 | R8: =VLOOKUP($A8,[6]HISTOJANV23!$A$7:$AU$45,29,0) -> 45000
A9: AS201654 | B9: =IF(D9=0,0,VLOOKUP($A9,[6]HISTOJANV23!$A$6:$BO$40,10,0)) -> 1 | C9: =VLOOKUP(A9,[7]LISTADHERENT!A$5:H$60,3,0) -> DJOMOU TCHAPDA | D9: =IF(G9="ECHEC",0,B$3) -> 25000 | E9: =D9+VLOOKUP($A9,[6]HISTOJANV23!$A$7:$AU$40,45,0)+F9 -> 40000 | F9: =VLOOKUP($A9,[6]HISTOJANV23!$A$7:$AU$45,7,0) -> 0 | G9: =VLOOKUP($A9,[6]HISTOJANV23!$A$7:$AU$45,8,0) -> BANQUE | H9: =VLOOKUP($A9,[6]HISTOJANV23!$A$6:$AU$45,35,0) -> 60000 | I9: =VLOOKUP($A9,[6]HISTOJANV23!$A$7:$AU$45,38,0) -> 3000 | J9: =IF(I9=0,0,VLOOKUP($A9,[6]HISTOJANV23!$A$7:$AU$45,42,0)) -> BANQUE | K9: =VLOOKUP($A9,[6]HISTOJANV23!$A$7:$AU$45,41,0) -> 0 | M9: =VLOOKUP($A9,[6]HISTOJANV23!$A$7:$AU$45,16,0) -> 0 | N9: =IF(M9<>0,VLOOKUP($A9,[6]HISTOJANV23!$A$7:$AU$45,8,0),"ECHEC") -> ECHEC | O9: =IF(R9=0,0,VLOOKUP($A9,[6]HISTOJANV23!$A$7:$AU$45,32,0)) -> 0 | P9: =VLOOKUP($A9,[6]HISTOJANV23!$A$7:$AU$45,33,0) -> 0 | Q9: =IF(R9=0,0,($C$3-R9)) -> 0 | R9: =VLOOKUP($A9,[6]HISTOJANV23!$A$7:$AU$45,29,0) -> 0
A10: AS201605 | B10: =IF(D10=0,0,VLOOKUP($A10,[6]HISTOJANV23!$A$6:$BO$40,10,0)) -> 1 | C10: =VLOOKUP(A10,[7]LISTADHERENT!A$5:H$60,3,0) -> DJOUKWE NANGUEN GUY BLAISE | D10: =IF(G10="ECHEC",0,B$3) -> 25000 | E10: =D10+VLOOKUP($A10,[6]HISTOJANV23!$A$7:$AU$40,45,0)+F10 -> 40000 | F10: =VLOOKUP($A10,[6]HISTOJANV23!$A$7:$AU$45,7,0) -> 0 | G10: =VLOOKUP($A10,[6]HISTOJANV23!$A$7:$AU$45,8,0) -> BANQUE | H10: =VLOOKUP($A10,[6]HISTOJANV23!$A$6:$AU$45,35,0) -> 60000 | I10: =VLOOKUP($A10,[6]HISTOJANV23!$A$7:$AU$45,38,0) -> 2000 | J10: =IF(I10=0,0,VLOOKUP($A10,[6]HISTOJANV23!$A$7:$AU$45,42,0)) -> BANQUE | K10: =VLOOKUP($A10,[6]HISTOJANV23!$A$7:$AU$45,41,0) -> 0 | M10: =VLOOKUP($A10,[6]HISTOJANV23!$A$7:$AU$45,16,0) -> 0 | N10: =IF(M10<>0,VLOOKUP($A10,[6]HISTOJANV23!$A$7:$AU$45,8,0),"ECHEC") -> ECHEC | O10: =IF(R10=0,0,VLOOKUP($A10,[6]HISTOJANV23!$A$7:$AU$45,32,0)) -> 0 | P10: =VLOOKUP($A10,[6]HISTOJANV23!$A$7:$AU$45,33,0) -> 0 | Q10: =IF(R10=0,0,($C$3-R10)) -> 0 | R10: =VLOOKUP($A10,[6]HISTOJANV23!$A$7:$AU$45,29,0) -> 0
A11: AS201608 | B11: =IF(D11=0,0,VLOOKUP($A11,[6]HISTOJANV23!$A$6:$BO$40,10,0)) -> 1 | C11: =VLOOKUP(A11,[7]LISTADHERENT!A$5:H$60,3,0) -> DJUOMBESSY ANTOINE | D11: =IF(G11="ECHEC",0,B$3) -> 25000 | E11: =D11+VLOOKUP($A11,[6]HISTOJANV23!$A$7:$AU$40,45,0)+F11 -> 45000 | F11: =VLOOKUP($A11,[6]HISTOJANV23!$A$7:$AU$45,7,0) -> 0 | G11: =VLOOKUP($A11,[6]HISTOJANV23!$A$7:$AU$45,8,0) -> BANQUE | H11: =VLOOKUP($A11,[6]HISTOJANV23!$A$6:$AU$45,35,0) -> 0 | I11: =VLOOKUP($A11,[6]HISTOJANV23!$A$7:$AU$45,38,0) -> 0 | J11: =IF(I11=0,0,VLOOKUP($A11,[6]HISTOJANV23!$A$7:$AU$45,42,0)) -> 0 | K11: =VLOOKUP($A11,[6]HISTOJANV23!$A$7:$AU$45,41,0) -> 0 | M11: =VLOOKUP($A11,[6]HISTOJANV23!$A$7:$AU$45,16,0) -> 0 | N11: =IF(M11<>0,VLOOKUP($A11,[6]HISTOJANV23!$A$7:$AU$45,8,0),"ECHEC") -> ECHEC | O11: =IF(R11=0,0,VLOOKUP($A11,[6]HISTOJANV23!$A$7:$AU$45,32,0)) -> 0 | P11: =VLOOKUP($A11,[6]HISTOJANV23!$A$7:$AU$45,33,0) -> 0 | Q11: =IF(R11=0,0,($C$3-R11)) -> 0 | R11: =VLOOKUP($A11,[6]HISTOJANV23!$A$7:$AU$45,29,0) -> 0
A12: AS201651 | B12: =IF(D12=0,0,VLOOKUP($A12,[6]HISTOJANV23!$A$6:$BO$40,10,0)) -> 1 | C12: =VLOOKUP(A12,[7]LISTADHERENT!A$5:H$60,3,0) -> DOMOU FABIEN | D12: =IF(G12="ECHEC",0,B$3) -> 25000 | E12: =D12+VLOOKUP($A12,[6]HISTOJANV23!$A$7:$AU$40,45,0)+F12 -> 40000 | F12: =VLOOKUP($A12,[6]HISTOJANV23!$A$7:$AU$45,7,0) -> 0 | G12: =VLOOKUP($A12,[6]HISTOJANV23!$A$7:$AU$45,8,0) -> BANQUE | H12: =VLOOKUP($A12,[6]HISTOJANV23!$A$6:$AU$45,35,0) -> 0 | I12: =VLOOKUP($A12,[6]HISTOJANV23!$A$7:$AU$45,38,0) -> 0 | J12: =IF(I12=0,0,VLOOKUP($A12,[6]HISTOJANV23!$A$7:$AU$45,42,0)) -> 0 | K12: =VLOOKUP($A12,[6]HISTOJANV23!$A$7:$AU$45,41,0) -> 0 | M12: =VLOOKUP($A12,[6]HISTOJANV23!$A$7:$AU$45,16,0) -> 0 | N12: =IF(M12<>0,VLOOKUP($A12,[6]HISTOJANV23!$A$7:$AU$45,8,0),"ECHEC") -> ECHEC | O12: =IF(R12=0,0,VLOOKUP($A12,[6]HISTOJANV23!$A$7:$AU$45,32,0)) -> 0 | P12: =VLOOKUP($A12,[6]HISTOJANV23!$A$7:$AU$45,33,0) -> 0 | Q12: =IF(R12=0,0,($C$3-R12)) -> 0 | R12: =VLOOKUP($A12,[6]HISTOJANV23!$A$7:$AU$45,29,0) -> 0
A13: AS201609 | B13: =IF(D13=0,0,VLOOKUP($A13,[6]HISTOJANV23!$A$6:$BO$40,10,0)) -> 1 | C13: =VLOOKUP(A13,[7]LISTADHERENT!A$5:H$60,3,0) -> DONHOU DAVID | D13: =IF(G13="ECHEC",0,B$3) -> 25000 | E13: =D13+VLOOKUP($A13,[6]HISTOJANV23!$A$7:$AU$40,45,0)+F13 -> 40000 | F13: =VLOOKUP($A13,[6]HISTOJANV23!$A$7:$AU$45,7,0) -> 0 | G13: =VLOOKUP($A13,[6]HISTOJANV23!$A$7:$AU$45,8,0) -> BANQUE | H13: =VLOOKUP($A13,[6]HISTOJANV23!$A$6:$AU$45,35,0) -> 0 | I13: =VLOOKUP($A13,[6]HISTOJANV23!$A$7:$AU$45,38,0) -> 0 | J13: =IF(I13=0,0,VLOOKUP($A13,[6]HISTOJANV23!$A$7:$AU$45,42,0)) -> 0 | K13: =VLOOKUP($A13,[6]HISTOJANV23!$A$7:$AU$45,41,0) -> 0 | M13: =VLOOKUP($A13,[6]HISTOJANV23!$A$7:$AU$45,16,0) -> 0 | N13: =IF(M13<>0,VLOOKUP($A13,[6]HISTOJANV23!$A$7:$AU$45,8,0),"ECHEC") -> ECHEC | O13: =IF(R13=0,0,VLOOKUP($A13,[6]HISTOJANV23!$A$7:$AU$45,32,0)) -> 0 | P13: =VLOOKUP($A13,[6]HISTOJANV23!$A$7:$AU$45,33,0) -> 0 | Q13: =IF(R13=0,0,($C$3-R13)) -> 0 | R13: =VLOOKUP($A13,[6]HISTOJANV23!$A$7:$AU$45,29,0) -> 0
A14: AS201611 | B14: =IF(D14=0,0,VLOOKUP($A14,[6]HISTOJANV23!$A$6:$BO$40,10,0)) -> 1 | C14: =VLOOKUP(A14,[7]LISTADHERENT!A$5:H$60,3,0) -> HENGUE PAUL OMER | D14: =IF(G14="ECHEC",0,B$3) -> 25000 | E14: =D14+VLOOKUP($A14,[6]HISTOJANV23!$A$7:$AU$40,45,0)+F14 -> 40000 | F14: =VLOOKUP($A14,[6]HISTOJANV23!$A$7:$AU$45,7,0) -> 0 | G14: =VLOOKUP($A14,[6]HISTOJANV23!$A$7:$AU$45,8,0) -> BANQUE | H14: =VLOOKUP($A14,[6]HISTOJANV23!$A$6:$AU$45,35,0) -> 0 | I14: =VLOOKUP($A14,[6]HISTOJANV23!$A$7:$AU$45,38,0) -> 0 | J14: =IF(I14=0,0,VLOOKUP($A14,[6]HISTOJANV23!$A$7:$AU$45,42,0)) -> 0 | K14: =VLOOKUP($A14,[6]HISTOJANV23!$A$7:$AU$45,41,0) -> 0 | M14: =VLOOKUP($A14,[6]HISTOJANV23!$A$7:$AU$45,16,0) -> 0 | N14: =IF(M14<>0,VLOOKUP($A14,[6]HISTOJANV23!$A$7:$AU$45,8,0),"ECHEC") -> ECHEC | O14: =IF(R14=0,0,VLOOKUP($A14,[6]HISTOJANV23!$A$7:$AU$45,32,0)) -> 0 | P14: =VLOOKUP($A14,[6]HISTOJANV23!$A$7:$AU$45,33,0) -> 0 | Q14: =IF(R14=0,0,($C$3-R14)) -> 0 | R14: =VLOOKUP($A14,[6]HISTOJANV23!$A$7:$AU$45,29,0) -> 0
A15: AS201613 | B15: =IF(D15=0,0,VLOOKUP($A15,[6]HISTOJANV23!$A$6:$BO$40,10,0)) -> 1 | C15: =VLOOKUP(A15,[7]LISTADHERENT!A$5:H$60,3,0) -> HOTCHO BENJAMIN | D15: =IF(G15="ECHEC",0,B$3) -> 25000 | E15: =D15+VLOOKUP($A15,[6]HISTOJANV23!$A$7:$AU$40,45,0)+F15 -> 75000 | F15: =VLOOKUP($A15,[6]HISTOJANV23!$A$7:$AU$45,7,0) -> 0 | G15: =VLOOKUP($A15,[6]HISTOJANV23!$A$7:$AU$45,8,0) -> BANQUE | H15: =VLOOKUP($A15,[6]HISTOJANV23!$A$6:$AU$45,35,0) -> 0 | I15: =VLOOKUP($A15,[6]HISTOJANV23!$A$7:$AU$45,38,0) -> 0 | J15: =IF(I15=0,0,VLOOKUP($A15,[6]HISTOJANV23!$A$7:$AU$45,42,0)) -> 0 | K15: =VLOOKUP($A15,[6]HISTOJANV23!$A$7:$AU$45,41,0) -> 0 | M15: =VLOOKUP($A15,[6]HISTOJANV23!$A$7:$AU$45,16,0) -> 0 | N15: =IF(M15<>0,VLOOKUP($A15,[6]HISTOJANV23!$A$7:$AU$45,8,0),"ECHEC") -> ECHEC | O15: =IF(R15=0,0,VLOOKUP($A15,[6]HISTOJANV23!$A$7:$AU$45,32,0)) -> 0 | P15: =VLOOKUP($A15,[6]HISTOJANV23!$A$7:$AU$45,33,0) -> 0 | Q15: =IF(R15=0,0,($C$3-R15)) -> 0 | R15: =VLOOKUP($A15,[6]HISTOJANV23!$A$7:$AU$45,29,0) -> 0
A16: AS201617 | B16: =IF(D16=0,0,VLOOKUP($A16,[6]HISTOJANV23!$A$6:$BO$40,10,0)) -> 1 | C16: =VLOOKUP(A16,[7]LISTADHERENT!A$5:H$60,3,0) -> KOUAMOU MOISE | D16: =IF(G16="ECHEC",0,B$3) -> 25000 | E16: =D16+VLOOKUP($A16,[6]HISTOJANV23!$A$7:$AU$40,45,0)+F16 -> 40000 | F16: =VLOOKUP($A16,[6]HISTOJANV23!$A$7:$AU$45,7,0) -> 0 | G16: =VLOOKUP($A16,[6]HISTOJANV23!$A$7:$AU$45,8,0) -> BANQUE | H16: =VLOOKUP($A16,[6]HISTOJANV23!$A$6:$AU$45,35,0) -> 0 | I16: =VLOOKUP($A16,[6]HISTOJANV23!$A$7:$AU$45,38,0) -> 0 | J16: =IF(I16=0,0,VLOOKUP($A16,[6]HISTOJANV23!$A$7:$AU$45,42,0)) -> 0 | K16: =VLOOKUP($A16,[6]HISTOJANV23!$A$7:$AU$45,41,0) -> 0 | M16: =VLOOKUP($A16,[6]HISTOJANV23!$A$7:$AU$45,16,0) -> 0 | N16: =IF(M16<>0,VLOOKUP($A16,[6]HISTOJANV23!$A$7:$AU$45,8,0),"ECHEC") -> ECHEC | O16: =IF(R16=0,0,VLOOKUP($A16,[6]HISTOJANV23!$A$7:$AU$45,32,0)) -> 0 | P16: =VLOOKUP($A16,[6]HISTOJANV23!$A$7:$AU$45,33,0) -> 0 | Q16: =IF(R16=0,0,($C$3-R16)) -> 0 | R16: =VLOOKUP($A16,[6]HISTOJANV23!$A$7:$AU$45,29,0) -> 0
A17: AS201619 | B17: =IF(D17=0,0,VLOOKUP($A17,[6]HISTOJANV23!$A$6:$BO$40,10,0)) -> 1 | C17: =VLOOKUP(A17,[7]LISTADHERENT!A$5:H$60,3,0) -> KOUATCHO MESSACK | D17: =IF(G17="ECHEC",0,B$3) -> 25000 | E17: =D17+VLOOKUP($A17,[6]HISTOJANV23!$A$7:$AU$40,45,0)+F17 -> 40000 | F17: =VLOOKUP($A17,[6]HISTOJANV23!$A$7:$AU$45,7,0) -> 0 | G17: =VLOOKUP($A17,[6]HISTOJANV23!$A$7:$AU$45,8,0) -> BANQUE | H17: =VLOOKUP($A17,[6]HISTOJANV23!$A$6:$AU$45,35,0) -> 0 | I17: =VLOOKUP($A17,[6]HISTOJANV23!$A$7:$AU$45,38,0) -> 0 | J17: =IF(I17=0,0,VLOOKUP($A17,[6]HISTOJANV23!$A$7:$AU$45,42,0)) -> 0 | K17: =VLOOKUP($A17,[6]HISTOJANV23!$A$7:$AU$45,41,0) -> 0 | M17: =VLOOKUP($A17,[6]HISTOJANV23!$A$7:$AU$45,16,0) -> 0 | N17: =IF(M17<>0,VLOOKUP($A17,[6]HISTOJANV23!$A$7:$AU$45,8,0),"ECHEC") -> ECHEC | O17: =IF(R17=0,0,VLOOKUP($A17,[6]HISTOJANV23!$A$7:$AU$45,32,0)) -> BANQUE | P17: =VLOOKUP($A17,[6]HISTOJANV23!$A$7:$AU$45,33,0) -> 0 | Q17: =IF(R17=0,0,($C$3-R17)) -> 286000 | R17: =VLOOKUP($A17,[6]HISTOJANV23!$A$7:$AU$45,29,0) -> 40000
... A35: AS201647 | B35: =IF(D35=0,0,VLOOKUP($A35,[6]HISTOJANV23!$A$6:$BO$40,10,0)) -> 1 | C35: =VLOOKUP(A35,[7]LISTADHERENT!A$5:H$60,3,0) -> YOUMBI EMMANUEL | D35: =IF(G35="ECHEC",0,B$3) -> 25000 | E35: =D35+VLOOKUP($A35,[6]HISTOJANV23!$A$7:$AU$40,45,0)+F35 -> 40000 | F35: =VLOOKUP($A35,[6]HISTOJANV23!$A$7:$AU$45,7,0) -> 0 | G35: =VLOOKUP($A35,[6]HISTOJANV23!$A$7:$AU$45,8,0) -> BANQUE | H35: =VLOOKUP($A35,[6]HISTOJANV23!$A$6:$AU$45,35,0) -> 0 | I35: =VLOOKUP($A35,[6]HISTOJANV23!$A$7:$AU$45,38,0) -> 0 | J35: =IF(I35=0,0,VLOOKUP($A35,[6]HISTOJANV23!$A$7:$AU$45,42,0)) -> 0 | K35: =VLOOKUP($A35,[6]HISTOJANV23!$A$7:$AU$45,41,0) -> 0 | M35: =VLOOKUP($A35,[6]HISTOJANV23!$A$7:$AU$45,16,0) -> 0 | N35: =IF(M35<>0,VLOOKUP($A35,[6]HISTOJANV23!$A$7:$AU$45,8,0),"ECHEC") -> ECHEC | O35: =IF(R35=0,0,VLOOKUP($A35,[6]HISTOJANV23!$A$7:$AU$45,32,0)) -> 0 | P35: =VLOOKUP($A35,[6]HISTOJANV23!$A$7:$AU$45,33,0) -> 0 | Q35: =IF(R35=0,0,($C$3-R35)) -> 0 | R35: =VLOOKUP($A35,[6]HISTOJANV23!$A$7:$AU$45,29,0) -> 0
A37: TOTAL PART | B37: =SUM(B6:B36) -> 30
A38: NBRE ADHERENT | B38: =COUNT(D6:D35) -> 30 | D38: =SUM(D6:D37) -> 750000 | E38: =SUM(E6:E37) -> 1444000 | F38: =SUM(F6:F37) -> 0 | H38: =SUM(H6:H37) -> 235000 | I38: =SUM(I6:I37) -> 9000 | L38: =SUM(L6:L37) -> 0 | M38: =SUM(M6:M37) -> 0 | N38: =SUM(N6:N37) -> 0 | O38: =SUM(O6:O37) -> 0 | P38: =SUM(P6:P37) -> 0 | Q38: =SUM(Q6:Q37) -> 567000 | R38: =SUM(R6:R37) -> 85000
N39: NBRE PART | O39: PART VENDUE
D40: MONTANT TONTINE | E40: MONTANT VERSE | G40: REMBOURSEMENT PETIT LOT | H40: VENTE PETIT LOT | I40: VENTE LOT PRINCIPAL | J40: SOLDE EN CAISSE | L40: TONTINE + REMB + INTERET VENTE | M40: =D44+G44+R38 -> 835000
D41: =SUMIFS(D6:D37,G6:G37,"ESPECES") -> 125000 | E41: =SUMIFS(E6:E37,G6:G37,"ESPECES") -> 264000 | F41: ESPECES | G41: =SUMIFS(M6:M35,N6:N35,"ESPECES") -> 0 | H41: =SUMIFS(H6:H37,J6:J37,"ESPECES") -> 0 | I41: =SUMIFS(Q6:Q37,O6:O37,"ESPECES") -> 0 | J41: =D41+G41-H41-I41 -> 125000 | L41: LOT PRINCIPAL | M41: =C3*COUNTIF(Q6:Q37,">0") -> 652000 | N41: =D3 -> 2 | O41: =COUNTIF(Q6:Q35,">0") -> 2
D42: =SUMIFS(D6:D37,G6:G37,"BANQUE") -> 625000 | E42: =SUMIFS(E6:E38,G6:G38,"BANQUE") -> 1180000 | F42: BANQUE | G42: =SUMIFS(M6:M35,N6:N35,"BANQUE") -> 0 | H42: =SUMIFS(H6:H37,J6:J37,"BANQUE") -> 235000 | I42: =SUMIFS(Q6:Q37,O6:O37,"BANQUE") -> 567000 | J42: =D42+G42-H42-I42 -> -177000
L43: PETIT LOT | M43: =M40-M41 -> 183000
D44: =D41+D42 -> 750000 | E44: =E41+E42 -> 1444000 | F44: TOTAL | G44: =G41+G42 -> 0 | H44: =H41+H42 -> 235000 | I44: =I41+I42 -> 567000 | J44: =J41+J42 -> -52000
F45: TOTAL+DEPOT | L45: RELIQUAT | M45: =M43-H38 -> -52000 | O45: =M45 -> -52000 | P45: CUMUL
L47: ECHEC TONTINE MOIS | M47: =COUNTIFS(G6:G36,"ECHEC")*25000 -> 0 | P47: CUMUL
L48: ECHEC REMBOURSEMENT MOIS | M48: =L38-G44 -> 0 | P48: CUMUL

Sheet TONTFEV23
A1: ASSOCIATION | B1: ASELBY
A2: ANNEE | B2: 2023 | C2: TONIINE | D2: NBRE PART
A3: TAUX TONTINE | B3: 25000 | C3: =B3*13+1000 -> 326000 | D3: =ROUNDDOWN(M40/C3,0) -> 3
C4: 44939
A5: MATRICULE | B5: NBREPART | C5: NOM ET PRENOM | D5: MONTANT TONTINE | E5: MONTANT VERSE | F5: PENALITE VERSEMENT ESPECES | G5: MODE VERSEMENT | H5: VENTE PETIT LOT | I5: INTERET PETIT LOT | J5: MODE VERSEMENT VENTE PETIT LOT | K5: NUMERO CHEQUE | L5: MONTANT A REMBOURSER PETIT LOT | M5: REMBOURSEMENT PETIT LOT | N5: MODE VERSEMENT REMBOURSEMENT | O5: MODE VERSEMENTLOT PRINCIPAL | P5: NUMERO CHEQUE | Q5: MONTANT LOT PRINCIPAL | R5: INTERET LOT PRINCIPAL
A6: AS201601 | B6: =IF(D6=0,0,VLOOKUP($A6,[6]HISTOFEV23!$A$6:$BO$40,10,0)) -> 1 | C6: =VLOOKUP(A6,[7]LISTADHERENT!A$5:H$60,3,0) -> BAKOP ACHILLE | D6: =IF(G6="ECHEC",0,B$3) -> 25000 | E6: =D6+VLOOKUP($A6,[6]HISTOFEV23!$A$7:$AU$40,45,0)+F6 -> 40000 | F6: =VLOOKUP($A6,[6]HISTOFEV23!$A$7:$AU$45,7,0) -> 0 | G6: =VLOOKUP($A6,[6]HISTOFEV23!$A$7:$AU$45,8,0) -> ESPECES | H6: =VLOOKUP($A6,[6]HISTOFEV23!$A$6:$AU$45,35,0) -> 0 | I6: =VLOOKUP($A6,[6]HISTOFEV23!$A$7:$AU$45,38,0) -> 0 | J6: =IF(I6=0,0,VLOOKUP($A6,[6]HISTOFEV23!$A$7:$AU$45,42,0)) -> 0 | K6: =VLOOKUP($A6,[6]HISTOFEV23!$A$7:$AU$45,41,0) -> 0 | L6: =TONTJANV23!H6+TONTJANV23!I6 -> 0 | M6: =VLOOKUP($A6,[6]HISTOFEV23!$A$7:$AU$45,16,0) -> 0 | N6: =IF(M6<>0,VLOOKUP($A6,[6]HISTOFEV23!$A$7:$AU$45,8,0),"ECHEC") -> ECHEC | O6: =IF(R6=0,0,VLOOKUP($A6,[6]HISTOFEV23!$A$7:$AU$45,32,0)) -> 0 | P6: =VLOOKUP($A6,[6]HISTOFEV23!$A$7:$AU$45,33,0) -> 0 | Q6: =IF(R6=0,0,($C$3-R6)) -> 0 | R6: =VLOOKUP($A6,[6]HISTOFEV23!$A$7:$AU$45,29,0) -> 0
A7: AS201602 | B7: =IF(D7=0,0,VLOOKUP($A7,[6]HISTOFEV23!$A$6:$BO$40,10,0)) -> 1 | C7: =VLOOKUP(A7,[7]LISTADHERENT!A$5:H$60,3,0) -> BOUTCHOUANG WILLIAM | D7: =IF(G7="ECHEC",0,B$3) -> 25000 | E7: =D7+VLOOKUP($A7,[6]HISTOFEV23!$A$7:$AU$40,45,0)+F7 -> 40000 | F7: =VLOOKUP($A7,[6]HISTOFEV23!$A$7:$AU$45,7,0) -> 0 | G7: =VLOOKUP($A7,[6]HISTOFEV23!$A$7:$AU$45,8,0) -> BANQUE | H7: =VLOOKUP($A7,[6]HISTOFEV23!$A$6:$AU$45,35,0) -> 0 | I7: =VLOOKUP($A7,[6]HISTOFEV23!$A$7:$AU$45,38,0) -> 0 | J7: =IF(I7=0,0,VLOOKUP($A7,[6]HISTOFEV23!$A$7:$AU$45,42,0)) -> 0 | K7: =VLOOKUP($A7,[6]HISTOFEV23!$A$7:$AU$45,41,0) -> 0 | L7: =TONTJANV23!H7+TONTJANV23!I7 -> 0 | M7: =VLOOKUP($A7,[6]HISTOFEV23!$A$7:$AU$45,16,0) -> 0 | N7: =IF(M7<>0,VLOOKUP($A7,[6]HISTOFEV23!$A$7:$AU$45,8,0),"ECHEC") -> ECHEC | O7: =IF(R7=0,0,VLOOKUP($A7,[6]HISTOFEV23!$A$7:$AU$45,32,0)) -> 0 | P7: =VLOOKUP($A7,[6]HISTOFEV23!$A$7:$AU$45,33,0) -> 0 | Q7: =IF(R7=0,0,($C$3-R7)) -> 0 | R7: =VLOOKUP($A7,[6]HISTOFEV23!$A$7:$AU$45,29,0) -> 0
A8: AS201604 | B8: =IF(D8=0,0,VLOOKUP($A8,[6]HISTOFEV23!$A$6:$BO$40,10,0)) -> 1 | C8: =VLOOKUP(A8,[7]LISTADHERENT!A$5:H$60,3,0) -> DJOMO JEAN PAUL | D8: =IF(G8="ECHEC",0,B$3) -> 25000 | E8: =D8+VLOOKUP($A8,[6]HISTOFEV23!$A$7:$AU$40,45,0)+F8 -> 48000 | F8: =VLOOKUP($A8,[6]HISTOFEV23!$A$7:$AU$45,7,0) -> 0 | G8: =VLOOKUP($A8,[6]HISTOFEV23!$A$7:$AU$45,8,0) -> BANQUE | H8: =VLOOKUP($A8,[6]HISTOFEV23!$A$6:$AU$45,35,0) -> 0 | I8: =VLOOKUP($A8,[6]HISTOFEV23!$A$7:$AU$45,38,0) -> 0 | J8: =IF(I8=0,0,VLOOKUP($A8,[6]HISTOFEV23!$A$7:$AU$45,42,0)) -> 0 | K8: =VLOOKUP($A8,[6]HISTOFEV23!$A$7:$AU$45,41,0) -> 0 | L8: =TONTJANV23!H8+TONTJANV23!I8 -> 0 | M8: =VLOOKUP($A8,[6]HISTOFEV23!$A$7:$AU$45,16,0) -> 0 | N8: =IF(M8<>0,VLOOKUP($A8,[6]HISTOFEV23!$A$7:$AU$45,8,0),"ECHEC") -> ECHEC | O8: =IF(R8=0,0,VLOOKUP($A8,[6]HISTOFEV23!$A$7:$AU$45,32,0)) -> 0 | P8: =VLOOKUP($A8,[6]HISTOFEV23!$A$7:$AU$45,33,0) -> 0 | Q8: =IF(R8=0,0,($C$3-R8)) -> 0 | R8: =VLOOKUP($A8,[6]HISTOFEV23!$A$7:$AU$45,29,0) -> 0
A9: AS201654 | B9: =IF(D9=0,0,VLOOKUP($A9,[6]HISTOFEV23!$A$6:$BO$40,10,0)) -> 1 | C9: =VLOOKUP(A9,[7]LISTADHERENT!A$5:H$60,3,0) -> DJOMOU TCHAPDA | D9: =IF(G9="ECHEC",0,B$3) -> 25000 | E9: =D9+VLOOKUP($A9,[6]HISTOFEV23!$A$7:$AU$40,45,0)+F9 -> 40000 | F9: =VLOOKUP($A9,[6]HISTOFEV23!$A$7:$AU$45,7,0) -> 0 | G9: =VLOOKUP($A9,[6]HISTOFEV23!$A$7:$AU$45,8,0) -> BANQUE | H9: =VLOOKUP($A9,[6]HISTOFEV23!$A$6:$AU$45,35,0) -> 40000 | I9: =VLOOKUP($A9,[6]HISTOFEV23!$A$7:$AU$45,38,0) -> 1000 | J9: =IF(I9=0,0,VLOOKUP($A9,[6]HISTOFEV23!$A$7:$AU$45,42,0)) -> BANQUE | K9: =VLOOKUP($A9,[6]HISTOFEV23!$A$7:$AU$45,41,0) -> 0 | L9: =TONTJANV23!H9+TONTJANV23!I9 -> 63000 | M9: =VLOOKUP($A9,[6]HISTOFEV23!$A$7:$AU$45,16,0) -> 63000 | N9: =IF(M9<>0,VLOOKUP($A9,[6]HISTOFEV23!$A$7:$AU$45,8,0),"ECHEC") -> BANQUE | O9: =IF(R9=0,0,VLOOKUP($A9,[6]HISTOFEV23!$A$7:$AU$45,32,0)) -> 0 | P9: =VLOOKUP($A9,[6]HISTOFEV23!$A$7:$AU$45,33,0) -> 0 | Q9: =IF(R9=0,0,($C$3-R9)) -> 0 | R9: =VLOOKUP($A9,[6]HISTOFEV23!$A$7:$AU$45,29,0) -> 0
A10: AS201605 | B10: =IF(D10=0,0,VLOOKUP($A10,[6]HISTOFEV23!$A$6:$BO$40,10,0)) -> 1 | C10: =VLOOKUP(A10,[7]LISTADHERENT!A$5:H$60,3,0) -> DJOUKWE NANGUEN GUY BLAISE | D10: =IF(G10="ECHEC",0,B$3) -> 25000 | E10: =D10+VLOOKUP($A10,[6]HISTOFEV23!$A$7:$AU$40,45,0)+F10 -> 40000 | F10: =VLOOKUP($A10,[6]HISTOFEV23!$A$7:$AU$45,7,0) -> 0 | G10: =VLOOKUP($A10,[6]HISTOFEV23!$A$7:$AU$45,8,0) -> BANQUE | H10: =VLOOKUP($A10,[6]HISTOFEV23!$A$6:$AU$45,35,0) -> 0 | I10: =VLOOKUP($A10,[6]HISTOFEV23!$A$7:$AU$45,38,0) -> 0 | J10: =IF(I10=0,0,VLOOKUP($A10,[6]HISTOFEV23!$A$7:$AU$45,42,0)) -> 0 | K10: =VLOOKUP($A10,[6]HISTOFEV23!$A$7:$AU$45,41,0) -> 0 | L10: =TONTJANV23!H10+TONTJANV23!I10 -> 62000 | M10: =VLOOKUP($A10,[6]HISTOFEV23!$A$7:$AU$45,16,0) -> 62000 | N10: =IF(M10<>0,VLOOKUP($A10,[6]HISTOFEV23!$A$7:$AU$45,8,0),"ECHEC") -> BANQUE | O10: =IF(R10=0,0,VLOOKUP($A10,[6]HISTOFEV23!$A$7:$AU$45,32,0)) -> 0 | P10: =VLOOKUP($A10,[6]HISTOFEV23!$A$7:$AU$45,33,0) -> 0 | Q10: =IF(R10=0,0,($C$3-R10)) -> 0 | R10: =VLOOKUP($A10,[6]HISTOFEV23!$A$7:$AU$45,29,0) -> 0
A11: AS201608 | B11: =IF(D11=0,0,VLOOKUP($A11,[6]HISTOFEV23!$A$6:$BO$40,10,0)) -> 1 | C11: =VLOOKUP(A11,[7]LISTADHERENT!A$5:H$60,3,0) -> DJUOMBESSY ANTOINE | D11: =IF(G11="ECHEC",0,B$3) -> 25000 | E11: =D11+VLOOKUP($A11,[6]HISTOFEV23!$A$7:$AU$40,45,0)+F11 -> 45000 | F11: =VLOOKUP($A11,[6]HISTOFEV23!$A$7:$AU$45,7,0) -> 0 | G11: =VLOOKUP($A11,[6]HISTOFEV23!$A$7:$AU$45,8,0) -> BANQUE | H11: =VLOOKUP($A11,[6]HISTOFEV23!$A$6:$AU$45,35,0) -> 0 | I11: =VLOOKUP($A11,[6]HISTOFEV23!$A$7:$AU$45,38,0) -> 0 | J11: =IF(I11=0,0,VLOOKUP($A11,[6]HISTOFEV23!$A$7:$AU$45,42,0)) -> 0 | K11: =VLOOKUP($A11,[6]HISTOFEV23!$A$7:$AU$45,41,0) -> 0 | L11: =TONTJANV23!H11+TONTJANV23!I11 -> 0 | M11: =VLOOKUP($A11,[6]HISTOFEV23!$A$7:$AU$45,16,0) -> 0 | N11: =IF(M11<>0,VLOOKUP($A11,[6]HISTOFEV23!$A$7:$AU$45,8,0),"ECHEC") -> ECHEC | O11: =IF(R11=0,0,VLOOKUP($A11,[6]HISTOFEV23!$A$7:$AU$45,32,0)) -> 0 | P11: =VLOOKUP($A11,[6]HISTOFEV23!$A$7:$AU$45,33,0) -> 0 | Q11: =IF(R11=0,0,($C$3-R11)) -> 0 | R11: =VLOOKUP($A11,[6]HISTOFEV23!$A$7:$AU$45,29,0) -> 0
A12: AS201651 | B12: =IF(D12=0,0,VLOOKUP($A12,[6]HISTOFEV23!$A$6:$BO$40,10,0)) -> 1 | C12: =VLOOKUP(A12,[7]LISTADHERENT!A$5:H$60,3,0) -> DOMOU FABIEN | D12: =IF(G12="ECHEC",0,B$3) -> 25000 | E12: =D12+VLOOKUP($A12,[6]HISTOFEV23!$A$7:$AU$40,45,0)+F12 -> 40000 | F12: =VLOOKUP($A12,[6]HISTOFEV23!$A$7:$AU$45,7,0) -> 0 | G12: =VLOOKUP($A12,[6]HISTOFEV23!$A$7:$AU$45,8,0) -> ESPECES | H12: =VLOOKUP($A12,[6]HISTOFEV23!$A$6:$AU$45,35,0) -> 0 | I12: =VLOOKUP($A12,[6]HISTOFEV23!$A$7:$AU$45,38,0) -> 0 | J12: =IF(I12=0,0,VLOOKUP($A12,[6]HISTOFEV23!$A$7:$AU$45,42,0)) -> 0 | K12: =VLOOKUP($A12,[6]HISTOFEV23!$A$7:$AU$45,41,0) -> 0 | L12: =TONTJANV23!H12+TONTJANV23!I12 -> 0 | M12: =VLOOKUP($A12,[6]HISTOFEV23!$A$7:$AU$45,16,0) -> 0 | N12: =IF(M12<>0,VLOOKUP($A12,[6]HISTOFEV23!$A$7:$AU$45,8,0),"ECHEC") -> ECHEC | O12: =IF(R12=0,0,VLOOKUP($A12,[6]HISTOFEV23!$A$7:$AU$45,32,0)) -> 0 | P12: =VLOOKUP($A12,[6]HISTOFEV23!$A$7:$AU$45,33,0) -> 0 | Q12: =IF(R12=0,0,($C$3-R12)) -> 0 | R12: =VLOOKUP($A12,[6]HISTOFEV23!$A$7:$AU$45,29,0) -> 0
A13: AS201609 | B13: =IF(D13=0,0,VLOOKUP($A13,[6]HISTOFEV23!$A$6:$BO$40,10,0)) -> 1 | C13: =VLOOKUP(A13,[7]LISTADHERENT!A$5:H$60,3,0) -> DONHOU DAVID | D13: =IF(G13="ECHEC",0,B$3) -> 25000 | E13: =D13+VLOOKUP($A13,[6]HISTOFEV23!$A$7:$AU$40,45,0)+F13 -> 40000 | F13: =VLOOKUP($A13,[6]HISTOFEV23!$A$7:$AU$45,7,0) -> 0 | G13: =VLOOKUP($A13,[6]HISTOFEV23!$A$7:$AU$45,8,0) -> BANQUE | H13: =VLOOKUP($A13,[6]HISTOFEV23!$A$6:$AU$45,35,0) -> 0 | I13: =VLOOKUP($A13,[6]HISTOFEV23!$A$7:$AU$45,38,0) -> 0 | J13: =IF(I13=0,0,VLOOKUP($A13,[6]HISTOFEV23!$A$7:$AU$45,42,0)) -> 0 | K13: =VLOOKUP($A13,[6]HISTOFEV23!$A$7:$AU$45,41,0) -> 0 | L13: =TONTJANV23!H13+TONTJANV23!I13 -> 0 | M13: =VLOOKUP($A13,[6]HISTOFEV23!$A$7:$AU$45,16,0) -> 0 | N13: =IF(M13<>0,VLOOKUP($A13,[6]HISTOFEV23!$A$7:$AU$45,8,0),"ECHEC") -> ECHEC | O13: =IF(R13=0,0,VLOOKUP($A13,[6]HISTOFEV23!$A$7:$AU$45,32,0)) -> 0 | P13: =VLOOKUP($A13,[6]HISTOFEV23!$A$7:$AU$45,33,0) -> 0 | Q13: =IF(R13=0,0,($C$3-R13)) -> 0 | R13: =VLOOKUP($A13,[6]HISTOFEV23!$A$7:$AU$45,29,0) -> 0
A14: AS201611 | B14: =IF(D14=0,0,VLOOKUP($A14,[6]HISTOFEV23!$A$6:$BO$40,10,0)) -> 1 | C14: =VLOOKUP(A14,[7]LISTADHERENT!A$5:H$60,3,0) -> HENGUE PAUL OMER | D14: =IF(G14="ECHEC",0,B$3) -> 25000 | E14: =D14+VLOOKUP($A14,[6]HISTOFEV23!$A$7:$AU$40,45,0)+F14 -> 40000 | F14: =VLOOKUP($A14,[6]HISTOFEV23!$A$7:$AU$45,7,0) -> 0 | G14: =VLOOKUP($A14,[6]HISTOFEV23!$A$7:$AU$45,8,0) -> BANQUE | H14: =VLOOKUP($A14,[6]HISTOFEV23!$A$6:$AU$45,35,0) -> 0 | I14: =VLOOKUP($A14,[6]HISTOFEV23!$A$7:$AU$45,38,0) -> 0 | J14: =IF(I14=0,0,VLOOKUP($A14,[6]HISTOFEV23!$A$7:$AU$45,42,0)) -> 0 | K14: =VLOOKUP($A14,[6]HISTOFEV23!$A$7:$AU$45,41,0) -> 0 | L14: =TONTJANV23!H14+TONTJANV23!I14 -> 0 | M14: =VLOOKUP($A14,[6]HISTOFEV23!$A$7:$AU$45,16,0) -> 0 | N14: =IF(M14<>0,VLOOKUP($A14,[6]HISTOFEV23!$A$7:$AU$45,8,0),"ECHEC") -> ECHEC | O14: =IF(R14=0,0,VLOOKUP($A14,[6]HISTOFEV23!$A$7:$AU$45,32,0)) -> 0 | P14: =VLOOKUP($A14,[6]HISTOFEV23!$A$7:$AU$45,33,0) -> 0 | Q14: =IF(R14=0,0,($C$3-R14)) -> 0 | R14: =VLOOKUP($A14,[6]HISTOFEV23!$A$7:$AU$45,29,0) -> 0
A15: AS201613 | B15: =IF(D15=0,0,VLOOKUP($A15,[6]HISTOFEV23!$A$6:$BO$40,10,0)) -> 1 | C15: =VLOOKUP(A15,[7]LISTADHERENT!A$5:H$60,3,0) -> HOTCHO BENJAMIN | D15: =IF(G15="ECHEC",0,B$3) -> 25000 | E15: =D15+VLOOKUP($A15,[6]HISTOFEV23!$A$7:$AU$40,45,0)+F15 -> 75000 | F15: =VLOOKUP($A15,[6]HISTOFEV23!$A$7:$AU$45,7,0) -> 0 | G15: =VLOOKUP($A15,[6]HISTOFEV23!$A$7:$AU$45,8,0) -> BANQUE | H15: =VLOOKUP($A15,[6]HISTOFEV23!$A$6:$AU$45,35,0) -> 0 | I15: =VLOOKUP($A15,[6]HISTOFEV23!$A$7:$AU$45,38,0) -> 0 | J15: =IF(I15=0,0,VLOOKUP($A15,[6]HISTOFEV23!$A$7:$AU$45,42,0)) -> 0 | K15: =VLOOKUP($A15,[6]HISTOFEV23!$A$7:$AU$45,41,0) -> 0 | L15: =TONTJANV23!H15+TONTJANV23!I15 -> 0 | M15: =VLOOKUP($A15,[6]HISTOFEV23!$A$7:$AU$45,16,0) -> 0 | N15: =IF(M15<>0,VLOOKUP($A15,[6]HISTOFEV23!$A$7:$AU$45,8,0),"ECHEC") -> ECHEC | O15: =IF(R15=0,0,VLOOKUP($A15,[6]HISTOFEV23!$A$7:$AU$45,32,0)) -> 0 | P15: =VLOOKUP($A15,[6]HISTOFEV23!$A$7:$AU$45,33,0) -> 0 | Q15: =IF(R15=0,0,($C$3-R15)) -> 0 | R15: =VLOOKUP($A15,[6]HISTOFEV23!$A$7:$AU$45,29,0) -> 0
A16: AS201617 | B16: =IF(D16=0,0,VLOOKUP($A16,[6]HISTOFEV23!$A$6:$BO$40,10,0)) -> 1 | C16: =VLOOKUP(A16,[7]LISTADHERENT!A$5:H$60,3,0) -> KOUAMOU MOISE | D16: =IF(G16="ECHEC",0,B$3) -> 25000 | E16: =D16+VLOOKUP($A16,[6]HISTOFEV23!$A$7:$AU$40,45,0)+F16 -> 40000 | F16: =VLOOKUP($A16,[6]HISTOFEV23!$A$7:$AU$45,7,0) -> 0 | G16: =VLOOKUP($A16,[6]HISTOFEV23!$A$7:$AU$45,8,0) -> BANQUE | H16: =VLOOKUP($A16,[6]HISTOFEV23!$A$6:$AU$45,35,0) -> 0 | I16: =VLOOKUP($A16,[6]HISTOFEV23!$A$7:$AU$45,38,0) -> 0 | J16: =IF(I16=0,0,VLOOKUP($A16,[6]HISTOFEV23!$A$7:$AU$45,42,0)) -> 0 | K16: =VLOOKUP($A16,[6]HISTOFEV23!$A$7:$AU$45,41,0) -> 0 | L16: =TONTJANV23!H16+TONTJANV23!I16 -> 0 | M16: =VLOOKUP($A16,[6]HISTOFEV23!$A$7:$AU$45,16,0) -> 0 | N16: =IF(M16<>0,VLOOKUP($A16,[6]HISTOFEV23!$A$7:$AU$45,8,0),"ECHEC") -> ECHEC | O16: =IF(R16=0,0,VLOOKUP($A16,[6]HISTOFEV23!$A$7:$AU$45,32,0)) -> BANQUE | P16: =VLOOKUP($A16,[6]HISTOFEV23!$A$7:$AU$45,33,0) -> 0 | Q16: =IF(R16=0,0,($C$3-R16)) -> 319500 | R16: =VLOOKUP($A16,[6]HISTOFEV23!$A$7:$AU$45,29,0) -> 6500
A17: AS201619 | B17: =IF(D17=0,0,VLOOKUP($A17,[6]HISTOFEV23!$A$6:$BO$40,10,0)) -> 1 | C17: =VLOOKUP(A17,[7]LISTADHERENT!A$5:H$60,3,0) -> KOUATCHO MESSACK | D17: =IF(G17="ECHEC",0,B$3) -> 25000 | E17: =D17+VLOOKUP($A17,[6]HISTOFEV23!$A$7:$AU$40,45,0)+F17 -> 40000 | F17: =VLOOKUP($A17,[6]HISTOFEV23!$A$7:$AU$45,7,0) -> 0 | G17: =VLOOKUP($A17,[6]HISTOFEV23!$A$7:$AU$45,8,0) -> BANQUE | H17: =VLOOKUP($A17,[6]HISTOFEV23!$A$6:$AU$45,35,0) -> 0 | I17: =VLOOKUP($A17,[6]HISTOFEV23!$A$7:$AU$45,38,0) -> 0 | J17: =IF(I17=0,0,VLOOKUP($A17,[6]HISTOFEV23!$A$7:$AU$45,42,0)) -> 0 | K17: =VLOOKUP($A17,[6]HISTOFEV23!$A$7:$AU$45,41,0) -> 0 | L17: =TONTJANV23!H17+TONTJANV23!I17 -> 0 | M17: =VLOOKUP($A17,[6]HISTOFEV23!$A$7:$AU$45,16,0) -> 0 | N17: =IF(M17<>0,VLOOKUP($A17,[6]HISTOFEV23!$A$7:$AU$45,8,0),"ECHEC") -> ECHEC | O17: =IF(R17=0,0,VLOOKUP($A17,[6]HISTOFEV23!$A$7:$AU$45,32,0)) -> 0 | P17: =VLOOKUP($A17,[6]HISTOFEV23!$A$7:$AU$45,33,0) -> 0 | Q17: =IF(R17=0,0,($C$3-R17)) -> 0 | R17: =VLOOKUP($A17,[6]HISTOFEV23!$A$7:$AU$45,29,0) -> 0
... A35: AS201647 | B35: =IF(D35=0,0,VLOOKUP($A35,[6]HISTOFEV23!$A$6:$BO$40,10,0)) -> 1 | C35: =VLOOKUP(A35,[7]LISTADHERENT!A$5:H$60,3,0) -> YOUMBI EMMANUEL | D35: =IF(G35="ECHEC",0,B$3) -> 25000 | E35: =D35+VLOOKUP($A35,[6]HISTOFEV23!$A$7:$AU$40,45,0)+F35 -> 40000 | F35: =VLOOKUP($A35,[6]HISTOFEV23!$A$7:$AU$45,7,0) -> 0 | G35: =VLOOKUP($A35,[6]HISTOFEV23!$A$7:$AU$45,8,0) -> BANQUE | H35: =VLOOKUP($A35,[6]HISTOFEV23!$A$6:$AU$45,35,0) -> 0 | I35: =VLOOKUP($A35,[6]HISTOFEV23!$A$7:$AU$45,38,0) -> 0 | J35: =IF(I35=0,0,VLOOKUP($A35,[6]HISTOFEV23!$A$7:$AU$45,42,0)) -> 0 | K35: =VLOOKUP($A35,[6]HISTOFEV23!$A$7:$AU$45,41,0) -> 0 | L35: =TONTJANV23!H35+TONTJANV23!I35 -> 0 | M35: =VLOOKUP($A35,[6]HISTOFEV23!$A$7:$AU$45,16,0) -> 0 | N35: =IF(M35<>0,VLOOKUP($A35,[6]HISTOFEV23!$A$7:$AU$45,8,0),"ECHEC") -> ECHEC | O35: =IF(R35=0,0,VLOOKUP($A35,[6]HISTOFEV23!$A$7:$AU$45,32,0)) -> 0 | P35: =VLOOKUP($A35,[6]HISTOFEV23!$A$7:$AU$45,33,0) -> 0 | Q35: =IF(R35=0,0,($C$3-R35)) -> 0 | R35: =VLOOKUP($A35,[6]HISTOFEV23!$A$7:$AU$45,29,0) -> 0
A37: TOTAL PART | B37: =SUM(B6:B36) -> 30
A38: NBRE ADHERENT | B38: =COUNT(D6:D35) -> 30 | D38: =SUM(D6:D37) -> 750000 | E38: =SUM(E6:E37) -> 1258000 | F38: =SUM(F6:F37) -> 0 | H38: =SUM(H6:H37) -> 111500 | I38: =SUM(I6:I37) -> 3000 | L38: =SUM(L6:L37) -> 244000 | M38: =SUM(M6:M37) -> 244000 | N38: =SUM(N6:N37) -> 0 | O38: =SUM(O6:O37) -> 0 | P38: =SUM(P6:P37) -> 0 | Q38: =SUM(Q6:Q37) -> 960500 | R38: =SUM(R6:R37) -> 17500
N39: NBRE PART | O39: PART VENDUE
D40: MONTANT TONTINE | E40: MONTANT VERSE | G40: REMBOURSEMENT PETIT LOT | H40: VENTE PETIT LOT | I40: VENTE LOT PRINCIPAL | J40: SOLDE EN CAISSE | L40: TONTINE + REMB + INTERET VENTE | M40: =D44+G44+R38 -> 1011500
D41: =SUMIFS(D6:D37,G6:G37,"ESPECES") -> 150000 | E41: =SUMIFS(E6:E37,G6:G37,"ESPECES") -> 240000 | F41: ESPECES | G41: =SUMIFS(M6:M35,N6:N35,"ESPECES") -> 62000 | H41: =SUMIFS(H6:H37,J6:J37,"ESPECES") -> 0 | I41: =SUMIFS(Q6:Q37,O6:O37,"ESPECES") -> 0 | J41: =D41+G41-H41-I41 -> 212000 | L41: LOT PRINCIPAL | M41: =C3*COUNTIF(Q6:Q37,">0") -> 978000 | N41: =D3 -> 3 | O41: =COUNTIF(Q6:Q35,">0") -> 3
D42: =SUMIFS(D6:D37,G6:G37,"BANQUE") -> 600000 | E42: =SUMIFS(E6:E38,G6:G38,"BANQUE") -> 1018000 | F42: BANQUE | G42: =SUMIFS(M6:M35,N6:N35,"BANQUE") -> 182000 | H42: =SUMIFS(H6:H37,J6:J37,"BANQUE") -> 111500 | I42: =SUMIFS(Q6:Q37,O6:O37,"BANQUE") -> 960500 | J42: =D42+G42-H42-I42 -> -290000
L43: PETIT LOT | M43: =M40-M41 -> 33500
D44: =D41+D42 -> 750000 | E44: =E41+E42 -> 1258000 | F44: TOTAL | G44: =G41+G42 -> 244000 | H44: =H41+H42 -> 111500 | I44: =I41+I42 -> 960500 | J44: =J41+J42 -> -78000
F45: TOTAL+DEPOT | L45: RELIQUAT | M45: =M43-H38 -> -78000 | O45: =TONTJANV23!O45+M45 -> -130000 | P45: CUMUL
L47: ECHEC TONTINE MOIS | M47: =COUNTIFS(G6:G36,"ECHEC")*25000 -> 0 | O47: =+TONTJANV23!O47+M47 -> 0 | P47: CUMUL
L48: ECHEC REMBOURSEMENT MOIS | M48: =L38-G44 -> 0 | O48: =+TONTJANV23!O48+M48 -> 0 | P48: CUMUL

Sheet TONTJANV22
A1: ASSOCIATION | B1: ASELBY
A2: ANNEE | B2: 2022 | C2: TONIINE | D2: NBRE PART
A3: TAUX TONTINE | B3: 23000 | C3: =B3*13+1000 -> 300000 | D3: =ROUNDDOWN(M36/C3,0) -> 2
C4: 44574
A5: MATRICULE | B5: NBREPART | C5: NOM ET PRENOM | D5: MONTANT TONTINE | E5: MONTANT VERSE | F5: PENALITE VERSEMENT ESPECES | G5: MODE VERSEMENT | H5: VENTE PETIT LOT | I5: INTERET PETIT LOT | J5: MODE VERSEMENT VENTE PETIT LOT | K5: NUMERO CHEQUE | L5: MONTANT A REMBOURSER PETIT LOT | M5: REMBOURSEMENT PETIT LOT | N5: MODE VERSEMENT REMBOURSEMENT | O5: MODE VERSEMENTLOT PRINCIPAL | P5: NUMERO CHEQUE | Q5: MONTANT LOT PRINCIPAL | R5: INTERET LOT PRINCIPAL | S5: INTERET DU
A6: AS201602 | B6: =IF(D6=0,0,VLOOKUP($A6,[8]HISTOJANV22!$A$6:$AZ$36,9,0)) -> 1 | C6: =VLOOKUP(A6,[9]LISTADHERENT!A$5:H$60,3,0) -> BOUTCHOUANG WILLIAM | D6: =IF(G6="ECHEC",0,B$3) -> 23000 | E6: =D6+VLOOKUP($A6,[10]HISTOJANV22!$A$7:$AU$38,45,0)+F6 -> 30000 | F6: =VLOOKUP($A6,[10]HISTOJANV22!$A$7:$AU$38,7,0) -> 0 | G6: =VLOOKUP($A6,[10]HISTOJANV22!$A$7:$AU$38,8,0) -> BANQUE | H6: =VLOOKUP($A6,[10]HISTOJANV22!$A$7:$AU$38,35,0) -> 0 | I6: =VLOOKUP($A6,[10]HISTOJANV22!$A$7:$AU$38,38,0) -> 0 | J6: =IF(I6=0,0,VLOOKUP($A6,[10]HISTOJANV22!$A$7:$AU$38,42,0)) -> 0 | K6: =VLOOKUP($A6,[10]HISTOJANV22!$A$7:$AU$38,41,0) -> 0 | M6: =VLOOKUP($A6,[10]HISTOJANV22!$A$7:$AU$38,16,0) -> 0 | N6: =IF(M6<>0,VLOOKUP($A6,[10]HISTOJANV22!$A$7:$AU$38,8,0),"ECHEC") -> ECHEC | O6: =IF(R6=0,0,VLOOKUP($A6,[10]HISTOJANV22!$A$7:$AU$38,32,0)) -> 0 | P6: =VLOOKUP($A6,[10]HISTOJANV22!$A$7:$AU$38,33,0) -> 0 | Q6: =IF(R6=0,0,($C$3-R6)) -> 0 | R6: =VLOOKUP($A6,[10]HISTOJANV22!$A$7:$AU$38,29,0) -> 0 | S6: =IF(R6=0,0,(R6-23000)) -> 0
A7: AS201604 | B7: =IF(D7=0,0,VLOOKUP($A7,[8]HISTOJANV22!$A$6:$AZ$36,9,0)) -> 1 | C7: =VLOOKUP(A7,[9]LISTADHERENT!A$5:H$60,3,0) -> DJOMO JEAN PAUL | D7: =IF(G7="ECHEC",0,B$3) -> 23000 | E7: =D7+VLOOKUP($A7,[10]HISTOJANV22!$A$7:$AU$38,45,0)+F7 -> 75000 | F7: =VLOOKUP($A7,[10]HISTOJANV22!$A$7:$AU$38,7,0) -> 0 | G7: =VLOOKUP($A7,[10]HISTOJANV22!$A$7:$AU$38,8,0) -> BANQUE | H7: =VLOOKUP($A7,[10]HISTOJANV22!$A$7:$AU$38,35,0) -> 0 | I7: =VLOOKUP($A7,[10]HISTOJANV22!$A$7:$AU$38,38,0) -> 0 | J7: =IF(I7=0,0,VLOOKUP($A7,[10]HISTOJANV22!$A$7:$AU$38,42,0)) -> 0 | K7: =VLOOKUP($A7,[10]HISTOJANV22!$A$7:$AU$38,41,0) -> 0 | M7: =VLOOKUP($A7,[10]HISTOJANV22!$A$7:$AU$38,16,0) -> 0 | N7: =IF(M7<>0,VLOOKUP($A7,[10]HISTOJANV22!$A$7:$AU$38,8,0),"ECHEC") -> ECHEC | O7: =IF(R7=0,0,VLOOKUP($A7,[10]HISTOJANV22!$A$7:$AU$38,32,0)) -> 0 | P7: =VLOOKUP($A7,[10]HISTOJANV22!$A$7:$AU$38,33,0) -> 0 | Q7: =IF(R7=0,0,($C$3-R7)) -> 0 | R7: =VLOOKUP($A7,[10]HISTOJANV22!$A$7:$AU$38,29,0) -> 0 | S7: =IF(R7=0,0,(R7-23000)) -> 0
A8: AS201654 | B8: =IF(D8=0,0,VLOOKUP($A8,[8]HISTOJANV22!$A$6:$AZ$36,9,0)) -> 1 | C8: =VLOOKUP(A8,[9]LISTADHERENT!A$5:H$60,3,0) -> DJOMOU TCHANDA | D8: =IF(G8="ECHEC",0,B$3) -> 23000 | E8: =D8+VLOOKUP($A8,[10]HISTOJANV22!$A$7:$AU$38,45,0)+F8 -> 30000 | F8: =VLOOKUP($A8,[10]HISTOJANV22!$A$7:$AU$38,7,0) -> 0 | G8: =VLOOKUP($A8,[10]HISTOJANV22!$A$7:$AU$38,8,0) -> BANQUE | H8: =VLOOKUP($A8,[10]HISTOJANV22!$A$7:$AU$38,35,0) -> 0 | I8: =VLOOKUP($A8,[10]HISTOJANV22!$A$7:$AU$38,38,0) -> 0 | J8: =IF(I8=0,0,VLOOKUP($A8,[10]HISTOJANV22!$A$7:$AU$38,42,0)) -> 0 | K8: =VLOOKUP($A8,[10]HISTOJANV22!$A$7:$AU$38,41,0) -> 0 | M8: =VLOOKUP($A8,[10]HISTOJANV22!$A$7:$AU$38,16,0) -> 0 | N8: =IF(M8<>0,VLOOKUP($A8,[10]HISTOJANV22!$A$7:$AU$38,8,0),"ECHEC") -> ECHEC | O8: =IF(R8=0,0,VLOOKUP($A8,[10]HISTOJANV22!$A$7:$AU$38,32,0)) -> 0 | P8: =VLOOKUP($A8,[10]HISTOJANV22!$A$7:$AU$38,33,0) -> 0 | Q8: =IF(R8=0,0,($C$3-R8)) -> 0 | R8: =VLOOKUP($A8,[10]HISTOJANV22!$A$7:$AU$38,29,0) -> 0 | S8: =IF(R8=0,0,(R8-23000)) -> 0
A9: AS201605 | B9: =IF(D9=0,0,VLOOKUP($A9,[8]HISTOJANV22!$A$6:$AZ$36,9,0)) -> 1 | C9: =VLOOKUP(A9,[9]LISTADHERENT!A$5:H$60,3,0) -> DJOUKWE NANGUEN GUY BLAISE | D9: =IF(G9="ECHEC",0,B$3) -> 23000 | E9: =D9+VLOOKUP($A9,[10]HISTOJANV22!$A$7:$AU$38,45,0)+F9 -> 35000 | F9: =VLOOKUP($A9,[10]HISTOJANV22!$A$7:$AU$38,7,0) -> 0 | G9: =VLOOKUP($A9,[10]HISTOJANV22!$A$7:$AU$38,8,0) -> BANQUE | H9: =VLOOKUP($A9,[10]HISTOJANV22!$A$7:$AU$38,35,0) -> 0 | I9: =VLOOKUP($A9,[10]HISTOJANV22!$A$7:$AU$38,38,0) -> 0 | J9: =IF(I9=0,0,VLOOKUP($A9,[10]HISTOJANV22!$A$7:$AU$38,42,0)) -> 0 | K9: =VLOOKUP($A9,[10]HISTOJANV22!$A$7:$AU$38,41,0) -> 0 | M9: =VLOOKUP($A9,[10]HISTOJANV22!$A$7:$AU$38,16,0) -> 0 | N9: =IF(M9<>0,VLOOKUP($A9,[10]HISTOJANV22!$A$7:$AU$38,8,0),"ECHEC") -> ECHEC | O9: =IF(R9=0,0,VLOOKUP($A9,[10]HISTOJANV22!$A$7:$AU$38,32,0)) -> 0 | P9: =VLOOKUP($A9,[10]HISTOJANV22!$A$7:$AU$38,33,0) -> 0 | Q9: =IF(R9=0,0,($C$3-R9)) -> 0 | R9: =VLOOKUP($A9,[10]HISTOJANV22!$A$7:$AU$38,29,0) -> 0 | S9: =IF(R9=0,0,(R9-23000)) -> 0
A10: AS201608 | B10: =IF(D10=0,0,VLOOKUP($A10,[8]HISTOJANV22!$A$6:$AZ$36,9,0)) -> 1 | C10: =VLOOKUP(A10,[9]LISTADHERENT!A$5:H$60,3,0) -> DJUOMBESSY ANTOINE | D10: =IF(G10="ECHEC",0,B$3) -> 23000 | E10: =D10+VLOOKUP($A10,[10]HISTOJANV22!$A$7:$AU$38,45,0)+F10 -> 30000 | F10: =VLOOKUP($A10,[10]HISTOJANV22!$A$7:$AU$38,7,0) -> 0 | G10: =VLOOKUP($A10,[10]HISTOJANV22!$A$7:$AU$38,8,0) -> BANQUE | H10: =VLOOKUP($A10,[10]HISTOJANV22!$A$7:$AU$38,35,0) -> 0 | I10: =VLOOKUP($A10,[10]HISTOJANV22!$A$7:$AU$38,38,0) -> 0 | J10: =IF(I10=0,0,VLOOKUP($A10,[10]HISTOJANV22!$A$7:$AU$38,42,0)) -> 0 | K10: =VLOOKUP($A10,[10]HISTOJANV22!$A$7:$AU$38,41,0) -> 0 | M10: =VLOOKUP($A10,[10]HISTOJANV22!$A$7:$AU$38,16,0) -> 0 | N10: =IF(M10<>0,VLOOKUP($A10,[10]HISTOJANV22!$A$7:$AU$38,8,0),"ECHEC") -> ECHEC | O10: =IF(R10=0,0,VLOOKUP($A10,[10]HISTOJANV22!$A$7:$AU$38,32,0)) -> 0 | P10: =VLOOKUP($A10,[10]HISTOJANV22!$A$7:$AU$38,33,0) -> 0 | Q10: =IF(R10=0,0,($C$3-R10)) -> 0 | R10: =VLOOKUP($A10,[10]HISTOJANV22!$A$7:$AU$38,29,0) -> 0 | S10: =IF(R10=0,0,(R10-23000)) -> 0
A11: AS201651 | B11: =IF(D11=0,0,VLOOKUP($A11,[8]HISTOJANV22!$A$6:$AZ$36,9,0)) -> 1 | C11: =VLOOKUP(A11,[9]LISTADHERENT!A$5:H$60,3,0) -> DOMOU FABIEN | D11: =IF(G11="ECHEC",0,B$3) -> 23000 | E11: =D11+VLOOKUP($A11,[10]HISTOJANV22!$A$7:$AU$38,45,0)+F11 -> 35000 | F11: =VLOOKUP($A11,[10]HISTOJANV22!$A$7:$AU$38,7,0) -> 0 | G11: =VLOOKUP($A11,[10]HISTOJANV22!$A$7:$AU$38,8,0) -> BANQUE | H11: =VLOOKUP($A11,[10]HISTOJANV22!$A$7:$AU$38,35,0) -> 0 | I11: =VLOOKUP($A11,[10]HISTOJANV22!$A$7:$AU$38,38,0) -> 0 | J11: =IF(I11=0,0,VLOOKUP($A11,[10]HISTOJANV22!$A$7:$AU$38,42,0)) -> 0 | K11: =VLOOKUP($A11,[10]HISTOJANV22!$A$7:$AU$38,41,0) -> 0 | M11: =VLOOKUP($A11,[10]HISTOJANV22!$A$7:$AU$38,16,0) -> 0 | N11: =IF(M11<>0,VLOOKUP($A11,[10]HISTOJANV22!$A$7:$AU$38,8,0),"ECHEC") -> ECHEC | O11: =IF(R11=0,0,VLOOKUP($A11,[10]HISTOJANV22!$A$7:$AU$38,32,0)) -> 0 | P11: =VLOOKUP($A11,[10]HISTOJANV22!$A$7:$AU$38,33,0) -> 0 | Q11: =IF(R11=0,0,($C$3-R11)) -> 0 | R11: =VLOOKUP($A11,[10]HISTOJANV22!$A$7:$AU$38,29,0) -> 0 | S11: =IF(R11=0,0,(R11-23000)) -> 0
A12: AS201609 | B12: =IF(D12=0,0,VLOOKUP($A12,[8]HISTOJANV22!$A$6:$AZ$36,9,0)) -> 1 | C12: =VLOOKUP(A12,[9]LISTADHERENT!A$5:H$60,3,0) -> DONHOU DAVID | D12: =IF(G12="ECHEC",0,B$3) -> 23000 | E12: =D12+VLOOKUP($A12,[10]HISTOJANV22!$A$7:$AU$38,45,0)+F12 -> 30000 | F12: =VLOOKUP($A12,[10]HISTOJANV22!$A$7:$AU$38,7,0) -> 0 | G12: =VLOOKUP($A12,[10]HISTOJANV22!$A$7:$AU$38,8,0) -> BANQUE | H12: =VLOOKUP($A12,[10]HISTOJANV22!$A$7:$AU$38,35,0) -> 0 | I12: =VLOOKUP($A12,[10]HISTOJANV22!$A$7:$AU$38,38,0) -> 0 | J12: =IF(I12=0,0,VLOOKUP($A12,[10]HISTOJANV22!$A$7:$AU$38,42,0)) -> 0 | K12: =VLOOKUP($A12,[10]HISTOJANV22!$A$7:$AU$38,41,0) -> 0 | M12: =VLOOKUP($A12,[10]HISTOJANV22!$A$7:$AU$38,16,0) -> 0 | N12: =IF(M12<>0,VLOOKUP($A12,[10]HISTOJANV22!$A$7:$AU$38,8,0),"ECHEC") -> ECHEC | O12: =IF(R12=0,0,VLOOKUP($A12,[10]HISTOJANV22!$A$7:$AU$38,32,0)) -> 0 | P12: =VLOOKUP($A12,[10]HISTOJANV22!$A$7:$AU$38,33,0) -> 0 | Q12: =IF(R12=0,0,($C$3-R12)) -> 0 | R12: =VLOOKUP($A12,[10]HISTOJANV22!$A$7:$AU$38,29,0) -> 0 | S12: =IF(R12=0,0,(R12-23000)) -> 0
A13: AS201611 | B13: =IF(D13=0,0,VLOOKUP($A13,[8]HISTOJANV22!$A$6:$AZ$36,9,0)) -> 1 | C13: =VLOOKUP(A13,[9]LISTADHERENT!A$5:H$60,3,0) -> HENGUE PAUL OMER | D13: =IF(G13="ECHEC",0,B$3) -> 23000 | E13: =D13+VLOOKUP($A13,[10]HISTOJANV22!$A$7:$AU$38,45,0)+F13 -> 30000 | F13: =VLOOKUP($A13,[10]HISTOJANV22!$A$7:$AU$38,7,0) -> 0 | G13: =VLOOKUP($A13,[10]HISTOJANV22!$A$7:$AU$38,8,0) -> BANQUE | H13: =VLOOKUP($A13,[10]HISTOJANV22!$A$7:$AU$38,35,0) -> 0 | I13: =VLOOKUP($A13,[10]HISTOJANV22!$A$7:$AU$38,38,0) -> 0 | J13: =IF(I13=0,0,VLOOKUP($A13,[10]HISTOJANV22!$A$7:$AU$38,42,0)) -> 0 | K13: =VLOOKUP($A13,[10]HISTOJANV22!$A$7:$AU$38,41,0) -> 0 | M13: =VLOOKUP($A13,[10]HISTOJANV22!$A$7:$AU$38,16,0) -> 0 | N13: =IF(M13<>0,VLOOKUP($A13,[10]HISTOJANV22!$A$7:$AU$38,8,0),"ECHEC") -> ECHEC | O13: =IF(R13=0,0,VLOOKUP($A13,[10]HISTOJANV22!$A$7:$AU$38,32,0)) -> 0 | P13: =VLOOKUP($A13,[10]HISTOJANV22!$A$7:$AU$38,33,0) -> 0 | Q13: =IF(R13=0,0,($C$3-R13)) -> 0 | R13: =VLOOKUP($A13,[10]HISTOJANV22!$A$7:$AU$38,29,0) -> 0 | S13: =IF(R13=0,0,(R13-23000)) -> 0
A14: AS201613 | B14: =IF(D14=0,0,VLOOKUP($A14,[8]HISTOJANV22!$A$6:$AZ$36,9,0)) -> 1 | C14: =VLOOKUP(A14,[9]LISTADHERENT!A$5:H$60,3,0) -> HOTCHO BENJAMIN | D14: =IF(G14="ECHEC",0,B$3) -> 23000 | E14: =D14+VLOOKUP($A14,[10]HISTOJANV22!$A$7:$AU$38,45,0)+F14 -> 75000 | F14: =VLOOKUP($A14,[10]HISTOJANV22!$A$7:$AU$38,7,0) -> 0 | G14: =VLOOKUP($A14,[10]HISTOJANV22!$A$7:$AU$38,8,0) -> BANQUE | H14: =VLOOKUP($A14,[10]HISTOJANV22!$A$7:$AU$38,35,0) -> 0 | I14: =VLOOKUP($A14,[10]HISTOJANV22!$A$7:$AU$38,38,0) -> 0 | J14: =IF(I14=0,0,VLOOKUP($A14,[10]HISTOJANV22!$A$7:$AU$38,42,0)) -> 0 | K14: =VLOOKUP($A14,[10]HISTOJANV22!$A$7:$AU$38,41,0) -> 0 | M14: =VLOOKUP($A14,[10]HISTOJANV22!$A$7:$AU$38,16,0) -> 0 | N14: =IF(M14<>0,VLOOKUP($A14,[10]HISTOJANV22!$A$7:$AU$38,8,0),"ECHEC") -> ECHEC | O14: =IF(R14=0,0,VLOOKUP($A14,[10]HISTOJANV22!$A$7:$AU$38,32,0)) -> 0 | P14: =VLOOKUP($A14,[10]HISTOJANV22!$A$7:$AU$38,33,0) -> 0 | Q14: =IF(R14=0,0,($C$3-R14)) -> 0 | R14: =VLOOKUP($A14,[10]HISTOJANV22!$A$7:$AU$38,29,0) -> 0 | S14: =IF(R14=0,0,(R14-23000)) -> 0
A15: AS201617 | B15: =IF(D15=0,0,VLOOKUP($A15,[8]HISTOJANV22!$A$6:$AZ$36,9,0)) -> 1 | C15: =VLOOKUP(A15,[9]LISTADHERENT!A$5:H$60,3,0) -> KOUAMOU MOISE | D15: =IF(G15="ECHEC",0,B$3) -> 23000 | E15: =D15+VLOOKUP($A15,[10]HISTOJANV22!$A$7:$AU$38,45,0)+F15 -> 30000 | F15: =VLOOKUP($A15,[10]HISTOJANV22!$A$7:$AU$38,7,0) -> 0 | G15: =VLOOKUP($A15,[10]HISTOJANV22!$A$7:$AU$38,8,0) -> BANQUE | H15: =VLOOKUP($A15,[10]HISTOJANV22!$A$7:$AU$38,35,0) -> 0 | I15: =VLOOKUP($A15,[10]HISTOJANV22!$A$7:$AU$38,38,0) -> 0 | J15: =IF(I15=0,0,VLOOKUP($A15,[10]HISTOJANV22!$A$7:$AU$38,42,0)) -> 0 | K15: =VLOOKUP($A15,[10]HISTOJANV22!$A$7:$AU$38,41,0) -> 0 | M15: =VLOOKUP($A15,[10]HISTOJANV22!$A$7:$AU$38,16,0) -> 0 | N15: =IF(M15<>0,VLOOKUP($A15,[10]HISTOJANV22!$A$7:$AU$38,8,0),"ECHEC") -> ECHEC | O15: =IF(R15=0,0,VLOOKUP($A15,[10]HISTOJANV22!$A$7:$AU$38,32,0)) -> 0 | P15: =VLOOKUP($A15,[10]HISTOJANV22!$A$7:$AU$38,33,0) -> 0 | Q15: =IF(R15=0,0,($C$3-R15)) -> 0 | R15: =VLOOKUP($A15,[10]HISTOJANV22!$A$7:$AU$38,29,0) -> 0 | S15: =IF(R15=0,0,(R15-23000)) -> 0
A16: AS201619 | B16: =IF(D16=0,0,VLOOKUP($A16,[8]HISTOJANV22!$A$6:$AZ$36,9,0)) -> 1 | C16: =VLOOKUP(A16,[9]LISTADHERENT!A$5:H$60,3,0) -> KOUATCHO MESSACK | D16: =IF(G16="ECHEC",0,B$3) -> 23000 | E16: =D16+VLOOKUP($A16,[10]HISTOJANV22!$A$7:$AU$38,45,0)+F16 -> 30000 | F16: =VLOOKUP($A16,[10]HISTOJANV22!$A$7:$AU$38,7,0) -> 0 | G16: =VLOOKUP($A16,[10]HISTOJANV22!$A$7:$AU$38,8,0) -> BANQUE | H16: =VLOOKUP($A16,[10]HISTOJANV22!$A$7:$AU$38,35,0) -> 26000 | I16: =VLOOKUP($A16,[10]HISTOJANV22!$A$7:$AU$38,38,0) -> 1500 | J16: =IF(I16=0,0,VLOOKUP($A16,[10]HISTOJANV22!$A$7:$AU$38,42,0)) -> BANQUE | K16: =VLOOKUP($A16,[10]HISTOJANV22!$A$7:$AU$38,41,0) -> 0 | M16: =VLOOKUP($A16,[10]HISTOJANV22!$A$7:$AU$38,16,0) -> 0 | N16: =IF(M16<>0,VLOOKUP($A16,[10]HISTOJANV22!$A$7:$AU$38,8,0),"ECHEC") -> ECHEC | O16: =IF(R16=0,0,VLOOKUP($A16,[10]HISTOJANV22!$A$7:$AU$38,32,0)) -> 0 | P16: =VLOOKUP($A16,[10]HISTOJANV22!$A$7:$AU$38,33,0) -> 0 | Q16: =IF(R16=0,0,($C$3-R16)) -> 0 | R16: =VLOOKUP($A16,[10]HISTOJANV22!$A$7:$AU$38,29,0) -> 0 | S16: =IF(R16=0,0,(R16-23000)) -> 0
A17: AS201620 | B17: =IF(D17=0,0,VLOOKUP($A17,[8]HISTOJANV22!$A$6:$AZ$36,9,0)) -> 1 | C17: =VLOOKUP(A17,[9]LISTADHERENT!A$5:H$60,3,0) -> LOWE JEAN | D17: =IF(G17="ECHEC",0,B$3) -> 23000 | E17: =D17+VLOOKUP($A17,[10]HISTOJANV22!$A$7:$AU$38,45,0)+F17 -> 30000 | F17: =VLOOKUP($A17,[10]HISTOJANV22!$A$7:$AU$38,7,0) -> 0 | G17: =VLOOKUP($A17,[10]HISTOJANV22!$A$7:$AU$38,8,0) -> BANQUE | H17: =VLOOKUP($A17,[10]HISTOJANV22!$A$7:$AU$38,35,0) -> 0 | I17: =VLOOKUP($A17,[10]HISTOJANV22!$A$7:$AU$38,38,0) -> 0 | J17: =IF(I17=0,0,VLOOKUP($A17,[10]HISTOJANV22!$A$7:$AU$38,42,0)) -> 0 | K17: =VLOOKUP($A17,[10]HISTOJANV22!$A$7:$AU$38,41,0) -> 0 | M17: =VLOOKUP($A17,[10]HISTOJANV22!$A$7:$AU$38,16,0) -> 0 | N17: =IF(M17<>0,VLOOKUP($A17,[10]HISTOJANV22!$A$7:$AU$38,8,0),"ECHEC") -> ECHEC | O17: =IF(R17=0,0,VLOOKUP($A17,[10]HISTOJANV22!$A$7:$AU$38,32,0)) -> 0 | P17: =VLOOKUP($A17,[10]HISTOJANV22!$A$7:$AU$38,33,0) -> 0 | Q17: =IF(R17=0,0,($C$3-R17)) -> 0 | R17: =VLOOKUP($A17,[10]HISTOJANV22!$A$7:$AU$38,29,0) -> 0 | S17: =IF(R17=0,0,(R17-23000)) -> 0
... A19: AS201639 | B19: =IF(D19=0,0,VLOOKUP($A19,[8]HISTOJANV22!$A$6:$AZ$36,9,0)) -> 1 | C19: =VLOOKUP(A19,[9]LISTADHERENT!A$5:H$60,3,0) -> NANGUEN MARTIN | D19: =IF(G19="ECHEC",0,B$3) -> 23000 | E19: =D19+VLOOKUP($A19,[10]HISTOJANV22!$A$7:$AU$38,45,0)+F19 -> 30000 | F19: =VLOOKUP($A19,[10]HISTOJANV22!$A$7:$AU$38,7,0) -> 0 | G19: =VLOOKUP($A19,[10]HISTOJANV22!$A$7:$AU$38,8,0) -> BANQUE | H19: =VLOOKUP($A19,[10]HISTOJANV22!$A$7:$AU$38,35,0) -> 0 | I19: =VLOOKUP($A19,[10]HISTOJANV22!$A$7:$AU$38,38,0) -> 0 | J19: =IF(I19=0,0,VLOOKUP($A19,[10]HISTOJANV22!$A$7:$AU$38,42,0)) -> 0 | K19: =VLOOKUP($A19,[10]HISTOJANV22!$A$7:$AU$38,41,0) -> 0 | M19: =VLOOKUP($A19,[10]HISTOJANV22!$A$7:$AU$38,16,0) -> 0 | N19: =IF(M19<>0,VLOOKUP($A19,[10]HISTOJANV22!$A$7:$AU$38,8,0),"ECHEC") -> ECHEC | O19: =IF(R19=0,0,VLOOKUP($A19,[10]HISTOJANV22!$A$7:$AU$38,32,0)) -> 0 | P19: =VLOOKUP($A19,[10]HISTOJANV22!$A$7:$AU$38,33,0) -> 0 | Q19: =IF(R19=0,0,($C$3-R19)) -> 0 | R19: =VLOOKUP($A19,[10]HISTOJANV22!$A$7:$AU$38,29,0) -> 0 | S19: =IF(R19=0,0,(R19-23000)) -> 0
A20: AS201621 | B20: =IF(D20=0,0,VLOOKUP($A20,[8]HISTOJANV22!$A$6:$AZ$36,9,0)) -> 1 | C20: =VLOOKUP(A20,[9]LISTADHERENT!A$5:H$60,3,0) -> NANKAM APPOLINAIRE | D20: =IF(G20="ECHEC",0,B$3) -> 23000 | E20: =D21+VLOOKUP($A21,[10]HISTOJANV22!$A$7:$AU$38,45,0)+F21 -> 40000 | F20: =VLOOKUP($A21,[10]HISTOJANV22!$A$7:$AU$38,7,0) -> 0 | G20: =VLOOKUP($A21,[10]HISTOJANV22!$A$7:$AU$38,8,0) -> BANQUE | H20: =VLOOKUP($A21,[10]HISTOJANV22!$A$7:$AU$38,35,0) -> 0 | I20: =VLOOKUP($A21,[10]HISTOJANV22!$A$7:$AU$38,38,0) -> 0 | J20: =IF(I21=0,0,VLOOKUP($A21,[10]HISTOJANV22!$A$7:$AU$38,42,0)) -> 0 | K20: =VLOOKUP($A21,[10]HISTOJANV22!$A$7:$AU$38,41,0) -> 0 | M20: =VLOOKUP($A21,[10]HISTOJANV22!$A$7:$AU$38,16,0) -> 0 | N20: =IF(M21<>0,VLOOKUP($A21,[10]HISTOJANV22!$A$7:$AU$38,8,0),"ECHEC") -> ECHEC | O20: =IF(R21=0,0,VLOOKUP($A21,[10]HISTOJANV22!$A$7:$AU$38,32,0)) -> 0 | P20: =VLOOKUP($A21,[10]HISTOJANV22!$A$7:$AU$38,33,0) -> 0 | Q20: =IF(R21=0,0,($C$3-R21)) -> 0 | R20: =VLOOKUP($A21,[10]HISTOJANV22!$A$7:$AU$38,29,0) -> 0 | S20: =IF(R20=0,0,(R20-23000)) -> 0
A21: AS201622 | B21: =IF(D21=0,0,VLOOKUP($A21,[8]HISTOJANV22!$A$6:$AZ$36,9,0)) -> 1 | C21: =VLOOKUP(A21,[9]LISTADHERENT!A$5:H$60,3,0) -> NDJOMO ETIENNE | D21: =IF(G21="ECHEC",0,B$3) -> 23000 | E21: =D21+VLOOKUP($A21,[10]HISTOJANV22!$A$7:$AU$38,45,0)+F21 -> 40000 | F21: =VLOOKUP($A21,[10]HISTOJANV22!$A$7:$AU$38,7,0) -> 0 | G21: =VLOOKUP($A21,[10]HISTOJANV22!$A$7:$AU$38,8,0) -> BANQUE | H21: =VLOOKUP($A21,[10]HISTOJANV22!$A$7:$AU$38,35,0) -> 0 | I21: =VLOOKUP($A21,[10]HISTOJANV22!$A$7:$AU$38,38,0) -> 0 | J21: =IF(I21=0,0,VLOOKUP($A21,[10]HISTOJANV22!$A$7:$AU$38,42,0)) -> 0 | K21: =VLOOKUP($A21,[10]HISTOJANV22!$A$7:$AU$38,41,0) -> 0 | M21: =VLOOKUP($A21,[10]HISTOJANV22!$A$7:$AU$38,16,0) -> 0 | N21: =IF(M21<>0,VLOOKUP($A21,[10]HISTOJANV22!$A$7:$AU$38,8,0),"ECHEC") -> ECHEC | O21: =IF(R21=0,0,VLOOKUP($A21,[10]HISTOJANV22!$A$7:$AU$38,32,0)) -> 0 | P21: =VLOOKUP($A21,[10]HISTOJANV22!$A$7:$AU$38,33,0) -> 0 | Q21: =IF(R21=0,0,($C$3-R21)) -> 0 | R21: =VLOOKUP($A21,[10]HISTOJANV22!$A$7:$AU$38,29,0) -> 0 | S21: =IF(R21=0,0,(R21-23000)) -> 0
A22: AS201624 | B22: =IF(D22=0,0,VLOOKUP($A22,[8]HISTOJANV22!$A$6:$AZ$36,9,0)) -> 1 | C22: =VLOOKUP(A22,[9]LISTADHERENT!A$5:H$60,3,0) -> NGONDIEP CLAUDE | D22: =IF(G22="ECHEC",0,B$3) -> 23000 | E22: =D22+VLOOKUP($A22,[10]HISTOJANV22!$A$7:$AU$38,45,0)+F22 -> 35000 | F22: =VLOOKUP($A22,[10]HISTOJANV22!$A$7:$AU$38,7,0) -> 0 | G22: =VLOOKUP($A22,[10]HISTOJANV22!$A$7:$AU$38,8,0) -> BANQUE | H22: =VLOOKUP($A22,[10]HISTOJANV22!$A$7:$AU$38,35,0) -> 0 | I22: =VLOOKUP($A22,[10]HISTOJANV22!$A$7:$AU$38,38,0) -> 0 | J22: =IF(I22=0,0,VLOOKUP($A22,[10]HISTOJANV22!$A$7:$AU$38,42,0)) -> 0 | K22: =VLOOKUP($A22,[10]HISTOJANV22!$A$7:$AU$38,41,0) -> 0 | M22: =VLOOKUP($A22,[10]HISTOJANV22!$A$7:$AU$38,16,0) -> 0 | N22: =IF(M22<>0,VLOOKUP($A22,[10]HISTOJANV22!$A$7:$AU$38,8,0),"ECHEC") -> ECHEC | O22: =IF(R22=0,0,VLOOKUP($A22,[10]HISTOJANV22!$A$7:$AU$38,32,0)) -> 0 | P22: =VLOOKUP($A22,[10]HISTOJANV22!$A$7:$AU$38,33,0) -> 0 | Q22: =IF(R22=0,0,($C$3-R22)) -> 0 | R22: =VLOOKUP($A22,[10]HISTOJANV22!$A$7:$AU$38,29,0) -> 0 | S22: =IF(R22=0,0,(R22-23000)) -> 0
A23: AS201626 | B23: =IF(D23=0,0,VLOOKUP($A23,[8]HISTOJANV22!$A$6:$AZ$36,9,0)) -> 1 | C23: =VLOOKUP(A23,[9]LISTADHERENT!A$5:H$60,3,0) -> NGUIEMEGNI MATHIEU BLAISE | D23: =IF(G23="ECHEC",0,B$3) -> 23000 | E23: =D23+VLOOKUP($A23,[10]HISTOJANV22!$A$7:$AU$38,45,0)+F23 -> 30000 | F23: =VLOOKUP($A23,[10]HISTOJANV22!$A$7:$AU$38,7,0) -> 0 | G23: =VLOOKUP($A23,[10]HISTOJANV22!$A$7:$AU$38,8,0) -> BANQUE | H23: =VLOOKUP($A23,[10]HISTOJANV22!$A$7:$AU$38,35,0) -> 25000 | I23: =VLOOKUP($A23,[10]HISTOJANV22!$A$7:$AU$38,38,0) -> 2000 | J23: =IF(I23=0,0,VLOOKUP($A23,[10]HISTOJANV22!$A$7:$AU$38,42,0)) -> BANQUE | K23: =VLOOKUP($A23,[10]HISTOJANV22!$A$7:$AU$38,41,0) -> 0 | M23: =VLOOKUP($A23,[10]HISTOJANV22!$A$7:$AU$38,16,0) -> 0 | N23: =IF(M23<>0,VLOOKUP($A23,[10]HISTOJANV22!$A$7:$AU$38,8,0),"ECHEC") -> ECHEC | O23: =IF(R23=0,0,VLOOKUP($A23,[10]HISTOJANV22!$A$7:$AU$38,32,0)) -> BANQUE | P23: =VLOOKUP($A23,[10]HISTOJANV22!$A$7:$AU$38,33,0) -> 0 | Q23: =IF(R23=0,0,($C$3-R23)) -> 261000 | R23: =VLOOKUP($A23,[10]HISTOJANV22!$A$7:$AU$38,29,0) -> 39000 | S23: =IF(R23=0,0,(R23-23000)) -> 16000
A24: AS201628 | B24: =IF(D24=0,0,VLOOKUP($A24,[8]HISTOJANV22!$A$6:$AZ$36,9,0)) -> 1 | C24: =VLOOKUP(A24,[9]LISTADHERENT!A$5:H$60,3,0) -> NKAMGANG JUSTIN DEJOLIE | D24: =IF(G24="ECHEC",0,B$3) -> 23000 | E24: =D24+VLOOKUP($A24,[10]HISTOJANV22!$A$7:$AU$38,45,0)+F24 -> 30000 | F24: =VLOOKUP($A24,[10]HISTOJANV22!$A$7:$AU$38,7,0) -> 0 | G24: =VLOOKUP($A24,[10]HISTOJANV22!$A$7:$AU$38,8,0) -> BANQUE | H24: =VLOOKUP($A24,[10]HISTOJANV22!$A$7:$AU$38,35,0) -> 25000 | I24: =VLOOKUP($A24,[10]HISTOJANV22!$A$7:$AU$38,38,0) -> 1000 | J24: =IF(I24=0,0,VLOOKUP($A24,[10]HISTOJANV22!$A$7:$AU$38,42,0)) -> BANQUE | K24: =VLOOKUP($A24,[10]HISTOJANV22!$A$7:$AU$38,41,0) -> 0 | M24: =VLOOKUP($A24,[10]HISTOJANV22!$A$7:$AU$38,16,0) -> 0 | N24: =IF(M24<>0,VLOOKUP($A24,[10]HISTOJANV22!$A$7:$AU$38,8,0),"ECHEC") -> ECHEC | O24: =IF(R24=0,0,VLOOKUP($A24,[10]HISTOJANV22!$A$7:$AU$38,32,0)) -> 0 | P24: =VLOOKUP($A24,[10]HISTOJANV22!$A$7:$AU$38,33,0) -> 0 | Q24: =IF(R24=0,0,($C$3-R24)) -> 0 | R24: =VLOOKUP($A24,[10]HISTOJANV22!$A$7:$AU$38,29,0) -> 0 | S24: =IF(R24=0,0,(R24-23000)) -> 0
A25: AS201629 | B25: =IF(D25=0,0,VLOOKUP($A25,[8]HISTOJANV22!$A$6:$AZ$36,9,0)) -> 1 | C25: =VLOOKUP(A25,[9]LISTADHERENT!A$5:H$60,3,0) -> NKEPSEU DIEUDONNE | D25: =IF(G25="ECHEC",0,B$3) -> 23000 | E25: =D25+VLOOKUP($A25,[10]HISTOJANV22!$A$7:$AU$38,45,0)+F25 -> 40000 | F25: =VLOOKUP($A25,[10]HISTOJANV22!$A$7:$AU$38,7,0) -> 0 | G25: =VLOOKUP($A25,[10]HISTOJANV22!$A$7:$AU$38,8,0) -> BANQUE | H25: =VLOOKUP($A25,[10]HISTOJANV22!$A$7:$AU$38,35,0) -> 0 | I25: =VLOOKUP($A25,[10]HISTOJANV22!$A$7:$AU$38,38,0) -> 0 | J25: =IF(I25=0,0,VLOOKUP($A25,[10]HISTOJANV22!$A$7:$AU$38,42,0)) -> 0 | K25: =VLOOKUP($A25,[10]HISTOJANV22!$A$7:$AU$38,41,0) -> 0 | M25: =VLOOKUP($A25,[10]HISTOJANV22!$A$7:$AU$38,16,0) -> 0 | N25: =IF(M25<>0,VLOOKUP($A25,[10]HISTOJANV22!$A$7:$AU$38,8,0),"ECHEC") -> ECHEC | O25: =IF(R25=0,0,VLOOKUP($A25,[10]HISTOJANV22!$A$7:$AU$38,32,0)) -> 0 | P25: =VLOOKUP($A25,[10]HISTOJANV22!$A$7:$AU$38,33,0) -> 0 | Q25: =IF(R25=0,0,($C$3-R25)) -> 0 | R25: =VLOOKUP($A25,[10]HISTOJANV22!$A$7:$AU$38,29,0) -> 0 | S25: =IF(R25=0,0,(R25-23000)) -> 0
A26: AS201633 | B26: =IF(D26=0,0,VLOOKUP($A26,[8]HISTOJANV22!$A$6:$AZ$36,9,0)) -> 1 | C26: =VLOOKUP(A26,[9]LISTADHERENT!A$5:H$60,3,0) -> PATEGO NJOSSU GUSTAVE | D26: =IF(G26="ECHEC",0,B$3) -> 23000 | E26: =D26+VLOOKUP($A26,[10]HISTOJANV22!$A$7:$AU$38,45,0)+F26 -> 30000 | F26: =VLOOKUP($A26,[10]HISTOJANV22!$A$7:$AU$38,7,0) -> 0 | G26: =VLOOKUP($A26,[10]HISTOJANV22!$A$7:$AU$38,8,0) -> BANQUE | H26: =VLOOKUP($A26,[10]HISTOJANV22!$A$7:$AU$38,35,0) -> 0 | I26: =VLOOKUP($A26,[10]HISTOJANV22!$A$7:$AU$38,38,0) -> 0 | J26: =IF(I26=0,0,VLOOKUP($A26,[10]HISTOJANV22!$A$7:$AU$38,42,0)) -> 0 | K26: =VLOOKUP($A26,[10]HISTOJANV22!$A$7:$AU$38,41,0) -> 0 | M26: =VLOOKUP($A26,[10]HISTOJANV22!$A$7:$AU$38,16,0) -> 0 | N26: =IF(M26<>0,VLOOKUP($A26,[10]HISTOJANV22!$A$7:$AU$38,8,0),"ECHEC") -> ECHEC | O26: =IF(R26=0,0,VLOOKUP($A26,[10]HISTOJANV22!$A$7:$AU$38,32,0)) -> 0 | P26: =VLOOKUP($A26,[10]HISTOJANV22!$A$7:$AU$38,33,0) -> 0 | Q26: =IF(R26=0,0,($C$3-R26)) -> 0 | R26: =VLOOKUP($A26,[10]HISTOJANV22!$A$7:$AU$38,29,0) -> 0 | S26: =IF(R26=0,0,(R26-23000)) -> 0
A27: AS201653 | B27: =IF(D27=0,0,VLOOKUP($A27,[8]HISTOJANV22!$A$6:$AZ$36,9,0)) -> 1 | C27: =VLOOKUP(A27,[9]LISTADHERENT!A$5:H$60,3,0) -> SIME BRICE | D27: =IF(G27="ECHEC",0,B$3) -> 23000 | E27: =D27+VLOOKUP($A27,[10]HISTOJANV22!$A$7:$AU$38,45,0)+F27 -> 30000 | F27: =VLOOKUP($A27,[10]HISTOJANV22!$A$7:$AU$38,7,0) -> 0 | G27: =VLOOKUP($A27,[10]HISTOJANV22!$A$7:$AU$38,8,0) -> BANQUE | H27: =VLOOKUP($A27,[10]HISTOJANV22!$A$7:$AU$38,35,0) -> 0 | I27: =VLOOKUP($A27,[10]HISTOJANV22!$A$7:$AU$38,38,0) -> 0 | J27: =IF(I27=0,0,VLOOKUP($A27,[10]HISTOJANV22!$A$7:$AU$38,42,0)) -> 0 | K27: =VLOOKUP($A27,[10]HISTOJANV22!$A$7:$AU$38,41,0) -> 0 | M27: =VLOOKUP($A27,[10]HISTOJANV22!$A$7:$AU$38,16,0) -> 0 | N27: =IF(M27<>0,VLOOKUP($A27,[10]HISTOJANV22!$A$7:$AU$38,8,0),"ECHEC") -> ECHEC | O27: =IF(R27=0,0,VLOOKUP($A27,[10]HISTOJANV22!$A$7:$AU$38,32,0)) -> 0 | P27: =VLOOKUP($A27,[10]HISTOJANV22!$A$7:$AU$38,33,0) -> 0 | Q27: =IF(R27=0,0,($C$3-R27)) -> 0 | R27: =VLOOKUP($A27,[10]HISTOJANV22!$A$7:$AU$38,29,0) -> 0 | S27: =IF(R27=0,0,(R27-23000)) -> 0
A28: AS201638 | B28: =IF(D28=0,0,VLOOKUP($A28,[8]HISTOJANV22!$A$6:$AZ$36,9,0)) -> 1 | C28: =VLOOKUP(A28,[9]LISTADHERENT!A$5:H$60,3,0) -> SIMO PIERRE | D28: =IF(G28="ECHEC",0,B$3) -> 23000 | E28: =D28+VLOOKUP($A28,[10]HISTOJANV22!$A$7:$AU$38,45,0)+F28 -> 45000 | F28: =VLOOKUP($A28,[10]HISTOJANV22!$A$7:$AU$38,7,0) -> 0 | G28: =VLOOKUP($A28,[10]HISTOJANV22!$A$7:$AU$38,8,0) -> BANQUE | H28: =VLOOKUP($A28,[10]HISTOJANV22!$A$7:$AU$38,35,0) -> 0 | I28: =VLOOKUP($A28,[10]HISTOJANV22!$A$7:$AU$38,38,0) -> 0 | J28: =IF(I28=0,0,VLOOKUP($A28,[10]HISTOJANV22!$A$7:$AU$38,42,0)) -> 0 | K28: =VLOOKUP($A28,[10]HISTOJANV22!$A$7:$AU$38,41,0) -> 0 | M28: =VLOOKUP($A28,[10]HISTOJANV22!$A$7:$AU$38,16,0) -> 0 | N28: =IF(M28<>0,VLOOKUP($A28,[10]HISTOJANV22!$A$7:$AU$38,8,0),"ECHEC") -> ECHEC | O28: =IF(R28=0,0,VLOOKUP($A28,[10]HISTOJANV22!$A$7:$AU$38,32,0)) -> 0 | P28: =VLOOKUP($A28,[10]HISTOJANV22!$A$7:$AU$38,33,0) -> 0 | Q28: =IF(R28=0,0,($C$3-R28)) -> 0 | R28: =VLOOKUP($A28,[10]HISTOJANV22!$A$7:$AU$38,29,0) -> 0 | S28: =IF(R28=0,0,(R28-23000)) -> 0
A29: AS201641 | B29: =IF(D29=0,0,VLOOKUP($A29,[8]HISTOJANV22!$A$6:$AZ$36,9,0)) -> 1 | C29: =VLOOKUP(A29,[9]LISTADHERENT!A$5:H$60,3,0) -> TCHOUAMOU MATHIEU | D29: =IF(G29="ECHEC",0,B$3) -> 23000 | E29: =D29+VLOOKUP($A29,[10]HISTOJANV22!$A$7:$AU$38,45,0)+F29 -> 30000 | F29: =VLOOKUP($A29,[10]HISTOJANV22!$A$7:$AU$38,7,0) -> 0 | G29: =VLOOKUP($A29,[10]HISTOJANV22!$A$7:$AU$38,8,0) -> BANQUE | H29: =VLOOKUP($A29,[10]HISTOJANV22!$A$7:$AU$38,35,0) -> 0 | I29: =VLOOKUP($A29,[10]HISTOJANV22!$A$7:$AU$38,38,0) -> 0 | J29: =IF(I29=0,0,VLOOKUP($A29,[10]HISTOJANV22!$A$7:$AU$38,42,0)) -> 0 | K29: =VLOOKUP($A29,[10]HISTOJANV22!$A$7:$AU$38,41,0) -> 0 | M29: =VLOOKUP($A29,[10]HISTOJANV22!$A$7:$AU$38,16,0) -> 0 | N29: =IF(M29<>0,VLOOKUP($A29,[10]HISTOJANV22!$A$7:$AU$38,8,0),"ECHEC") -> ECHEC | O29: =IF(R29=0,0,VLOOKUP($A29,[10]HISTOJANV22!$A$7:$AU$38,32,0)) -> 0 | P29: =VLOOKUP($A29,[10]HISTOJANV22!$A$7:$AU$38,33,0) -> 0 | Q29: =IF(R29=0,0,($C$3-R29)) -> 0 | R29: =VLOOKUP($A29,[10]HISTOJANV22!$A$7:$AU$38,29,0) -> 0 | S29: =IF(R29=0,0,(R29-23000)) -> 0
A30: AS201646 | B30: =IF(D30=0,0,VLOOKUP($A30,[8]HISTOJANV22!$A$6:$AZ$36,9,0)) -> 1 | C30: =VLOOKUP(A30,[9]LISTADHERENT!A$5:H$60,3,0) -> YEPMOU JEAN JACQUES | D30: =IF(G30="ECHEC",0,B$3) -> 23000 | E30: =D30+VLOOKUP($A30,[10]HISTOJANV22!$A$7:$AU$38,45,0)+F30 -> 33000 | F30: =VLOOKUP($A30,[10]HISTOJANV22!$A$7:$AU$38,7,0) -> 3000 | G30: =VLOOKUP($A30,[10]HISTOJANV22!$A$7:$AU$38,8,0) -> ESPECES | H30: =VLOOKUP($A30,[10]HISTOJANV22!$A$7:$AU$38,35,0) -> 0 | I30: =VLOOKUP($A30,[10]HISTOJANV22!$A$7:$AU$38,38,0) -> 0 | J30: =IF(I30=0,0,VLOOKUP($A30,[10]HISTOJANV22!$A$7:$AU$38,42,0)) -> 0 | K30: =VLOOKUP($A30,[10]HISTOJANV22!$A$7:$AU$38,41,0) -> 0 | M30: =VLOOKUP($A30,[10]HISTOJANV22!$A$7:$AU$38,16,0) -> 0 | N30: =IF(M30<>0,VLOOKUP($A30,[10]HISTOJANV22!$A$7:$AU$38,8,0),"ECHEC") -> ECHEC | O30: =IF(R30=0,0,VLOOKUP($A30,[10]HISTOJANV22!$A$7:$AU$38,32,0)) -> 0 | P30: =VLOOKUP($A30,[10]HISTOJANV22!$A$7:$AU$38,33,0) -> 0 | Q30: =IF(R30=0,0,($C$3-R30)) -> 0 | R30: =VLOOKUP($A30,[10]HISTOJANV22!$A$7:$AU$38,29,0) -> 0 | S30: =IF(R30=0,0,(R30-23000)) -> 0
A31: AS201647 | B31: =IF(D31=0,0,VLOOKUP($A31,[8]HISTOJANV22!$A$6:$AZ$36,9,0)) -> 1 | C31: =VLOOKUP(A31,[9]LISTADHERENT!A$5:H$60,3,0) -> YOUMBI EMMANUEL | D31: =IF(G31="ECHEC",0,B$3) -> 23000 | E31: =D31+VLOOKUP($A31,[10]HISTOJANV22!$A$7:$AU$38,45,0)+F31 -> 30000 | F31: =VLOOKUP($A31,[10]HISTOJANV22!$A$7:$AU$38,7,0) -> 0 | G31: =VLOOKUP($A31,[10]HISTOJANV22!$A$7:$AU$38,8,0) -> BANQUE | H31: =VLOOKUP($A31,[10]HISTOJANV22!$A$7:$AU$38,35,0) -> 0 | I31: =VLOOKUP($A31,[10]HISTOJANV22!$A$7:$AU$38,38,0) -> 0 | J31: =IF(I31=0,0,VLOOKUP($A31,[10]HISTOJANV22!$A$7:$AU$38,42,0)) -> 0 | K31: =VLOOKUP($A31,[10]HISTOJANV22!$A$7:$AU$38,41,0) -> 0 | M31: =VLOOKUP($A31,[10]HISTOJANV22!$A$7:$AU$38,16,0) -> 0 | N31: =IF(M31<>0,VLOOKUP($A31,[10]HISTOJANV22!$A$7:$AU$38,8,0),"ECHEC") -> ECHEC | O31: =IF(R31=0,0,VLOOKUP($A31,[10]HISTOJANV22!$A$7:$AU$38,32,0)) -> 0 | P31: =VLOOKUP($A31,[10]HISTOJANV22!$A$7:$AU$38,33,0) -> 0 | Q31: =IF(R31=0,0,($C$3-R31)) -> 0 | R31: =VLOOKUP($A31,[10]HISTOJANV22!$A$7:$AU$38,29,0) -> 0 | S31: =IF(R31=0,0,(R31-23000)) -> 0
A33: TOTAL PART | B33: =SUM(B6:B32) -> 26
