Workbook

Sheet Sheet1

Sheet Sheet2

Sheet Sheet3

Sheet Sheet4

Sheet Sheet5
A1: ASSOCIATION | B1: ASELBY
A2: ANNEE | B2: 2016/2017
A3: TONTINE | B3: 20 000
A4: MATRICULE | B4: NOM ET PRENOM | C4: DECEMBRE | D4: JANVIER | E4: FÉVRIER | F4: MARS | G4: AVRIL | H4: MAI | I4: JUIN | J4: JUILLET | K4: AOÛT | L4: SEPTEMBRE | M4: OCTOBRE | N4: NOVEMBRE
A5: AS201648 | B5: =VLOOKUP(A5,LISTADHERENT!A$5:H$52,2,0) -> ASELBY | C5: 0
A6: AS201601 | B6: =VLOOKUP(A6,LISTADHERENT!A$5:H$52,2,0) -> BAKOP ACHILLE | C6: 390000
A7: AS201602 | B7: =VLOOKUP(A7,LISTADHERENT!A$5:H$52,2,0) -> BOUTCHOUANG WILLIAM | C7: 390000
A8: AS201603 | B8: =VLOOKUP(A8,LISTADHERENT!A$5:H$52,2,0) -> CHINGUE FABRICE | C8: 390000
A9: AS201604 | B9: =VLOOKUP(A9,LISTADHERENT!A$5:H$52,2,0) -> DJOMO JEAN PAUL | C9: 390000
A10: AS201605 | B10: =VLOOKUP(A10,LISTADHERENT!A$5:H$52,2,0) -> DJOUKWE GUY | C10: 390000
A11: AS201606 | B11: =VLOOKUP(A11,LISTADHERENT!A$5:H$52,2,0) -> DJOSSEU JOSUE | C11: 0
A12: AS201607 | B12: =VLOOKUP(A12,LISTADHERENT!A$5:H$52,2,0) -> DJOUNKEP SAMUEL | C12: 390000
A13: AS201608 | B13: =VLOOKUP(A13,LISTADHERENT!A$5:H$52,2,0) -> DJUOMBESSY ANTOINE | C13: =390000-70866 -> 319134 | L13: 390000
A14: AS201609 | B14: =VLOOKUP(A14,LISTADHERENT!A$5:H$52,2,0) -> DONHOU DAVID | C14: 390000
A15: AS201610 | B15: =VLOOKUP(A15,LISTADHERENT!A$5:H$52,2,0) -> FOTSO THOMAS | C15: 390000
A16: AS201611 | B16: =VLOOKUP(A16,LISTADHERENT!A$5:H$52,2,0) -> HENGUE PAUL OMER | C16: 390000
A17: AS201612 | B17: =VLOOKUP(A17,LISTADHERENT!A$5:H$52,2,0) -> HODIEP JULES | C17: 0 | I17: 50000
A18: AS201613 | B18: =VLOOKUP(A18,LISTADHERENT!A$5:H$52,2,0) -> HOTCHO BENJAMIN | C18: 390000
A19: AS201614 | B19: =VLOOKUP(A19,LISTADHERENT!A$5:H$52,2,0) -> KEPHE DAVID | C19: 0
A20: AS201615 | B20: =VLOOKUP(A20,LISTADHERENT!A$5:H$52,2,0) -> KEPSEU FRANCIS | C20: 390000
A21: AS201616 | B21: =VLOOKUP(A21,LISTADHERENT!A$5:H$52,2,0) -> KOUAMOU EMMANUEL | C21: 390000
A22: AS201617 | B22: =VLOOKUP(A22,LISTADHERENT!A$5:H$52,2,0) -> KOUAMOU MOISE | C22: =390000-75000 -> 315000 | I22: 390000
A23: AS201618 | B23: =VLOOKUP(A23,LISTADHERENT!A$5:H$52,2,0) -> KOUAMOU VICTOR PEGUY | C23: 390000
A24: AS201619 | B24: =VLOOKUP(A24,LISTADHERENT!A$5:H$52,2,0) -> KOUATCHO MESSACK | C24: 390000
A25: AS201620 | B25: =VLOOKUP(A25,LISTADHERENT!A$5:H$52,2,0) -> LOWE JEAN | C25: 390000
A26: AS201621 | B26: =VLOOKUP(A26,LISTADHERENT!A$5:H$52,2,0) -> NANKAM APPOLINAIRE | C26: 390000
A27: AS201622 | B27: =VLOOKUP(A27,LISTADHERENT!A$5:H$52,2,0) -> NDJOMO ETIENNE | C27: 390000
A28: AS201623 | B28: =VLOOKUP(A28,LISTADHERENT!A$5:H$52,2,0) -> NDOMBOU JEAN CLAUDE | C28: 0
A29: AS201624 | B29: =VLOOKUP(A29,LISTADHERENT!A$5:H$52,2,0) -> NGONDIEP CLAUDE | C29: 390000
A30: AS201625 | B30: =VLOOKUP(A30,LISTADHERENT!A$5:H$52,2,0) -> NGONGANG JEAN THEODORE | C30: 0
A31: AS201626 | B31: =VLOOKUP(A31,LISTADHERENT!A$5:H$52,2,0) -> NGUIEMEGNI MATHIEU BLAISE | C31: =390000-375111 -> 14889 | L31: 390000
A32: AS201627 | B32: =VLOOKUP(A32,LISTADHERENT!A$5:H$52,2,0) -> NJEPDJIO MBOUKAM DELUXE | C32: 390000
A33: AS201628 | B33: =VLOOKUP(A33,LISTADHERENT!A$5:H$52,2,0) -> NKAMGANG JUSTIN DEJOLIE | C33: 0 | K33: 372800
A34: AS201629 | B34: =VLOOKUP(A34,LISTADHERENT!A$5:H$52,2,0) -> NKEPSEU DIEUDONNE | C34: 390000
A35: AS201630 | B35: =VLOOKUP(A35,LISTADHERENT!A$5:H$52,2,0) -> NKEPSEU HENANG RENE | C35: 390000
A36: AS201631 | B36: =VLOOKUP(A36,LISTADHERENT!A$5:H$52,2,0) -> NTEPDIE TUEMAC MZ | C36: 0
A37: AS201632 | B37: =VLOOKUP(A37,LISTADHERENT!A$5:H$52,2,0) -> NTOMBOU ADOLPHE | C37: 0
A38: AS201633 | B38: =VLOOKUP(A38,LISTADHERENT!A$5:H$52,2,0) -> PATEGO NJOSSU GUSTAVE | C38: 390000
A39: AS201634 | B39: =VLOOKUP(A39,LISTADHERENT!A$5:H$52,2,0) -> SEUNOU RICHELOT | C39: 390000
A40: AS201635 | B40: =VLOOKUP(A40,LISTADHERENT!A$5:H$52,2,0) -> SIME ABEL | C40: 0 | L40: 390000
...

Sheet Sheet6
A1: ASSOCIATION | B1: ASELBY
A2: ANNEE | B2: 2016/2017
A3: TONTINE | B3: 20 000
A4: MATRICULE | B4: NOM ET PRENOM | C4: FONDS DE CAISSE | D4: RELIQUAT 2015 | E4: REPARTITION INTERET | F4: CAPITAL COMPOSE | G4: SANCTION | H4: MONTANT VERSE | I4: EPARGNE | J4: FONDS DE ROULEMENT | K4: FRAIS EXCEPTIONNEL | L4: COLLATION | M4: MUTUELLE | N4: TONTINE | O4: EMPRUNT | P4: INTERET EMPRUNT | Q4: REMBOURSEMENT | R4: PENALITE EMPRUNT | S4: PENALITE FONDS
A5: AS201648 | B5: =VLOOKUP(A5,LISTADHERENT!A$5:H$52,2,0) -> ASELBY | C5: =VLOOKUP(A5,FONDSDECAISSE!A$5:C$52,3,0) -> 0 | D5: 318145 | E5: =$P$56/$F$56*F5 -> 1799.2102 | F5: =RECAPTONT20000!C5+RECAPTONT20000!D5+TONT20000DEC2015!I5 -> 318145
A6: AS201601 | B6: =VLOOKUP(A6,LISTADHERENT!A$5:H$52,2,0) -> BAKOP ACHILLE | C6: =VLOOKUP(A6,FONDSDECAISSE!A$5:C$52,3,0) -> 390000 | D6: 33536 | E6: =$P$56/$F$56*F6 -> 2412.1955 | F6: =RECAPTONT20000!C6+RECAPTONT20000!D6+TONT20000DEC2015!I6 -> 426536 | H6: =I6+J6+K6+L6+M7+N7 -> 20000 | I6: 3000 | J6: 500 | K6: 1000 | L6: 2500 | N6: 13000 | P6: =IF(O6<=500000,(O6*1*3/100),(O6*12/100)) -> 0
A7: AS201602 | B7: =VLOOKUP(A7,LISTADHERENT!A$5:H$51,2) -> BOUTCHOUANG WILLIAM | C7: =VLOOKUP(A7,FONDSDECAISSE!A$5:C$52,3,0) -> 390000 | D7: 1704 | E7: =$P$56/$F$56*F7 -> 2232.1755 | F7: =RECAPTONT20000!C7+RECAPTONT20000!D7+TONT20000DEC2015!I7 -> 394704 | H7: =I7+J7+K7+L7+M8+N8 -> 20000 | I7: 3000 | J7: 500 | K7: 1000 | L7: 2500 | N7: 13000 | P7: =IF(O7<=500000,(O7*1*3/100),(O7*12/100)) -> 0
A8: AS201603 | B8: =VLOOKUP(A8,LISTADHERENT!A$5:H$51,2) -> CHINGUE FABRICE | C8: =VLOOKUP(A8,FONDSDECAISSE!A$5:C$52,3,0) -> 390000 | D8: 1842 | E8: =$P$56/$F$56*F8 -> 2232.9559 | F8: =RECAPTONT20000!C8+RECAPTONT20000!D8+TONT20000DEC2015!I8 -> 394842 | H8: =I8+J8+K8+L8+M8+N8 -> 20000 | I8: 3000 | J8: 500 | K8: 1000 | L8: 2500 | N8: 13000 | P8: =IF(O8<=500000,(O8*1*3/100),(O8*12/100)) -> 0
A9: AS201604 | B9: =VLOOKUP(A9,LISTADHERENT!A$5:H$51,2) -> DJOMO JEAN PAUL | C9: =VLOOKUP(A9,FONDSDECAISSE!A$5:C$52,3,0) -> 390000 | D9: 8156 | E9: =$P$56/$F$56*F9 -> 2268.6636 | F9: =RECAPTONT20000!C9+RECAPTONT20000!D9+TONT20000DEC2015!I9 -> 401156 | H9: =I9+J9+K9+L9+M9+N9 -> 20000 | I9: 3000 | J9: 500 | K9: 1000 | L9: 2500 | N9: 13000 | P9: =IF(O9<=500000,(O9*1*3/100),(O9*12/100)) -> 0
A10: AS201605 | B10: =VLOOKUP(A10,LISTADHERENT!A$5:H$51,2) -> DJOUKWE GUY | C10: =VLOOKUP(A10,FONDSDECAISSE!A$5:C$52,3,0) -> 390000 | D10: 5905 | E10: =$P$56/$F$56*F10 -> 2284.21 | F10: =RECAPTONT20000!C10+RECAPTONT20000!D10+TONT20000DEC2015!I10 -> 403905 | H10: =I10+J10+K10+L10+M10+N10 -> 25000 | I10: 8000 | J10: 500 | K10: 1000 | L10: 2500 | N10: 13000 | P10: =IF(O10<=500000,(O10*1*3/100),(O10*12/100)) -> 0
A11: AS201606 | B11: =VLOOKUP(A11,LISTADHERENT!A$5:H$51,2) -> DJOSSEU JOSUE | C11: =VLOOKUP(A11,FONDSDECAISSE!A$5:C$52,3,0) -> 0 | D11: 0 | E11: =$P$56/$F$56*F11 -> 28.276575 | F11: =RECAPTONT20000!C11+RECAPTONT20000!D11+TONT20000DEC2015!I11 -> 5000 | H11: =I11+J11+K11+L11+M11+N11 -> 22000 | I11: 5000 | J11: 500 | K11: 1000 | L11: 2500 | N11: 13000 | P11: =IF(O11<=500000,(O11*1*3/100),(O11*12/100)) -> 0
A12: AS201607 | B12: =VLOOKUP(A12,LISTADHERENT!A$5:H$51,2) -> DJOUNKEP SAMUEL | C12: =VLOOKUP(A12,FONDSDECAISSE!A$5:C$52,3,0) -> 390000 | D12: 1055294 | E12: =$P$56/$F$56*F12 -> 7796.3551 | F12: =RECAPTONT20000!C12+RECAPTONT20000!D12+TONT20000DEC2015!I12 -> 1378589 | H12: =I12+J12+K12+L12+M12+N12 -> 20000 | I12: 3000 | J12: 500 | K12: 1000 | L12: 2500 | N12: 13000 | P12: =IF(O12<=500000,(O12*1*3/100),(O12*12/100)) -> 0
A13: AS201608 | B13: =VLOOKUP(A13,LISTADHERENT!A$5:H$51,2) -> DJUOMBESSY ANTOINE | C13: =VLOOKUP(A13,FONDSDECAISSE!A$5:C$52,3,0) -> 319134 | D13: 0 | E13: =$P$56/$F$56*F13 -> 1821.7693 | F13: =RECAPTONT20000!C13+RECAPTONT20000!D13+TONT20000DEC2015!I13 -> 322134 | H13: =I13+J13+K13+L13+M13+N13 -> 20000 | I13: 3000 | J13: 500 | K13: 1000 | L13: 2500 | N13: 13000 | P13: =IF(O13<=500000,(O13*1*3/100),(O13*12/100)) -> 0
A14: AS201609 | B14: =VLOOKUP(A14,LISTADHERENT!A$5:H$51,2) -> DONHOU DAVID | C14: =VLOOKUP(A14,FONDSDECAISSE!A$5:C$52,3,0) -> 390000 | D14: 44734 | E14: =$P$56/$F$56*F14 -> 2475.5237 | F14: =RECAPTONT20000!C14+RECAPTONT20000!D14+TONT20000DEC2015!I14 -> 437734 | H14: =I14+J14+K14+L14+M14+N14 -> 20000 | I14: 3000 | J14: 500 | K14: 1000 | L14: 2500 | N14: 13000 | P14: =IF(O14<=500000,(O14*1*3/100),(O14*12/100)) -> 0
A15: AS201610 | B15: =VLOOKUP(A15,LISTADHERENT!A$5:H$51,2) -> FOTSO THOMAS | C15: =VLOOKUP(A15,FONDSDECAISSE!A$5:C$52,3,0) -> 390000 | D15: 3318 | E15: =$P$56/$F$56*F15 -> 2241.3032 | F15: =RECAPTONT20000!C15+RECAPTONT20000!D15+TONT20000DEC2015!I15 -> 396318 | H15: =I15+J15+K15+L15+M15+N15 -> 20000 | I15: 3000 | J15: 500 | K15: 1000 | L15: 2500 | N15: 13000 | P15: =IF(O15<=500000,(O15*1*3/100),(O15*12/100)) -> 0
A16: AS201611 | B16: =VLOOKUP(A16,LISTADHERENT!A$5:H$51,2) -> HENGUE PAUL OMER | C16: =VLOOKUP(A16,FONDSDECAISSE!A$5:C$52,3,0) -> 390000 | E16: =$P$56/$F$56*F16 -> 2222.5388 | F16: =RECAPTONT20000!C16+RECAPTONT20000!D16+TONT20000DEC2015!I16 -> 393000 | H16: =I16+J16+K16+L16+M16+N16 -> 20000 | I16: 3000 | J16: 500 | K16: 1000 | L16: 2500 | N16: 13000 | P16: =IF(O16<=500000,(O16*1*3/100),(O16*12/100)) -> 0
A17: AS201612 | B17: =VLOOKUP(A17,LISTADHERENT!A$5:H$51,2) -> HODIEP JULES | C17: =VLOOKUP(A17,FONDSDECAISSE!A$5:C$52,3,0) -> 0 | D17: 0 | E17: =$P$56/$F$56*F17 -> 16.965945 | F17: =RECAPTONT20000!C17+RECAPTONT20000!D17+TONT20000DEC2015!I17 -> 3000 | H17: =I17+J17+K17+L17+M17+N17 -> 20000 | I17: 3000 | J17: 500 | K17: 1000 | L17: 2500 | N17: 13000 | P17: =IF(O17<=500000,(O17*1*3/100),(O17*12/100)) -> 0
A18: AS201613 | B18: =VLOOKUP(A18,LISTADHERENT!A$5:H$51,2) -> HOTCHO BENJAMIN | C18: =VLOOKUP(A18,FONDSDECAISSE!A$5:C$52,3,0) -> 390000 | D18: 8723 | E18: =$P$56/$F$56*F18 -> 2271.8701 | F18: =RECAPTONT20000!C18+RECAPTONT20000!D18+TONT20000DEC2015!I18 -> 401723 | H18: =I18+J18+K18+L18+M18+N18 -> 20000 | I18: 3000 | J18: 500 | K18: 1000 | L18: 2500 | N18: 13000 | P18: =IF(O18<=500000,(O18*1*3/100),(O18*12/100)) -> 0
A19: AS201614 | B19: =VLOOKUP(A19,LISTADHERENT!A$5:H$51,2) -> KEPHE DAVID | C19: =VLOOKUP(A19,FONDSDECAISSE!A$5:C$52,3,0) -> 0 | D19: 12795 | E19: =$P$56/$F$56*F19 -> 89.325701 | F19: =RECAPTONT20000!C19+RECAPTONT20000!D19+TONT20000DEC2015!I19 -> 15795 | H19: =I19+J19+K19+L19+M19+N19 -> 20000 | I19: 3000 | J19: 500 | K19: 1000 | L19: 2500 | N19: 13000 | P19: =IF(O19<=500000,(O19*1*3/100),(O19*12/100)) -> 0
A20: AS201615 | B20: =VLOOKUP(A20,LISTADHERENT!A$5:H$51,2) -> KEPSEU FRANCIS | C20: =VLOOKUP(A20,FONDSDECAISSE!A$5:C$52,3,0) -> 390000 | D20: 186997 | E20: =$P$56/$F$56*F20 -> 3297.0317 | F20: =RECAPTONT20000!C20+RECAPTONT20000!D20+TONT20000DEC2015!I20 -> 582997 | H20: =I20+J20+K20+L20+M20+N20 -> 23000 | I20: 6000 | J20: 500 | K20: 1000 | L20: 2500 | N20: 13000 | P20: =IF(O20<=500000,(O20*1*3/100),(O20*12/100)) -> 0
A21: AS201616 | B21: =VLOOKUP(A21,LISTADHERENT!A$5:H$51,2) -> KOUAMOU EMMANUEL | C21: =VLOOKUP(A21,FONDSDECAISSE!A$5:C$52,3,0) -> 390000 | D21: 2723 | E21: =$P$56/$F$56*F21 -> 2237.9382 | F21: =RECAPTONT20000!C21+RECAPTONT20000!D21+TONT20000DEC2015!I21 -> 395723 | H21: =I21+J21+K21+L21+M21+N21 -> 20000 | I21: 3000 | J21: 500 | K21: 1000 | L21: 2500 | N21: 13000 | P21: =IF(O21<=500000,(O21*1*3/100),(O21*12/100)) -> 0
A22: AS201617 | B22: =VLOOKUP(A22,LISTADHERENT!A$5:H$51,2) -> KOUAMOU MOISE | C22: =VLOOKUP(A22,FONDSDECAISSE!A$5:C$52,3,0) -> 315000 | D22: 2099 | E22: =$P$56/$F$56*F22 -> 1810.2607 | F22: =RECAPTONT20000!C22+RECAPTONT20000!D22+TONT20000DEC2015!I22 -> 320099 | H22: =I22+J22+K22+L22+M22+N22 -> 20000 | I22: 3000 | J22: 500 | K22: 1000 | L22: 2500 | N22: 13000 | P22: =IF(O22<=500000,(O22*1*3/100),(O22*12/100)) -> 0
A23: AS201618 | B23: =VLOOKUP(A23,LISTADHERENT!A$5:H$51,2) -> KOUAMOU VICTOR PEGUY | C23: =VLOOKUP(A23,FONDSDECAISSE!A$5:C$52,3,0) -> 390000 | D23: 36629 | E23: =$P$56/$F$56*F23 -> 2429.6874 | F23: =RECAPTONT20000!C23+RECAPTONT20000!D23+TONT20000DEC2015!I23 -> 429629 | H23: =I23+J23+K23+L23+M23+N23 -> 20000 | I23: 3000 | J23: 500 | K23: 1000 | L23: 2500 | N23: 13000 | P23: =IF(O23<=500000,(O23*1*3/100),(O23*12/100)) -> 0
A24: AS201619 | B24: =VLOOKUP(A24,LISTADHERENT!A$5:H$51,2) -> KOUATCHO MESSACK | C24: =VLOOKUP(A24,FONDSDECAISSE!A$5:C$52,3,0) -> 390000 | D24: 0 | E24: =$P$56/$F$56*F24 -> 2222.5388 | F24: =RECAPTONT20000!C24+RECAPTONT20000!D24+TONT20000DEC2015!I24 -> 393000 | H24: =I24+J24+K24+L24+M24+N24 -> 20000 | I24: 3000 | J24: 500 | K24: 1000 | L24: 2500 | N24: 13000 | O24: 600000 | P24: =IF(O24<=500000,(O24*1*3/100),(O24*12/100)) -> 72000
A25: AS201620 | B25: =VLOOKUP(A25,LISTADHERENT!A$5:H$51,2) -> LOWE JEAN | C25: =VLOOKUP(A25,FONDSDECAISSE!A$5:C$52,3,0) -> 390000 | D25: 4331 | E25: =$P$56/$F$56*F25 -> 2247.032 | F25: =RECAPTONT20000!C25+RECAPTONT20000!D25+TONT20000DEC2015!I25 -> 397331 | H25: =I25+J25+K25+L25+M25+N25 -> 20000 | I25: 3000 | J25: 500 | K25: 1000 | L25: 2500 | N25: 13000 | P25: =IF(O25<=500000,(O25*1*3/100),(O25*12/100)) -> 0
A26: AS201621 | B26: =VLOOKUP(A26,LISTADHERENT!A$5:H$51,2) -> NANKAM APPOLINAIRE | C26: =VLOOKUP(A26,FONDSDECAISSE!A$5:C$52,3,0) -> 390000 | D26: 4411 | E26: =$P$56/$F$56*F26 -> 2247.4844 | F26: =RECAPTONT20000!C26+RECAPTONT20000!D26+TONT20000DEC2015!I26 -> 397411 | H26: =I26+J26+K26+L26+M26+N26 -> 20000 | I26: 3000 | J26: 500 | K26: 1000 | L26: 2500 | N26: 13000 | P26: =IF(O26<=500000,(O26*1*3/100),(O26*12/100)) -> 0
A27: AS201622 | B27: =VLOOKUP(A27,LISTADHERENT!A$5:H$51,2) -> NDJOMO ETIENNE | C27: =VLOOKUP(A27,FONDSDECAISSE!A$5:C$52,3,0) -> 390000 | D27: 2060 | E27: =$P$56/$F$56*F27 -> 2262.4653 | F27: =RECAPTONT20000!C27+RECAPTONT20000!D27+TONT20000DEC2015!I27 -> 400060 | H27: =I27+J27+K27+L27+M27+N27 -> 25000 | I27: 8000 | J27: 500 | K27: 1000 | L27: 2500 | N27: 13000 | O27: 400000 | P27: =IF(O27<=500000,(O27*1*3/100),(O27*12/100)) -> 12000
A28: AS201623 | B28: =VLOOKUP(A28,LISTADHERENT!A$5:H$51,2) -> NDOMBOU JEAN CLAUDE | C28: =VLOOKUP(A28,FONDSDECAISSE!A$5:C$52,3,0) -> 0 | D28: 0 | E28: =$P$56/$F$56*F28 -> 0 | F28: =RECAPTONT20000!C28+RECAPTONT20000!D28+TONT20000DEC2015!I28 -> 0 | H28: =I28+J28+K28+L28+M28+N28 -> 0 | P28: =IF(O28<=500000,(O28*1*3/100),(O28*12/100)) -> 0
A29: AS201624 | B29: =VLOOKUP(A29,LISTADHERENT!A$5:H$51,2) -> NGONDIEP CLAUDE | C29: =VLOOKUP(A29,FONDSDECAISSE!A$5:C$52,3,0) -> 390000 | D29: 179574 | E29: =$P$56/$F$56*F29 -> 3238.0864 | F29: =RECAPTONT20000!C29+RECAPTONT20000!D29+TONT20000DEC2015!I29 -> 572574 | H29: =I29+J29+K29+L29+M29+N29 -> 20000 | I29: 3000 | J29: 500 | K29: 1000 | L29: 2500 | N29: 13000 | P29: =IF(O29<=500000,(O29*1*3/100),(O29*12/100)) -> 0
A30: AS201625 | B30: =VLOOKUP(A30,LISTADHERENT!A$5:H$51,2) -> NGONGANG JEAN THEODORE | C30: =VLOOKUP(A30,FONDSDECAISSE!A$5:C$52,3,0) -> 0 | D30: 0 | E30: =$P$56/$F$56*F30 -> 16.965945 | F30: =RECAPTONT20000!C30+RECAPTONT20000!D30+TONT20000DEC2015!I30 -> 3000 | H30: =I30+J30+K30+L30+M30+N30 -> 20000 | I30: 3000 | J30: 500 | K30: 1000 | L30: 2500 | N30: 13000 | P30: =IF(O30<=500000,(O30*1*3/100),(O30*12/100)) -> 0
A31: AS201626 | B31: =VLOOKUP(A31,LISTADHERENT!A$5:H$51,2) -> NGUIEMEGNI MATHIEU BLAISE | C31: =VLOOKUP(A31,FONDSDECAISSE!A$5:C$52,3,0) -> 14889 | D31: 0 | E31: =$P$56/$F$56*F31 -> 101.16793 | F31: =RECAPTONT20000!C31+RECAPTONT20000!D31+TONT20000DEC2015!I31 -> 17889 | H31: =I31+J31+K31+L31+M31+N31 -> 20000 | I31: 3000 | J31: 500 | K31: 1000 | L31: 2500 | N31: 13000 | P31: =IF(O31<=500000,(O31*1*3/100),(O31*12/100)) -> 0
A32: AS201627 | B32: =VLOOKUP(A32,LISTADHERENT!A$5:H$51,2) -> NJEPDJIO MBOUKAM DELUXE | C32: =VLOOKUP(A32,FONDSDECAISSE!A$5:C$52,3,0) -> 390000 | D32: 1734 | E32: =$P$56/$F$56*F32 -> 2243.6558 | F32: =RECAPTONT20000!C32+RECAPTONT20000!D32+TONT20000DEC2015!I32 -> 396734 | H32: =I32+J32+K32+L32+M32+N32 -> 22000 | I32: 5000 | J32: 500 | K32: 1000 | L32: 2500 | N32: 13000 | P32: =IF(O32<=500000,(O32*1*3/100),(O32*12/100)) -> 0
A33: AS201628 | B33: =VLOOKUP(A33,LISTADHERENT!A$5:H$51,2) -> NKAMGANG JUSTIN DEJOLIE | C33: =VLOOKUP(A33,FONDSDECAISSE!A$5:C$52,3,0) -> 0 | D33: 0 | E33: =$P$56/$F$56*F33 -> 33.93189 | F33: =RECAPTONT20000!C33+RECAPTONT20000!D33+TONT20000DEC2015!I33 -> 6000 | H33: =I33+J33+K33+L33+M33+N33 -> 23000 | I33: 6000 | J33: 500 | K33: 1000 | L33: 2500 | N33: 13000 | P33: =IF(O33<=500000,(O33*1*3/100),(O33*12/100)) -> 0
A34: AS201629 | B34: =VLOOKUP(A34,LISTADHERENT!A$5:H$51,2) -> NKEPSEU DIEUDONNE | C34: =VLOOKUP(A34,FONDSDECAISSE!A$5:C$52,3,0) -> 390000 | D34: 8739 | E34: =$P$56/$F$56*F34 -> 2300.2372 | F34: =RECAPTONT20000!C34+RECAPTONT20000!D34+TONT20000DEC2015!I34 -> 406739 | H34: =I34+J34+K34+L34+M34+N34 -> 25000 | I34: 8000 | J34: 500 | K34: 1000 | L34: 2500 | N34: 13000 | P34: =IF(O34<=500000,(O34*1*3/100),(O34*12/100)) -> 0
A35: AS201630 | B35: =VLOOKUP(A35,LISTADHERENT!A$5:H$51,2) -> NKEPSEU HENANG RENE | C35: =VLOOKUP(A35,FONDSDECAISSE!A$5:C$52,3,0) -> 390000 | D35: 7983 | E35: =$P$56/$F$56*F35 -> 2267.6852 | F35: =RECAPTONT20000!C35+RECAPTONT20000!D35+TONT20000DEC2015!I35 -> 400983 | H35: =I35+J35+K35+L35+M35+N35 -> 20000 | I35: 3000 | J35: 500 | K35: 1000 | L35: 2500 | N35: 13000 | P35: =IF(O35<=500000,(O35*1*3/100),(O35*12/100)) -> 0
A36: AS201631 | B36: =VLOOKUP(A36,LISTADHERENT!A$5:H$51,2) -> NTEPDIE TUEMAC MZ | C36: =VLOOKUP(A36,FONDSDECAISSE!A$5:C$52,3,0) -> 0 | D36: 0 | E36: =$P$56/$F$56*F36 -> 16.965945 | F36: =RECAPTONT20000!C36+RECAPTONT20000!D36+TONT20000DEC2015!I36 -> 3000 | H36: =I36+J36+K36+L36+M36+N36 -> 20000 | I36: 3000 | J36: 500 | K36: 1000 | L36: 2500 | N36: 13000 | P36: =IF(O36<=500000,(O36*1*3/100),(O36*12/100)) -> 0
A37: AS201632 | B37: =VLOOKUP(A37,LISTADHERENT!A$5:H$51,2) -> NTOMBOU ADOLPHE | C37: =VLOOKUP(A37,FONDSDECAISSE!A$5:C$52,3,0) -> 0 | D37: 0 | E37: =$P$56/$F$56*F37 -> 16.965945 | F37: =RECAPTONT20000!C37+RECAPTONT20000!D37+TONT20000DEC2015!I37 -> 3000 | H37: =I37+J37+K37+L37+M37+N37 -> 20000 | I37: 3000 | J37: 500 | K37: 1000 | L37: 2500 | N37: 13000 | P37: =IF(O37<=500000,(O37*1*3/100),(O37*12/100)) -> 0
A38: AS201633 | B38: =VLOOKUP(A38,LISTADHERENT!A$5:H$51,2) -> PATEGO NJOSSU GUSTAVE | C38: =VLOOKUP(A38,FONDSDECAISSE!A$5:C$52,3,0) -> 390000 | D38: 140 | E38: =$P$56/$F$56*F38 -> 2223.3306 | F38: =RECAPTONT20000!C38+RECAPTONT20000!D38+TONT20000DEC2015!I38 -> 393140 | H38: =I38+J38+K38+L38+M38+N38 -> 20000 | I38: 3000 | J38: 500 | K38: 1000 | L38: 2500 | N38: 13000 | P38: =IF(O38<=500000,(O38*1*3/100),(O38*12/100)) -> 0
A39: AS201634 | B39: =VLOOKUP(A39,LISTADHERENT!A$5:H$51,2) -> SEUNOU RICHELOT | C39: =VLOOKUP(A39,FONDSDECAISSE!A$5:C$52,3,0) -> 390000 | D39: 2632 | E39: =$P$56/$F$56*F39 -> 2237.4236 | F39: =RECAPTONT20000!C39+RECAPTONT20000!D39+TONT20000DEC2015!I39 -> 395632 | H39: =I39+J39+K39+L39+M39+N39 -> 20000 | I39: 3000 | J39: 500 | K39: 1000 | L39: 2500 | N39: 13000 | P39: =IF(O39<=500000,(O39*1*3/100),(O39*12/100)) -> 0
A40: AS201635 | B40: =VLOOKUP(A40,LISTADHERENT!A$5:H$51,2) -> SIME ABEL | C40: =VLOOKUP(A40,FONDSDECAISSE!A$5:C$52,3,0) -> 0 | D40: 0 | E40: =$P$56/$F$56*F40 -> 16.965945 | F40: =RECAPTONT20000!C40+RECAPTONT20000!D40+TONT20000DEC2015!I40 -> 3000 | H40: =I40+J40+K40+L40+M40+N40 -> 20000 | I40: 3000 | J40: 500 | K40: 1000 | L40: 2500 | N40: 13000 | P40: =IF(O40<=500000,(O40*1*3/100),(O40*12/100)) -> 0
...

Sheet Sheet7
A1: ASSOCIATION | B1: ASELBY
A2: ANNEE | B2: 2016/2017
A3: TONTINE | B3: 20 000
A4: MATRICULE | B4: NOM ET PRENOM | C4: REPARTITION INTERET | D4: CAPITAL COMPOSE | E4: SANCTION | F4: MONTANT VERSE | G4: EPARGNE | H4: FONDS DE ROULEMENT | I4: FRAIS EXCEPTIONNEL | J4: COLLATION | K4: MUTUELLE | L4: TONTINE | M4: EMPRUNT | N4: INTERET EMPRUNT | O4: REMBOURSEMENT | P4: PENALITE EMPRUNT | Q4: PENALITE FONDS
A5: AS201648 | B5: =VLOOKUP(A5,LISTADHERENT!A$5:H$52,2,0) -> ASELBY | C5: =$N$56/$D$56*D5 -> 3347.8159 | D5: =TONT20000DEC2015!F5+TONT20000DEC2015!E5+TONT20000JANV!G5 -> 319944.21
A6: AS201601 | B6: =VLOOKUP(A6,LISTADHERENT!A$5:H$52,2,0) -> BAKOP ACHILLE | C6: =$N$56/$D$56*D6 -> 4519.7974 | D6: =TONT20000DEC2015!F6+TONT20000DEC2015!E6+TONT20000JANV!G6 -> 431948.2 | F6: =G6+H6+I6+J6+K6+L6 -> 20000 | G6: 3000 | H6: 500 | I6: 1000 | J6: 2500 | L6: 13000 | N6: =IF(M6<=500000,(M6*1*3/100),(M6*12/100)) -> 0
A7: AS201602 | B7: =VLOOKUP(A7,LISTADHERENT!A$5:H$51,2) -> BOUTCHOUANG WILLIAM | C7: =$N$56/$D$56*D7 -> 4184.8317 | D7: =TONT20000DEC2015!F7+TONT20000DEC2015!E7+TONT20000JANV!G7 -> 399936.18 | F7: =G7+H7+I7+J7+K7+L7 -> 20000 | G7: 3000 | H7: 500 | I7: 1000 | J7: 2500 | L7: 13000 | N7: =IF(M7<=500000,(M7*1*3/100),(M7*12/100)) -> 0
A8: AS201603 | B8: =VLOOKUP(A8,LISTADHERENT!A$5:H$51,2) -> CHINGUE FABRICE | C8: =$N$56/$D$56*D8 -> 4186.2839 | D8: =TONT20000DEC2015!F8+TONT20000DEC2015!E8+TONT20000JANV!G8 -> 400074.96 | F8: =G8+H8+I8+J8+K8+L8 -> 20000 | G8: 3000 | H8: 500 | I8: 1000 | J8: 2500 | L8: 13000 | M8: 1000000 | N8: =IF(M8<=500000,(M8*1*3/100),(M8*12/100))/2 -> 60000
A9: AS201604 | B9: =VLOOKUP(A9,LISTADHERENT!A$5:H$51,2) -> DJOMO JEAN PAUL | C9: =$N$56/$D$56*D9 -> 4252.7256 | D9: =TONT20000DEC2015!F9+TONT20000DEC2015!E9+TONT20000JANV!G9 -> 406424.66 | F9: =G9+H9+I9+J9+K9+L9 -> 20000 | G9: 3000 | H9: 500 | I9: 1000 | J9: 2500 | L9: 13000 | N9: =IF(M9<=500000,(M9*1*3/100),(M9*12/100)) -> 0
A10: AS201605 | B10: =VLOOKUP(A10,LISTADHERENT!A$5:H$51,2) -> DJOUKWE GUY | C10: =$N$56/$D$56*D10 -> 4281.6531 | D10: =TONT20000DEC2015!F10+TONT20000DEC2015!E10+TONT20000JANV!G10 -> 409189.21 | F10: =G10+H10+I10+J10+K10+L10 -> 20000 | G10: 3000 | H10: 500 | I10: 1000 | J10: 2500 | L10: 13000 | N10: =IF(M10<=500000,(M10*1*3/100),(M10*12/100)) -> 0
A11: AS201606 | B11: =VLOOKUP(A11,LISTADHERENT!A$5:H$51,2) -> DJOSSEU JOSUE | C11: =$N$56/$D$56*D11 -> 52.614623 | D11: =TONT20000DEC2015!F11+TONT20000DEC2015!E11+TONT20000JANV!G11 -> 5028.2766 | F11: =G11+H11+I11+J11+K11+L11 -> 0 | N11: =IF(M11<=500000,(M11*1*3/100),(M11*12/100)) -> 0
A12: AS201607 | B12: =VLOOKUP(A12,LISTADHERENT!A$5:H$51,2) -> DJOUNKEP SAMUEL | C12: =$N$56/$D$56*D12 -> 14747.454 | D12: =TONT20000DEC2015!F12+TONT20000DEC2015!E12+TONT20000JANV!G12 -> 1409385.4 | F12: =G12+H12+I12+J12+K12+L12 -> 40000 | G12: 23000 | H12: 500 | I12: 1000 | J12: 2500 | L12: 13000 | N12: =IF(M12<=500000,(M12*1*3/100),(M12*12/100)) -> 0
A13: AS201608 | B13: =VLOOKUP(A13,LISTADHERENT!A$5:H$51,2) -> DJUOMBESSY ANTOINE | C13: =$N$56/$D$56*D13 -> 3421.1831 | D13: =TONT20000DEC2015!F13+TONT20000DEC2015!E13+TONT20000JANV!G13 -> 326955.77 | F13: =G13+H13+I13+J13+K13+L13 -> 20000 | G13: 3000 | H13: 500 | I13: 1000 | J13: 2500 | L13: 13000 | N13: =IF(M13<=500000,(M13*1*3/100),(M13*12/100)) -> 0
A14: AS201609 | B14: =VLOOKUP(A14,LISTADHERENT!A$5:H$51,2) -> DONHOU DAVID | C14: =$N$56/$D$56*D14 -> 4637.6331 | D14: =TONT20000DEC2015!F14+TONT20000DEC2015!E14+TONT20000JANV!G14 -> 443209.52 | F14: =G14+H14+I14+J14+K14+L14 -> 20000 | G14: 3000 | H14: 500 | I14: 1000 | J14: 2500 | L14: 13000 | N14: =IF(M14<=500000,(M14*1*3/100),(M14*12/100)) -> 0
A15: AS201610 | B15: =VLOOKUP(A15,LISTADHERENT!A$5:H$51,2) -> FOTSO THOMAS | C15: =$N$56/$D$56*D15 -> 4201.8157 | D15: =TONT20000DEC2015!F15+TONT20000DEC2015!E15+TONT20000JANV!G15 -> 401559.3 | F15: =G15+H15+I15+J15+K15+L15 -> 20000 | G15: 3000 | H15: 500 | I15: 1000 | J15: 2500 | L15: 13000 | N15: =IF(M15<=500000,(M15*1*3/100),(M15*12/100)) -> 0
A16: AS201611 | B16: =VLOOKUP(A16,LISTADHERENT!A$5:H$51,2) -> HENGUE PAUL OMER | C16: =$N$56/$D$56*D16 -> 4166.9006 | D16: =TONT20000DEC2015!F16+TONT20000DEC2015!E16+TONT20000JANV!G16 -> 398222.54 | F16: =G16+H16+I16+J16+K16+L16 -> 20000 | G16: 3000 | H16: 500 | I16: 1000 | J16: 2500 | L16: 13000 | N16: =IF(M16<=500000,(M16*1*3/100),(M16*12/100)) -> 0
A17: AS201612 | B17: =VLOOKUP(A17,LISTADHERENT!A$5:H$51,2) -> HODIEP JULES | C17: =$N$56/$D$56*D17 -> 62.96002 | D17: =TONT20000DEC2015!F17+TONT20000DEC2015!E17+TONT20000JANV!G17 -> 6016.9659 | F17: =G17+H17+I17+J17+K17+L17 -> 20000 | G17: 3000 | H17: 500 | I17: 1000 | J17: 2500 | L17: 13000 | N17: =IF(M17<=500000,(M17*1*3/100),(M17*12/100)) -> 0
A18: AS201613 | B18: =VLOOKUP(A18,LISTADHERENT!A$5:H$51,2) -> HOTCHO BENJAMIN | C18: =$N$56/$D$56*D18 -> 4258.6921 | D18: =TONT20000DEC2015!F18+TONT20000DEC2015!E18+TONT20000JANV!G18 -> 406994.87 | F18: =G18+H18+I18+J18+K18+L18 -> 20000 | G18: 3000 | H18: 500 | I18: 1000 | J18: 2500 | L18: 13000 | N18: =IF(M18<=500000,(M18*1*3/100),(M18*12/100)) -> 0
A19: AS201614 | B19: =VLOOKUP(A19,LISTADHERENT!A$5:H$51,2) -> KEPHE DAVID | C19: =$N$56/$D$56*D19 -> 197.60084 | D19: =TONT20000DEC2015!F19+TONT20000DEC2015!E19+TONT20000JANV!G19 -> 18884.326 | F19: =G19+H19+I19+J19+K19+L19 -> 20000 | G19: 3000 | H19: 500 | I19: 1000 | J19: 2500 | L19: 13000 | N19: =IF(M19<=500000,(M19*1*3/100),(M19*12/100)) -> 0
A20: AS201615 | B20: =VLOOKUP(A20,LISTADHERENT!A$5:H$51,2) -> KEPSEU FRANCIS | C20: =$N$56/$D$56*D20 -> 6197.616 | D20: =TONT20000DEC2015!F20+TONT20000DEC2015!E20+TONT20000JANV!G20 -> 592294.03 | F20: =G20+H20+I20+J20+K20+L20 -> 23000 | G20: 6000 | H20: 500 | I20: 1000 | J20: 2500 | L20: 13000 | N20: =IF(M20<=500000,(M20*1*3/100),(M20*12/100)) -> 0
A21: AS201616 | B21: =VLOOKUP(A21,LISTADHERENT!A$5:H$51,2) -> KOUAMOU EMMANUEL | C21: =$N$56/$D$56*D21 -> 4195.5546 | D21: =TONT20000DEC2015!F21+TONT20000DEC2015!E21+TONT20000JANV!G21 -> 400960.94 | F21: =G21+H21+I21+J21+K21+L21 -> 20000 | G21: 3000 | H21: 500 | I21: 1000 | J21: 2500 | L21: 13000 | N21: =IF(M21<=500000,(M21*1*3/100),(M21*12/100)) -> 0
A22: AS201617 | B22: =VLOOKUP(A22,LISTADHERENT!A$5:H$51,2) -> KOUAMOU MOISE | C22: =$N$56/$D$56*D22 -> 3399.7689 | D22: =TONT20000DEC2015!F22+TONT20000DEC2015!E22+TONT20000JANV!G22 -> 324909.26 | F22: =G22+H22+I22+J22+K22+L22 -> 20000 | G22: 3000 | H22: 500 | I22: 1000 | J22: 2500 | L22: 13000 | N22: =IF(M22<=500000,(M22*1*3/100),(M22*12/100)) -> 0
A23: AS201618 | B23: =VLOOKUP(A23,LISTADHERENT!A$5:H$51,2) -> KOUAMOU VICTOR PEGUY | C23: =$N$56/$D$56*D23 -> 4552.3448 | D23: =TONT20000DEC2015!F23+TONT20000DEC2015!E23+TONT20000JANV!G23 -> 435058.69 | F23: =G23+H23+I23+J23+K23+L23 -> 20000 | G23: 3000 | H23: 500 | I23: 1000 | J23: 2500 | L23: 13000 | N23: =IF(M23<=500000,(M23*1*3/100),(M23*12/100)) -> 0
... A27: AS201622 | B27: =VLOOKUP(A27,LISTADHERENT!A$5:H$51,2) -> NDJOMO ETIENNE | C27: =$N$56/$D$56*D27 -> 4293.5112 | D27: =TONT20000DEC2015!F27+TONT20000DEC2015!E27+TONT20000JANV!G27 -> 410322.47 | F27: =G27+H27+I27+J27+K27+L27 -> 25000 | G27: 8000 | H27: 500 | I27: 1000 | J27: 2500 | L27: 13000 | N27: =IF(M27<=500000,(M27*1*3/100),(M27*12/100)) -> 0
A28: AS201623 | B28: =VLOOKUP(A28,LISTADHERENT!A$5:H$51,2) -> NDOMBOU JEAN CLAUDE | C28: =$N$56/$D$56*D28 -> 0 | D28: =TONT20000DEC2015!F28+TONT20000DEC2015!E28+TONT20000JANV!G28 -> 0 | F28: =G28+H28+I28+J28+K28+L28 -> 0 | N28: =IF(M28<=500000,(M28*1*3/100),(M28*12/100)) -> 0
A29: AS201624 | B29: =VLOOKUP(A29,LISTADHERENT!A$5:H$51,2) -> NGONDIEP CLAUDE | C29: =$N$56/$D$56*D29 -> 6056.5443 | D29: =TONT20000DEC2015!F29+TONT20000DEC2015!E29+TONT20000JANV!G29 -> 578812.09 | F29: =G29+H29+I29+J29+K29+L29 -> 20000 | G29: 3000 | H29: 500 | I29: 1000 | J29: 2500 | L29: 13000 | N29: =IF(M29<=500000,(M29*1*3/100),(M29*12/100)) -> 0
A30: AS201625 | B30: =VLOOKUP(A30,LISTADHERENT!A$5:H$51,2) -> NGONGANG JEAN THEODORE | C30: =$N$56/$D$56*D30 -> 62.96002 | D30: =TONT20000DEC2015!F30+TONT20000DEC2015!E30+TONT20000JANV!G30 -> 6016.9659 | F30: =G30+H30+I30+J30+K30+L30 -> 20000 | G30: 3000 | H30: 500 | I30: 1000 | J30: 2500 | L30: 13000 | N30: =IF(M30<=500000,(M30*1*3/100),(M30*12/100)) -> 0
A31: AS201626 | B31: =VLOOKUP(A31,LISTADHERENT!A$5:H$51,2) -> NGUIEMEGNI MATHIEU BLAISE | C31: =$N$56/$D$56*D31 -> 219.63585 | D31: =TONT20000DEC2015!F31+TONT20000DEC2015!E31+TONT20000JANV!G31 -> 20990.168 | F31: =G31+H31+I31+J31+K31+L31 -> 20000 | G31: 3000 | H31: 500 | I31: 1000 | J31: 2500 | L31: 13000 | N31: =IF(M31<=500000,(M31*1*3/100),(M31*12/100)) -> 0
A32: AS201627 | B32: =VLOOKUP(A32,LISTADHERENT!A$5:H$51,2) -> NJEPDJIO MBOUKAM DELUXE | C32: =$N$56/$D$56*D32 -> 4206.1932 | D32: =TONT20000DEC2015!F32+TONT20000DEC2015!E32+TONT20000JANV!G32 -> 401977.66 | F32: =G32+H32+I32+J32+K32+L32 -> 20000 | G32: 3000 | H32: 500 | I32: 1000 | J32: 2500 | L32: 13000 | N32: =IF(M32<=500000,(M32*1*3/100),(M32*12/100)) -> 0
A33: AS201628 | B33: =VLOOKUP(A33,LISTADHERENT!A$5:H$51,2) -> NKAMGANG JUSTIN DEJOLIE | C33: =$N$56/$D$56*D33 -> 125.92004 | D33: =TONT20000DEC2015!F33+TONT20000DEC2015!E33+TONT20000JANV!G33 -> 12033.932 | F33: =G33+H33+I33+J33+K33+L33 -> 23000 | G33: 6000 | H33: 500 | I33: 1000 | J33: 2500 | L33: 13000 | N33: =IF(M33<=500000,(M33*1*3/100),(M33*12/100)) -> 0
A34: AS201629 | B34: =VLOOKUP(A34,LISTADHERENT!A$5:H$51,2) -> NKEPSEU DIEUDONNE | C34: =$N$56/$D$56*D34 -> 4363.7938 | D34: =TONT20000DEC2015!F34+TONT20000DEC2015!E34+TONT20000JANV!G34 -> 417039.24 | F34: =G34+H34+I34+J34+K34+L34 -> 25000 | G34: 8000 | H34: 500 | I34: 1000 | J34: 2500 | L34: 13000 | N34: =IF(M34<=500000,(M34*1*3/100),(M34*12/100)) -> 0
A35: AS201630 | B35: =VLOOKUP(A35,LISTADHERENT!A$5:H$51,2) -> NKEPSEU HENANG RENE | C35: =$N$56/$D$56*D35 -> 4250.9051 | D35: =TONT20000DEC2015!F35+TONT20000DEC2015!E35+TONT20000JANV!G35 -> 406250.69 | F35: =G35+H35+I35+J35+K35+L35 -> 20000 | G35: 3000 | H35: 500 | I35: 1000 | J35: 2500 | L35: 13000 | N35: =IF(M35<=500000,(M35*1*3/100),(M35*12/100)) -> 0
A36: AS201631 | B36: =VLOOKUP(A36,LISTADHERENT!A$5:H$51,2) -> NTEPDIE TUEMAC MZ | C36: =$N$56/$D$56*D36 -> 62.96002 | D36: =TONT20000DEC2015!F36+TONT20000DEC2015!E36+TONT20000JANV!G36 -> 6016.9659 | F36: =G36+H36+I36+J36+K36+L36 -> 20000 | G36: 3000 | H36: 500 | I36: 1000 | J36: 2500 | L36: 13000 | N36: =IF(M36<=500000,(M36*1*3/100),(M36*12/100)) -> 0
A37: AS201632 | B37: =VLOOKUP(A37,LISTADHERENT!A$5:H$51,2) -> NTOMBOU ADOLPHE | C37: =$N$56/$D$56*D37 -> 62.96002 | D37: =TONT20000DEC2015!F37+TONT20000DEC2015!E37+TONT20000JANV!G37 -> 6016.9659 | F37: =G37+H37+I37+J37+K37+L37 -> 20000 | G37: 3000 | H37: 500 | I37: 1000 | J37: 2500 | L37: 13000 | N37: =IF(M37<=500000,(M37*1*3/100),(M37*12/100)) -> 0
A38: AS201633 | B38: =VLOOKUP(A38,LISTADHERENT!A$5:H$51,2) -> PATEGO NJOSSU GUSTAVE | C38: =$N$56/$D$56*D38 -> 4168.3738 | D38: =TONT20000DEC2015!F38+TONT20000DEC2015!E38+TONT20000JANV!G38 -> 398363.33 | F38: =G38+H38+I38+J38+K38+L38 -> 20000 | G38: 3000 | H38: 500 | I38: 1000 | J38: 2500 | L38: 13000 | N38: =IF(M38<=500000,(M38*1*3/100),(M38*12/100)) -> 0
A39: AS201634 | B39: =VLOOKUP(A39,LISTADHERENT!A$5:H$51,2) -> SEUNOU RICHELOT | C39: =$N$56/$D$56*D39 -> 4194.597 | D39: =TONT20000DEC2015!F39+TONT20000DEC2015!E39+TONT20000JANV!G39 -> 400869.42 | F39: =G39+H39+I39+J39+K39+L39 -> 20000 | G39: 3000 | H39: 500 | I39: 1000 | J39: 2500 | L39: 13000 | N39: =IF(M39<=500000,(M39*1*3/100),(M39*12/100)) -> 0
A40: AS201635 | B40: =VLOOKUP(A40,LISTADHERENT!A$5:H$51,2) -> SIME ABEL | C40: =$N$56/$D$56*D40 -> 62.96002 | D40: =TONT20000DEC2015!F40+TONT20000DEC2015!E40+TONT20000JANV!G40 -> 6016.9659 | F40: =G40+H40+I40+J40+K40+L40 -> 20000 | G40: 3000 | H40: 500 | I40: 1000 | J40: 2500 | L40: 13000 | N40: =IF(M40<=500000,(M40*1*3/100),(M40*12/100)) -> 0
... A42: AS201637 | B42: =VLOOKUP(A42,LISTADHERENT!A$5:H$51,2) -> SIME MATHIEU | C42: =$N$56/$D$56*D42 -> 4173.5932 | D42: =TONT20000DEC2015!F42+TONT20000DEC2015!E42+TONT20000JANV!G42 -> 398862.14 | F42: =G42+H42+I42+J42+K42+L42 -> 20000 | G42: 3000 | H42: 500 | I42: 1000 | J42: 2500 | L42: 13000 | N42: =IF(M42<=500000,(M42*1*3/100),(M42*12/100)) -> 0
A43: AS201638 | B43: =VLOOKUP(A43,LISTADHERENT!A$5:H$51,2) -> SIME PIERRE | C43: =$N$56/$D$56*D43 -> 14964.253 | D43: =TONT20000DEC2015!F43+TONT20000DEC2015!E43+TONT20000JANV!G43 -> 1430104.3 | F43: =G43+H43+I43+J43+K43+L43 -> 20000 | G43: 3000 | H43: 500 | I43: 1000 | J43: 2500 | L43: 13000 | M43: 200000 | N43: =IF(M43<=500000,(M43*1*3/100),(M43*12/100)) -> 6000
A44: AS201639 | B44: =VLOOKUP(A44,LISTADHERENT!A$5:H$51,2) -> TAGNE NANGUEN MARTIN | C44: =$N$56/$D$56*D44 -> 62.96002 | D44: =TONT20000DEC2015!F44+TONT20000DEC2015!E44+TONT20000JANV!G44 -> 6016.9659 | F44: =G44+H44+I44+J44+K44+L44 -> 20000 | G44: 3000 | H44: 500 | I44: 1000 | J44: 2500 | L44: 13000 | N44: =IF(M44<=500000,(M44*1*3/100),(M44*12/100)) -> 0
...

Sheet Sheet8
A1: ASSOCIATION | B1: ASELBY
A2: ANNEE | B2: 2016/2017
A3: TONTINE | B3: 20 000
A4: MATRICULE | B4: NOM ET PRENOM | C4: REPARTITION INTERET | D4: CAPITAL COMPOSE | E4: SANCTION | F4: MONTANT VERSE | G4: EPARGNE | H4: FONDS DE ROULEMENT | I4: FRAIS EXCEPTIONNEL | J4: COLLATION | K4: MUTUELLE | L4: TONTINE | M4: EMPRUNT | N4: INTERET EMPRUNT | O4: REMBOURSEMENT | P4: PENALITE EMPRUNT | Q4: PENALITE FONDS
A5: AS201648 | B5: =VLOOKUP(A5,LISTADHERENT!A$5:H$52,2,0) -> ASELBY | C5: =$N$56/$D$56*D5 -> 401.49071 | D5: =TONT20000JANV!C5+TONT20000JANV!D5+TONT20000FEV!G5 -> 323292.03
A6: AS201601 | B6: =VLOOKUP(A6,LISTADHERENT!A$5:H$52,2,0) -> BAKOP ACHILLE | C6: =$N$56/$D$56*D6 -> 545.76761 | D6: =TONT20000JANV!C6+TONT20000JANV!D6+TONT20000FEV!G6 -> 439467.99 | F6: =G6+H6+I6+J6+K6+L6 -> 20000 | G6: 3000 | H6: 500 | I6: 1000 | J6: 2500 | L6: 13000 | N6: =IF(M6<=500000,(M6*1*3/100),(M6*12/100)) -> 0
A7: AS201602 | B7: =VLOOKUP(A7,LISTADHERENT!A$5:H$51,2) -> BOUTCHOUANG WILLIAM | C7: =$N$56/$D$56*D7 -> 505.59646 | D7: =TONT20000JANV!C7+TONT20000JANV!D7+TONT20000FEV!G7 -> 407121.01 | F7: =G7+H7+I7+J7+K7+L7 -> 20000 | G7: 3000 | H7: 500 | I7: 1000 | J7: 2500 | L7: 13000 | N7: =IF(M7<=500000,(M7*1*3/100),(M7*12/100)) -> 0
A8: AS201603 | B8: =VLOOKUP(A8,LISTADHERENT!A$5:H$51,2) -> CHINGUE FABRICE | C8: =$N$56/$D$56*D8 -> 505.77061 | D8: =TONT20000JANV!C8+TONT20000JANV!D8+TONT20000FEV!G8 -> 407261.24 | F8: =G8+H8+I8+J8+K8+L8 -> 20000 | G8: 3000 | H8: 500 | I8: 1000 | J8: 2500 | L8: 13000 | N8: =IF(M8<=500000,(M8*1*3/100),(M8*12/100)) -> 0
A9: AS201604 | B9: =VLOOKUP(A9,LISTADHERENT!A$5:H$51,2) -> DJOMO JEAN PAUL | C9: =$N$56/$D$56*D9 -> 513.73871 | D9: =TONT20000JANV!C9+TONT20000JANV!D9+TONT20000FEV!G9 -> 413677.39 | F9: =G9+H9+I9+J9+K9+L9 -> 20000 | G9: 3000 | H9: 500 | I9: 1000 | J9: 2500 | L9: 13000 | N9: =IF(M9<=500000,(M9*1*3/100),(M9*12/100)) -> 0
A10: AS201605 | B10: =VLOOKUP(A10,LISTADHERENT!A$5:H$51,2) -> DJOUKWE GUY | C10: =$N$56/$D$56*D10 -> 517.20788 | D10: =TONT20000JANV!C10+TONT20000JANV!D10+TONT20000FEV!G10 -> 416470.86 | F10: =G10+H10+I10+J10+K10+L10 -> 20000 | G10: 3000 | H10: 500 | I10: 1000 | J10: 2500 | L10: 13000 | M10: 250000 | N10: =IF(M10<=500000,(M10*1*3/100),(M10*12/100)) -> 7500
A11: AS201606 | B11: =VLOOKUP(A11,LISTADHERENT!A$5:H$51,2) -> DJOSSEU JOSUE | C11: =$N$56/$D$56*D11 -> 6.3098699 | D11: =TONT20000JANV!C11+TONT20000JANV!D11+TONT20000FEV!G11 -> 5080.8912 | F11: =G11+H11+I11+J11+K11+L11 -> 0 | N11: =IF(M11<=500000,(M11*1*3/100),(M11*12/100)) -> 0
A12: AS201607 | B12: =VLOOKUP(A12,LISTADHERENT!A$5:H$51,2) -> DJOUNKEP SAMUEL | C12: =$N$56/$D$56*D12 -> 1772.3313 | D12: =TONT20000JANV!C12+TONT20000JANV!D12+TONT20000FEV!G12 -> 1427132.8 | F12: =G12+H12+I12+J12+K12+L12 -> 20000 | G12: 3000 | H12: 500 | I12: 1000 | J12: 2500 | L12: 13000 | N12: =IF(M12<=500000,(M12*1*3/100),(M12*12/100)) -> 0
A13: AS201608 | B13: =VLOOKUP(A13,LISTADHERENT!A$5:H$51,2) -> DJUOMBESSY ANTOINE | C13: =$N$56/$D$56*D13 -> 414.015 | D13: =TONT20000JANV!C13+TONT20000JANV!D13+TONT20000FEV!G13 -> 333376.95 | F13: =G13+H13+I13+J13+K13+L13 -> 20000 | G13: 3000 | H13: 500 | I13: 1000 | J13: 2500 | L13: 13000 | N13: =IF(M13<=500000,(M13*1*3/100),(M13*12/100)) -> 0
A14: AS201609 | B14: =VLOOKUP(A14,LISTADHERENT!A$5:H$51,2) -> DONHOU DAVID | C14: =$N$56/$D$56*D14 -> 559.8992 | D14: =TONT20000JANV!C14+TONT20000JANV!D14+TONT20000FEV!G14 -> 450847.16 | F14: =G14+H14+I14+J14+K14+L14 -> 20000 | G14: 3000 | H14: 500 | I14: 1000 | J14: 2500 | L14: 13000 | N14: =IF(M14<=500000,(M14*1*3/100),(M14*12/100)) -> 0
A15: AS201610 | B15: =VLOOKUP(A15,LISTADHERENT!A$5:H$51,2) -> FOTSO THOMAS | C15: =$N$56/$D$56*D15 -> 507.63328 | D15: =TONT20000JANV!C15+TONT20000JANV!D15+TONT20000FEV!G15 -> 408761.12 | F15: =G15+H15+I15+J15+K15+L15 -> 20000 | G15: 3000 | H15: 500 | I15: 1000 | J15: 2500 | L15: 13000 | N15: =IF(M15<=500000,(M15*1*3/100),(M15*12/100)) -> 0
A16: AS201611 | B16: =VLOOKUP(A16,LISTADHERENT!A$5:H$51,2) -> HENGUE PAUL OMER | C16: =$N$56/$D$56*D16 -> 503.44605 | D16: =TONT20000JANV!C16+TONT20000JANV!D16+TONT20000FEV!G16 -> 405389.44 | F16: =G16+H16+I16+J16+K16+L16 -> 20000 | G16: 3000 | H16: 500 | I16: 1000 | J16: 2500 | L16: 13000 | N16: =IF(M16<=500000,(M16*1*3/100),(M16*12/100)) -> 0
A17: AS201612 | B17: =VLOOKUP(A17,LISTADHERENT!A$5:H$51,2) -> HODIEP JULES | C17: =$N$56/$D$56*D17 -> 11.276201 | D17: =TONT20000JANV!C17+TONT20000JANV!D17+TONT20000FEV!G17 -> 9079.926 | F17: =G17+H17+I17+J17+K17+L17 -> 20000 | G17: 3000 | H17: 500 | I17: 1000 | J17: 2500 | L17: 13000 | N17: =IF(M17<=500000,(M17*1*3/100),(M17*12/100)) -> 0
A18: AS201613 | B18: =VLOOKUP(A18,LISTADHERENT!A$5:H$51,2) -> HOTCHO BENJAMIN | C18: =$N$56/$D$56*D18 -> 514.45425 | D18: =TONT20000JANV!C18+TONT20000JANV!D18+TONT20000FEV!G18 -> 414253.56 | F18: =G18+H18+I18+J18+K18+L18 -> 20000 | G18: 3000 | H18: 500 | I18: 1000 | J18: 2500 | L18: 13000 | N18: =IF(M18<=500000,(M18*1*3/100),(M18*12/100)) -> 0
A19: AS201614 | B19: =VLOOKUP(A19,LISTADHERENT!A$5:H$51,2) -> KEPHE DAVID | C19: =$N$56/$D$56*D19 -> 27.423158 | D19: =TONT20000JANV!C19+TONT20000JANV!D19+TONT20000FEV!G19 -> 22081.927 | F19: =G19+H19+I19+J19+K19+L19 -> 20000 | G19: 3000 | H19: 500 | I19: 1000 | J19: 2500 | L19: 13000 | N19: =IF(M19<=500000,(M19*1*3/100),(M19*12/100)) -> 0
A20: AS201615 | B20: =VLOOKUP(A20,LISTADHERENT!A$5:H$51,2) -> KEPSEU FRANCIS | C20: =$N$56/$D$56*D20 -> 750.7076 | D20: =TONT20000JANV!C20+TONT20000JANV!D20+TONT20000FEV!G20 -> 604491.65 | F20: =G20+H20+I20+J20+K20+L20 -> 23000 | G20: 6000 | H20: 500 | I20: 1000 | J20: 2500 | L20: 13000 | N20: =IF(M20<=500000,(M20*1*3/100),(M20*12/100)) -> 0
A21: AS201616 | B21: =VLOOKUP(A21,LISTADHERENT!A$5:H$51,2) -> KOUAMOU EMMANUEL | C21: =$N$56/$D$56*D21 -> 506.88241 | D21: =TONT20000JANV!C21+TONT20000JANV!D21+TONT20000FEV!G21 -> 408156.49 | F21: =G21+H21+I21+J21+K21+L21 -> 20000 | G21: 3000 | H21: 500 | I21: 1000 | J21: 2500 | L21: 13000 | N21: =IF(M21<=500000,(M21*1*3/100),(M21*12/100)) -> 0
A22: AS201617 | B22: =VLOOKUP(A22,LISTADHERENT!A$5:H$51,2) -> KOUAMOU MOISE | C22: =$N$56/$D$56*D22 -> 411.44689 | D22: =TONT20000JANV!C22+TONT20000JANV!D22+TONT20000FEV!G22 -> 331309.03 | F22: =G22+H22+I22+J22+K22+L22 -> 20000 | G22: 3000 | H22: 500 | I22: 1000 | J22: 2500 | L22: 13000 | N22: =IF(M22<=500000,(M22*1*3/100),(M22*12/100)) -> 0
A23: AS201618 | B23: =VLOOKUP(A23,LISTADHERENT!A$5:H$51,2) -> KOUAMOU VICTOR PEGUY | C23: =$N$56/$D$56*D23 -> 549.6709 | D23: =TONT20000JANV!C23+TONT20000JANV!D23+TONT20000FEV!G23 -> 442611.03 | F23: =G23+H23+I23+J23+K23+L23 -> 20000 | G23: 3000 | H23: 500 | I23: 1000 | J23: 2500 | L23: 13000 | N23: =IF(M23<=500000,(M23*1*3/100),(M23*12/100)) -> 0
... A27: AS201622 | B27: =VLOOKUP(A27,LISTADHERENT!A$5:H$51,2) -> NDJOMO ETIENNE | C27: =$N$56/$D$56*D27 -> 524.83939 | D27: =TONT20000JANV!C27+TONT20000JANV!D27+TONT20000FEV!G27 -> 422615.98 | F27: =G27+H27+I27+J27+K27+L27 -> 25000 | G27: 8000 | H27: 500 | I27: 1000 | J27: 2500 | L27: 13000 | N27: =IF(M27<=500000,(M27*1*3/100),(M27*12/100)) -> 0
A28: AS201623 | B28: =VLOOKUP(A28,LISTADHERENT!A$5:H$51,2) -> NDOMBOU JEAN CLAUDE | C28: =$N$56/$D$56*D28 -> 0 | D28: =TONT20000JANV!C28+TONT20000JANV!D28+TONT20000FEV!G28 -> 0 | F28: =G28+H28+I28+J28+K28+L28 -> 0 | N28: =IF(M28<=500000,(M28*1*3/100),(M28*12/100)) -> 0
A29: AS201624 | B29: =VLOOKUP(A29,LISTADHERENT!A$5:H$51,2) -> NGONDIEP CLAUDE | C29: =$N$56/$D$56*D29 -> 730.06377 | D29: =TONT20000JANV!C29+TONT20000JANV!D29+TONT20000FEV!G29 -> 587868.63 | F29: =G29+H29+I29+J29+K29+L29 -> 20000 | G29: 3000 | H29: 500 | I29: 1000 | J29: 2500 | L29: 13000 | N29: =IF(M29<=500000,(M29*1*3/100),(M29*12/100)) -> 0
A30: AS201625 | B30: =VLOOKUP(A30,LISTADHERENT!A$5:H$51,2) -> NGONGANG JEAN THEODORE | C30: =$N$56/$D$56*D30 -> 11.276201 | D30: =TONT20000JANV!C30+TONT20000JANV!D30+TONT20000FEV!G30 -> 9079.926 | F30: =G30+H30+I30+J30+K30+L30 -> 20000 | G30: 3000 | H30: 500 | I30: 1000 | J30: 2500 | L30: 13000 | N30: =IF(M30<=500000,(M30*1*3/100),(M30*12/100)) -> 0
A31: AS201626 | B31: =VLOOKUP(A31,LISTADHERENT!A$5:H$51,2) -> NGUIEMEGNI MATHIEU BLAISE | C31: =$N$56/$D$56*D31 -> 30.065732 | D31: =TONT20000JANV!C31+TONT20000JANV!D31+TONT20000FEV!G31 -> 24209.804 | F31: =G31+H31+I31+J31+K31+L31 -> 20000 | G31: 3000 | H31: 500 | I31: 1000 | J31: 2500 | L31: 13000 | N31: =IF(M31<=500000,(M31*1*3/100),(M31*12/100)) -> 0
A32: AS201627 | B32: =VLOOKUP(A32,LISTADHERENT!A$5:H$51,2) -> NJEPDJIO MBOUKAM DELUXE | C32: =$N$56/$D$56*D32 -> 514.36768 | D32: =TONT20000JANV!C32+TONT20000JANV!D32+TONT20000FEV!G32 -> 414183.85 | F32: =G32+H32+I32+J32+K32+L32 -> 25000 | G32: 8000 | H32: 500 | I32: 1000 | J32: 2500 | L32: 13000 | N32: =IF(M32<=500000,(M32*1*3/100),(M32*12/100)) -> 0
A33: AS201628 | B33: =VLOOKUP(A33,LISTADHERENT!A$5:H$51,2) -> NKAMGANG JUSTIN DEJOLIE | C33: =$N$56/$D$56*D33 -> 22.552402 | D33: =TONT20000JANV!C33+TONT20000JANV!D33+TONT20000FEV!G33 -> 18159.852 | F33: =G33+H33+I33+J33+K33+L33 -> 23000 | G33: 6000 | H33: 500 | I33: 1000 | J33: 2500 | L33: 13000 | N33: =IF(M33<=500000,(M33*1*3/100),(M33*12/100)) -> 0
A34: AS201629 | B34: =VLOOKUP(A34,LISTADHERENT!A$5:H$51,2) -> NKEPSEU DIEUDONNE | C34: =$N$56/$D$56*D34 -> 533.26811 | D34: =TONT20000JANV!C34+TONT20000JANV!D34+TONT20000FEV!G34 -> 429403.03 | F34: =G34+H34+I34+J34+K34+L34 -> 25000 | G34: 8000 | H34: 500 | I34: 1000 | J34: 2500 | L34: 13000 | N34: =IF(M34<=500000,(M34*1*3/100),(M34*12/100)) -> 0
A35: AS201630 | B35: =VLOOKUP(A35,LISTADHERENT!A$5:H$51,2) -> NKEPSEU HENANG RENE | C35: =$N$56/$D$56*D35 -> 513.52039 | D35: =TONT20000JANV!C35+TONT20000JANV!D35+TONT20000FEV!G35 -> 413501.59 | F35: =G35+H35+I35+J35+K35+L35 -> 20000 | G35: 3000 | H35: 500 | I35: 1000 | J35: 2500 | L35: 13000 | N35: =IF(M35<=500000,(M35*1*3/100),(M35*12/100)) -> 0
A36: AS201631 | B36: =VLOOKUP(A36,LISTADHERENT!A$5:H$51,2) -> NTEPDIE TUEMAC MZ | C36: =$N$56/$D$56*D36 -> 7.5505537 | D36: =TONT20000JANV!C36+TONT20000JANV!D36+TONT20000FEV!G36 -> 6079.926 | F36: =G36+H36+I36+J36+K36+L36 -> 0 | N36: =IF(M36<=500000,(M36*1*3/100),(M36*12/100)) -> 0
A37: AS201632 | B37: =VLOOKUP(A37,LISTADHERENT!A$5:H$51,2) -> NTOMBOU ADOLPHE | C37: =$N$56/$D$56*D37 -> 11.276201 | D37: =TONT20000JANV!C37+TONT20000JANV!D37+TONT20000FEV!G37 -> 9079.926 | F37: =G37+H37+I37+J37+K37+L37 -> 20000 | G37: 3000 | H37: 500 | I37: 1000 | J37: 2500 | L37: 13000 | N37: =IF(M37<=500000,(M37*1*3/100),(M37*12/100)) -> 0
A38: AS201633 | B38: =VLOOKUP(A38,LISTADHERENT!A$5:H$51,2) -> PATEGO NJOSSU GUSTAVE | C38: =$N$56/$D$56*D38 -> 503.62273 | D38: =TONT20000JANV!C38+TONT20000JANV!D38+TONT20000FEV!G38 -> 405531.7 | F38: =G38+H38+I38+J38+K38+L38 -> 20000 | G38: 3000 | H38: 500 | I38: 1000 | J38: 2500 | L38: 13000 | N38: =IF(M38<=500000,(M38*1*3/100),(M38*12/100)) -> 0
A39: AS201634 | B39: =VLOOKUP(A39,LISTADHERENT!A$5:H$51,2) -> SEUNOU RICHELOT | C39: =$N$56/$D$56*D39 -> 506.76757 | D39: =TONT20000JANV!C39+TONT20000JANV!D39+TONT20000FEV!G39 -> 408064.02 | F39: =G39+H39+I39+J39+K39+L39 -> 20000 | G39: 3000 | H39: 500 | I39: 1000 | J39: 2500 | L39: 13000 | N39: =IF(M39<=500000,(M39*1*3/100),(M39*12/100)) -> 0
A40: AS201635 | B40: =VLOOKUP(A40,LISTADHERENT!A$5:H$51,2) -> SIME ABEL | C40: =$N$56/$D$56*D40 -> 11.276201 | D40: =TONT20000JANV!C40+TONT20000JANV!D40+TONT20000FEV!G40 -> 9079.926 | F40: =G40+H40+I40+J40+K40+L40 -> 20000 | G40: 3000 | H40: 500 | I40: 1000 | J40: 2500 | L40: 13000 | N40: =IF(M40<=500000,(M40*1*3/100),(M40*12/100)) -> 0
A41: AS201636 | B41: =VLOOKUP(A41,LISTADHERENT!A$5:H$51,2) -> SIME FONGANG ERIC | C41: =$N$56/$D$56*D41 -> 504.68531 | D41: =TONT20000JANV!C41+TONT20000JANV!D41+TONT20000FEV!G41 -> 406387.33 | F41: =G41+H41+I41+J41+K41+L41 -> 20000 | G41: 3000 | H41: 500 | I41: 1000 | J41: 2500 | L41: 13000 | N41: =IF(M41<=500000,(M41*1*3/100),(M41*12/100)) -> 0
A42: AS201637 | B42: =VLOOKUP(A42,LISTADHERENT!A$5:H$51,2) -> SIME MATHIEU | C42: =$N$56/$D$56*D42 -> 504.24867 | D42: =TONT20000JANV!C42+TONT20000JANV!D42+TONT20000FEV!G42 -> 406035.73 | F42: =G42+H42+I42+J42+K42+L42 -> 20000 | G42: 3000 | H42: 500 | I42: 1000 | J42: 2500 | L42: 13000 | N42: =IF(M42<=500000,(M42*1*3/100),(M42*12/100)) -> 0
A43: AS201638 | B43: =VLOOKUP(A43,LISTADHERENT!A$5:H$51,2) -> SIME PIERRE | C43: =$N$56/$D$56*D43 -> 1798.331 | D43: =TONT20000JANV!C43+TONT20000JANV!D43+TONT20000FEV!G43 -> 1448068.6 | F43: =G43+H43+I43+J43+K43+L43 -> 20000 | G43: 3000 | H43: 500 | I43: 1000 | J43: 2500 | L43: 13000 | N43: =IF(M43<=500000,(M43*1*3/100),(M43*12/100)) -> 0
...

Sheet Sheet9
A1: ASSOCIATION | B1: ASELBY
A2: ANNEE | B2: 2016/2017
A3: TONTINE | B3: 20 000
A4: MATRICULE | B4: NOM ET PRENOM | C4: REPARTITION INTERET | D4: CAPITAL COMPOSE | E4: SANCTION | F4: MONTANT VERSE | G4: EPARGNE | H4: FONDS DE ROULEMENT | I4: FRAIS EXCEPTIONNEL | J4: COLLATION | K4: MUTUELLE | L4: TONTINE | M4: EMPRUNT | N4: INTERET EMPRUNT | O4: REMBOURSEMENT | P4: PENALITE EMPRUNT | Q4: PENALITE FONDS
A5: AS201648 | B5: =VLOOKUP(A5,LISTADHERENT!A$5:H$52,2,0) -> ASELBY | C5: =$N$56/$D$56*D5 -> 1043.2007 | D5: =TONT20000FEV!C5+TONT20000FEV!D5+TONT20000MARS!G5 -> 323693.52
A6: AS201601 | B6: =VLOOKUP(A6,LISTADHERENT!A$5:H$52,2,0) -> BAKOP ACHILLE | C6: =$N$56/$D$56*D6 -> 1427.7464 | D6: =TONT20000FEV!C6+TONT20000FEV!D6+TONT20000MARS!G6 -> 443013.76 | F6: =G6+H6+I6+J6+K6+L6 -> 20000 | G6: 3000 | H6: 500 | I6: 1000 | J6: 2500 | L6: 13000 | N6: =IF(M6<=500000,(M6*1*3/100),(M6*12/100)) -> 0
A7: AS201602 | B7: =VLOOKUP(A7,LISTADHERENT!A$5:H$51,2) -> BOUTCHOUANG WILLIAM | C7: =$N$56/$D$56*D7 -> 1323.369 | D7: =TONT20000FEV!C7+TONT20000FEV!D7+TONT20000MARS!G7 -> 410626.6 | F7: =G7+H7+I7+J7+K7+L7 -> 20000 | G7: 3000 | H7: 500 | I7: 1000 | J7: 2500 | L7: 13000 | N7: =IF(M7<=500000,(M7*1*3/100),(M7*12/100)) -> 0
A8: AS201603 | B8: =VLOOKUP(A8,LISTADHERENT!A$5:H$51,2) -> CHINGUE FABRICE | C8: =$N$56/$D$56*D8 -> 1323.8215 | D8: =TONT20000FEV!C8+TONT20000FEV!D8+TONT20000MARS!G8 -> 410767.01 | F8: =G8+H8+I8+J8+K8+L8 -> 20000 | G8: 3000 | H8: 500 | I8: 1000 | J8: 2500 | L8: 13000 | N8: =IF(M8<=500000,(M8*1*3/100),(M8*12/100)) -> 0
A9: AS201604 | B9: =VLOOKUP(A9,LISTADHERENT!A$5:H$51,2) -> DJOMO JEAN PAUL | C9: =$N$56/$D$56*D9 -> 1344.5252 | D9: =TONT20000FEV!C9+TONT20000FEV!D9+TONT20000MARS!G9 -> 417191.13 | F9: =G9+H9+I9+J9+K9+L9 -> 20000 | G9: 3000 | H9: 500 | I9: 1000 | J9: 2500 | L9: 13000 | N9: =IF(M9<=500000,(M9*1*3/100),(M9*12/100)) -> 0
A10: AS201605 | B10: =VLOOKUP(A10,LISTADHERENT!A$5:H$51,2) -> DJOUKWE GUY | C10: =$N$56/$D$56*D10 -> 1353.5392 | D10: =TONT20000FEV!C10+TONT20000FEV!D10+TONT20000MARS!G10 -> 419988.07 | F10: =G10+H10+I10+J10+K10+L10 -> 20000 | G10: 3000 | H10: 500 | I10: 1000 | J10: 2500 | L10: 13000 | N10: =IF(M10<=500000,(M10*1*3/100),(M10*12/100)) -> 0
A11: AS201606 | B11: =VLOOKUP(A11,LISTADHERENT!A$5:H$51,2) -> DJOSSEU JOSUE | C11: =$N$56/$D$56*D11 -> 16.395051 | D11: =TONT20000FEV!C11+TONT20000FEV!D11+TONT20000MARS!G11 -> 5087.2011 | F11: =G11+H11+I11+J11+K11+L11 -> 0 | N11: =IF(M11<=500000,(M11*1*3/100),(M11*12/100)) -> 0
A12: AS201607 | B12: =VLOOKUP(A12,LISTADHERENT!A$5:H$51,2) -> DJOUNKEP SAMUEL | C12: =$N$56/$D$56*D12 -> 4614.7494 | D12: =TONT20000FEV!C12+TONT20000FEV!D12+TONT20000MARS!G12 -> 1431905.1 | F12: =G12+H12+I12+J12+K12+L12 -> 20000 | G12: 3000 | H12: 500 | I12: 1000 | J12: 2500 | L12: 13000 | N12: =IF(M12<=500000,(M12*1*3/100),(M12*12/100)) -> 0
A13: AS201608 | B13: =VLOOKUP(A13,LISTADHERENT!A$5:H$51,2) -> DJUOMBESSY ANTOINE | C13: =$N$56/$D$56*D13 -> 1085.4112 | D13: =TONT20000FEV!C13+TONT20000FEV!D13+TONT20000MARS!G13 -> 336790.97 | F13: =G13+H13+I13+J13+K13+L13 -> 20000 | G13: 3000 | H13: 500 | I13: 1000 | J13: 2500 | L13: 13000 | N13: =IF(M13<=500000,(M13*1*3/100),(M13*12/100)) -> 0
A14: AS201609 | B14: =VLOOKUP(A14,LISTADHERENT!A$5:H$51,2) -> DONHOU DAVID | C14: =$N$56/$D$56*D14 -> 1464.4648 | D14: =TONT20000FEV!C14+TONT20000FEV!D14+TONT20000MARS!G14 -> 454407.06 | F14: =G14+H14+I14+J14+K14+L14 -> 20000 | G14: 3000 | H14: 500 | I14: 1000 | J14: 2500 | L14: 13000 | N14: =IF(M14<=500000,(M14*1*3/100),(M14*12/100)) -> 0
A15: AS201610 | B15: =VLOOKUP(A15,LISTADHERENT!A$5:H$51,2) -> FOTSO THOMAS | C15: =$N$56/$D$56*D15 -> 1328.6613 | D15: =TONT20000FEV!C15+TONT20000FEV!D15+TONT20000MARS!G15 -> 412268.75 | F15: =G15+H15+I15+J15+K15+L15 -> 20000 | G15: 3000 | H15: 500 | I15: 1000 | J15: 2500 | L15: 13000 | N15: =IF(M15<=500000,(M15*1*3/100),(M15*12/100)) -> 0
A16: AS201611 | B16: =VLOOKUP(A16,LISTADHERENT!A$5:H$51,2) -> HENGUE PAUL OMER | C16: =$N$56/$D$56*D16 -> 1317.7816 | D16: =TONT20000FEV!C16+TONT20000FEV!D16+TONT20000MARS!G16 -> 408892.89 | F16: =G16+H16+I16+J16+K16+L16 -> 20000 | G16: 3000 | H16: 500 | I16: 1000 | J16: 2500 | L16: 13000 | N16: =IF(M16<=500000,(M16*1*3/100),(M16*12/100)) -> 0
A17: AS201612 | B17: =VLOOKUP(A17,LISTADHERENT!A$5:H$51,2) -> HODIEP JULES | C17: =$N$56/$D$56*D17 -> 38.967573 | D17: =TONT20000FEV!C17+TONT20000FEV!D17+TONT20000MARS!G17 -> 12091.202 | F17: =G17+H17+I17+J17+K17+L17 -> 20000 | G17: 3000 | H17: 500 | I17: 1000 | J17: 2500 | L17: 13000 | N17: =IF(M17<=500000,(M17*1*3/100),(M17*12/100)) -> 0
A18: AS201613 | B18: =VLOOKUP(A18,LISTADHERENT!A$5:H$51,2) -> HOTCHO BENJAMIN | C18: =$N$56/$D$56*D18 -> 1346.3844 | D18: =TONT20000FEV!C18+TONT20000FEV!D18+TONT20000MARS!G18 -> 417768.02 | F18: =G18+H18+I18+J18+K18+L18 -> 20000 | G18: 3000 | H18: 500 | I18: 1000 | J18: 2500 | L18: 13000 | N18: =IF(M18<=500000,(M18*1*3/100),(M18*12/100)) -> 0
A19: AS201614 | B19: =VLOOKUP(A19,LISTADHERENT!A$5:H$51,2) -> KEPHE DAVID | C19: =$N$56/$D$56*D19 -> 80.922508 | D19: =TONT20000FEV!C19+TONT20000FEV!D19+TONT20000MARS!G19 -> 25109.35 | F19: =G19+H19+I19+J19+K19+L19 -> 20000 | G19: 3000 | H19: 500 | I19: 1000 | J19: 2500 | L19: 13000 | N19: =IF(M19<=500000,(M19*1*3/100),(M19*12/100)) -> 0
A20: AS201615 | B20: =VLOOKUP(A20,LISTADHERENT!A$5:H$51,2) -> KEPSEU FRANCIS | C20: =$N$56/$D$56*D20 -> 2421.1067 | D20: =TONT20000FEV!C20+TONT20000FEV!D20+TONT20000MARS!G20 -> 751242.36 | F20: =G20+H20+I20+J20+K20+L20 -> 163000 | G20: 146000 | H20: 500 | I20: 1000 | J20: 2500 | L20: 13000 | N20: =IF(M20<=500000,(M20*1*3/100),(M20*12/100)) -> 0
A21: AS201616 | B21: =VLOOKUP(A21,LISTADHERENT!A$5:H$51,2) -> KOUAMOU EMMANUEL | C21: =$N$56/$D$56*D21 -> 1326.7103 | D21: =TONT20000FEV!C21+TONT20000FEV!D21+TONT20000MARS!G21 -> 411663.38 | F21: =G21+H21+I21+J21+K21+L21 -> 20000 | G21: 3000 | H21: 500 | I21: 1000 | J21: 2500 | L21: 13000 | N21: =IF(M21<=500000,(M21*1*3/100),(M21*12/100)) -> 0
A22: AS201617 | B22: =VLOOKUP(A22,LISTADHERENT!A$5:H$51,2) -> KOUAMOU MOISE | C22: =$N$56/$D$56*D22 -> 1078.7384 | D22: =TONT20000FEV!C22+TONT20000FEV!D22+TONT20000MARS!G22 -> 334720.48 | F22: =G22+H22+I22+J22+K22+L22 -> 20000 | G22: 3000 | H22: 500 | I22: 1000 | J22: 2500 | L22: 13000 | N22: =IF(M22<=500000,(M22*1*3/100),(M22*12/100)) -> 0
A23: AS201618 | B23: =VLOOKUP(A23,LISTADHERENT!A$5:H$51,2) -> KOUAMOU VICTOR PEGUY | C23: =$N$56/$D$56*D23 -> 1437.8884 | D23: =TONT20000FEV!C23+TONT20000FEV!D23+TONT20000MARS!G23 -> 446160.7 | F23: =G23+H23+I23+J23+K23+L23 -> 20000 | G23: 3000 | H23: 500 | I23: 1000 | J23: 2500 | L23: 13000 | N23: =IF(M23<=500000,(M23*1*3/100),(M23*12/100)) -> 0
A24: AS201619 | B24: =VLOOKUP(A24,LISTADHERENT!A$5:H$51,2) -> KOUATCHO MESSACK | C24: =$N$56/$D$56*D24 -> 1317.7816 | D24: =TONT20000FEV!C24+TONT20000FEV!D24+TONT20000MARS!G24 -> 408892.89 | F24: =G24+H24+I24+J24+K24+L24 -> 20000 | G24: 3000 | H24: 500 | I24: 1000 | J24: 2500 | L24: 13000 | N24: =IF(M24<=500000,(M24*1*3/100),(M24*12/100)) -> 0
A25: AS201620 | B25: =VLOOKUP(A25,LISTADHERENT!A$5:H$51,2) -> LOWE JEAN | C25: =$N$56/$D$56*D25 -> 1331.9829 | D25: =TONT20000FEV!C25+TONT20000FEV!D25+TONT20000MARS!G25 -> 413299.42 | F25: =G25+H25+I25+J25+K25+L25 -> 20000 | G25: 3000 | H25: 500 | I25: 1000 | J25: 2500 | L25: 13000 | M25: 80000 | N25: =IF(M25<=500000,(M25*1*3/100),(M25*12/100)) -> 2400
A26: AS201621 | B26: =VLOOKUP(A26,LISTADHERENT!A$5:H$51,2) -> NANKAM APPOLINAIRE | C26: =$N$56/$D$56*D26 -> 1332.2453 | D26: =TONT20000FEV!C26+TONT20000FEV!D26+TONT20000MARS!G26 -> 413380.81 | F26: =G26+H26+I26+J26+K26+L26 -> 20000 | G26: 3000 | H26: 500 | I26: 1000 | J26: 2500 | L26: 13000 | N26: =IF(M26<=500000,(M26*1*3/100),(M26*12/100)) -> 0
A27: AS201622 | B27: =VLOOKUP(A27,LISTADHERENT!A$5:H$51,2) -> NDJOMO ETIENNE | C27: =$N$56/$D$56*D27 -> 1389.4823 | D27: =TONT20000FEV!C27+TONT20000FEV!D27+TONT20000MARS!G27 -> 431140.82 | F27: =G27+H27+I27+J27+K27+L27 -> 25000 | G27: 8000 | H27: 500 | I27: 1000 | J27: 2500 | L27: 13000 | M27: 400000 | N27: =IF(M27<=500000,(M27*1*3/100),(M27*12/100)) -> 12000 | O27: 400000
A28: AS201623 | B28: =VLOOKUP(A28,LISTADHERENT!A$5:H$51,2) -> NDOMBOU JEAN CLAUDE | C28: =$N$56/$D$56*D28 -> 0 | D28: =TONT20000FEV!C28+TONT20000FEV!D28+TONT20000MARS!G28 -> 0 | F28: =G28+H28+I28+J28+K28+L28 -> 0 | N28: =IF(M28<=500000,(M28*1*3/100),(M28*12/100)) -> 0
A29: AS201624 | B29: =VLOOKUP(A29,LISTADHERENT!A$5:H$51,2) -> NGONDIEP CLAUDE | C29: =$N$56/$D$56*D29 -> 1906.6065 | D29: =TONT20000FEV!C29+TONT20000FEV!D29+TONT20000MARS!G29 -> 591598.69 | F29: =G29+H29+I29+J29+K29+L29 -> 20000 | G29: 3000 | H29: 500 | I29: 1000 | J29: 2500 | L29: 13000 | N29: =IF(M29<=500000,(M29*1*3/100),(M29*12/100)) -> 0
A30: AS201625 | B30: =VLOOKUP(A30,LISTADHERENT!A$5:H$51,2) -> NGONGANG JEAN THEODORE | C30: =$N$56/$D$56*D30 -> 38.967573 | D30: =TONT20000FEV!C30+TONT20000FEV!D30+TONT20000MARS!G30 -> 12091.202 | F30: =G30+H30+I30+J30+K30+L30 -> 20000 | G30: 3000 | H30: 500 | I30: 1000 | J30: 2500 | L30: 13000 | N30: =IF(M30<=500000,(M30*1*3/100),(M30*12/100)) -> 0
A31: AS201626 | B31: =VLOOKUP(A31,LISTADHERENT!A$5:H$51,2) -> NGUIEMEGNI MATHIEU BLAISE | C31: =$N$56/$D$56*D31 -> 87.788756 | D31: =TONT20000FEV!C31+TONT20000FEV!D31+TONT20000MARS!G31 -> 27239.87 | F31: =G31+H31+I31+J31+K31+L31 -> 20000 | G31: 3000 | H31: 500 | I31: 1000 | J31: 2500 | L31: 13000 | N31: =IF(M31<=500000,(M31*1*3/100),(M31*12/100)) -> 0
A32: AS201627 | B32: =VLOOKUP(A32,LISTADHERENT!A$5:H$51,2) -> NJEPDJIO MBOUKAM DELUXE | C32: =$N$56/$D$56*D32 -> 1355.8278 | D32: =TONT20000FEV!C32+TONT20000FEV!D32+TONT20000MARS!G32 -> 420698.22 | F32: =G32+H32+I32+J32+K32+L32 -> 23000 | G32: 6000 | H32: 500 | I32: 1000 | J32: 2500 | L32: 13000 | M32: 1000000 | N32: =IF(M32<=500000,(M32*1*3/100),(M32*12/100))/4 -> 30000
A33: AS201628 | B33: =VLOOKUP(A33,LISTADHERENT!A$5:H$51,2) -> NKAMGANG JUSTIN DEJOLIE | C33: =$N$56/$D$56*D33 -> 77.935145 | D33: =TONT20000FEV!C33+TONT20000FEV!D33+TONT20000MARS!G33 -> 24182.404 | F33: =G33+H33+I33+J33+K33+L33 -> 23000 | G33: 6000 | H33: 500 | I33: 1000 | J33: 2500 | L33: 13000 | N33: =IF(M33<=500000,(M33*1*3/100),(M33*12/100)) -> 0
A34: AS201629 | B34: =VLOOKUP(A34,LISTADHERENT!A$5:H$51,2) -> NKEPSEU DIEUDONNE | C34: =$N$56/$D$56*D34 -> 1411.3828 | D34: =TONT20000FEV!C34+TONT20000FEV!D34+TONT20000MARS!G34 -> 437936.3 | F34: =G34+H34+I34+J34+K34+L34 -> 25000 | G34: 8000 | H34: 500 | I34: 1000 | J34: 2500 | L34: 13000 | N34: =IF(M34<=500000,(M34*1*3/100),(M34*12/100)) -> 0
A35: AS201630 | B35: =VLOOKUP(A35,LISTADHERENT!A$5:H$51,2) -> NKEPSEU HENANG RENE | C35: =$N$56/$D$56*D35 -> 1343.9579 | D35: =TONT20000FEV!C35+TONT20000FEV!D35+TONT20000MARS!G35 -> 417015.11 | F35: =G35+H35+I35+J35+K35+L35 -> 20000 | G35: 3000 | H35: 500 | I35: 1000 | J35: 2500 | L35: 13000 | N35: =IF(M35<=500000,(M35*1*3/100),(M35*12/100)) -> 0
A36: AS201631 | B36: =VLOOKUP(A36,LISTADHERENT!A$5:H$51,2) -> NTEPDIE TUEMAC MZ | C36: =$N$56/$D$56*D36 -> 19.618743 | D36: =TONT20000FEV!C36+TONT20000FEV!D36+TONT20000MARS!G36 -> 6087.4765 | F36: =G36+H36+I36+J36+K36+L36 -> 0 | N36: =IF(M36<=500000,(M36*1*3/100),(M36*12/100)) -> 0
A37: AS201632 | B37: =VLOOKUP(A37,LISTADHERENT!A$5:H$51,2) -> NTOMBOU ADOLPHE | C37: =$N$56/$D$56*D37 -> 38.967573 | D37: =TONT20000FEV!C37+TONT20000FEV!D37+TONT20000MARS!G37 -> 12091.202 | F37: =G37+H37+I37+J37+K37+L37 -> 20000 | G37: 3000 | H37: 500 | I37: 1000 | J37: 2500 | L37: 13000 | N37: =IF(M37<=500000,(M37*1*3/100),(M37*12/100)) -> 0
A38: AS201633 | B38: =VLOOKUP(A38,LISTADHERENT!A$5:H$51,2) -> PATEGO NJOSSU GUSTAVE | C38: =$N$56/$D$56*D38 -> 1318.2406 | D38: =TONT20000FEV!C38+TONT20000FEV!D38+TONT20000MARS!G38 -> 409035.33 | F38: =G38+H38+I38+J38+K38+L38 -> 20000 | G38: 3000 | H38: 500 | I38: 1000 | J38: 2500 | L38: 13000 | N38: =IF(M38<=500000,(M38*1*3/100),(M38*12/100)) -> 0
A39: AS201634 | B39: =VLOOKUP(A39,LISTADHERENT!A$5:H$51,2) -> SEUNOU RICHELOT | C39: =$N$56/$D$56*D39 -> 1326.4119 | D39: =TONT20000FEV!C39+TONT20000FEV!D39+TONT20000MARS!G39 -> 411570.79 | F39: =G39+H39+I39+J39+K39+L39 -> 20000 | G39: 3000 | H39: 500 | I39: 1000 | J39: 2500 | L39: 13000 | N39: =IF(M39<=500000,(M39*1*3/100),(M39*12/100)) -> 0
A40: AS201635 | B40: =VLOOKUP(A40,LISTADHERENT!A$5:H$51,2) -> SIME ABEL | C40: =$N$56/$D$56*D40 -> 38.967573 | D40: =TONT20000FEV!C40+TONT20000FEV!D40+TONT20000MARS!G40 -> 12091.202 | F40: =G40+H40+I40+J40+K40+L40 -> 20000 | G40: 3000 | H40: 500 | I40: 1000 | J40: 2500 | L40: 13000 | N40: =IF(M40<=500000,(M40*1*3/100),(M40*12/100)) -> 0
...

Sheet Sheet10
A1: ASSOCIATION | B1: ASELBY
A2: ANNEE | B2: 2016/2017
A3: TONTINE | B3: 20 000
A4: MATRICULE | B4: NOM ET PRENOM | C4: REPARTITION INTERET | D4: CAPITAL COMPOSE | E4: SANCTION | F4: MONTANT VERSE | G4: EPARGNE | H4: FONDS DE ROULEMENT | I4: FRAIS EXCEPTIONNEL | J4: COLLATION | K4: MUTUELLE | L4: TONTINE | M4: EMPRUNT | N4: INTERET EMPRUNT | O4: REMBOURSEMENT | P4: PENALITE EMPRUNT | Q4: PENALITE FONDS
A5: AS201648 | B5: =VLOOKUP(A5,LISTADHERENT!A$5:H$52,2,0) -> ASELBY | C5: =$N$56/$D$56*D5 -> 4206.7983 | D5: =TONT20000MARS!C5+TONT20000MARS!D5+TONT20000AVRIL!G5 -> 324736.72
A6: AS201601 | B6: =VLOOKUP(A6,LISTADHERENT!A$5:H$51,2) -> BAKOP ACHILLE | C6: =$N$56/$D$56*D6 -> 5796.3762 | D6: =TONT20000MARS!C6+TONT20000MARS!D6+TONT20000AVRIL!G6 -> 447441.51 | F6: =G6+H6+I6+J6+K6+L6 -> 20000 | G6: 3000 | H6: 500 | I6: 1000 | J6: 2500 | L6: 13000 | N6: =IF(M6<=500000,(M6*1*3/100),(M6*12/100)) -> 0
A7: AS201602 | B7: =VLOOKUP(A7,LISTADHERENT!A$5:H$51,2) -> BOUTCHOUANG WILLIAM | C7: =$N$56/$D$56*D7 -> 5375.465 | D7: =TONT20000MARS!C7+TONT20000MARS!D7+TONT20000AVRIL!G7 -> 414949.97 | F7: =G7+H7+I7+J7+K7+L7 -> 20000 | G7: 3000 | H7: 500 | I7: 1000 | J7: 2500 | L7: 13000 | N7: =IF(M7<=500000,(M7*1*3/100),(M7*12/100)) -> 0
A8: AS201603 | B8: =VLOOKUP(A8,LISTADHERENT!A$5:H$51,2) -> CHINGUE FABRICE | C8: =$N$56/$D$56*D8 -> 5377.2897 | D8: =TONT20000MARS!C8+TONT20000MARS!D8+TONT20000AVRIL!G8 -> 415090.83 | F8: =G8+H8+I8+J8+K8+L8 -> 20000 | G8: 3000 | H8: 500 | I8: 1000 | J8: 2500 | L8: 13000 | N8: =IF(M8<=500000,(M8*1*3/100),(M8*12/100)) -> 0
A9: AS201604 | B9: =VLOOKUP(A9,LISTADHERENT!A$5:H$51,2) -> DJOMO JEAN PAUL | C9: =$N$56/$D$56*D9 -> 5460.7791 | D9: =TONT20000MARS!C9+TONT20000MARS!D9+TONT20000AVRIL!G9 -> 421535.65 | F9: =G9+H9+I9+J9+K9+L9 -> 20000 | G9: 3000 | H9: 500 | I9: 1000 | J9: 2500 | L9: 13000 | N9: =IF(M9<=500000,(M9*1*3/100),(M9*12/100)) -> 0
A10: AS201605 | B10: =VLOOKUP(A10,LISTADHERENT!A$5:H$51,2) -> DJOUKWE GUY | C10: =$N$56/$D$56*D10 -> 5561.9013 | D10: =TONT20000MARS!C10+TONT20000MARS!D10+TONT20000AVRIL!G10 -> 429341.61 | F10: =G10+H10+I10+J10+K10+L10 -> 25000 | G10: 8000 | H10: 500 | I10: 1000 | J10: 2500 | L10: 13000 | N10: =IF(M10<=500000,(M10*1*3/100),(M10*12/100)) -> 0
A11: AS201606 | B11: =VLOOKUP(A11,LISTADHERENT!A$5:H$51,2) -> DJOSSEU JOSUE | C11: =$N$56/$D$56*D11 -> 66.114481 | D11: =TONT20000MARS!C11+TONT20000MARS!D11+TONT20000AVRIL!G11 -> 5103.5961 | F11: =G11+H11+I11+J11+K11+L11 -> 0 | N11: =IF(M11<=500000,(M11*1*3/100),(M11*12/100)) -> 0
A12: AS201607 | B12: =VLOOKUP(A12,LISTADHERENT!A$5:H$51,2) -> DJOUNKEP SAMUEL | C12: =$N$56/$D$56*D12 -> 18648.245 | D12: =TONT20000MARS!C12+TONT20000MARS!D12+TONT20000AVRIL!G12 -> 1439519.9 | F12: =G12+H12+I12+J12+K12+L12 -> 20000 | G12: 3000 | H12: 500 | I12: 1000 | J12: 2500 | L12: 13000 | N12: =IF(M12<=500000,(M12*1*3/100),(M12*12/100)) -> 0
A13: AS201608 | B13: =VLOOKUP(A13,LISTADHERENT!A$5:H$51,2) -> DJUOMBESSY ANTOINE | C13: =$N$56/$D$56*D13 -> 4415.8794 | D13: =TONT20000MARS!C13+TONT20000MARS!D13+TONT20000AVRIL!G13 -> 340876.38 | F13: =G13+H13+I13+J13+K13+L13 -> 20000 | G13: 3000 | H13: 500 | I13: 1000 | J13: 2500 | L13: 13000 | N13: =IF(M13<=500000,(M13*1*3/100),(M13*12/100)) -> 0
