Workbook
Name BANQUE: #REF!
Name BANQUE: #REF!
Name BANQUE: #REF!
Name BANQUE: #REF!
Name BANQUE: #REF!
Name BANQUE: #REF!
Name BANQUE: #REF!
Name BANQUE: #REF!
Name BANQUE: #REF!
Name BANQUE: #REF!
Name BANQUE: #REF!
Name BANQUE: #REF!
Name BANQUE: #REF!
Name BANQUE: #REF!
Name BANQUE: #REF!
Name BANQUE: #REF!
Name BANQUE: #REF!
Name BANQUE: #REF!
Name BANQUE: #REF!
Name BANQUE: #REF!
Name BANQUE: #REF!
Name BANQUE: #REF!
Name BANQUE: #REF!
Name BANQUE: #REF!
Name BANQUE: #REF!
Name BANQUE: #REF!
Name BANQUE: #REF!
Name BANQUE: #REF!
Name BANQUE: #REF!
Name BANQUE: #REF!
Name BANQUE: #REF!
Name BANQUE: #REF!
Name BANQUE: #REF!
Name BANQUE: #REF!
Name BANQUE: #REF!
Name BANQUE: #REF!
Name BANQUE: #REF!
Name ECHEC: #REF!
Name MODEET30000: [1]MODEVERSEMENT!$A$1:$A$3
Name MODEET30000: [2]MODEVERSEMENT!$A$1:$A$3
Name MODEET30000: [2]MODEVERSEMENT!$A$1:$A$3
Name MODEET30000: [2]MODEVERSEMENT!$A$1:$A$3
Name MODEET30000: [2]MODEVERSEMENT!$A$1:$A$3
Name MODEET30000: [2]MODEVERSEMENT!$A$1:$A$3
Name MODEET30000: [2]MODEVERSEMENT!$A$1:$A$3
Name MODEET30000: [2]MODEVERSEMENT!$A$1:$A$3
Name MODEET30000: [2]MODEVERSEMENT!$A$1:$A$3
Name MODEET30000: [2]MODEVERSEMENT!$A$1:$A$3
Name MODEET30000: [2]MODEVERSEMENT!$A$1:$A$3
Name MODEET30000: [2]MODEVERSEMENT!$A$1:$A$3
Name MODEET30000: [2]MODEVERSEMENT!$A$1:$A$3
Name MODEET30000: [2]MODEVERSEMENT!$A$1:$A$3
Name MODEET30000: [2]MODEVERSEMENT!$A$1:$A$3
Name MODEET30000: [3]MODEVERSEMENT!$A$1:$A$3
Name MODEPAID: [4]Feuil2!$A$1:$A$3
Name MODEPAID: [5]Feuil2!$A$1:$A$3
Name MODEPAID: #REF!
Name MODEPAID: [6]Feuil2!$A$1:$A$3
Name MODEPAID: [5]Feuil2!$A$1:$A$3
Name MODEPAID30000: MVTAOUT22!#REF!

Sheet TAF
A1: AIDE
A2: PRÊT
A3: REMBOURSEMENT
A4: AGIOS BANCAIRE
A5: DETAIL CHEQUE
A6: RAPPORT FINANCIER

Sheet MODEVERSEMENT
A1: BANQUE
A2: ESPECES
A3: ECHEC

Sheet MODET25000
A1: BANQUE
A2: ESPECES
A3: ECHEC

Sheet MVTDEC21
A1: ASSOCIATION | B1: ASELBY | G1: K
A2: ANNEE | B2: 2022
A3: TONTINE
J4: 44578
A5: MATRICULE | B5: NOM ET PRENOM | C5: FONDES DE DEPART | D5: RELIQUAT | E5: RETRAIT PARTIEL | F5: FONDS DEFINITIF | G5: REPARTITION INTERET | H5: CAPITAL COMPOSE | I5: SANCTION | J5: RESTE | K5: EPARGNE | L5: FONDS DE ROULEMENT | M5: FRAIS EXCEPTIONNEL | N5: COLLATION | O5: PENALITE VST ESPECES | P5: INSCRISPTION | Q5: MUTUELLE | R5: PRÊT FONDS | S5: INTERETPRET FONDS | T5: NUMERO CHEQUE | U5: REMBOURSEMENTPRET FONDS | V5: MODE VERSEMENT REMBOURSEMENT | W5: MODE VERSEMENT PRÊT | X5: NUMERO CHEQUE | Y5: PENALITE PRET FONDS | Z5: PENALITE FONDS | AA5: PENALITE ECHEC TONTINE | AB5: PENALITE RETARD TONTINE | AC5: REMBOURSEMENT TRANSPORT | AD5: CONTRIBUTION FOYER | AE5: DEPENSE FONCTIONNEMENT
A6: AS201648 | B6: =VLOOKUP(A6,[15]LISTADHERENT!A$5:H$60,3,0) -> ASELBY | C6: 584177.01 | F6: =C6-E6 -> 584177.01 | G6: =$S$40/$H$40*H6 -> 44951.215 | H6: =F6+D6+K6 -> 584177.01 | AE6: =[16]HISTOMVTDEPENSE!$T$39 -> 0
A7: AS201602 | B7: =VLOOKUP(A7,[15]LISTADHERENT!A$5:H$60,3,0) -> BOUTCHOUANG WILLIAM | C7: 570000 | D7: -258.93851 | E7: =VLOOKUP($A7,[16]HISTOJANV22!$A$6:$BA$39,48,0) -> 0 | F7: =C7-E7 -> 570000 | G7: =$S$40/$H$40*H7 -> 44071.242 | H7: =F7+D7+K7 -> 572741.06 | I7: =VLOOKUP($A7,[16]HISTOJANV22!$A$6:$AQ$37,22,0) -> 0 | J7: =VLOOKUP($A7,[16]HISTOJANV22!$A$6:$AU$39,45,0) -> 7000 | K7: =IF(J7=0,0,J7-(L7+M7+N7)) -> 3000 | L7: =IF(J7=0,0,500) -> 500 | M7: =IF(J7=0,0,1000) -> 1000 | N7: =IF(J7=0,0,2500) -> 2500 | O7: =VLOOKUP($A7,[16]HISTOJANV22!$A$6:$AU$39,7,0) -> 0 | P7: =VLOOKUP($A7,[16]HISTOJANV22!$A$6:$AU$39,23,0) -> 0 | Q7: =VLOOKUP($A7,[16]HISTOJANV22!$A$6:$AU$39,46,0) -> 0 | R7: =VLOOKUP($A7,[16]HISTODEC21!$A$6:$AU$39,26,0) -> 525000 | S7: =R7*1/1200*12 -> 5250 | T7: =VLOOKUP($A7,[16]HISTOJANV22!$A$6:$AU$39,28,0) -> 0 | U7: =VLOOKUP($A7,[16]HISTOJANV22!$A$6:$AU$39,19,0) -> 0 | V7: =VLOOKUP($A7,[16]HISTOJANV22!$A$6:$AU$39,20,0) -> 0 | W7: =VLOOKUP($A7,[16]HISTOJANV22!$A$6:$AU$39,27,0) -> 0 | X7: =VLOOKUP($A7,[16]HISTOJANV22!$A$6:$AU$39,33,0) -> 0 | Y7: 4000 | AA7: =VLOOKUP($A7,[16]HISTOJANV22!$A$6:$AU$39,43,0) -> 0 | AB7: =VLOOKUP($A7,[16]HISTOJANV22!$A$6:$AU$39,44,0) -> 0 | AC7: =VLOOKUP($A7,[16]HISTOJANV22!$A$6:$AU$39,47,0) -> 0 | AD7: =VLOOKUP(A7,[16]HISTOJANV22!$A$6:$BB$36,54,0) -> 0
A8: AS201604 | B8: =VLOOKUP(A8,[15]LISTADHERENT!A$5:H$60,3,0) -> DJOMO JEAN PAUL | C8: 570000 | D8: 1714.0012 | E8: =VLOOKUP($A8,[16]HISTOJANV22!$A$6:$BA$39,48,0) -> 0 | F8: =C8-E8 -> 570000 | G8: =$S$40/$H$40*H8 -> 47685.713 | H8: =F8+D8+K8 -> 619714 | I8: =VLOOKUP($A8,[16]HISTOJANV22!$A$6:$AQ$37,22,0) -> 0 | J8: =VLOOKUP($A8,[16]HISTOJANV22!$A$6:$AU$39,45,0) -> 52000 | K8: =IF(J8=0,0,J8-(L8+M8+N8)) -> 48000 | L8: =IF(J8=0,0,500) -> 500 | M8: =IF(J8=0,0,1000) -> 1000 | N8: =IF(J8=0,0,2500) -> 2500 | O8: =VLOOKUP($A8,[16]HISTOJANV22!$A$6:$AU$39,7,0) -> 0 | P8: =VLOOKUP($A8,[16]HISTOJANV22!$A$6:$AU$39,23,0) -> 0 | Q8: =VLOOKUP($A8,[16]HISTOJANV22!$A$6:$AU$39,46,0) -> 0 | R8: =VLOOKUP($A8,[16]HISTODEC21!$A$6:$AU$39,26,0) -> 1000000 | S8: =R8*12/1200*12 -> 120000 | T8: =VLOOKUP($A8,[16]HISTOJANV22!$A$6:$AU$39,28,0) -> OKK | U8: =VLOOKUP($A8,[16]HISTOJANV22!$A$6:$AU$39,19,0) -> 0 | V8: =VLOOKUP($A8,[16]HISTOJANV22!$A$6:$AU$39,20,0) -> 0 | W8: =VLOOKUP($A8,[16]HISTOJANV22!$A$6:$AU$39,27,0) -> BANQUE | X8: =VLOOKUP($A8,[16]HISTOJANV22!$A$6:$AU$39,33,0) -> 0 | AA8: =VLOOKUP($A8,[16]HISTOJANV22!$A$6:$AU$39,43,0) -> 0 | AB8: =VLOOKUP($A8,[16]HISTOJANV22!$A$6:$AU$39,44,0) -> 0 | AC8: =VLOOKUP($A8,[16]HISTOJANV22!$A$6:$AU$39,47,0) -> 0 | AD8: =VLOOKUP(A8,[16]HISTOJANV22!$A$6:$BB$36,54,0) -> 0
A9: AS201654 | B9: =VLOOKUP(A9,[15]LISTADHERENT!A$5:H$60,3,0) -> DJOMOU TCHANDA | C9: 570000 | D9: 359 | E9: =VLOOKUP($A9,[16]HISTOJANV22!$A$6:$BA$39,48,0) -> 0 | F9: =C9-E9 -> 570000 | G9: =$S$40/$H$40*H9 -> 44118.791 | H9: =F9+D9+K9 -> 573359 | I9: =VLOOKUP($A9,[16]HISTOJANV22!$A$6:$AQ$37,22,0) -> 0 | J9: =VLOOKUP($A9,[16]HISTOJANV22!$A$6:$AU$39,45,0) -> 7000 | K9: =IF(J9=0,0,J9-(L9+M9+N9)) -> 3000 | L9: =IF(J9=0,0,500) -> 500 | M9: =IF(J9=0,0,1000) -> 1000 | N9: =IF(J9=0,0,2500) -> 2500 | O9: =VLOOKUP($A9,[16]HISTOJANV22!$A$6:$AU$39,7,0) -> 0 | P9: =VLOOKUP($A9,[16]HISTOJANV22!$A$6:$AU$39,23,0) -> 0 | Q9: =VLOOKUP($A9,[16]HISTOJANV22!$A$6:$AU$39,46,0) -> 0 | R9: =VLOOKUP($A9,[16]HISTODEC21!$A$6:$AU$39,26,0) -> 0 | S9: =R9*12/1200*12 -> 0 | T9: =VLOOKUP($A9,[16]HISTOJANV22!$A$6:$AU$39,28,0) -> 0 | U9: =VLOOKUP($A9,[16]HISTOJANV22!$A$6:$AU$39,19,0) -> 0 | V9: =VLOOKUP($A9,[16]HISTOJANV22!$A$6:$AU$39,20,0) -> 0 | W9: =VLOOKUP($A9,[16]HISTOJANV22!$A$6:$AU$39,27,0) -> 0 | X9: =VLOOKUP($A9,[16]HISTOJANV22!$A$6:$AU$39,33,0) -> 0 | AA9: =VLOOKUP($A9,[16]HISTOJANV22!$A$6:$AU$39,43,0) -> 0 | AB9: =VLOOKUP($A9,[16]HISTOJANV22!$A$6:$AU$39,44,0) -> 0 | AC9: =VLOOKUP($A9,[16]HISTOJANV22!$A$6:$AU$39,47,0) -> 0 | AD9: =VLOOKUP(A9,[16]HISTOJANV22!$A$6:$BB$36,54,0) -> 0
A10: AS201605 | B10: =VLOOKUP(A10,[15]LISTADHERENT!A$5:H$60,3,0) -> DJOUKWE NANGUEN GUY BLAISE | C10: 570000 | D10: 110412.64 | E10: =VLOOKUP($A10,[16]HISTOJANV22!$A$6:$BA$39,48,0) -> 0 | F10: =C10-E10 -> 570000 | G10: =$S$40/$H$40*H10 -> 52971.932 | H10: =F10+D10+K10 -> 688412.64 | I10: =VLOOKUP($A10,[16]HISTOJANV22!$A$6:$AQ$37,22,0) -> 0 | J10: =VLOOKUP($A10,[16]HISTOJANV22!$A$6:$AU$39,45,0) -> 12000 | K10: =IF(J10=0,0,J10-(L10+M10+N10)) -> 8000 | L10: =IF(J10=0,0,500) -> 500 | M10: =IF(J10=0,0,1000) -> 1000 | N10: =IF(J10=0,0,2500) -> 2500 | O10: =VLOOKUP($A10,[16]HISTOJANV22!$A$6:$AU$39,7,0) -> 0 | P10: =VLOOKUP($A10,[16]HISTOJANV22!$A$6:$AU$39,23,0) -> 0 | Q10: =VLOOKUP($A10,[16]HISTOJANV22!$A$6:$AU$39,46,0) -> 0 | R10: =VLOOKUP($A10,[16]HISTODEC21!$A$6:$AU$39,26,0) -> 1000000 | S10: =R10*1/1200*12 -> 10000 | T10: =VLOOKUP($A10,[16]HISTOJANV22!$A$6:$AU$39,28,0) -> OKK | U10: =VLOOKUP($A10,[16]HISTOJANV22!$A$6:$AU$39,19,0) -> 0 | V10: =VLOOKUP($A10,[16]HISTOJANV22!$A$6:$AU$39,20,0) -> 0 | W10: =VLOOKUP($A10,[16]HISTOJANV22!$A$6:$AU$39,27,0) -> BANQUE | X10: =VLOOKUP($A10,[16]HISTOJANV22!$A$6:$AU$39,33,0) -> 0 | AA10: =VLOOKUP($A10,[16]HISTOJANV22!$A$6:$AU$39,43,0) -> 0 | AB10: =VLOOKUP($A10,[16]HISTOJANV22!$A$6:$AU$39,44,0) -> 0 | AC10: =VLOOKUP($A10,[16]HISTOJANV22!$A$6:$AU$39,47,0) -> 0 | AD10: =VLOOKUP(A10,[16]HISTOJANV22!$A$6:$BB$36,54,0) -> 0
A11: AS201608 | B11: =VLOOKUP(A11,[15]LISTADHERENT!A$5:H$60,3,0) -> DJUOMBESSY ANTOINE | C11: 570000 | D11: 18508.85 | E11: =VLOOKUP($A11,[16]HISTOJANV22!$A$6:$BA$39,48,0) -> 0 | F11: =C11-E11 -> 570000 | G11: =$S$40/$H$40*H11 -> 45515.385 | H11: =F11+D11+K11 -> 591508.85 | I11: =VLOOKUP($A11,[16]HISTOJANV22!$A$6:$AQ$37,22,0) -> 0 | J11: =VLOOKUP($A11,[16]HISTOJANV22!$A$6:$AU$39,45,0) -> 7000 | K11: =IF(J11=0,0,J11-(L11+M11+N11)) -> 3000 | L11: =IF(J11=0,0,500) -> 500 | M11: =IF(J11=0,0,1000) -> 1000 | N11: =IF(J11=0,0,2500) -> 2500 | O11: =VLOOKUP($A11,[16]HISTOJANV22!$A$6:$AU$39,7,0) -> 0 | P11: =VLOOKUP($A11,[16]HISTOJANV22!$A$6:$AU$39,23,0) -> 0 | Q11: =VLOOKUP($A11,[16]HISTOJANV22!$A$6:$AU$39,46,0) -> 0 | R11: =VLOOKUP($A11,[16]HISTODEC21!$A$6:$AU$39,26,0) -> 1029000 | S11: =R11*1/1200*12 -> 10290 | T11: =VLOOKUP($A11,[16]HISTOJANV22!$A$6:$AU$39,28,0) -> 0 | U11: =VLOOKUP($A11,[16]HISTOJANV22!$A$6:$AU$39,19,0) -> 1000000 | V11: =VLOOKUP($A11,[16]HISTOJANV22!$A$6:$AU$39,20,0) -> BANQUE | W11: =VLOOKUP($A11,[16]HISTOJANV22!$A$6:$AU$39,27,0) -> 0 | X11: =VLOOKUP($A11,[16]HISTOJANV22!$A$6:$AU$39,33,0) -> 0 | Y11: 29000 | AA11: =VLOOKUP($A11,[16]HISTOJANV22!$A$6:$AU$39,43,0) -> 0 | AB11: =VLOOKUP($A11,[16]HISTOJANV22!$A$6:$AU$39,44,0) -> 0 | AC11: =VLOOKUP($A11,[16]HISTOJANV22!$A$6:$AU$39,47,0) -> 0 | AD11: =VLOOKUP(A11,[16]HISTOJANV22!$A$6:$BB$36,54,0) -> 61000
A12: AS201651 | B12: =VLOOKUP(A12,[15]LISTADHERENT!A$5:H$60,3,0) -> DOMOU FABIEN | C12: 570000 | D12: 6527.0543 | E12: =VLOOKUP($A12,[16]HISTOJANV22!$A$6:$BA$39,48,0) -> 0 | F12: =C12-E12 -> 570000 | G12: =$S$40/$H$40*H12 -> 44978.15 | H12: =F12+D12+K12 -> 584527.05 | I12: =VLOOKUP($A12,[16]HISTOJANV22!$A$6:$AQ$37,22,0) -> 0 | J12: =VLOOKUP($A12,[16]HISTOJANV22!$A$6:$AU$39,45,0) -> 12000 | K12: =IF(J12=0,0,J12-(L12+M12+N12)) -> 8000 | L12: =IF(J12=0,0,500) -> 500 | M12: =IF(J12=0,0,1000) -> 1000 | N12: =IF(J12=0,0,2500) -> 2500 | O12: =VLOOKUP($A12,[16]HISTOJANV22!$A$6:$AU$39,7,0) -> 0 | P12: =VLOOKUP($A12,[16]HISTOJANV22!$A$6:$AU$39,23,0) -> 0 | Q12: =VLOOKUP($A12,[16]HISTOJANV22!$A$6:$AU$39,46,0) -> 0 | R12: =VLOOKUP($A12,[16]HISTODEC21!$A$6:$AU$39,26,0) -> 1000000 | S12: =R12*12/1200*12 -> 120000 | T12: =VLOOKUP($A12,[16]HISTOJANV22!$A$6:$AU$39,28,0) -> OKK | U12: =VLOOKUP($A12,[16]HISTOJANV22!$A$6:$AU$39,19,0) -> 0 | V12: =VLOOKUP($A12,[16]HISTOJANV22!$A$6:$AU$39,20,0) -> 0 | W12: =VLOOKUP($A12,[16]HISTOJANV22!$A$6:$AU$39,27,0) -> BANQUE | X12: =VLOOKUP($A12,[16]HISTOJANV22!$A$6:$AU$39,33,0) -> 0 | AA12: =VLOOKUP($A12,[16]HISTOJANV22!$A$6:$AU$39,43,0) -> 0 | AB12: =VLOOKUP($A12,[16]HISTOJANV22!$A$6:$AU$39,44,0) -> 0 | AC12: =VLOOKUP($A12,[16]HISTOJANV22!$A$6:$AU$39,47,0) -> 0 | AD12: =VLOOKUP(A12,[16]HISTOJANV22!$A$6:$BB$36,54,0) -> 57000
A13: AS201609 | B13: =VLOOKUP(A13,[15]LISTADHERENT!A$5:H$60,3,0) -> DONHOU DAVID | C13: 570000 | D13: 253289.51 | E13: =VLOOKUP($A13,[16]HISTOJANV22!$A$6:$BA$39,48,0) -> 0 | F13: =C13-E13 -> 570000 | G13: =$S$40/$H$40*H13 -> 63581.272 | H13: =F13+D13+K13 -> 826289.51 | I13: =VLOOKUP($A13,[16]HISTOJANV22!$A$6:$AQ$37,22,0) -> 0 | J13: =VLOOKUP($A13,[16]HISTOJANV22!$A$6:$AU$39,45,0) -> 7000 | K13: =IF(J13=0,0,J13-(L13+M13+N13)) -> 3000 | L13: =IF(J13=0,0,500) -> 500 | M13: =IF(J13=0,0,1000) -> 1000 | N13: =IF(J13=0,0,2500) -> 2500 | O13: =VLOOKUP($A13,[16]HISTOJANV22!$A$6:$AU$39,7,0) -> 0 | P13: =VLOOKUP($A13,[16]HISTOJANV22!$A$6:$AU$39,23,0) -> 0 | Q13: =VLOOKUP($A13,[16]HISTOJANV22!$A$6:$AU$39,46,0) -> 0 | R13: =VLOOKUP($A13,[16]HISTODEC21!$A$6:$AU$39,26,0) -> 0 | S13: =R13*12/1200*12 -> 0 | T13: =VLOOKUP($A13,[16]HISTOJANV22!$A$6:$AU$39,28,0) -> 0 | U13: =VLOOKUP($A13,[16]HISTOJANV22!$A$6:$AU$39,19,0) -> 0 | V13: =VLOOKUP($A13,[16]HISTOJANV22!$A$6:$AU$39,20,0) -> 0 | W13: =VLOOKUP($A13,[16]HISTOJANV22!$A$6:$AU$39,27,0) -> 0 | X13: =VLOOKUP($A13,[16]HISTOJANV22!$A$6:$AU$39,33,0) -> 0 | AA13: =VLOOKUP($A13,[16]HISTOJANV22!$A$6:$AU$39,43,0) -> 0 | AB13: =VLOOKUP($A13,[16]HISTOJANV22!$A$6:$AU$39,44,0) -> 0 | AC13: =VLOOKUP($A13,[16]HISTOJANV22!$A$6:$AU$39,47,0) -> 0 | AD13: =VLOOKUP(A13,[16]HISTOJANV22!$A$6:$BB$36,54,0) -> 70000
A14: AS201610 | B14: =VLOOKUP(A14,[15]LISTADHERENT!A$5:H$60,3,0) -> FOTSO THOMAS | C14: 540000 | D14: -2105.0986 | E14: =VLOOKUP($A14,[16]HISTOJANV22!$A$6:$BA$39,48,0) -> 0 | F14: =C14-E14 -> 540000 | G14: =$S$40/$H$40*H14 -> 41389.902 | H14: =F14+D14+K14 -> 537894.9 | I14: =VLOOKUP($A14,[16]HISTOJANV22!$A$6:$AQ$37,22,0) -> 0 | J14: =VLOOKUP($A14,[16]HISTOJANV22!$A$6:$AU$39,45,0) -> 0 | K14: =IF(J14=0,0,J14-(L14+M14+N14)) -> 0 | L14: =IF(J14=0,0,500) -> 0 | M14: =IF(J14=0,0,1000) -> 0 | N14: =IF(J14=0,0,2500) -> 0 | O14: =VLOOKUP($A14,[16]HISTOJANV22!$A$6:$AU$39,7,0) -> 0 | P14: =VLOOKUP($A14,[16]HISTOJANV22!$A$6:$AU$39,23,0) -> 0 | Q14: =VLOOKUP($A14,[16]HISTOJANV22!$A$6:$AU$39,46,0) -> 0 | R14: =VLOOKUP($A14,[16]HISTODEC21!$A$6:$AU$39,26,0) -> 1155000 | S14: =R14*0/1200*12 -> 0 | T14: =VLOOKUP($A14,[16]HISTOJANV22!$A$6:$AU$39,28,0) -> 0 | U14: =VLOOKUP($A14,[16]HISTOJANV22!$A$6:$AU$39,19,0) -> 0 | V14: =VLOOKUP($A14,[16]HISTOJANV22!$A$6:$AU$39,20,0) -> 0 | W14: =VLOOKUP($A14,[16]HISTOJANV22!$A$6:$AU$39,27,0) -> BANQUE | X14: =VLOOKUP($A14,[16]HISTOJANV22!$A$6:$AU$39,33,0) -> 0 | Y14: 155000 | AA14: =VLOOKUP($A14,[16]HISTOJANV22!$A$6:$AU$39,43,0) -> 0 | AB14: =VLOOKUP($A14,[16]HISTOJANV22!$A$6:$AU$39,44,0) -> 0 | AC14: =VLOOKUP($A14,[16]HISTOJANV22!$A$6:$AU$39,47,0) -> 0 | AD14: =VLOOKUP(A14,[16]HISTOJANV22!$A$6:$BB$36,54,0) -> 0
A15: AS201611 | B15: =VLOOKUP(A15,[15]LISTADHERENT!A$5:H$60,3,0) -> HENGUE PAUL OMER | C15: 570000 | D15: 3435.9669 | E15: =VLOOKUP($A15,[16]HISTOJANV22!$A$6:$BA$39,48,0) -> 0 | F15: =C15-E15 -> 570000 | G15: =$S$40/$H$40*H15 -> 44355.558 | H15: =F15+D15+K15 -> 576435.97 | I15: =VLOOKUP($A15,[16]HISTOJANV22!$A$6:$AQ$37,22,0) -> 0 | J15: =VLOOKUP($A15,[16]HISTOJANV22!$A$6:$AU$39,45,0) -> 7000 | K15: =IF(J15=0,0,J15-(L15+M15+N15)) -> 3000 | L15: =IF(J15=0,0,500) -> 500 | M15: =IF(J15=0,0,1000) -> 1000 | N15: =IF(J15=0,0,2500) -> 2500 | O15: =VLOOKUP($A15,[16]HISTOJANV22!$A$6:$AU$39,7,0) -> 0 | P15: =VLOOKUP($A15,[16]HISTOJANV22!$A$6:$AU$39,23,0) -> 0 | Q15: =VLOOKUP($A15,[16]HISTOJANV22!$A$6:$AU$39,46,0) -> 0 | R15: =VLOOKUP($A15,[16]HISTODEC21!$A$6:$AU$39,26,0) -> 0 | S15: =R15*12/1200*12 -> 0 | T15: =VLOOKUP($A15,[16]HISTOJANV22!$A$6:$AU$39,28,0) -> 0 | U15: =VLOOKUP($A15,[16]HISTOJANV22!$A$6:$AU$39,19,0) -> 0 | V15: =VLOOKUP($A15,[16]HISTOJANV22!$A$6:$AU$39,20,0) -> 0 | W15: =VLOOKUP($A15,[16]HISTOJANV22!$A$6:$AU$39,27,0) -> 0 | X15: =VLOOKUP($A15,[16]HISTOJANV22!$A$6:$AU$39,33,0) -> 0 | AA15: =VLOOKUP($A15,[16]HISTOJANV22!$A$6:$AU$39,43,0) -> 0 | AB15: =VLOOKUP($A15,[16]HISTOJANV22!$A$6:$AU$39,44,0) -> 0 | AC15: =VLOOKUP($A15,[16]HISTOJANV22!$A$6:$AU$39,47,0) -> 0 | AD15: =VLOOKUP(A15,[16]HISTOJANV22!$A$6:$BB$36,54,0) -> 0
A16: AS201613 | B16: =VLOOKUP(A16,[15]LISTADHERENT!A$5:H$60,3,0) -> HOTCHO BENJAMIN | C16: 570000 | D16: 17580.42 | E16: =VLOOKUP($A16,[16]HISTOJANV22!$A$6:$BA$39,48,0) -> 0 | F16: =C16-E16 -> 570000 | G16: =$S$40/$H$40*H16 -> 48906.601 | H16: =F16+D16+K16 -> 635580.42 | I16: =VLOOKUP($A16,[16]HISTOJANV22!$A$6:$AQ$37,22,0) -> 0 | J16: =VLOOKUP($A16,[16]HISTOJANV22!$A$6:$AU$39,45,0) -> 52000 | K16: =IF(J16=0,0,J16-(L16+M16+N16)) -> 48000 | L16: =IF(J16=0,0,500) -> 500 | M16: =IF(J16=0,0,1000) -> 1000 | N16: =IF(J16=0,0,2500) -> 2500 | O16: =VLOOKUP($A16,[16]HISTOJANV22!$A$6:$AU$39,7,0) -> 0 | P16: =VLOOKUP($A16,[16]HISTOJANV22!$A$6:$AU$39,23,0) -> 0 | Q16: =VLOOKUP($A16,[16]HISTOJANV22!$A$6:$AU$39,46,0) -> 0 | R16: =VLOOKUP($A16,[16]HISTODEC21!$A$6:$AU$39,26,0) -> 0 | S16: =R16*12/1200*12 -> 0 | T16: =VLOOKUP($A16,[16]HISTOJANV22!$A$6:$AU$39,28,0) -> 0 | U16: =VLOOKUP($A16,[16]HISTOJANV22!$A$6:$AU$39,19,0) -> 0 | V16: =VLOOKUP($A16,[16]HISTOJANV22!$A$6:$AU$39,20,0) -> 0 | W16: =VLOOKUP($A16,[16]HISTOJANV22!$A$6:$AU$39,27,0) -> 0 | X16: =VLOOKUP($A16,[16]HISTOJANV22!$A$6:$AU$39,33,0) -> 0 | AA16: =VLOOKUP($A16,[16]HISTOJANV22!$A$6:$AU$39,43,0) -> 0 | AB16: =VLOOKUP($A16,[16]HISTOJANV22!$A$6:$AU$39,44,0) -> 0 | AC16: =VLOOKUP($A16,[16]HISTOJANV22!$A$6:$AU$39,47,0) -> 0 | AD16: =VLOOKUP(A16,[16]HISTOJANV22!$A$6:$BB$36,54,0) -> 70000
A17: AS201617 | B17: =VLOOKUP(A17,[15]LISTADHERENT!A$5:H$60,3,0) -> KOUAMOU MOISE | C17: 570000 | D17: 5406.5483 | E17: =VLOOKUP($A17,[16]HISTOJANV22!$A$6:$BA$39,48,0) -> 0 | F17: =C17-E17 -> 570000 | G17: =$S$40/$H$40*H17 -> 44507.19 | H17: =F17+D17+K17 -> 578406.55 | I17: =VLOOKUP($A17,[16]HISTOJANV22!$A$6:$AQ$37,22,0) -> 0 | J17: =VLOOKUP($A17,[16]HISTOJANV22!$A$6:$AU$39,45,0) -> 7000 | K17: =IF(J17=0,0,J17-(L17+M17+N17)) -> 3000 | L17: =IF(J17=0,0,500) -> 500 | M17: =IF(J17=0,0,1000) -> 1000 | N17: =IF(J17=0,0,2500) -> 2500 | O17: =VLOOKUP($A17,[16]HISTOJANV22!$A$6:$AU$39,7,0) -> 0 | P17: =VLOOKUP($A17,[16]HISTOJANV22!$A$6:$AU$39,23,0) -> 0 | Q17: =VLOOKUP($A17,[16]HISTOJANV22!$A$6:$AU$39,46,0) -> 0 | R17: =VLOOKUP($A17,[16]HISTODEC21!$A$6:$AU$39,26,0) -> 0 | S17: =R17*12/1200*12 -> 0 | T17: =VLOOKUP($A17,[16]HISTOJANV22!$A$6:$AU$39,28,0) -> 0 | U17: =VLOOKUP($A17,[16]HISTOJANV22!$A$6:$AU$39,19,0) -> 0 | V17: =VLOOKUP($A17,[16]HISTOJANV22!$A$6:$AU$39,20,0) -> 0 | W17: =VLOOKUP($A17,[16]HISTOJANV22!$A$6:$AU$39,27,0) -> 0 | X17: =VLOOKUP($A17,[16]HISTOJANV22!$A$6:$AU$39,33,0) -> 0 | AA17: =VLOOKUP($A17,[16]HISTOJANV22!$A$6:$AU$39,43,0) -> 0 | AB17: =VLOOKUP($A17,[16]HISTOJANV22!$A$6:$AU$39,44,0) -> 0 | AC17: =VLOOKUP($A17,[16]HISTOJANV22!$A$6:$AU$39,47,0) -> 0 | AD17: =VLOOKUP(A17,[16]HISTOJANV22!$A$6:$BB$36,54,0) -> 0
A18: AS201619 | B18: =VLOOKUP(A18,[15]LISTADHERENT!A$5:H$60,3,0) -> KOUATCHO MESSACK | C18: 570000 | D18: 8241.6184 | E18: =VLOOKUP($A18,[16]HISTOJANV22!$A$6:$BA$39,48,0) -> 0 | F18: =C18-E18 -> 570000 | G18: =$S$40/$H$40*H18 -> 44725.343 | H18: =F18+D18+K18 -> 581241.62 | I18: =VLOOKUP($A18,[16]HISTOJANV22!$A$6:$AQ$37,22,0) -> 0 | J18: =VLOOKUP($A18,[16]HISTOJANV22!$A$6:$AU$39,45,0) -> 7000 | K18: =IF(J18=0,0,J18-(L18+M18+N18)) -> 3000 | L18: =IF(J18=0,0,500) -> 500 | M18: =IF(J18=0,0,1000) -> 1000 | N18: =IF(J18=0,0,2500) -> 2500 | O18: =VLOOKUP($A18,[16]HISTOJANV22!$A$6:$AU$39,7,0) -> 0 | P18: =VLOOKUP($A18,[16]HISTOJANV22!$A$6:$AU$39,23,0) -> 0 | Q18: =VLOOKUP($A18,[16]HISTOJANV22!$A$6:$AU$39,46,0) -> 0 | R18: =VLOOKUP($A18,[16]HISTODEC21!$A$6:$AU$39,26,0) -> 1000000 | S18: =R18*12/1200*12 -> 120000 | T18: =VLOOKUP($A18,[16]HISTOJANV22!$A$6:$AU$39,28,0) -> OKK | U18: =VLOOKUP($A18,[16]HISTOJANV22!$A$6:$AU$39,19,0) -> 0 | V18: =VLOOKUP($A18,[16]HISTOJANV22!$A$6:$AU$39,20,0) -> 0 | W18: =VLOOKUP($A18,[16]HISTOJANV22!$A$6:$AU$39,27,0) -> BANQUE | X18: =VLOOKUP($A18,[16]HISTOJANV22!$A$6:$AU$39,33,0) -> 0 | AA18: =VLOOKUP($A18,[16]HISTOJANV22!$A$6:$AU$39,43,0) -> 0 | AB18: =VLOOKUP($A18,[16]HISTOJANV22!$A$6:$AU$39,44,0) -> 0 | AC18: =VLOOKUP($A18,[16]HISTOJANV22!$A$6:$AU$39,47,0) -> 0 | AD18: =VLOOKUP(A18,[16]HISTOJANV22!$A$6:$BB$36,54,0) -> 0
A19: AS201620 | B19: =VLOOKUP(A19,[15]LISTADHERENT!A$5:H$60,3,0) -> LOWE JEAN | C19: 570000 | D19: 393.95927 | E19: =VLOOKUP($A19,[16]HISTOJANV22!$A$6:$BA$39,48,0) -> 0 | F19: =C19-E19 -> 570000 | G19: =$S$40/$H$40*H19 -> 44121.481 | H19: =F19+D19+K19 -> 573393.96 | I19: =VLOOKUP($A19,[16]HISTOJANV22!$A$6:$AQ$37,22,0) -> 0 | J19: =VLOOKUP($A19,[16]HISTOJANV22!$A$6:$AU$39,45,0) -> 7000 | K19: =IF(J19=0,0,J19-(L19+M19+N19)) -> 3000 | L19: =IF(J19=0,0,500) -> 500 | M19: =IF(J19=0,0,1000) -> 1000 | N19: =IF(J19=0,0,2500) -> 2500 | O19: =VLOOKUP($A19,[16]HISTOJANV22!$A$6:$AU$39,7,0) -> 0 | P19: =VLOOKUP($A19,[16]HISTOJANV22!$A$6:$AU$39,23,0) -> 0 | Q19: =VLOOKUP($A19,[16]HISTOJANV22!$A$6:$AU$39,46,0) -> 0 | R19: =VLOOKUP($A19,[16]HISTODEC21!$A$6:$AU$39,26,0) -> 500000 | S19: =R19*12/1200*12 -> 60000 | T19: =VLOOKUP($A19,[16]HISTOJANV22!$A$6:$AU$39,28,0) -> OKK | U19: =VLOOKUP($A19,[16]HISTOJANV22!$A$6:$AU$39,19,0) -> 0 | V19: =VLOOKUP($A19,[16]HISTOJANV22!$A$6:$AU$39,20,0) -> 0 | W19: =VLOOKUP($A19,[16]HISTOJANV22!$A$6:$AU$39,27,0) -> BANQUE | X19: =VLOOKUP($A19,[16]HISTOJANV22!$A$6:$AU$39,33,0) -> 0 | AA19: =VLOOKUP($A19,[16]HISTOJANV22!$A$6:$AU$39,43,0) -> 0 | AB19: =VLOOKUP($A19,[16]HISTOJANV22!$A$6:$AU$39,44,0) -> 0 | AC19: =VLOOKUP($A19,[16]HISTOJANV22!$A$6:$AU$39,47,0) -> 0 | AD19: =VLOOKUP(A19,[16]HISTOJANV22!$A$6:$BB$36,54,0) -> 0
A20: AS201649 | B20: =VLOOKUP(A20,[15]LISTADHERENT!A$5:H$60,3,0) -> MBOGNING TUGMA GUY | C20: 570000 | D20: 112.46349 | E20: =VLOOKUP($A20,[16]HISTOJANV22!$A$6:$BA$39,48,0) -> 0 | F20: =C20-E20 -> 570000 | G20: =$S$40/$H$40*H20 -> 44099.821 | H20: =F20+D20+K20 -> 573112.46 | I20: =VLOOKUP($A20,[16]HISTOJANV22!$A$6:$AQ$37,22,0) -> 0 | J20: =VLOOKUP($A20,[16]HISTOJANV22!$A$6:$AU$39,45,0) -> 7000 | K20: =IF(J20=0,0,J20-(L20+M20+N20)) -> 3000 | L20: =IF(J20=0,0,500) -> 500 | M20: =IF(J20=0,0,1000) -> 1000 | N20: =IF(J20=0,0,2500) -> 2500 | O20: =VLOOKUP($A20,[16]HISTOJANV22!$A$6:$AU$39,7,0) -> 0 | P20: =VLOOKUP($A20,[16]HISTOJANV22!$A$6:$AU$39,23,0) -> 0 | Q20: =VLOOKUP($A20,[16]HISTOJANV22!$A$6:$AU$39,46,0) -> 0 | R20: =VLOOKUP($A20,[16]HISTODEC21!$A$6:$AU$39,26,0) -> 1050000 | S20: =R20*12/1200*12 -> 126000 | T20: =VLOOKUP($A20,[16]HISTOJANV22!$A$6:$AU$39,28,0) -> 0 | U20: =VLOOKUP($A20,[16]HISTOJANV22!$A$6:$AU$39,19,0) -> 1050000 | V20: =VLOOKUP($A20,[16]HISTOJANV22!$A$6:$AU$39,20,0) -> BANQUE | W20: =VLOOKUP($A20,[16]HISTOJANV22!$A$6:$AU$39,27,0) -> BANQUE | X20: =VLOOKUP($A20,[16]HISTOJANV22!$A$6:$AU$39,33,0) -> 0 | AA20: =VLOOKUP($A20,[16]HISTOJANV22!$A$6:$AU$39,43,0) -> 0 | AB20: =VLOOKUP($A20,[16]HISTOJANV22!$A$6:$AU$39,44,0) -> 0 | AC20: =VLOOKUP($A20,[16]HISTOJANV22!$A$6:$AU$39,47,0) -> 0 | AD20: =VLOOKUP(A20,[16]HISTOJANV22!$A$6:$BB$36,54,0) -> 0
A21: AS201639 | B21: =VLOOKUP(A21,[15]LISTADHERENT!A$5:H$60,3,0) -> NANGUEN MARTIN | C21: 570000 | D21: 30757.615 | E21: =VLOOKUP($A21,[16]HISTOJANV22!$A$6:$BA$39,48,0) -> 0 | F21: =C21-E21 -> 570000 | G21: =$S$40/$H$40*H21 -> 46457.902 | H21: =F21+D21+K21 -> 603757.62 | I21: =VLOOKUP($A21,[16]HISTOJANV22!$A$6:$AQ$37,22,0) -> 0 | J21: =VLOOKUP($A21,[16]HISTOJANV22!$A$6:$AU$39,45,0) -> 7000 | K21: =IF(J21=0,0,J21-(L21+M21+N21)) -> 3000 | L21: =IF(J21=0,0,500) -> 500 | M21: =IF(J21=0,0,1000) -> 1000 | N21: =IF(J21=0,0,2500) -> 2500 | O21: =VLOOKUP($A21,[16]HISTOJANV22!$A$6:$AU$39,7,0) -> 0 | P21: =VLOOKUP($A21,[16]HISTOJANV22!$A$6:$AU$39,23,0) -> 0 | Q21: =VLOOKUP($A21,[16]HISTOJANV22!$A$6:$AU$39,46,0) -> 0 | R21: =VLOOKUP($A21,[16]HISTODEC21!$A$6:$AU$39,26,0) -> 0 | S21: =R21*12/1200*12 -> 0 | T21: =VLOOKUP($A21,[16]HISTOJANV22!$A$6:$AU$39,28,0) -> 0 | U21: =VLOOKUP($A21,[16]HISTOJANV22!$A$6:$AU$39,19,0) -> 0 | V21: =VLOOKUP($A21,[16]HISTOJANV22!$A$6:$AU$39,20,0) -> 0 | W21: =VLOOKUP($A21,[16]HISTOJANV22!$A$6:$AU$39,27,0) -> 0 | X21: =VLOOKUP($A21,[16]HISTOJANV22!$A$6:$AU$39,33,0) -> 0 | AA21: =VLOOKUP($A21,[16]HISTOJANV22!$A$6:$AU$39,43,0) -> 0 | AB21: =VLOOKUP($A21,[16]HISTOJANV22!$A$6:$AU$39,44,0) -> 0 | AC21: =VLOOKUP($A21,[16]HISTOJANV22!$A$6:$AU$39,47,0) -> 0 | AD21: =VLOOKUP(A21,[16]HISTOJANV22!$A$6:$BB$36,54,0) -> 0
A22: AS201621 | B22: =VLOOKUP(A22,[15]LISTADHERENT!A$5:H$60,3,0) -> NANKAM APPOLINAIRE | C22: 570000 | D22: 84601.912 | E22: =VLOOKUP($A22,[16]HISTOJANV22!$A$6:$BA$39,48,0) -> 0 | F22: =C22-E22 -> 570000 | G22: =$S$40/$H$40*H22 -> 50601.109 | H22: =F22+D22+K22 -> 657601.91 | I22: =VLOOKUP($A22,[16]HISTOJANV22!$A$6:$AQ$37,22,0) -> 0 | J22: =VLOOKUP($A22,[16]HISTOJANV22!$A$6:$AU$39,45,0) -> 7000 | K22: =IF(J22=0,0,J22-(L22+M22+N22)) -> 3000 | L22: =IF(J22=0,0,500) -> 500 | M22: =IF(J22=0,0,1000) -> 1000 | N22: =IF(J22=0,0,2500) -> 2500 | O22: =VLOOKUP($A22,[16]HISTOJANV22!$A$6:$AU$39,7,0) -> 0 | P22: =VLOOKUP($A22,[16]HISTOJANV22!$A$6:$AU$39,23,0) -> 0 | Q22: =VLOOKUP($A22,[16]HISTOJANV22!$A$6:$AU$39,46,0) -> 0 | R22: =VLOOKUP($A22,[16]HISTODEC21!$A$6:$AU$39,26,0) -> 924000 | S22: =R22*12/1200*12 -> 110880 | T22: =VLOOKUP($A22,[16]HISTOJANV22!$A$6:$AU$39,28,0) -> 0 | U22: =VLOOKUP($A22,[16]HISTOJANV22!$A$6:$AU$39,19,0) -> 924000 | V22: =VLOOKUP($A22,[16]HISTOJANV22!$A$6:$AU$39,20,0) -> BANQUE | W22: =VLOOKUP($A22,[16]HISTOJANV22!$A$6:$AU$39,27,0) -> 0 | X22: =VLOOKUP($A22,[16]HISTOJANV22!$A$6:$AU$39,33,0) -> 0 | Y22: 50000 | AA22: =VLOOKUP($A22,[16]HISTOJANV22!$A$6:$AU$39,43,0) -> 0 | AB22: =VLOOKUP($A22,[16]HISTOJANV22!$A$6:$AU$39,44,0) -> 0 | AC22: =VLOOKUP($A22,[16]HISTOJANV22!$A$6:$AU$39,47,0) -> 0 | AD22: =VLOOKUP(A22,[16]HISTOJANV22!$A$6:$BB$36,54,0) -> 0
A23: AS201622 | B23: =VLOOKUP(A23,[15]LISTADHERENT!A$5:H$60,3,0) -> NDJOMO ETIENNE | C23: 570000 | D23: 101446.17 | E23: =VLOOKUP($A23,[16]HISTOJANV22!$A$6:$BA$39,48,0) -> 0 | F23: =C23-E23 -> 570000 | G23: =$S$40/$H$40*H23 -> 52666.72 | H23: =F23+D23+K23 -> 684446.17 | I23: =VLOOKUP($A23,[16]HISTOJANV22!$A$6:$AQ$37,22,0) -> 0 | J23: =VLOOKUP($A23,[16]HISTOJANV22!$A$6:$AU$39,45,0) -> 17000 | K23: =IF(J23=0,0,J23-(L23+M23+N23)) -> 13000 | L23: =IF(J23=0,0,500) -> 500 | M23: =IF(J23=0,0,1000) -> 1000 | N23: =IF(J23=0,0,2500) -> 2500 | O23: =VLOOKUP($A23,[16]HISTOJANV22!$A$6:$AU$39,7,0) -> 0 | P23: =VLOOKUP($A23,[16]HISTOJANV22!$A$6:$AU$39,23,0) -> 0 | Q23: =VLOOKUP($A23,[16]HISTOJANV22!$A$6:$AU$39,46,0) -> 0 | R23: =VLOOKUP($A23,[16]HISTODEC21!$A$6:$AU$39,26,0) -> 500000 | S23: =R23*12/1200*12 -> 60000 | T23: =VLOOKUP($A23,[16]HISTOJANV22!$A$6:$AU$39,28,0) -> OKK | U23: =VLOOKUP($A23,[16]HISTOJANV22!$A$6:$AU$39,19,0) -> 0 | V23: =VLOOKUP($A23,[16]HISTOJANV22!$A$6:$AU$39,20,0) -> 0 | W23: =VLOOKUP($A23,[16]HISTOJANV22!$A$6:$AU$39,27,0) -> BANQUE | X23: =VLOOKUP($A23,[16]HISTOJANV22!$A$6:$AU$39,33,0) -> 0 | AA23: =VLOOKUP($A23,[16]HISTOJANV22!$A$6:$AU$39,43,0) -> 0 | AB23: =VLOOKUP($A23,[16]HISTOJANV22!$A$6:$AU$39,44,0) -> 0 | AC23: =VLOOKUP($A23,[16]HISTOJANV22!$A$6:$AU$39,47,0) -> 0 | AD23: =VLOOKUP(A23,[16]HISTOJANV22!$A$6:$BB$36,54,0) -> 0
A24: AS201624 | B24: =VLOOKUP(A24,[15]LISTADHERENT!A$5:H$60,3,0) -> NGONDIEP CLAUDE | C24: 570000 | D24: 2927.3714 | E24: =VLOOKUP($A24,[16]HISTOJANV22!$A$6:$BA$39,48,0) -> 0 | F24: =C24-E24 -> 570000 | G24: =$S$40/$H$40*H24 -> 44701.162 | H24: =F24+D24+K24 -> 580927.37 | I24: =VLOOKUP($A24,[16]HISTOJANV22!$A$6:$AQ$37,22,0) -> 0 | J24: =VLOOKUP($A24,[16]HISTOJANV22!$A$6:$AU$39,45,0) -> 12000 | K24: =IF(J24=0,0,J24-(L24+M24+N24)) -> 8000 | L24: =IF(J24=0,0,500) -> 500 | M24: =IF(J24=0,0,1000) -> 1000 | N24: =IF(J24=0,0,2500) -> 2500 | O24: =VLOOKUP($A24,[16]HISTOJANV22!$A$6:$AU$39,7,0) -> 0 | P24: =VLOOKUP($A24,[16]HISTOJANV22!$A$6:$AU$39,23,0) -> 0 | Q24: =VLOOKUP($A24,[16]HISTOJANV22!$A$6:$AU$39,46,0) -> 0 | R24: =VLOOKUP($A24,[16]HISTODEC21!$A$6:$AU$39,26,0) -> 1000000 | S24: =R24*12/1200*12 -> 120000 | T24: =VLOOKUP($A24,[16]HISTOJANV22!$A$6:$AU$39,28,0) -> OKK | U24: =VLOOKUP($A24,[16]HISTOJANV22!$A$6:$AU$39,19,0) -> 0 | V24: =VLOOKUP($A24,[16]HISTOJANV22!$A$6:$AU$39,20,0) -> 0 | W24: =VLOOKUP($A24,[16]HISTOJANV22!$A$6:$AU$39,27,0) -> BANQUE | X24: =VLOOKUP($A24,[16]HISTOJANV22!$A$6:$AU$39,33,0) -> 0 | AA24: =VLOOKUP($A24,[16]HISTOJANV22!$A$6:$AU$39,43,0) -> 0 | AB24: =VLOOKUP($A24,[16]HISTOJANV22!$A$6:$AU$39,44,0) -> 0 | AC24: =VLOOKUP($A24,[16]HISTOJANV22!$A$6:$AU$39,47,0) -> 0 | AD24: =VLOOKUP(A24,[16]HISTOJANV22!$A$6:$BB$36,54,0) -> 70000
A25: AS201626 | B25: =VLOOKUP(A25,[15]LISTADHERENT!A$5:H$60,3,0) -> NGUIEMEGNI MATHIEU BLAISE | C25: 570000 | D25: 3871.4175 | E25: =VLOOKUP($A25,[16]HISTOJANV22!$A$6:$BA$39,48,0) -> 0 | F25: =C25-E25 -> 570000 | G25: =$S$40/$H$40*H25 -> 44389.065 | H25: =F25+D25+K25 -> 576871.42 | I25: =VLOOKUP($A25,[16]HISTOJANV22!$A$6:$AQ$37,22,0) -> 0 | J25: =VLOOKUP($A25,[16]HISTOJANV22!$A$6:$AU$39,45,0) -> 7000 | K25: =IF(J25=0,0,J25-(L25+M25+N25)) -> 3000 | L25: =IF(J25=0,0,500) -> 500 | M25: =IF(J25=0,0,1000) -> 1000 | N25: =IF(J25=0,0,2500) -> 2500 | O25: =VLOOKUP($A25,[16]HISTOJANV22!$A$6:$AU$39,7,0) -> 0 | P25: =VLOOKUP($A25,[16]HISTOJANV22!$A$6:$AU$39,23,0) -> 0 | Q25: =VLOOKUP($A25,[16]HISTOJANV22!$A$6:$AU$39,46,0) -> 0 | R25: =VLOOKUP($A25,[16]HISTODEC21!$A$6:$AU$39,26,0) -> 1000000 | S25: =R25*12/1200*12 -> 120000 | T25: =VLOOKUP($A25,[16]HISTOJANV22!$A$6:$AU$39,28,0) -> OKK | U25: =VLOOKUP($A25,[16]HISTOJANV22!$A$6:$AU$39,19,0) -> 0 | V25: =VLOOKUP($A25,[16]HISTOJANV22!$A$6:$AU$39,20,0) -> 0 | W25: =VLOOKUP($A25,[16]HISTOJANV22!$A$6:$AU$39,27,0) -> BANQUE | X25: =VLOOKUP($A25,[16]HISTOJANV22!$A$6:$AU$39,33,0) -> 0 | AA25: =VLOOKUP($A25,[16]HISTOJANV22!$A$6:$AU$39,43,0) -> 0 | AB25: =VLOOKUP($A25,[16]HISTOJANV22!$A$6:$AU$39,44,0) -> 0 | AC25: =VLOOKUP($A25,[16]HISTOJANV22!$A$6:$AU$39,47,0) -> 0 | AD25: =VLOOKUP(A25,[16]HISTOJANV22!$A$6:$BB$36,54,0) -> 70000
A26: AS201628 | B26: =VLOOKUP(A26,[15]LISTADHERENT!A$5:H$60,3,0) -> NKAMGANG JUSTIN DEJOLIE | C26: 570000 | D26: 11084.68 | E26: =VLOOKUP($A26,[16]HISTOJANV22!$A$6:$BA$39,48,0) -> 0 | F26: =C26-E26 -> 570000 | G26: =$S$40/$H$40*H26 -> 44944.11 | H26: =F26+D26+K26 -> 584084.68 | I26: =VLOOKUP($A26,[16]HISTOJANV22!$A$6:$AQ$37,22,0) -> 0 | J26: =VLOOKUP($A26,[16]HISTOJANV22!$A$6:$AU$39,45,0) -> 7000 | K26: =IF(J26=0,0,J26-(L26+M26+N26)) -> 3000 | L26: =IF(J26=0,0,500) -> 500 | M26: =IF(J26=0,0,1000) -> 1000 | N26: =IF(J26=0,0,2500) -> 2500 | O26: =VLOOKUP($A26,[16]HISTOJANV22!$A$6:$AU$39,7,0) -> 0 | P26: =VLOOKUP($A26,[16]HISTOJANV22!$A$6:$AU$39,23,0) -> 0 | Q26: =VLOOKUP($A26,[16]HISTOJANV22!$A$6:$AU$39,46,0) -> 0 | R26: =VLOOKUP($A26,[16]HISTODEC21!$A$6:$AU$39,26,0) -> 1155000 | S26: =R26*0/1200*12 -> 0 | T26: =VLOOKUP($A26,[16]HISTOJANV22!$A$6:$AU$39,28,0) -> 0 | U26: =VLOOKUP($A26,[16]HISTOJANV22!$A$6:$AU$39,19,0) -> 0 | V26: =VLOOKUP($A26,[16]HISTOJANV22!$A$6:$AU$39,20,0) -> 0 | W26: =VLOOKUP($A26,[16]HISTOJANV22!$A$6:$AU$39,27,0) -> BANQUE | X26: =VLOOKUP($A26,[16]HISTOJANV22!$A$6:$AU$39,33,0) -> 0 | Y26: 155000 | AA26: =VLOOKUP($A26,[16]HISTOJANV22!$A$6:$AU$39,43,0) -> 0 | AB26: =VLOOKUP($A26,[16]HISTOJANV22!$A$6:$AU$39,44,0) -> 0 | AC26: =VLOOKUP($A26,[16]HISTOJANV22!$A$6:$AU$39,47,0) -> 0 | AD26: =VLOOKUP(A26,[16]HISTOJANV22!$A$6:$BB$36,54,0) -> 0
A27: AS201614 | B27: =VLOOKUP(A27,[15]LISTADHERENT!A$5:H$60,3,0) -> NKEHE DAVID | C27: 534974.28 | D27: -5025.7225 | E27: =VLOOKUP($A27,[16]HISTOJANV22!$A$6:$BA$39,48,0) -> 0 | F27: =C27-E27 -> 534974.28 | G27: =$S$40/$H$40*H27 -> 40778.447 | H27: =F27+D27+K27 -> 529948.56 | I27: =VLOOKUP($A27,[16]HISTOJANV22!$A$6:$AQ$37,22,0) -> 0 | J27: =VLOOKUP($A27,[16]HISTOJANV22!$A$6:$AU$39,45,0) -> 0 | K27: =IF(J27=0,0,J27-(L27+M27+N27)) -> 0 | L27: =IF(J27=0,0,500) -> 0 | M27: =IF(J27=0,0,1000) -> 0 | N27: =IF(J27=0,0,2500) -> 0 | O27: =VLOOKUP($A27,[16]HISTOJANV22!$A$6:$AU$39,7,0) -> 0 | P27: =VLOOKUP($A27,[16]HISTOJANV22!$A$6:$AU$39,23,0) -> 0 | Q27: =VLOOKUP($A27,[16]HISTOJANV22!$A$6:$AU$39,46,0) -> 0 | R27: =VLOOKUP($A27,[16]HISTODEC21!$A$6:$AU$39,26,0) -> 1155000 | S27: =R27*12/1200*12 -> 138600 | T27: =VLOOKUP($A27,[16]HISTOJANV22!$A$6:$AU$39,28,0) -> 0 | U27: =VLOOKUP($A27,[16]HISTOJANV22!$A$6:$AU$39,19,0) -> 0 | V27: =VLOOKUP($A27,[16]HISTOJANV22!$A$6:$AU$39,20,0) -> 0 | W27: =VLOOKUP($A27,[16]HISTOJANV22!$A$6:$AU$39,27,0) -> BANQUE | X27: =VLOOKUP($A27,[16]HISTOJANV22!$A$6:$AU$39,33,0) -> 0 | AA27: =VLOOKUP($A27,[16]HISTOJANV22!$A$6:$AU$39,43,0) -> 0 | AB27: =VLOOKUP($A27,[16]HISTOJANV22!$A$6:$AU$39,44,0) -> 0 | AC27: =VLOOKUP($A27,[16]HISTOJANV22!$A$6:$AU$39,47,0) -> 0 | AD27: =VLOOKUP(A27,[16]HISTOJANV22!$A$6:$BB$36,54,0) -> 0
A28: AS201629 | B28: =VLOOKUP(A28,[15]LISTADHERENT!A$5:H$60,3,0) -> NKEPSEU DIEUDONNE | C28: 570000 | D28: 12062.781 | E28: =VLOOKUP($A28,[16]HISTOJANV22!$A$6:$BA$39,48,0) -> 0 | F28: =C28-E28 -> 570000 | G28: =$S$40/$H$40*H28 -> 45788.852 | H28: =F28+D28+K28 -> 595062.78 | I28: =VLOOKUP($A28,[16]HISTOJANV22!$A$6:$AQ$37,22,0) -> 0 | J28: =VLOOKUP($A28,[16]HISTOJANV22!$A$6:$AU$39,45,0) -> 17000 | K28: =IF(J28=0,0,J28-(L28+M28+N28)) -> 13000 | L28: =IF(J28=0,0,500) -> 500 | M28: =IF(J28=0,0,1000) -> 1000 | N28: =IF(J28=0,0,2500) -> 2500 | O28: =VLOOKUP($A28,[16]HISTOJANV22!$A$6:$AU$39,7,0) -> 0 | P28: =VLOOKUP($A28,[16]HISTOJANV22!$A$6:$AU$39,23,0) -> 0 | Q28: =VLOOKUP($A28,[16]HISTOJANV22!$A$6:$AU$39,46,0) -> 0 | R28: =VLOOKUP($A28,[16]HISTODEC21!$A$6:$AU$39,26,0) -> 1000000 | S28: =R28*12/1200*12 -> 120000 | T28: =VLOOKUP($A28,[16]HISTOJANV22!$A$6:$AU$39,28,0) -> OKK | U28: =VLOOKUP($A28,[16]HISTOJANV22!$A$6:$AU$39,19,0) -> 0 | V28: =VLOOKUP($A28,[16]HISTOJANV22!$A$6:$AU$39,20,0) -> 0 | W28: =VLOOKUP($A28,[16]HISTOJANV22!$A$6:$AU$39,27,0) -> BANQUE | X28: =VLOOKUP($A28,[16]HISTOJANV22!$A$6:$AU$39,33,0) -> 0 | AA28: =VLOOKUP($A28,[16]HISTOJANV22!$A$6:$AU$39,43,0) -> 0 | AB28: =VLOOKUP($A28,[16]HISTOJANV22!$A$6:$AU$39,44,0) -> 0 | AC28: =VLOOKUP($A28,[16]HISTOJANV22!$A$6:$AU$39,47,0) -> 0 | AD28: =VLOOKUP(A28,[16]HISTOJANV22!$A$6:$BB$36,54,0) -> 0
A29: AS201633 | B29: =VLOOKUP(A29,[15]LISTADHERENT!A$5:H$60,3,0) -> PATEGO NJOSSU GUSTAVE | C29: 570000 | D29: 21819.132 | E29: =VLOOKUP($A29,[16]HISTOJANV22!$A$6:$BA$39,48,0) -> 0 | F29: =C29-E29 -> 570000 | G29: =$S$40/$H$40*H29 -> 45770.104 | H29: =F29+D29+K29 -> 594819.13 | I29: =VLOOKUP($A29,[16]HISTOJANV22!$A$6:$AQ$37,22,0) -> 0 | J29: =VLOOKUP($A29,[16]HISTOJANV22!$A$6:$AU$39,45,0) -> 7000 | K29: =IF(J29=0,0,J29-(L29+M29+N29)) -> 3000 | L29: =IF(J29=0,0,500) -> 500 | M29: =IF(J29=0,0,1000) -> 1000 | N29: =IF(J29=0,0,2500) -> 2500 | O29: =VLOOKUP($A29,[16]HISTOJANV22!$A$6:$AU$39,7,0) -> 0 | P29: =VLOOKUP($A29,[16]HISTOJANV22!$A$6:$AU$39,23,0) -> 0 | Q29: =VLOOKUP($A29,[16]HISTOJANV22!$A$6:$AU$39,46,0) -> 0 | R29: =VLOOKUP($A29,[16]HISTODEC21!$A$6:$AU$39,26,0) -> 0 | S29: =R29*12/1200*12 -> 0 | T29: =VLOOKUP($A29,[16]HISTOJANV22!$A$6:$AU$39,28,0) -> 0 | U29: =VLOOKUP($A29,[16]HISTOJANV22!$A$6:$AU$39,19,0) -> 0 | V29: =VLOOKUP($A29,[16]HISTOJANV22!$A$6:$AU$39,20,0) -> 0 | W29: =VLOOKUP($A29,[16]HISTOJANV22!$A$6:$AU$39,27,0) -> 0 | X29: =VLOOKUP($A29,[16]HISTOJANV22!$A$6:$AU$39,33,0) -> 0 | AA29: =VLOOKUP($A29,[16]HISTOJANV22!$A$6:$AU$39,43,0) -> 0 | AB29: =VLOOKUP($A29,[16]HISTOJANV22!$A$6:$AU$39,44,0) -> 0 | AC29: =VLOOKUP($A29,[16]HISTOJANV22!$A$6:$AU$39,47,0) -> 0 | AD29: =VLOOKUP(A29,[16]HISTOJANV22!$A$6:$BB$36,54,0) -> 0
A30: AS201653 | B30: =VLOOKUP(A30,[15]LISTADHERENT!A$5:H$60,3,0) -> SIME BRICE | C30: 570000 | D30: 277025.73 | E30: =VLOOKUP($A30,[16]HISTOJANV22!$A$6:$BA$39,48,0) -> 0 | F30: =C30-E30 -> 570000 | G30: =$S$40/$H$40*H30 -> 65407.725 | H30: =F30+D30+K30 -> 850025.73 | I30: =VLOOKUP($A30,[16]HISTOJANV22!$A$6:$AQ$37,22,0) -> 0 | J30: =VLOOKUP($A30,[16]HISTOJANV22!$A$6:$AU$39,45,0) -> 7000 | K30: =IF(J30=0,0,J30-(L30+M30+N30)) -> 3000 | L30: =IF(J30=0,0,500) -> 500 | M30: =IF(J30=0,0,1000) -> 1000 | N30: =IF(J30=0,0,2500) -> 2500 | O30: =VLOOKUP($A30,[16]HISTOJANV22!$A$6:$AU$39,7,0) -> 0 | P30: =VLOOKUP($A30,[16]HISTOJANV22!$A$6:$AU$39,23,0) -> 0 | Q30: =VLOOKUP($A30,[16]HISTOJANV22!$A$6:$AU$39,46,0) -> 0 | R30: =VLOOKUP($A30,[16]HISTODEC21!$A$6:$AU$39,26,0) -> 0 | S30: =R30*12/1200*12 -> 0 | T30: =VLOOKUP($A30,[16]HISTOJANV22!$A$6:$AU$39,28,0) -> 0 | U30: =VLOOKUP($A30,[16]HISTOJANV22!$A$6:$AU$39,19,0) -> 0 | V30: =VLOOKUP($A30,[16]HISTOJANV22!$A$6:$AU$39,20,0) -> 0 | W30: =VLOOKUP($A30,[16]HISTOJANV22!$A$6:$AU$39,27,0) -> 0 | X30: =VLOOKUP($A30,[16]HISTOJANV22!$A$6:$AU$39,33,0) -> 0 | AA30: =VLOOKUP($A30,[16]HISTOJANV22!$A$6:$AU$39,43,0) -> 0 | AB30: =VLOOKUP($A30,[16]HISTOJANV22!$A$6:$AU$39,44,0) -> 0 | AC30: =VLOOKUP($A30,[16]HISTOJANV22!$A$6:$AU$39,47,0) -> 0 | AD30: =VLOOKUP(A30,[16]HISTOJANV22!$A$6:$BB$36,54,0) -> 0
A31: AS201636 | B31: =VLOOKUP(A31,[15]LISTADHERENT!A$5:H$60,3,0) -> SIMO FONGANG ERIC | C31: 570000 | D31: 23309.374 | E31: =VLOOKUP($A31,[16]HISTOJANV22!$A$6:$BA$39,48,0) -> 0 | F31: =C31-E31 -> 570000 | G31: =$S$40/$H$40*H31 -> 45653.931 | H31: =F31+D31+K31 -> 593309.37 | I31: =VLOOKUP($A31,[16]HISTOJANV22!$A$6:$AQ$37,22,0) -> 0 | J31: =VLOOKUP($A31,[16]HISTOJANV22!$A$6:$AU$39,45,0) -> 0 | K31: =IF(J31=0,0,J31-(L31+M31+N31)) -> 0 | L31: =IF(J31=0,0,500) -> 0 | M31: =IF(J31=0,0,1000) -> 0 | N31: =IF(J31=0,0,2500) -> 0 | O31: =VLOOKUP($A31,[16]HISTOJANV22!$A$6:$AU$39,7,0) -> 0 | P31: =VLOOKUP($A31,[16]HISTOJANV22!$A$6:$AU$39,23,0) -> 0 | Q31: =VLOOKUP($A31,[16]HISTOJANV22!$A$6:$AU$39,46,0) -> 0 | R31: =VLOOKUP($A31,[16]HISTODEC21!$A$6:$AU$39,26,0) -> 1166000 | S31: =R31*12/1200*12 -> 139920 | T31: =VLOOKUP($A31,[16]HISTOJANV22!$A$6:$AU$39,28,0) -> 0 | U31: =VLOOKUP($A31,[16]HISTOJANV22!$A$6:$AU$39,19,0) -> 0 | V31: =VLOOKUP($A31,[16]HISTOJANV22!$A$6:$AU$39,20,0) -> 0 | W31: =VLOOKUP($A31,[16]HISTOJANV22!$A$6:$AU$39,27,0) -> BANQUE | X31: =VLOOKUP($A31,[16]HISTOJANV22!$A$6:$AU$39,33,0) -> 0 | AA31: =VLOOKUP($A31,[16]HISTOJANV22!$A$6:$AU$39,43,0) -> 0 | AB31: =VLOOKUP($A31,[16]HISTOJANV22!$A$6:$AU$39,44,0) -> 0 | AC31: =VLOOKUP($A31,[16]HISTOJANV22!$A$6:$AU$39,47,0) -> 0 | AD31: =VLOOKUP(A31,[16]HISTOJANV22!$A$6:$BB$36,54,0) -> 0
A32: AS201638 | B32: =VLOOKUP(A32,[15]LISTADHERENT!A$5:H$60,3,0) -> SIMO PIERRE | C32: 570000 | D32: 38450.871 | E32: =VLOOKUP($A32,[16]HISTOJANV22!$A$6:$BA$39,48,0) -> 0 | F32: =C32-E32 -> 570000 | G32: =$S$40/$H$40*H32 -> 48204.101 | H32: =F32+D32+K32 -> 626450.87 | I32: =VLOOKUP($A32,[16]HISTOJANV22!$A$6:$AQ$37,22,0) -> 0 | J32: =VLOOKUP($A32,[16]HISTOJANV22!$A$6:$AU$39,45,0) -> 22000 | K32: =IF(J32=0,0,J32-(L32+M32+N32)) -> 18000 | L32: =IF(J32=0,0,500) -> 500 | M32: =IF(J32=0,0,1000) -> 1000 | N32: =IF(J32=0,0,2500) -> 2500 | O32: =VLOOKUP($A32,[16]HISTOJANV22!$A$6:$AU$39,7,0) -> 0 | P32: =VLOOKUP($A32,[16]HISTOJANV22!$A$6:$AU$39,23,0) -> 0 | Q32: =VLOOKUP($A32,[16]HISTOJANV22!$A$6:$AU$39,46,0) -> 0 | R32: =VLOOKUP($A32,[16]HISTODEC21!$A$6:$AU$39,26,0) -> 0 | S32: =R32*12/1200*12 -> 0 | T32: =VLOOKUP($A32,[16]HISTOJANV22!$A$6:$AU$39,28,0) -> 0 | U32: =VLOOKUP($A32,[16]HISTOJANV22!$A$6:$AU$39,19,0) -> 0 | V32: =VLOOKUP($A32,[16]HISTOJANV22!$A$6:$AU$39,20,0) -> 0 | W32: =VLOOKUP($A32,[16]HISTOJANV22!$A$6:$AU$39,27,0) -> BANQUE | X32: =VLOOKUP($A32,[16]HISTOJANV22!$A$6:$AU$39,33,0) -> 0 | AA32: =VLOOKUP($A32,[16]HISTOJANV22!$A$6:$AU$39,43,0) -> 0 | AB32: =VLOOKUP($A32,[16]HISTOJANV22!$A$6:$AU$39,44,0) -> 0 | AC32: =VLOOKUP($A32,[16]HISTOJANV22!$A$6:$AU$39,47,0) -> 0 | AD32: =VLOOKUP(A32,[16]HISTOJANV22!$A$6:$BB$36,54,0) -> 70000
A33: AS201641 | B33: =VLOOKUP(A33,[15]LISTADHERENT!A$5:H$60,3,0) -> TCHOUAMOU MATHIEU | C33: 570000 | D33: 6233.7835 | E33: =VLOOKUP($A33,[16]HISTOJANV22!$A$6:$BA$39,48,0) -> 0 | F33: =C33-E33 -> 570000 | G33: =$S$40/$H$40*H33 -> 44570.844 | H33: =F33+D33+K33 -> 579233.78 | I33: =VLOOKUP($A33,[16]HISTOJANV22!$A$6:$AQ$37,22,0) -> 0 | J33: =VLOOKUP($A33,[16]HISTOJANV22!$A$6:$AU$39,45,0) -> 7000 | K33: =IF(J33=0,0,J33-(L33+M33+N33)) -> 3000 | L33: =IF(J33=0,0,500) -> 500 | M33: =IF(J33=0,0,1000) -> 1000 | N33: =IF(J33=0,0,2500) -> 2500 | O33: =VLOOKUP($A33,[16]HISTOJANV22!$A$6:$AU$39,7,0) -> 0 | P33: =VLOOKUP($A33,[16]HISTOJANV22!$A$6:$AU$39,23,0) -> 0 | Q33: =VLOOKUP($A33,[16]HISTOJANV22!$A$6:$AU$39,46,0) -> 0 | R33: =VLOOKUP($A33,[16]HISTODEC21!$A$6:$AU$39,26,0) -> 560000 | S33: =R33*12/1200*12 -> 67200 | T33: =VLOOKUP($A33,[16]HISTOJANV22!$A$6:$AU$39,28,0) -> OKK | U33: =VLOOKUP($A33,[16]HISTOJANV22!$A$6:$AU$39,19,0) -> 0 | V33: =VLOOKUP($A33,[16]HISTOJANV22!$A$6:$AU$39,20,0) -> 0 | W33: =VLOOKUP($A33,[16]HISTOJANV22!$A$6:$AU$39,27,0) -> BANQUE | X33: =VLOOKUP($A33,[16]HISTOJANV22!$A$6:$AU$39,33,0) -> 0 | AA33: =VLOOKUP($A33,[16]HISTOJANV22!$A$6:$AU$39,43,0) -> 0 | AB33: =VLOOKUP($A33,[16]HISTOJANV22!$A$6:$AU$39,44,0) -> 0 | AC33: =VLOOKUP($A33,[16]HISTOJANV22!$A$6:$AU$39,47,0) -> 0 | AD33: =VLOOKUP(A33,[16]HISTOJANV22!$A$6:$BB$36,54,0) -> 0
A34: AS201644 | B34: =VLOOKUP(A34,[15]LISTADHERENT!A$5:H$60,3,0) -> TIEYAM ERNEST | C34: 535508.28 | D34: -4491.7217 | E34: =VLOOKUP($A34,[16]HISTOJANV22!$A$6:$BA$39,48,0) -> 0 | F34: =C34-E34 -> 535508.28 | G34: =$S$40/$H$40*H34 -> 40860.628 | H34: =F34+D34+K34 -> 531016.56 | I34: =VLOOKUP($A34,[16]HISTOJANV22!$A$6:$AQ$37,22,0) -> 0 | J34: =VLOOKUP($A34,[16]HISTOJANV22!$A$6:$AU$39,45,0) -> 0 | K34: =IF(J34=0,0,J34-(L34+M34+N34)) -> 0 | L34: =IF(J34=0,0,500) -> 0 | M34: =IF(J34=0,0,1000) -> 0 | N34: =IF(J34=0,0,2500) -> 0 | O34: =VLOOKUP($A34,[16]HISTOJANV22!$A$6:$AU$39,7,0) -> 0 | P34: =VLOOKUP($A34,[16]HISTOJANV22!$A$6:$AU$39,23,0) -> 0 | Q34: =VLOOKUP($A34,[16]HISTOJANV22!$A$6:$AU$39,46,0) -> 0 | R34: =VLOOKUP($A34,[16]HISTODEC21!$A$6:$AU$39,26,0) -> 1112500 | S34: =R34*12/1200*12 -> 133500 | T34: =VLOOKUP($A34,[16]HISTOJANV22!$A$6:$AU$39,28,0) -> 0 | U34: =VLOOKUP($A34,[16]HISTOJANV22!$A$6:$AU$39,19,0) -> 0 | V34: =VLOOKUP($A34,[16]HISTOJANV22!$A$6:$AU$39,20,0) -> 0 | W34: =VLOOKUP($A34,[16]HISTOJANV22!$A$6:$AU$39,27,0) -> BANQUE | X34: =VLOOKUP($A34,[16]HISTOJANV22!$A$6:$AU$39,33,0) -> 0 | AA34: =VLOOKUP($A34,[16]HISTOJANV22!$A$6:$AU$39,43,0) -> 0 | AB34: =VLOOKUP($A34,[16]HISTOJANV22!$A$6:$AU$39,44,0) -> 0 | AC34: =VLOOKUP($A34,[16]HISTOJANV22!$A$6:$AU$39,47,0) -> 0 | AD34: =VLOOKUP(A34,[16]HISTOJANV22!$A$6:$BB$36,54,0) -> 0
A35: AS201646 | B35: =VLOOKUP(A35,[15]LISTADHERENT!A$5:H$60,3,0) -> YEPMOU JEAN JACQUES | C35: 570000 | D35: 811081.3 | E35: =VLOOKUP($A35,[16]HISTOJANV22!$A$6:$BA$39,48,0) -> 0 | F35: =C35-E35 -> 570000 | G35: =$S$40/$H$40*H35 -> 106502.2 | H35: =F35+D35+K35 -> 1384081.3 | I35: =VLOOKUP($A35,[16]HISTOJANV22!$A$6:$AQ$37,22,0) -> 0 | J35: =VLOOKUP($A35,[16]HISTOJANV22!$A$6:$AU$39,45,0) -> 7000 | K35: =IF(J35=0,0,J35-(L35+M35+N35)) -> 3000 | L35: =IF(J35=0,0,500) -> 500 | M35: =IF(J35=0,0,1000) -> 1000 | N35: =IF(J35=0,0,2500) -> 2500 | O35: =VLOOKUP($A35,[16]HISTOJANV22!$A$6:$AU$39,7,0) -> 3000 | P35: =VLOOKUP($A35,[16]HISTOJANV22!$A$6:$AU$39,23,0) -> 0 | Q35: =VLOOKUP($A35,[16]HISTOJANV22!$A$6:$AU$39,46,0) -> 0 | R35: =VLOOKUP($A35,[16]HISTODEC21!$A$6:$AU$39,26,0) -> 1155000 | S35: =R35*0/1200*12 -> 0 | T35: =VLOOKUP($A35,[16]HISTOJANV22!$A$6:$AU$39,28,0) -> 0 | U35: =VLOOKUP($A35,[16]HISTOJANV22!$A$6:$AU$39,19,0) -> 0 | V35: =VLOOKUP($A35,[16]HISTOJANV22!$A$6:$AU$39,20,0) -> 0 | W35: =VLOOKUP($A35,[16]HISTOJANV22!$A$6:$AU$39,27,0) -> BANQUE | X35: =VLOOKUP($A35,[16]HISTOJANV22!$A$6:$AU$39,33,0) -> 0 | Y35: 155000 | AA35: =VLOOKUP($A35,[16]HISTOJANV22!$A$6:$AU$39,43,0) -> 0 | AB35: =VLOOKUP($A35,[16]HISTOJANV22!$A$6:$AU$39,44,0) -> 0 | AC35: =VLOOKUP($A35,[16]HISTOJANV22!$A$6:$AU$39,47,0) -> 0 | AD35: =VLOOKUP(A35,[16]HISTOJANV22!$A$6:$BB$36,54,0) -> 0
A36: AS201647 | B36: =VLOOKUP(A36,[15]LISTADHERENT!A$5:H$60,3,0) -> YOUMBI EMMANUEL | C36: 570000 | D36: 913245.29 | E36: =VLOOKUP($A36,[16]HISTOJANV22!$A$6:$BA$39,48,0) -> 0 | F36: =C36-E36 -> 570000 | G36: =$S$40/$H$40*H36 -> 114363.51 | H36: =F36+D36+K36 -> 1486245.3 | I36: =VLOOKUP($A36,[16]HISTOJANV22!$A$6:$AQ$37,22,0) -> 0 | J36: =VLOOKUP($A36,[16]HISTOJANV22!$A$6:$AU$39,45,0) -> 7000 | K36: =IF(J36=0,0,J36-(L36+M36+N36)) -> 3000 | L36: =IF(J36=0,0,500) -> 500 | M36: =IF(J36=0,0,1000) -> 1000 | N36: =IF(J36=0,0,2500) -> 2500 | O36: =VLOOKUP($A36,[16]HISTOJANV22!$A$6:$AU$39,7,0) -> 0 | P36: =VLOOKUP($A36,[16]HISTOJANV22!$A$6:$AU$39,23,0) -> 0 | Q36: =VLOOKUP($A36,[16]HISTOJANV22!$A$6:$AU$39,46,0) -> 0 | R36: =VLOOKUP($A36,[16]HISTODEC21!$A$6:$AU$39,26,0) -> 0 | S36: =R36*12/1200*12 -> 0 | T36: =VLOOKUP($A36,[16]HISTOJANV22!$A$6:$AU$39,28,0) -> 0 | U36: =VLOOKUP($A36,[16]HISTOJANV22!$A$6:$AU$39,19,0) -> 0 | V36: =VLOOKUP($A36,[16]HISTOJANV22!$A$6:$AU$39,20,0) -> 0 | W36: =VLOOKUP($A36,[16]HISTOJANV22!$A$6:$AU$39,27,0) -> 0 | X36: =VLOOKUP($A36,[16]HISTOJANV22!$A$6:$AU$39,33,0) -> 0 | AA36: =VLOOKUP($A36,[16]HISTOJANV22!$A$6:$AU$39,43,0) -> 0 | AB36: =VLOOKUP($A36,[16]HISTOJANV22!$A$6:$AU$39,44,0) -> 0 | AC36: =VLOOKUP($A36,[16]HISTOJANV22!$A$6:$AU$39,47,0) -> 0 | AD36: =VLOOKUP(A36,[16]HISTOJANV22!$A$6:$BB$36,54,0) -> 70000
A40: TOTAL | C40: =SUM(C6:C39) -> 17584660 | D40: =SUM(D6:D39) -> 2752018 | E40: =SUM(E6:E39) -> 0 | F40: =SUM(F6:F39) -> 17584660 | G40: =SUM(G6:G39) -> 1581640 | H40: =SUM(H6:H39) -> 20554678 | I40: =SUM(I6:I39) -> 0 | J40: =SUM(J6:J39) -> 322000 | ... AE40: =SUM(AE6:AE39) -> 0

Sheet MVTJANV22
A1: ASSOCIATION | B1: ASELBY | G1: K
A2: ANNEE | B2: 2022
A3: TONTINE
J4: 44578
A5: MATRICULE | B5: NOM ET PRENOM | C5: FONDES DE DEPART | D5: RELIQUAT | E5: RETRAIT PARTIEL | F5: FONDS DEFINITIF | G5: REPARTITION INTERET | H5: CAPITAL COMPOSE | I5: SANCTION | J5: RESTE | K5: EPARGNE | L5: FONDS DE ROULEMENT | M5: FRAIS EXCEPTIONNEL | N5: COLLATION | O5: PENALITE VST ESPECES | P5: INSCRISPTION | Q5: MUTUELLE | R5: PRÊT FONDS | S5: INTERETPRET FONDS | T5: NUMERO CHEQUE | U5: REMBOURSEMENTPRET FONDS | V5: MODE VERSEMENT REMBOURSEMENT | W5: MODE VERSEMENT PRÊT | X5: NUMERO CHEQUE | Y5: PENALITE PRET FONDS | Z5: PENALITE FONDS | AA5: PENALITE ECHEC TONTINE | AB5: PENALITE RETARD TONTINE | AC5: REMBOURSEMENT TRANSPORT | AD5: CONTRIBUTION FOYER | AE5: FONDS DE ROULEMENT | AF5: FRAIS EXCEPTIONNEL | AG5: FONDS MUTUELLE | AH5: COLLATION RECEPTION | AI5: PENALITE PRET FONDS | AJ5: DEPENSE PENALITE VERSEMENT BANQUE
A6: AS201648 | B6: =VLOOKUP(A6,[15]LISTADHERENT!A$5:H$60,3,0) -> ASELBY | C6: 584177.01 | F6: =C6-E6 -> 584177.01 | G6: =$S$40/$H$40*H6 -> 34046.887 | H6: =F6+D6+K6-E6 -> 584177.01 | AE6: =VLOOKUP($A6,[16]HISTOJANV22!$A$6:$CA$36,60,0) -> 51000 | AF6: =VLOOKUP($A6,[16]HISTOJANV22!$A$6:$CA$36,61,0) -> 0 | AG6: =VLOOKUP($A6,[16]HISTOJANV22!$A$6:$CA$36,62,0) -> 0 | AH6: =VLOOKUP($A6,[16]HISTOJANV22!$A$6:$CA$36,63,0) -> 70000 | AI6: =VLOOKUP($A6,[16]HISTOJANV22!$A$6:$CA$36,64,0) -> 0 | AJ6: =VLOOKUP($A6,[16]HISTOJANV22!$A$6:$CA$36,65,0) -> 450000
A7: AS201602 | B7: =VLOOKUP(A7,[15]LISTADHERENT!A$5:H$60,3,0) -> BOUTCHOUANG WILLIAM | C7: 570000 | D7: -258.93851 | E7: =VLOOKUP($A7,[16]HISTOJANV22!$A$6:$BA$39,48,0) -> 0 | F7: =C7-E7 -> 570000 | G7: =$S$40/$H$40*H7 -> 33380.379 | H7: =F7+D7+K7-E7 -> 572741.06 | I7: =VLOOKUP($A7,[16]HISTOJANV22!$A$6:$AQ$37,22,0) -> 0 | J7: =VLOOKUP($A7,[16]HISTOJANV22!$A$6:$AU$39,45,0) -> 7000 | K7: =IF(J7=0,0,J7-(L7+M7+N7)) -> 3000 | L7: =IF(J7=0,0,500) -> 500 | M7: =IF(J7=0,0,1000) -> 1000 | N7: =IF(J7=0,0,2500) -> 2500 | O7: =VLOOKUP($A7,[16]HISTOJANV22!$A$6:$AU$39,7,0) -> 0 | P7: =VLOOKUP($A7,[16]HISTOJANV22!$A$6:$AU$39,23,0) -> 0 | Q7: =VLOOKUP($A7,[16]HISTOJANV22!$A$6:$AU$39,46,0) -> 0 | R7: =VLOOKUP($A7,[16]HISTOJANV22!$A$6:$AU$39,26,0) -> 0 | S7: =VLOOKUP($A7,[16]HISTOJANV22!$A$6:$BG$39,58,0) -> 0 | T7: =VLOOKUP($A7,[16]HISTOJANV22!$A$6:$AU$39,28,0) -> 0 | U7: =VLOOKUP($A7,[16]HISTOJANV22!$A$6:$AU$39,19,0) -> 0 | V7: =VLOOKUP($A7,[16]HISTOJANV22!$A$6:$AU$39,20,0) -> 0 | W7: =VLOOKUP($A7,[16]HISTOJANV22!$A$6:$AU$39,27,0) -> 0 | X7: =VLOOKUP($A7,[16]HISTOJANV22!$A$6:$BM$39,33,0) -> 0 | Y7: =VLOOKUP($A7,[16]HISTOJANV22!$A$6:$BM$39,65,0) -> 0 | AA7: =VLOOKUP($A7,[16]HISTOJANV22!$A$6:$AU$39,43,0) -> 0 | AB7: =VLOOKUP($A7,[16]HISTOJANV22!$A$6:$AU$39,44,0) -> 0 | AC7: =VLOOKUP($A7,[16]HISTOJANV22!$A$6:$AU$39,47,0) -> 0 | AD7: =VLOOKUP(A7,[16]HISTOJANV22!$A$6:$BB$36,54,0) -> 0 | AE7: =VLOOKUP($A7,[16]HISTOJANV22!$A$6:$CA$36,60,0) -> 0 | AF7: =VLOOKUP($A7,[16]HISTOJANV22!$A$6:$CA$36,61,0) -> 0 | AG7: =VLOOKUP($A7,[16]HISTOJANV22!$A$6:$CA$36,62,0) -> 0 | AH7: =VLOOKUP($A7,[16]HISTOJANV22!$A$6:$CA$36,63,0) -> 0 | AI7: =VLOOKUP($A7,[16]HISTOJANV22!$A$6:$CA$36,64,0) -> 25000 | AJ7: =VLOOKUP($A7,[16]HISTOJANV22!$A$6:$CA$36,65,0) -> 0
A8: AS201604 | B8: =VLOOKUP(A8,[15]LISTADHERENT!A$5:H$60,3,0) -> DJOMO JEAN PAUL | C8: 570000 | D8: 1714.0012 | E8: =VLOOKUP($A8,[16]HISTOJANV22!$A$6:$BA$39,48,0) -> 0 | F8: =C8-E8 -> 570000 | G8: =$S$40/$H$40*H8 -> 36118.047 | H8: =F8+D8+K8-E8 -> 619714 | I8: =VLOOKUP($A8,[16]HISTOJANV22!$A$6:$AQ$37,22,0) -> 0 | J8: =VLOOKUP($A8,[16]HISTOJANV22!$A$6:$AU$39,45,0) -> 52000 | K8: =IF(J8=0,0,J8-(L8+M8+N8)) -> 48000 | L8: =IF(J8=0,0,500) -> 500 | M8: =IF(J8=0,0,1000) -> 1000 | N8: =IF(J8=0,0,2500) -> 2500 | O8: =VLOOKUP($A8,[16]HISTOJANV22!$A$6:$AU$39,7,0) -> 0 | P8: =VLOOKUP($A8,[16]HISTOJANV22!$A$6:$AU$39,23,0) -> 0 | Q8: =VLOOKUP($A8,[16]HISTOJANV22!$A$6:$AU$39,46,0) -> 0 | R8: =VLOOKUP($A8,[16]HISTOJANV22!$A$6:$AU$39,26,0) -> 1000000 | S8: =VLOOKUP($A8,[16]HISTOJANV22!$A$6:$BG$39,58,0) -> 120000 | T8: =VLOOKUP($A8,[16]HISTOJANV22!$A$6:$AU$39,28,0) -> OKK | U8: =VLOOKUP($A8,[16]HISTOJANV22!$A$6:$AU$39,19,0) -> 0 | V8: =VLOOKUP($A8,[16]HISTOJANV22!$A$6:$AU$39,20,0) -> 0 | W8: =VLOOKUP($A8,[16]HISTOJANV22!$A$6:$AU$39,27,0) -> BANQUE | X8: =VLOOKUP($A8,[16]HISTOJANV22!$A$6:$AU$39,33,0) -> 0 | Y8: =VLOOKUP($A8,[16]HISTOJANV22!$A$6:$BM$39,65,0) -> 0 | AA8: =VLOOKUP($A8,[16]HISTOJANV22!$A$6:$AU$39,43,0) -> 0 | AB8: =VLOOKUP($A8,[16]HISTOJANV22!$A$6:$AU$39,44,0) -> 0 | AC8: =VLOOKUP($A8,[16]HISTOJANV22!$A$6:$AU$39,47,0) -> 0 | AD8: =VLOOKUP(A8,[16]HISTOJANV22!$A$6:$BB$36,54,0) -> 0 | AE8: =VLOOKUP($A8,[16]HISTOJANV22!$A$6:$CA$36,60,0) -> 0 | AF8: =VLOOKUP($A8,[16]HISTOJANV22!$A$6:$CA$36,61,0) -> 0 | AG8: =VLOOKUP($A8,[16]HISTOJANV22!$A$6:$CA$36,62,0) -> 0 | AH8: =VLOOKUP($A8,[16]HISTOJANV22!$A$6:$CA$36,63,0) -> 0 | AI8: =VLOOKUP($A8,[16]HISTOJANV22!$A$6:$CA$36,64,0) -> 0 | AJ8: =VLOOKUP($A8,[16]HISTOJANV22!$A$6:$CA$36,65,0) -> 0
A9: AS201654 | B9: =VLOOKUP(A9,[15]LISTADHERENT!A$5:H$60,3,0) -> DJOMOU TCHANDA | C9: 570000 | D9: 359 | E9: =VLOOKUP($A9,[16]HISTOJANV22!$A$6:$BA$39,48,0) -> 0 | F9: =C9-E9 -> 570000 | G9: =$S$40/$H$40*H9 -> 33416.394 | H9: =F9+D9+K9-E9 -> 573359 | I9: =VLOOKUP($A9,[16]HISTOJANV22!$A$6:$AQ$37,22,0) -> 0 | J9: =VLOOKUP($A9,[16]HISTOJANV22!$A$6:$AU$39,45,0) -> 7000 | K9: =IF(J9=0,0,J9-(L9+M9+N9)) -> 3000 | L9: =IF(J9=0,0,500) -> 500 | M9: =IF(J9=0,0,1000) -> 1000 | N9: =IF(J9=0,0,2500) -> 2500 | O9: =VLOOKUP($A9,[16]HISTOJANV22!$A$6:$AU$39,7,0) -> 0 | P9: =VLOOKUP($A9,[16]HISTOJANV22!$A$6:$AU$39,23,0) -> 0 | Q9: =VLOOKUP($A9,[16]HISTOJANV22!$A$6:$AU$39,46,0) -> 0 | R9: =VLOOKUP($A9,[16]HISTOJANV22!$A$6:$AU$39,26,0) -> 0 | S9: =VLOOKUP($A9,[16]HISTOJANV22!$A$6:$BG$39,58,0) -> 0 | T9: =VLOOKUP($A9,[16]HISTOJANV22!$A$6:$AU$39,28,0) -> 0 | U9: =VLOOKUP($A9,[16]HISTOJANV22!$A$6:$AU$39,19,0) -> 0 | V9: =VLOOKUP($A9,[16]HISTOJANV22!$A$6:$AU$39,20,0) -> 0 | W9: =VLOOKUP($A9,[16]HISTOJANV22!$A$6:$AU$39,27,0) -> 0 | X9: =VLOOKUP($A9,[16]HISTOJANV22!$A$6:$AU$39,33,0) -> 0 | Y9: =VLOOKUP($A9,[16]HISTOJANV22!$A$6:$BM$39,65,0) -> 0 | AA9: =VLOOKUP($A9,[16]HISTOJANV22!$A$6:$AU$39,43,0) -> 0 | AB9: =VLOOKUP($A9,[16]HISTOJANV22!$A$6:$AU$39,44,0) -> 0 | AC9: =VLOOKUP($A9,[16]HISTOJANV22!$A$6:$AU$39,47,0) -> 0 | AD9: =VLOOKUP(A9,[16]HISTOJANV22!$A$6:$BB$36,54,0) -> 0 | AE9: =VLOOKUP($A9,[16]HISTOJANV22!$A$6:$CA$36,60,0) -> 0 | AF9: =VLOOKUP($A9,[16]HISTOJANV22!$A$6:$CA$36,61,0) -> 0 | AG9: =VLOOKUP($A9,[16]HISTOJANV22!$A$6:$CA$36,62,0) -> 0 | AH9: =VLOOKUP($A9,[16]HISTOJANV22!$A$6:$CA$36,63,0) -> 0 | AI9: =VLOOKUP($A9,[16]HISTOJANV22!$A$6:$CA$36,64,0) -> 0 | AJ9: =VLOOKUP($A9,[16]HISTOJANV22!$A$6:$CA$36,65,0) -> 0
A10: AS201605 | B10: =VLOOKUP(A10,[15]LISTADHERENT!A$5:H$60,3,0) -> DJOUKWE NANGUEN GUY BLAISE | C10: 570000 | D10: 110412.64 | E10: =VLOOKUP($A10,[16]HISTOJANV22!$A$6:$BA$39,48,0) -> 0 | F10: =C10-E10 -> 570000 | G10: =$S$40/$H$40*H10 -> 40121.927 | H10: =F10+D10+K10-E10 -> 688412.64 | I10: =VLOOKUP($A10,[16]HISTOJANV22!$A$6:$AQ$37,22,0) -> 0 | J10: =VLOOKUP($A10,[16]HISTOJANV22!$A$6:$AU$39,45,0) -> 12000 | K10: =IF(J10=0,0,J10-(L10+M10+N10)) -> 8000 | L10: =IF(J10=0,0,500) -> 500 | M10: =IF(J10=0,0,1000) -> 1000 | N10: =IF(J10=0,0,2500) -> 2500 | O10: =VLOOKUP($A10,[16]HISTOJANV22!$A$6:$AU$39,7,0) -> 0 | P10: =VLOOKUP($A10,[16]HISTOJANV22!$A$6:$AU$39,23,0) -> 0 | Q10: =VLOOKUP($A10,[16]HISTOJANV22!$A$6:$AU$39,46,0) -> 0 | R10: =VLOOKUP($A10,[16]HISTOJANV22!$A$6:$AU$39,26,0) -> 1000000 | S10: =VLOOKUP($A10,[16]HISTOJANV22!$A$6:$BG$39,58,0) -> 120000 | T10: =VLOOKUP($A10,[16]HISTOJANV22!$A$6:$AU$39,28,0) -> OKK | U10: =VLOOKUP($A10,[16]HISTOJANV22!$A$6:$AU$39,19,0) -> 0 | V10: =VLOOKUP($A10,[16]HISTOJANV22!$A$6:$AU$39,20,0) -> 0 | W10: =VLOOKUP($A10,[16]HISTOJANV22!$A$6:$AU$39,27,0) -> BANQUE | X10: =VLOOKUP($A10,[16]HISTOJANV22!$A$6:$AU$39,33,0) -> 0 | Y10: =VLOOKUP($A10,[16]HISTOJANV22!$A$6:$BM$39,65,0) -> 0 | AA10: =VLOOKUP($A10,[16]HISTOJANV22!$A$6:$AU$39,43,0) -> 0 | AB10: =VLOOKUP($A10,[16]HISTOJANV22!$A$6:$AU$39,44,0) -> 0 | AC10: =VLOOKUP($A10,[16]HISTOJANV22!$A$6:$AU$39,47,0) -> 0 | AD10: =VLOOKUP(A10,[16]HISTOJANV22!$A$6:$BB$36,54,0) -> 0 | AE10: =VLOOKUP($A10,[16]HISTOJANV22!$A$6:$CA$36,60,0) -> 0 | AF10: =VLOOKUP($A10,[16]HISTOJANV22!$A$6:$CA$36,61,0) -> 0 | AG10: =VLOOKUP($A10,[16]HISTOJANV22!$A$6:$CA$36,62,0) -> 0 | AH10: =VLOOKUP($A10,[16]HISTOJANV22!$A$6:$CA$36,63,0) -> 0 | AI10: =VLOOKUP($A10,[16]HISTOJANV22!$A$6:$CA$36,64,0) -> 0 | AJ10: =VLOOKUP($A10,[16]HISTOJANV22!$A$6:$CA$36,65,0) -> 0
A11: AS201608 | B11: =VLOOKUP(A11,[15]LISTADHERENT!A$5:H$60,3,0) -> DJUOMBESSY ANTOINE | C11: 570000 | D11: 18508.85 | E11: =VLOOKUP($A11,[16]HISTOJANV22!$A$6:$BA$39,48,0) -> 0 | F11: =C11-E11 -> 570000 | G11: =$S$40/$H$40*H11 -> 34474.2 | H11: =F11+D11+K11-E11 -> 591508.85 | I11: =VLOOKUP($A11,[16]HISTOJANV22!$A$6:$AQ$37,22,0) -> 0 | J11: =VLOOKUP($A11,[16]HISTOJANV22!$A$6:$AU$39,45,0) -> 7000 | K11: =IF(J11=0,0,J11-(L11+M11+N11)) -> 3000 | L11: =IF(J11=0,0,500) -> 500 | M11: =IF(J11=0,0,1000) -> 1000 | N11: =IF(J11=0,0,2500) -> 2500 | O11: =VLOOKUP($A11,[16]HISTOJANV22!$A$6:$AU$39,7,0) -> 0 | P11: =VLOOKUP($A11,[16]HISTOJANV22!$A$6:$AU$39,23,0) -> 0 | Q11: =VLOOKUP($A11,[16]HISTOJANV22!$A$6:$AU$39,46,0) -> 0 | R11: =VLOOKUP($A11,[16]HISTOJANV22!$A$6:$AU$39,26,0) -> 0 | S11: =VLOOKUP($A11,[16]HISTOJANV22!$A$6:$BG$39,58,0) -> 0 | T11: =VLOOKUP($A11,[16]HISTOJANV22!$A$6:$AU$39,28,0) -> 0 | U11: =VLOOKUP($A11,[16]HISTOJANV22!$A$6:$AU$39,19,0) -> 1000000 | V11: =VLOOKUP($A11,[16]HISTOJANV22!$A$6:$AU$39,20,0) -> BANQUE | W11: =VLOOKUP($A11,[16]HISTOJANV22!$A$6:$AU$39,27,0) -> 0 | X11: =VLOOKUP($A11,[16]HISTOJANV22!$A$6:$AU$39,33,0) -> 0 | Y11: =VLOOKUP($A11,[16]HISTOJANV22!$A$6:$BM$39,65,0) -> 0 | AA11: =VLOOKUP($A11,[16]HISTOJANV22!$A$6:$AU$39,43,0) -> 0 | AB11: =VLOOKUP($A11,[16]HISTOJANV22!$A$6:$AU$39,44,0) -> 0 | AC11: =VLOOKUP($A11,[16]HISTOJANV22!$A$6:$AU$39,47,0) -> 0 | AD11: =VLOOKUP(A11,[16]HISTOJANV22!$A$6:$BB$36,54,0) -> 61000 | AE11: =VLOOKUP($A11,[16]HISTOJANV22!$A$6:$CA$36,60,0) -> 0 | AF11: =VLOOKUP($A11,[16]HISTOJANV22!$A$6:$CA$36,61,0) -> 0 | AG11: =VLOOKUP($A11,[16]HISTOJANV22!$A$6:$CA$36,62,0) -> 0 | AH11: =VLOOKUP($A11,[16]HISTOJANV22!$A$6:$CA$36,63,0) -> 0 | AI11: =VLOOKUP($A11,[16]HISTOJANV22!$A$6:$CA$36,64,0) -> 49000 | AJ11: =VLOOKUP($A11,[16]HISTOJANV22!$A$6:$CA$36,65,0) -> 0
A12: AS201651 | B12: =VLOOKUP(A12,[15]LISTADHERENT!A$5:H$60,3,0) -> DOMOU FABIEN | C12: 570000 | D12: 6527.0543 | E12: =VLOOKUP($A12,[16]HISTOJANV22!$A$6:$BA$39,48,0) -> 0 | F12: =C12-E12 -> 570000 | G12: =$S$40/$H$40*H12 -> 34067.288 | H12: =F12+D12+K12-E12 -> 584527.05 | I12: =VLOOKUP($A12,[16]HISTOJANV22!$A$6:$AQ$37,22,0) -> 0 | J12: =VLOOKUP($A12,[16]HISTOJANV22!$A$6:$AU$39,45,0) -> 12000 | K12: =IF(J12=0,0,J12-(L12+M12+N12)) -> 8000 | L12: =IF(J12=0,0,500) -> 500 | M12: =IF(J12=0,0,1000) -> 1000 | N12: =IF(J12=0,0,2500) -> 2500 | O12: =VLOOKUP($A12,[16]HISTOJANV22!$A$6:$AU$39,7,0) -> 0 | P12: =VLOOKUP($A12,[16]HISTOJANV22!$A$6:$AU$39,23,0) -> 0 | Q12: =VLOOKUP($A12,[16]HISTOJANV22!$A$6:$AU$39,46,0) -> 0 | R12: =VLOOKUP($A12,[16]HISTOJANV22!$A$6:$AU$39,26,0) -> 1000000 | S12: =VLOOKUP($A12,[16]HISTOJANV22!$A$6:$BG$39,58,0) -> 120000 | T12: =VLOOKUP($A12,[16]HISTOJANV22!$A$6:$AU$39,28,0) -> OKK | U12: =VLOOKUP($A12,[16]HISTOJANV22!$A$6:$AU$39,19,0) -> 0 | V12: =VLOOKUP($A12,[16]HISTOJANV22!$A$6:$AU$39,20,0) -> 0 | W12: =VLOOKUP($A12,[16]HISTOJANV22!$A$6:$AU$39,27,0) -> BANQUE | X12: =VLOOKUP($A12,[16]HISTOJANV22!$A$6:$AU$39,33,0) -> 0 | Y12: =VLOOKUP($A12,[16]HISTOJANV22!$A$6:$BM$39,65,0) -> 0 | AA12: =VLOOKUP($A12,[16]HISTOJANV22!$A$6:$AU$39,43,0) -> 0 | AB12: =VLOOKUP($A12,[16]HISTOJANV22!$A$6:$AU$39,44,0) -> 0 | AC12: =VLOOKUP($A12,[16]HISTOJANV22!$A$6:$AU$39,47,0) -> 0 | AD12: =VLOOKUP(A12,[16]HISTOJANV22!$A$6:$BB$36,54,0) -> 57000 | AE12: =VLOOKUP($A12,[16]HISTOJANV22!$A$6:$CA$36,60,0) -> 0 | AF12: =VLOOKUP($A12,[16]HISTOJANV22!$A$6:$CA$36,61,0) -> 0 | AG12: =VLOOKUP($A12,[16]HISTOJANV22!$A$6:$CA$36,62,0) -> 0 | AH12: =VLOOKUP($A12,[16]HISTOJANV22!$A$6:$CA$36,63,0) -> 0 | AI12: =VLOOKUP($A12,[16]HISTOJANV22!$A$6:$CA$36,64,0) -> 0 | AJ12: =VLOOKUP($A12,[16]HISTOJANV22!$A$6:$CA$36,65,0) -> 0
A13: AS201609 | B13: =VLOOKUP(A13,[15]LISTADHERENT!A$5:H$60,3,0) -> DONHOU DAVID | C13: 570000 | D13: 253289.51 | E13: =VLOOKUP($A13,[16]HISTOJANV22!$A$6:$BA$39,48,0) -> 0 | F13: =C13-E13 -> 570000 | G13: =$S$40/$H$40*H13 -> 48157.638 | H13: =F13+D13+K13-E13 -> 826289.51 | I13: =VLOOKUP($A13,[16]HISTOJANV22!$A$6:$AQ$37,22,0) -> 0 | J13: =VLOOKUP($A13,[16]HISTOJANV22!$A$6:$AU$39,45,0) -> 7000 | K13: =IF(J13=0,0,J13-(L13+M13+N13)) -> 3000 | L13: =IF(J13=0,0,500) -> 500 | M13: =IF(J13=0,0,1000) -> 1000 | N13: =IF(J13=0,0,2500) -> 2500 | O13: =VLOOKUP($A13,[16]HISTOJANV22!$A$6:$AU$39,7,0) -> 0 | P13: =VLOOKUP($A13,[16]HISTOJANV22!$A$6:$AU$39,23,0) -> 0 | Q13: =VLOOKUP($A13,[16]HISTOJANV22!$A$6:$AU$39,46,0) -> 0 | R13: =VLOOKUP($A13,[16]HISTOJANV22!$A$6:$AU$39,26,0) -> 0 | S13: =VLOOKUP($A13,[16]HISTOJANV22!$A$6:$BG$39,58,0) -> 0 | T13: =VLOOKUP($A13,[16]HISTOJANV22!$A$6:$AU$39,28,0) -> 0 | U13: =VLOOKUP($A13,[16]HISTOJANV22!$A$6:$AU$39,19,0) -> 0 | V13: =VLOOKUP($A13,[16]HISTOJANV22!$A$6:$AU$39,20,0) -> 0 | W13: =VLOOKUP($A13,[16]HISTOJANV22!$A$6:$AU$39,27,0) -> 0 | X13: =VLOOKUP($A13,[16]HISTOJANV22!$A$6:$AU$39,33,0) -> 0 | Y13: =VLOOKUP($A13,[16]HISTOJANV22!$A$6:$BM$39,65,0) -> 0 | AA13: =VLOOKUP($A13,[16]HISTOJANV22!$A$6:$AU$39,43,0) -> 0 | AB13: =VLOOKUP($A13,[16]HISTOJANV22!$A$6:$AU$39,44,0) -> 0 | AC13: =VLOOKUP($A13,[16]HISTOJANV22!$A$6:$AU$39,47,0) -> 0 | AD13: =VLOOKUP(A13,[16]HISTOJANV22!$A$6:$BB$36,54,0) -> 70000 | AE13: =VLOOKUP($A13,[16]HISTOJANV22!$A$6:$CA$36,60,0) -> 0 | AF13: =VLOOKUP($A13,[16]HISTOJANV22!$A$6:$CA$36,61,0) -> 0 | AG13: =VLOOKUP($A13,[16]HISTOJANV22!$A$6:$CA$36,62,0) -> 0 | AH13: =VLOOKUP($A13,[16]HISTOJANV22!$A$6:$CA$36,63,0) -> 0 | AI13: =VLOOKUP($A13,[16]HISTOJANV22!$A$6:$CA$36,64,0) -> 0 | AJ13: =VLOOKUP($A13,[16]HISTOJANV22!$A$6:$CA$36,65,0) -> 0
A14: AS201610 | B14: =VLOOKUP(A14,[15]LISTADHERENT!A$5:H$60,3,0) -> FOTSO THOMAS | C14: 540000 | D14: -2105.0986 | E14: =VLOOKUP($A14,[16]HISTOJANV22!$A$6:$BA$39,48,0) -> 0 | F14: =C14-E14 -> 540000 | G14: =$S$40/$H$40*H14 -> 0 | I14: =VLOOKUP($A14,[16]HISTOJANV22!$A$6:$AQ$37,22,0) -> 0 | J14: =VLOOKUP($A14,[16]HISTOJANV22!$A$6:$AU$39,45,0) -> 0 | K14: =IF(J14=0,0,J14-(L14+M14+N14)) -> 0 | L14: =IF(J14=0,0,500) -> 0 | M14: =IF(J14=0,0,1000) -> 0 | N14: =IF(J14=0,0,2500) -> 0 | O14: =VLOOKUP($A14,[16]HISTOJANV22!$A$6:$AU$39,7,0) -> 0 | P14: =VLOOKUP($A14,[16]HISTOJANV22!$A$6:$AU$39,23,0) -> 0 | Q14: =VLOOKUP($A14,[16]HISTOJANV22!$A$6:$AU$39,46,0) -> 0 | R14: =VLOOKUP($A14,[16]HISTOJANV22!$A$6:$AU$39,26,0) -> 1155000 | S14: =VLOOKUP($A14,[16]HISTOJANV22!$A$6:$BG$39,58,0) -> 0 | T14: =VLOOKUP($A14,[16]HISTOJANV22!$A$6:$AU$39,28,0) -> 0 | U14: =VLOOKUP($A14,[16]HISTOJANV22!$A$6:$AU$39,19,0) -> 0 | V14: =VLOOKUP($A14,[16]HISTOJANV22!$A$6:$AU$39,20,0) -> 0 | W14: =VLOOKUP($A14,[16]HISTOJANV22!$A$6:$AU$39,27,0) -> BANQUE | X14: =VLOOKUP($A14,[16]HISTOJANV22!$A$6:$AU$39,33,0) -> 0 | Y14: =VLOOKUP($A14,[16]HISTOJANV22!$A$6:$BM$39,65,0) -> 0 | AA14: =VLOOKUP($A14,[16]HISTOJANV22!$A$6:$AU$39,43,0) -> 0 | AB14: =VLOOKUP($A14,[16]HISTOJANV22!$A$6:$AU$39,44,0) -> 0 | AC14: =VLOOKUP($A14,[16]HISTOJANV22!$A$6:$AU$39,47,0) -> 0 | AD14: =VLOOKUP(A14,[16]HISTOJANV22!$A$6:$BB$36,54,0) -> 0 | AE14: =VLOOKUP($A14,[16]HISTOJANV22!$A$6:$CA$36,60,0) -> 0 | AF14: =VLOOKUP($A14,[16]HISTOJANV22!$A$6:$CA$36,61,0) -> 0 | AG14: =VLOOKUP($A14,[16]HISTOJANV22!$A$6:$CA$36,62,0) -> 0 | AH14: =VLOOKUP($A14,[16]HISTOJANV22!$A$6:$CA$36,63,0) -> 0 | AI14: =VLOOKUP($A14,[16]HISTOJANV22!$A$6:$CA$36,64,0) -> 155000 | AJ14: =VLOOKUP($A14,[16]HISTOJANV22!$A$6:$CA$36,65,0) -> 0
