Workbook

Sheet Sheet1

Sheet Sheet2

Sheet Sheet3

Sheet Sheet4

Sheet Sheet5

Sheet Sheet6

Sheet Sheet7

Sheet Sheet8

Sheet Sheet9

Sheet Sheet10

Sheet Sheet11

Sheet Sheet12
A1: ASSOCIATION | B1: ASELBY
A2: ANNEE | B2: 2016/2017
A3: TONTINE | B3: 20 000
A4: MATRICULE | B4: NOM ET PRENOM | C4: REPARTITION INTERET | D4: CAPITAL COMPOSE | E4: SANCTION | F4: MONTANT VERSE | G4: EPARGNE | H4: FONDS DE ROULEMENT | I4: FRAIS EXCEPTIONNEL | J4: COLLATION | K4: MUTUELLE | L4: TONTINE | M4: EMPRUNT | N4: INTERET EMPRUNT | O4: REMBOURSEMENT | P4: PENALITE EMPRUNT | Q4: PENALITE FONDS
A5: AS201648 | B5: =VLOOKUP(A5,LISTADHERENT!A$5:H$52,2,0) -> ASELBY | C5: =$N$56/$D$56*D5 -> 4585.7298 | D5: =TONT20000MAI!C5+TONT20000MAI!D5+TONT20000JUIN!G5 -> 330432.66
A6: AS201601 | B6: =VLOOKUP(A6,LISTADHERENT!A$5:H$51,2) -> BAKOP ACHILLE | C6: =$N$56/$D$56*D6 -> 6401.9466 | D6: =TONT20000MAI!C6+TONT20000MAI!D6+TONT20000JUIN!G6 -> 461303.29 | F6: =G6+H6+I6+J6+K6+L6 -> 20000 | G6: 3000 | H6: 500 | I6: 1000 | J6: 2500 | L6: 13000 | N6: =IF(M6<=500000,(M6*1*3/100),(M6*12/100)) -> 0
A7: AS201602 | B7: =VLOOKUP(A7,LISTADHERENT!A$5:H$51,2) -> BOUTCHOUANG WILLIAM | C7: =$N$56/$D$56*D7 -> 5943.1214 | D7: =TONT20000MAI!C7+TONT20000MAI!D7+TONT20000JUIN!G7 -> 428241.85 | F7: =G7+H7+I7+J7+K7+L7 -> 20000 | G7: 3000 | H7: 500 | I7: 1000 | J7: 2500 | L7: 13000 | N7: =IF(M7<=500000,(M7*1*3/100),(M7*12/100)) -> 0
A8: AS201603 | B8: =VLOOKUP(A8,LISTADHERENT!A$5:H$51,2) -> CHINGUE FABRICE | C8: =$N$56/$D$56*D8 -> 5945.1105 | D8: =TONT20000MAI!C8+TONT20000MAI!D8+TONT20000JUIN!G8 -> 428385.18 | F8: =G8+H8+I8+J8+K8+L8 -> 20000 | G8: 3000 | H8: 500 | I8: 1000 | J8: 2500 | L8: 13000 | M8: 1000000 | N8: =IF(M8<=500000,(M8*1*3/100),(M8*12/100)) -> 120000 | O8: 1000000
A9: AS201604 | B9: =VLOOKUP(A9,LISTADHERENT!A$5:H$51,2) -> DJOMO JEAN PAUL | C9: =$N$56/$D$56*D9 -> 6036.1203 | D9: =TONT20000MAI!C9+TONT20000MAI!D9+TONT20000JUIN!G9 -> 434943.04 | F9: =G9+H9+I9+J9+K9+L9 -> 20000 | G9: 3000 | H9: 500 | I9: 1000 | J9: 2500 | L9: 13000 | N9: =IF(M9<=500000,(M9*1*3/100),(M9*12/100)) -> 0
A10: AS201605 | B10: =VLOOKUP(A10,LISTADHERENT!A$5:H$51,2) -> DJOUKWE GUY | C10: =$N$56/$D$56*D10 -> 6562.6898 | D10: =TONT20000MAI!C10+TONT20000MAI!D10+TONT20000JUIN!G10 -> 472885.92 | F10: =G10+H10+I10+J10+K10+L10 -> 50000 | G10: 33000 | H10: 500 | I10: 1000 | J10: 2500 | L10: 13000 | N10: =IF(M10<=500000,(M10*1*3/100),(M10*12/100)) -> 0
A11: AS201606 | B11: =VLOOKUP(A11,LISTADHERENT!A$5:H$51,2) -> DJOSSEU JOSUE | C11: =$N$56/$D$56*D11 -> 72.069807 | D11: =TONT20000MAI!C11+TONT20000MAI!D11+TONT20000JUIN!G11 -> 5193.1141 | F11: =G11+H11+I11+J11+K11+L11 -> 0 | N11: =IF(M11<=500000,(M11*1*3/100),(M11*12/100)) -> 0
A12: AS201607 | B12: =VLOOKUP(A12,LISTADHERENT!A$5:H$51,2) -> DJOUNKEP SAMUEL | C12: =$N$56/$D$56*D12 -> 27381.851 | D12: =TONT20000MAI!C12+TONT20000MAI!D12+TONT20000JUIN!G12 -> 1973046.4 | F12: =G12+H12+I12+J12+K12+L12 -> 20000 | G12: 3000 | H12: 500 | I12: 1000 | J12: 2500 | L12: 13000 | N12: =IF(M12<=500000,(M12*1*3/100),(M12*12/100)) -> 0
A13: AS201608 | B13: =VLOOKUP(A13,LISTADHERENT!A$5:H$51,2) -> DJUOMBESSY ANTOINE | C13: =$N$56/$D$56*D13 -> 4897.1002 | D13: =TONT20000MAI!C13+TONT20000MAI!D13+TONT20000JUIN!G13 -> 352868.99 | F13: =G13+H13+I13+J13+K13+L13 -> 20000 | G13: 3000 | H13: 500 | I13: 1000 | J13: 2500 | L13: 13000 | N13: =IF(M13<=500000,(M13*1*3/100),(M13*12/100)) -> 0
A14: AS201609 | B14: =VLOOKUP(A14,LISTADHERENT!A$5:H$51,2) -> DONHOU DAVID | C14: =$N$56/$D$56*D14 -> 6563.3542 | D14: =TONT20000MAI!C14+TONT20000MAI!D14+TONT20000JUIN!G14 -> 472933.79 | F14: =G14+H14+I14+J14+K14+L14 -> 20000 | G14: 3000 | H14: 500 | I14: 1000 | J14: 2500 | L14: 13000 | N14: =IF(M14<=500000,(M14*1*3/100),(M14*12/100)) -> 0
A15: AS201610 | B15: =VLOOKUP(A15,LISTADHERENT!A$5:H$51,2) -> FOTSO THOMAS | C15: =$N$56/$D$56*D15 -> 5966.3855 | D15: =TONT20000MAI!C15+TONT20000MAI!D15+TONT20000JUIN!G15 -> 429918.18 | F15: =G15+H15+I15+J15+K15+L15 -> 20000 | G15: 3000 | H15: 500 | I15: 1000 | J15: 2500 | L15: 13000 | N15: =IF(M15<=500000,(M15*1*3/100),(M15*12/100)) -> 0
A16: AS201611 | B16: =VLOOKUP(A16,LISTADHERENT!A$5:H$51,2) -> HENGUE PAUL OMER | C16: =$N$56/$D$56*D16 -> 5918.56 | D16: =TONT20000MAI!C16+TONT20000MAI!D16+TONT20000JUIN!G16 -> 426472.03 | F16: =G16+H16+I16+J16+K16+L16 -> 20000 | G16: 3000 | H16: 500 | I16: 1000 | J16: 2500 | L16: 13000 | N16: =IF(M16<=500000,(M16*1*3/100),(M16*12/100)) -> 0
A17: AS201612 | B17: =VLOOKUP(A17,LISTADHERENT!A$5:H$51,2) -> HODIEP JULES | C17: =$N$56/$D$56*D17 -> 991.01284 | D17: =TONT20000MAI!C17+TONT20000MAI!D17+TONT20000JUIN!G17+50000 -> 71409.137 | F17: =G17+H17+I17+J17+K17+L17 -> 20000 | G17: 3000 | H17: 500 | I17: 1000 | J17: 2500 | L17: 13000 | N17: =IF(M17<=500000,(M17*1*3/100),(M17*12/100)) -> 0
A18: AS201613 | B18: =VLOOKUP(A18,LISTADHERENT!A$5:H$51,2) -> HOTCHO BENJAMIN | C18: =$N$56/$D$56*D18 -> 6044.293 | D18: =TONT20000MAI!C18+TONT20000MAI!D18+TONT20000JUIN!G18 -> 435531.94 | F18: =G18+H18+I18+J18+K18+L18 -> 20000 | G18: 3000 | H18: 500 | I18: 1000 | J18: 2500 | L18: 13000 | N18: =IF(M18<=500000,(M18*1*3/100),(M18*12/100)) -> 0
A19: AS201614 | B19: =VLOOKUP(A19,LISTADHERENT!A$5:H$51,2) -> KEPHE DAVID | C19: =$N$56/$D$56*D19 -> 481.54169 | D19: =TONT20000MAI!C19+TONT20000MAI!D19+TONT20000JUIN!G19 -> 34698.316 | F19: =G19+H19+I19+J19+K19+L19 -> 20000 | G19: 3000 | H19: 500 | I19: 1000 | J19: 2500 | L19: 13000 | N19: =IF(M19<=500000,(M19*1*3/100),(M19*12/100)) -> 0
A20: AS201615 | B20: =VLOOKUP(A20,LISTADHERENT!A$5:H$51,2) -> KEPSEU FRANCIS | C20: =$N$56/$D$56*D20 -> 15695.675 | D20: =TONT20000MAI!C20+TONT20000MAI!D20+TONT20000JUIN!G20 -> 1130978.9 | F20: =G20+H20+I20+J20+K20+L20 -> 23000 | G20: 6000 | H20: 500 | I20: 1000 | J20: 2500 | L20: 13000 | N20: =IF(M20<=500000,(M20*1*3/100),(M20*12/100)) -> 0
A21: AS201616 | B21: =VLOOKUP(A21,LISTADHERENT!A$5:H$51,2) -> KOUAMOU EMMANUEL | C21: =$N$56/$D$56*D21 -> 5957.8092 | D21: =TONT20000MAI!C21+TONT20000MAI!D21+TONT20000JUIN!G21 -> 429300.2 | F21: =G21+H21+I21+J21+K21+L21 -> 20000 | G21: 3000 | H21: 500 | I21: 1000 | J21: 2500 | L21: 13000 | N21: =IF(M21<=500000,(M21*1*3/100),(M21*12/100)) -> 0
A22: AS201617 | B22: =VLOOKUP(A22,LISTADHERENT!A$5:H$51,2) -> KOUAMOU MOISE | C22: =$N$56/$D$56*D22 -> 5908.6145 | D22: =TONT20000MAI!C22+TONT20000MAI!D22+TONT20000JUIN!G22+75000 -> 425755.39 | F22: =G22+H22+I22+J22+K22+L22 -> 20000 | G22: 3000 | H22: 500 | I22: 1000 | J22: 2500 | L22: 13000 | M22: 60000 | N22: =IF(M22<=500000,(M22*1*3/100),(M22*12/100)) -> 1800
A23: AS201618 | B23: =VLOOKUP(A23,LISTADHERENT!A$5:H$51,2) -> KOUAMOU VICTOR PEGUY | C23: =$N$56/$D$56*D23 -> 6446.529 | D23: =TONT20000MAI!C23+TONT20000MAI!D23+TONT20000JUIN!G23 -> 464515.75 | F23: =G23+H23+I23+J23+K23+L23 -> 20000 | G23: 3000 | H23: 500 | I23: 1000 | J23: 2500 | L23: 13000 | N23: =IF(M23<=500000,(M23*1*3/100),(M23*12/100)) -> 0
A24: AS201619 | B24: =VLOOKUP(A24,LISTADHERENT!A$5:H$51,2) -> KOUATCHO MESSACK | C24: =$N$56/$D$56*D24 -> 5918.56 | D24: =TONT20000MAI!C24+TONT20000MAI!D24+TONT20000JUIN!G24 -> 426472.03 | F24: =G24+H24+I24+J24+K24+L24 -> 20000 | G24: 3000 | H24: 500 | I24: 1000 | J24: 2500 | L24: 13000 | N24: =IF(M24<=500000,(M24*1*3/100),(M24*12/100)) -> 0
A25: AS201620 | B25: =VLOOKUP(A25,LISTADHERENT!A$5:H$51,2) -> LOWE JEAN | C25: =$N$56/$D$56*D25 -> 5980.9869 | D25: =TONT20000MAI!C25+TONT20000MAI!D25+TONT20000JUIN!G25 -> 430970.31 | F25: =G25+H25+I25+J25+K25+L25 -> 20000 | G25: 3000 | H25: 500 | I25: 1000 | J25: 2500 | L25: 13000 | M25: 80000 | N25: =IF(M25<=500000,(M25*1*3/100),(M25*12/100)) -> 2400 | O25: 80000
A26: AS201621 | B26: =VLOOKUP(A26,LISTADHERENT!A$5:H$51,2) -> NANKAM APPOLINAIRE | C26: =$N$56/$D$56*D26 -> 5982.14 | D26: =TONT20000MAI!C26+TONT20000MAI!D26+TONT20000JUIN!G26 -> 431053.4 | F26: =G26+H26+I26+J26+K26+L26 -> 20000 | G26: 3000 | H26: 500 | I26: 1000 | J26: 2500 | L26: 13000 | N26: =IF(M26<=500000,(M26*1*3/100),(M26*12/100)) -> 0
A27: AS201622 | B27: =VLOOKUP(A27,LISTADHERENT!A$5:H$51,2) -> NDJOMO ETIENNE | C27: =$N$56/$D$56*D27 -> 6443.4445 | D27: =TONT20000MAI!C27+TONT20000MAI!D27+TONT20000JUIN!G27 -> 464293.49 | F27: =G27+H27+I27+J27+K27+L27 -> 25000 | G27: 8000 | H27: 500 | I27: 1000 | J27: 2500 | L27: 13000 | M27: 400000 | N27: =IF(M27<=500000,(M27*1*3/100),(M27*12/100)) -> 12000 | O27: 400000
A28: AS201623 | B28: =VLOOKUP(A28,LISTADHERENT!A$5:H$51,2) -> NDOMBOU JEAN CLAUDE | C28: =$N$56/$D$56*D28 -> 0 | D28: =TONT20000MAI!C28+TONT20000MAI!D28+TONT20000JUIN!G28 -> 0 | F28: =G28+H28+I28+J28+K28+L28 -> 0 | N28: =IF(M28<=500000,(M28*1*3/100),(M28*12/100)) -> 0
A29: AS201624 | B29: =VLOOKUP(A29,LISTADHERENT!A$5:H$51,2) -> NGONDIEP CLAUDE | C29: =$N$56/$D$56*D29 -> 8506.9327 | D29: =TONT20000MAI!C29+TONT20000MAI!D29+TONT20000JUIN!G29 -> 612981.69 | F29: =G29+H29+I29+J29+K29+L29 -> 20000 | G29: 3000 | H29: 500 | I29: 1000 | J29: 2500 | L29: 13000 | N29: =IF(M29<=500000,(M29*1*3/100),(M29*12/100)) -> 0
A30: AS201625 | B30: =VLOOKUP(A30,LISTADHERENT!A$5:H$51,2) -> NGONGANG JEAN THEODORE | C30: =$N$56/$D$56*D30 -> 297.11505 | D30: =TONT20000MAI!C30+TONT20000MAI!D30+TONT20000JUIN!G30 -> 21409.137 | F30: =G30+H30+I30+J30+K30+L30 -> 20000 | G30: 3000 | H30: 500 | I30: 1000 | J30: 2500 | L30: 13000 | N30: =IF(M30<=500000,(M30*1*3/100),(M30*12/100)) -> 0
A31: AS201626 | B31: =VLOOKUP(A31,LISTADHERENT!A$5:H$51,2) -> NGUIEMEGNI MATHIEU BLAISE | C31: =$N$56/$D$56*D31 -> 2177.0792 | D31: =TONT20000MAI!C31+TONT20000MAI!D31+TONT20000JUIN!G31 -> 156873.19 | F31: =G31+H31+I31+J31+K31+L31 -> 140000 | G31: 123000 | H31: 500 | I31: 1000 | J31: 2500 | L31: 13000 | N31: =IF(M31<=500000,(M31*1*3/100),(M31*12/100)) -> 0
A32: AS201627 | B32: =VLOOKUP(A32,LISTADHERENT!A$5:H$51,2) -> NJEPDJIO MBOUKAM DELUXE | C32: =$N$56/$D$56*D32 -> 6169.8028 | D32: =TONT20000MAI!C32+TONT20000MAI!D32+TONT20000JUIN!G32 -> 444575.77 | F32: =G32+H32+I32+J32+K32+L32 -> 23000 | G32: 6000 | H32: 500 | I32: 1000 | J32: 2500 | L32: 13000 | M32: 1000000 | N32: =IF(M32<=500000,(M32*1*3/100),(M32*12/100)) -> 120000 | O32: 1000000
A33: AS201628 | B33: =VLOOKUP(A33,LISTADHERENT!A$5:H$51,2) -> NKAMGANG JUSTIN DEJOLIE | C33: =$N$56/$D$56*D33 -> 594.2301 | D33: =TONT20000MAI!C33+TONT20000MAI!D33+TONT20000JUIN!G33 -> 42818.273 | F33: =G33+H33+I33+J33+K33+L33 -> 23000 | G33: 6000 | H33: 500 | I33: 1000 | J33: 2500 | L33: 13000 | N33: =IF(M33<=500000,(M33*1*3/100),(M33*12/100)) -> 0
A34: AS201629 | B34: =VLOOKUP(A34,LISTADHERENT!A$5:H$51,2) -> NKEPSEU DIEUDONNE | C34: =$N$56/$D$56*D34 -> 6539.7154 | D34: =TONT20000MAI!C34+TONT20000MAI!D34+TONT20000JUIN!G34 -> 471230.45 | F34: =G34+H34+I34+J34+K34+L34 -> 25000 | G34: 8000 | H34: 500 | I34: 1000 | J34: 2500 | L34: 13000 | N34: =IF(M34<=500000,(M34*1*3/100),(M34*12/100)) -> 0
A35: AS201630 | B35: =VLOOKUP(A35,LISTADHERENT!A$5:H$51,2) -> NKEPSEU HENANG RENE | C35: =$N$56/$D$56*D35 -> 6033.6267 | D35: =TONT20000MAI!C35+TONT20000MAI!D35+TONT20000JUIN!G35 -> 434763.36 | F35: =G35+H35+I35+J35+K35+L35 -> 20000 | G35: 3000 | H35: 500 | I35: 1000 | J35: 2500 | L35: 13000 | N35: =IF(M35<=500000,(M35*1*3/100),(M35*12/100)) -> 0
A36: AS201631 | B36: =VLOOKUP(A36,LISTADHERENT!A$5:H$51,2) -> NTEPDIE TUEMAC MZ | C36: =$N$56/$D$56*D36 -> 86.240598 | D36: =TONT20000MAI!C36+TONT20000MAI!D36+TONT20000JUIN!G36 -> 6214.2148 | F36: =G36+H36+I36+J36+K36+L36 -> 0 | N36: =IF(M36<=500000,(M36*1*3/100),(M36*12/100)) -> 0
A37: AS201632 | B37: =VLOOKUP(A37,LISTADHERENT!A$5:H$51,2) -> NTOMBOU ADOLPHE | C37: =$N$56/$D$56*D37 -> 297.11505 | D37: =TONT20000MAI!C37+TONT20000MAI!D37+TONT20000JUIN!G37 -> 21409.137 | F37: =G37+H37+I37+J37+K37+L37 -> 20000 | G37: 3000 | H37: 500 | I37: 1000 | J37: 2500 | L37: 13000 | N37: =IF(M37<=500000,(M37*1*3/100),(M37*12/100)) -> 0
A38: AS201633 | B38: =VLOOKUP(A38,LISTADHERENT!A$5:H$51,2) -> PATEGO NJOSSU GUSTAVE | C38: =$N$56/$D$56*D38 -> 5920.578 | D38: =TONT20000MAI!C38+TONT20000MAI!D38+TONT20000JUIN!G38 -> 426617.44 | F38: =G38+H38+I38+J38+K38+L38 -> 20000 | G38: 3000 | H38: 500 | I38: 1000 | J38: 2500 | L38: 13000 | N38: =IF(M38<=500000,(M38*1*3/100),(M38*12/100)) -> 0
A39: AS201634 | B39: =VLOOKUP(A39,LISTADHERENT!A$5:H$51,2) -> SEUNOU RICHELOT | C39: =$N$56/$D$56*D39 -> 5956.4976 | D39: =TONT20000MAI!C39+TONT20000MAI!D39+TONT20000JUIN!G39 -> 429205.69 | F39: =G39+H39+I39+J39+K39+L39 -> 20000 | G39: 3000 | H39: 500 | I39: 1000 | J39: 2500 | L39: 13000 | N39: =IF(M39<=500000,(M39*1*3/100),(M39*12/100)) -> 0
A40: AS201635 | B40: =VLOOKUP(A40,LISTADHERENT!A$5:H$51,2) -> SIME ABEL | C40: =$N$56/$D$56*D40 -> 297.11505 | D40: =TONT20000MAI!C40+TONT20000MAI!D40+TONT20000JUIN!G40 -> 21409.137 | F40: =G40+H40+I40+J40+K40+L40 -> 20000 | G40: 3000 | H40: 500 | I40: 1000 | J40: 2500 | L40: 13000 | N40: =IF(M40<=500000,(M40*1*3/100),(M40*12/100)) -> 0
...
