Workbook

Sheet Sheet1
A2: BILAN ALLANT DE LA PERIODE DU 01 DECEMBRE 2015 AU 30 NOVEMBRE 2016
A5: RUBRIQUE | B5: REPORT A NOUVEAU | C5: ENTREES | D5: SORTIES | E5: SOLDE
A7: EPARGNE\RELIQUAT2015 | B7: =TRAVAUXINVENTAIRE!D54 -> 3525236 | C7: =TRAVAUXINVENTAIRE!R54+C17 -> 6051809 | D7: =EPARGNE!D17+TRAVAUXINVENTAIRE!L54 -> 3142500 | E7: =B7+C7-D7 -> 6434545
A8: FONDS DE CAISSE | B8: =TRAVAUXINVENTAIRE!C54 -> 14428521 | C8: =TRAVAUXINVENTAIRE!M54 -> 1050000 | E8: =B8+C8-D8 -> 15478521
A9: FONDS DE ROULEMENT | C9: =TRAVAUXINVENTAIRE!S54 -> 250500 | D9: =TRAVAUXINVENTAIREDEC!B5 -> 0 | E9: =B9+C9-D9 -> 250500
A10: FRAIS EXCEPTIONNELS | C10: =TRAVAUXINVENTAIRE!T54 -> 501000 | D10: =TRAVAUXINVENTAIREDEC!B6 -> 1100000 | E10: =B10+C10-D10 -> -599000
A11: COLLATION | C11: =TRAVAUXINVENTAIRE!U54 -> 1252500 | D11: =TRAVAUXINVENTAIREDEC!B7 -> 1260000 | E11: =B11+C11-D11 -> -7500
A12: MUTUELLE\COMPLEMENT MUTUEL | C12: =TRAVAUXINVENTAIRE!V54+TRAVAUXINVENTAIRE!O54 -> 1954860 | D12: =TRAVAUXINVENTAIREDEC!B8 -> 2595000 | E12: =B12+C12-D12 -> -640140
A14: FOYER
A15: RECOUVREMENT POUR LAGWEU GENERAL | C15: =320750+16500 -> 337250 | F15: 1711250
A16: AUTRES
A17: INTERET EMPRUNT | C17: =TRAVAUXINVENTAIRE!G54 -> 2230668 | E17: =B17+C17-D17 -> 2230668
A19: EMPRUNT | D19: =EMPRUNT!BB54 -> 21 | E19: =EMPRUNT!BB54 -> 21
A21: RELIQUAT 2016 | C21: =TRAVAUXINVENTAIRE!E54 -> 3212114
A24: COMPTE CCA | C24: 19683000 | D24: 18428363 | E24: =C24-D24 -> 1254637
A25: COMPTE AFRILAND | E25: 4369987
A26: COMPTE MC2 | C26: 614769 | E26: =C26-D26 -> 614769
A27: ASELBY CAISSE(NDJOMO ETIENNE) | C27: 353000 | E27: =C27-D27 -> 353000
A29: RETRAIT DISTRIBUTION EPARGNE | C29: 8000000 | E29: =C29-D29 -> 8000000
A31: SOUS TOTAL | E31: =SUM(E24:E29) -> 14592393
A33: MONTANT DISPONIBLE | E33: =E19+E31 -> 14592414

Sheet Sheet2
A1: LIEU RECEPTION | D1: TONTINE 20 000 | E1: TONTINE 60 000 | F1: TONTINE 100 000
A2: NOM ADHERENT
A3: DATE TONTINE
A4: NOM ACHETEUR
A5: MONTANT INTERET ACHAT
A6: NOM AVALISTE
A8: NATURE OPERATION | B8: EPARGNE | D8: FONDS DE ROULEMENT | F8: FRAIS EXCEPTIONNEL | H8: COLLATION | J8: EMPRUNT/REMBOURSEMENT | L8: PENALITE EMPRUNT | M8: PENALITE FONDS | N8: PENALITE TONTINE | O8: INTERET ACHAT TONTINE | P8: COMPLEMENT TONTINE | R8: SANCTION
B9: ENTREE | C9: SORTIE | D9: ENTREE | E9: SORTIE | F9: ENTREE | G9: SORTIE | H9: ENTREE | I9: SORTIE | J9: ENTREE | K9: SORTIE | L9: ENTREE | M9: ENTREE | O9: ENTREE | P9: ENTREE | Q9: SORTIE | R9: ENTREE | S9: SORTIE

Sheet Sheet3

Sheet Sheet4

Sheet Sheet5
A2: LIBELLE | B2: DEC2016 | C2: 42736 | D2: 42767 | E2: 42795 | F2: 42826 | G2: 42856 | H2: 42887 | I2: 42917 | J2: 42948 | K2: 42979 | L2: 43009 | M2: 43040
A4: PAIEMENT EPARGNE 2015
A5: LOWE JEAN
A6: KOUAMOU VICTOR PEGUY
A7: KEPSEU FRANCIS
A8: BOUTCHOUANG WILLIAM
A17: TOTAL | B17: =SUM(B4:B16) -> 0 | C17: =SUM(C4:C16) -> 0 | D17: =SUM(D4:D16) -> 0 | E17: =SUM(E4:E16) -> 0 | F17: =SUM(F4:F16) -> 0 | G17: =SUM(G4:G16) -> 0 | H17: =SUM(H4:H16) -> 0 | I17: =SUM(I4:I16) -> 0 | ... M17: =SUM(M4:M16) -> 0

Sheet Sheet6
A2: LIBELLE | B2: DEC2016 | C2: 42736 | D2: 42767 | E2: 42795 | F2: 42826 | G2: 42856 | H2: 42887 | I2: 42917 | J2: 42948 | K2: 42979 | L2: 43009 | M2: 43040
A4: TROP PERCU
A5: NKAMGANG JUSTIN DEJOLIE
A6: TCHOUAMOU MATHIEU
A7: NDJOMO ETIENNE
A8: GRATIFICATION BUREAU
A9: TAXI BANQUE
A10: PHOTOCOPIE DES DOCUMENTS
A11: OUVERTURE COMPTE
A12: COMMISSION FINANCE
A13: REUNION DE BUREAU
A14: LAVAGE ECHAPPE
A15: COOMMISSION BUREAU
A16: COMMUNICATION
A18: TOTAL | B18: =SUM(B5:B17) -> 0 | C18: =SUM(C5:C17) -> 0 | D18: =SUM(D5:D17) -> 0 | E18: =SUM(E5:E17) -> 0 | F18: =SUM(F5:F17) -> 0 | G18: =SUM(G5:G17) -> 0 | H18: =SUM(H5:H17) -> 0 | I18: =SUM(I5:I17) -> 0 | ... M18: =SUM(M5:M17) -> 0

Sheet Sheet7
A2: LIBELLE | B2: DEC2016 | C2: 42736 | D2: 42767 | E2: 42795 | F2: 42826 | G2: 42856 | H2: 42887 | I2: 42917 | J2: 42948 | K2: 42979 | L2: 43009 | M2: 43040
A4: ACHAT ORDINATEUR | J4: 400000
A5: CEDIL | F5: 700000
A17: TOTAL | B17: =SUM(B4:B16) -> 0 | C17: =SUM(C4:C16) -> 0 | D17: =SUM(D4:D16) -> 0 | E17: =SUM(E4:E16) -> 0 | F17: =SUM(F4:F16) -> 700000 | G17: =SUM(G4:G16) -> 0 | H17: =SUM(H4:H16) -> 0 | I17: =SUM(I4:I16) -> 0 | ... M17: =SUM(M4:M16) -> 0

Sheet Sheet8
B2: DEC2016 | C2: 42736 | D2: 42767 | E2: 42795 | F2: 42826 | G2: 42856 | H2: 42887 | I2: 42917 | J2: 42948 | K2: 42979 | L2: 43009 | M2: 43040
A4: COLLATION | B4: 100000 | C4: 100000 | D4: 100000 | E4: 100000 | F4: 100000 | G4: 100000 | H4: 100000 | I4: 100000 | J4: 100000 | K4: 100000 | L4: 100000 | M4: 100000
A5: VEILLEE NKEPSEU HENANG | K5: 40000
A6: BOISSON DU 22/12/2015 | C6: 20000
A17: TOTAL | B17: =SUM(B4:B16) -> 100000 | C17: =SUM(C4:C16) -> 120000 | D17: =SUM(D4:D16) -> 100000 | E17: =SUM(E4:E16) -> 100000 | F17: =SUM(F4:F16) -> 100000 | G17: =SUM(G4:G16) -> 100000 | H17: =SUM(H4:H16) -> 100000 | I17: =SUM(I4:I16) -> 100000 | ... M17: =SUM(M4:M16) -> 100000

Sheet Sheet9
A2: LIBELLE | B2: DEC2016 | C2: 42736 | D2: 42767 | E2: 42795 | F2: 42826 | G2: 42856 | H2: 42887 | I2: 42917 | J2: 42948 | K2: 42979 | L2: 43009 | M2: 43040
A4: OBSEQUES DJOSSEU JOSUE | C4: 500000
A5: OBSEQUES NKEPSEU HENANG | K5: 500000
A6: OBSEQUES NTOMBO ADOLPHE | J6: 500000
A7: FUNERAILLES CHEF DE FAMILLE | C7: 150000
A8: AIDE PÈRE HOTCHO | E8: 100000
A9: AIDE BEAU PÈRE NTOMBO | H9: 100000
A10: AIDES BELLE MERE KEPSEU FRANCIS | H10: 100000
A11: AIDE ENFANT KOUAMO EMMANUEL | J11: 45000
A12: AIDE PÈRE BAKOP | J12: 100000
A13: AIDE PÈRE MBOUTCHOUANG | J13: 100000
A14: AIDE MERE SIMO MATHIEU | K14: 100000
A15: AIDE BEAU PÈRE BOUTCHOUANG | M15: 100000
A16: AIDE MERE DOWOU DAVID | M16: 100000
A17: AIDE PÈRE KOUAMOU EMMANUEL | C17: 100000
A19: TOTAL | B19: =SUM(B4:B16) -> 0 | C19: =SUM(C4:C17) -> 750000 | D19: =SUM(D4:D17) -> 0 | E19: =SUM(E4:E17) -> 100000 | F19: =SUM(F4:F17) -> 0 | G19: =SUM(G4:G17) -> 0 | H19: =SUM(H4:H17) -> 200000 | I19: =SUM(I4:I17) -> 0 | J19: =SUM(J4:J17) -> 745000 | ... M19: =SUM(M4:M17) -> 200000

Sheet Sheet10
A2: LIBELLE | B2: DEC2016 | C2: 42736 | D2: 42767 | E2: 42795 | F2: 42826 | G2: 42856 | H2: 42887 | I2: 42917 | J2: 42948 | K2: 42979 | L2: 43009 | M2: 43040

Sheet Sheet11
B1: INSCRIPTION
A3: MATRICULE | B3: NOM | C3: DEC2016 | D3: 42736 | E3: 42767 | F3: 42795 | G3: 42826 | H3: 42856 | I3: 42887 | J3: 42917 | K3: 42948 | L3: 42979 | M3: 43009 | N3: 43040
A5: AS201648 | B5: ASELBY | C5: 25000
A6: AS201601 | B6: BAKOP ACHILLE | C6: 25000
A7: AS201602 | B7: BOUTCHOUANG WILLIAM | C7: 25000
A8: AS201603 | B8: CHINGUE FABRICE | C8: 25000
A9: AS201604 | B9: DJOMO JEAN PAUL | C9: 25000
A10: AS201605 | B10: DJOUKWE GUY | C10: 25000
A11: AS201606 | B11: DJOSSEU JOSUE | C11: 25000
A12: AS201607 | B12: DJOUNKEP SAMUEL | C12: 25000
A13: AS201608 | B13: DJUOMBESSY ANTOINE | C13: 25000
A14: AS201609 | B14: DONHOU DAVID | C14: 25000
A15: AS201610 | B15: FOTSO THOMAS | C15: 25000
A16: AS201611 | B16: HENGUE PAUL OMER | C16: 25000
... A52: AS201647 | B52: YOUMBI EMMANUEL | C52: 25000
B55: TOTAL | C55: =SUM(C5:C54) -> 1200000

Sheet Sheet12
B1: EMPRUNT ENCOURS
C4: 43313 | F4: 43344 | J4: 43374 | N4: 43405 | R4: 43435 | V4: 43466 | Z4: 43497 | AD4: 43525 | AH4: 43556 | AL4: 43586 | AP4: 43617 | AT4: 43647 | AX4: 43678 | BB4: TOTAL
A5: MATRICULE | B5: NOM | C5: SOLDE FIN | D5: MONTANT A REMBOURSER | E5: REMBOURSEMENT | F5: PRÊT | G5: INTERET | H5: PRÊT NET | I5: REMBOURSEMENT | J5: PRÊT | K5: INTERET | L5: PRÊT NET | M5: REMBOURSEMENT | N5: PRÊT | O5: INTERET | P5: PRÊT NET | Q5: REMBOURSEMENT | R5: PRÊT | S5: INTERET | T5: PRÊT NET | U5: REMBOURSEMENT | V5: PRÊT | W5: INTERET | X5: PRÊT NET | Y5: REMBOURSEMENT | Z5: PRÊT | AA5: INTERET | AB5: PRÊT NET | AC5: REMBOURSEMENT | AD5: PRÊT | AE5: INTERET | AF5: PRÊT NET | AG5: REMBOURSEMENT | AH5: PRÊT | AI5: INTERET | AJ5: PRÊT NET | AK5: REMBOURSEMENT | AL5: PRÊT | AM5: INTERET | AN5: PRÊT NET | AO5: REMBOURSEMENT | AP5: PRÊT | AQ5: INTERET | AR5: PRÊT NET | AS5: REMBOURSEMENT | AT5: PRÊT | AU5: INTERET | AV5: PRÊT NET | AW5: REMBOURSEMENT | AX5: PRÊT | AY5: INTERET | AZ5: PRÊT NET | BA5: REMBOURSEMENT | BB5: PRÊT | BC5: INTERET | BD5: PRÊT NET | BE5: REMBOURSEMENT | BF5: MOIS REMBOURSEMENT | BG5: PENALITE 2018 | BH5: OBSERVATION
A6: AS201648 | B6: =VLOOKUP(A6,[3]LISTADHERENT!A$5:H$58,2,0) -> ASELBY
A7: AS201601 | B7: =VLOOKUP(A7,[3]LISTADHERENT!A$5:H$58,2,0) -> BAKOP ACHILLE | D7: 588000 | F7: =[4]MVTSEPT!$P7 -> 588000 | G7: =[4]MVTSEPT!$Q7 -> 0 | H7: =F7-I7 -> 588000 | I7: =[4]MVTSEPT!$S7 -> 0 | J7: =[4]MVTOCT!$N7 -> 0 | K7: =[4]MVTOCT!$O7 -> 0 | L7: =H7+J7-M7 -> 588000 | M7: =[4]MVTOCT!$Q7 -> 0 | N7: =[4]MVTNOV!$N7 -> 0 | O7: =[4]MVTNOV!$O7 -> 0 | P7: =L7+N7-Q7 -> 588000 | Q7: =[4]MVTNOV!$Q7 -> 0 | R7: =[4]MVTDEC!$N7 -> 0 | S7: =[4]MVTDEC!$O7 -> 0 | T7: =P7+R7-U7 -> 588000 | U7: =[4]MVTDEC!$Q7 -> 0 | V7: =[4]MVTJANV!$N7 -> 0 | W7: =[4]MVTJANV!$O7 -> 0 | X7: =T7+V7-Y7 -> 588000 | Y7: =[4]MVTJANV!$Q7 -> 0 | Z7: =[4]MVTFEV!$N7 -> 0 | AA7: =[4]MVTFEV!$O7 -> 0 | AB7: =X7+Z7-AC7 -> 588000 | AC7: =[4]MVTFEV!$Q7 -> 0 | AD7: =[4]MVTMARS!$N7 -> 0 | AE7: =[4]MVTMARS!$O7 -> 0 | AF7: =AB7+AD7-AG7 -> 588000 | AG7: =[4]MVTMARS!$Q7 -> 0 | AH7: =[4]MVTAVRIL!$N7 -> 0 | AI7: =[4]MVTAVRIL!$O7 -> 0 | AJ7: =AF7+AH7-AK7 -> 588000 | AK7: =[4]MVTAVRIL!$Q7 -> 0 | AL7: =[4]MVTMAI!$N7 -> 0 | AM7: =[4]MVTMAI!$O7 -> 0 | AN7: =AJ7+AL7-AO7 -> 588000 | AO7: =[4]MVTMAI!$Q7 -> 0 | AP7: =[4]MVTJUIN!$N7 -> 0 | AQ7: =[4]MVTJUIN!$O7 -> 0 | AR7: =AN7+AP7-AS7 -> 588000 | AS7: =[4]MVTJUIN!$Q7 -> 0 | AT7: =[4]MVTJUIL!$N7 -> 0 | AU7: =[4]MVTJUIL!$O7 -> 0 | AV7: =AR7+AT7-AW7 -> 588000 | AW7: =[4]MVTJUIL!$Q7 -> 0 | AX7: =[4]MVTAOUT2019!$N7 -> 0 | AY7: =[4]MVTAOUT2019!$O7 -> 0 | AZ7: =AV7+AX7-BA7 -> 588000 | BA7: =[4]MVTAOUT2019!$Q7 -> 0 | BB7: 0 | BC7: =G7+K7+O7+S7+W7+AA7+AE7+AI7+AM7+AQ7+AU7+AY7 -> 0 | BD7: =AZ7 -> 588000 | BE7: =I7+M7+Q7+U7+Y7+AC7+AG7+AK7+AO7+AS7+AW7+BA7 -> 0 | BF7: 43678 | BG7: 88000
A8: AS201602 | B8: =VLOOKUP(A8,[3]LISTADHERENT!A$5:H$58,2,0) -> BOUTCHOUANG WILLIAM | D8: 0 | F8: =[4]MVTSEPT!$P8 -> 0 | G8: =[4]MVTSEPT!$Q8 -> 0 | H8: =F8-I8 -> 0 | I8: =[4]MVTSEPT!$S8 -> 0 | J8: =[4]MVTOCT!$N8 -> 0 | K8: =[4]MVTOCT!$O8 -> 0 | L8: =H8+J8-M8 -> 0 | M8: =[4]MVTOCT!$Q8 -> 0 | N8: =[4]MVTNOV!$N8 -> 0 | O8: =[4]MVTNOV!$O8 -> 0 | P8: =L8+N8-Q8 -> 0 | Q8: =[4]MVTNOV!$Q8 -> 0 | R8: =[4]MVTDEC!$N8 -> 1000000 | S8: =[4]MVTDEC!$O8 -> 30000 | T8: =P8+R8-U8 -> 1000000 | U8: =[4]MVTDEC!$Q8 -> 0 | V8: =[4]MVTJANV!$N8 -> 0 | W8: =[4]MVTJANV!$O8 -> 0 | X8: =T8+V8-Y8 -> 1000000 | Y8: =[4]MVTJANV!$Q8 -> 0 | Z8: =[4]MVTFEV!$N8 -> 0 | AA8: =[4]MVTFEV!$O8 -> 0 | AB8: =X8+Z8-AC8 -> 1000000 | AC8: =[4]MVTFEV!$Q8 -> 0 | AD8: =[4]MVTMARS!$N8 -> 0 | AE8: =[4]MVTMARS!$O8 -> 0 | AF8: =AB8+AD8-AG8 -> 1000000 | AG8: =[4]MVTMARS!$Q8 -> 0 | AH8: =[4]MVTAVRIL!$N8 -> 0 | AI8: =[4]MVTAVRIL!$O8 -> 0 | AJ8: =AF8+AH8-AK8 -> 1000000 | AK8: =[4]MVTAVRIL!$Q8 -> 0 | AL8: =[4]MVTMAI!$N8 -> 0 | AM8: =[4]MVTMAI!$O8 -> 0 | AN8: =AJ8+AL8-AO8 -> 1000000 | AO8: =[4]MVTMAI!$Q8 -> 0 | AP8: =[4]MVTJUIN!$N8 -> 0 | AQ8: =[4]MVTJUIN!$O8 -> 0 | AR8: =AN8+AP8-AS8 -> 1000000 | AS8: =[4]MVTJUIN!$Q8 -> 0 | AT8: =[4]MVTJUIL!$N8 -> 0 | AU8: =[4]MVTJUIL!$O8 -> 0 | AV8: =AR8+AT8-AW8 -> 1000000 | AW8: =[4]MVTJUIL!$Q8 -> 0 | AX8: =[4]MVTAOUT2019!$N8 -> 0 | AY8: =[4]MVTAOUT2019!$O8 -> 0 | AZ8: =AV8+AX8-BA8 -> 1000000 | BA8: =[4]MVTAOUT2019!$Q8 -> 0 | BB8: 0 | BC8: =G8+K8+O8+S8+W8+AA8+AE8+AI8+AM8+AQ8+AU8+AY8 -> 30000 | BD8: =AZ8 -> 1000000 | BE8: =I8+M8+Q8+U8+Y8+AC8+AG8+AK8+AO8+AS8+AW8+BA8 -> 0 | BF8: 43525 | BG8: 0
A9: AS201603 | B9: =VLOOKUP(A9,[3]LISTADHERENT!A$5:H$58,2,0) -> CHINGUE FABRICE | F9: =[4]MVTSEPT!$P9 -> 700000 | G9: =[4]MVTSEPT!$Q9 -> 84000 | H9: =F9-I9 -> 700000 | I9: =[4]MVTSEPT!$S9 -> 0 | J9: =[4]MVTOCT!$N9 -> 0 | K9: =[4]MVTOCT!$O9 -> 0 | L9: =H9+J9-M9 -> 700000 | M9: =[4]MVTOCT!$Q9 -> 0 | N9: =[4]MVTNOV!$N9 -> 0 | O9: =[4]MVTNOV!$O9 -> 0 | P9: =L9+N9-Q9 -> 700000 | Q9: =[4]MVTNOV!$Q9 -> 0 | R9: =[4]MVTDEC!$N9 -> 0 | S9: =[4]MVTDEC!$O9 -> 0 | T9: =P9+R9-U9 -> 700000 | U9: =[4]MVTDEC!$Q9 -> 0 | V9: =[4]MVTJANV!$N9 -> 0 | W9: =[4]MVTJANV!$O9 -> 0 | X9: =T9+V9-Y9 -> 700000 | Y9: =[4]MVTJANV!$Q9 -> 0 | Z9: =[4]MVTFEV!$N9 -> 0 | AA9: =[4]MVTFEV!$O9 -> 0 | AB9: =X9+Z9-AC9 -> 700000 | AC9: =[4]MVTFEV!$Q9 -> 0 | AD9: =[4]MVTMARS!$N9 -> 0 | AE9: =[4]MVTMARS!$O9 -> 0 | AF9: =AB9+AD9-AG9 -> 700000 | AG9: =[4]MVTMARS!$Q9 -> 0 | AH9: =[4]MVTAVRIL!$N9 -> 0 | AI9: =[4]MVTAVRIL!$O9 -> 0 | AJ9: =AF9+AH9-AK9 -> 700000 | AK9: =[4]MVTAVRIL!$Q9 -> 0 | AL9: =[4]MVTMAI!$N9 -> 0 | AM9: =[4]MVTMAI!$O9 -> 0 | AN9: =AJ9+AL9-AO9 -> 700000 | AO9: =[4]MVTMAI!$Q9 -> 0 | AP9: =[4]MVTJUIN!$N9 -> 0 | AQ9: =[4]MVTJUIN!$O9 -> 0 | AR9: =AN9+AP9-AS9 -> 700000 | AS9: =[4]MVTJUIN!$Q9 -> 0 | AT9: =[4]MVTJUIL!$N9 -> 0 | AU9: =[4]MVTJUIL!$O9 -> 0 | AV9: =AR9+AT9-AW9 -> 700000 | AW9: =[4]MVTJUIL!$Q9 -> 0 | AX9: =[4]MVTAOUT2019!$N9 -> 0 | AY9: =[4]MVTAOUT2019!$O9 -> 0 | AZ9: =AV9+AX9-BA9 -> 700000 | BA9: =[4]MVTAOUT2019!$Q9 -> 0 | BB9: 0 | BC9: =G9+K9+O9+S9+W9+AA9+AE9+AI9+AM9+AQ9+AU9+AY9 -> 84000 | BD9: =AZ9 -> 700000 | BE9: =I9+M9+Q9+U9+Y9+AC9+AG9+AK9+AO9+AS9+AW9+BA9 -> 0 | BF9: 43678 | BG9: 0
A10: AS201650 | B10: =VLOOKUP(A10,[3]LISTADHERENT!A$5:H$58,2,0) -> DJOMO DOMO | F10: =[4]MVTSEPT!$P10 -> 0 | G10: =[4]MVTSEPT!$Q10 -> 0 | H10: =F10-I10 -> 0 | I10: =[4]MVTSEPT!$S10 -> 0 | J10: =[4]MVTOCT!$N10 -> 0 | K10: =[4]MVTOCT!$O10 -> 0 | L10: =H10+J10-M10 -> 0 | M10: =[4]MVTOCT!$Q10 -> 0 | N10: =[4]MVTNOV!$N10 -> 0 | O10: =[4]MVTNOV!$O10 -> 0 | P10: =L10+N10-Q10 -> 0 | Q10: =[4]MVTNOV!$Q10 -> 0 | R10: =[4]MVTDEC!$N10 -> 0 | S10: =[4]MVTDEC!$O10 -> 0 | T10: =P10+R10-U10 -> 0 | U10: =[4]MVTDEC!$Q10 -> 0 | V10: =[4]MVTJANV!$N10 -> 0 | W10: =[4]MVTJANV!$O10 -> 0 | X10: =T10+V10-Y10 -> 0 | Y10: =[4]MVTJANV!$Q10 -> 0 | Z10: =[4]MVTFEV!$N10 -> 0 | AA10: =[4]MVTFEV!$O10 -> 0 | AB10: =X10+Z10-AC10 -> 0 | AC10: =[4]MVTFEV!$Q10 -> 0 | AD10: =[4]MVTMARS!$N10 -> 0 | AE10: =[4]MVTMARS!$O10 -> 0 | AF10: =AB10+AD10-AG10 -> 0 | AG10: =[4]MVTMARS!$Q10 -> 0 | AH10: =[4]MVTAVRIL!$N10 -> 0 | AI10: =[4]MVTAVRIL!$O10 -> 0 | AJ10: =AF10+AH10-AK10 -> 0 | AK10: =[4]MVTAVRIL!$Q10 -> 0 | AL10: =[4]MVTMAI!$N10 -> 0 | AM10: =[4]MVTMAI!$O10 -> 0 | AN10: =AJ10+AL10-AO10 -> 0 | AO10: =[4]MVTMAI!$Q10 -> 0 | AP10: =[4]MVTJUIN!$N10 -> 0 | AQ10: =[4]MVTJUIN!$O10 -> 0 | AR10: =AN10+AP10-AS10 -> 0 | AS10: =[4]MVTJUIN!$Q10 -> 0 | AT10: =[4]MVTJUIL!$N10 -> 0 | AU10: =[4]MVTJUIL!$O10 -> 0 | AV10: =AR10+AT10-AW10 -> 0 | AW10: =[4]MVTJUIL!$Q10 -> 0 | AX10: =[4]MVTAOUT2019!$N10 -> 0 | AY10: =[4]MVTAOUT2019!$O10 -> 0 | AZ10: =AV10+AX10-BA10 -> 0 | BA10: =[4]MVTAOUT2019!$Q10 -> 0 | BB10: 0 | BC10: =G10+K10+O10+S10+W10+AA10+AE10+AI10+AM10+AQ10+AU10+AY10 -> 0 | BD10: =AZ10 -> 0 | BE10: =I10+M10+Q10+U10+Y10+AC10+AG10+AK10+AO10+AS10+AW10+BA10 -> 0 | BF10: 43678
A11: AS201604 | B11: =VLOOKUP(A11,[3]LISTADHERENT!A$5:H$58,2,0) -> DJOMO JEAN PAUL | D11: 693000 | E11: 693000 | F11: =[4]MVTSEPT!$P11 -> 800000 | G11: =[4]MVTSEPT!$Q11 -> 88000 | H11: =F11-I11 -> 800000 | I11: =[4]MVTSEPT!$S11 -> 0 | J11: =[4]MVTOCT!$N11 -> 0 | K11: =[4]MVTOCT!$O11 -> 0 | L11: =H11+J11-M11 -> 800000 | M11: =[4]MVTOCT!$Q11 -> 0 | N11: =[4]MVTNOV!$N11 -> 0 | O11: =[4]MVTNOV!$O11 -> 0 | P11: =L11+N11-Q11 -> 800000 | Q11: =[4]MVTNOV!$Q11 -> 0 | R11: =[4]MVTDEC!$N11 -> 0 | S11: =[4]MVTDEC!$O11 -> 0 | T11: =P11+R11-U11 -> 800000 | U11: =[4]MVTDEC!$Q11 -> 0 | V11: =[4]MVTJANV!$N11 -> 0 | W11: =[4]MVTJANV!$O11 -> 0 | X11: =T11+V11-Y11 -> 800000 | Y11: =[4]MVTJANV!$Q11 -> 0 | Z11: =[4]MVTFEV!$N11 -> 0 | AA11: =[4]MVTFEV!$O11 -> 0 | AB11: =X11+Z11-AC11 -> 800000 | AC11: =[4]MVTFEV!$Q11 -> 0 | AD11: =[4]MVTMARS!$N11 -> 0 | AE11: =[4]MVTMARS!$O11 -> 0 | AF11: =AB11+AD11-AG11 -> 800000 | AG11: =[4]MVTMARS!$Q11 -> 0 | AH11: =[4]MVTAVRIL!$N11 -> 0 | AI11: =[4]MVTAVRIL!$O11 -> 0 | AJ11: =AF11+AH11-AK11 -> 800000 | AK11: =[4]MVTAVRIL!$Q11 -> 0 | AL11: =[4]MVTMAI!$N11 -> 0 | AM11: =[4]MVTMAI!$O11 -> 0 | AN11: =AJ11+AL11-AO11 -> 800000 | AO11: =[4]MVTMAI!$Q11 -> 0 | AP11: =[4]MVTJUIN!$N11 -> 0 | AQ11: =[4]MVTJUIN!$O11 -> 0 | AR11: =AN11+AP11-AS11 -> 800000 | AS11: =[4]MVTJUIN!$Q11 -> 0 | AT11: =[4]MVTJUIL!$N11 -> 0 | AU11: =[4]MVTJUIL!$O11 -> 0 | AV11: =AR11+AT11-AW11 -> 800000 | AW11: =[4]MVTJUIL!$Q11 -> 0 | AX11: =[4]MVTAOUT2019!$N11 -> 0 | AY11: =[4]MVTAOUT2019!$O11 -> 0 | AZ11: =AV11+AX11-BA11 -> 800000 | BA11: =[4]MVTAOUT2019!$Q11 -> 0 | BB11: 0 | BC11: =G11+K11+O11+S11+W11+AA11+AE11+AI11+AM11+AQ11+AU11+AY11 -> 88000 | BD11: =AZ11 -> 800000 | BE11: =I11+M11+Q11+U11+Y11+AC11+AG11+AK11+AO11+AS11+AW11+BA11 -> 0 | BF11: 43678 | BG11: 34650 | BH11: OK
A12: AS201605 | B12: =VLOOKUP(A12,[3]LISTADHERENT!A$5:H$58,2,0) -> DJOUKWE NANGUEN GUY BLAISE | F12: =[4]MVTSEPT!$P12 -> 1000000 | G12: =[4]MVTSEPT!$Q12 -> 120000 | H12: =F12-I12 -> 1000000 | I12: =[4]MVTSEPT!$S12 -> 0 | J12: =[4]MVTOCT!$N12 -> 0 | K12: =[4]MVTOCT!$O12 -> 0 | L12: =H12+J12-M12 -> 1000000 | M12: =[4]MVTOCT!$Q12 -> 0 | N12: =[4]MVTNOV!$N12 -> 0 | O12: =[4]MVTNOV!$O12 -> 0 | P12: =L12+N12-Q12 -> 1000000 | Q12: =[4]MVTNOV!$Q12 -> 0 | R12: =[4]MVTDEC!$N12 -> 0 | S12: =[4]MVTDEC!$O12 -> 0 | T12: =P12+R12-U12 -> 1000000 | U12: =[4]MVTDEC!$Q12 -> 0 | V12: =[4]MVTJANV!$N12 -> 0 | W12: =[4]MVTJANV!$O12 -> 0 | X12: =T12+V12-Y12 -> 1000000 | Y12: =[4]MVTJANV!$Q12 -> 0 | Z12: =[4]MVTFEV!$N12 -> 0 | AA12: =[4]MVTFEV!$O12 -> 0 | AB12: =X12+Z12-AC12 -> 1000000 | AC12: =[4]MVTFEV!$Q12 -> 0 | AD12: =[4]MVTMARS!$N12 -> 0 | AE12: =[4]MVTMARS!$O12 -> 0 | AF12: =AB12+AD12-AG12 -> 1000000 | AG12: =[4]MVTMARS!$Q12 -> 0 | AH12: =[4]MVTAVRIL!$N12 -> 0 | AI12: =[4]MVTAVRIL!$O12 -> 0 | AJ12: =AF12+AH12-AK12 -> 1000000 | AK12: =[4]MVTAVRIL!$Q12 -> 0 | AL12: =[4]MVTMAI!$N12 -> 0 | AM12: =[4]MVTMAI!$O12 -> 0 | AN12: =AJ12+AL12-AO12 -> 1000000 | AO12: =[4]MVTMAI!$Q12 -> 0 | AP12: =[4]MVTJUIN!$N12 -> 0 | AQ12: =[4]MVTJUIN!$O12 -> 0 | AR12: =AN12+AP12-AS12 -> 1000000 | AS12: =[4]MVTJUIN!$Q12 -> 0 | AT12: =[4]MVTJUIL!$N12 -> 0 | AU12: =[4]MVTJUIL!$O12 -> 0 | AV12: =AR12+AT12-AW12 -> 1000000 | AW12: =[4]MVTJUIL!$Q12 -> 0 | AX12: =[4]MVTAOUT2019!$N12 -> 0 | AY12: =[4]MVTAOUT2019!$O12 -> 0 | AZ12: =AV12+AX12-BA12 -> 1000000 | BA12: =[4]MVTAOUT2019!$Q12 -> 0 | BB12: 0 | BC12: =G12+K12+O12+S12+W12+AA12+AE12+AI12+AM12+AQ12+AU12+AY12 -> 120000 | BD12: =AZ12 -> 1000000 | BE12: =I12+M12+Q12+U12+Y12+AC12+AG12+AK12+AO12+AS12+AW12+BA12 -> 0 | BF12: 43678 | BG12: 0
A13: AS201608 | B13: =VLOOKUP(A13,[3]LISTADHERENT!A$5:H$58,2,0) -> DJUOMBESSY ANTOINE | D13: 1000000 | F13: =[4]MVTSEPT!$P13 -> 1000000 | G13: =[4]MVTSEPT!$Q13 -> 40000 | H13: =F13-I13 -> 1000000 | I13: =[4]MVTSEPT!$S13 -> 0 | J13: =[4]MVTOCT!$N13 -> 0 | K13: =[4]MVTOCT!$O13 -> 0 | L13: =H13+J13-M13 -> 1000000 | M13: =[4]MVTOCT!$Q13 -> 0 | N13: =[4]MVTNOV!$N13 -> 0 | O13: =[4]MVTNOV!$O13 -> 0 | P13: =L13+N13-Q13 -> 1000000 | Q13: =[4]MVTNOV!$Q13 -> 0 | R13: =[4]MVTDEC!$N13 -> 0 | S13: =[4]MVTDEC!$O13 -> 70000 | T13: =P13+R13-U13 -> 1000000 | U13: =[4]MVTDEC!$Q13 -> 0 | V13: =[4]MVTJANV!$N13 -> 0 | W13: =[4]MVTJANV!$O13 -> 0 | X13: =T13+V13-Y13 -> 1000000 | Y13: =[4]MVTJANV!$Q13 -> 0 | Z13: =[4]MVTFEV!$N13 -> 0 | AA13: =[4]MVTFEV!$O13 -> 0 | AB13: =X13+Z13-AC13 -> 1000000 | AC13: =[4]MVTFEV!$Q13 -> 0 | AD13: =[4]MVTMARS!$N13 -> 0 | AE13: =[4]MVTMARS!$O13 -> 0 | AF13: =AB13+AD13-AG13 -> 1000000 | AG13: =[4]MVTMARS!$Q13 -> 0 | AH13: =[4]MVTAVRIL!$N13 -> 0 | AI13: =[4]MVTAVRIL!$O13 -> 0 | AJ13: =AF13+AH13-AK13 -> 1000000 | AK13: =[4]MVTAVRIL!$Q13 -> 0 | AL13: =[4]MVTMAI!$N13 -> 0 | AM13: =[4]MVTMAI!$O13 -> 0 | AN13: =AJ13+AL13-AO13 -> 1000000 | AO13: =[4]MVTMAI!$Q13 -> 0 | AP13: =[4]MVTJUIN!$N13 -> 0 | AQ13: =[4]MVTJUIN!$O13 -> 0 | AR13: =AN13+AP13-AS13 -> 1000000 | AS13: =[4]MVTJUIN!$Q13 -> 0 | AT13: =[4]MVTJUIL!$N13 -> 0 | AU13: =[4]MVTJUIL!$O13 -> 0 | AV13: =AR13+AT13-AW13 -> 1000000 | AW13: =[4]MVTJUIL!$Q13 -> 0 | AX13: =[4]MVTAOUT2019!$N13 -> 0 | AY13: =[4]MVTAOUT2019!$O13 -> 0 | AZ13: =AV13+AX13-BA13 -> 1000000 | BA13: =[4]MVTAOUT2019!$Q13 -> 0 | BB13: 0 | BC13: =G13+K13+O13+S13+W13+AA13+AE13+AI13+AM13+AQ13+AU13+AY13 -> 110000 | BD13: =AZ13 -> 1000000 | BE13: =I13+M13+Q13+U13+Y13+AC13+AG13+AK13+AO13+AS13+AW13+BA13 -> 0 | BF13: 43678 | BG13: 50000 | BH13: OK
A14: AS201651 | B14: =VLOOKUP(A14,[3]LISTADHERENT!A$5:H$58,2,0) -> DOMOU FABIEN | F14: =[4]MVTSEPT!$P14 -> 1000000 | G14: =[4]MVTSEPT!$Q14 -> 110000 | H14: =F14-I14 -> 1000000 | I14: =[4]MVTSEPT!$S14 -> 0 | J14: =[4]MVTOCT!$N14 -> 0 | K14: =[4]MVTOCT!$O14 -> 0 | L14: =H14+J14-M14 -> 1000000 | M14: =[4]MVTOCT!$Q14 -> 0 | N14: =[4]MVTNOV!$N14 -> 0 | O14: =[4]MVTNOV!$O14 -> 0 | P14: =L14+N14-Q14 -> 1000000 | Q14: =[4]MVTNOV!$Q14 -> 0 | R14: =[4]MVTDEC!$N14 -> 0 | S14: =[4]MVTDEC!$O14 -> 0 | T14: =P14+R14-U14 -> 1000000 | U14: =[4]MVTDEC!$Q14 -> 0 | V14: =[4]MVTJANV!$N14 -> 0 | W14: =[4]MVTJANV!$O14 -> 0 | X14: =T14+V14-Y14 -> 1000000 | Y14: =[4]MVTJANV!$Q14 -> 0 | Z14: =[4]MVTFEV!$N14 -> 0 | AA14: =[4]MVTFEV!$O14 -> 0 | AB14: =X14+Z14-AC14 -> 1000000 | AC14: =[4]MVTFEV!$Q14 -> 0 | AD14: =[4]MVTMARS!$N14 -> 0 | AE14: =[4]MVTMARS!$O14 -> 0 | AF14: =AB14+AD14-AG14 -> 1000000 | AG14: =[4]MVTMARS!$Q14 -> 0 | AH14: =[4]MVTAVRIL!$N14 -> 0 | AI14: =[4]MVTAVRIL!$O14 -> 0 | AJ14: =AF14+AH14-AK14 -> 1000000 | AK14: =[4]MVTAVRIL!$Q14 -> 0 | AL14: =[4]MVTMAI!$N14 -> 0 | AM14: =[4]MVTMAI!$O14 -> 0 | AN14: =AJ14+AL14-AO14 -> 1000000 | AO14: =[4]MVTMAI!$Q14 -> 0 | AP14: =[4]MVTJUIN!$N14 -> 0 | AQ14: =[4]MVTJUIN!$O14 -> 0 | AR14: =AN14+AP14-AS14 -> 1000000 | AS14: =[4]MVTJUIN!$Q14 -> 0 | AT14: =[4]MVTJUIL!$N14 -> 0 | AU14: =[4]MVTJUIL!$O14 -> 0 | AV14: =AR14+AT14-AW14 -> 1000000 | AW14: =[4]MVTJUIL!$Q14 -> 0 | AX14: =[4]MVTAOUT2019!$N14 -> 0 | AY14: =[4]MVTAOUT2019!$O14 -> 0 | AZ14: =AV14+AX14-BA14 -> 1000000 | BA14: =[4]MVTAOUT2019!$Q14 -> 0 | BB14: 0 | BC14: =G14+K14+O14+S14+W14+AA14+AE14+AI14+AM14+AQ14+AU14+AY14 -> 110000 | BD14: =AZ14 -> 1000000 | BE14: =I14+M14+Q14+U14+Y14+AC14+AG14+AK14+AO14+AS14+AW14+BA14 -> 0 | BF14: 43678
A15: AS201609 | B15: =VLOOKUP(A15,[3]LISTADHERENT!A$5:H$58,2,0) -> DONHOU DAVID | D15: 700000 | F15: 700000 | G15: =[4]MVTSEPT!$Q15+105800 -> 182800 | H15: 808500 | I15: =[4]MVTSEPT!$S15 -> 0 | J15: =[4]MVTOCT!$N15 -> 0 | K15: =[4]MVTOCT!$O15 -> 0 | L15: =H15+J15-M15 -> 808500 | M15: =[4]MVTOCT!$Q15 -> 0 | N15: =[4]MVTNOV!$N15 -> 0 | O15: =[4]MVTNOV!$O15 -> 0 | P15: =L15+N15-Q15 -> 808500 | Q15: =[4]MVTNOV!$Q15 -> 0 | R15: =[4]MVTDEC!$N15 -> 0 | S15: =[4]MVTDEC!$O15 -> 0 | T15: =P15+R15-U15 -> 808500 | U15: =[4]MVTDEC!$Q15 -> 0 | V15: =[4]MVTJANV!$N15 -> 0 | W15: =[4]MVTJANV!$O15 -> 0 | X15: =T15+V15-Y15 -> 808500 | Y15: =[4]MVTJANV!$Q15 -> 0 | Z15: =[4]MVTFEV!$N15 -> 0 | AA15: =[4]MVTFEV!$O15 -> 0 | AB15: =X15+Z15-AC15 -> 808500 | AC15: =[4]MVTFEV!$Q15 -> 0 | AD15: =[4]MVTMARS!$N15 -> 0 | AE15: =[4]MVTMARS!$O15 -> 0 | AF15: =AB15+AD15-AG15 -> 808500 | AG15: =[4]MVTMARS!$Q15 -> 0 | AH15: =[4]MVTAVRIL!$N15 -> 0 | AI15: =[4]MVTAVRIL!$O15 -> 0 | AJ15: =AF15+AH15-AK15 -> 808500 | AK15: =[4]MVTAVRIL!$Q15 -> 0 | AL15: =[4]MVTMAI!$N15 -> 0 | AM15: =[4]MVTMAI!$O15 -> 0 | AN15: =AJ15+AL15-AO15 -> 808500 | AO15: =[4]MVTMAI!$Q15 -> 0 | AP15: =[4]MVTJUIN!$N15 -> 0 | AQ15: =[4]MVTJUIN!$O15 -> 0 | AR15: =AN15+AP15-AS15 -> 808500 | AS15: =[4]MVTJUIN!$Q15 -> 0 | AT15: =[4]MVTJUIL!$N15 -> 0 | AU15: =[4]MVTJUIL!$O15 -> 0 | AV15: =AR15+AT15-AW15 -> 808500 | AW15: =[4]MVTJUIL!$Q15 -> 0 | AX15: =[4]MVTAOUT2019!$N15 -> 0 | AY15: =[4]MVTAOUT2019!$O15 -> 0 | AZ15: =AV15+AX15-BA15 -> 808500 | BA15: =[4]MVTAOUT2019!$Q15 -> 0 | BB15: 0 | BC15: =G15+K15+O15+S15+W15+AA15+AE15+AI15+AM15+AQ15+AU15+AY15 -> 182800 | BD15: =AZ15 -> 808500 | BE15: =I15+M15+Q15+U15+Y15+AC15+AG15+AK15+AO15+AS15+AW15+BA15 -> 0 | BF15: 43678 | BG15: 35000 | BH15: OK
A16: AS201610 | B16: =VLOOKUP(A16,[3]LISTADHERENT!A$5:H$58,2,0) -> FOTSO THOMAS | D16: =666000-666000 -> 0 | F16: =[4]MVTSEPT!$P16 -> 1000000 | G16: =[4]MVTSEPT!$Q16 -> 120000 | H16: =F16-I16 -> 1000000 | I16: =[4]MVTSEPT!$S16 -> 0 | J16: =[4]MVTOCT!$N16 -> 0 | K16: =[4]MVTOCT!$O16 -> 0 | L16: =H16+J16-M16 -> 1000000 | M16: =[4]MVTOCT!$Q16 -> 0 | N16: =[4]MVTNOV!$N16 -> 0 | O16: =[4]MVTNOV!$O16 -> 0 | P16: =L16+N16-Q16 -> 1000000 | Q16: =[4]MVTNOV!$Q16 -> 0 | R16: =[4]MVTDEC!$N16 -> 0 | S16: =[4]MVTDEC!$O16 -> 0 | T16: =P16+R16-U16 -> 1000000 | U16: =[4]MVTDEC!$Q16 -> 0 | V16: =[4]MVTJANV!$N16 -> 0 | W16: =[4]MVTJANV!$O16 -> 0 | X16: =T16+V16-Y16 -> 1000000 | Y16: =[4]MVTJANV!$Q16 -> 0 | Z16: =[4]MVTFEV!$N16 -> 0 | AA16: =[4]MVTFEV!$O16 -> 0 | AB16: =X16+Z16-AC16 -> 1000000 | AC16: =[4]MVTFEV!$Q16 -> 0 | AD16: =[4]MVTMARS!$N16 -> 0 | AE16: =[4]MVTMARS!$O16 -> 0 | AF16: =AB16+AD16-AG16 -> 1000000 | AG16: =[4]MVTMARS!$Q16 -> 0 | AH16: =[4]MVTAVRIL!$N16 -> 0 | AI16: =[4]MVTAVRIL!$O16 -> 0 | AJ16: =AF16+AH16-AK16 -> 1000000 | AK16: =[4]MVTAVRIL!$Q16 -> 0 | AL16: =[4]MVTMAI!$N16 -> 0 | AM16: =[4]MVTMAI!$O16 -> 0 | AN16: =AJ16+AL16-AO16 -> 1000000 | AO16: =[4]MVTMAI!$Q16 -> 0 | AP16: =[4]MVTJUIN!$N16 -> 0 | AQ16: =[4]MVTJUIN!$O16 -> 0 | AR16: =AN16+AP16-AS16 -> 1000000 | AS16: =[4]MVTJUIN!$Q16 -> 0 | AT16: =[4]MVTJUIL!$N16 -> 0 | AU16: =[4]MVTJUIL!$O16 -> 0 | AV16: =AR16+AT16-AW16 -> 1000000 | AW16: =[4]MVTJUIL!$Q16 -> 0 | AX16: =[4]MVTAOUT2019!$N16 -> 0 | AY16: =[4]MVTAOUT2019!$O16 -> 0 | AZ16: =AV16+AX16-BA16 -> 1000000 | BA16: =[4]MVTAOUT2019!$Q16 -> 0 | BB16: 0 | BC16: =G16+K16+O16+S16+W16+AA16+AE16+AI16+AM16+AQ16+AU16+AY16 -> 120000 | BD16: =AZ16 -> 1000000 | BE16: =I16+M16+Q16+U16+Y16+AC16+AG16+AK16+AO16+AS16+AW16+BA16 -> 0 | BF16: 43678 | BG16: 0
A17: AS201611 | B17: =VLOOKUP(A17,[3]LISTADHERENT!A$5:H$58,2,0) -> HENGUE PAUL OMER | F17: =[4]MVTSEPT!$P17 -> 0 | G17: =[4]MVTSEPT!$Q17 -> 0 | H17: =F17-I17 -> 0 | I17: =[4]MVTSEPT!$S17 -> 0 | J17: =[4]MVTOCT!$N17 -> 0 | K17: =[4]MVTOCT!$O17 -> 0 | L17: =H17+J17-M17 -> 0 | M17: =[4]MVTOCT!$Q17 -> 0 | N17: =[4]MVTNOV!$N17 -> 0 | O17: =[4]MVTNOV!$O17 -> 0 | P17: =L17+N17-Q17 -> 0 | Q17: =[4]MVTNOV!$Q17 -> 0 | R17: =[4]MVTDEC!$N17 -> 0 | S17: =[4]MVTDEC!$O17 -> 0 | T17: =P17+R17-U17 -> 0 | U17: =[4]MVTDEC!$Q17 -> 0 | V17: =[4]MVTJANV!$N17 -> 0 | W17: =[4]MVTJANV!$O17 -> 0 | X17: =T17+V17-Y17 -> 0 | Y17: =[4]MVTJANV!$Q17 -> 0 | Z17: =[4]MVTFEV!$N17 -> 0 | AA17: =[4]MVTFEV!$O17 -> 0 | AB17: =X17+Z17-AC17 -> 0 | AC17: =[4]MVTFEV!$Q17 -> 0 | AD17: =[4]MVTMARS!$N17 -> 0 | AE17: =[4]MVTMARS!$O17 -> 0 | AF17: =AB17+AD17-AG17 -> 0 | AG17: =[4]MVTMARS!$Q17 -> 0 | AH17: =[4]MVTAVRIL!$N17 -> 0 | AI17: =[4]MVTAVRIL!$O17 -> 0 | AJ17: =AF17+AH17-AK17 -> 0 | AK17: =[4]MVTAVRIL!$Q17 -> 0 | AL17: =[4]MVTMAI!$N17 -> 0 | AM17: =[4]MVTMAI!$O17 -> 0 | AN17: =AJ17+AL17-AO17 -> 0 | AO17: =[4]MVTMAI!$Q17 -> 0 | AP17: =[4]MVTJUIN!$N17 -> 0 | AQ17: =[4]MVTJUIN!$O17 -> 0 | AR17: =AN17+AP17-AS17 -> 0 | AS17: =[4]MVTJUIN!$Q17 -> 0 | AT17: =[4]MVTJUIL!$N17 -> 0 | AU17: =[4]MVTJUIL!$O17 -> 0 | AV17: =AR17+AT17-AW17 -> 0 | AW17: =[4]MVTJUIL!$Q17 -> 0 | AX17: =[4]MVTAOUT2019!$N17 -> 0 | AY17: =[4]MVTAOUT2019!$O17 -> 0 | AZ17: =AV17+AX17-BA17 -> 0 | BA17: =[4]MVTAOUT2019!$Q17 -> 0 | BB17: 0 | BC17: =G17+K17+O17+S17+W17+AA17+AE17+AI17+AM17+AQ17+AU17+AY17 -> 0 | BD17: =AZ17 -> 0 | BE17: =I17+M17+Q17+U17+Y17+AC17+AG17+AK17+AO17+AS17+AW17+BA17 -> 0 | BF17: 43678 | BG17: 0
A18: AS201613 | B18: =VLOOKUP(A18,[3]LISTADHERENT!A$5:H$58,2,0) -> HOTCHO BENJAMIN | D18: 219000 | E18: 219000 | F18: =[4]MVTSEPT!$P18 -> 0 | G18: =[4]MVTSEPT!$Q18 -> 0 | H18: =F18-I18 -> 0 | I18: =[4]MVTSEPT!$S18 -> 0 | J18: =[4]MVTOCT!$N18 -> 0 | K18: =[4]MVTOCT!$O18 -> 0 | L18: =H18+J18-M18 -> 0 | M18: =[4]MVTOCT!$Q18 -> 0 | N18: =[4]MVTNOV!$N18 -> 0 | O18: =[4]MVTNOV!$O18 -> 0 | P18: =L18+N18-Q18 -> 0 | Q18: =[4]MVTNOV!$Q18 -> 0 | R18: =[4]MVTDEC!$N18 -> 0 | S18: =[4]MVTDEC!$O18 -> 0 | T18: =P18+R18-U18 -> 0 | U18: =[4]MVTDEC!$Q18 -> 0 | V18: =[4]MVTJANV!$N18 -> 0 | W18: =[4]MVTJANV!$O18 -> 0 | X18: =T18+V18-Y18 -> 0 | Y18: =[4]MVTJANV!$Q18 -> 0 | Z18: =[4]MVTFEV!$N18 -> 0 | AA18: =[4]MVTFEV!$O18 -> 0 | AB18: =X18+Z18-AC18 -> 0 | AC18: =[4]MVTFEV!$Q18 -> 0 | AD18: =[4]MVTMARS!$N18 -> 0 | AE18: =[4]MVTMARS!$O18 -> 0 | AF18: =AB18+AD18-AG18 -> 0 | AG18: =[4]MVTMARS!$Q18 -> 0 | AH18: =[4]MVTAVRIL!$N18 -> 0 | AI18: =[4]MVTAVRIL!$O18 -> 0 | AJ18: =AF18+AH18-AK18 -> 0 | AK18: =[4]MVTAVRIL!$Q18 -> 0 | AL18: =[4]MVTMAI!$N18 -> 0 | AM18: =[4]MVTMAI!$O18 -> 0 | AN18: =AJ18+AL18-AO18 -> 0 | AO18: =[4]MVTMAI!$Q18 -> 0 | AP18: =[4]MVTJUIN!$N18 -> 0 | AQ18: =[4]MVTJUIN!$O18 -> 0 | AR18: =AN18+AP18-AS18 -> 0 | AS18: =[4]MVTJUIN!$Q18 -> 0 | AT18: =[4]MVTJUIL!$N18 -> 0 | AU18: =[4]MVTJUIL!$O18 -> 0 | AV18: =AR18+AT18-AW18 -> 0 | AW18: =[4]MVTJUIL!$Q18 -> 0 | AX18: =[4]MVTAOUT2019!$N18 -> 0 | AY18: =[4]MVTAOUT2019!$O18 -> 0 | AZ18: =AV18+AX18-BA18 -> 0 | BA18: =[4]MVTAOUT2019!$Q18 -> 0 | BB18: 0 | BC18: =G18+K18+O18+S18+W18+AA18+AE18+AI18+AM18+AQ18+AU18+AY18 -> 0 | BD18: =AZ18 -> 0 | BE18: =I18+M18+Q18+U18+Y18+AC18+AG18+AK18+AO18+AS18+AW18+BA18 -> 0 | BF18: 43678 | BG18: 10950 | BH18: OK
A19: AS201615 | B19: =VLOOKUP(A19,[3]LISTADHERENT!A$5:H$58,2,0) -> KEPSEU FRANCIS | F19: =[4]MVTSEPT!$P19 -> 0 | G19: =[4]MVTSEPT!$Q19 -> 0 | H19: =F19-I19 -> 0 | I19: =[4]MVTSEPT!$S19 -> 0 | J19: =[4]MVTOCT!$N19 -> 0 | K19: =[4]MVTOCT!$O19 -> 0 | L19: =H19+J19-M19 -> 0 | M19: =[4]MVTOCT!$Q19 -> 0 | N19: =[4]MVTNOV!$N19 -> 0 | O19: =[4]MVTNOV!$O19 -> 0 | P19: =L19+N19-Q19 -> 0 | Q19: =[4]MVTNOV!$Q19 -> 0 | R19: =[4]MVTDEC!$N19 -> 0 | S19: =[4]MVTDEC!$O19 -> 0 | T19: =P19+R19-U19 -> 0 | U19: =[4]MVTDEC!$Q19 -> 0 | V19: =[4]MVTJANV!$N19 -> 0 | W19: =[4]MVTJANV!$O19 -> 0 | X19: =T19+V19-Y19 -> 0 | Y19: =[4]MVTJANV!$Q19 -> 0 | Z19: =[4]MVTFEV!$N19 -> 0 | AA19: =[4]MVTFEV!$O19 -> 0 | AB19: =X19+Z19-AC19 -> 0 | AC19: =[4]MVTFEV!$Q19 -> 0 | AD19: =[4]MVTMARS!$N19 -> 0 | AE19: =[4]MVTMARS!$O19 -> 0 | AF19: =AB19+AD19-AG19 -> 0 | AG19: =[4]MVTMARS!$Q19 -> 0 | AH19: =[4]MVTAVRIL!$N19 -> 0 | AI19: =[4]MVTAVRIL!$O19 -> 0 | AJ19: =AF19+AH19-AK19 -> 0 | AK19: =[4]MVTAVRIL!$Q19 -> 0 | AL19: =[4]MVTMAI!$N19 -> 0 | AM19: =[4]MVTMAI!$O19 -> 0 | AN19: =AJ19+AL19-AO19 -> 0 | AO19: =[4]MVTMAI!$Q19 -> 0 | AP19: =[4]MVTJUIN!$N19 -> 0 | AQ19: =[4]MVTJUIN!$O19 -> 0 | AR19: =AN19+AP19-AS19 -> 0 | AS19: =[4]MVTJUIN!$Q19 -> 0 | AT19: =[4]MVTJUIL!$N19 -> 0 | AU19: =[4]MVTJUIL!$O19 -> 0 | AV19: =AR19+AT19-AW19 -> 0 | AW19: =[4]MVTJUIL!$Q19 -> 0 | AX19: =[4]MVTAOUT2019!$N19 -> 0 | AY19: =[4]MVTAOUT2019!$O19 -> 0 | AZ19: =AV19+AX19-BA19 -> 0 | BA19: =[4]MVTAOUT2019!$Q19 -> 0 | BB19: 0 | BC19: =G19+K19+O19+S19+W19+AA19+AE19+AI19+AM19+AQ19+AU19+AY19 -> 0 | BD19: =AZ19 -> 0 | BE19: =I19+M19+Q19+U19+Y19+AC19+AG19+AK19+AO19+AS19+AW19+BA19 -> 0 | BF19: 43678 | BG19: 0
A20: AS201618 | B20: =VLOOKUP(A20,[3]LISTADHERENT!A$5:H$58,2,0) -> KOUAMO VICTOR PEGUY | D20: 700000 | F20: =[4]MVTSEPT!$P20 -> 900000 | G20: =[4]MVTSEPT!$Q20 -> 99000 | H20: =F20-I20 -> 900000 | I20: =[4]MVTSEPT!$S20 -> 0 | J20: =[4]MVTOCT!$N20 -> 0 | K20: =[4]MVTOCT!$O20 -> 0 | L20: =H20+J20-M20 -> 900000 | M20: =[4]MVTOCT!$Q20 -> 0 | N20: =[4]MVTNOV!$N20 -> 0 | O20: =[4]MVTNOV!$O20 -> 0 | P20: =L20+N20-Q20 -> 900000 | Q20: =[4]MVTNOV!$Q20 -> 0 | R20: =[4]MVTDEC!$N20 -> 0 | S20: =[4]MVTDEC!$O20 -> 0 | T20: =P20+R20-U20 -> 900000 | U20: =[4]MVTDEC!$Q20 -> 0 | V20: =[4]MVTJANV!$N20 -> 0 | W20: =[4]MVTJANV!$O20 -> 0 | X20: =T20+V20-Y20 -> 900000 | Y20: =[4]MVTJANV!$Q20 -> 0 | Z20: =[4]MVTFEV!$N20 -> 0 | AA20: =[4]MVTFEV!$O20 -> 0 | AB20: =X20+Z20-AC20 -> 900000 | AC20: =[4]MVTFEV!$Q20 -> 0 | AD20: =[4]MVTMARS!$N20 -> 0 | AE20: =[4]MVTMARS!$O20 -> 0 | AF20: =AB20+AD20-AG20 -> 900000 | AG20: =[4]MVTMARS!$Q20 -> 0 | AH20: =[4]MVTAVRIL!$N20 -> 0 | AI20: =[4]MVTAVRIL!$O20 -> 0 | AJ20: =AF20+AH20-AK20 -> 900000 | AK20: =[4]MVTAVRIL!$Q20 -> 0 | AL20: =[4]MVTMAI!$N20 -> 0 | AM20: =[4]MVTMAI!$O20 -> 0 | AN20: =AJ20+AL20-AO20 -> 900000 | AO20: =[4]MVTMAI!$Q20 -> 0 | AP20: =[4]MVTJUIN!$N20 -> 0 | AQ20: =[4]MVTJUIN!$O20 -> 0 | AR20: =AN20+AP20-AS20 -> 900000 | AS20: =[4]MVTJUIN!$Q20 -> 0 | AT20: =[4]MVTJUIL!$N20 -> 0 | AU20: =[4]MVTJUIL!$O20 -> 0 | AV20: =AR20+AT20-AW20 -> 900000 | AW20: =[4]MVTJUIL!$Q20 -> 0 | AX20: =[4]MVTAOUT2019!$N20 -> 0 | AY20: =[4]MVTAOUT2019!$O20 -> 0 | AZ20: =AV20+AX20-BA20 -> 900000 | BA20: =[4]MVTAOUT2019!$Q20 -> 0 | BB20: 0 | BC20: =G20+K20+O20+S20+W20+AA20+AE20+AI20+AM20+AQ20+AU20+AY20 -> 99000 | BD20: =AZ20 -> 900000 | BE20: =I20+M20+Q20+U20+Y20+AC20+AG20+AK20+AO20+AS20+AW20+BA20 -> 0 | BF20: 43678 | BG20: 35000 | BH20: OK
A21: AS201616 | B21: =VLOOKUP(A21,[3]LISTADHERENT!A$5:H$58,2,0) -> KOUAMOU EMMANUEL | D21: 648000 | F21: =[4]MVTSEPT!$P21 -> 700000 | G21: =[4]MVTSEPT!$Q21 -> 77000 | H21: =F21-I21 -> 700000 | I21: =[4]MVTSEPT!$S21 -> 0 | J21: =[4]MVTOCT!$N21 -> 0 | K21: =[4]MVTOCT!$O21 -> 0 | L21: =H21+J21-M21 -> 700000 | M21: =[4]MVTOCT!$Q21 -> 0 | N21: =[4]MVTNOV!$N21 -> 0 | O21: =[4]MVTNOV!$O21 -> 0 | P21: =L21+N21-Q21 -> 700000 | Q21: =[4]MVTNOV!$Q21 -> 0 | R21: =[4]MVTDEC!$N21 -> 0 | S21: =[4]MVTDEC!$O21 -> 0 | T21: =P21+R21-U21 -> 700000 | U21: =[4]MVTDEC!$Q21 -> 0 | V21: =[4]MVTJANV!$N21 -> 0 | W21: =[4]MVTJANV!$O21 -> 0 | X21: =T21+V21-Y21 -> 700000 | Y21: =[4]MVTJANV!$Q21 -> 0 | Z21: =[4]MVTFEV!$N21 -> 0 | AA21: =[4]MVTFEV!$O21 -> 0 | AB21: =X21+Z21-AC21 -> 700000 | AC21: =[4]MVTFEV!$Q21 -> 0 | AD21: =[4]MVTMARS!$N21 -> 0 | AE21: =[4]MVTMARS!$O21 -> 0 | AF21: =AB21+AD21-AG21 -> 700000 | AG21: =[4]MVTMARS!$Q21 -> 0 | AH21: =[4]MVTAVRIL!$N21 -> 0 | AI21: =[4]MVTAVRIL!$O21 -> 0 | AJ21: =AF21+AH21-AK21 -> 700000 | AK21: =[4]MVTAVRIL!$Q21 -> 0 | AL21: =[4]MVTMAI!$N21 -> 0 | AM21: =[4]MVTMAI!$O21 -> 0 | AN21: =AJ21+AL21-AO21 -> 700000 | AO21: =[4]MVTMAI!$Q21 -> 0 | AP21: =[4]MVTJUIN!$N21 -> 0 | AQ21: =[4]MVTJUIN!$O21 -> 0 | AR21: =AN21+AP21-AS21 -> 700000 | AS21: =[4]MVTJUIN!$Q21 -> 0 | AT21: =[4]MVTJUIL!$N21 -> 0 | AU21: =[4]MVTJUIL!$O21 -> 0 | AV21: =AR21+AT21-AW21 -> 700000 | AW21: =[4]MVTJUIL!$Q21 -> 0 | AX21: =[4]MVTAOUT2019!$N21 -> 0 | AY21: =[4]MVTAOUT2019!$O21 -> 0 | AZ21: =AV21+AX21-BA21 -> 700000 | BA21: =[4]MVTAOUT2019!$Q21 -> 0 | BB21: 0 | BC21: =G21+K21+O21+S21+W21+AA21+AE21+AI21+AM21+AQ21+AU21+AY21 -> 77000 | BD21: =AZ21 -> 700000 | BE21: =I21+M21+Q21+U21+Y21+AC21+AG21+AK21+AO21+AS21+AW21+BA21 -> 0 | BF21: 43678 | BG21: 32400 | BH21: OK
A22: AS201617 | B22: =VLOOKUP(A22,[3]LISTADHERENT!A$5:H$58,2,0) -> KOUAMOU MOISE | F22: =[4]MVTSEPT!$P22 -> 1000000 | G22: =[4]MVTSEPT!$Q22 -> 110000 | H22: =F22-I22 -> 1000000 | I22: =[4]MVTSEPT!$S22 -> 0 | J22: =[4]MVTOCT!$N22 -> 0 | K22: =[4]MVTOCT!$O22 -> 0 | L22: =H22+J22-M22 -> 1000000 | M22: =[4]MVTOCT!$Q22 -> 0 | N22: =[4]MVTNOV!$N22 -> 0 | O22: =[4]MVTNOV!$O22 -> 0 | P22: =L22+N22-Q22 -> 1000000 | Q22: =[4]MVTNOV!$Q22 -> 0 | R22: =[4]MVTDEC!$N22 -> 0 | S22: =[4]MVTDEC!$O22 -> 0 | T22: =P22+R22-U22 -> 1000000 | U22: =[4]MVTDEC!$Q22 -> 0 | V22: =[4]MVTJANV!$N22 -> 0 | W22: =[4]MVTJANV!$O22 -> 0 | X22: =T22+V22-Y22 -> 1000000 | Y22: =[4]MVTJANV!$Q22 -> 0 | Z22: =[4]MVTFEV!$N22 -> 0 | AA22: =[4]MVTFEV!$O22 -> 0 | AB22: =X22+Z22-AC22 -> 1000000 | AC22: =[4]MVTFEV!$Q22 -> 0 | AD22: =[4]MVTMARS!$N22 -> 0 | AE22: =[4]MVTMARS!$O22 -> 0 | AF22: =AB22+AD22-AG22 -> 1000000 | AG22: =[4]MVTMARS!$Q22 -> 0 | AH22: =[4]MVTAVRIL!$N22 -> 0 | AI22: =[4]MVTAVRIL!$O22 -> 0 | AJ22: =AF22+AH22-AK22 -> 1000000 | AK22: =[4]MVTAVRIL!$Q22 -> 0 | AL22: =[4]MVTMAI!$N22 -> 0 | AM22: =[4]MVTMAI!$O22 -> 0 | AN22: =AJ22+AL22-AO22 -> 1000000 | AO22: =[4]MVTMAI!$Q22 -> 0 | AP22: =[4]MVTJUIN!$N22 -> 0 | AQ22: =[4]MVTJUIN!$O22 -> 0 | AR22: =AN22+AP22-AS22 -> 1000000 | AS22: =[4]MVTJUIN!$Q22 -> 0 | AT22: =[4]MVTJUIL!$N22 -> 0 | AU22: =[4]MVTJUIL!$O22 -> 0 | AV22: =AR22+AT22-AW22 -> 1000000 | AW22: =[4]MVTJUIL!$Q22 -> 0 | AX22: =[4]MVTAOUT2019!$N22 -> 0 | AY22: =[4]MVTAOUT2019!$O22 -> 0 | AZ22: =AV22+AX22-BA22 -> 1000000 | BA22: =[4]MVTAOUT2019!$Q22 -> 0 | BB22: 0 | BC22: =G22+K22+O22+S22+W22+AA22+AE22+AI22+AM22+AQ22+AU22+AY22 -> 110000 | BD22: =AZ22 -> 1000000 | BE22: =I22+M22+Q22+U22+Y22+AC22+AG22+AK22+AO22+AS22+AW22+BA22 -> 0 | BF22: 43678 | BG22: 800 | BH22: OK
A23: AS201619 | B23: =VLOOKUP(A23,[3]LISTADHERENT!A$5:H$58,2,0) -> KOUATCHO MESSACK | D23: =850000-850000 -> 0 | F23: =[4]MVTSEPT!$P23 -> 1000000 | G23: =[4]MVTSEPT!$Q23 -> 110000 | H23: =F23-I23 -> 1000000 | I23: =[4]MVTSEPT!$S23 -> 0 | J23: =[4]MVTOCT!$N23 -> 0 | K23: =[4]MVTOCT!$O23 -> 0 | L23: =H23+J23-M23 -> 1000000 | M23: =[4]MVTOCT!$Q23 -> 0 | N23: =[4]MVTNOV!$N23 -> 0 | O23: =[4]MVTNOV!$O23 -> 0 | P23: =L23+N23-Q23 -> 1000000 | Q23: =[4]MVTNOV!$Q23 -> 0 | R23: =[4]MVTDEC!$N23 -> 0 | S23: =[4]MVTDEC!$O23 -> 0 | T23: =P23+R23-U23 -> 1000000 | U23: =[4]MVTDEC!$Q23 -> 0 | V23: =[4]MVTJANV!$N23 -> 0 | W23: =[4]MVTJANV!$O23 -> 0 | X23: =T23+V23-Y23 -> 1000000 | Y23: =[4]MVTJANV!$Q23 -> 0 | Z23: =[4]MVTFEV!$N23 -> 0 | AA23: =[4]MVTFEV!$O23 -> 0 | AB23: =X23+Z23-AC23 -> 1000000 | AC23: =[4]MVTFEV!$Q23 -> 0 | AD23: =[4]MVTMARS!$N23 -> 0 | AE23: =[4]MVTMARS!$O23 -> 0 | AF23: =AB23+AD23-AG23 -> 1000000 | AG23: =[4]MVTMARS!$Q23 -> 0 | AH23: =[4]MVTAVRIL!$N23 -> 0 | AI23: =[4]MVTAVRIL!$O23 -> 0 | AJ23: =AF23+AH23-AK23 -> 1000000 | AK23: =[4]MVTAVRIL!$Q23 -> 0 | AL23: =[4]MVTMAI!$N23 -> 0 | AM23: =[4]MVTMAI!$O23 -> 0 | AN23: =AJ23+AL23-AO23 -> 1000000 | AO23: =[4]MVTMAI!$Q23 -> 0 | AP23: =[4]MVTJUIN!$N23 -> 0 | AQ23: =[4]MVTJUIN!$O23 -> 0 | AR23: =AN23+AP23-AS23 -> 1000000 | AS23: =[4]MVTJUIN!$Q23 -> 0 | AT23: =[4]MVTJUIL!$N23 -> 0 | AU23: =[4]MVTJUIL!$O23 -> 0 | AV23: =AR23+AT23-AW23 -> 1000000 | AW23: =[4]MVTJUIL!$Q23 -> 0 | AX23: =[4]MVTAOUT2019!$N23 -> 0 | AY23: =[4]MVTAOUT2019!$O23 -> 0 | AZ23: =AV23+AX23-BA23 -> 1000000 | BA23: =[4]MVTAOUT2019!$Q23 -> 0 | BB23: 0 | BC23: =G23+K23+O23+S23+W23+AA23+AE23+AI23+AM23+AQ23+AU23+AY23 -> 110000 | BD23: =AZ23 -> 1000000 | BE23: =I23+M23+Q23+U23+Y23+AC23+AG23+AK23+AO23+AS23+AW23+BA23 -> 0 | BF23: 43678 | BG23: 0
A24: AS201620 | B24: =VLOOKUP(A24,[3]LISTADHERENT!A$5:H$58,2,0) -> LOWE JEAN | D24: 168000 | F24: =[4]MVTSEPT!$P24 -> 176400 | G24: =[4]MVTSEPT!$Q24 -> 19404 | H24: =F24-I24 -> 0 | I24: =[4]MVTSEPT!$S24 -> 176400 | J24: =[4]MVTOCT!$N24 -> 0 | K24: =[4]MVTOCT!$O24 -> 0 | L24: =H24+J24-M24 -> 0 | M24: =[4]MVTOCT!$Q24 -> 0 | N24: =[4]MVTNOV!$N24 -> 0 | O24: =[4]MVTNOV!$O24 -> 0 | P24: =L24+N24-Q24 -> 0 | Q24: =[4]MVTNOV!$Q24 -> 0 | R24: =[4]MVTDEC!$N24 -> 0 | S24: =[4]MVTDEC!$O24 -> 0 | T24: =P24+R24-U24 -> 0 | U24: =[4]MVTDEC!$Q24 -> 0 | V24: =[4]MVTJANV!$N24 -> 0 | W24: =[4]MVTJANV!$O24 -> 0 | X24: =T24+V24-Y24 -> 0 | Y24: =[4]MVTJANV!$Q24 -> 0 | Z24: =[4]MVTFEV!$N24 -> 0 | AA24: =[4]MVTFEV!$O24 -> 0 | AB24: =X24+Z24-AC24 -> 0 | AC24: =[4]MVTFEV!$Q24 -> 0 | AD24: =[4]MVTMARS!$N24 -> 0 | AE24: =[4]MVTMARS!$O24 -> 0 | AF24: =AB24+AD24-AG24 -> 0 | AG24: =[4]MVTMARS!$Q24 -> 0 | AH24: =[4]MVTAVRIL!$N24 -> 0 | AI24: =[4]MVTAVRIL!$O24 -> 0 | AJ24: =AF24+AH24-AK24 -> 0 | AK24: =[4]MVTAVRIL!$Q24 -> 0 | AL24: =[4]MVTMAI!$N24 -> 0 | AM24: =[4]MVTMAI!$O24 -> 0 | AN24: =AJ24+AL24-AO24 -> 0 | AO24: =[4]MVTMAI!$Q24 -> 0 | AP24: =[4]MVTJUIN!$N24 -> 0 | AQ24: =[4]MVTJUIN!$O24 -> 0 | AR24: =AN24+AP24-AS24 -> 0 | AS24: =[4]MVTJUIN!$Q24 -> 0 | AT24: =[4]MVTJUIL!$N24 -> 0 | AU24: =[4]MVTJUIL!$O24 -> 0 | AV24: =AR24+AT24-AW24 -> 0 | AW24: =[4]MVTJUIL!$Q24 -> 0 | AX24: =[4]MVTAOUT2019!$N24 -> 0 | AY24: =[4]MVTAOUT2019!$O24 -> 0 | AZ24: =AV24+AX24-BA24 -> 0 | BA24: =[4]MVTAOUT2019!$Q24 -> 0 | BB24: 0 | BC24: =G24+K24+O24+S24+W24+AA24+AE24+AI24+AM24+AQ24+AU24+AY24 -> 19404 | BD24: =AZ24 -> 0 | BE24: =I24+M24+Q24+U24+Y24+AC24+AG24+AK24+AO24+AS24+AW24+BA24 -> 176400 | BF24: 43678 | BG24: 8400 | BH24: OK
A25: AS201649 | B25: =VLOOKUP(A25,[3]LISTADHERENT!A$5:H$58,2,0) -> MBOGNING TUGMA GUY | D25: =1060000-1060000 -> 0 | F25: =[4]MVTSEPT!$P25 -> 900000 | G25: =[4]MVTSEPT!$Q25 -> 108000 | H25: =F25-I25 -> 900000 | I25: =[4]MVTSEPT!$S25 -> 0 | J25: =[4]MVTOCT!$N25 -> 0 | K25: =[4]MVTOCT!$O25 -> 0 | L25: =H25+J25-M25 -> 900000 | M25: =[4]MVTOCT!$Q25 -> 0 | N25: =[4]MVTNOV!$N25 -> 0 | O25: =[4]MVTNOV!$O25 -> 0 | P25: =L25+N25-Q25 -> 900000 | Q25: =[4]MVTNOV!$Q25 -> 0 | R25: =[4]MVTDEC!$N25 -> 0 | S25: =[4]MVTDEC!$O25 -> 0 | T25: =P25+R25-U25 -> 900000 | U25: =[4]MVTDEC!$Q25 -> 0 | V25: =[4]MVTJANV!$N25 -> 0 | W25: =[4]MVTJANV!$O25 -> 0 | X25: =T25+V25-Y25 -> 900000 | Y25: =[4]MVTJANV!$Q25 -> 0 | Z25: =[4]MVTFEV!$N25 -> 0 | AA25: =[4]MVTFEV!$O25 -> 0 | AB25: =X25+Z25-AC25 -> 900000 | AC25: =[4]MVTFEV!$Q25 -> 0 | AD25: =[4]MVTMARS!$N25 -> 0 | AE25: =[4]MVTMARS!$O25 -> 0 | AF25: =AB25+AD25-AG25 -> 900000 | AG25: =[4]MVTMARS!$Q25 -> 0 | AH25: =[4]MVTAVRIL!$N25 -> 0 | AI25: =[4]MVTAVRIL!$O25 -> 0 | AJ25: =AF25+AH25-AK25 -> 900000 | AK25: =[4]MVTAVRIL!$Q25 -> 0 | AL25: =[4]MVTMAI!$N25 -> 0 | AM25: =[4]MVTMAI!$O25 -> 0 | AN25: =AJ25+AL25-AO25 -> 900000 | AO25: =[4]MVTMAI!$Q25 -> 0 | AP25: =[4]MVTJUIN!$N25 -> 0 | AQ25: =[4]MVTJUIN!$O25 -> 0 | AR25: =AN25+AP25-AS25 -> 900000 | AS25: =[4]MVTJUIN!$Q25 -> 0 | AT25: =[4]MVTJUIL!$N25 -> 0 | AU25: =[4]MVTJUIL!$O25 -> 0 | AV25: =AR25+AT25-AW25 -> 900000 | AW25: =[4]MVTJUIL!$Q25 -> 0 | AX25: =[4]MVTAOUT2019!$N25 -> 0 | AY25: =[4]MVTAOUT2019!$O25 -> 0 | AZ25: =AV25+AX25-BA25 -> 900000 | BA25: =[4]MVTAOUT2019!$Q25 -> 0 | BB25: 0 | BC25: =G25+K25+O25+S25+W25+AA25+AE25+AI25+AM25+AQ25+AU25+AY25 -> 108000 | BD25: =AZ25 -> 900000 | BE25: =I25+M25+Q25+U25+Y25+AC25+AG25+AK25+AO25+AS25+AW25+BA25 -> 0 | BF25: 43678 | BG25: 0
A26: AS201639 | B26: =VLOOKUP(A26,[3]LISTADHERENT!A$5:H$58,2,0) -> NANGUEN MARTIN | F26: =[4]MVTSEPT!$P26 -> 0 | G26: =[4]MVTSEPT!$Q26 -> 0 | H26: =F26-I26 -> 0 | I26: =[4]MVTSEPT!$S26 -> 0 | J26: =[4]MVTOCT!$N26 -> 0 | K26: =[4]MVTOCT!$O26 -> 0 | L26: =H26+J26-M26 -> 0 | M26: =[4]MVTOCT!$Q26 -> 0 | N26: =[4]MVTNOV!$N26 -> 0 | O26: =[4]MVTNOV!$O26 -> 0 | P26: =L26+N26-Q26 -> 0 | Q26: =[4]MVTNOV!$Q26 -> 0 | R26: =[4]MVTDEC!$N26 -> 0 | S26: =[4]MVTDEC!$O26 -> 0 | T26: =P26+R26-U26 -> 0 | U26: =[4]MVTDEC!$Q26 -> 0 | V26: =[4]MVTJANV!$N26 -> 0 | W26: =[4]MVTJANV!$O26 -> 0 | X26: =T26+V26-Y26 -> 0 | Y26: =[4]MVTJANV!$Q26 -> 0 | Z26: =[4]MVTFEV!$N26 -> 0 | AA26: =[4]MVTFEV!$O26 -> 0 | AB26: =X26+Z26-AC26 -> 0 | AC26: =[4]MVTFEV!$Q26 -> 0 | AD26: =[4]MVTMARS!$N26 -> 0 | AE26: =[4]MVTMARS!$O26 -> 0 | AF26: =AB26+AD26-AG26 -> 0 | AG26: =[4]MVTMARS!$Q26 -> 0 | AH26: =[4]MVTAVRIL!$N26 -> 0 | AI26: =[4]MVTAVRIL!$O26 -> 0 | AJ26: =AF26+AH26-AK26 -> 0 | AK26: =[4]MVTAVRIL!$Q26 -> 0 | AL26: =[4]MVTMAI!$N26 -> 0 | AM26: =[4]MVTMAI!$O26 -> 0 | AN26: =AJ26+AL26-AO26 -> 0 | AO26: =[4]MVTMAI!$Q26 -> 0 | AP26: =[4]MVTJUIN!$N26 -> 0 | AQ26: =[4]MVTJUIN!$O26 -> 0 | AR26: =AN26+AP26-AS26 -> 0 | AS26: =[4]MVTJUIN!$Q26 -> 0 | AT26: =[4]MVTJUIL!$N26 -> 0 | AU26: =[4]MVTJUIL!$O26 -> 0 | AV26: =AR26+AT26-AW26 -> 0 | AW26: =[4]MVTJUIL!$Q26 -> 0 | AX26: =[4]MVTAOUT2019!$N26 -> 0 | AY26: =[4]MVTAOUT2019!$O26 -> 0 | AZ26: =AV26+AX26-BA26 -> 0 | BA26: =[4]MVTAOUT2019!$Q26 -> 0 | BB26: 0 | BC26: =G26+K26+O26+S26+W26+AA26+AE26+AI26+AM26+AQ26+AU26+AY26 -> 0 | BD26: =AZ26 -> 0 | BE26: =I26+M26+Q26+U26+Y26+AC26+AG26+AK26+AO26+AS26+AW26+BA26 -> 0 | BF26: 43678 | BG26: 0
A27: AS201621 | B27: =VLOOKUP(A27,[3]LISTADHERENT!A$5:H$58,2,0) -> NANKAM APPOLINAIRE | F27: =[4]MVTSEPT!$P27 -> 1000000 | G27: =[4]MVTSEPT!$Q27 -> 110000 | H27: =F27-I27 -> 1000000 | I27: =[4]MVTSEPT!$S27 -> 0 | J27: =[4]MVTOCT!$N27 -> 0 | K27: =[4]MVTOCT!$O27 -> 0 | L27: =H27+J27-M27 -> 1000000 | M27: =[4]MVTOCT!$Q27 -> 0 | N27: =[4]MVTNOV!$N27 -> 0 | O27: =[4]MVTNOV!$O27 -> 0 | P27: =L27+N27-Q27 -> 1000000 | Q27: =[4]MVTNOV!$Q27 -> 0 | R27: =[4]MVTDEC!$N27 -> 0 | S27: =[4]MVTDEC!$O27 -> 0 | T27: =P27+R27-U27 -> 1000000 | U27: =[4]MVTDEC!$Q27 -> 0 | V27: =[4]MVTJANV!$N27 -> 0 | W27: =[4]MVTJANV!$O27 -> 0 | X27: =T27+V27-Y27 -> 1000000 | Y27: =[4]MVTJANV!$Q27 -> 0 | Z27: =[4]MVTFEV!$N27 -> 0 | AA27: =[4]MVTFEV!$O27 -> 0 | AB27: =X27+Z27-AC27 -> 1000000 | AC27: =[4]MVTFEV!$Q27 -> 0 | AD27: =[4]MVTMARS!$N27 -> 0 | AE27: =[4]MVTMARS!$O27 -> 0 | AF27: =AB27+AD27-AG27 -> 1000000 | AG27: =[4]MVTMARS!$Q27 -> 0 | AH27: =[4]MVTAVRIL!$N27 -> 0 | AI27: =[4]MVTAVRIL!$O27 -> 0 | AJ27: =AF27+AH27-AK27 -> 1000000 | AK27: =[4]MVTAVRIL!$Q27 -> 0 | AL27: =[4]MVTMAI!$N27 -> 0 | AM27: =[4]MVTMAI!$O27 -> 0 | AN27: =AJ27+AL27-AO27 -> 1000000 | AO27: =[4]MVTMAI!$Q27 -> 0 | AP27: =[4]MVTJUIN!$N27 -> 0 | AQ27: =[4]MVTJUIN!$O27 -> 0 | AR27: =AN27+AP27-AS27 -> 1000000 | AS27: =[4]MVTJUIN!$Q27 -> 0 | AT27: =[4]MVTJUIL!$N27 -> 0 | AU27: =[4]MVTJUIL!$O27 -> 0 | AV27: =AR27+AT27-AW27 -> 1000000 | AW27: =[4]MVTJUIL!$Q27 -> 0 | AX27: =[4]MVTAOUT2019!$N27 -> 0 | AY27: =[4]MVTAOUT2019!$O27 -> 0 | AZ27: =AV27+AX27-BA27 -> 1000000 | BA27: =[4]MVTAOUT2019!$Q27 -> 0 | BB27: 0 | BC27: =G27+K27+O27+S27+W27+AA27+AE27+AI27+AM27+AQ27+AU27+AY27 -> 110000 | BD27: =AZ27 -> 1000000 | BE27: =I27+M27+Q27+U27+Y27+AC27+AG27+AK27+AO27+AS27+AW27+BA27 -> 0 | BF27: 43678 | BG27: 0
A28: AS201622 | B28: =VLOOKUP(A28,[3]LISTADHERENT!A$5:H$58,2,0) -> NDJOMO ETIENNE | F28: =[4]MVTSEPT!$P28 -> 500000 | G28: =[4]MVTSEPT!$Q28 -> 50000 | H28: =F28-I28 -> 500000 | I28: =[4]MVTSEPT!$S28 -> 0 | J28: =[4]MVTOCT!$N28 -> 0 | K28: =[4]MVTOCT!$O28 -> 0 | L28: =H28+J28-M28 -> 500000 | M28: =[4]MVTOCT!$Q28 -> 0 | N28: =[4]MVTNOV!$N28 -> 0 | O28: =[4]MVTNOV!$O28 -> 0 | P28: =L28+N28-Q28 -> 500000 | Q28: =[4]MVTNOV!$Q28 -> 0 | R28: =[4]MVTDEC!$N28 -> 0 | S28: =[4]MVTDEC!$O28 -> 0 | T28: =P28+R28-U28 -> 500000 | U28: =[4]MVTDEC!$Q28 -> 0 | V28: =[4]MVTJANV!$N28 -> 0 | W28: =[4]MVTJANV!$O28 -> 0 | X28: =T28+V28-Y28 -> 500000 | Y28: =[4]MVTJANV!$Q28 -> 0 | Z28: =[4]MVTFEV!$N28 -> 0 | AA28: =[4]MVTFEV!$O28 -> 0 | AB28: =X28+Z28-AC28 -> 500000 | AC28: =[4]MVTFEV!$Q28 -> 0 | AD28: =[4]MVTMARS!$N28 -> 0 | AE28: =[4]MVTMARS!$O28 -> 0 | AF28: =AB28+AD28-AG28 -> 500000 | AG28: =[4]MVTMARS!$Q28 -> 0 | AH28: =[4]MVTAVRIL!$N28 -> 0 | AI28: =[4]MVTAVRIL!$O28 -> 0 | AJ28: =AF28+AH28-AK28 -> 500000 | AK28: =[4]MVTAVRIL!$Q28 -> 0 | AL28: =[4]MVTMAI!$N28 -> 0 | AM28: =[4]MVTMAI!$O28 -> 0 | AN28: =AJ28+AL28-AO28 -> 500000 | AO28: =[4]MVTMAI!$Q28 -> 0 | AP28: =[4]MVTJUIN!$N28 -> 0 | AQ28: =[4]MVTJUIN!$O28 -> 0 | AR28: =AN28+AP28-AS28 -> 500000 | AS28: =[4]MVTJUIN!$Q28 -> 0 | AT28: =[4]MVTJUIL!$N28 -> 0 | AU28: =[4]MVTJUIL!$O28 -> 0 | AV28: =AR28+AT28-AW28 -> 500000 | AW28: =[4]MVTJUIL!$Q28 -> 0 | AX28: =[4]MVTAOUT2019!$N28 -> 0 | AY28: =[4]MVTAOUT2019!$O28 -> 0 | AZ28: =AV28+AX28-BA28 -> 500000 | BA28: =[4]MVTAOUT2019!$Q28 -> 0 | BB28: 0 | BC28: =G28+K28+O28+S28+W28+AA28+AE28+AI28+AM28+AQ28+AU28+AY28 -> 50000 | BD28: =AZ28 -> 500000 | BE28: =I28+M28+Q28+U28+Y28+AC28+AG28+AK28+AO28+AS28+AW28+BA28 -> 0 | BF28: 43617
A29: AS201652 | B29: =VLOOKUP(A29,[3]LISTADHERENT!A$5:H$58,2,0) -> NGANHOU JEAN | F29: =[4]MVTSEPT!$P29 -> 0 | G29: =[4]MVTSEPT!$Q29 -> 0 | H29: =F29-I29 -> 0 | I29: =[4]MVTSEPT!$S29 -> 0 | J29: =[4]MVTOCT!$N29 -> 0 | K29: =[4]MVTOCT!$O29 -> 0 | L29: =H29+J29-M29 -> 0 | M29: =[4]MVTOCT!$Q29 -> 0 | N29: =[4]MVTNOV!$N29 -> 0 | O29: =[4]MVTNOV!$O29 -> 0 | P29: =L29+N29-Q29 -> 0 | Q29: =[4]MVTNOV!$Q29 -> 0 | R29: =[4]MVTDEC!$N29 -> 0 | S29: =[4]MVTDEC!$O29 -> 0 | T29: =P29+R29-U29 -> 0 | U29: =[4]MVTDEC!$Q29 -> 0 | V29: =[4]MVTJANV!$N29 -> 0 | W29: =[4]MVTJANV!$O29 -> 0 | X29: =T29+V29-Y29 -> 0 | Y29: =[4]MVTJANV!$Q29 -> 0 | Z29: =[4]MVTFEV!$N29 -> 0 | AA29: =[4]MVTFEV!$O29 -> 0 | AB29: =X29+Z29-AC29 -> 0 | AC29: =[4]MVTFEV!$Q29 -> 0 | AD29: =[4]MVTMARS!$N29 -> 0 | AE29: =[4]MVTMARS!$O29 -> 0 | AF29: =AB29+AD29-AG29 -> 0 | AG29: =[4]MVTMARS!$Q29 -> 0 | AH29: =[4]MVTAVRIL!$N29 -> 0 | AI29: =[4]MVTAVRIL!$O29 -> 0 | AJ29: =AF29+AH29-AK29 -> 0 | AK29: =[4]MVTAVRIL!$Q29 -> 0 | AL29: =[4]MVTMAI!$N29 -> 0 | AM29: =[4]MVTMAI!$O29 -> 0 | AN29: =AJ29+AL29-AO29 -> 0 | AO29: =[4]MVTMAI!$Q29 -> 0 | AP29: =[4]MVTJUIN!$N29 -> 0 | AQ29: =[4]MVTJUIN!$O29 -> 0 | AR29: =AN29+AP29-AS29 -> 0 | AS29: =[4]MVTJUIN!$Q29 -> 0 | AT29: =[4]MVTJUIL!$N29 -> 0 | AU29: =[4]MVTJUIL!$O29 -> 0 | AV29: =AR29+AT29-AW29 -> 0 | AW29: =[4]MVTJUIL!$Q29 -> 0 | AX29: =[4]MVTAOUT2019!$N29 -> 0 | AY29: =[4]MVTAOUT2019!$O29 -> 0 | AZ29: =AV29+AX29-BA29 -> 0 | BA29: =[4]MVTAOUT2019!$Q29 -> 0 | BB29: 0 | BC29: =G29+K29+O29+S29+W29+AA29+AE29+AI29+AM29+AQ29+AU29+AY29 -> 0 | BD29: =AZ29 -> 0 | BE29: =I29+M29+Q29+U29+Y29+AC29+AG29+AK29+AO29+AS29+AW29+BA29 -> 0 | BF29: 43678
A30: AS201624 | B30: =VLOOKUP(A30,[3]LISTADHERENT!A$5:H$58,2,0) -> NGONDIEP CLAUDE | D30: 1120000 | F30: =[4]MVTSEPT!$P30 -> 1176000 | G30: =[4]MVTSEPT!$Q30 -> 129360 | H30: =F30-I30 -> 1176000 | I30: =[4]MVTSEPT!$S30 -> 0 | J30: =[4]MVTOCT!$N30 -> 0 | K30: =[4]MVTOCT!$O30 -> 0 | L30: =H30+J30-M30 -> 1176000 | M30: =[4]MVTOCT!$Q30 -> 0 | N30: =[4]MVTNOV!$N30 -> 0 | O30: =[4]MVTNOV!$O30 -> 0 | P30: =L30+N30-Q30 -> 1176000 | Q30: =[4]MVTNOV!$Q30 -> 0 | R30: =[4]MVTDEC!$N30 -> 0 | S30: =[4]MVTDEC!$O30 -> 0 | T30: =P30+R30-U30 -> 1176000 | U30: =[4]MVTDEC!$Q30 -> 0 | V30: =[4]MVTJANV!$N30 -> 0 | W30: =[4]MVTJANV!$O30 -> 0 | X30: =T30+V30-Y30 -> 1176000 | Y30: =[4]MVTJANV!$Q30 -> 0 | Z30: =[4]MVTFEV!$N30 -> 0 | AA30: =[4]MVTFEV!$O30 -> 0 | AB30: =X30+Z30-AC30 -> 1176000 | AC30: =[4]MVTFEV!$Q30 -> 0 | AD30: =[4]MVTMARS!$N30 -> 0 | AE30: =[4]MVTMARS!$O30 -> 0 | AF30: =AB30+AD30-AG30 -> 1176000 | AG30: =[4]MVTMARS!$Q30 -> 0 | AH30: =[4]MVTAVRIL!$N30 -> 0 | AI30: =[4]MVTAVRIL!$O30 -> 0 | AJ30: =AF30+AH30-AK30 -> 1176000 | AK30: =[4]MVTAVRIL!$Q30 -> 0 | AL30: =[4]MVTMAI!$N30 -> 0 | AM30: =[4]MVTMAI!$O30 -> 0 | AN30: =AJ30+AL30-AO30 -> 1176000 | AO30: =[4]MVTMAI!$Q30 -> 0 | AP30: =[4]MVTJUIN!$N30 -> 0 | AQ30: =[4]MVTJUIN!$O30 -> 0 | AR30: =AN30+AP30-AS30 -> 1176000 | AS30: =[4]MVTJUIN!$Q30 -> 0 | AT30: =[4]MVTJUIL!$N30 -> 0 | AU30: =[4]MVTJUIL!$O30 -> 0 | AV30: =AR30+AT30-AW30 -> 1176000 | AW30: =[4]MVTJUIL!$Q30 -> 0 | AX30: =[4]MVTAOUT2019!$N30 -> 0 | AY30: =[4]MVTAOUT2019!$O30 -> 0 | AZ30: =AV30+AX30-BA30 -> 1176000 | BA30: =[4]MVTAOUT2019!$Q30 -> 0 | BB30: 0 | BC30: =G30+K30+O30+S30+W30+AA30+AE30+AI30+AM30+AQ30+AU30+AY30 -> 129360 | BD30: =AZ30 -> 1176000 | BE30: =I30+M30+Q30+U30+Y30+AC30+AG30+AK30+AO30+AS30+AW30+BA30 -> 0 | BF30: 43678 | BG30: 56000 | BH30: OK
A31: AS201625 | B31: =VLOOKUP(A31,[3]LISTADHERENT!A$5:H$58,2,0) -> NGONGANG JEAN THEODORE | F31: =[4]MVTSEPT!$P31 -> 0 | G31: =[4]MVTSEPT!$Q31 -> 0 | H31: =F31-I31 -> 0 | I31: =[4]MVTSEPT!$S31 -> 0 | J31: =[4]MVTOCT!$N31 -> 0 | K31: =[4]MVTOCT!$O31 -> 0 | L31: =H31+J31-M31 -> 0 | M31: =[4]MVTOCT!$Q31 -> 0 | N31: =[4]MVTNOV!$N31 -> 0 | O31: =[4]MVTNOV!$O31 -> 0 | P31: =L31+N31-Q31 -> 0 | Q31: =[4]MVTNOV!$Q31 -> 0 | R31: =[4]MVTDEC!$N31 -> 0 | S31: =[4]MVTDEC!$O31 -> 0 | T31: =P31+R31-U31 -> 0 | U31: =[4]MVTDEC!$Q31 -> 0 | V31: =[4]MVTJANV!$N31 -> 0 | W31: =[4]MVTJANV!$O31 -> 0 | X31: =T31+V31-Y31 -> 0 | Y31: =[4]MVTJANV!$Q31 -> 0 | Z31: =[4]MVTFEV!$N31 -> 0 | AA31: =[4]MVTFEV!$O31 -> 0 | AB31: =X31+Z31-AC31 -> 0 | AC31: =[4]MVTFEV!$Q31 -> 0 | AD31: =[4]MVTMARS!$N31 -> 0 | AE31: =[4]MVTMARS!$O31 -> 0 | AF31: =AB31+AD31-AG31 -> 0 | AG31: =[4]MVTMARS!$Q31 -> 0 | AH31: =[4]MVTAVRIL!$N31 -> 0 | AI31: =[4]MVTAVRIL!$O31 -> 0 | AJ31: =AF31+AH31-AK31 -> 0 | AK31: =[4]MVTAVRIL!$Q31 -> 0 | AL31: =[4]MVTMAI!$N31 -> 0 | AM31: =[4]MVTMAI!$O31 -> 0 | AN31: =AJ31+AL31-AO31 -> 0 | AO31: =[4]MVTMAI!$Q31 -> 0 | AP31: =[4]MVTJUIN!$N31 -> 0 | AQ31: =[4]MVTJUIN!$O31 -> 0 | AR31: =AN31+AP31-AS31 -> 0 | AS31: =[4]MVTJUIN!$Q31 -> 0 | AT31: =[4]MVTJUIL!$N31 -> 0 | AU31: =[4]MVTJUIL!$O31 -> 0 | AV31: =AR31+AT31-AW31 -> 0 | AW31: =[4]MVTJUIL!$Q31 -> 0 | AX31: =[4]MVTAOUT2019!$N31 -> 0 | AY31: =[4]MVTAOUT2019!$O31 -> 0 | AZ31: =AV31+AX31-BA31 -> 0 | BA31: =[4]MVTAOUT2019!$Q31 -> 0 | BB31: 0 | BC31: =G31+K31+O31+S31+W31+AA31+AE31+AI31+AM31+AQ31+AU31+AY31 -> 0 | BD31: =AZ31 -> 0 | BE31: =I31+M31+Q31+U31+Y31+AC31+AG31+AK31+AO31+AS31+AW31+BA31 -> 0 | BF31: 43678 | BG31: 0
A32: AS201626 | B32: =VLOOKUP(A32,[3]LISTADHERENT!A$5:H$58,2,0) -> NGUIEMEGNI MATHIEU BLAISE | F32: =[4]MVTSEPT!$P32 -> 1000000 | G32: =[4]MVTSEPT!$Q32 -> 110000 | H32: =F32-I32 -> 1000000 | I32: =[4]MVTSEPT!$S32 -> 0 | J32: =[4]MVTOCT!$N32 -> 0 | K32: =[4]MVTOCT!$O32 -> 0 | L32: =H32+J32-M32 -> 1000000 | M32: =[4]MVTOCT!$Q32 -> 0 | N32: =[4]MVTNOV!$N32 -> 0 | O32: =[4]MVTNOV!$O32 -> 0 | P32: =L32+N32-Q32 -> 1000000 | Q32: =[4]MVTNOV!$Q32 -> 0 | R32: =[4]MVTDEC!$N32 -> 0 | S32: =[4]MVTDEC!$O32 -> 0 | T32: =P32+R32-U32 -> 1000000 | U32: =[4]MVTDEC!$Q32 -> 0 | V32: =[4]MVTJANV!$N32 -> 0 | W32: =[4]MVTJANV!$O32 -> 0 | X32: =T32+V32-Y32 -> 1000000 | Y32: =[4]MVTJANV!$Q32 -> 0 | Z32: =[4]MVTFEV!$N32 -> 0 | AA32: =[4]MVTFEV!$O32 -> 0 | AB32: =X32+Z32-AC32 -> 1000000 | AC32: =[4]MVTFEV!$Q32 -> 0 | AD32: =[4]MVTMARS!$N32 -> 0 | AE32: =[4]MVTMARS!$O32 -> 0 | AF32: =AB32+AD32-AG32 -> 1000000 | AG32: =[4]MVTMARS!$Q32 -> 0 | AH32: =[4]MVTAVRIL!$N32 -> 0 | AI32: =[4]MVTAVRIL!$O32 -> 0 | AJ32: =AF32+AH32-AK32 -> 1000000 | AK32: =[4]MVTAVRIL!$Q32 -> 0 | AL32: =[4]MVTMAI!$N32 -> 0 | AM32: =[4]MVTMAI!$O32 -> 0 | AN32: =AJ32+AL32-AO32 -> 1000000 | AO32: =[4]MVTMAI!$Q32 -> 0 | AP32: =[4]MVTJUIN!$N32 -> 0 | AQ32: =[4]MVTJUIN!$O32 -> 0 | AR32: =AN32+AP32-AS32 -> 1000000 | AS32: =[4]MVTJUIN!$Q32 -> 0 | AT32: =[4]MVTJUIL!$N32 -> 0 | AU32: =[4]MVTJUIL!$O32 -> 0 | AV32: =AR32+AT32-AW32 -> 1000000 | AW32: =[4]MVTJUIL!$Q32 -> 0 | AX32: =[4]MVTAOUT2019!$N32 -> 0 | AY32: =[4]MVTAOUT2019!$O32 -> 0 | AZ32: =AV32+AX32-BA32 -> 1000000 | BA32: =[4]MVTAOUT2019!$Q32 -> 0 | BB32: 0 | BC32: =G32+K32+O32+S32+W32+AA32+AE32+AI32+AM32+AQ32+AU32+AY32 -> 110000 | BD32: =AZ32 -> 1000000 | BE32: =I32+M32+Q32+U32+Y32+AC32+AG32+AK32+AO32+AS32+AW32+BA32 -> 0 | BF32: 43678 | BG32: 0
A33: AS201627 | B33: =VLOOKUP(A33,[3]LISTADHERENT!A$5:H$58,2,0) -> NJEPDJIO MBOUKAM DELUXE | F33: =[4]MVTSEPT!$P33 -> 700000 | G33: =[4]MVTSEPT!$Q33 -> 84000 | H33: =F33-I33 -> 700000 | I33: =[4]MVTSEPT!$S33 -> 0 | J33: =[4]MVTOCT!$N33 -> 0 | K33: =[4]MVTOCT!$O33 -> 0 | L33: =H33+J33-M33 -> 700000 | M33: =[4]MVTOCT!$Q33 -> 0 | N33: =[4]MVTNOV!$N33 -> 0 | O33: =[4]MVTNOV!$O33 -> 0 | P33: =L33+N33-Q33 -> 700000 | Q33: =[4]MVTNOV!$Q33 -> 0 | R33: =[4]MVTDEC!$N33 -> 0 | S33: =[4]MVTDEC!$O33 -> 0 | T33: =P33+R33-U33 -> 700000 | U33: =[4]MVTDEC!$Q33 -> 0 | V33: =[4]MVTJANV!$N33 -> 0 | W33: =[4]MVTJANV!$O33 -> 0 | X33: =T33+V33-Y33 -> 700000 | Y33: =[4]MVTJANV!$Q33 -> 0 | Z33: =[4]MVTFEV!$N33 -> 0 | AA33: =[4]MVTFEV!$O33 -> 0 | AB33: =X33+Z33-AC33 -> 700000 | AC33: =[4]MVTFEV!$Q33 -> 0 | AD33: =[4]MVTMARS!$N33 -> 0 | AE33: =[4]MVTMARS!$O33 -> 0 | AF33: =AB33+AD33-AG33 -> 700000 | AG33: =[4]MVTMARS!$Q33 -> 0 | AH33: =[4]MVTAVRIL!$N33 -> 0 | AI33: =[4]MVTAVRIL!$O33 -> 0 | AJ33: =AF33+AH33-AK33 -> 700000 | AK33: =[4]MVTAVRIL!$Q33 -> 0 | AL33: =[4]MVTMAI!$N33 -> 0 | AM33: =[4]MVTMAI!$O33 -> 0 | AN33: =AJ33+AL33-AO33 -> 700000 | AO33: =[4]MVTMAI!$Q33 -> 0 | AP33: =[4]MVTJUIN!$N33 -> 0 | AQ33: =[4]MVTJUIN!$O33 -> 0 | AR33: =AN33+AP33-AS33 -> 700000 | AS33: =[4]MVTJUIN!$Q33 -> 0 | AT33: =[4]MVTJUIL!$N33 -> 0 | AU33: =[4]MVTJUIL!$O33 -> 0 | AV33: =AR33+AT33-AW33 -> 700000 | AW33: =[4]MVTJUIL!$Q33 -> 0 | AX33: =[4]MVTAOUT2019!$N33 -> 0 | AY33: =[4]MVTAOUT2019!$O33 -> 0 | AZ33: =AV33+AX33-BA33 -> 700000 | BA33: =[4]MVTAOUT2019!$Q33 -> 0 | BB33: 0 | BC33: =G33+K33+O33+S33+W33+AA33+AE33+AI33+AM33+AQ33+AU33+AY33 -> 84000 | BD33: =AZ33 -> 700000 | BE33: =I33+M33+Q33+U33+Y33+AC33+AG33+AK33+AO33+AS33+AW33+BA33 -> 0 | BF33: 43678 | BG33: 0
A34: AS201628 | B34: =VLOOKUP(A34,[3]LISTADHERENT!A$5:H$58,2,0) -> NKAMGANG JUSTIN DEJOLIE | F34: =[4]MVTSEPT!$P34 -> 1000000 | G34: =[4]MVTSEPT!$Q34 -> 20000 | H34: =F34-I34 -> 1000000 | I34: =[4]MVTSEPT!$S34 -> 0 | J34: =[4]MVTOCT!$N34 -> 1000000 | K34: =[4]MVTOCT!$O34 -> 100000 | L34: =H34+J34-M34 -> 1000000 | M34: =[4]MVTOCT!$Q34 -> 1000000 | N34: =[4]MVTNOV!$N34 -> 0 | O34: =[4]MVTNOV!$O34 -> 0 | P34: =L34+N34-Q34 -> 1000000 | Q34: =[4]MVTNOV!$Q34 -> 0 | R34: =[4]MVTDEC!$N34 -> 0 | S34: =[4]MVTDEC!$O34 -> 0 | T34: =P34+R34-U34 -> 1000000 | U34: =[4]MVTDEC!$Q34 -> 0 | V34: =[4]MVTJANV!$N34 -> 0 | W34: =[4]MVTJANV!$O34 -> 0 | X34: =T34+V34-Y34 -> 1000000 | Y34: =[4]MVTJANV!$Q34 -> 0 | Z34: =[4]MVTFEV!$N34 -> 0 | AA34: =[4]MVTFEV!$O34 -> 0 | AB34: =X34+Z34-AC34 -> 1000000 | AC34: =[4]MVTFEV!$Q34 -> 0 | AD34: =[4]MVTMARS!$N34 -> 0 | AE34: =[4]MVTMARS!$O34 -> 0 | AF34: =AB34+AD34-AG34 -> 1000000 | AG34: =[4]MVTMARS!$Q34 -> 0 | AH34: =[4]MVTAVRIL!$N34 -> 0 | AI34: =[4]MVTAVRIL!$O34 -> 0 | AJ34: =AF34+AH34-AK34 -> 1000000 | AK34: =[4]MVTAVRIL!$Q34 -> 0 | AL34: =[4]MVTMAI!$N34 -> 0 | AM34: =[4]MVTMAI!$O34 -> 0 | AN34: =AJ34+AL34-AO34 -> 1000000 | AO34: =[4]MVTMAI!$Q34 -> 0 | AP34: =[4]MVTJUIN!$N34 -> 0 | AQ34: =[4]MVTJUIN!$O34 -> 0 | AR34: =AN34+AP34-AS34 -> 1000000 | AS34: =[4]MVTJUIN!$Q34 -> 0 | AT34: =[4]MVTJUIL!$N34 -> 0 | AU34: =[4]MVTJUIL!$O34 -> 0 | AV34: =AR34+AT34-AW34 -> 1000000 | AW34: =[4]MVTJUIL!$Q34 -> 0 | AX34: =[4]MVTAOUT2019!$N34 -> 0 | AY34: =[4]MVTAOUT2019!$O34 -> 0 | AZ34: =AV34+AX34-BA34 -> 1000000 | BA34: =[4]MVTAOUT2019!$Q34 -> 0 | BB34: 0 | BC34: =G34+K34+O34+S34+W34+AA34+AE34+AI34+AM34+AQ34+AU34+AY34 -> 120000 | BD34: =AZ34 -> 1000000 | BE34: =I34+M34+Q34+U34+Y34+AC34+AG34+AK34+AO34+AS34+AW34+BA34 -> 1000000 | BF34: 43678 | BG34: 0
A35: AS201614 | B35: =VLOOKUP(A35,[3]LISTADHERENT!A$5:H$58,2,0) -> NKEHE DAVID | F35: =[4]MVTSEPT!$P35 -> 1000000 | G35: =[4]MVTSEPT!$Q35 -> 120000 | H35: =F35-I35 -> 1000000 | I35: =[4]MVTSEPT!$S35 -> 0 | J35: =[4]MVTOCT!$N35 -> 0 | K35: =[4]MVTOCT!$O35 -> 0 | L35: =H35+J35-M35 -> 1000000 | M35: =[4]MVTOCT!$Q35 -> 0 | N35: =[4]MVTNOV!$N35 -> 0 | O35: =[4]MVTNOV!$O35 -> 0 | P35: =L35+N35-Q35 -> 1000000 | Q35: =[4]MVTNOV!$Q35 -> 0 | R35: =[4]MVTDEC!$N35 -> 0 | S35: =[4]MVTDEC!$O35 -> 0 | T35: =P35+R35-U35 -> 1000000 | U35: =[4]MVTDEC!$Q35 -> 0 | V35: =[4]MVTJANV!$N35 -> 0 | W35: =[4]MVTJANV!$O35 -> 0 | X35: =T35+V35-Y35 -> 1000000 | Y35: =[4]MVTJANV!$Q35 -> 0 | Z35: =[4]MVTFEV!$N35 -> 0 | AA35: =[4]MVTFEV!$O35 -> 0 | AB35: =X35+Z35-AC35 -> 1000000 | AC35: =[4]MVTFEV!$Q35 -> 0 | AD35: =[4]MVTMARS!$N35 -> 0 | AE35: =[4]MVTMARS!$O35 -> 0 | AF35: =AB35+AD35-AG35 -> 1000000 | AG35: =[4]MVTMARS!$Q35 -> 0 | AH35: =[4]MVTAVRIL!$N35 -> 0 | AI35: =[4]MVTAVRIL!$O35 -> 0 | AJ35: =AF35+AH35-AK35 -> 1000000 | AK35: =[4]MVTAVRIL!$Q35 -> 0 | AL35: =[4]MVTMAI!$N35 -> 0 | AM35: =[4]MVTMAI!$O35 -> 0 | AN35: =AJ35+AL35-AO35 -> 1000000 | AO35: =[4]MVTMAI!$Q35 -> 0 | AP35: =[4]MVTJUIN!$N35 -> 0 | AQ35: =[4]MVTJUIN!$O35 -> 0 | AR35: =AN35+AP35-AS35 -> 1000000 | AS35: =[4]MVTJUIN!$Q35 -> 0 | AT35: =[4]MVTJUIL!$N35 -> 0 | AU35: =[4]MVTJUIL!$O35 -> 0 | AV35: =AR35+AT35-AW35 -> 1000000 | AW35: =[4]MVTJUIL!$Q35 -> 0 | AX35: =[4]MVTAOUT2019!$N35 -> 0 | AY35: =[4]MVTAOUT2019!$O35 -> 0 | AZ35: =AV35+AX35-BA35 -> 1000000 | BA35: =[4]MVTAOUT2019!$Q35 -> 0 | BB35: 0 | BC35: =G35+K35+O35+S35+W35+AA35+AE35+AI35+AM35+AQ35+AU35+AY35 -> 120000 | BD35: =AZ35 -> 1000000 | BE35: =I35+M35+Q35+U35+Y35+AC35+AG35+AK35+AO35+AS35+AW35+BA35 -> 0 | BF35: 43678 | BG35: 0
A36: AS201629 | B36: =VLOOKUP(A36,[3]LISTADHERENT!A$5:H$58,2,0) -> NKEPSEU DIEUDONNE | F36: =[4]MVTSEPT!$P36 -> 1000000 | G36: =[4]MVTSEPT!$Q36 -> 110000 | H36: =F36-I36 -> 1000000 | I36: =[4]MVTSEPT!$S36 -> 0 | J36: =[4]MVTOCT!$N36 -> 0 | K36: =[4]MVTOCT!$O36 -> 0 | L36: =H36+J36-M36 -> 1000000 | M36: =[4]MVTOCT!$Q36 -> 0 | N36: =[4]MVTNOV!$N36 -> 0 | O36: =[4]MVTNOV!$O36 -> 0 | P36: =L36+N36-Q36 -> 1000000 | Q36: =[4]MVTNOV!$Q36 -> 0 | R36: =[4]MVTDEC!$N36 -> 0 | S36: =[4]MVTDEC!$O36 -> 0 | T36: =P36+R36-U36 -> 1000000 | U36: =[4]MVTDEC!$Q36 -> 0 | V36: =[4]MVTJANV!$N36 -> 0 | W36: =[4]MVTJANV!$O36 -> 0 | X36: =T36+V36-Y36 -> 1000000 | Y36: =[4]MVTJANV!$Q36 -> 0 | Z36: =[4]MVTFEV!$N36 -> 0 | AA36: =[4]MVTFEV!$O36 -> 0 | AB36: =X36+Z36-AC36 -> 1000000 | AC36: =[4]MVTFEV!$Q36 -> 0 | AD36: =[4]MVTMARS!$N36 -> 0 | AE36: =[4]MVTMARS!$O36 -> 0 | AF36: =AB36+AD36-AG36 -> 1000000 | AG36: =[4]MVTMARS!$Q36 -> 0 | AH36: =[4]MVTAVRIL!$N36 -> 0 | AI36: =[4]MVTAVRIL!$O36 -> 0 | AJ36: =AF36+AH36-AK36 -> 1000000 | AK36: =[4]MVTAVRIL!$Q36 -> 0 | AL36: =[4]MVTMAI!$N36 -> 0 | AM36: =[4]MVTMAI!$O36 -> 0 | AN36: =AJ36+AL36-AO36 -> 1000000 | AO36: =[4]MVTMAI!$Q36 -> 0 | AP36: =[4]MVTJUIN!$N36 -> 0 | AQ36: =[4]MVTJUIN!$O36 -> 0 | AR36: =AN36+AP36-AS36 -> 1000000 | AS36: =[4]MVTJUIN!$Q36 -> 0 | AT36: =[4]MVTJUIL!$N36 -> 0 | AU36: =[4]MVTJUIL!$O36 -> 0 | AV36: =AR36+AT36-AW36 -> 1000000 | AW36: =[4]MVTJUIL!$Q36 -> 0 | AX36: =[4]MVTAOUT2019!$N36 -> 0 | AY36: =[4]MVTAOUT2019!$O36 -> 0 | AZ36: =AV36+AX36-BA36 -> 1000000 | BA36: =[4]MVTAOUT2019!$Q36 -> 0 | BB36: 0 | BC36: =G36+K36+O36+S36+W36+AA36+AE36+AI36+AM36+AQ36+AU36+AY36 -> 110000 | BD36: =AZ36 -> 1000000 | BE36: =I36+M36+Q36+U36+Y36+AC36+AG36+AK36+AO36+AS36+AW36+BA36 -> 0 | BF36: 43678 | BG36: 0
