Workbook
Name BANQUE: #REF!
Name BANQUE: #REF!
Name BANQUE: #REF!
Name BANQUE: #REF!
Name BANQUE: #REF!
Name BANQUE: #REF!
Name BANQUE: #REF!
Name BANQUE: #REF!
Name MODEPAID: [1]Feuil2!$A$1:$A$3
Name MODEPAID: [1]Feuil2!$A$1:$A$3
Name MODEPAID: [2]Feuil2!$A$1:$A$3
Name MODEPAID: [2]Feuil2!$A$1:$A$3
Name MODEPAID: [2]Feuil2!$A$1:$A$3
Name MODEPAID: [2]Feuil2!$A$1:$A$3
Name MODEPAID: [2]Feuil2!$A$1:$A$3
Name MODEPAID: [1]Feuil2!$A$1:$A$3
Name MODEPAID: [3]Feuil2!$A$1:$A$3
Name MODET25000: [4]MODEVERSEMENT!$A$1:$A$3
Name MODEVERSEMENT: #REF!
Name MODEVERSEMENT: #REF!
Name MODEVERSEMENT: #REF!
Name MODEVERSEMENT: #REF!
Name MODEVERSEMENT: #REF!
Name MODEVERSEMENT: #REF!
Name MODEVERSEMENT: #REF!
Name MODEVERSEMENT: #REF!
Name MODEVERSEMENTS: #REF!
Name MODEVERSEMENTS: #REF!
Name MODEVERSEMENTS: #REF!
Name MODEVERSEMENTS: #REF!
Name MODEVERSEMENTS: #REF!
Name MODEVERSEMENTS: [5]MODEVERSEMENT!$A$1:$A$3
Name VALMODEPAID: [6]MODEPAID!$A$1:$A$3
Name VALMODEPAID: [6]MODEPAID!$A$1:$A$3
Name VALMODEPAID: [6]MODEPAID!$A$1:$A$3
Name VALMODEPAID: [6]MODEPAID!$A$1:$A$3
Name VALMODEPAID: [6]MODEPAID!$A$1:$A$3
Name VALMODEPAID: [7]MODEPAID!$A$1:$A$3

Sheet BILAN 2016
A2: BILAN ALLANT DE LA PERIODE DU 01 DECEMBRE 2015 AU 30 NOVEMBRE 2016
A5: RUBRIQUE | B5: REPORT A NOUVEAU | C5: ENTREES | D5: SORTIES | E5: SOLDE
A7: EPARGNE\RELIQUAT2015 | B7: 29756024 | C7: =[8]TRAVAUXINVENTAIRE!R54+C20+1050000+2230668 -> 7101809 | E7: =B7+C7-D7 -> 36857833
A8: FONDS DE CAISSE | C8: 28382451 | D8: 39386431 | E8: =B8+C8-D8 -> -11003980
A9: FONDS DE ROULEMENT | B9: 3031178 | C9: =[8]TRAVAUXINVENTAIRE!S54 -> 250500 | D9: ='[9]BILAN 2016'!$D$9 -> 224500 | E9: =B9+C9-D9 -> 3057178
A10: FRAIS EXCEPTIONNELS | B10: 1267460 | C10: =[8]TRAVAUXINVENTAIRE!T54 -> 501000 | D10: =[8]TRAVAUXINVENTAIREDEC!B6 -> 1100000 | E10: =B10+C10-D10 -> 668460
A11: COLLATION | B11: 940125 | C11: =[8]TRAVAUXINVENTAIRE!U54 -> 1252500 | D11: =[8]TRAVAUXINVENTAIREDEC!B7 -> 1260000 | E11: =B11+C11-D11 -> 932625
A12: MUTUELLE\COMPLEMENT MUTUEL | B12: =-101500 -> -101500 | C12: =[8]TRAVAUXINVENTAIRE!V54+[8]TRAVAUXINVENTAIRE!O54 -> 1954860 | D12: =[8]TRAVAUXINVENTAIREDEC!B8 -> 2595000 | E12: =B12+C12-D12 -> -741640
A13: INSCRIPTION | B13: 530000 | E13: =B13+C13-D13 -> 530000
A14: FONDS GELE | B14: 54508 | E14: =B14+C14-D14 -> 54508
A15: CHAISE | B15: -164500 | E15: =B15+C15-D15 -> -164500
A16: TENUE | B16: -75000 | E16: =B16+C16-D16 -> -75000
A17: FOYER | E17: =B17+C17-D17 -> 0
A18: RECOUVREMENT POUR LAGWEU GENERAL | C18: =320750+16500 -> 337250 | E18: =B18+C18-D18 -> 337250 | F18: 1711250
A19: AUTRES | E19: =B19+C19-D19 -> 0
A20: INTERET EMPRUNT | E20: =B20+C20-D20 -> 0
A22: EMPRUNT
A24: RELIQUAT 2016
A27: COMPTE CCA
A28: COMPTE AFRILAND
A29: INTERET BQUE AFRILAND | B29: 1779594 | E29: =B29+C29-D29 -> 1779594
A30: COMPTE MC2
A31: ASELBY CAISSE(NDJOMO ETIENNE)
A33: RETRAIT DISTRIBUTION EPARGNE
A35: SOUS TOTAL
A37: MONTANT DISPONIBLE | B37: =SUM(B7:B36) -> 37017889 | C37: =SUM(C7:C36) -> 39780370 | D37: =SUM(D7:D36) -> 44565931 | E37: =B37+C37-D37 -> 32232328

Sheet BILAN 2017
A2: BILAN ALLANT DE LA PERIODE DU 01 DECEMBRE 2016 AU 30 AOUT 2017
A5: RUBRIQUE | B5: REPORT A NOUVEAU | C5: ENTREES | D5: SORTIES | E5: SOLDE
A7: EPARGNE\RELIQUAT2016 | B7: ='BILAN 2016'!E7 -> 36857833 | C7: =[10]BILANFINAOUT2017!E56 -> 3963693 | D7: 13500000 | E7: =B7+C7-D7 -> 27321526
A8: FONDS DE CAISSE | B8: ='BILAN 2016'!E8 -> -11003980 | C8: =[10]BILANFINAOUT2017!C56 -> 16310819 | E8: =B8+C8-D8 -> 5306839
A9: FONDS DE ROULEMENT | B9: ='BILAN 2016'!E9 -> 3057178 | C9: =[10]BILANFINAOUT2017!F56 -> 182000 | D9: =89000+84000+12000+10000+6000+48000+13000+5000 -> 267000 | E9: =B9+C9-D9 -> 2972178
A10: FRAIS EXCEPTIONNELS | B10: ='BILAN 2016'!E10 -> 668460 | C10: =[10]BILANFINAOUT2017!G56 -> 364000 | D10: =200000+345000 -> 545000 | E10: =B10+C10-D10 -> 487460
A11: COLLATION | B11: ='BILAN 2016'!E11 -> 932625 | C11: =[10]BILANFINAOUT2017!H56 -> 910000 | D11: =100000+110000+100000+100000+100000+100000+100000+100000+100000 -> 910000 | E11: =B11+C11-D11 -> 932625
A12: MUTUELLE\COMPLEMENT MUTUEL | B12: ='BILAN 2016'!E12 -> -741640 | C12: =[10]BILANFINAOUT2017!I56 -> 2009927 | D12: =200000+100000+640000 -> 940000 | E12: =B12+C12-D12 -> 328287
A13: PENALITE VERSEMENT EN ESPECES | C13: =[10]BILANFINAOUT2017!R56 -> 125000 | E13: =B13+C13-D13 -> 125000
A14: SANCTION | C14: =+[10]BILANFINAOUT2017!J56 -> 0
A15: INSCRIPTION | B15: ='BILAN 2016'!E13 -> 530000 | E15: =B15+C15-D15 -> 530000
A16: FONDS GELE | B16: ='BILAN 2016'!E14 -> 54508 | E16: =B16+C16-D16 -> 54508
A17: CHAISE | B17: ='BILAN 2016'!E15 -> -164500 | E17: =B17+C17-D17 -> -164500
A18: TENUE | B18: ='BILAN 2016'!E16 -> -75000 | E18: =B18+C18-D18 -> -75000
E19: =B19+C19-D19 -> 0
A20: FOYER | E20: =B20+C20-D20 -> 0
A21: RECOUVREMENT POUR LAGWEU GENERAL | B21: ='BILAN 2016'!E18 -> 337250 | E21: =B21+C21-D21 -> 337250
A22: AUTRES
A23: INTERET EMPRUNT
A25: EMPRUNT | E25: =B25+C25-D25 -> 0
A27: RELIQUAT 2016
A29: INTERET BQUE AFRILAND | B29: 1779594 | E29: =B29+C29-D29 -> 1779594
A30: COMPTE CCA
A31: COMPTE AFRILAND
A32: COMPTE MC2
A33: ASELBY CAISSE(NDJOMO ETIENNE)
A35: RETRAIT DISTRIBUTION EPARGNE
A39: MONTANT DISPONIBLE | B39: =SUM(B7:B38) -> 32232328 | C39: =SUM(C7:C38) -> 23865439 | D39: =SUM(D7:D38) -> 16162000 | E39: =B39+C39-D39 -> 39935767

Sheet SITFINANCIERE
A2: SITUATION TRESORERIE ALLANT DE LA PERIODE DU 01 SEPTEMBRE 2017 AU 30 AOUT 2018
A5: RUBRIQUE | B5: MOUVEMENT ASELBY | C5: TRESORERIE | D5: SOLDE
A7: CAISSE | C7: 0
A8: COMPTE CCA | C8: 10660936
A9: COMPTE AFRILAND | C9: 4817411
A10: COMPTE MC2 | C10: 630005
A11: FRAIS EXCEPTIONNELS | B11: ='BILAN 2018'!E7 -> 9719176.9
A12: FONDS DE CAISSE | B12: ='BILAN 2018'!E8 -> 6536839
A13: EPARGNE | B13: =INVENT2017_2018!K56 -> 8164348.9
A14: FONDS DE ROULEMENT | B14: ='BILAN 2018'!E10 -> 2895678
A15: FRAIS EXCEPTIONNELS | B15: ='BILAN 2018'!E11 -> 331960
A16: COLLATION | B16: ='BILAN 2018'!E12 -> 927625
A17: MUTUELLE\COMPLEMENT MUTUEL | B17: ='BILAN 2018'!E13 -> 88287
A18: PENALITE VERSEMENT EN ESPECES | B18: ='BILAN 2018'!E14 -> 323500
A19: INSCRIPTION | B19: ='BILAN 2018'!E15 -> 580000
A20: SANCTION | B20: ='BILAN 2018'!E16 -> 0
A21: AUTRES
A22: PRET EN COURS | C22: =INVENT2017_2018!S56 -> 10310500
A24: MONTANT DISPONIBLE | B24: =SUM(B11:B23) -> 29567415 | C24: =SUM(C7:C23) -> 26418852 | D24: =B24-C24 -> 3148562.8

Sheet BILAN 2018
A2: BILAN ALLANT DE LA PERIODE DU 01 SEPTEMBRE 2017 AU 30 AOUT 2018
A5: RUBRIQUE | B5: REPORT A NOUVEAU | C5: ENTREES | D5: SORTIES | E5: SOLDE
A7: RELIQUAT 2017/EPARGNE | B7: ='BILAN 2017'!E7 -> 27321526 | C7: =INVENT2017_2018!C56+3860500 -> 10034614 | D7: =24505800+3131163 -> 27636963 | E7: =B7+C7-D7 -> 9719176.9
A8: FONDS DE CAISSE | B8: ='BILAN 2017'!E8 -> 5306839 | C8: =INVENT2017_2018!J56 -> 1230000 | E8: =B8+C8-D8 -> 6536839
A9: EPARGNE | E9: =B9+C9-D9 -> 0
A10: FONDS DE ROULEMENT | B10: ='BILAN 2017'!E9 -> 2972178 | C10: =ENTREE!C22 -> 229000 | D10: =SORTIE!C22 -> 305500 | E10: =B10+C10-D10 -> 2895678
A11: FRAIS EXCEPTIONNELS | B11: ='BILAN 2017'!E10 -> 487460 | C11: =ENTREE!D22 -> 458000 | D11: =SORTIE!D22 -> 613500 | E11: =B11+C11-D11 -> 331960
A12: COLLATION | B12: ='BILAN 2017'!E11 -> 932625 | C12: =ENTREE!E22 -> 1145000 | D12: =SORTIE!E22 -> 1150000 | E12: =B12+C12-D12 -> 927625
A13: MUTUELLE\COMPLEMENT MUTUEL | B13: ='BILAN 2017'!E12 -> 328287 | C13: =ENTREE!H22 -> 860000 | D13: =SORTIE!H22 -> 1100000 | E13: =B13+C13-D13 -> 88287
A14: PENALITE VERSEMENT EN ESPECES | B14: =+'BILAN 2017'!E13 -> 125000 | C14: =ENTREE!F22 -> 198500 | E14: =B14+C14-D14 -> 323500
A15: INSCRIPTION | B15: ='BILAN 2017'!E15 -> 530000 | C15: =ENTREE!G22 -> 50000 | E15: =B15+C15-D15 -> 580000
A16: SANCTION | E16: =B16+C16-D16 -> 0
A17: FONDS GELE | B17: ='BILAN 2017'!E16 -> 54508 | E17: =B17+C17-D17 -> 54508
A18: CHAISE | B18: ='BILAN 2017'!E17 -> -164500 | E18: =B18+C18-D18 -> -164500
A19: TENUE | B19: ='BILAN 2017'!E18 -> -75000 | E19: =B19+C19-D19 -> -75000
E20: =B20+C20-D20 -> 0
A21: RECOUVREMENT POUR LAGWEU GENERAL 2 | C21: =+'INVENT2017_2018 (4)'!L58 -> 655300 | D21: 1400000 | E21: =B21+C21-D21 -> -744700
A22: RECOUVREMENT POUR LAGWEU GENERAL | B22: ='BILAN 2017'!E21 -> 337250 | E22: =B22+C22-D22 -> 337250
A23: AUTRES | E23: =B23+C23-D23 -> 0
A24: PRET EN COURS | B24: ='BILAN 2017'!E25 -> 0 | E24: =B24+C24-D24 -> 0
A25: INTERET PRET 18 MOIS | E25: =B25+C25-D25 -> 0
E26: =B26+C26-D26 -> 0
E27: =B27+C27-D27 -> 0
E28: =B28+C28-D28 -> 0
E29: =B29+C29-D29 -> 0
E30: =B30+C30-D30 -> 0
A31: COMPTE CCA | C31: 13614473 | E31: =B31+C31-D31 -> 13614473
A32: COMPTE AFRILAND | C32: 4817411 | E32: =B32+C32-D32 -> 4817411
A33: INTERET BQUE AFRILAND | B33: ='BILAN 2017'!B29 -> 1779594 | E33: =B33+C33-D33 -> 1779594
A34: COMPTE MC2 | C34: 630005 | E34: =B34+C34-D34 -> 630005
E35: =B35+C35-D35 -> 0
A36: RETRAIT DISTRIBUTION EPARGNE | E36: =B36+C36-D36 -> 0
E37: =B37+C37-D37 -> 0
E38: =B38+C38-D38 -> 0
A40: MONTANT DISPONIBLE | B40: =SUM(B7:B39) -> 39935767 | C40: =SUM(C7:C30) -> 14860414 | D40: =SUM(D7:D30) -> 32205963 | E40: =B40+C40-D40 -> 22590218

Sheet ENTREE
B2: ENTREE DES DIFFERENTES RUBRIQUES
A3: ANNEE | B3: 2017-2018
A6: MOIS | B6: EPARGNE | C6: FONDS DE ROULEMENT | D6: FRAIS EXCEPTIONNEL | E6: COLLATION | F6: PENALITE VST ESPECES | G6: INSCRIPTION | H6: MUTUELLE | I6: TOTAL
A7: REPORT
A8: AOUT | B8: =+[11]MVTAOUT!H$54 -> 359000 | C8: =+[11]MVTAOUT!I$54 -> 23000 | D8: =+[11]MVTAOUT!J$54 -> 46000 | E8: =+[11]MVTAOUT!K$54 -> 115000 | F8: =+[11]MVTAOUT!L$54 -> 27500 | G8: =+[11]MVTAOUT!M$54 -> 0 | H8: =+[11]MVTAOUT!N$54 -> 30000 | I8: =SUM(B8:H8) -> 600500
A9: SEPTEMBRE | B9: =+[11]MVTSEPT!I$54 -> 233000 | C9: =+[11]MVTSEPT!J$54 -> 18000 | D9: =+[11]MVTSEPT!K$54 -> 36000 | E9: =+[11]MVTSEPT!L$54 -> 90000 | F9: =+[11]MVTSEPT!M$54 -> 15000 | G9: =+[11]MVTSEPT!N$54 -> 0 | H9: =+[11]MVTSEPT!O$54 -> 0 | I9: =SUM(B9:H9) -> 392000
A10: OCTOBRE | B10: =+[11]MVTOCT!G$54 -> 182000 | C10: =+[11]MVTOCT!H$54 -> 18500 | D10: =+[11]MVTOCT!I$54 -> 37000 | E10: =+[11]MVTOCT!J$54 -> 92500 | F10: =+[11]MVTOCT!K$54 -> 14000 | G10: =+[11]MVTOCT!L$54 -> 0 | H10: =+[11]MVTOCT!M$54 -> 0 | I10: =SUM(B10:H10) -> 344000
A11: NOVEMBRE | B11: =+[11]MVTNOV!G$54 -> 182500 | C11: =+[11]MVTNOV!H$54 -> 18500 | D11: =+[11]MVTNOV!I$54 -> 37000 | E11: =+[11]MVTNOV!J$54 -> 92500 | F11: =+[11]MVTNOV!K$54 -> 17000 | G11: =+[11]MVTNOV!L$54 -> 25000 | H11: =+[11]MVTNOV!M$54 -> 0 | I11: =SUM(B11:H11) -> 372500
A12: DÉCEMBRE | B12: =+[11]MVTDEC!G$54 -> 212000 | C12: =+[11]MVTDEC!H$54 -> 18000 | D12: =+[11]MVTDEC!I$54 -> 36000 | E12: =+[11]MVTDEC!J$54 -> 90000 | F12: =+[11]MVTDEC!K$54 -> 17000 | G12: =+[11]MVTDEC!L$54 -> 0 | H12: =+[11]MVTDEC!M$54 -> 220000 | I12: =SUM(B12:H12) -> 593000
A13: JANVIER | B13: =+[11]MVTJANV!G$54 -> 138000 | C13: =+[11]MVTJANV!H$54 -> 19500 | D13: =+[11]MVTJANV!I$54 -> 39000 | E13: =+[11]MVTJANV!J$54 -> 97500 | F13: =+[11]MVTJANV!K$54 -> 17000 | G13: =+[11]MVTJANV!L$54 -> 0 | H13: =+[11]MVTJANV!M$54 -> 50000 | I13: =SUM(B13:H13) -> 361000
A14: FÉVRIER | B14: =+[11]MVTFEV!G$54 -> 192000 | C14: =+[11]MVTFEV!H$54 -> 18500 | D14: =+[11]MVTFEV!I$54 -> 37000 | E14: =+[11]MVTFEV!J$54 -> 92500 | F14: =+[11]MVTFEV!K$54 -> 17000 | G14: =+[11]MVTFEV!L$54 -> 0 | H14: =+[11]MVTFEV!M$54 -> 0 | I14: =SUM(B14:H14) -> 357000
A15: MARS | B15: =+[11]MVTMARS!G$54 -> 191000 | C15: =+[11]MVTMARS!H$54 -> 18500 | D15: =+[11]MVTMARS!I$54 -> 37000 | E15: =+[11]MVTMARS!J$54 -> 92500 | F15: =+[11]MVTMARS!K$54 -> 12000 | G15: =+[11]MVTMARS!L$54 -> 0 | H15: =+[11]MVTMARS!M$54 -> 20000 | I15: =SUM(B15:H15) -> 371000
A16: AVRIL | B16: =+[11]MVTAVRIL!G$54 -> 345000 | C16: =+[11]MVTAVRIL!H$54 -> 20000 | D16: =+[11]MVTAVRIL!I$54 -> 40000 | E16: =+[11]MVTAVRIL!J$54 -> 100000 | F16: =+[11]MVTAVRIL!K$54 -> 13000 | G16: =+[11]MVTAVRIL!L$54 -> 25000 | H16: =+[11]MVTAVRIL!M$54 -> 170000 | I16: =SUM(B16:H16) -> 713000
A17: MAI | B17: =+[11]MVTMAI!G$54 -> 1389000 | C17: =+[11]MVTMAI!H$54 -> 19000 | D17: =+[11]MVTMAI!I$54 -> 38000 | E17: =+[11]MVTMAI!J$54 -> 95000 | F17: =+[11]MVTMAI!K$54 -> 14000 | G17: =+[11]MVTMAI!L$54 -> 0 | H17: =+[11]MVTMAI!M$54 -> 200000 | I17: =SUM(B17:H17) -> 1755000
A18: JUIN | B18: =+[11]MVTJUIN!G$54 -> 135000 | C18: =+[11]MVTJUIN!H$54 -> 19000 | D18: =+[11]MVTJUIN!I$54 -> 38000 | E18: =+[11]MVTJUIN!J$54 -> 95000 | F18: =+[11]MVTJUIN!K$54 -> 19000 | G18: =+[11]MVTJUIN!L$54 -> 0 | H18: =+[11]MVTJUIN!M$54 -> 170000 | I18: =SUM(B18:H18) -> 476000
A19: JUILLET | B19: =+[11]MVTJUIL!G$54 -> 148000 | C19: =+[11]MVTJUIL!H$54 -> 18500 | D19: =+[11]MVTJUIL!I$54 -> 37000 | E19: =+[11]MVTJUIL!J$54 -> 92500 | F19: =+[11]MVTJUIL!K$54 -> 16000 | G19: =+[11]MVTJUIL!L$54 -> 0 | H19: =+[11]MVTJUIL!M$54 -> 0 | I19: =SUM(B19:H19) -> 312000
A20: AOÛT | B20: =+[12]MVTAOUT!G$54 -> 0 | C20: =+[12]MVTAOUT!H$54 -> 0 | D20: =+[12]MVTAOUT!I$54 -> 0 | E20: =+[12]MVTAOUT!J$54 -> 0 | F20: =+[12]MVTAOUT!K$54 -> 0 | G20: =+[12]MVTAOUT!L$54 -> 0 | H20: =+[12]MVTAOUT!M$54 -> 0 | I20: =SUM(B20:H20) -> 0
A22: TOTAL | B22: =SUM(B8:B21) -> 3706500 | C22: =SUM(C8:C21) -> 229000 | D22: =SUM(D8:D21) -> 458000 | E22: =SUM(E8:E21) -> 1145000 | F22: =SUM(F8:F21) -> 198500 | G22: =SUM(G8:G21) -> 50000 | H22: =SUM(H8:H21) -> 860000 | I22: =SUM(I8:I21) -> 6647000
C25: =+INVENT2017_2018!D56-ENTREE!B22 -> 154000

Sheet SORTIE
B2: SORTIE DES DIFFERENTES RUBRIQUES
A3: ANNEE | B3: 2017-2018
A6: MOIS | B6: EPARGNE | C6: FONDS DE ROULEMENT | D6: FRAIS EXCEPTIONNEL | E6: COLLATION | F6: PENALITE VST ESPECES | G6: INSCRIPTION | H6: MUTUELLE | I6: TOTAL
A7: REPORT
A8: AOUT | C8: =SORTIEDETAILLE!$C$13 -> 5000 | D8: =SORTIEDETAILLE!$C$20 -> 0 | E8: =SORTIEDETAILLE!$C$24 -> 100000 | H8: =SORTIEDETAILLE!$C$26 -> 0 | I8: =SUM(B8:H8) -> 105000
A9: SEPTEMBRE | C9: =SORTIEDETAILLE!$D$13 -> 60500 | D9: =SORTIEDETAILLE!$D$20 -> 0 | E9: =SORTIEDETAILLE!$D$24 -> 100000 | H9: =SORTIEDETAILLE!$D$26 -> 0 | I9: =SUM(B9:H9) -> 160500
A10: OCTOBRE | C10: =SORTIEDETAILLE!$E$13 -> 0 | D10: =SORTIEDETAILLE!$E$20 -> 0 | E10: =SORTIEDETAILLE!$E$24 -> 0 | H10: =SORTIEDETAILLE!$E$26 -> 0 | I10: =SUM(B10:H10) -> 0
A11: NOVEMBRE | C11: =SORTIEDETAILLE!$F$13 -> 18000 | D11: =SORTIEDETAILLE!$F$20 -> 300000 | E11: =SORTIEDETAILLE!$F$24 -> 110000 | H11: =SORTIEDETAILLE!$F$26 -> 100000 | I11: =SUM(B11:H11) -> 528000
A12: DÉCEMBRE | C12: =SORTIEDETAILLE!$G$13 -> 29000 | D12: =SORTIEDETAILLE!$G$20 -> 0 | E12: =SORTIEDETAILLE!$G$24 -> 100000 | H12: =SORTIEDETAILLE!$G$26 -> 0 | I12: =SUM(B12:H12) -> 129000
A13: JANVIER | C13: =SORTIEDETAILLE!$H$13 -> 18000 | D13: =SORTIEDETAILLE!$H$20 -> 3500 | E13: =SORTIEDETAILLE!$H$24 -> 100000 | H13: =SORTIEDETAILLE!$H$26 -> 100000 | I13: =SUM(B13:H13) -> 221500
A14: FÉVRIER | C14: =SORTIEDETAILLE!$I$13 -> 0 | D14: =SORTIEDETAILLE!$I$20 -> 310000 | E14: =SORTIEDETAILLE!$I$24 -> 0 | H14: =SORTIEDETAILLE!$I$26 -> 0 | I14: =SUM(B14:H14) -> 310000
A15: MARS | C15: =SORTIEDETAILLE!$J$13 -> 14000 | D15: =SORTIEDETAILLE!$J$20 -> 0 | E15: =SORTIEDETAILLE!$J$24 -> 100000 | H15: =SORTIEDETAILLE!$J$26 -> 0 | I15: =SUM(B15:H15) -> 114000
A16: AVRIL | C16: =SORTIEDETAILLE!$K$13 -> 12000 | D16: =SORTIEDETAILLE!$K$20 -> 0 | E16: =SORTIEDETAILLE!$K$24 -> 100000 | H16: =SORTIEDETAILLE!$K$26 -> 0 | I16: =SUM(B16:H16) -> 112000
A17: MAI | C17: =SORTIEDETAILLE!$L$13 -> 15000 | D17: =SORTIEDETAILLE!$L$20 -> 0 | E17: =SORTIEDETAILLE!$L$24 -> 100000 | H17: =SORTIEDETAILLE!$L$26 -> 100000 | I17: =SUM(B17:H17) -> 215000
A18: JUIN | C18: =SORTIEDETAILLE!$M$13 -> 93000 | D18: =SORTIEDETAILLE!$M$20 -> 0 | E18: =SORTIEDETAILLE!$M$24 -> 100000 | H18: =SORTIEDETAILLE!$M$26 -> 100000 | I18: =SUM(B18:H18) -> 293000
A19: JUILLET | C19: =SORTIEDETAILLE!$N$13 -> 0 | D19: =SORTIEDETAILLE!$N$20 -> 0 | E19: =SORTIEDETAILLE!$N$24 -> 140000 | H19: =SORTIEDETAILLE!$N$26 -> 500000 | I19: =SUM(B19:H19) -> 640000
A20: AOÛT | B20: 4862745.3 | C20: =SORTIEDETAILLE!$O$13 -> 41000 | D20: =SORTIEDETAILLE!$O$20 -> 0 | E20: =SORTIEDETAILLE!$O$24 -> 100000 | H20: =SORTIEDETAILLE!$O$26 -> 200000 | I20: =SUM(B20:H20) -> 5203745.3
A22: TOTAL | B22: =SUM(B8:B21) -> 4862745.3 | C22: =SUM(C8:C21) -> 305500 | D22: =SUM(D8:D21) -> 613500 | E22: =SUM(E8:E21) -> 1150000 | F22: =SUM(F8:F21) -> 0 | G22: =SUM(G8:G21) -> 0 | H22: =SUM(H8:H21) -> 1100000 | I22: =SUM(I8:I21) -> 8031745.3

Sheet SORTIEDETAILLE
B1: SORTIE DETAILLEES DES DIFFERENTES RUBRIQUES
A2: ANNEE | B2: 2017-2018
A6: LIBELLE | B6: COMPTE | C6: AOUT 2017 | D6: SEPTEMBRE | E6: OCTOBRE | F6: NOVEMBRE | G6: DÉCEMBRE | H6: JANVIER | I6: FÉVRIER | J6: MARS | K6: AVRIL | L6: MAI | M6: JUIN | N6: JUILLET | O6: AOÛT
A8: PRÊT | C8: 150000 | D8: 600000 | E8: MUET | F8: 1000000 | G8: 600000 | H8: 990000 | I8: 1850000 | J8: 700000 | K8: 2000000 | L8: 2000000 | M8: 500000
A9: COMMUNICATION | B9: FONDS DE ROULEMENT | C9: 5000 | D9: 3000 | F9: 18000 | G9: 5000 | M9: 3000
A10: COMMISSION | B10: FONDS DE ROULEMENT | D10: 57500 | G10: 24000 | H10: 18000 | J10: 14000 | K10: 12000 | L10: 15000 | O10: =33000+8000 -> 41000
A11: AIDE UEEB ET CONT FEMME | B11: FONDS DE ROULEMENT | M11: 90000
A13: S/TOTAL | C13: =SUM(C9:C11) -> 5000 | D13: =SUM(D9:D11) -> 60500 | E13: =SUM(E9:E11) -> 0 | F13: =SUM(F9:F11) -> 18000 | G13: =SUM(G9:G11) -> 29000 | H13: =SUM(H9:H11) -> 18000 | I13: =SUM(I9:I11) -> 0 | J13: =SUM(J9:J11) -> 14000 | ... O13: =SUM(O9:O11) -> 41000
A15: ACHAT SOURIS ET PHOTOCOPIE | B15: FRAIS EXEPTIONNEL | H15: 3500
A16: GRATIFICATION BUREAU | B16: FRAIS EXEPTIONNEL | I16: 200000
A17: CONTRIBUTION ET PRÊT CONSEIL | B17: FRAIS EXEPTIONNEL | I17: 110000
A18: FESTAC | B18: FRAIS EXEPTIONNEL | F18: 300000
A20: S/TOTAL | C20: =SUM(C15:C18) -> 0 | D20: =SUM(D15:D18) -> 0 | E20: =SUM(E15:E18) -> 0 | F20: =SUM(F15:F18) -> 300000 | G20: =SUM(G15:G18) -> 0 | H20: =SUM(H15:H18) -> 3500 | I20: =SUM(I15:I18) -> 310000 | J20: =SUM(J15:J18) -> 0 | ... O20: =SUM(O15:O18) -> 0
A22: COLLATION | B22: COLLATION | C22: 100000 | D22: 100000 | F22: 100000 | G22: 100000 | H22: 100000 | J22: 100000 | K22: 100000 | L22: 100000 | M22: 100000 | N22: 100000 | O22: 100000
A23: BOISSON | B23: COLLATION | F23: 10000 | N23: 40000
A24: S/TOTAL | C24: =SUM(C22:C23) -> 100000 | D24: =SUM(D22:D23) -> 100000 | E24: =SUM(E22:E23) -> 0 | F24: =SUM(F22:F23) -> 110000 | G24: =SUM(G22:G23) -> 100000 | H24: =SUM(H22:H23) -> 100000 | I24: =SUM(I22:I23) -> 0 | J24: =SUM(J22:J23) -> 100000 | ... O24: =SUM(O22:O23) -> 100000
A26: DECES | B26: MUTUELLE | F26: 100000 | H26: 100000 | L26: 100000 | M26: 100000 | N26: 500000 | O26: 200000
A28: S/TOTAL | C28: =C13+C20+C24+C26 -> 105000 | D28: =D13+D20+D24+D26 -> 160500 | E28: =E13+E20+E24+E26 -> 0 | F28: =F13+F20+F24+F26 -> 528000 | G28: =G13+G20+G24+G26 -> 129000 | H28: =H13+H20+H24+H26 -> 221500 | I28: =I13+I20+I24+I26 -> 310000 | J28: =J13+J20+J24+J26 -> 114000 | ... O28: =O13+O20+O24+O26 -> 341000

Sheet INVENT2016_2017
B1: CALCUL INTERET EPARGNE DECEMBRE 2016- JUILLET 2017
A3: NOM ET PRENOM | B3: FONDS CAISSE | C3: RELIQUAT | D3: EPARGNE | E3: INTERETEPARGNE | F3: TOTAL AVOIR | G3: SANCTION | H3: AVANCE | I3: TOTAL A PERCEVOIR | J3: NOUVEAU FONDS | K3: SOLDE TOUT COMPTE | L3: EMPRUNT | M3: INTERET EMPRUNT | N3: A REMBOURSER AOUT 2017
A4: ASELBY | B4: 0 | C4: =[5]TONT20000DEC2016!$D5 -> 355097 | E4: =[5]TONT20000DEC2016!$E5+[5]TONT20000JANV2017!$C5+[5]TONT20000FEV2017!$C5+[5]TONT20000MARS2017!$C5+[5]TONT20000AVRIL2017!$C5+[5]TONT20000MAI2017!$C5+[5]TONT20000JUIN2017!$C5+[5]TONT20000JUIL2017!$C5 -> 23403.204 | F4: =+C4+D4+E4 -> 378500.2 | K4: =B4+I4-N4 -> 0
A5: BAKOP ACHILLE | B5: 420000 | C5: =[5]TONT20000DEC2016!$D6 -> 51993 | E5: =[5]TONT20000DEC2016!$E6+[5]TONT20000JANV2017!$C6+[5]TONT20000FEV2017!$C6+[5]TONT20000MARS2017!$C6+[5]TONT20000AVRIL2017!$C6+[5]TONT20000MAI2017!$C6+[5]TONT20000JUIN2017!$C6+[5]TONT20000JUIL2017!$C6 -> 31107.412 | F5: =+C5+D5+E5 -> 83100.412 | G5: 23250 | J5: =[11]MVTSEPT!$C6 -> 450000 | K5: =B5+I5-N5 -> -168000 | M5: =[5]TONT20000DEC2016!R6+[5]TONT20000JANV2017!P6+[5]TONT20000FEV2017!P6+[5]TONT20000MARS2017!P6+[5]TONT20000AVRIL2017!P6+[5]TONT20000MAI2017!P6+[5]TONT20000JUIN2017!P6+[5]TONT20000JUIL2017!P6 -> 0 | N5: =[8]EMPRUNT!$D6 -> 588000
A6: BOUTCHOUANG WILLIAM | B6: 420000 | C6: =[5]TONT20000DEC2016!$D7 -> 2720 | D6: =+[5]TONT20000DEC2016!$L7+[5]TONT20000JANV2017!$J7+[5]TONT20000FEV2017!$J7+[5]TONT20000MARS2017!$J7+[5]TONT20000AVRIL2017!$J7+[5]TONT20000MAI2017!$J7+[5]TONT20000JUIN2017!$J7+[5]TONT20000JUIL2017!$J7 -> 24000 | E6: =[5]TONT20000DEC2016!$E7+[5]TONT20000JANV2017!$C7+[5]TONT20000FEV2017!$C7+[5]TONT20000MARS2017!$C7+[5]TONT20000AVRIL2017!$C7+[5]TONT20000MAI2017!$C7+[5]TONT20000JUIN2017!$C7+[5]TONT20000JUIL2017!$C7 -> 28906.871 | F6: =+C6+D6+E6 -> 55626.871 | G6: 100 | H6: 8000 | I6: =F6-G6-H6 -> 47526.871 | J6: =[11]MVTSEPT!$C7 -> 450000 | K6: =B6+I6-N6 -> -316473.13 | M6: =[5]TONT20000DEC2016!R7+[5]TONT20000JANV2017!P7+[5]TONT20000FEV2017!P7+[5]TONT20000MARS2017!P7+[5]TONT20000AVRIL2017!P7+[5]TONT20000MAI2017!P7+[5]TONT20000JUIN2017!P7+[5]TONT20000JUIL2017!P7 -> 0 | N6: =[8]EMPRUNT!$D7 -> 784000
A7: CHINGUE FABRICE | B7: 420000 | C7: =[5]TONT20000DEC2016!$D8 -> 5874 | D7: =+[5]TONT20000DEC2016!$L8+[5]TONT20000JANV2017!$J8+[5]TONT20000FEV2017!$J8+[5]TONT20000MARS2017!$J8+[5]TONT20000AVRIL2017!$J8+[5]TONT20000MAI2017!$J8+[5]TONT20000JUIN2017!$J8+[5]TONT20000JUIL2017!$J8 -> 24000 | E7: =[5]TONT20000DEC2016!$E8+[5]TONT20000JANV2017!$C8+[5]TONT20000FEV2017!$C8+[5]TONT20000MARS2017!$C8+[5]TONT20000AVRIL2017!$C8+[5]TONT20000MAI2017!$C8+[5]TONT20000JUIN2017!$C8+[5]TONT20000JUIL2017!$C8 -> 29114.74 | F7: =+C7+D7+E7 -> 58988.74 | G7: 19100 | I7: =F7-G7-H7 -> 39888.74 | J7: =[11]MVTSEPT!$C8 -> 450000 | K7: =B7+I7-N7 -> -833711.26 | M7: =[5]TONT20000DEC2016!R8+[5]TONT20000JANV2017!P8+[5]TONT20000FEV2017!P8+[5]TONT20000MARS2017!P8+[5]TONT20000AVRIL2017!P8+[5]TONT20000MAI2017!P8+[5]TONT20000JUIN2017!P8+[5]TONT20000JUIL2017!P8 -> 0 | N7: =[8]EMPRUNT!$D8 -> 1293600
A8: DJOMO JEAN PAUL | B8: 420000 | C8: =[5]TONT20000DEC2016!$D9 -> 2570 | D8: =+[5]TONT20000DEC2016!$L9+[5]TONT20000JANV2017!$J9+[5]TONT20000FEV2017!$J9+[5]TONT20000MARS2017!$J9+[5]TONT20000AVRIL2017!$J9+[5]TONT20000MAI2017!$J9+[5]TONT20000JUIN2017!$J9+[5]TONT20000JUIL2017!$J9 -> 34500 | E8: =[5]TONT20000DEC2016!$E9+[5]TONT20000JANV2017!$C9+[5]TONT20000FEV2017!$C9+[5]TONT20000MARS2017!$C9+[5]TONT20000AVRIL2017!$C9+[5]TONT20000MAI2017!$C9+[5]TONT20000JUIN2017!$C9+[5]TONT20000JUIL2017!$C9 -> 29354.098 | F8: =+C8+D8+E8 -> 66424.098 | G8: 43200 | I8: =F8-G8-H8 -> 23224.098 | J8: =[11]MVTSEPT!$C9 -> 450000 | K8: =B8+I8-N8 -> -573775.9 | M8: =[5]TONT20000DEC2016!R9+[5]TONT20000JANV2017!P9+[5]TONT20000FEV2017!P9+[5]TONT20000MARS2017!P9+[5]TONT20000AVRIL2017!P9+[5]TONT20000MAI2017!P9+[5]TONT20000JUIN2017!P9+[5]TONT20000JUIL2017!P9 -> 120000 | N8: =[8]EMPRUNT!$D9 -> 1017000
A9: DJOUKWE NANGUEN GUY BLAISE | B9: 420000 | C9: =[5]TONT20000DEC2016!$D10 -> 2697 | D9: =+[5]TONT20000DEC2016!$L10+[5]TONT20000JANV2017!$J10+[5]TONT20000FEV2017!$J10+[5]TONT20000MARS2017!$J10+[5]TONT20000AVRIL2017!$J10+[5]TONT20000MAI2017!$J10+[5]TONT20000JUIN2017!$J10+[5]TONT20000JUIL2017!$J10 -> 37000 | E9: =[5]TONT20000DEC2016!$E10+[5]TONT20000JANV2017!$C10+[5]TONT20000FEV2017!$C10+[5]TONT20000MARS2017!$C10+[5]TONT20000AVRIL2017!$C10+[5]TONT20000MAI2017!$C10+[5]TONT20000JUIN2017!$C10+[5]TONT20000JUIL2017!$C10 -> 29309.04 | F9: =+C9+D9+E9 -> 69006.04 | I9: =F9-G9-H9 -> 69006.04 | J9: =[11]MVTSEPT!$C10 -> 450000 | K9: =B9+I9-N9 -> 349006.04 | M9: =[5]TONT20000DEC2016!R10+[5]TONT20000JANV2017!P10+[5]TONT20000FEV2017!P10+[5]TONT20000MARS2017!P10+[5]TONT20000AVRIL2017!P10+[5]TONT20000MAI2017!P10+[5]TONT20000JUIN2017!P10+[5]TONT20000JUIL2017!P10 -> 0 | N9: =[8]EMPRUNT!$D10 -> 140000
A10: DJOSSEU JOSUE | B10: 0 | C10: =[5]TONT20000DEC2016!$D11 -> 0 | K10: =B10+I10-N10 -> 0
A11: DJOUNKEP SAMUEL | B11: 420000 | C11: =[5]TONT20000DEC2016!$D12 -> 635540 | D11: =+[5]TONT20000DEC2016!$L12+[5]TONT20000JANV2017!$J12+[5]TONT20000FEV2017!$J12+[5]TONT20000MARS2017!$J12+[5]TONT20000AVRIL2017!$J12+[5]TONT20000MAI2017!$J12+[5]TONT20000JUIN2017!$J12+[5]TONT20000JUIL2017!$J12 -> 24000 | E11: =[5]TONT20000DEC2016!$E12+[5]TONT20000JANV2017!$C12+[5]TONT20000FEV2017!$C12+[5]TONT20000MARS2017!$C12+[5]TONT20000AVRIL2017!$C12+[5]TONT20000MAI2017!$C12+[5]TONT20000JUIN2017!$C12+[5]TONT20000JUIL2017!$C12 -> 70613.828 | F11: =+C11+D11+E11 -> 730153.83 | G11: 0 | I11: =F11-G11-H11 -> 730153.83 | J11: =[11]MVTSEPT!$C11 -> 450000 | K11: =B11+I11-N11 -> 30153.828 | M11: =[5]TONT20000DEC2016!R12+[5]TONT20000JANV2017!P12+[5]TONT20000FEV2017!P12+[5]TONT20000MARS2017!P12+[5]TONT20000AVRIL2017!P12+[5]TONT20000MAI2017!P12+[5]TONT20000JUIN2017!P12+[5]TONT20000JUIL2017!P12 -> 100000 | N11: =[8]EMPRUNT!$D11 -> 1120000
A12: DJUOMBESSY ANTOINE | B12: 420000 | C12: =[5]TONT20000DEC2016!$D13 -> 2746 | D12: =+[5]TONT20000DEC2016!$L13+[5]TONT20000JANV2017!$J13+[5]TONT20000FEV2017!$J13+[5]TONT20000MARS2017!$J13+[5]TONT20000AVRIL2017!$J13+[5]TONT20000MAI2017!$J13+[5]TONT20000JUIN2017!$J13+[5]TONT20000JUIL2017!$J13 -> 24000 | E12: =[5]TONT20000DEC2016!$E13+[5]TONT20000JANV2017!$C13+[5]TONT20000FEV2017!$C13+[5]TONT20000MARS2017!$C13+[5]TONT20000AVRIL2017!$C13+[5]TONT20000MAI2017!$C13+[5]TONT20000JUIN2017!$C13+[5]TONT20000JUIL2017!$C13 -> 28908.584 | F12: =+C12+D12+E12 -> 55654.584 | G12: 8000 | I12: =F12-G12-H12 -> 47654.584 | J12: =[11]MVTSEPT!$C12 -> 450000 | K12: =B12+I12-N12 -> -316345.42 | M12: =[5]TONT20000DEC2016!R13+[5]TONT20000JANV2017!P13+[5]TONT20000FEV2017!P13+[5]TONT20000MARS2017!P13+[5]TONT20000AVRIL2017!P13+[5]TONT20000MAI2017!P13+[5]TONT20000JUIN2017!P13+[5]TONT20000JUIL2017!P13 -> 70000 | N12: =[8]EMPRUNT!$D12 -> 784000
A13: DONHOU DAVID | B13: 420000 | C13: =[5]TONT20000DEC2016!$D14 -> 53748 | D13: =+[5]TONT20000DEC2016!$L14+[5]TONT20000JANV2017!$J14+[5]TONT20000FEV2017!$J14+[5]TONT20000MARS2017!$J14+[5]TONT20000AVRIL2017!$J14+[5]TONT20000MAI2017!$J14+[5]TONT20000JUIN2017!$J14+[5]TONT20000JUIL2017!$J14 -> 24000 | E13: =[5]TONT20000DEC2016!$E14+[5]TONT20000JANV2017!$C14+[5]TONT20000FEV2017!$C14+[5]TONT20000MARS2017!$C14+[5]TONT20000AVRIL2017!$C14+[5]TONT20000MAI2017!$C14+[5]TONT20000JUIN2017!$C14+[5]TONT20000JUIL2017!$C14 -> 32269.948 | F13: =+C13+D13+E13 -> 110017.95 | G13: 0 | I13: =F13-G13-H13 -> 110017.95 | J13: =[11]MVTSEPT!$C13 -> 450000 | K13: =B13+I13-N13 -> 530017.95 | M13: =[5]TONT20000DEC2016!R14+[5]TONT20000JANV2017!P14+[5]TONT20000FEV2017!P14+[5]TONT20000MARS2017!P14+[5]TONT20000AVRIL2017!P14+[5]TONT20000MAI2017!P14+[5]TONT20000JUIN2017!P14+[5]TONT20000JUIL2017!P14 -> 0 | N13: =[8]EMPRUNT!$D13 -> 0
A14: FOTSO THOMAS | B14: 420000 | C14: =[5]TONT20000DEC2016!$D15 -> 2522 | D14: =+[5]TONT20000DEC2016!$L15+[5]TONT20000JANV2017!$J15+[5]TONT20000FEV2017!$J15+[5]TONT20000MARS2017!$J15+[5]TONT20000AVRIL2017!$J15+[5]TONT20000MAI2017!$J15+[5]TONT20000JUIN2017!$J15+[5]TONT20000JUIL2017!$J15 -> 24000 | E14: =[5]TONT20000DEC2016!$E15+[5]TONT20000JANV2017!$C15+[5]TONT20000FEV2017!$C15+[5]TONT20000MARS2017!$C15+[5]TONT20000AVRIL2017!$C15+[5]TONT20000MAI2017!$C15+[5]TONT20000JUIN2017!$C15+[5]TONT20000JUIL2017!$C15 -> 28893.821 | F14: =+C14+D14+E14 -> 55415.821 | G14: 8000 | I14: =F14-G14-H14 -> 47415.821 | J14: =[11]MVTSEPT!$C14 -> 450000 | K14: =B14+I14-N14 -> -826184.18 | M14: =[5]TONT20000DEC2016!R15+[5]TONT20000JANV2017!P15+[5]TONT20000FEV2017!P15+[5]TONT20000MARS2017!P15+[5]TONT20000AVRIL2017!P15+[5]TONT20000MAI2017!P15+[5]TONT20000JUIN2017!P15+[5]TONT20000JUIL2017!P15 -> 0 | N14: =[8]EMPRUNT!$D14 -> 1293600
A15: HENGUE PAUL OMER | B15: 420000 | D15: =+[5]TONT20000DEC2016!$L16+[5]TONT20000JANV2017!$J16+[5]TONT20000FEV2017!$J16+[5]TONT20000MARS2017!$J16+[5]TONT20000AVRIL2017!$J16+[5]TONT20000MAI2017!$J16+[5]TONT20000JUIN2017!$J16+[5]TONT20000JUIL2017!$J16 -> 90000 | E15: =[5]TONT20000DEC2016!$E16+[5]TONT20000JANV2017!$C16+[5]TONT20000FEV2017!$C16+[5]TONT20000MARS2017!$C16+[5]TONT20000AVRIL2017!$C16+[5]TONT20000MAI2017!$C16+[5]TONT20000JUIN2017!$C16+[5]TONT20000JUIL2017!$C16 -> 33077.435 | F15: =+C15+D15+E15 -> 123077.43 | G15: 8100 | J15: =[11]MVTSEPT!$C15 -> 450000 | K15: =B15+I15-N15 -> 420000 | M15: =[5]TONT20000DEC2016!R16+[5]TONT20000JANV2017!P16+[5]TONT20000FEV2017!P16+[5]TONT20000MARS2017!P16+[5]TONT20000AVRIL2017!P16+[5]TONT20000MAI2017!P16+[5]TONT20000JUIN2017!P16+[5]TONT20000JUIL2017!P16 -> 0 | N15: =[8]EMPRUNT!$D15 -> 0
A16: HODIEP JULES | B16: 50000 | C16: =[5]TONT20000DEC2016!$D17 -> 260 | E16: =[5]TONT20000DEC2016!$E17+[5]TONT20000JANV2017!$C17+[5]TONT20000FEV2017!$C17+[5]TONT20000MARS2017!$C17+[5]TONT20000AVRIL2017!$C17+[5]TONT20000MAI2017!$C17+[5]TONT20000JUIN2017!$C17+[5]TONT20000JUIL2017!$C17 -> 3312.4612 | F16: =+C16+D16+E16 -> 3572.4612 | G16: 0 | J16: =[11]MVTSEPT!$C16 -> 80000 | K16: =B16+I16-N16 -> 50000 | M16: =[5]TONT20000DEC2016!R17+[5]TONT20000JANV2017!P17+[5]TONT20000FEV2017!P17+[5]TONT20000MARS2017!P17+[5]TONT20000AVRIL2017!P17+[5]TONT20000MAI2017!P17+[5]TONT20000JUIN2017!P17+[5]TONT20000JUIL2017!P17 -> 0 | N16: =[8]EMPRUNT!$D16 -> 0
A17: HOTCHO BENJAMIN | B17: 420000 | C17: =[5]TONT20000DEC2016!$D18 -> 112685 | D17: =+[5]TONT20000DEC2016!$L18+[5]TONT20000JANV2017!$J18+[5]TONT20000FEV2017!$J18+[5]TONT20000MARS2017!$J18+[5]TONT20000AVRIL2017!$J18+[5]TONT20000MAI2017!$J18+[5]TONT20000JUIN2017!$J18+[5]TONT20000JUIL2017!$J18 -> 24000 | E17: =[5]TONT20000DEC2016!$E18+[5]TONT20000JANV2017!$C18+[5]TONT20000FEV2017!$C18+[5]TONT20000MARS2017!$C18+[5]TONT20000AVRIL2017!$C18+[5]TONT20000MAI2017!$C18+[5]TONT20000JUIN2017!$C18+[5]TONT20000JUIL2017!$C18 -> 36154.28 | F17: =+C17+D17+E17 -> 172839.28 | G17: 20000 | H17: 70000 | I17: =F17-G17-H17 -> 82839.28 | J17: =[11]MVTSEPT!$C17 -> 450000 | K17: =B17+I17-N17 -> -281160.72 | M17: =[5]TONT20000DEC2016!R18+[5]TONT20000JANV2017!P18+[5]TONT20000FEV2017!P18+[5]TONT20000MARS2017!P18+[5]TONT20000AVRIL2017!P18+[5]TONT20000MAI2017!P18+[5]TONT20000JUIN2017!P18+[5]TONT20000JUIL2017!P18 -> 84000 | N17: =[8]EMPRUNT!$D17 -> 784000
A18: KEPHE DAVID | B18: 357000 | C18: =[5]TONT20000DEC2016!$D19 -> 177 | D18: =+[5]TONT20000DEC2016!$L19+[5]TONT20000JANV2017!$J19+[5]TONT20000FEV2017!$J19+[5]TONT20000MARS2017!$J19+[5]TONT20000AVRIL2017!$J19+[5]TONT20000MAI2017!$J19+[5]TONT20000JUIN2017!$J19+[5]TONT20000JUIL2017!$J19 -> 24000 | E18: =[5]TONT20000DEC2016!$E19+[5]TONT20000JANV2017!$C19+[5]TONT20000FEV2017!$C19+[5]TONT20000MARS2017!$C19+[5]TONT20000AVRIL2017!$C19+[5]TONT20000MAI2017!$C19+[5]TONT20000JUIN2017!$C19+[5]TONT20000JUIL2017!$C19 -> 24587.16 | F18: =+C18+D18+E18 -> 48764.16 | G18: 100 | I18: =F18-G18-H18 -> 48664.16 | J18: =[11]MVTSEPT!$C18 -> 387000 | K18: =B18+I18-N18 -> 405664.16 | M18: =[5]TONT20000DEC2016!R19+[5]TONT20000JANV2017!P19+[5]TONT20000FEV2017!P19+[5]TONT20000MARS2017!P19+[5]TONT20000AVRIL2017!P19+[5]TONT20000MAI2017!P19+[5]TONT20000JUIN2017!P19+[5]TONT20000JUIL2017!P19 -> 0 | N18: =[8]EMPRUNT!$D18 -> 0
A19: KEPSEU FRANCIS | B19: 420000 | C19: =[5]TONT20000DEC2016!$D20 -> 705425 | D19: =+[5]TONT20000DEC2016!$L20+[5]TONT20000JANV2017!$J20+[5]TONT20000FEV2017!$J20+[5]TONT20000MARS2017!$J20+[5]TONT20000AVRIL2017!$J20+[5]TONT20000MAI2017!$J20+[5]TONT20000JUIN2017!$J20+[5]TONT20000JUIL2017!$J20 -> 2048000 | E19: =[5]TONT20000DEC2016!$E20+[5]TONT20000JANV2017!$C20+[5]TONT20000FEV2017!$C20+[5]TONT20000MARS2017!$C20+[5]TONT20000AVRIL2017!$C20+[5]TONT20000MAI2017!$C20+[5]TONT20000JUIN2017!$C20+[5]TONT20000JUIL2017!$C20 -> 158003.91 | F19: =+C19+D19+E19 -> 2911428.9 | G19: 0 | H19: 1000000 | I19: =F19-G19-H19 -> 1911428.9 | J19: =[11]MVTSEPT!$C19 -> 450000 | K19: =B19+I19-N19 -> 2331428.9 | M19: =[5]TONT20000DEC2016!R20+[5]TONT20000JANV2017!P20+[5]TONT20000FEV2017!P20+[5]TONT20000MARS2017!P20+[5]TONT20000AVRIL2017!P20+[5]TONT20000MAI2017!P20+[5]TONT20000JUIN2017!P20+[5]TONT20000JUIL2017!P20 -> 0 | N19: =[8]EMPRUNT!$D19 -> 0
A20: KOUAMOU EMMANUEL | B20: 420000 | C20: =[5]TONT20000DEC2016!$D21 -> 2357 | D20: =+[5]TONT20000DEC2016!$L21+[5]TONT20000JANV2017!$J21+[5]TONT20000FEV2017!$J21+[5]TONT20000MARS2017!$J21+[5]TONT20000AVRIL2017!$J21+[5]TONT20000MAI2017!$J21+[5]TONT20000JUIN2017!$J21+[5]TONT20000JUIL2017!$J21 -> 24000 | E20: =[5]TONT20000DEC2016!$E21+[5]TONT20000JANV2017!$C21+[5]TONT20000FEV2017!$C21+[5]TONT20000MARS2017!$C21+[5]TONT20000AVRIL2017!$C21+[5]TONT20000MAI2017!$C21+[5]TONT20000JUIN2017!$C21+[5]TONT20000JUIL2017!$C21 -> 28882.947 | F20: =+C20+D20+E20 -> 55239.947 | G20: 0 | H20: 8000 | I20: =F20-G20-H20 -> 47239.947 | J20: =[11]MVTSEPT!$C20 -> 450000 | K20: =B20+I20-N20 -> -632760.05 | M20: =[5]TONT20000DEC2016!R21+[5]TONT20000JANV2017!P21+[5]TONT20000FEV2017!P21+[5]TONT20000MARS2017!P21+[5]TONT20000AVRIL2017!P21+[5]TONT20000MAI2017!P21+[5]TONT20000JUIN2017!P21+[5]TONT20000JUIL2017!P21 -> 0 | N20: =[8]EMPRUNT!$D20 -> 1100000
A21: KOUAMOU MOISE | B21: 420000 | C21: =[5]TONT20000DEC2016!$D22 -> 3048 | D21: =+[5]TONT20000DEC2016!$L22+[5]TONT20000JANV2017!$J22+[5]TONT20000FEV2017!$J22+[5]TONT20000MARS2017!$J22+[5]TONT20000AVRIL2017!$J22+[5]TONT20000MAI2017!$J22+[5]TONT20000JUIN2017!$J22+[5]TONT20000JUIL2017!$J22 -> 24000 | E21: =[5]TONT20000DEC2016!$E22+[5]TONT20000JANV2017!$C22+[5]TONT20000FEV2017!$C22+[5]TONT20000MARS2017!$C22+[5]TONT20000AVRIL2017!$C22+[5]TONT20000MAI2017!$C22+[5]TONT20000JUIN2017!$C22+[5]TONT20000JUIL2017!$C22 -> 28860.893 | F21: =+C21+D21+E21 -> 55908.893 | G21: 2100 | I21: =F21-G21-H21 -> 53808.893 | J21: =[11]MVTSEPT!$C21 -> 450000 | K21: =B21+I21-N21 -> -118191.11 | M21: =[5]TONT20000DEC2016!R22+[5]TONT20000JANV2017!P22+[5]TONT20000FEV2017!P22+[5]TONT20000MARS2017!P22+[5]TONT20000AVRIL2017!P22+[5]TONT20000MAI2017!P22+[5]TONT20000JUIN2017!P22+[5]TONT20000JUIL2017!P22 -> 15000 | N21: =[8]EMPRUNT!$D21 -> 592000
A22: KOUAMO VICTOR PEGUY | B22: 420000 | C22: =[5]TONT20000DEC2016!$D23 -> 2686 | D22: =+[5]TONT20000DEC2016!$L23+[5]TONT20000JANV2017!$J23+[5]TONT20000FEV2017!$J23+[5]TONT20000MARS2017!$J23+[5]TONT20000AVRIL2017!$J23+[5]TONT20000MAI2017!$J23+[5]TONT20000JUIN2017!$J23+[5]TONT20000JUIL2017!$J23 -> 24000 | E22: =[5]TONT20000DEC2016!$E23+[5]TONT20000JANV2017!$C23+[5]TONT20000FEV2017!$C23+[5]TONT20000MARS2017!$C23+[5]TONT20000AVRIL2017!$C23+[5]TONT20000MAI2017!$C23+[5]TONT20000JUIN2017!$C23+[5]TONT20000JUIL2017!$C23 -> 28904.63 | F22: =+C22+D22+E22 -> 55590.63 | G22: 16500 | I22: =F22-G22-H22 -> 39090.63 | J22: =[11]MVTSEPT!$C22 -> 450000 | K22: =B22+I22-N22 -> -436909.37 | M22: =[5]TONT20000DEC2016!R23+[5]TONT20000JANV2017!P23+[5]TONT20000FEV2017!P23+[5]TONT20000MARS2017!P23+[5]TONT20000AVRIL2017!P23+[5]TONT20000MAI2017!P23+[5]TONT20000JUIN2017!P23+[5]TONT20000JUIL2017!P23 -> 0 | N22: =[8]EMPRUNT!$D22 -> 896000
A23: KOUATCHO MESSACK | B23: 420000 | C23: =[5]TONT20000DEC2016!$D24 -> 3818 | D23: =+[5]TONT20000DEC2016!$L24+[5]TONT20000JANV2017!$J24+[5]TONT20000FEV2017!$J24+[5]TONT20000MARS2017!$J24+[5]TONT20000AVRIL2017!$J24+[5]TONT20000MAI2017!$J24+[5]TONT20000JUIN2017!$J24+[5]TONT20000JUIL2017!$J24 -> 24000 | E23: =[5]TONT20000DEC2016!$E24+[5]TONT20000JANV2017!$C24+[5]TONT20000FEV2017!$C24+[5]TONT20000MARS2017!$C24+[5]TONT20000AVRIL2017!$C24+[5]TONT20000MAI2017!$C24+[5]TONT20000JUIN2017!$C24+[5]TONT20000JUIL2017!$C24 -> 28979.236 | F23: =+C23+D23+E23 -> 56797.236 | G23: 20000 | I23: =F23-G23-H23 -> 36797.236 | J23: =[11]MVTSEPT!$C23 -> 450000 | K23: =B23+I23-N23 -> -663202.76 | M23: =[5]TONT20000DEC2016!R24+[5]TONT20000JANV2017!P24+[5]TONT20000FEV2017!P24+[5]TONT20000MARS2017!P24+[5]TONT20000AVRIL2017!P24+[5]TONT20000MAI2017!P24+[5]TONT20000JUIN2017!P24+[5]TONT20000JUIL2017!P24 -> 120000 | N23: =[8]EMPRUNT!$D23 -> 1120000
A24: LOWE JEAN | B24: 420000 | C24: =[5]TONT20000DEC2016!$D25 -> 2652 | D24: =+[5]TONT20000DEC2016!$L25+[5]TONT20000JANV2017!$J25+[5]TONT20000FEV2017!$J25+[5]TONT20000MARS2017!$J25+[5]TONT20000AVRIL2017!$J25+[5]TONT20000MAI2017!$J25+[5]TONT20000JUIN2017!$J25+[5]TONT20000JUIL2017!$J25 -> 21000 | E24: =[5]TONT20000DEC2016!$E25+[5]TONT20000JANV2017!$C25+[5]TONT20000FEV2017!$C25+[5]TONT20000MARS2017!$C25+[5]TONT20000AVRIL2017!$C25+[5]TONT20000MAI2017!$C25+[5]TONT20000JUIN2017!$C25+[5]TONT20000JUIL2017!$C25 -> 28854.896 | F24: =+C24+D24+E24 -> 52506.896 | G24: 0 | H24: 5000 | I24: =F24-G24-H24 -> 47506.896 | J24: =[11]MVTSEPT!$C24 -> 450000 | K24: =B24+I24-N24 -> 313006.9 | M24: =[5]TONT20000DEC2016!R25+[5]TONT20000JANV2017!P25+[5]TONT20000FEV2017!P25+[5]TONT20000MARS2017!P25+[5]TONT20000AVRIL2017!P25+[5]TONT20000MAI2017!P25+[5]TONT20000JUIN2017!P25+[5]TONT20000JUIL2017!P25 -> 0 | N24: =[8]EMPRUNT!$D24 -> 154500
A25: NANKAM APPOLINAIRE | B25: 420000 | C25: =[5]TONT20000DEC2016!$D26 -> 2741 | D25: =+[5]TONT20000DEC2016!$L26+[5]TONT20000JANV2017!$J26+[5]TONT20000FEV2017!$J26+[5]TONT20000MARS2017!$J26+[5]TONT20000AVRIL2017!$J26+[5]TONT20000MAI2017!$J26+[5]TONT20000JUIN2017!$J26+[5]TONT20000JUIL2017!$J26 -> 24000 | E25: =[5]TONT20000DEC2016!$E26+[5]TONT20000JANV2017!$C26+[5]TONT20000FEV2017!$C26+[5]TONT20000MARS2017!$C26+[5]TONT20000AVRIL2017!$C26+[5]TONT20000MAI2017!$C26+[5]TONT20000JUIN2017!$C26+[5]TONT20000JUIL2017!$C26 -> 28908.255 | F25: =+C25+D25+E25 -> 55649.255 | G25: 100 | H25: 8000 | I25: =F25-G25-H25 -> 47549.255 | J25: =[11]MVTSEPT!$C25 -> 450000 | K25: =B25+I25-N25 -> 467549.25 | M25: =[5]TONT20000DEC2016!R26+[5]TONT20000JANV2017!P26+[5]TONT20000FEV2017!P26+[5]TONT20000MARS2017!P26+[5]TONT20000AVRIL2017!P26+[5]TONT20000MAI2017!P26+[5]TONT20000JUIN2017!P26+[5]TONT20000JUIL2017!P26 -> 0 | N25: =[8]EMPRUNT!$D25 -> 0
A26: NDJOMO ETIENNE | B26: 420000 | C26: =[5]TONT20000DEC2016!$D27 -> 2818 | D26: =+[5]TONT20000DEC2016!$L27+[5]TONT20000JANV2017!$J27+[5]TONT20000FEV2017!$J27+[5]TONT20000MARS2017!$J27+[5]TONT20000AVRIL2017!$J27+[5]TONT20000MAI2017!$J27+[5]TONT20000JUIN2017!$J27+[5]TONT20000JUIL2017!$J27 -> 64000 | E26: =[5]TONT20000DEC2016!$E27+[5]TONT20000JANV2017!$C27+[5]TONT20000FEV2017!$C27+[5]TONT20000MARS2017!$C27+[5]TONT20000AVRIL2017!$C27+[5]TONT20000MAI2017!$C27+[5]TONT20000JUIN2017!$C27+[5]TONT20000JUIL2017!$C27 -> 30658.114 | F26: =+C26+D26+E26 -> 97476.114 | G26: 0 | H26: 50000 | I26: =F26-G26-H26 -> 47476.114 | J26: =[11]MVTSEPT!$C26 -> 450000 | K26: =B26+I26-N26 -> -204523.89 | M26: =[5]TONT20000DEC2016!R27+[5]TONT20000JANV2017!P27+[5]TONT20000FEV2017!P27+[5]TONT20000MARS2017!P27+[5]TONT20000AVRIL2017!P27+[5]TONT20000MAI2017!P27+[5]TONT20000JUIN2017!P27+[5]TONT20000JUIL2017!P27 -> 84000 | N26: =[8]EMPRUNT!$D26 -> 672000
A27: NDOMBOU JEAN CLAUDE | B27: 420000 | C27: =[5]TONT20000DEC2016!$D28 -> 0 | E27: =[5]TONT20000DEC2016!$E28+[5]TONT20000JANV2017!$C28+[5]TONT20000FEV2017!$C28+[5]TONT20000MARS2017!$C28+[5]TONT20000AVRIL2017!$C28+[5]TONT20000MAI2017!$C28+[5]TONT20000JUIN2017!$C28+[5]TONT20000JUIL2017!$C28 -> 27680.734 | F27: =+C27+D27+E27 -> 27680.734 | G27: 0 | I27: =F27-G27-H27 -> 27680.734 | J27: =[11]MVTSEPT!$C27 -> 450000 | K27: =B27+I27-N27 -> 447680.73 | N27: =[8]EMPRUNT!$D27 -> 0
A28: NGONDIEP CLAUDE | B28: 420000 | C28: =[5]TONT20000DEC2016!$D29 -> 3250 | D28: =+[5]TONT20000DEC2016!$L29+[5]TONT20000JANV2017!$J29+[5]TONT20000FEV2017!$J29+[5]TONT20000MARS2017!$J29+[5]TONT20000AVRIL2017!$J29+[5]TONT20000MAI2017!$J29+[5]TONT20000JUIN2017!$J29+[5]TONT20000JUIL2017!$J29 -> 33000 | E28: =[5]TONT20000DEC2016!$E29+[5]TONT20000JANV2017!$C29+[5]TONT20000FEV2017!$C29+[5]TONT20000MARS2017!$C29+[5]TONT20000AVRIL2017!$C29+[5]TONT20000MAI2017!$C29+[5]TONT20000JUIN2017!$C29+[5]TONT20000JUIL2017!$C29 -> 29529.518 | F28: =+C28+D28+E28 -> 65779.518 | G28: 18100 | I28: =F28-G28-H28 -> 47679.518 | J28: =[11]MVTSEPT!$C28 -> 450000 | K28: =B28+I28-N28 -> -652320.48 | M28: =[5]TONT20000DEC2016!R29+[5]TONT20000JANV2017!P29+[5]TONT20000FEV2017!P29+[5]TONT20000MARS2017!P29+[5]TONT20000AVRIL2017!P29+[5]TONT20000MAI2017!P29+[5]TONT20000JUIN2017!P29+[5]TONT20000JUIL2017!P29 -> 120000 | N28: =[8]EMPRUNT!$D28 -> 1120000
A29: NGONGANG JEAN THEODORE | B29: 0 | C29: =[5]TONT20000DEC2016!$D30 -> 106 | E29: =[5]TONT20000DEC2016!$E30+[5]TONT20000JANV2017!$C30+[5]TONT20000FEV2017!$C30+[5]TONT20000MARS2017!$C30+[5]TONT20000AVRIL2017!$C30+[5]TONT20000MAI2017!$C30+[5]TONT20000JUIN2017!$C30+[5]TONT20000JUIL2017!$C30 -> 969.65037 | F29: =+C29+D29+E29 -> 1075.6504 | G29: 5250 | I29: =F29-G29-H29 -> -4174.3496 | J29: =[11]MVTSEPT!$C29 -> 30000 | K29: =B29+I29-N29 -> -4174.3496 | M29: =[5]TONT20000DEC2016!R30+[5]TONT20000JANV2017!P30+[5]TONT20000FEV2017!P30+[5]TONT20000MARS2017!P30+[5]TONT20000AVRIL2017!P30+[5]TONT20000MAI2017!P30+[5]TONT20000JUIN2017!P30+[5]TONT20000JUIL2017!P30 -> 0 | N29: =[8]EMPRUNT!$D29 -> 0
A30: NGUIEMEGNI MATHIEU BLAISE | B30: 420000 | C30: =[5]TONT20000DEC2016!$D31 -> 40133 | D30: =+[5]TONT20000DEC2016!$L31+[5]TONT20000JANV2017!$J31+[5]TONT20000FEV2017!$J31+[5]TONT20000MARS2017!$J31+[5]TONT20000AVRIL2017!$J31+[5]TONT20000MAI2017!$J31+[5]TONT20000JUIN2017!$J31+[5]TONT20000JUIL2017!$J31 -> 24000 | E30: =[5]TONT20000DEC2016!$E31+[5]TONT20000JANV2017!$C31+[5]TONT20000FEV2017!$C31+[5]TONT20000MARS2017!$C31+[5]TONT20000AVRIL2017!$C31+[5]TONT20000MAI2017!$C31+[5]TONT20000JUIN2017!$C31+[5]TONT20000JUIL2017!$C31 -> 31372.631 | F30: =+C30+D30+E30 -> 95505.631 | G30: 2300 | I30: =F30-G30-H30 -> 93205.631 | J30: =[11]MVTSEPT!$C30 -> 450000 | K30: =B30+I30-N30 -> 513205.63 | M30: =[5]TONT20000DEC2016!R31+[5]TONT20000JANV2017!P31+[5]TONT20000FEV2017!P31+[5]TONT20000MARS2017!P31+[5]TONT20000AVRIL2017!P31+[5]TONT20000MAI2017!P31+[5]TONT20000JUIN2017!P31+[5]TONT20000JUIL2017!P31 -> 0 | N30: =[8]EMPRUNT!$D30 -> 0
A31: NJEPDJIO MBOUKAM DELUXE | B31: 420000 | C31: =[5]TONT20000DEC2016!$D32 -> 2773 | D31: =+[5]TONT20000DEC2016!$L32+[5]TONT20000JANV2017!$J32+[5]TONT20000FEV2017!$J32+[5]TONT20000MARS2017!$J32+[5]TONT20000AVRIL2017!$J32+[5]TONT20000MAI2017!$J32+[5]TONT20000JUIN2017!$J32+[5]TONT20000JUIL2017!$J32 -> 29000 | E31: =[5]TONT20000DEC2016!$E32+[5]TONT20000JANV2017!$C32+[5]TONT20000FEV2017!$C32+[5]TONT20000MARS2017!$C32+[5]TONT20000AVRIL2017!$C32+[5]TONT20000MAI2017!$C32+[5]TONT20000JUIN2017!$C32+[5]TONT20000JUIL2017!$C32 -> 29236.873 | F31: =+C31+D31+E31 -> 61009.873 | G31: 200 | H31: 13900 | I31: =F31-G31-H31 -> 46909.873 | J31: =[11]MVTSEPT!$C31 -> 450000 | K31: =B31+I31-N31 -> -429090.13 | M31: =[5]TONT20000DEC2016!R32+[5]TONT20000JANV2017!P32+[5]TONT20000FEV2017!P32+[5]TONT20000MARS2017!P32+[5]TONT20000AVRIL2017!P32+[5]TONT20000MAI2017!P32+[5]TONT20000JUIN2017!P32+[5]TONT20000JUIL2017!P32 -> 96000 | N31: =[8]EMPRUNT!$D31 -> 896000
A32: NKAMGANG JUSTIN DEJOLIE | B32: 420000 | C32: =[5]TONT20000DEC2016!$D33 -> 69808 | D32: =+[5]TONT20000DEC2016!$L33+[5]TONT20000JANV2017!$J33+[5]TONT20000FEV2017!$J33+[5]TONT20000MARS2017!$J33+[5]TONT20000AVRIL2017!$J33+[5]TONT20000MAI2017!$J33+[5]TONT20000JUIN2017!$J33+[5]TONT20000JUIL2017!$J33 -> 50000 | E32: =[5]TONT20000DEC2016!$E33+[5]TONT20000JANV2017!$C33+[5]TONT20000FEV2017!$C33+[5]TONT20000MARS2017!$C33+[5]TONT20000AVRIL2017!$C33+[5]TONT20000MAI2017!$C33+[5]TONT20000JUIN2017!$C33+[5]TONT20000JUIL2017!$C33 -> 34505.881 | F32: =+C32+D32+E32 -> 154313.88 | G32: 0 | H32: 100000 | I32: =F32-G32-H32 -> 54313.881 | J32: =[11]MVTSEPT!$C32 -> 450000 | K32: =B32+I32-N32 -> -645686.12 | M32: =[5]TONT20000DEC2016!R33+[5]TONT20000JANV2017!P33+[5]TONT20000FEV2017!P33+[5]TONT20000MARS2017!P33+[5]TONT20000AVRIL2017!P33+[5]TONT20000MAI2017!P33+[5]TONT20000JUIN2017!P33+[5]TONT20000JUIL2017!P33 -> 0 | N32: =[8]EMPRUNT!$D32 -> 1120000
A33: NKEPSEU DIEUDONNE | B33: 420000 | C33: =[5]TONT20000DEC2016!$D34 -> 2772 | D33: =+[5]TONT20000DEC2016!$L34+[5]TONT20000JANV2017!$J34+[5]TONT20000FEV2017!$J34+[5]TONT20000MARS2017!$J34+[5]TONT20000AVRIL2017!$J34+[5]TONT20000MAI2017!$J34+[5]TONT20000JUIN2017!$J34+[5]TONT20000JUIL2017!$J34 -> 164000 | E33: =[5]TONT20000DEC2016!$E34+[5]TONT20000JANV2017!$C34+[5]TONT20000FEV2017!$C34+[5]TONT20000MARS2017!$C34+[5]TONT20000AVRIL2017!$C34+[5]TONT20000MAI2017!$C34+[5]TONT20000JUIN2017!$C34+[5]TONT20000JUIL2017!$C34 -> 37245.733 | F33: =+C33+D33+E33 -> 204017.73 | G33: 4000 | H33: 150000 | I33: =F33-G33-H33 -> 50017.733 | J33: =[11]MVTSEPT!$C33 -> 450000 | K33: =B33+I33-N33 -> -1982.267 | M33: =[5]TONT20000DEC2016!R34+[5]TONT20000JANV2017!P34+[5]TONT20000FEV2017!P34+[5]TONT20000MARS2017!P34+[5]TONT20000AVRIL2017!P34+[5]TONT20000MAI2017!P34+[5]TONT20000JUIN2017!P34+[5]TONT20000JUIL2017!P34 -> 0 | N33: =[8]EMPRUNT!$D33 -> 472000
A34: NKEPSEU HENANG RENE | B34: 0 | C34: =[5]TONT20000DEC2016!$D35 -> 0 | F34: =+C34+D34+E34 -> 0 | I34: =F34-G34-H34 -> 0 | K34: =B34+I34-N34 -> 0 | N34: 0
A35: NTEPDIE TUEMAC MZ | B35: 0 | E35: =[5]TONT20000DEC2016!$E36+[5]TONT20000JANV2017!$C36+[5]TONT20000FEV2017!$C36+[5]TONT20000MARS2017!$C36+[5]TONT20000AVRIL2017!$C36+[5]TONT20000MAI2017!$C36+[5]TONT20000JUIN2017!$C36+[5]TONT20000JUIL2017!$C36 -> 0 | F35: =+C35+D35+E35 -> 0 | I35: =F35-G35-H35 -> 0 | K35: =B35+I35-N35 -> 0 | M35: =[5]TONT20000DEC2016!R36+[5]TONT20000JANV2017!P36+[5]TONT20000FEV2017!P36+[5]TONT20000MARS2017!P36+[5]TONT20000AVRIL2017!P36+[5]TONT20000MAI2017!P36+[5]TONT20000JUIN2017!P36+[5]TONT20000JUIL2017!P36 -> 0 | N35: 0
A36: NTOMBOU ADOLPHE | B36: 0 | C36: =[5]TONT20000DEC2016!$D37 -> 0 | F36: =+C36+D36+E36 -> 0 | I36: =F36-G36-H36 -> 0 | K36: =B36+I36-N36 -> 0 | N36: 0
A37: PATEGO NJOSSU GUSTAVE | B37: 420000 | C37: =[5]TONT20000DEC2016!$D38 -> 2474 | D37: =+[5]TONT20000DEC2016!$L38+[5]TONT20000JANV2017!$J38+[5]TONT20000FEV2017!$J38+[5]TONT20000MARS2017!$J38+[5]TONT20000AVRIL2017!$J38+[5]TONT20000MAI2017!$J38+[5]TONT20000JUIN2017!$J38+[5]TONT20000JUIL2017!$J38 -> 24000 | E37: =[5]TONT20000DEC2016!$E38+[5]TONT20000JANV2017!$C38+[5]TONT20000FEV2017!$C38+[5]TONT20000MARS2017!$C38+[5]TONT20000AVRIL2017!$C38+[5]TONT20000MAI2017!$C38+[5]TONT20000JUIN2017!$C38+[5]TONT20000JUIL2017!$C38 -> 28890.658 | F37: =+C37+D37+E37 -> 55364.658 | G37: 8200 | I37: =F37-G37-H37 -> 47164.658 | J37: =[11]MVTSEPT!$C35 -> 450000 | K37: =B37+I37-N37 -> 467164.66 | M37: =[5]TONT20000DEC2016!R38+[5]TONT20000JANV2017!P38+[5]TONT20000FEV2017!P38+[5]TONT20000MARS2017!P38+[5]TONT20000AVRIL2017!P38+[5]TONT20000MAI2017!P38+[5]TONT20000JUIN2017!P38+[5]TONT20000JUIL2017!P38 -> 0 | N37: =[8]EMPRUNT!$D35 -> 0
A38: SEUNOU RICHELOT | B38: 420000 | C38: =[5]TONT20000DEC2016!$D39 -> 6756 | D38: =+[5]TONT20000DEC2016!$L39+[5]TONT20000JANV2017!$J39+[5]TONT20000FEV2017!$J39+[5]TONT20000MARS2017!$J39+[5]TONT20000AVRIL2017!$J39+[5]TONT20000MAI2017!$J39+[5]TONT20000JUIN2017!$J39+[5]TONT20000JUIL2017!$J39 -> 24000 | E38: =[5]TONT20000DEC2016!$E39+[5]TONT20000JANV2017!$C39+[5]TONT20000FEV2017!$C39+[5]TONT20000MARS2017!$C39+[5]TONT20000AVRIL2017!$C39+[5]TONT20000MAI2017!$C39+[5]TONT20000JUIN2017!$C39+[5]TONT20000JUIL2017!$C39 -> 29172.869 | F38: =+C38+D38+E38 -> 59928.869 | G38: 20500 | I38: =F38-G38-H38 -> 39428.869 | J38: =[11]MVTSEPT!$C36 -> 450000 | K38: =B38+I38-N38 -> -660571.13 | M38: =[5]TONT20000DEC2016!R39+[5]TONT20000JANV2017!P39+[5]TONT20000FEV2017!P39+[5]TONT20000MARS2017!P39+[5]TONT20000AVRIL2017!P39+[5]TONT20000MAI2017!P39+[5]TONT20000JUIN2017!P39+[5]TONT20000JUIL2017!P39 -> 0 | N38: =[8]EMPRUNT!$D36 -> 1120000
A39: SIME ABEL | B39: 390000 | C39: =[5]TONT20000DEC2016!$D40 -> 488 | D39: =+[5]TONT20000DEC2016!$L40+[5]TONT20000JANV2017!$J40+[5]TONT20000FEV2017!$J40+[5]TONT20000MARS2017!$J40+[5]TONT20000AVRIL2017!$J40+[5]TONT20000MAI2017!$J40+[5]TONT20000JUIN2017!$J40+[5]TONT20000JUIL2017!$J40 -> 21000 | E39: =[5]TONT20000DEC2016!$E40+[5]TONT20000JANV2017!$C40+[5]TONT20000FEV2017!$C40+[5]TONT20000MARS2017!$C40+[5]TONT20000AVRIL2017!$C40+[5]TONT20000MAI2017!$C40+[5]TONT20000JUIN2017!$C40+[5]TONT20000JUIL2017!$C40 -> 26648.781 | F39: =+C39+D39+E39 -> 48136.781 | G39: 5250 | I39: =F39-G39-H39 -> 42886.781 | J39: =[11]MVTSEPT!$C37+30000-106000 -> 344000 | K39: =B39+I39-N39 -> -351113.22 | M39: =[5]TONT20000DEC2016!R40+[5]TONT20000JANV2017!P40+[5]TONT20000FEV2017!P40+[5]TONT20000MARS2017!P40+[5]TONT20000AVRIL2017!P40+[5]TONT20000MAI2017!P40+[5]TONT20000JUIN2017!P40+[5]TONT20000JUIL2017!P40 -> 84000 | N39: =[8]EMPRUNT!$D37 -> 784000
A40: SIME FONGANG ERIC | B40: 420000 | C40: =[5]TONT20000DEC2016!$D41 -> 4914 | D40: =+[5]TONT20000DEC2016!$L41+[5]TONT20000JANV2017!$J41+[5]TONT20000FEV2017!$J41+[5]TONT20000MARS2017!$J41+[5]TONT20000AVRIL2017!$J41+[5]TONT20000MAI2017!$J41+[5]TONT20000JUIN2017!$J41+[5]TONT20000JUIL2017!$J41 -> 24000 | E40: =[5]TONT20000DEC2016!$E41+[5]TONT20000JANV2017!$C41+[5]TONT20000FEV2017!$C41+[5]TONT20000MARS2017!$C41+[5]TONT20000AVRIL2017!$C41+[5]TONT20000MAI2017!$C41+[5]TONT20000JUIN2017!$C41+[5]TONT20000JUIL2017!$C41 -> 29051.469 | F40: =+C40+D40+E40 -> 57965.469 | G40: 4000 | I40: =F40-G40-H40 -> 53965.469 | J40: =[11]MVTSEPT!$C38 -> 450000 | K40: =B40+I40-N40 -> -646034.53 | M40: =[5]TONT20000DEC2016!R41+[5]TONT20000JANV2017!P41+[5]TONT20000FEV2017!P41+[5]TONT20000MARS2017!P41+[5]TONT20000AVRIL2017!P41+[5]TONT20000MAI2017!P41+[5]TONT20000JUIN2017!P41+[5]TONT20000JUIL2017!P41 -> 120000 | N40: =[8]EMPRUNT!$D38 -> 1120000
A41: SIME MATHIEU | B41: 420000 | C41: =[5]TONT20000DEC2016!$D42 -> 4528 | D41: =+[5]TONT20000DEC2016!$L42+[5]TONT20000JANV2017!$J42+[5]TONT20000FEV2017!$J42+[5]TONT20000MARS2017!$J42+[5]TONT20000AVRIL2017!$J42+[5]TONT20000MAI2017!$J42+[5]TONT20000JUIN2017!$J42+[5]TONT20000JUIL2017!$J42 -> 24000 | E41: =[5]TONT20000DEC2016!$E42+[5]TONT20000JANV2017!$C42+[5]TONT20000FEV2017!$C42+[5]TONT20000MARS2017!$C42+[5]TONT20000AVRIL2017!$C42+[5]TONT20000MAI2017!$C42+[5]TONT20000JUIN2017!$C42+[5]TONT20000JUIL2017!$C42 -> 29026.03 | F41: =+C41+D41+E41 -> 57554.03 | G41: 8100 | I41: =F41-G41-H41 -> 49454.03 | J41: =[11]MVTSEPT!$C39 -> 450000 | K41: =B41+I41-N41 -> -493545.97 | M41: =[5]TONT20000DEC2016!R42+[5]TONT20000JANV2017!P42+[5]TONT20000FEV2017!P42+[5]TONT20000MARS2017!P42+[5]TONT20000AVRIL2017!P42+[5]TONT20000MAI2017!P42+[5]TONT20000JUIN2017!P42+[5]TONT20000JUIL2017!P42 -> 120000 | N41: =[8]EMPRUNT!$D39 -> 963000
...

Sheet INVENT2017_2018
B1: CALCUL INTERET EPARGNE AOUT 2017- JUILLET 2018
A3: NOM ET PRENOM | B3: FONDS CAISSE | C3: RELIQUAT | D3: EPARGNE | E3: INTERETEPARGNE | F3: TOTAL AVOIR | G3: SANCTION | H3: AVANCE | I3: COMPLEMENT MUTUELLE | J3: COMPLEMENT FONDS | K3: TOTAL A PERCEVOIR | L3: NOUVEAU FONDS | M3: SOLDE TOUT COMPTE | N3: AVANCE | O3: EMPRUNT 2018 | P3: INTERET EMPRUNT | Q3: REPORT EMPRUNT 2017 | R3: REMBOURSEMENT 2017-2018 | S3: EMPRUNT EN COURS 2018 | T3: PENALITE | U3: EMPRUNT EN COURS 2018 PENALITE | V3: DATE REMBOURSEMENT | X3: OBSERVATION | Z3: PENALITE | AA3: REMBOURSEMENT
A4: ASELBY | C4: =+INVENT2016_2017!I4 -> 0 | D4: =[11]MVTAOUT!$H5+[11]MVTSEPT!$I5+[11]MVTOCT!$G5+[11]MVTNOV!$G5+[11]MVTDEC!$G5+[11]MVTJANV!$G5+[11]MVTFEV!$G5+[11]MVTMARS!$G5+[11]MVTAVRIL!$G5+[11]MVTMAI!$G5+[11]MVTJUIN!$G5+[11]MVTJUIL!$G5+[11]MVTAOUT2018!$G5 -> 0 | E4: =+[11]MVTAOUT!$D5+[11]MVTSEPT!$E5+[11]MVTOCT!$C5+[11]MVTNOV!$C5+[11]MVTDEC!$C5+[11]MVTJANV!$C5+[11]MVTFEV!$C5+[11]MVTMARS!$C5+[11]MVTAVRIL!$C5+[11]MVTMAI!$C5+[11]MVTJUIN!$C5+[11]MVTJUIL!$C5 -> 15580.723 | F4: =+C4+D4+E4 -> 15580.723 | K4: =F4-G4-H4-I4-J4 -> 15580.723 | M4: =K4+L4 -> 15580.723 | O4: =[11]MVTAOUT!O5+[11]MVTSEPT!P5+[11]MVTOCT!N5+[11]MVTNOV!N5+[11]MVTDEC!N5+[11]MVTJANV!N5+[11]MVTFEV!N5+[11]MVTMARS!N5+[11]MVTAVRIL!N5+[11]MVTMAI!N5+[11]MVTJUIN!N5+[11]MVTJUIL!N5 -> 0 | P4: =[11]MVTAOUT!P5+[11]MVTSEPT!Q5+[11]MVTOCT!O5+[11]MVTNOV!O5+[11]MVTDEC!O5+[11]MVTJANV!O5+[11]MVTFEV!O5+[11]MVTMARS!O5+[11]MVTAVRIL!O5+[11]MVTMAI!O5+[11]MVTJUIN!O5+[11]MVTJUIL!O5 -> 0 | Q4: =+INVENT2016_2017!N4 -> 0 | R4: =[11]MVTAOUT!$Q5+[11]MVTSEPT!$R5+[11]MVTOCT!$P5+[11]MVTNOV!$P5+[11]MVTDEC!$P5+[11]MVTJANV!$P5+[11]MVTFEV!$P5+[11]MVTMARS!$P5+[11]MVTAVRIL!$P5+[11]MVTMAI!$P5+[11]MVTJUIN!$P5+[11]MVTJUIL!$P5+[11]MVTAOUT2018!$P$5 -> 0
A5: BAKOP ACHILLE | B5: =+INVENT2016_2017!J5 -> 450000 | C5: =+INVENT2016_2017!I5 -> 0 | D5: =[11]MVTAOUT!$H6+[11]MVTSEPT!$I6+[11]MVTOCT!$G6+[11]MVTNOV!$G6+[11]MVTDEC!$G6+[11]MVTJANV!$G6+[11]MVTFEV!$G6+[11]MVTMARS!$G6+[11]MVTAVRIL!$G6+[11]MVTMAI!$G6+[11]MVTJUIN!$G6+[11]MVTJUIL!$G6+[11]MVTAOUT2018!$G6 -> 68000 | E5: =+[11]MVTAOUT!$D6+[11]MVTSEPT!$E6+[11]MVTOCT!$C6+[11]MVTNOV!$C6+[11]MVTDEC!$C6+[11]MVTJANV!$C6+[11]MVTFEV!$C6+[11]MVTMARS!$C6+[11]MVTAVRIL!$C6+[11]MVTMAI!$C6+[11]MVTJUIN!$C6+[11]MVTJUIL!$C6 -> 19643.082 | F5: =+C5+D5+E5 -> 87643.082 | I5: 25000 | J5: 30000 | K5: =F5-G5-H5-I5-J5 -> 32643.082 | L5: =B5+J5 -> 480000 | M5: =K5+L5 -> 512643.08 | O5: =[11]MVTAOUT!O6+[11]MVTSEPT!P6+[11]MVTOCT!N6+[11]MVTNOV!N6+[11]MVTDEC!N6+[11]MVTJANV!N6+[11]MVTFEV!N6+[11]MVTMARS!N6+[11]MVTAVRIL!N6+[11]MVTMAI!N6+[11]MVTJUIN!N6+[11]MVTJUIL!N6 -> 0 | P5: =[11]MVTAOUT!P6+[11]MVTSEPT!Q6+[11]MVTOCT!O6+[11]MVTNOV!O6+[11]MVTDEC!O6+[11]MVTJANV!O6+[11]MVTFEV!O6+[11]MVTMARS!O6+[11]MVTAVRIL!O6+[11]MVTMAI!O6+[11]MVTJUIN!O6+[11]MVTJUIL!O6 -> 0 | Q5: =+INVENT2016_2017!N5 -> 588000 | R5: =[11]MVTAOUT!$Q6+[11]MVTSEPT!$R6+[11]MVTOCT!$P6+[11]MVTNOV!$P6+[11]MVTDEC!$P6+[11]MVTJANV!$P6+[11]MVTFEV!$P6+[11]MVTMARS!$P6+[11]MVTAVRIL!$P6+[11]MVTMAI!$P6+[11]MVTJUIN!$P6+[11]MVTJUIL!$P6+[11]MVTAOUT2018!$P$6 -> 0 | S5: 588000 | T5: 88000 | U5: =+S5 -> 588000 | V5: 42904 | Z5: 88000 | AA5: =S5 -> 588000
A6: BOUTCHOUANG WILLIAM | B6: =+INVENT2016_2017!J6 -> 450000 | C6: =+INVENT2016_2017!I6 -> 47526.871 | D6: =[11]MVTAOUT!$H7+[11]MVTSEPT!$I7+[11]MVTOCT!$G7+[11]MVTNOV!$G7+[11]MVTDEC!$G7+[11]MVTJANV!$G7+[11]MVTFEV!$G7+[11]MVTMARS!$G7+[11]MVTAVRIL!$G7+[11]MVTMAI!$G7+[11]MVTJUIN!$G7+[11]MVTJUIL!$G7+[11]MVTAOUT2018!$G7 -> 39000 | E6: =+[11]MVTAOUT!$D7+[11]MVTSEPT!$E7+[11]MVTOCT!$C7+[11]MVTNOV!$C7+[11]MVTDEC!$C7+[11]MVTJANV!$C7+[11]MVTFEV!$C7+[11]MVTMARS!$C7+[11]MVTAVRIL!$C7+[11]MVTMAI!$C7+[11]MVTJUIN!$C7+[11]MVTJUIL!$C7 -> 19804.409 | F6: =+C6+D6+E6 -> 106331.28 | I6: 25000 | J6: 30000 | K6: =F6-G6-H6-I6-J6 -> 51331.28 | L6: =B6+J6 -> 480000 | M6: =K6+L6 -> 531331.28 | O6: =[11]MVTAOUT!O7+[11]MVTSEPT!P7+[11]MVTOCT!N7+[11]MVTNOV!N7+[11]MVTDEC!N7+[11]MVTJANV!N7+[11]MVTFEV!N7+[11]MVTMARS!N7+[11]MVTAVRIL!N7+[11]MVTMAI!N7+[11]MVTJUIN!N7+[11]MVTJUIL!N7 -> 0 | P6: =[11]MVTAOUT!P7+[11]MVTSEPT!Q7+[11]MVTOCT!O7+[11]MVTNOV!O7+[11]MVTDEC!O7+[11]MVTJANV!O7+[11]MVTFEV!O7+[11]MVTMARS!O7+[11]MVTAVRIL!O7+[11]MVTMAI!O7+[11]MVTJUIN!O7+[11]MVTJUIL!O7 -> 0 | Q6: =+INVENT2016_2017!N6 -> 784000 | R6: =[11]MVTAOUT!$Q7+[11]MVTSEPT!$R7+[11]MVTOCT!$P7+[11]MVTNOV!$P7+[11]MVTDEC!$P7+[11]MVTJANV!$P7+[11]MVTFEV!$P7+[11]MVTMARS!$P7+[11]MVTAVRIL!$P7+[11]MVTMAI!$P7+[11]MVTJUIN!$P7+[11]MVTJUIL!$P7+[11]MVTAOUT2018!$P$7 -> 823200 | S6: 0 | X6: OK
A7: CHINGUE FABRICE | B7: =+INVENT2016_2017!J7 -> 450000 | C7: =+INVENT2016_2017!I7 -> 39888.74 | D7: =[11]MVTAOUT!$H8+[11]MVTSEPT!$I8+[11]MVTOCT!$G8+[11]MVTNOV!$G8+[11]MVTDEC!$G8+[11]MVTJANV!$G8+[11]MVTFEV!$G8+[11]MVTMARS!$G8+[11]MVTAVRIL!$G8+[11]MVTMAI!$G8+[11]MVTJUIN!$G8+[11]MVTJUIL!$G8+[11]MVTAOUT2018!$G8 -> 39000 | E7: =+[11]MVTAOUT!$D8+[11]MVTSEPT!$E8+[11]MVTOCT!$C8+[11]MVTNOV!$C8+[11]MVTDEC!$C8+[11]MVTJANV!$C8+[11]MVTFEV!$C8+[11]MVTMARS!$C8+[11]MVTAVRIL!$C8+[11]MVTMAI!$C8+[11]MVTJUIN!$C8+[11]MVTJUIL!$C8 -> 19815.212 | F7: =+C7+D7+E7 -> 98703.952 | I7: 25000 | J7: 30000 | K7: =F7-G7-H7-I7-J7 -> 43703.952 | L7: =B7+J7 -> 480000 | M7: =K7+L7 -> 523703.95 | O7: =[11]MVTAOUT!O8+[11]MVTSEPT!P8+[11]MVTOCT!N8+[11]MVTNOV!N8+[11]MVTDEC!N8+[11]MVTJANV!N8+[11]MVTFEV!N8+[11]MVTMARS!N8+[11]MVTAVRIL!N8+[11]MVTMAI!N8+[11]MVTJUIN!N8+[11]MVTJUIL!N8 -> 0 | P7: =[11]MVTAOUT!P8+[11]MVTSEPT!Q8+[11]MVTOCT!O8+[11]MVTNOV!O8+[11]MVTDEC!O8+[11]MVTJANV!O8+[11]MVTFEV!O8+[11]MVTMARS!O8+[11]MVTAVRIL!O8+[11]MVTMAI!O8+[11]MVTJUIN!O8+[11]MVTJUIL!O8 -> 0 | Q7: =+INVENT2016_2017!N7 -> 1293600 | R7: =[11]MVTAOUT!$Q8+[11]MVTSEPT!$R8+[11]MVTOCT!$P8+[11]MVTNOV!$P8+[11]MVTDEC!$P8+[11]MVTJANV!$P8+[11]MVTFEV!$P8+[11]MVTMARS!$P8+[11]MVTAVRIL!$P8+[11]MVTMAI!$P8+[11]MVTJUIN!$P8+[11]MVTJUIL!$P8+[11]MVTAOUT2018!$P$8 -> 1293500
A8: DJOMO JEAN PAUL | B8: =+INVENT2016_2017!J8 -> 450000 | C8: =+INVENT2016_2017!I8 -> 23224.098 | D8: =[11]MVTAOUT!$H9+[11]MVTSEPT!$I9+[11]MVTOCT!$G9+[11]MVTNOV!$G9+[11]MVTDEC!$G9+[11]MVTJANV!$G9+[11]MVTFEV!$G9+[11]MVTMARS!$G9+[11]MVTAVRIL!$G9+[11]MVTMAI!$G9+[11]MVTJUIN!$G9+[11]MVTJUIL!$G9+[11]MVTAOUT2018!$G9 -> 39000 | E8: =+[11]MVTAOUT!$D9+[11]MVTSEPT!$E9+[11]MVTOCT!$C9+[11]MVTNOV!$C9+[11]MVTDEC!$C9+[11]MVTJANV!$C9+[11]MVTFEV!$C9+[11]MVTMARS!$C9+[11]MVTAVRIL!$C9+[11]MVTMAI!$C9+[11]MVTJUIN!$C9+[11]MVTJUIL!$C9 -> 19830.392 | F8: =+C8+D8+E8 -> 82054.49 | I8: 25000 | J8: 30000 | K8: =F8-G8-H8-I8-J8 -> 27054.49 | L8: =B8+J8 -> 480000 | M8: =K8+L8 -> 507054.49 | O8: =[11]MVTAOUT!O9+[11]MVTSEPT!P9+[11]MVTOCT!N9+[11]MVTNOV!N9+[11]MVTDEC!N9+[11]MVTJANV!N9+[11]MVTFEV!N9+[11]MVTMARS!N9+[11]MVTAVRIL!N9+[11]MVTMAI!N9+[11]MVTJUIN!N9+[11]MVTJUIL!N9 -> 693000 | P8: =[11]MVTAOUT!P9+[11]MVTSEPT!Q9+[11]MVTOCT!O9+[11]MVTNOV!O9+[11]MVTDEC!O9+[11]MVTJANV!O9+[11]MVTFEV!O9+[11]MVTMARS!O9+[11]MVTAVRIL!O9+[11]MVTMAI!O9+[11]MVTJUIN!O9+[11]MVTJUIL!O9 -> 49000 | Q8: =+INVENT2016_2017!N8 -> 1017000 | R8: =[11]MVTAOUT!$Q9+[11]MVTSEPT!$R9+[11]MVTOCT!$P9+[11]MVTNOV!$P9+[11]MVTDEC!$P9+[11]MVTJANV!$P9+[11]MVTFEV!$P9+[11]MVTMARS!$P9+[11]MVTAVRIL!$P9+[11]MVTMAI!$P9+[11]MVTJUIN!$P9+[11]MVTJUIL!$P9+[11]MVTAOUT2018!$P$9 -> 1040000 | S8: 693000 | T8: =S8*5/100 -> 34650 | U8: =+S8+T8 -> 727650 | V8: 43121 | X8: OK | Z8: =+AA8-S8 -> 34650 | AA8: =S8+(S8*5/100) -> 727650
A9: DJOUKWE NANGUEN GUY BLAISE | B9: =+INVENT2016_2017!J9 -> 450000 | C9: =+INVENT2016_2017!I9 -> 69006.04 | D9: =[11]MVTAOUT!$H10+[11]MVTSEPT!$I10+[11]MVTOCT!$G10+[11]MVTNOV!$G10+[11]MVTDEC!$G10+[11]MVTJANV!$G10+[11]MVTFEV!$G10+[11]MVTMARS!$G10+[11]MVTAVRIL!$G10+[11]MVTMAI!$G10+[11]MVTJUIN!$G10+[11]MVTJUIL!$G10+[11]MVTAOUT2018!$G10 -> 51000 | E9: =+[11]MVTAOUT!$D10+[11]MVTSEPT!$E10+[11]MVTOCT!$C10+[11]MVTNOV!$C10+[11]MVTDEC!$C10+[11]MVTJANV!$C10+[11]MVTFEV!$C10+[11]MVTMARS!$C10+[11]MVTAVRIL!$C10+[11]MVTMAI!$C10+[11]MVTJUIN!$C10+[11]MVTJUIL!$C10 -> 20026.542 | F9: =+C9+D9+E9 -> 140032.58 | I9: 25000 | J9: 30000 | K9: =F9-G9-H9-I9-J9 -> 85032.582 | L9: =B9+J9 -> 480000 | M9: =K9+L9 -> 565032.58 | O9: =[11]MVTAOUT!O10+[11]MVTSEPT!P10+[11]MVTOCT!N10+[11]MVTNOV!N10+[11]MVTDEC!N10+[11]MVTJANV!N10+[11]MVTFEV!N10+[11]MVTMARS!N10+[11]MVTAVRIL!N10+[11]MVTMAI!N10+[11]MVTJUIN!N10+[11]MVTJUIL!N10 -> 0 | P9: =[11]MVTAOUT!P10+[11]MVTSEPT!Q10+[11]MVTOCT!O10+[11]MVTNOV!O10+[11]MVTDEC!O10+[11]MVTJANV!O10+[11]MVTFEV!O10+[11]MVTMARS!O10+[11]MVTAVRIL!O10+[11]MVTMAI!O10+[11]MVTJUIN!O10+[11]MVTJUIL!O10 -> 0 | Q9: =+INVENT2016_2017!N9 -> 140000 | R9: =[11]MVTAOUT!$Q10+[11]MVTSEPT!$R10+[11]MVTOCT!$P10+[11]MVTNOV!$P10+[11]MVTDEC!$P10+[11]MVTJANV!$P10+[11]MVTFEV!$P10+[11]MVTMARS!$P10+[11]MVTAVRIL!$P10+[11]MVTMAI!$P10+[11]MVTJUIN!$P10+[11]MVTJUIL!$P10+[11]MVTAOUT2018!$P$10 -> 210000
A11: DJOUNKEP SAMUEL | B11: =+INVENT2016_2017!J11 -> 450000 | C11: =+INVENT2016_2017!I11 -> 730153.83 | D11: =[11]MVTAOUT!$H11+[11]MVTSEPT!$I11+[11]MVTOCT!$G11+[11]MVTNOV!$G11+[11]MVTDEC!$G11+[11]MVTJANV!$G11+[11]MVTFEV!$G11+[11]MVTMARS!$G11+[11]MVTAVRIL!$G11+[11]MVTMAI!$G11+[11]MVTJUIN!$G11+[11]MVTJUIL!$G11+[11]MVTAOUT2018!$G11 -> 233000 | E11: =+[11]MVTAOUT!$D11+[11]MVTSEPT!$E11+[11]MVTOCT!$C11+[11]MVTNOV!$C11+[11]MVTDEC!$C11+[11]MVTJANV!$C11+[11]MVTFEV!$C11+[11]MVTMARS!$C11+[11]MVTAVRIL!$C11+[11]MVTMAI!$C11+[11]MVTJUIN!$C11+[11]MVTJUIL!$C11 -> 22119.98 | F11: =+C11+D11+E11 -> 985273.81 | K11: =F11-G11-H11-I11-J11 -> 985273.81 | L11: =B11+J11 -> 450000 | M11: =K11+L11 -> 1435273.8 | O11: =[11]MVTAOUT!O11+[11]MVTSEPT!P11+[11]MVTOCT!N11+[11]MVTNOV!N11+[11]MVTDEC!N11+[11]MVTJANV!N11+[11]MVTFEV!N11+[11]MVTMARS!N11+[11]MVTAVRIL!N11+[11]MVTMAI!N11+[11]MVTJUIN!N11+[11]MVTJUIL!N11 -> 0 | P11: =[11]MVTAOUT!P11+[11]MVTSEPT!Q11+[11]MVTOCT!O11+[11]MVTNOV!O11+[11]MVTDEC!O11+[11]MVTJANV!O11+[11]MVTFEV!O11+[11]MVTMARS!O11+[11]MVTAVRIL!O11+[11]MVTMAI!O11+[11]MVTJUIN!O11+[11]MVTJUIL!O11 -> 0 | Q11: =+INVENT2016_2017!N11 -> 1120000 | R11: =[11]MVTAOUT!$Q11+[11]MVTSEPT!$R11+[11]MVTOCT!$P11+[11]MVTNOV!$P11+[11]MVTDEC!$P11+[11]MVTJANV!$P11+[11]MVTFEV!$P11+[11]MVTMARS!$P11+[11]MVTAVRIL!$P11+[11]MVTMAI!$P11+[11]MVTJUIN!$P11+[11]MVTJUIL!$P11+[11]MVTAOUT2018!$P$11 -> 1100000 | S11: 0 | W11: =Q11-R11 -> 20000 | X11: OK
