Workbook

Sheet Sheet1

Sheet Sheet2

Sheet Sheet3

Sheet Sheet4

Sheet Sheet5

Sheet Sheet6

Sheet Sheet7

Sheet Sheet8

Sheet Sheet9

Sheet Sheet10

Sheet Sheet11

Sheet Sheet12

Sheet Sheet13

Sheet Sheet14

Sheet Sheet15

Sheet Sheet16

Sheet Sheet17

Sheet Sheet18

Sheet Sheet19

Sheet Sheet20

Sheet Sheet21

Sheet Sheet22

Sheet Sheet23

Sheet Sheet24

Sheet Sheet25

Sheet Sheet26

Sheet Sheet27

Sheet Sheet28

Sheet Sheet29
A1: ASSOCIATION | B1: ASELBY
A2: ANNEE | B2: 2023
A3: 1 | B3: 2 | C3: 3 | D3: 4 | E3: 5 | F3: 6 | G3: 7 | H3: 8 | I3: 9 | J3: 10 | K3: 11 | L3: 12 | M3: 13 | N3: 14 | O3: 15 | P3: 16 | Q3: 17 | R3: 18 | S3: 19 | T3: 20 | U3: 21 | V3: 22 | W3: 23 | X3: 24 | Y3: 25 | Z3: 26 | AA3: 27 | AB3: 28 | AC3: 29 | AD3: 30 | AE3: 31 | AF3: 32 | AG3: 33 | AH3: 34 | AI3: 35 | AJ3: 36 | AK3: 37 | AL3: 38 | AM3: 39 | AN3: 40 | AO3: 41 | AP3: 42 | AQ3: 43 | AR3: 44 | AS3: 45 | AT3: 46 | AU3: 47 | AV3: 48 | AW3: 49 | AX3: 50 | AY3: 51 | AZ3: 52 | BA3: 53 | BB3: 54 | BC3: 55 | BD3: 56 | BE3: 57 | BF3: 58 | BG3: 59 | BH3: 60 | BI3: 61 | BJ3: 62 | BK3: 63 | BL3: 64 | BM3: 65 | BN3: 66 | BO3: 67 | BP3: 68
B4: TABLEAU DE BORD SAISIE DES DONNEES
A5: MATRICULE | B5: NOM ET PRENOM | C5: BONUS MALUS | D5: HISTORIQUE BANQUE | E5: HITORIQUE ESPECES | F5: HITORIQUE TONTINE | G5: PENALITE VERSEMENT ESPECES | H5: MODE PAIEMENT TONTINE | I5: COMPLEMENT EPARGNE | J5: NBRE DE LOT | K5: TONTINE 40 000 | L5: NBRE DE LOT | M5: TONTINE 75 000 | N5: NBRE DE LOT | O5: TONTINE 100 000 | P5: REMBOURSEMENT PETIT LOT T40 | Q5: REMBOURSEMENT PETIT LOT T75 | R5: REMBOURSEMENT PETIT LOT T100 | S5: REMBOURSEMENT PRÊT FONDS | T5: MODE PAIEMENT REMBOURSEMENT PRÊT FONDS | U5: MONTANT ENGAGEMENT | V5: SANCTION | W5: INSCRIPTION | X5: EPARGNE ASSURANCE | Y5: RECONSTITUTION FONDS | Z5: PRÊT FONDS | AA5: MODE PAIEMENT PRÊT | AB5: NUM CHEQUE | AC5: ACHAT LOT PRINCIPAL T40 | AD5: ACHAT LOT PRINCIPAL T75 | AE5: ACHAT LOT PRINCIPAL T100 | AF5: MODE PAIEMENT LOT PRINCIPAL | AG5: NUM CHEQUE | AH5: PENALITE VERSEMENT ESPECES | AI5: VENTE PETIT LOT T40 | AJ5: VENTE PETIT LOT T75 | AK5: VENTE PETIT LOT T100 | AL5: INTERET PETIT LOT T40 | AM5: INTERET PETIT LOT T75 | AN5: INTERET PETIT LOT T100 | AO5: NUM CHEQUE | AP5: MODE PAIEMENT PETEIT LOT | AQ5: PENELAITE RETARD TONTINE | AR5: PENELAITE ECHEC TONTINE | AS5: RESTE | AT5: MUTUELLE | AU5: REMBOURSEMENT TRANSPORT | AV5: RETRAIT PARTIEL FONDS | AW5: MONTANT T40 | AX5: MONTANT T75 | AY5: MONTANT T100 | AZ5: MONTANT CHEQUE | BA5: MONTANT ESPECES | BB5: CONTRIBUTION FOYER | BC5: AUTRES SOTIES | BD5: MONTANT CHEQUE EFFECTIF | BE5: NUMERO CHEQUE | BF5: INTERET PRÊT | BG5: NBRE MOIS | BH5: DEPENSE FONDS DE ROULEMENT | BI5: DEPENSE FRAIS EXCEPTIONNEL | BJ5: DEPENSE FONDS MUTUEL | BK5: DEPENSE COLLATION RECEPTION | BL5: PENALITE PRET FONDS | BM5: DEPENSE PENALITE VERSEMENT BANQUE | BN5: LIBELLE | BO5: COMPTE | BP5: MONTANT
A6: AS201648 | B6: =VLOOKUP(A6,[17]LISTADHERENT!A$5:H$39,3,0) -> ASELBY | C6: =D6+E6+F6-U6-BB6 -> 0 | D6: =VLOOKUP(A6,[18]HISTOBQUEDEC23!$A$6:$G$44,3,0) -> 175000 | E6: =VLOOKUP(A6,[18]HISTOBQUEDEC23!$A$6:$G$39,4,0) -> 0 | F6: =VLOOKUP(A6,[18]HISTOBQUEDEC23!$A$6:$G$39,5,0) -> 0 | G6: =IF(H6="ESPECES",3000,0) -> 0 | H6: =IF($D6<>0,"BANQUE",IF($E6<>0,"ESPECES","ECHEC")) -> BANQUE | K6: =IF($D6<>0,J6*40000,IF($E6<>0,J6*40000,0)) -> 0 | L6: 1 | M6: =IF($D6<>0,L6*75000,IF($E6<>0,L6*75000,0)) -> 75000 | N6: 1 | O6: =IF($D6<>0,N6*100000,IF($E6<>0,N6*100000,0)) -> 100000 | Q6: =VLOOKUP($A6,[13]TONTDEC23!$A$6:$P$20,10,0) -> 0 | R6: =VLOOKUP($A6,[19]TONTDEC23!$A$6:$P$21,10,0) -> 0 | U6: =G6+S6++R6+P6+O6+M6+I6+K6+Q6+W6 -> 175000 | AD6: 7500 | AE6: 10000 | AQ6: =IF(H6="ECHEC",((K6+M6+O6)*20/100),0) -> 0 | AR6: =IF(H6="ECHEC",((K6+M6+O6)*20/100),0) -> 0 | AW6: =IF(AC6=0,AI6,(1*25000*12)+AI6-AC6) -> 0 | AX6: =IF(AD6=0,AJ6,(1*75000*12)+(AJ6)-AD6) -> 892500 | AY6: =IF(AE6=0,AK6,(1*100000*12)+(AK6)-AE6) -> 1190000 | AZ6: =SUM(AV6:AY6)-BF6+Z6-F6+BH6+BI6+BJ6+BK6+BL6+BM6 -> 2088500 | BD6: =IF(AZ6=0,(AZ6-BA6-BC6),(AZ6-BA6-BB6-BC6))+F6 -> 2088500 | BF6: =Z6*1/100*BG6 -> 0 | BG6: 12 | BH6: =BP16 -> 6000 | BI6: =BP28 -> 0 | BJ6: =BP33 -> 0 | BM6: =BP22 -> 0 | BN6: ACHAT FOURNITURE | BO6: FONDS DE ROULEMENT
A7: AS201601 | B7: =VLOOKUP(A7,[17]LISTADHERENT!A$5:H$39,3,0) -> BAKOP ACHILLE | C7: =D7+E7+F7-U7-BB7 -> 0 | D7: =VLOOKUP(A7,[18]HISTOBQUEDEC23!$A$6:$G$44,3,0) -> 0 | E7: =VLOOKUP(A7,[18]HISTOBQUEDEC23!$A$6:$G$39,4,0) -> 669000 | F7: =VLOOKUP(A7,[18]HISTOBQUEDEC23!$A$6:$G$39,5,0) -> 0 | G7: =IF(H7="ESPECES",3000,0)-3000 -> 0 | H7: =IF($D7<>0,"BANQUE",IF($E7<>0,"ESPECES","ECHEC")) -> ESPECES | J7: 1 | K7: =IF($D7<>0,J7*40000,IF($E7<>0,J7*40000,0)) -> 40000 | M7: =IF($D7<>0,L7*75000,IF($E7<>0,L7*75000,0)) -> 0 | O7: =IF($D7<>0,N7*100000,IF($E7<>0,N7*100000,0)) -> 0 | P7: =VLOOKUP($A7,[20]TONTDEC23!$A$6:$P$35,12,0) -> 29000 | S7: 600000 | T7: BANQUE | U7: =G7+S7++R7+P7+O7+M7+I7+K7+Q7+W7 -> 669000 | AQ7: =IF(H7="ECHEC",((K7+M7+O7)*20/100),0) -> 0 | AR7: =IF(H7="ECHEC",((K7+M7+O7)*20/100),0) -> 0 | AS7: =IF(H7="ECHEC",0,(K7+I7-25000)) -> 15000 | AW7: =IF(AC7=0,AI7,(1*25000*12)+AI7-AC7) -> 0 | AX7: =IF(AD7=0,AJ7,(1*75000*12)+(AJ7)-AD7) -> 0 | AY7: =IF(AE7=0,AK7,(1*100000*12)+(AK7)-AE7) -> 0 | AZ7: =SUM(AV7:AY7)-BF7+Z7-F7+BH7+BI7+BJ7+BK7+BL7+BM7 -> 0 | BD7: =IF(AZ7=0,(AZ7-BA7-BC7),(AZ7-BA7-BB7-BC7))+F7 -> 0 | BF7: =Z7*1/100*BG7 -> 0 | BG7: 12 | BH7: =BP17 -> 0 | BI7: =BP27 -> 0 | BJ7: =BP33 -> 0 | BM7: =BP23 -> 0 | BN7: COMMUNICATION | BO7: FONDS DE ROULEMENT
A8: AS201602 | B8: =VLOOKUP(A8,[17]LISTADHERENT!A$5:H$39,3,0) -> BOUTCHOUANG WILLIAM | C8: =D8+E8+F8-U8-BB8 -> 0 | D8: =VLOOKUP(A8,[18]HISTOBQUEDEC23!$A$6:$G$44,3,0) -> 115000 | E8: =VLOOKUP(A8,[18]HISTOBQUEDEC23!$A$6:$G$39,4,0) -> 0 | F8: =VLOOKUP(A8,[18]HISTOBQUEDEC23!$A$6:$G$39,5,0) -> 0 | G8: =IF(H8="ESPECES",3000,0) -> 0 | H8: =IF($D8<>0,"BANQUE",IF($E8<>0,"ESPECES","ECHEC")) -> BANQUE | J8: 1 | K8: =IF($D8<>0,J8*40000,IF($E8<>0,J8*40000,0)) -> 40000 | L8: 1 | M8: =IF($D8<>0,L8*75000,IF($E8<>0,L8*75000,0)) -> 75000 | O8: =IF($D8<>0,N8*100000,IF($E8<>0,N8*100000,0)) -> 0 | P8: =VLOOKUP($A8,[20]TONTDEC23!$A$6:$P$35,12,0) -> 0 | Q8: =VLOOKUP($A8,[20]TONTDEC23!$A$6:$P$35,12,0) -> 0 | U8: =G8+S8++R8+P8+O8+M8+I8+K8+Q8+W8 -> 115000 | V8: =19000 -> 19000 | Z8: 500000 | AQ8: =IF(H8="ECHEC",((K8+M8+O8)*20/100),0) -> 0 | AR8: =IF(H8="ECHEC",((K8+M8+O8)*20/100),0) -> 0 | AS8: =IF(H8="ECHEC",0,(K8+I8-25000)) -> 15000 | AW8: =IF(AC8=0,AI8,(1*25000*12)+AI8-AC8) -> 0 | AX8: =IF(AD8=0,AJ8,(1*75000*12)+(AJ8)-AD8) -> 0 | AY8: =IF(AE8=0,AK8,(1*100000*12)+(AK8)-AE8) -> 0 | AZ8: =SUM(AV8:AY8)-BF8+Z8-F8+BH8+BI8+BJ8+BK8+BL8+BM8 -> 485000 | BD8: =IF(AZ8=0,(AZ8-BA8-BC8),(AZ8-BA8-BB8-BC8))+F8 -> 485000 | BF8: =Z8*1/100*BG8 -> 15000 | BG8: 3 | BN8: COMMISSION | BO8: FONDS DE ROULEMENT
A9: AS201604 | B9: =VLOOKUP(A9,[17]LISTADHERENT!A$5:H$39,3,0) -> DJOMO JEAN PAUL | C9: =D9+E9+F9-U9-BB9 -> 221000 | D9: =VLOOKUP(A9,[18]HISTOBQUEDEC23!$A$6:$G$44,3,0) -> 386000 | E9: =VLOOKUP(A9,[18]HISTOBQUEDEC23!$A$6:$G$39,4,0) -> 1000000 | F9: =VLOOKUP(A9,[18]HISTOBQUEDEC23!$A$6:$G$39,5,0) -> 0 | G9: =IF(H9="ESPECES",3000,0) -> 0 | H9: =IF($D9<>0,"BANQUE",IF($E9<>0,"ESPECES","ECHEC")) -> BANQUE | I9: 25000 | J9: 1 | K9: =IF($D9<>0,J9*40000,IF($E9<>0,J9*40000,0)) -> 40000 | M9: =IF($D9<>0,L9*75000,IF($E9<>0,L9*75000,0)) -> 0 | N9: 1 | O9: =IF($D9<>0,N9*100000,IF($E9<>0,N9*100000,0)) -> 100000 | P9: =VLOOKUP($A9,[20]TONTDEC23!$A$6:$P$35,12,0) -> 0 | R9: =VLOOKUP($A9,[19]TONTDEC23!$A$6:$P$21,10,0) -> 0 | S9: 1000000 | T9: BANQUE | U9: =G9+S9++R9+P9+O9+M9+I9+K9+Q9+W9 -> 1165000 | V9: 9000 | Z9: 1000000 | AA9: BANQUE | AQ9: =IF(H9="ECHEC",((K9+M9+O9)*20/100),0) -> 0 | AR9: =IF(H9="ECHEC",((K9+M9+O9)*20/100),0) -> 0 | AS9: =IF(H9="ECHEC",0,(K9+I9-25000)) -> 40000 | AW9: =IF(AC9=0,AI9,(1*25000*12)+AI9-AC9) -> 0 | AX9: =IF(AD9=0,AJ9,(1*75000*12)+(AJ9)-AD9) -> 0 | AY9: =IF(AE9=0,AK9,(1*100000*12)+(AK9)-AE9) -> 0 | AZ9: =SUM(AV9:AY9)-BF9+Z9-F9+BH9+BI9+BJ9+BK9+BL9+BM9 -> 880000 | BD9: =IF(AZ9=0,(AZ9-BA9-BC9),(AZ9-BA9-BB9-BC9))+F9 -> 880000 | BF9: =Z9*1/100*BG9 -> 120000 | BG9: 12 | BN9: AIDE UEEB ET CONT FEMME | BO9: FONDS DE ROULEMENT
A10: AS201654 | B10: =VLOOKUP(A10,[17]LISTADHERENT!A$5:H$39,3,0) -> DJOMOU TCHAPDA | C10: =D10+E10+F10-U10-BB10 -> 0 | D10: =VLOOKUP(A10,[18]HISTOBQUEDEC23!$A$6:$G$44,3,0) -> 0 | E10: =VLOOKUP(A10,[18]HISTOBQUEDEC23!$A$6:$G$39,4,0) -> 40000 | F10: =VLOOKUP(A10,[18]HISTOBQUEDEC23!$A$6:$G$39,5,0) -> 0 | G10: =IF(H10="ESPECES",3000,0)-3000 -> 0 | H10: =IF($D10<>0,"BANQUE",IF($E10<>0,"ESPECES","ECHEC")) -> ESPECES | J10: 1 | K10: =IF($D10<>0,J10*40000,IF($E10<>0,J10*40000,0)) -> 40000 | M10: =IF($D10<>0,L10*75000,IF($E10<>0,L10*75000,0)) -> 0 | O10: =IF($D10<>0,N10*100000,IF($E10<>0,N10*100000,0)) -> 0 | P10: =VLOOKUP($A10,[20]TONTDEC23!$A$6:$P$35,12,0) -> 0 | U10: =G10+S10++R10+P10+O10+M10+I10+K10+Q10+W10 -> 40000 | V10: =12000+10000 -> 22000 | Z10: 1000000 | AA10: BANQUE | AQ10: =IF(H10="ECHEC",((K10+M10+O10)*20/100),0) -> 0 | AR10: =IF(H10="ECHEC",((K10+M10+O10)*20/100),0) -> 0 | AS10: =IF(H10="ECHEC",0,(K10+I10-25000)) -> 15000 | AW10: =IF(AC10=0,AI10,(1*25000*12)+AI10-AC10) -> 0 | AX10: =IF(AD10=0,AJ10,(1*75000*12)+(AJ10)-AD10) -> 0 | AY10: =IF(AE10=0,AK10,(1*100000*12)+(AK10)-AE10) -> 0 | AZ10: =SUM(AV10:AY10)-BF10+Z10-F10+BH10+BI10+BJ10+BK10+BL10+BM10 -> 880000 | BD10: =IF(AZ10=0,(AZ10-BA10-BC10),(AZ10-BA10-BB10-BC10))+F10+49000 -> 929000 | BF10: =Z10*1/100*BG10 -> 120000 | BG10: 12 | BN10: CREDIT TELEPHONE | BO10: FONDS DE ROULEMENT
A11: AS201605 | B11: =VLOOKUP(A11,[17]LISTADHERENT!A$5:H$39,3,0) -> DJOUKWE NANGUEN GUY BLAISE | C11: =D11+E11+F11-U11-BB11 -> 0 | D11: =VLOOKUP(A11,[18]HISTOBQUEDEC23!$A$6:$G$44,3,0) -> 115000 | E11: =VLOOKUP(A11,[18]HISTOBQUEDEC23!$A$6:$G$39,4,0)+77000 -> 1077000 | F11: =VLOOKUP(A11,[18]HISTOBQUEDEC23!$A$6:$G$39,5,0) -> 0 | G11: =IF(H11="ESPECES",3000,0) -> 0 | H11: =IF($D11<>0,"BANQUE",IF($E11<>0,"ESPECES","ECHEC")) -> BANQUE | J11: 1 | K11: =IF($D11<>0,J11*40000,IF($E11<>0,J11*40000,0)) -> 40000 | L11: 1 | M11: =IF($D11<>0,L11*75000,IF($E11<>0,L11*75000,0)) -> 75000 | O11: =IF($D11<>0,N11*100000,IF($E11<>0,N11*100000,0)) -> 0 | P11: =VLOOKUP($A11,[20]TONTDEC23!$A$6:$P$35,12,0) -> 0 | Q11: =VLOOKUP($A11,[13]TONTDEC23!$A$6:$P$20,10,0) -> 77000 | S11: 1000000 | T11: BANQUE | U11: =G11+S11++R11+P11+O11+M11+I11+K11+Q11+W11 -> 1192000 | Z11: 1000000 | AA11: BANQUE | AQ11: =IF(H11="ECHEC",((K11+M11+O11)*20/100),0) -> 0 | AR11: =IF(H11="ECHEC",((K11+M11+O11)*20/100),0) -> 0 | AS11: =IF(H11="ECHEC",0,(K11+I11-25000)) -> 15000 | AW11: =IF(AC11=0,AI11,(1*25000*12)+AI11-AC11) -> 0 | AX11: =IF(AD11=0,AJ11,(1*75000*12)+(AJ11)-AD11) -> 0 | AY11: =IF(AE11=0,AK11,(1*100000*12)+(AK11)-AE11) -> 0 | AZ11: =SUM(AV11:AY11)-BF11+Z11-F11+BH11+BI11+BJ11+BK11+BL11+BM11 -> 980000 | BD11: =IF(AZ11=0,(AZ11-BA11-BC11),(AZ11-BA11-BB11-BC11))+F11 -> 980000 | BF11: =Z11*1/100*BG11 -> 20000 | BG11: 2 | BN11: PRODUCTION RAPPORT | BO11: FONDS DE ROULEMENT
A12: AS201608 | B12: =VLOOKUP(A12,[17]LISTADHERENT!A$5:H$39,3,0) -> DJUOMBESSY ANTOINE | C12: =D12+E12+F12-U12-BB12 -> 0 | D12: =VLOOKUP(A12,[18]HISTOBQUEDEC23!$A$6:$G$44,3,0) -> 1040000 | E12: =VLOOKUP(A12,[18]HISTOBQUEDEC23!$A$6:$G$39,4,0)+206000 -> 257000 | F12: =VLOOKUP(A12,[18]HISTOBQUEDEC23!$A$6:$G$39,5,0) -> 0 | G12: =IF(H12="ESPECES",3000,0) -> 0 | H12: =IF($D12<>0,"BANQUE",IF($E12<>0,"ESPECES","ECHEC")) -> BANQUE | I12: =5000+800 -> 5800 | J12: 1 | K12: =IF($D12<>0,J12*40000,IF($E12<>0,J12*40000,0)) -> 40000 | L12: 1 | M12: =IF($D12<>0,L12*75000,IF($E12<>0,L12*75000,0)) -> 75000 | N12: 2 | O12: =IF($D12<>0,N12*100000,IF($E12<>0,N12*100000,0)) -> 200000 | P12: =VLOOKUP($A12,[20]TONTDEC23!$A$6:$P$35,12,0) -> 0 | Q12: =VLOOKUP($A12,[13]TONTDEC23!$A$6:$P$20,10,0) -> 51000 | R12: =VLOOKUP($A12,[19]TONTDEC23!$A$6:$P$21,10,0) -> 206000 | S12: 719200 | T12: BANQUE | U12: =G12+S12++R12+P12+O12+M12+I12+K12+Q12+W12 -> 1297000 | Z12: 1000000 | AA12: BANQUE | AQ12: =IF(H12="ECHEC",((K12+M12+O12)*20/100),0) -> 0 | AR12: =IF(H12="ECHEC",((K12+M12+O12)*20/100),0) -> 0 | AS12: =IF(H12="ECHEC",0,(K12+I12-25000)) -> 20800 | AW12: =IF(AC12=0,AI12,(1*25000*12)+AI12-AC12) -> 0 | AX12: =IF(AD12=0,AJ12,(1*75000*12)+(AJ12)-AD12) -> 0 | AY12: =IF(AE12=0,AK12,(1*100000*12)+(AK12)-AE12) -> 0 | AZ12: =SUM(AV12:AY12)-BF12+Z12-F12+BH12+BI12+BJ12+BK12+BL12+BM12 -> 940000 | BD12: =IF(AZ12=0,(AZ12-BA12-BC12),(AZ12-BA12-BB12-BC12))+F12+150000 -> 1090000 | BF12: =Z12*1/100*BG12 -> 60000 | BG12: 6 | BN12: ACHAT SOURIS ET PHOTOCOPIE | BO12: FONDS DE ROULEMENT
A13: AS201651 | B13: =VLOOKUP(A13,[17]LISTADHERENT!A$5:H$39,3,0) -> DOMOU FABIEN | C13: =D13+E13+F13-U13-BB13 -> 0 | D13: =VLOOKUP(A13,[18]HISTOBQUEDEC23!$A$6:$G$44,3,0) -> 1040000 | E13: =VLOOKUP(A13,[18]HISTOBQUEDEC23!$A$6:$G$39,4,0) -> 0 | F13: =VLOOKUP(A13,[18]HISTOBQUEDEC23!$A$6:$G$39,5,0) -> 0 | G13: =IF(H13="ESPECES",3000,0) -> 0 | H13: =IF($D13<>0,"BANQUE",IF($E13<>0,"ESPECES","ECHEC")) -> BANQUE | J13: 1 | K13: =IF($D13<>0,J13*40000,IF($E13<>0,J13*40000,0)) -> 40000 | M13: =IF($D13<>0,L13*75000,IF($E13<>0,L13*75000,0)) -> 0 | O13: =IF($D13<>0,N13*100000,IF($E13<>0,N13*100000,0)) -> 0 | P13: =VLOOKUP($A13,[20]TONTDEC23!$A$6:$P$35,12,0) -> 0 | S13: 1000000 | T13: BANQUE | U13: =G13+S13++R13+P13+O13+M13+I13+K13+Q13+W13 -> 1040000 | Z13: 1000000 | AA13: BANQUE | AQ13: =IF(H13="ECHEC",((K13+M13+O13)*20/100),0) -> 0 | AR13: =IF(H13="ECHEC",((K13+M13+O13)*20/100),0) -> 0 | AS13: =IF(H13="ECHEC",0,(K13+I13-25000)) -> 15000 | AW13: =IF(AC13=0,AI13,(1*25000*12)+AI13-AC13) -> 0 | AX13: =IF(AD13=0,AJ13,(1*75000*12)+(AJ13)-AD13) -> 0 | AY13: =IF(AE13=0,AK13,(1*100000*12)+(AK13)-AE13) -> 0 | AZ13: =SUM(AV13:AY13)-BF13+Z13-F13+BH13+BI13+BJ13+BK13+BL13+BM13 -> 880000 | BD13: =IF(AZ13=0,(AZ13-BA13-BC13),(AZ13-BA13-BB13-BC13))+F13+21000 -> 901000 | BF13: =Z13*1/100*BG13 -> 120000 | BG13: 12 | BN13: TAXI BANQUE | BO13: FONDS DE ROULEMENT | BP13: 6000
A14: AS201609 | B14: =VLOOKUP(A14,[17]LISTADHERENT!A$5:H$39,3,0) -> DONHOU DAVID | C14: =D14+E14+F14-U14-BB14 -> 0 | D14: =VLOOKUP(A14,[18]HISTOBQUEDEC23!$A$6:$G$44,3,0) -> 40000 | E14: =VLOOKUP(A14,[18]HISTOBQUEDEC23!$A$6:$G$39,4,0) -> 0 | F14: =VLOOKUP(A14,[18]HISTOBQUEDEC23!$A$6:$G$39,5,0) -> 0 | G14: =IF(H14="ESPECES",3000,0) -> 0 | H14: =IF($D14<>0,"BANQUE",IF($E14<>0,"ESPECES","ECHEC")) -> BANQUE | J14: 1 | K14: =IF($D14<>0,J14*40000,IF($E14<>0,J14*40000,0)) -> 40000 | M14: =IF($D14<>0,L14*75000,IF($E14<>0,L14*75000,0)) -> 0 | O14: =IF($D14<>0,N14*100000,IF($E14<>0,N14*100000,0)) -> 0 | P14: =VLOOKUP($A14,[20]TONTDEC23!$A$6:$P$35,12,0) -> 0 | U14: =G14+S14++R14+P14+O14+M14+I14+K14+Q14+W14 -> 40000 | AQ14: =IF(H14="ECHEC",((K14+M14+O14)*20/100),0) -> 0 | AR14: =IF(H14="ECHEC",((K14+M14+O14)*20/100),0) -> 0 | AS14: =IF(H14="ECHEC",0,(K14+I14-25000)) -> 15000 | AW14: =IF(AC14=0,AI14,(1*25000*12)+AI14-AC14) -> 0 | AX14: =IF(AD14=0,AJ14,(1*75000*12)+(AJ14)-AD14) -> 0 | AY14: =IF(AE14=0,AK14,(1*100000*12)+(AK14)-AE14) -> 0 | AZ14: =SUM(AV14:AY14)-BF14+Z14-F14+BH14+BI14+BJ14+BK14+BL14+BM14 -> 0 | BD14: =IF(AZ14=0,(AZ14-BA14-BC14),(AZ14-BA14-BB14-BC14))+F14 -> 0 | BF14: =Z14*1/100*BG14 -> 0 | BG14: 12 | BN14: CONFECTION CACHET | BO14: FONDS DE ROULEMENT
A15: AS201611 | B15: =VLOOKUP(A15,[17]LISTADHERENT!A$5:H$39,3,0) -> HENGUE PAUL OMER | C15: =D15+E15+F15-U15-BB15 -> 0 | D15: =VLOOKUP(A15,[18]HISTOBQUEDEC23!$A$6:$G$44,3,0) -> 115000 | E15: =VLOOKUP(A15,[18]HISTOBQUEDEC23!$A$6:$G$39,4,0) -> 0 | F15: =VLOOKUP(A15,[18]HISTOBQUEDEC23!$A$6:$G$39,5,0) -> 0 | G15: =IF(H15="ESPECES",3000,0) -> 0 | H15: =IF($D15<>0,"BANQUE",IF($E15<>0,"ESPECES","ECHEC")) -> BANQUE | J15: 1 | K15: =IF($D15<>0,J15*40000,IF($E15<>0,J15*40000,0)) -> 40000 | L15: 1 | M15: =IF($D15<>0,L15*75000,IF($E15<>0,L15*75000,0)) -> 75000 | O15: =IF($D15<>0,N15*100000,IF($E15<>0,N15*100000,0)) -> 0 | P15: =VLOOKUP($A15,[20]TONTDEC23!$A$6:$P$35,12,0) -> 0 | Q15: =VLOOKUP($A15,[13]TONTDEC23!$A$6:$P$20,10,0) -> 0 | U15: =G15+S15++R15+P15+O15+M15+I15+K15+Q15+W15 -> 115000 | V15: =9000+9000 -> 18000 | AQ15: =IF(H15="ECHEC",((K15+M15+O15)*20/100),0) -> 0 | AR15: =IF(H15="ECHEC",((K15+M15+O15)*20/100),0) -> 0 | AS15: =IF(H15="ECHEC",0,(K15+I15-25000)) -> 15000 | AW15: =IF(AC15=0,AI15,(1*25000*12)+AI15-AC15) -> 0 | AX15: =IF(AD15=0,AJ15,(1*75000*12)+(AJ15)-AD15) -> 0 | AY15: =IF(AE15=0,AK15,(1*100000*12)+(AK15)-AE15) -> 0 | AZ15: =SUM(AV15:AY15)-BF15+Z15-F15+BH15+BI15+BJ15+BK15+BL15+BM15 -> 0 | BD15: =IF(AZ15=0,(AZ15-BA15-BC15),(AZ15-BA15-BB15-BC15))+F15 -> 0 | BF15: =Z15*1/100*BG15 -> 0 | BG15: 12
A16: AS201613 | B16: =VLOOKUP(A16,[17]LISTADHERENT!A$5:H$39,3,0) -> HOTCHO BENJAMIN | C16: =D16+E16+F16-U16-BB16 -> 0 | D16: =VLOOKUP(A16,[18]HISTOBQUEDEC23!$A$6:$G$44,3,0) -> 250000 | E16: =VLOOKUP(A16,[18]HISTOBQUEDEC23!$A$6:$G$39,4,0)+206000+125000+238500 -> 569500 | F16: =VLOOKUP(A16,[18]HISTOBQUEDEC23!$A$6:$G$39,5,0) -> 0 | G16: =IF(H16="ESPECES",3000,0) -> 0 | H16: =IF($D16<>0,"BANQUE",IF($E16<>0,"ESPECES","ECHEC")) -> BANQUE | I16: 35000 | J16: 1 | K16: =IF($D16<>0,J16*40000,IF($E16<>0,J16*40000,0)) -> 40000 | L16: 1 | M16: =IF($D16<>0,L16*75000,IF($E16<>0,L16*75000,0)) -> 75000 | N16: 1 | O16: =IF($D16<>0,N16*100000,IF($E16<>0,N16*100000,0)) -> 100000 | P16: =VLOOKUP($A16,[20]TONTDEC23!$A$6:$P$35,12,0) -> 0 | Q16: =VLOOKUP($A16,[13]TONTDEC23!$A$6:$P$20,10,0) -> 0 | R16: =VLOOKUP($A16,[19]TONTDEC23!$A$6:$P$21,10,0) -> 206000 | S16: =125000+238500 -> 363500 | T16: BANQUE | U16: =G16+S16++R16+P16+O16+M16+I16+K16+Q16+W16 -> 819500 | V16: =9000+3000 -> 12000 | AQ16: =IF(H16="ECHEC",((K16+M16+O16)*20/100),0) -> 0 | AR16: =IF(H16="ECHEC",((K16+M16+O16)*20/100),0) -> 0 | AS16: =IF(H16="ECHEC",0,(K16+I16-25000)) -> 50000 | AW16: =IF(AC16=0,AI16,(1*25000*12)+AI16-AC16) -> 0 | AX16: =IF(AD16=0,AJ16,(1*75000*12)+(AJ16)-AD16) -> 0 | AY16: =IF(AE16=0,AK16,(1*100000*12)+(AK16)-AE16) -> 0 | AZ16: =SUM(AV16:AY16)-BF16+Z16-F16+BH16+BI16+BJ16+BK16+BL16+BM16 -> 0 | BD16: =IF(AZ16=0,(AZ16-BA16-BC16),(AZ16-BA16-BB16-BC16))+F16+400000 -> 400000 | BF16: =Z16*1/100*BG16 -> 0 | BG16: 12 | BN16: S/TOTAL | BP16: =SUM(BP6:BP15) -> 6000
A17: AS201617 | B17: =VLOOKUP(A17,[17]LISTADHERENT!A$5:H$39,3,0) -> KOUAMOU MOISE | C17: =D17+E17+F17-U17-BB17 -> 0 | D17: =VLOOKUP(A17,[18]HISTOBQUEDEC23!$A$6:$G$44,3,0) -> 1140000 | E17: =VLOOKUP(A17,[18]HISTOBQUEDEC23!$A$6:$G$39,4,0) -> 0 | F17: =VLOOKUP(A17,[18]HISTOBQUEDEC23!$A$6:$G$39,5,0) -> 0 | G17: =IF(H17="ESPECES",3000,0) -> 0 | H17: =IF($D17<>0,"BANQUE",IF($E17<>0,"ESPECES","ECHEC")) -> BANQUE | J17: 1 | K17: =IF($D17<>0,J17*40000,IF($E17<>0,J17*40000,0)) -> 40000 | M17: =IF($D17<>0,L17*75000,IF($E17<>0,L17*75000,0)) -> 0 | N17: 1 | O17: =IF($D17<>0,N17*100000,IF($E17<>0,N17*100000,0)) -> 100000 | P17: =VLOOKUP($A17,[20]TONTDEC23!$A$6:$P$35,12,0) -> 0 | R17: =VLOOKUP($A17,[19]TONTDEC23!$A$6:$P$21,10,0) -> 0 | S17: 1000000 | T17: BANQUE | U17: =G17+S17++R17+P17+O17+M17+I17+K17+Q17+W17 -> 1140000 | V17: 9000 | AQ17: =IF(H17="ECHEC",((K17+M17+O17)*20/100),0) -> 0 | AR17: =IF(H17="ECHEC",((K17+M17+O17)*20/100),0) -> 0 | AS17: =IF(H17="ECHEC",0,(K17+I17-25000)) -> 15000 | AW17: =IF(AC17=0,AI17,(1*25000*12)+AI17-AC17) -> 0 | AX17: =IF(AD17=0,AJ17,(1*75000*12)+(AJ17)-AD17) -> 0 | AY17: =IF(AE17=0,AK17,(1*100000*12)+(AK17)-AE17) -> 0 | AZ17: =SUM(AV17:AY17)-BF17+Z17-F17+BH17+BI17+BJ17+BK17+BL17+BM17 -> 0 | BD17: =IF(AZ17=0,(AZ17-BA17-BC17),(AZ17-BA17-BB17-BC17))+F17 -> 0 | BF17: =Z17*1/100*BG17 -> 0 | BG17: 12
A18: AS201619 | B18: =VLOOKUP(A18,[17]LISTADHERENT!A$5:H$39,3,0) -> KOUATCHO MESSACK | C18: =D18+E18+F18-U18-BB18 -> 0 | D18: =VLOOKUP(A18,[18]HISTOBQUEDEC23!$A$6:$G$44,3,0) -> 1000000 | E18: =VLOOKUP(A18,[18]HISTOBQUEDEC23!$A$6:$G$39,4,0) -> 447500 | F18: =VLOOKUP(A18,[18]HISTOBQUEDEC23!$A$6:$G$39,5,0) -> 0 | G18: =IF(H18="ESPECES",3000,0) -> 0 | H18: =IF($D18<>0,"BANQUE",IF($E18<>0,"ESPECES","ECHEC")) -> BANQUE | J18: 1 | K18: =IF($D18<>0,J18*40000,IF($E18<>0,J18*40000,0)) -> 40000 | L18: 1 | M18: =IF($D18<>0,L18*75000,IF($E18<>0,L18*75000,0)) -> 75000 | N18: 1 | O18: =IF($D18<>0,N18*100000,IF($E18<>0,N18*100000,0)) -> 100000 | P18: =VLOOKUP($A18,[20]TONTDEC23!$A$6:$P$35,12,0) -> 30500 | Q18: =VLOOKUP($A18,[13]TONTDEC23!$A$6:$P$20,10,0) -> 202000 | R18: =VLOOKUP($A18,[19]TONTDEC23!$A$6:$P$21,10,0) -> 0 | S18: 1000000 | T18: BANQUE | U18: =G18+S18++R18+P18+O18+M18+I18+K18+Q18+W18 -> 1447500 | V18: 3000 | Z18: 1000000 | AA18: BANQUE | AQ18: =IF(H18="ECHEC",((K18+M18+O18)*20/100),0) -> 0 | AR18: =IF(H18="ECHEC",((K18+M18+O18)*20/100),0) -> 0 | AS18: =IF(H18="ECHEC",0,(K18+I18-25000)) -> 15000 | AW18: =IF(AC18=0,AI18,(1*25000*12)+AI18-AC18) -> 0 | AX18: =IF(AD18=0,AJ18,(1*75000*12)+(AJ18)-AD18) -> 0 | AY18: =IF(AE18=0,AK18,(1*100000*12)+(AK18)-AE18) -> 0 | AZ18: =SUM(AV18:AY18)-BF18+Z18-F18+BH18+BI18+BJ18+BK18+BL18+BM18 -> 950000 | BD18: =IF(AZ18=0,(AZ18-BA18-BC18),(AZ18-BA18-BB18-BC18))+F18 -> 950000 | BF18: =Z18*1/100*BG18 -> 50000 | BG18: 5 | BN18: GRATIFICATION BUREAU 2021 | BO18: PENALITE VERSEMENT ESPECES
A19: AS201620 | B19: =VLOOKUP(A19,[17]LISTADHERENT!A$5:H$39,3,0) -> LOWE JEAN | C19: =D19+E19+F19-U19-BB19 -> 0 | D19: =VLOOKUP(A19,[18]HISTOBQUEDEC23!$A$6:$G$44,3,0) -> 40000 | E19: =VLOOKUP(A19,[18]HISTOBQUEDEC23!$A$6:$G$39,4,0) -> 0 | F19: =VLOOKUP(A19,[18]HISTOBQUEDEC23!$A$6:$G$39,5,0) -> 0 | G19: =IF(H19="ESPECES",3000,0) -> 0 | H19: =IF($D19<>0,"BANQUE",IF($E19<>0,"ESPECES","ECHEC")) -> BANQUE | J19: 1 | K19: =IF($D19<>0,J19*40000,IF($E19<>0,J19*40000,0)) -> 40000 | M19: =IF($D19<>0,L19*75000,IF($E19<>0,L19*75000,0)) -> 0 | O19: =IF($D19<>0,N19*100000,IF($E19<>0,N19*100000,0)) -> 0 | P19: =VLOOKUP($A19,[20]TONTDEC23!$A$6:$P$35,12,0) -> 0 | U19: =G19+S19++R19+P19+O19+M19+I19+K19+Q19+W19 -> 40000 | V19: =10000+10000 -> 20000 | AQ19: =IF(H19="ECHEC",((K19+M19+O19)*20/100),0) -> 0 | AR19: =IF(H19="ECHEC",((K19+M19+O19)*20/100),0) -> 0 | AS19: =IF(H19="ECHEC",0,(K19+I19-25000)) -> 15000 | AW19: =IF(AC19=0,AI19,(1*25000*12)+AI19-AC19) -> 0 | AX19: =IF(AD19=0,AJ19,(1*75000*12)+(AJ19)-AD19) -> 0 | AY19: =IF(AE19=0,AK19,(1*100000*12)+(AK19)-AE19) -> 0 | AZ19: =SUM(AV19:AY19)-BF19+Z19-F19+BH19+BI19+BJ19+BK19+BL19+BM19 -> 0 | BD19: =IF(AZ19=0,(AZ19-BA19-BC19),(AZ19-BA19-BB19-BC19))+F19 -> 0 | BF19: =Z19*1/100*BG19 -> 0 | BG19: 12 | BN19: ACHAT LAPTOP | BO19: PENALITE VERSEMENT ESPECES
A20: AS201649 | B20: =VLOOKUP(A20,[17]LISTADHERENT!A$5:H$39,3,0) -> MBOGNING TUGMA GUY | C20: =D20+E20+F20-U20-BB20 -> 0 | D20: =VLOOKUP(A20,[18]HISTOBQUEDEC23!$A$6:$G$44,3,0) -> 0 | E20: =VLOOKUP(A20,[18]HISTOBQUEDEC23!$A$6:$G$39,4,0)+300000 -> 1829000 | F20: =VLOOKUP(A20,[18]HISTOBQUEDEC23!$A$6:$G$39,5,0) -> 0 | G20: =IF(H20="ESPECES",3000,0)-3000 -> 0 | H20: =IF($D20<>0,"BANQUE",IF($E20<>0,"ESPECES","ECHEC")) -> ESPECES | J20: 1 | K20: =IF($D20<>0,J20*40000,IF($E20<>0,J20*40000,0)) -> 40000 | L20: 1 | M20: =IF($D20<>0,L20*75000,IF($E20<>0,L20*75000,0)) -> 75000 | N20: 1 | O20: =IF($D20<>0,N20*100000,IF($E20<>0,N20*100000,0)) -> 100000 | P20: =VLOOKUP($A20,[20]TONTDEC23!$A$6:$P$35,12,0) -> 0 | Q20: =VLOOKUP($A20,[13]TONTDEC23!$A$6:$P$20,10,0) -> 307000 | R20: =VLOOKUP($A20,[19]TONTDEC23!$A$6:$P$21,10,0) -> 307000 | S20: 1000000 | T20: BANQUE | U20: =G20+S20++R20+P20+O20+M20+I20+K20+Q20+W20 -> 1829000 | Z20: 1000000 | AA20: BANQUE | AQ20: =IF(H20="ECHEC",((K20+M20+O20)*20/100),0) -> 0 | AR20: =IF(H20="ECHEC",((K20+M20+O20)*20/100),0) -> 0 | AS20: =IF(H20="ECHEC",0,(K20+I20-25000)) -> 15000 | AW20: =IF(AC20=0,AI20,(1*25000*12)+AI20-AC20) -> 0 | AX20: =IF(AD20=0,AJ20,(1*75000*12)+(AJ20)-AD20) -> 0 | AY20: =IF(AE20=0,AK20,(1*100000*12)+(AK20)-AE20) -> 0 | AZ20: =SUM(AV20:AY20)-BF20+Z20-F20+BH20+BI20+BJ20+BK20+BL20+BM20 -> 940000 | BD20: =IF(AZ20=0,(AZ20-BA20-BC20),(AZ20-BA20-BB20-BC20))+F20 -> 940000 | BF20: =Z20*1/100*BG20 -> 60000 | BG20: 6
A21: AS201639 | B21: =VLOOKUP(A21,[17]LISTADHERENT!A$5:H$39,3,0) -> NANGUEN MARTIN | C21: =D21+E21+F21-U21-BB21 -> 0 | D21: =VLOOKUP(A21,[18]HISTOBQUEDEC23!$A$6:$G$44,3,0) -> 540000 | E21: =VLOOKUP(A21,[18]HISTOBQUEDEC23!$A$6:$G$39,4,0) -> 0 | F21: =VLOOKUP(A21,[18]HISTOBQUEDEC23!$A$6:$G$39,5,0) -> 0 | G21: =IF(H21="ESPECES",3000,0) -> 0 | H21: =IF($D21<>0,"BANQUE",IF($E21<>0,"ESPECES","ECHEC")) -> BANQUE | J21: 1 | K21: =IF($D21<>0,J21*40000,IF($E21<>0,J21*40000,0)) -> 40000 | M21: =IF($D21<>0,L21*75000,IF($E21<>0,L21*75000,0)) -> 0 | O21: =IF($D21<>0,N21*100000,IF($E21<>0,N21*100000,0)) -> 0 | P21: =VLOOKUP($A21,[20]TONTDEC23!$A$6:$P$35,12,0) -> 0 | S21: 500000 | T21: BANQUE | U21: =G21+S21++R21+P21+O21+M21+I21+K21+Q21+W21 -> 540000 | Z21: 300000 | AA21: BANQUE | AQ21: =IF(H21="ECHEC",((K21+M21+O21)*20/100),0) -> 0 | AR21: =IF(H21="ECHEC",((K21+M21+O21)*20/100),0) -> 0 | AS21: =IF(H21="ECHEC",0,(K21+I21-25000)) -> 15000 | AW21: =IF(AC21=0,AI21,(1*25000*12)+AI21-AC21) -> 0 | AX21: =IF(AD21=0,AJ21,(1*75000*12)+(AJ21)-AD21) -> 0 | AY21: =IF(AE21=0,AK21,(1*100000*12)+(AK21)-AE21) -> 0 | AZ21: =SUM(AV21:AY21)-BF21+Z21-F21+BH21+BI21+BJ21+BK21+BL21+BM21 -> 282000 | BD21: =IF(AZ21=0,(AZ21-BA21-BC21),(AZ21-BA21-BB21-BC21))+F21 -> 282000 | BF21: =Z21*1/100*BG21 -> 18000 | BG21: 6
A22: AS201621 | B22: =VLOOKUP(A22,[17]LISTADHERENT!A$5:H$39,3,0) -> NANKAM APPOLINAIRE | C22: =D22+E22+F22-U22-BB22 -> 0 | D22: =VLOOKUP(A22,[18]HISTOBQUEDEC23!$A$6:$G$44,3,0) -> 222500 | E22: =VLOOKUP(A22,[18]HISTOBQUEDEC23!$A$6:$G$39,4,0) -> 0 | F22: =VLOOKUP(A22,[18]HISTOBQUEDEC23!$A$6:$G$39,5,0) -> 0 | G22: =IF(H22="ESPECES",3000,0) -> 0 | H22: =IF($D22<>0,"BANQUE",IF($E22<>0,"ESPECES","ECHEC")) -> BANQUE | J22: 1 | K22: =IF($D22<>0,J22*40000,IF($E22<>0,J22*40000,0)) -> 40000 | L22: 1 | M22: =IF($D22<>0,L22*75000,IF($E22<>0,L22*75000,0)) -> 75000 | O22: =IF($D22<>0,N22*100000,IF($E22<>0,N22*100000,0)) -> 0 | P22: =VLOOKUP($A22,[20]TONTDEC23!$A$6:$P$35,12,0) -> 0 | Q22: =VLOOKUP($A22,[13]TONTDEC23!$A$6:$P$20,10,0) -> 0 | S22: 107500 | T22: BANQUE | U22: =G22+S22++R22+P22+O22+M22+I22+K22+Q22+W22 -> 222500 | V22: =5000+6000+9000 -> 20000 | Z22: 1000000 | AA22: BANQUE | AQ22: =IF(H22="ECHEC",((K22+M22+O22)*20/100),0) -> 0 | AR22: =IF(H22="ECHEC",((K22+M22+O22)*20/100),0) -> 0 | AS22: =IF(H22="ECHEC",0,(K22+I22-25000)) -> 15000 | AW22: =IF(AC22=0,AI22,(1*25000*12)+AI22-AC22) -> 0 | AX22: =IF(AD22=0,AJ22,(1*75000*12)+(AJ22)-AD22) -> 0 | AY22: =IF(AE22=0,AK22,(1*100000*12)+(AK22)-AE22) -> 0 | AZ22: =SUM(AV22:AY22)-BF22+Z22-F22+BH22+BI22+BJ22+BK22+BL22+BM22 -> 880000 | BD22: =IF(AZ22=0,(AZ22-BA22-BC22),(AZ22-BA22-BB22-BC22))+F22+53000 -> 933000 | BF22: =Z22*1/100*BG22 -> 120000 | BG22: 12 | BN22: S/TOTAL | BP22: =SUM(BP18:BP21) -> 0
A23: AS201622 | B23: =VLOOKUP(A23,[17]LISTADHERENT!A$5:H$39,3,0) -> NDJOMO ETIENNE | C23: =D23+E23+F23-U23-BB23 -> 0 | D23: =VLOOKUP(A23,[18]HISTOBQUEDEC23!$A$6:$G$44,3,0) -> 850000 | E23: =VLOOKUP(A23,[18]HISTOBQUEDEC23!$A$6:$G$39,4,0) -> 0 | F23: =VLOOKUP(A23,[18]HISTOBQUEDEC23!$A$6:$G$39,5,0) -> 0 | G23: =IF(H23="ESPECES",3000,0) -> 0 | H23: =IF($D23<>0,"BANQUE",IF($E23<>0,"ESPECES","ECHEC")) -> BANQUE | I23: 10000 | J23: 1 | K23: =IF($D23<>0,J23*40000,IF($E23<>0,J23*40000,0)) -> 40000 | M23: =IF($D23<>0,L23*75000,IF($E23<>0,L23*75000,0)) -> 0 | N23: 2 | O23: =IF($D23<>0,N23*100000,IF($E23<>0,N23*100000,0)) -> 200000 | P23: =VLOOKUP($A23,[20]TONTDEC23!$A$6:$P$35,12,0) -> 0 | R23: =VLOOKUP($A23,[19]TONTDEC23!$A$6:$P$21,10,0) -> 0 | S23: 600000 | T23: BANQUE | U23: =G23+S23++R23+P23+O23+M23+I23+K23+Q23+W23 -> 850000 | Z23: 500000 | AA23: BANQUE | AQ23: =IF(H23="ECHEC",((K23+M23+O23)*20/100),0) -> 0 | AR23: =IF(H23="ECHEC",((K23+M23+O23)*20/100),0) -> 0 | AS23: =IF(H23="ECHEC",0,(K23+I23-25000)) -> 25000 | AW23: =IF(AC23=0,AI23,(1*25000*12)+AI23-AC23) -> 0 | AX23: =IF(AD23=0,AJ23,(1*75000*12)+(AJ23)-AD23) -> 0 | AY23: =IF(AE23=0,AK23,(1*100000*12)+(AK23)-AE23) -> 0 | AZ23: =SUM(AV23:AY23)-BF23+Z23-F23+BH23+BI23+BJ23+BK23+BL23+BM23 -> 470000 | BD23: =IF(AZ23=0,(AZ23-BA23-BC23),(AZ23-BA23-BB23-BC23))+F23+220000 -> 690000 | BF23: =Z23*1/100*BG23 -> 30000 | BG23: 6
A24: AS201624 | B24: =VLOOKUP(A24,[17]LISTADHERENT!A$5:H$39,3,0) -> NGONDIEP CLAUDE | C24: =D24+E24+F24-U24-BB24 -> 0 | D24: =VLOOKUP(A24,[18]HISTOBQUEDEC23!$A$6:$G$44,3,0) -> 1215000 | E24: =VLOOKUP(A24,[18]HISTOBQUEDEC23!$A$6:$G$39,4,0) -> 202000 | F24: =VLOOKUP(A24,[18]HISTOBQUEDEC23!$A$6:$G$39,5,0) -> 0 | G24: =IF(H24="ESPECES",3000,0) -> 0 | H24: =IF($D24<>0,"BANQUE",IF($E24<>0,"ESPECES","ECHEC")) -> BANQUE | J24: 1 | K24: =IF($D24<>0,J24*40000,IF($E24<>0,J24*40000,0)) -> 40000 | L24: 1 | M24: =IF($D24<>0,L24*75000,IF($E24<>0,L24*75000,0)) -> 75000 | N24: 1 | O24: =IF($D24<>0,N24*100000,IF($E24<>0,N24*100000,0)) -> 100000 | P24: =VLOOKUP($A24,[20]TONTDEC23!$A$6:$P$35,12,0) -> 0 | Q24: =VLOOKUP($A24,[13]TONTDEC23!$A$6:$P$20,10,0) -> 0 | R24: =VLOOKUP($A24,[19]TONTDEC23!$A$6:$P$21,10,0) -> 202000 | S24: 1000000 | T24: BANQUE | U24: =G24+S24++R24+P24+O24+M24+I24+K24+Q24+W24 -> 1417000 | V24: =9000+6000 -> 15000 | Z24: 1000000 | AA24: BANQUE | AQ24: =IF(H24="ECHEC",((K24+M24+O24)*20/100),0) -> 0 | AR24: =IF(H24="ECHEC",((K24+M24+O24)*20/100),0) -> 0 | AS24: =IF(H24="ECHEC",0,(K24+I24-25000)) -> 15000 | AW24: =IF(AC24=0,AI24,(1*25000*12)+AI24-AC24) -> 0 | AX24: =IF(AD24=0,AJ24,(1*75000*12)+(AJ24)-AD24) -> 0 | AY24: =IF(AE24=0,AK24,(1*100000*12)+(AK24)-AE24) -> 0 | AZ24: =SUM(AV24:AY24)-BF24+Z24-F24+BH24+BI24+BJ24+BK24+BL24+BM24 -> 880000 | BD24: =IF(AZ24=0,(AZ24-BA24-BC24),(AZ24-BA24-BB24-BC24))+F24-202000 -> 678000 | BF24: =Z24*1/100*BG24 -> 120000 | BG24: 12 | BN24: GRATIFICATION BUREAU 2021 | BO24: FRAIS EXEPTIONNEL
A25: AS201626 | B25: =VLOOKUP(A25,[17]LISTADHERENT!A$5:H$39,3,0) -> NGUIEMEGNI MATHIEU BLAISE | C25: =D25+E25+F25-U25-BB25 -> 0 | D25: =VLOOKUP(A25,[18]HISTOBQUEDEC23!$A$6:$G$44,3,0) -> 600000 | E25: =VLOOKUP(A25,[18]HISTOBQUEDEC23!$A$6:$G$39,4,0) -> 1000000 | F25: =VLOOKUP(A25,[18]HISTOBQUEDEC23!$A$6:$G$39,5,0) -> 0 | G25: =IF(H25="ESPECES",3000,0) -> 0 | H25: =IF($D25<>0,"BANQUE",IF($E25<>0,"ESPECES","ECHEC")) -> BANQUE | I25: 108000 | J25: 1 | K25: =IF($D25<>0,J25*40000,IF($E25<>0,J25*40000,0)) -> 40000 | L25: 2 | M25: =IF($D25<>0,L25*75000,IF($E25<>0,L25*75000,0)) -> 150000 | N25: 1 | O25: =IF($D25<>0,N25*100000,IF($E25<>0,N25*100000,0)) -> 100000 | P25: =VLOOKUP($A25,[20]TONTDEC23!$A$6:$P$35,12,0) -> 0 | Q25: =VLOOKUP($A25,[13]TONTDEC23!$A$6:$P$20,10,0) -> 0 | R25: =VLOOKUP($A25,[19]TONTDEC23!$A$6:$P$21,10,0) -> 202000 | S25: 1000000 | T25: BANQUE | U25: =G25+S25++R25+P25+O25+M25+I25+K25+Q25+W25 -> 1600000 | V25: =9000+6000 -> 15000 | Z25: 1000000 | AA25: BANQUE | AQ25: =IF(H25="ECHEC",((K25+M25+O25)*20/100),0) -> 0 | AR25: =IF(H25="ECHEC",((K25+M25+O25)*20/100),0) -> 0 | AS25: =IF(H25="ECHEC",0,(K25+I25-25000)) -> 123000 | AW25: =IF(AC25=0,AI25,(1*25000*12)+AI25-AC25) -> 0 | AX25: =IF(AD25=0,AJ25,(1*75000*12)+(AJ25)-AD25) -> 0 | AY25: =IF(AE25=0,AK25,(1*100000*12)+(AK25)-AE25) -> 0 | AZ25: =SUM(AV25:AY25)-BF25+Z25-F25+BH25+BI25+BJ25+BK25+BL25+BM25 -> 880000 | BD25: =IF(AZ25=0,(AZ25-BA25-BC25),(AZ25-BA25-BB25-BC25))+F25+300000 -> 1180000 | BF25: =Z25*1/100*BG25 -> 120000 | BG25: 12 | BN25: DEVELOPPEMENT LAGWEU | BO25: FRAIS EXEPTIONNEL
A26: AS201628 | B26: =VLOOKUP(A26,[17]LISTADHERENT!A$5:H$39,3,0) -> NKAMGANG JUSTIN DEJOLIE | C26: =D26+E26+F26-U26-BB26 -> 0 | D26: =VLOOKUP(A26,[18]HISTOBQUEDEC23!$A$6:$G$44,3,0) -> 0 | E26: =VLOOKUP(A26,[18]HISTOBQUEDEC23!$A$6:$G$39,4,0) -> 1040000 | F26: =VLOOKUP(A26,[18]HISTOBQUEDEC23!$A$6:$G$39,5,0) -> 0 | G26: =IF(H26="ESPECES",3000,0)-3000 -> 0 | H26: =IF($D26<>0,"BANQUE",IF($E26<>0,"ESPECES","ECHEC")) -> ESPECES | J26: 1 | K26: =IF($D26<>0,J26*40000,IF($E26<>0,J26*40000,0)) -> 40000 | M26: =IF($D26<>0,L26*75000,IF($E26<>0,L26*75000,0)) -> 0 | O26: =IF($D26<>0,N26*100000,IF($E26<>0,N26*100000,0)) -> 0 | P26: =VLOOKUP($A26,[20]TONTDEC23!$A$6:$P$35,12,0) -> 0 | S26: 1000000 | T26: BANQUE | U26: =G26+S26++R26+P26+O26+M26+I26+K26+Q26+W26 -> 1040000 | Z26: 1000000 | AA26: BANQUE | AQ26: =IF(H26="ECHEC",((K26+M26+O26)*20/100),0) -> 0 | AR26: =IF(H26="ECHEC",((K26+M26+O26)*20/100),0) -> 0 | AS26: =IF(H26="ECHEC",0,(K26+I26-25000)) -> 15000 | AW26: =IF(AC26=0,AI26,(1*25000*12)+AI26-AC26) -> 0 | AX26: =IF(AD26=0,AJ26,(1*75000*12)+(AJ26)-AD26) -> 0 | AY26: =IF(AE26=0,AK26,(1*100000*12)+(AK26)-AE26) -> 0 | AZ26: =SUM(AV26:AY26)-BF26+Z26-F26+BH26+BI26+BJ26+BK26+BL26+BM26 -> 970000 | BD26: =IF(AZ26=0,(AZ26-BA26-BC26),(AZ26-BA26-BB26-BC26))+F26 -> 970000 | BF26: =Z26*1/100*BG26 -> 30000 | BG26: 3 | BN26: DEUIL TCHEMNOU EMMANUEL | BO26: FRAIS EXEPTIONNEL
A27: AS201656 | B27: =VLOOKUP(A27,[17]LISTADHERENT!A$5:H$39,3,0) -> NOUBE ETIENNE | C27: =D27+E27+F27-U27-BB27 -> 0 | D27: =VLOOKUP(A27,[18]HISTOBQUEDEC23!$A$6:$G$44,3,0) -> 50000 | E27: =VLOOKUP(A27,[18]HISTOBQUEDEC23!$A$6:$G$39,4,0) -> 0 | F27: =VLOOKUP(A27,[18]HISTOBQUEDEC23!$A$6:$G$39,5,0) -> 0 | G27: =IF(H27="ESPECES",3000,0) -> 0 | H27: =IF($D27<>0,"BANQUE",IF($E27<>0,"ESPECES","ECHEC")) -> BANQUE | I27: 10000 | J27: 1 | K27: =IF($D27<>0,J27*40000,IF($E27<>0,J27*40000,0)) -> 40000 | M27: =IF($D27<>0,L27*75000,IF($E27<>0,L27*75000,0)) -> 0 | O27: =IF($D27<>0,N27*100000,IF($E27<>0,N27*100000,0)) -> 0 | P27: =VLOOKUP($A27,[20]TONTDEC23!$A$6:$P$35,12,0) -> 0 | U27: =G27+S27++R27+P27+O27+M27+I27+K27+Q27+W27 -> 50000 | AQ27: =IF(H27="ECHEC",((K27+M27+O27)*20/100),0) -> 0 | AR27: =IF(H27="ECHEC",((K27+M27+O27)*20/100),0) -> 0 | AS27: =IF(H27="ECHEC",0,(K27+I27-25000)) -> 25000 | AW27: =IF(AC27=0,AI27,(1*25000*12)+AI27-AC27) -> 0 | AX27: =IF(AD27=0,AJ27,(1*75000*12)+(AJ27)-AD27) -> 0 | AY27: =IF(AE27=0,AK27,(1*100000*12)+(AK27)-AE27) -> 0 | AZ27: =SUM(AV27:AY27)-BF27+Z27-F27+BH27+BI27+BJ27+BK27+BL27+BM27 -> 0 | BD27: =IF(AZ27=0,(AZ27-BA27-BC27),(AZ27-BA27-BB27-BC27))+F27 -> 0 | BF27: =Z27*1/100*BG27 -> 0 | BG27: 12
A28: AS201633 | B28: =VLOOKUP(A28,[17]LISTADHERENT!A$5:H$39,3,0) -> PATEGO NJOSSU GUSTAVE | C28: =D28+E28+F28-U28-BB28 -> 0 | D28: =VLOOKUP(A28,[18]HISTOBQUEDEC23!$A$6:$G$44,3,0) -> 115000 | E28: =VLOOKUP(A28,[18]HISTOBQUEDEC23!$A$6:$G$39,4,0) -> 0 | F28: =VLOOKUP(A28,[18]HISTOBQUEDEC23!$A$6:$G$39,5,0) -> 0 | G28: =IF(H28="ESPECES",3000,0) -> 0 | H28: =IF($D28<>0,"BANQUE",IF($E28<>0,"ESPECES","ECHEC")) -> BANQUE | J28: 1 | K28: =IF($D28<>0,J28*40000,IF($E28<>0,J28*40000,0)) -> 40000 | L28: 1 | M28: =IF($D28<>0,L28*75000,IF($E28<>0,L28*75000,0)) -> 75000 | O28: =IF($D28<>0,N28*100000,IF($E28<>0,N28*100000,0)) -> 0 | P28: =VLOOKUP($A28,[20]TONTDEC23!$A$6:$P$35,12,0) -> 0 | Q28: =VLOOKUP($A28,[13]TONTDEC23!$A$6:$P$20,10,0) -> 0 | U28: =G28+S28++R28+P28+O28+M28+I28+K28+Q28+W28 -> 115000 | AQ28: =IF(H28="ECHEC",((K28+M28+O28)*20/100),0) -> 0 | AR28: =IF(H28="ECHEC",((K28+M28+O28)*20/100),0) -> 0 | AS28: =IF(H28="ECHEC",0,(K28+I28-25000)) -> 15000 | AW28: =IF(AC28=0,AI28,(1*25000*12)+AI28-AC28) -> 0 | AX28: =IF(AD28=0,AJ28,(1*75000*12)+(AJ28)-AD28) -> 0 | AY28: =IF(AE28=0,AK28,(1*100000*12)+(AK28)-AE28) -> 0 | AZ28: =SUM(AV28:AY28)-BF28+Z28-F28+BH28+BI28+BJ28+BK28+BL28+BM28 -> 0 | BD28: =IF(AZ28=0,(AZ28-BA28-BC28),(AZ28-BA28-BB28-BC28))+F28 -> 0 | BF28: =Z28*1/100*BG28 -> 0 | BG28: 12 | BN28: S/TOTAL | BP28: =SUM(BP24:BP26) -> 0
A29: AS201657 | B29: =VLOOKUP(A29,[17]LISTADHERENT!A$5:H$39,3,0) -> SEUMO POLYCARPE | C29: =D29+E29+F29-U29-BB29 -> 0 | D29: =VLOOKUP(A29,[18]HISTOBQUEDEC23!$A$6:$G$44,3,0) -> 40000 | E29: =VLOOKUP(A29,[18]HISTOBQUEDEC23!$A$6:$G$39,4,0) -> 0 | F29: =VLOOKUP(A29,[18]HISTOBQUEDEC23!$A$6:$G$39,5,0) -> 0 | G29: =IF(H29="ESPECES",3000,0) -> 0 | H29: =IF($D29<>0,"BANQUE",IF($E29<>0,"ESPECES","ECHEC")) -> BANQUE | J29: 1 | K29: =IF($D29<>0,J29*40000,IF($E29<>0,J29*40000,0)) -> 40000 | M29: =IF($D29<>0,L29*75000,IF($E29<>0,L29*75000,0)) -> 0 | O29: =IF($D29<>0,N29*100000,IF($E29<>0,N29*100000,0)) -> 0 | P29: =VLOOKUP($A29,[20]TONTDEC23!$A$6:$P$35,12,0) -> 0 | U29: =G29+S29++R29+P29+O29+M29+I29+K29+Q29+W29 -> 40000 | AQ29: =IF(H29="ECHEC",((K29+M29+O29)*20/100),0) -> 0 | AR29: =IF(H29="ECHEC",((K29+M29+O29)*20/100),0) -> 0 | AS29: =IF(H29="ECHEC",0,(K29+I29-25000)) -> 15000 | AW29: =IF(AC29=0,AI29,(1*25000*12)+AI29-AC29) -> 0 | AX29: =IF(AD29=0,AJ29,(1*75000*12)+(AJ29)-AD29) -> 0 | AY29: =IF(AE29=0,AK29,(1*100000*12)+(AK29)-AE29) -> 0 | AZ29: =SUM(AV29:AY29)-BF29+Z29-F29+BH29+BI29+BJ29+BK29+BL29+BM29 -> 0 | BD29: =IF(AZ29=0,(AZ29-BA29-BC29),(AZ29-BA29-BB29-BC29))+F29 -> 0 | BF29: =Z29*1/100*BG29 -> 0 | BG29: 12
A30: AS201653 | B30: =VLOOKUP(A30,[17]LISTADHERENT!A$5:H$39,3,0) -> SIME BRICE | C30: =D30+E30+F30-U30-BB30 -> 0 | D30: =VLOOKUP(A30,[18]HISTOBQUEDEC23!$A$6:$G$44,3,0) -> 115000 | E30: =VLOOKUP(A30,[18]HISTOBQUEDEC23!$A$6:$G$39,4,0) -> 0 | F30: =VLOOKUP(A30,[18]HISTOBQUEDEC23!$A$6:$G$39,5,0) -> 0 | G30: =IF(H30="ESPECES",3000,0) -> 0 | H30: =IF($D30<>0,"BANQUE",IF($E30<>0,"ESPECES","ECHEC")) -> BANQUE | J30: 1 | K30: =IF($D30<>0,J30*40000,IF($E30<>0,J30*40000,0)) -> 40000 | L30: 1 | M30: =IF($D30<>0,L30*75000,IF($E30<>0,L30*75000,0)) -> 75000 | O30: =IF($D30<>0,N30*100000,IF($E30<>0,N30*100000,0)) -> 0 | P30: =VLOOKUP($A30,[20]TONTDEC23!$A$6:$P$35,12,0) -> 0 | Q30: =VLOOKUP($A30,[13]TONTDEC23!$A$6:$P$20,10,0) -> 0 | U30: =G30+S30++R30+P30+O30+M30+I30+K30+Q30+W30 -> 115000 | V30: =10000+12000+12000 -> 34000 | Z30: 1000000 | AA30: BANQUE | AQ30: =IF(H30="ECHEC",((K30+M30+O30)*20/100),0) -> 0 | AR30: =IF(H30="ECHEC",((K30+M30+O30)*20/100),0) -> 0 | AS30: =IF(H30="ECHEC",0,(K30+I30-25000)) -> 15000 | AW30: =IF(AC30=0,AI30,(1*25000*12)+AI30-AC30) -> 0 | AX30: =IF(AD30=0,AJ30,(1*75000*12)+(AJ30)-AD30) -> 0 | AY30: =IF(AE30=0,AK30,(1*100000*12)+(AK30)-AE30) -> 0 | AZ30: =SUM(AV30:AY30)-BF30+Z30-F30+BH30+BI30+BJ30+BK30+BL30+BM30 -> 940000 | BD30: =IF(AZ30=0,(AZ30-BA30-BC30),(AZ30-BA30-BB30-BC30))+F30-772000 -> 168000 | BF30: =Z30*1/100*BG30 -> 60000 | BG30: 6 | BN30: DECES | BO30: MUTUELLE
A31: AS201638 | B31: =VLOOKUP(A31,[17]LISTADHERENT!A$5:H$39,3,0) -> SIMO PIERRE | C31: =D31+E31+F31-U31-BB31 -> 0 | D31: =VLOOKUP(A31,[18]HISTOBQUEDEC23!$A$6:$G$44,3,0) -> 1171000 | E31: =VLOOKUP(A31,[18]HISTOBQUEDEC23!$A$6:$G$39,4,0) -> 0 | F31: =VLOOKUP(A31,[18]HISTOBQUEDEC23!$A$6:$G$39,5,0) -> 0 | G31: =IF(H31="ESPECES",3000,0) -> 0 | H31: =IF($D31<>0,"BANQUE",IF($E31<>0,"ESPECES","ECHEC")) -> BANQUE | J31: 1 | K31: =IF($D31<>0,J31*40000,IF($E31<>0,J31*40000,0)) -> 40000 | M31: =IF($D31<>0,L31*75000,IF($E31<>0,L31*75000,0)) -> 0 | N31: 1 | O31: =IF($D31<>0,N31*100000,IF($E31<>0,N31*100000,0)) -> 100000 | P31: =VLOOKUP($A31,[20]TONTDEC23!$A$6:$P$35,12,0) -> 0 | R31: =VLOOKUP($A31,[19]TONTDEC23!$A$6:$P$21,10,0) -> 31000 | S31: 1000000 | T31: BANQUE | U31: =G31+S31++R31+P31+O31+M31+I31+K31+Q31+W31 -> 1171000 | Z31: 250000 | AA31: BANQUE | AQ31: =IF(H31="ECHEC",((K31+M31+O31)*20/100),0) -> 0 | AR31: =IF(H31="ECHEC",((K31+M31+O31)*20/100),0) -> 0 | AS31: =IF(H31="ECHEC",0,(K31+I31-25000)) -> 15000 | AW31: =IF(AC31=0,AI31,(1*25000*12)+AI31-AC31) -> 0 | AX31: =IF(AD31=0,AJ31,(1*75000*12)+(AJ31)-AD31) -> 0 | AY31: =IF(AE31=0,AK31,(1*100000*12)+(AK31)-AE31) -> 0 | AZ31: =SUM(AV31:AY31)-BF31+Z31-F31+BH31+BI31+BJ31+BK31+BL31+BM31 -> 235000 | BD31: =IF(AZ31=0,(AZ31-BA31-BC31),(AZ31-BA31-BB31-BC31))+F31+230000 -> 465000 | BF31: =Z31*1/100*BG31 -> 15000 | BG31: 6 | BN31: TRANSPORT DELEGUE | BO31: MUTUELLE
A32: AS201641 | B32: =VLOOKUP(A32,[17]LISTADHERENT!A$5:H$39,3,0) -> TCHOUAMOU MATHIEU | C32: =D32+E32+F32-U32-BB32 -> 0 | D32: =VLOOKUP(A32,[18]HISTOBQUEDEC23!$A$6:$G$44,3,0) -> 416000 | E32: =VLOOKUP(A32,[18]HISTOBQUEDEC23!$A$6:$G$39,4,0) -> 0 | F32: =VLOOKUP(A32,[18]HISTOBQUEDEC23!$A$6:$G$39,5,0) -> 0 | G32: =IF(H32="ESPECES",3000,0) -> 0 | H32: =IF($D32<>0,"BANQUE",IF($E32<>0,"ESPECES","ECHEC")) -> BANQUE | J32: 1 | K32: =IF($D32<>0,J32*40000,IF($E32<>0,J32*40000,0)) -> 40000 | L32: 1 | M32: =IF($D32<>0,L32*75000,IF($E32<>0,L32*75000,0)) -> 75000 | O32: =IF($D32<>0,N32*100000,IF($E32<>0,N32*100000,0)) -> 0 | P32: =VLOOKUP($A32,[20]TONTDEC23!$A$6:$P$35,12,0) -> 0 | Q32: =VLOOKUP($A32,[13]TONTDEC23!$A$6:$P$20,10,0) -> 101000 | S32: 200000 | T32: BANQUE | U32: =G32+S32++R32+P32+O32+M32+I32+K32+Q32+W32 -> 416000 | AQ32: =IF(H32="ECHEC",((K32+M32+O32)*20/100),0) -> 0 | AR32: =IF(H32="ECHEC",((K32+M32+O32)*20/100),0) -> 0 | AS32: =IF(H32="ECHEC",0,(K32+I32-25000)) -> 15000 | AW32: =IF(AC32=0,AI32,(1*25000*12)+AI32-AC32) -> 0 | AX32: =IF(AD32=0,AJ32,(1*75000*12)+(AJ32)-AD32) -> 0 | AY32: =IF(AE32=0,AK32,(1*100000*12)+(AK32)-AE32) -> 0 | AZ32: =SUM(AV32:AY32)-BF32+Z32-F32+BH32+BI32+BJ32+BK32+BL32+BM32 -> 0 | BD32: =IF(AZ32=0,(AZ32-BA32-BC32),(AZ32-BA32-BB32-BC32))+F32 -> 0 | BF32: =Z32*1/100*BG32 -> 0 | BG32: 12
A33: AS201643 | B33: =VLOOKUP(A33,[17]LISTADHERENT!A$5:H$39,3,0) -> TCHOUTOU NANA CLAUDE | C33: =D33+E33+F33-U33-BB33+70000 -> 40000 | D33: =VLOOKUP(A33,[18]HISTOBQUEDEC23!$A$6:$G$44,3,0) -> 90000 | E33: =VLOOKUP(A33,[18]HISTOBQUEDEC23!$A$6:$G$39,4,0) -> 0 | F33: =VLOOKUP(A33,[18]HISTOBQUEDEC23!$A$6:$G$39,5,0) -> 0 | G33: =IF(H33="ESPECES",3000,0) -> 0 | H33: =IF($D33<>0,"BANQUE",IF($E33<>0,"ESPECES","ECHEC")) -> BANQUE | I33: 10000 | J33: 1 | K33: =IF($D33<>0,J33*40000,IF($E33<>0,J33*40000,0)) -> 40000 | M33: =IF($D33<>0,L33*75000,IF($E33<>0,L33*75000,0)) -> 0 | O33: =IF($D33<>0,N33*100000,IF($E33<>0,N33*100000,0)) -> 0 | P33: =VLOOKUP($A33,[20]TONTDEC23!$A$6:$P$35,12,0) -> 0 | U33: =G33+S33++R33+P33+O33+M33+I33+K33+Q33+W33 -> 50000 | AC33: 2500 | AQ33: =IF(H33="ECHEC",((K33+M33+O33)*20/100),0) -> 0 | AR33: =IF(H33="ECHEC",((K33+M33+O33)*20/100),0) -> 0 | AS33: =IF(H33="ECHEC",0,(K33+I33-25000)) -> 25000 | AW33: =IF(AC33=0,AI33,(1*25000*12)+AI33-AC33) -> 297500 | AX33: =IF(AD33=0,AJ33,(1*75000*12)+(AJ33)-AD33) -> 0 | AY33: =IF(AE33=0,AK33,(1*100000*12)+(AK33)-AE33) -> 0 | AZ33: =SUM(AV33:AY33)-BF33+Z33-F33+BH33+BI33+BJ33+BK33+BL33+BM33 -> 297500 | BB33: 70000 | BD33: =IF(AZ33=0,(AZ33-BA33-BC33),(AZ33-BA33-BB33-BC33))+F33-51500 -> 176000 | BF33: =Z33*1/100*BG33 -> 0 | BG33: 12 | BN33: S/TOTAL | BP33: =SUM(BP30:BP32) -> 0
A34: AS201658 | B34: =VLOOKUP(A34,[17]LISTADHERENT!A$5:H$39,3,0) -> YANTCHOU GERVAIS | C34: =D34+E34+F34-U34-BB34 -> 0 | D34: =VLOOKUP(A34,[18]HISTOBQUEDEC23!$A$6:$G$44,3,0) -> 40000 | E34: =VLOOKUP(A34,[18]HISTOBQUEDEC23!$A$6:$G$39,4,0) -> 0 | F34: =VLOOKUP(A34,[18]HISTOBQUEDEC23!$A$6:$G$39,5,0) -> 0 | G34: =IF(H34="ESPECES",3000,0) -> 0 | H34: =IF($D34<>0,"BANQUE",IF($E34<>0,"ESPECES","ECHEC")) -> BANQUE | J34: 1 | K34: =IF($D34<>0,J34*40000,IF($E34<>0,J34*40000,0)) -> 40000 | M34: =IF($D34<>0,L34*75000,IF($E34<>0,L34*75000,0)) -> 0 | O34: =IF($D34<>0,N34*100000,IF($E34<>0,N34*100000,0)) -> 0 | P34: =VLOOKUP($A34,[20]TONTDEC23!$A$6:$P$35,12,0) -> 0 | U34: =G34+S34++R34+P34+O34+M34+I34+K34+Q34+W34 -> 40000 | Z34: 700000 | AA34: BANQUE | AQ34: =IF(H34="ECHEC",((K34+M34+O34)*20/100),0) -> 0 | AR34: =IF(H34="ECHEC",((K34+M34+O34)*20/100),0) -> 0 | AS34: =IF(H34="ECHEC",0,(K34+I34-25000)) -> 15000 | AW34: =IF(AC34=0,AI34,(1*25000*12)+AI34-AC34) -> 0 | AX34: =IF(AD34=0,AJ34,(1*75000*12)+(AJ34)-AD34) -> 0 | AY34: =IF(AE34=0,AK34,(1*100000*12)+(AK34)-AE34) -> 0 | AZ34: =SUM(AV34:AY34)-BF34+Z34-F34+BH34+BI34+BJ34+BK34+BL34+BM34 -> 616000 | BD34: =IF(AZ34=0,(AZ34-BA34-BC34),(AZ34-BA34-BB34-BC34))+F34 -> 616000 | BF34: =Z34*1/100*BG34 -> 84000 | BG34: 12
A35: AS201646 | B35: =VLOOKUP(A35,[17]LISTADHERENT!A$5:H$39,3,0) -> YEPMOU JEAN JACQUES | C35: =D35+E35+F35-U35-BB35+70000 -> 0 | D35: =VLOOKUP(A35,[18]HISTOBQUEDEC23!$A$6:$G$44,3,0)+227500 -> 227500 | E35: =VLOOKUP(A35,[18]HISTOBQUEDEC23!$A$6:$G$39,4,0) -> 40000 | F35: =VLOOKUP(A35,[18]HISTOBQUEDEC23!$A$6:$G$39,5,0) -> 0 | G35: =IF(H35="ESPECES",3000,0) -> 0 | H35: =IF($D35<>0,"BANQUE",IF($E35<>0,"ESPECES","ECHEC")) -> BANQUE | J35: 1 | K35: =IF($D35<>0,J35*40000,IF($E35<>0,J35*40000,0)) -> 40000 | M35: =IF($D35<>0,L35*75000,IF($E35<>0,L35*75000,0)) -> 0 | O35: =IF($D35<>0,N35*100000,IF($E35<>0,N35*100000,0)) -> 0 | P35: =VLOOKUP($A35,[20]TONTDEC23!$A$6:$P$35,12,0) -> 0 | S35: 227500 | T35: BANQUE | U35: =G35+S35++R35+P35+O35+M35+I35+K35+Q35+W35 -> 267500 | AC35: 2500 | AQ35: =IF(H35="ECHEC",((K35+M35+O35)*20/100),0) -> 0 | AR35: =IF(H35="ECHEC",((K35+M35+O35)*20/100),0) -> 0 | AS35: =IF(H35="ECHEC",0,(K35+I35-25000)) -> 15000 | AW35: =IF(AC35=0,AI35,(1*25000*12)+AI35-AC35) -> 297500 | AX35: =IF(AD35=0,AJ35,(1*75000*12)+(AJ35)-AD35) -> 0 | AY35: =IF(AE35=0,AK35,(1*100000*12)+(AK35)-AE35) -> 0 | AZ35: =SUM(AV35:AY35)-BF35+Z35-F35+BH35+BI35+BJ35+BK35+BL35+BM35 -> 297500 | BB35: 70000 | BD35: =IF(AZ35=0,(AZ35-BA35-BC35),(AZ35-BA35-BB35-BC35))+F35 -> 227500 | BF35: =Z35*1/100*BG35 -> 0 | BG35: 12 | BN35: COLLATION | BO35: COLLATION
A36: AS201647 | B36: =VLOOKUP(A36,[17]LISTADHERENT!A$5:H$39,3,0) -> YOUMBI EMMANUEL | C36: =D36+E36+F36-U36-BB36 -> 0 | D36: =VLOOKUP(A36,[18]HISTOBQUEDEC23!$A$6:$G$44,3,0) -> 290000 | E36: =VLOOKUP(A36,[18]HISTOBQUEDEC23!$A$6:$G$39,4,0) -> 0 | F36: =VLOOKUP(A36,[18]HISTOBQUEDEC23!$A$6:$G$39,5,0) -> 0 | G36: =IF(H36="ESPECES",3000,0) -> 0 | H36: =IF($D36<>0,"BANQUE",IF($E36<>0,"ESPECES","ECHEC")) -> BANQUE | J36: 1 | K36: =IF($D36<>0,J36*40000,IF($E36<>0,J36*40000,0)) -> 40000 | L36: 2 | M36: =IF($D36<>0,L36*75000,IF($E36<>0,L36*75000,0)) -> 150000 | N36: 1 | O36: =IF($D36<>0,N36*100000,IF($E36<>0,N36*100000,0)) -> 100000 | P36: =VLOOKUP($A36,[20]TONTDEC23!$A$6:$P$35,12,0) -> 0 | Q36: =VLOOKUP($A36,[13]TONTDEC23!$A$6:$P$20,10,0) -> 0 | R36: =VLOOKUP($A36,[19]TONTDEC23!$A$6:$P$21,10,0) -> 0 | U36: =G36+S36++R36+P36+O36+M36+I36+K36+Q36+W36 -> 290000 | V36: =5000+6000 -> 11000 | AQ36: =IF(H36="ECHEC",((K36+M36+O36)*20/100),0) -> 0 | AR36: =IF(H36="ECHEC",((K36+M36+O36)*20/100),0) -> 0 | AS36: =IF(H36="ECHEC",0,(K36+I36-25000)) -> 15000 | AW36: =IF(AC36=0,AI36,(1*25000*12)+AI36-AC36) -> 0 | AX36: =IF(AD36=0,AJ36,(1*75000*12)+(AJ36)-AD36) -> 0 | AY36: =IF(AE36=0,AK36,(1*100000*12)+(AK36)-AE36) -> 0 | AZ36: =SUM(AV36:AY36)-BF36+Z36-F36+BH36+BI36+BJ36+BK36+BL36+BM36 -> 0 | BD36: =IF(AZ36=0,(AZ36-BA36-BC36),(AZ36-BA36-BB36-BC36))+F36 -> 0 | BF36: =Z36*1/100*BG36 -> 0 | BG36: 12 | BN36: BOISSON | BO36: COLLATION
B38: TOTAUX | C38: =SUM(C6:C37) -> 261000 | D38: =SUM(D6:D37) -> 11438000 | E38: =SUM(E6:E37) -> 8171000 | F38: =SUM(F6:F37) -> 0 | G38: =SUM(G6:G37) -> 0 | H38: =SUM(H6:H37) -> 0 | I38: =SUM(I6:I37) -> 203800 | J38: =SUM(J6:J37) -> 30 | ... S38: =SUM(S6:S37) -> 13317700 | U38: =SUM(U6:U37) -> 19348000 | V38: =SUM(V6:V37) -> 207000 | W38: =SUM(W6:W37) -> 0 | X38: =SUM(X6:X37) -> 0 | Y38: =SUM(Y6:Y37) -> 0 | Z38: =SUM(Z6:Z37) -> 14250000 | AA38: =SUM(AA6:AA37) -> 0 | AC38: =SUM(AC6:AC37) -> 5000 | AD38: =SUM(AD6:AD37) -> 7500 | AE38: =SUM(AE6:AE37) -> 10000 | AF38: =SUM(AF6:AF37) -> 0 | AG38: =SUM(AG6:AG37) -> 0 | AI38: =SUM(AI6:AI37) -> 0 | AJ38: =SUM(AJ6:AJ37) -> 0 | AK38: =SUM(AK6:AK37) -> 0 | AL38: =SUM(AL6:AL37) -> 0 | AM38: =SUM(AM6:AM37) -> 0 | AN38: =SUM(AN6:AN37) -> 0 | AO38: =SUM(AO6:AO37) -> 0 | AP38: =SUM(AP6:AP37) -> 0 | ... BD38: =SUM(BD6:BD37) -> 16029000 | BF38: =SUM(BF6:BF37) -> 1162000 | BH38: =SUM(BH6:BH37) -> 6000 | BI38: =SUM(BI6:BI37) -> 0 | BJ38: =SUM(BJ6:BJ37) -> 0 | BK38: =SUM(BK6:BK37) -> 0 | BL38: =SUM(BL6:BL37) -> 0 | BM38: =SUM(BM6:BM37) -> 0 | BN38: S/TOTAL | BP38: =SUM(BP35:BP36) -> 0
C40: BANQUE | F40: ESPECES
B41: LIBELLE | C41: SORTIE | D41: ENTREE | E41: SOLDE | F41: ENTREE | G41: SORTIE | H41: SOLDE | BN41: S/TOTAL | BP41: =BP16+BP22+BP28+BP33+BP38 -> 6000
B42: REPORT
...

Sheet Sheet30
A1: ASSOCIATION | B1: ASELBY
A2: ANNEE | B2: 2023
A3: 1 | B3: 2 | C3: 3 | D3: 4 | E3: 5 | F3: 6 | G3: 7 | H3: 8 | I3: 9 | J3: 10 | K3: 11 | L3: 12 | M3: 13 | N3: 14 | O3: 15 | P3: 16 | Q3: 17 | R3: 18 | S3: 19 | T3: 20 | U3: 21 | V3: 22 | W3: 23 | X3: 24 | Y3: 25 | Z3: 26 | AA3: 27 | AB3: 28 | AC3: 29 | AD3: 30 | AE3: 31 | AF3: 32 | AG3: 33 | AH3: 34 | AI3: 35 | AJ3: 36 | AK3: 37 | AL3: 38 | AM3: 39 | AN3: 40 | AO3: 41 | AP3: 42 | AQ3: 43 | AR3: 44 | AS3: 45 | AT3: 46 | AU3: 47 | AV3: 48 | AW3: 49 | AX3: 50 | AY3: 51 | AZ3: 52 | BA3: 53 | BB3: 54 | BC3: 55 | BD3: 56 | BE3: 57 | BF3: 58 | BG3: 59 | BH3: 60 | BI3: 61 | BJ3: 62 | BK3: 63 | BL3: 64 | BM3: 65 | BN3: 66 | BO3: 67 | BP3: 68
B4: TABLEAU DE BORD SAISIE DES DONNEES
A5: MATRICULE | B5: NOM ET PRENOM | C5: BONUS MALUS | D5: HISTORIQUE BANQUE | E5: HITORIQUE ESPECES | F5: HITORIQUE TONTINE | G5: PENALITE VERSEMENT ESPECES | H5: MODE PAIEMENT TONTINE | I5: COMPLEMENT EPARGNE | J5: NBRE DE LOT | K5: TONTINE 40 000 | L5: NBRE DE LOT | M5: TONTINE 75 000 | N5: NBRE DE LOT | O5: TONTINE 100 000 | P5: REMBOURSEMENT PETIT LOT T40 | Q5: REMBOURSEMENT PETIT LOT T75 | R5: REMBOURSEMENT PETIT LOT T100 | S5: REMBOURSEMENT PRÊT FONDS | T5: MODE PAIEMENT REMBOURSEMENT PRÊT FONDS | U5: MONTANT ENGAGEMENT | V5: SANCTION | W5: INSCRIPTION | X5: EPARGNE ASSURANCE | Y5: RECONSTITUTION FONDS | Z5: PRÊT FONDS | AA5: MODE PAIEMENT PRÊT | AB5: NUM CHEQUE | AC5: ACHAT LOT PRINCIPAL T40 | AD5: ACHAT LOT PRINCIPAL T75 | AE5: ACHAT LOT PRINCIPAL T100 | AF5: MODE PAIEMENT LOT PRINCIPAL | AG5: NUM CHEQUE | AH5: PENALITE VERSEMENT ESPECES | AI5: VENTE PETIT LOT T40 | AJ5: VENTE PETIT LOT T75 | AK5: VENTE PETIT LOT T100 | AL5: INTERET PETIT LOT T40 | AM5: INTERET PETIT LOT T75 | AN5: INTERET PETIT LOT T100 | AO5: NUM CHEQUE | AP5: MODE PAIEMENT PETEIT LOT | AQ5: PENELAITE RETARD TONTINE | AR5: PENELAITE ECHEC TONTINE | AS5: RESTE | AT5: MUTUELLE | AU5: REMBOURSEMENT TRANSPORT | AV5: RETRAIT PARTIEL FONDS | AW5: MONTANT T40 | AX5: MONTANT T75 | AY5: MONTANT T100 | AZ5: MONTANT CHEQUE | BA5: MONTANT ESPECES | BB5: CONTRIBUTION FOYER | BC5: AUTRES SOTIES | BD5: MONTANT CHEQUE EFFECTIF | BE5: NUMERO CHEQUE | BF5: INTERET PRÊT | BG5: NBRE MOIS | BH5: DEPENSE FONDS DE ROULEMENT | BI5: DEPENSE FRAIS EXCEPTIONNEL | BJ5: DEPENSE FONDS MUTUEL | BK5: DEPENSE COLLATION RECEPTION | BL5: PENALITE PRET FONDS | BM5: DEPENSE PENALITE VERSEMENT BANQUE | BN5: LIBELLE | BO5: COMPTE | BP5: MONTANT
A6: AS201648 | B6: =VLOOKUP(A6,[17]LISTADHERENT!A$5:H$39,3,0) -> ASELBY | C6: =HISTOJANV23!C6+HISTOFEV23!C6+HISTOMARS23!C6+HISTOAVRIL23!C6+HISTOMAI23!C6+HISTOJUIN23!C6+HISTOJUIL23!C6+HISTOAOUT23!C6+HISTOSEPT23!C6+HISTOOCT23!C6+HISTONOV23!C6+HISTODEC23!C6 -> 0 | D6: =HISTOJANV23!D6+HISTOFEV23!D6+HISTOMARS23!D6+HISTOAVRIL23!D6+HISTOMAI23!D6+HISTOJUIN23!D6+HISTOJUIL23!D6+HISTOAOUT23!D6+HISTOSEPT23!D6+HISTOOCT23!D6+HISTONOV23!D6+HISTODEC23!D6 -> 2100000 | E6: =HISTOJANV23!E6+HISTOFEV23!E6+HISTOMARS23!E6+HISTOAVRIL23!E6+HISTOMAI23!E6+HISTOJUIN23!E6+HISTOJUIL23!E6+HISTOAOUT23!E6+HISTOSEPT23!E6+HISTOOCT23!E6+HISTONOV23!E6+HISTODEC23!E6 -> 0 | F6: =HISTOJANV23!F6+HISTOFEV23!F6+HISTOMARS23!F6+HISTOAVRIL23!F6+HISTOMAI23!F6+HISTOJUIN23!F6+HISTOJUIL23!F6+HISTOAOUT23!F6+HISTOSEPT23!F6+HISTOOCT23!F6+HISTONOV23!F6+HISTODEC23!F6 -> 0 | G6: =HISTOJANV23!G6+HISTOFEV23!G6+HISTOMARS23!G6+HISTOAVRIL23!G6+HISTOMAI23!G6+HISTOJUIN23!G6+HISTOJUIL23!G6+HISTOAOUT23!G6+HISTOSEPT23!G6+HISTOOCT23!G6+HISTONOV23!G6+HISTODEC23!G6 -> 0 | H6: =IF($D6<>0,"BANQUE",IF($E6<>0,"ESPECES","ECHEC")) -> BANQUE | I6: =HISTOJANV23!I6+HISTOFEV23!I6+HISTOMARS23!I6+HISTOAVRIL23!I6+HISTOMAI23!I6+HISTOJUIN23!I6+HISTOJUIL23!I6+HISTOAOUT23!I6+HISTOSEPT23!I6+HISTOOCT23!I6+HISTONOV23!I6+HISTODEC23!I6 -> 0 | J6: =HISTOJANV23!J6+HISTOFEV23!J6+HISTOMARS23!J6+HISTOAVRIL23!J6+HISTOMAI23!J6+HISTOJUIN23!J6+HISTOJUIL23!J6+HISTOAOUT23!J6+HISTOSEPT23!J6+HISTOOCT23!J6+HISTONOV23!J6+HISTODEC23!J6 -> 0 | K6: =HISTOJANV23!K6+HISTOFEV23!K6+HISTOMARS23!K6+HISTOAVRIL23!K6+HISTOMAI23!K6+HISTOJUIN23!K6+HISTOJUIL23!K6+HISTOAOUT23!K6+HISTOSEPT23!K6+HISTOOCT23!K6+HISTONOV23!K6+HISTODEC23!K6 -> 0 | L6: =HISTOJANV23!L6+HISTOFEV23!L6+HISTOMARS23!L6+HISTOAVRIL23!L6+HISTOMAI23!L6+HISTOJUIN23!L6+HISTOJUIL23!L6+HISTOAOUT23!L6+HISTOSEPT23!L6+HISTOOCT23!L6+HISTONOV23!L6+HISTODEC23!L6 -> 12 | M6: =HISTOJANV23!M6+HISTOFEV23!M6+HISTOMARS23!M6+HISTOAVRIL23!M6+HISTOMAI23!M6+HISTOJUIN23!M6+HISTOJUIL23!M6+HISTOAOUT23!M6+HISTOSEPT23!M6+HISTOOCT23!M6+HISTONOV23!M6+HISTODEC23!M6 -> 900000 | N6: =HISTOJANV23!N6+HISTOFEV23!N6+HISTOMARS23!N6+HISTOAVRIL23!N6+HISTOMAI23!N6+HISTOJUIN23!N6+HISTOJUIL23!N6+HISTOAOUT23!N6+HISTOSEPT23!N6+HISTOOCT23!N6+HISTONOV23!N6+HISTODEC23!N6 -> 12 | O6: =HISTOJANV23!O6+HISTOFEV23!O6+HISTOMARS23!O6+HISTOAVRIL23!O6+HISTOMAI23!O6+HISTOJUIN23!O6+HISTOJUIL23!O6+HISTOAOUT23!O6+HISTOSEPT23!O6+HISTOOCT23!O6+HISTONOV23!O6+HISTODEC23!O6 -> 1200000 | P6: =HISTOJANV23!P6+HISTOFEV23!P6+HISTOMARS23!P6+HISTOAVRIL23!P6+HISTOMAI23!P6+HISTOJUIN23!P6+HISTOJUIL23!P6+HISTOAOUT23!P6+HISTOSEPT23!P6+HISTOOCT23!P6+HISTONOV23!P6+HISTODEC23!P6 -> 0 | ... T6: =HISTOJANV23!T6+HISTOFEV23!T6+HISTOMARS23!T6+HISTOAVRIL23!T6+HISTOMAI23!T6+HISTOJUIN23!T6+HISTOJUIL23!T6+HISTOAOUT23!T6+HISTOSEPT23!T6+HISTOOCT23!T6+HISTONOV23!T6+HISTODEC23!T6 -> 0 | U6: =G6+S6++R6+P6+O6+M6+I6+K6+Q6+V6+W6 -> 2100000 | V6: =HISTOJANV23!V6+HISTOFEV23!V6+HISTOMARS23!V6+HISTOAVRIL23!V6+HISTOMAI23!V6+HISTOJUIN23!V6+HISTOJUIL23!V6+HISTOAOUT23!V6+HISTOSEPT23!V6+HISTOOCT23!V6+HISTONOV23!V6+HISTODEC23!V6 -> 0 | W6: =HISTOJANV23!W6+HISTOFEV23!W6+HISTOMARS23!W6+HISTOAVRIL23!W6+HISTOMAI23!W6+HISTOJUIN23!W6+HISTOJUIL23!W6+HISTOAOUT23!W6+HISTOSEPT23!W6+HISTOOCT23!W6+HISTONOV23!W6+HISTODEC23!W6 -> 0 | X6: =HISTOJANV23!X6+HISTOFEV23!X6+HISTOMARS23!X6+HISTOAVRIL23!X6+HISTOMAI23!X6+HISTOJUIN23!X6+HISTOJUIL23!X6+HISTOAOUT23!X6+HISTOSEPT23!X6+HISTOOCT23!X6+HISTONOV23!X6+HISTODEC23!X6 -> 0 | Y6: =HISTOJANV23!Y6+HISTOFEV23!Y6+HISTOMARS23!Y6+HISTOAVRIL23!Y6+HISTOMAI23!Y6+HISTOJUIN23!Y6+HISTOJUIL23!Y6+HISTOAOUT23!Y6+HISTOSEPT23!Y6+HISTOOCT23!Y6+HISTONOV23!Y6+HISTODEC23!Y6 -> 0 | Z6: =HISTOJANV23!Z6+HISTOFEV23!Z6+HISTOMARS23!Z6+HISTOAVRIL23!Z6+HISTOMAI23!Z6+HISTOJUIN23!Z6+HISTOJUIL23!Z6+HISTOAOUT23!Z6+HISTOSEPT23!Z6+HISTOOCT23!Z6+HISTONOV23!Z6+HISTODEC23!Z6 -> 0 | AA6: =HISTOJANV23!AA6+HISTOFEV23!AA6+HISTOMARS23!AA6+HISTOAVRIL23!AA6+HISTOMAI23!AA6+HISTOJUIN23!AA6+HISTOJUIL23!AA6+HISTOAOUT23!AA6+HISTOSEPT23!AA6+HISTOOCT23!AA6+HISTONOV23!AA6+HISTODEC23!AA6 -> 0 | AB6: =HISTOJANV23!AB6+HISTOFEV23!AB6+HISTOMARS23!AB6+HISTOAVRIL23!AB6+HISTOMAI23!AB6+HISTOJUIN23!AB6+HISTOJUIL23!AB6+HISTOAOUT23!AB6+HISTOSEPT23!AB6+HISTOOCT23!AB6+HISTONOV23!AB6+HISTODEC23!AB6 -> 0 | AC6: =HISTOJANV23!AC6+HISTOFEV23!AC6+HISTOMARS23!AC6+HISTOAVRIL23!AC6+HISTOMAI23!AC6+HISTOJUIN23!AC6+HISTOJUIL23!AC6+HISTOAOUT23!AC6+HISTOSEPT23!AC6+HISTOOCT23!AC6+HISTONOV23!AC6+HISTODEC23!AC6 -> 0 | ... BM6: =HISTOJANV23!BM6+HISTOFEV23!BM6+HISTOMARS23!BM6+HISTOAVRIL23!BM6+HISTOMAI23!BM6+HISTOJUIN23!BM6+HISTOJUIL23!BM6+HISTOAOUT23!BM6+HISTOSEPT23!BM6+HISTOOCT23!BM6+HISTONOV23!BM6+HISTODEC23!BM6 -> 200000 | BN6: ACHAT FOURNITURE | BO6: FONDS DE ROULEMENT | BP6: =HISTOJANV23!BP6+HISTOFEV23!BP6+HISTOMARS23!BP6+HISTOAVRIL23!BP6+HISTOMAI23!BP6+HISTOJUIN23!BP6+HISTOJUIL23!BP6+HISTOAOUT23!BP6+HISTOSEPT23!BP6+HISTOOCT23!BP6+HISTONOV23!BP6+HISTODEC23!BP6 -> 0
A7: AS201601 | B7: =VLOOKUP(A7,[17]LISTADHERENT!A$5:H$39,3,0) -> BAKOP ACHILLE | C7: =HISTOJANV23!C7+HISTOFEV23!C7+HISTOMARS23!C7+HISTOAVRIL23!C7+HISTOMAI23!C7+HISTOJUIN23!C7+HISTOJUIL23!C7+HISTOAOUT23!C7+HISTOSEPT23!C7+HISTOOCT23!C7+HISTONOV23!C7+HISTODEC23!C7 -> 0 | D7: =HISTOJANV23!D7+HISTOFEV23!D7+HISTOMARS23!D7+HISTOAVRIL23!D7+HISTOMAI23!D7+HISTOJUIN23!D7+HISTOJUIL23!D7+HISTOAOUT23!D7+HISTOSEPT23!D7+HISTOOCT23!D7+HISTONOV23!D7+HISTODEC23!D7 -> 388000 | E7: =HISTOJANV23!E7+HISTOFEV23!E7+HISTOMARS23!E7+HISTOAVRIL23!E7+HISTOMAI23!E7+HISTOJUIN23!E7+HISTOJUIL23!E7+HISTOAOUT23!E7+HISTOSEPT23!E7+HISTOOCT23!E7+HISTONOV23!E7+HISTODEC23!E7 -> 846500 | F7: =HISTOJANV23!F7+HISTOFEV23!F7+HISTOMARS23!F7+HISTOAVRIL23!F7+HISTOMAI23!F7+HISTOJUIN23!F7+HISTOJUIL23!F7+HISTOAOUT23!F7+HISTOSEPT23!F7+HISTOOCT23!F7+HISTONOV23!F7+HISTODEC23!F7 -> 140000 | G7: =HISTOJANV23!G7+HISTOFEV23!G7+HISTOMARS23!G7+HISTOAVRIL23!G7+HISTOMAI23!G7+HISTOJUIN23!G7+HISTOJUIL23!G7+HISTOAOUT23!G7+HISTOSEPT23!G7+HISTOOCT23!G7+HISTONOV23!G7+HISTODEC23!G7 -> 3000 | H7: =IF($D7<>0,"BANQUE",IF($E7<>0,"ESPECES","ECHEC")) -> BANQUE | I7: =HISTOJANV23!I7+HISTOFEV23!I7+HISTOMARS23!I7+HISTOAVRIL23!I7+HISTOMAI23!I7+HISTOJUIN23!I7+HISTOJUIL23!I7+HISTOAOUT23!I7+HISTOSEPT23!I7+HISTOOCT23!I7+HISTONOV23!I7+HISTODEC23!I7 -> 64000 | J7: =HISTOJANV23!J7+HISTOFEV23!J7+HISTOMARS23!J7+HISTOAVRIL23!J7+HISTOMAI23!J7+HISTOJUIN23!J7+HISTOJUIL23!J7+HISTOAOUT23!J7+HISTOSEPT23!J7+HISTOOCT23!J7+HISTONOV23!J7+HISTODEC23!J7 -> 12 | K7: =HISTOJANV23!K7+HISTOFEV23!K7+HISTOMARS23!K7+HISTOAVRIL23!K7+HISTOMAI23!K7+HISTOJUIN23!K7+HISTOJUIL23!K7+HISTOAOUT23!K7+HISTOSEPT23!K7+HISTOOCT23!K7+HISTONOV23!K7+HISTODEC23!K7 -> 480000 | L7: =HISTOJANV23!L7+HISTOFEV23!L7+HISTOMARS23!L7+HISTOAVRIL23!L7+HISTOMAI23!L7+HISTOJUIN23!L7+HISTOJUIL23!L7+HISTOAOUT23!L7+HISTOSEPT23!L7+HISTOOCT23!L7+HISTONOV23!L7+HISTODEC23!L7 -> 0 | M7: =HISTOJANV23!M7+HISTOFEV23!M7+HISTOMARS23!M7+HISTOAVRIL23!M7+HISTOMAI23!M7+HISTOJUIN23!M7+HISTOJUIL23!M7+HISTOAOUT23!M7+HISTOSEPT23!M7+HISTOOCT23!M7+HISTONOV23!M7+HISTODEC23!M7 -> 0 | N7: =HISTOJANV23!N7+HISTOFEV23!N7+HISTOMARS23!N7+HISTOAVRIL23!N7+HISTOMAI23!N7+HISTOJUIN23!N7+HISTOJUIL23!N7+HISTOAOUT23!N7+HISTOSEPT23!N7+HISTOOCT23!N7+HISTONOV23!N7+HISTODEC23!N7 -> 0 | O7: =HISTOJANV23!O7+HISTOFEV23!O7+HISTOMARS23!O7+HISTOAVRIL23!O7+HISTOMAI23!O7+HISTOJUIN23!O7+HISTOJUIL23!O7+HISTOAOUT23!O7+HISTOSEPT23!O7+HISTOOCT23!O7+HISTONOV23!O7+HISTODEC23!O7 -> 0 | P7: =HISTOJANV23!P7+HISTOFEV23!P7+HISTOMARS23!P7+HISTOAVRIL23!P7+HISTOMAI23!P7+HISTOJUIN23!P7+HISTOJUIL23!P7+HISTOAOUT23!P7+HISTOSEPT23!P7+HISTOOCT23!P7+HISTONOV23!P7+HISTODEC23!P7 -> 87500 | ... T7: =HISTOJANV23!T7+HISTOFEV23!T7+HISTOMARS23!T7+HISTOAVRIL23!T7+HISTOMAI23!T7+HISTOJUIN23!T7+HISTOJUIL23!T7+HISTOAOUT23!T7+HISTOSEPT23!T7+HISTOOCT23!T7+HISTONOV23!T7+HISTODEC23!T7 -> #VALUE! | U7: =G7+S7++R7+P7+O7+M7+I7+K7+Q7+V7+W7 -> 1234500 | V7: =HISTOJANV23!V7+HISTOFEV23!V7+HISTOMARS23!V7+HISTOAVRIL23!V7+HISTOMAI23!V7+HISTOJUIN23!V7+HISTOJUIL23!V7+HISTOAOUT23!V7+HISTOSEPT23!V7+HISTOOCT23!V7+HISTONOV23!V7+HISTODEC23!V7 -> 0 | W7: =HISTOJANV23!W7+HISTOFEV23!W7+HISTOMARS23!W7+HISTOAVRIL23!W7+HISTOMAI23!W7+HISTOJUIN23!W7+HISTOJUIL23!W7+HISTOAOUT23!W7+HISTOSEPT23!W7+HISTOOCT23!W7+HISTONOV23!W7+HISTODEC23!W7 -> 0 | X7: =HISTOJANV23!X7+HISTOFEV23!X7+HISTOMARS23!X7+HISTOAVRIL23!X7+HISTOMAI23!X7+HISTOJUIN23!X7+HISTOJUIL23!X7+HISTOAOUT23!X7+HISTOSEPT23!X7+HISTOOCT23!X7+HISTONOV23!X7+HISTODEC23!X7 -> 0 | Y7: =HISTOJANV23!Y7+HISTOFEV23!Y7+HISTOMARS23!Y7+HISTOAVRIL23!Y7+HISTOMAI23!Y7+HISTOJUIN23!Y7+HISTOJUIL23!Y7+HISTOAOUT23!Y7+HISTOSEPT23!Y7+HISTOOCT23!Y7+HISTONOV23!Y7+HISTODEC23!Y7 -> 0 | Z7: =HISTOJANV23!Z7+HISTOFEV23!Z7+HISTOMARS23!Z7+HISTOAVRIL23!Z7+HISTOMAI23!Z7+HISTOJUIN23!Z7+HISTOJUIL23!Z7+HISTOAOUT23!Z7+HISTOSEPT23!Z7+HISTOOCT23!Z7+HISTONOV23!Z7+HISTODEC23!Z7 -> 600000 | AA7: =HISTOJANV23!AA7+HISTOFEV23!AA7+HISTOMARS23!AA7+HISTOAVRIL23!AA7+HISTOMAI23!AA7+HISTOJUIN23!AA7+HISTOJUIL23!AA7+HISTOAOUT23!AA7+HISTOSEPT23!AA7+HISTOOCT23!AA7+HISTONOV23!AA7+HISTODEC23!AA7 -> #VALUE! | AB7: =HISTOJANV23!AB7+HISTOFEV23!AB7+HISTOMARS23!AB7+HISTOAVRIL23!AB7+HISTOMAI23!AB7+HISTOJUIN23!AB7+HISTOJUIL23!AB7+HISTOAOUT23!AB7+HISTOSEPT23!AB7+HISTOOCT23!AB7+HISTONOV23!AB7+HISTODEC23!AB7 -> 0 | AC7: =HISTOJANV23!AC7+HISTOFEV23!AC7+HISTOMARS23!AC7+HISTOAVRIL23!AC7+HISTOMAI23!AC7+HISTOJUIN23!AC7+HISTOJUIL23!AC7+HISTOAOUT23!AC7+HISTOSEPT23!AC7+HISTOOCT23!AC7+HISTONOV23!AC7+HISTODEC23!AC7 -> 3000 | ... BM7: =HISTOJANV23!BM7+HISTOFEV23!BM7+HISTOMARS23!BM7+HISTOAVRIL23!BM7+HISTOMAI23!BM7+HISTOJUIN23!BM7+HISTOJUIL23!BM7+HISTOAOUT23!BM7+HISTOSEPT23!BM7+HISTOOCT23!BM7+HISTONOV23!BM7+HISTODEC23!BM7 -> 0 | BN7: COMMUNICATION | BO7: FONDS DE ROULEMENT | BP7: =HISTOJANV23!BP7+HISTOFEV23!BP7+HISTOMARS23!BP7+HISTOAVRIL23!BP7+HISTOMAI23!BP7+HISTOJUIN23!BP7+HISTOJUIL23!BP7+HISTOAOUT23!BP7+HISTOSEPT23!BP7+HISTOOCT23!BP7+HISTONOV23!BP7+HISTODEC23!BP7 -> 0
