Workbook
Name MODEPAID: MODEPAID!$A$1:$A$3
Name MODEPAID: #REF!
Name MODEPAID: #REF!
Name MODEPAID: #REF!
Name MODEPAID: #REF!
Name MODEPAID: #REF!
Name MODEPAID: #REF!
Name MODEPAID: #REF!
Name MODEPAID: #REF!
Name MODEPAID: #REF!
Name MODEPAID: #REF!
Name MODEPAID: #REF!
Name MODEPAID: #REF!
Name MODEPAID: #REF!
Name MODEPAID: #REF!
Name MODEPAID: #REF!
Name MODEPAID: #REF!
Name MODEPAID: #REF!
Name MODEPAID: #REF!
Name VALMODEPAID: MODEPAID!$A$1:$A$3

Sheet MODEPAID
A1: BANQUE
A2: ESPECES
A3: ECHEC

Sheet TONTJUIL
A1: ASSOCIATION | B1: ASELBY
A2: ANNEE | B2: 2019/2020
A3: TONTINE | B3: 75000
C4: 44031
A5: MATRICULE | B5: NOM ET PRENOM | C5: MONTANT TONTINE | D5: PENALITE | E5: MODE VERSEMENT TONTINE | F5: VENTE PETIT LOT | G5: INTERET PETIT LOT | H5: MODE VERSEMENT VENTE PETIT LOT | I5: NUMERO CHEQUE | J5: MONTANT A REMOURSER | K5: MONTANT REMBOURSE | L5: MODE VERSEMENT REMBOURSEMENT | M5: MODE VERSEMENT TONTINE PRINCIPAL | N5: NUMERO CHEQUE | O5: MONTANT TONTINE LOT PRINCIPAL | P5: INTERET LOT PRINCIPAL
A6: AS201602 | B6: =VLOOKUP(A6,[1]LISTADHERENT!A$5:H$60,3,0) -> BOUTCHOUANG WILLIAM | C6: =IF(E6="ECHEC",0,IF(E6="",0,75000)) -> 75000 | D6: =IF(E6="ESPECES",0,0) -> 0 | E6: BANQUE | K6: =J6 -> 0 | O6: =IF(P6=0,0,($C$36-P6)) -> 0
A7: AS201603 | B7: =VLOOKUP(A7,[1]LISTADHERENT!A$5:H$60,3,0) -> CHINGUE FABRICE | C7: =IF(E7="ECHEC",0,IF(E7="",0,75000)) -> 75000 | D7: =IF(E7="ESPECES",0,0) -> 0 | E7: BANQUE | K7: =J7 -> 0 | O7: =IF(P7=0,0,($C$36-P7)) -> 0
A8: AS201604 | B8: =VLOOKUP(A8,[1]LISTADHERENT!A$5:H$60,3,0) -> DJOMO JEAN PAUL | C8: =IF(E8="ECHEC",0,IF(E8="",0,75000)) -> 75000 | D8: =IF(E8="ESPECES",0,0) -> 0 | E8: BANQUE | F8: 100000 | G8: 2000 | K8: =J8 -> 0 | O8: =IF(P8=0,0,($C$36-P8)) -> 1000000 | P8: 200000
A9: AS201605 | B9: =VLOOKUP(A9,[1]LISTADHERENT!A$5:H$60,3,0) -> DJOUKWE NANGUEN GUY BLAISE | C9: =IF(E9="ECHEC",0,IF(E9="",0,75000)) -> 75000 | D9: =IF(E9="ESPECES",0,0) -> 0 | E9: BANQUE | K9: =J9 -> 0 | O9: =IF(P9=0,0,($C$36-P9)) -> 0
A10: AS201613 | B10: =VLOOKUP(A10,[1]LISTADHERENT!A$5:H$60,3,0) -> HOTCHO BENJAMIN | C10: =IF(E10="ECHEC",0,IF(E10="",0,75000)) -> 75000 | D10: =IF(E10="ESPECES",0,0) -> 0 | E10: BANQUE | K10: =J10 -> 0 | O10: =IF(P10=0,0,($C$36-P10)) -> 0
A11: AS201611 | B11: =VLOOKUP(A11,[1]LISTADHERENT!A$5:H$60,3,0) -> HENGUE PAUL OMER | C11: =IF(E11="ECHEC",0,IF(E11="",0,75000)) -> 75000 | D11: =IF(E11="ESPECES",0,0) -> 0 | E11: BANQUE | K11: =J11 -> 0 | O11: =IF(P11=0,0,($C$36-P11)) -> 0
A12: AS201619 | B12: =VLOOKUP(A12,[1]LISTADHERENT!A$5:H$60,3,0) -> KOUATCHO MESSACK | C12: =IF(E12="ECHEC",0,IF(E12="",0,75000)) -> 75000 | D12: =IF(E12="ESPECES",0,0) -> 0 | E12: BANQUE | F12: 100000 | G12: 2000 | K12: =J12 -> 0 | O12: =IF(P12=0,0,($C$36-P12)) -> 0
A13: AS201621 | B13: =VLOOKUP(A13,[1]LISTADHERENT!A$5:H$60,3,0) -> NANKAM APPOLINAIRE | C13: =IF(E13="ECHEC",0,IF(E13="",0,75000)) -> 75000 | D13: =IF(E13="ESPECES",0,0) -> 0 | E13: BANQUE | K13: =J13 -> 0 | O13: =IF(P13=0,0,($C$36-P13)) -> 0
A14: AS201649 | B14: =VLOOKUP(A14,[1]LISTADHERENT!A$5:H$60,3,0) -> MBOGNING TUGMA GUY | C14: =IF(E14="ECHEC",0,IF(E14="",0,75000)) -> 75000 | D14: =IF(E14="ESPECES",0,0) -> 0 | E14: BANQUE | F14: 100000 | G14: 2000 | K14: =J14 -> 0 | O14: =IF(P14=0,0,($C$36-P14)) -> 0
A15: AS201649 | B15: =VLOOKUP(A15,[1]LISTADHERENT!A$5:H$60,3,0) -> MBOGNING TUGMA GUY | C15: =IF(E15="ECHEC",0,IF(E15="",0,75000)) -> 75000 | D15: =IF(E15="ESPECES",0,0) -> 0 | E15: BANQUE | K15: =J15 -> 0 | O15: =IF(P15=0,0,($C$36-P15)) -> 0
A16: AS201649 | B16: =VLOOKUP(A16,[1]LISTADHERENT!A$5:H$60,3,0) -> MBOGNING TUGMA GUY | C16: =IF(E16="ECHEC",0,IF(E16="",0,75000)) -> 75000 | D16: =IF(E16="ESPECES",0,0) -> 0 | E16: BANQUE | K16: =J16 -> 0 | O16: =IF(P16=0,0,($C$36-P16)) -> 0
A17: AS201626 | B17: =VLOOKUP(A17,[1]LISTADHERENT!A$5:H$60,3,0) -> NGUIEMEGNI MATHIEU BLAISE | C17: =IF(E17="ECHEC",0,IF(E17="",0,75000)) -> 75000 | D17: =IF(E17="ESPECES",0,0) -> 0 | E17: BANQUE | K17: =J17 -> 0 | O17: =IF(P17=0,0,($C$36-P17)) -> 0
A18: AS201626 | B18: =VLOOKUP(A18,[1]LISTADHERENT!A$5:H$60,3,0) -> NGUIEMEGNI MATHIEU BLAISE | C18: =IF(E18="ECHEC",0,IF(E18="",0,75000)) -> 75000 | D18: =IF(E18="ESPECES",0,0) -> 0 | E18: BANQUE | K18: =J18 -> 0 | O18: =IF(P18=0,0,($C$36-P18)) -> 0
A19: AS201628 | B19: =VLOOKUP(A19,[1]LISTADHERENT!A$5:H$60,3,0) -> NKAMGANG JUSTIN DEJOLIE | C19: =IF(E19="ECHEC",0,IF(E19="",0,75000)) -> 75000 | D19: =IF(E19="ESPECES",0,0) -> 0 | E19: BANQUE | F19: 50000 | G19: 1000 | K19: =J19 -> 0 | O19: =IF(P19=0,0,($C$36-P19)) -> 0
A20: AS201633 | B20: =VLOOKUP(A20,[1]LISTADHERENT!A$5:H$60,3,0) -> PATEGO NJOSSU GUSTAVE | C20: =IF(E20="ECHEC",0,IF(E20="",0,75000)) -> 75000 | D20: =IF(E20="ESPECES",0,0) -> 0 | E20: BANQUE | K20: =J20 -> 0 | O20: =IF(P20=0,0,($C$36-P20)) -> 0
A21: AS201638 | B21: =VLOOKUP(A21,[1]LISTADHERENT!A$5:H$60,3,0) -> SIMO PIERRE | C21: =IF(E21="ECHEC",0,IF(E21="",0,75000)) -> 75000 | D21: =IF(E21="ESPECES",0,0) -> 0 | E21: BANQUE | K21: =J21 -> 0 | O21: =IF(P21=0,0,($C$36-P21)) -> 0
A22: AS201655 | B22: =VLOOKUP(A22,[1]LISTADHERENT!A$5:H$60,3,0) -> TCHEMHOU EMMANUEL | C22: =IF(E22="ECHEC",0,IF(E22="",0,75000)) -> 0 | D22: =IF(E22="ESPECES",0,0) -> 0 | E22: ECHEC | J22: =K22 -> 0 | K22: =+TONTJUIL!F21+TONTJUIL!G21 -> 0 | O22: =IF(P22=0,0,($C$36-P22)) -> 0
A23: AS201647 | B23: =VLOOKUP(A23,[1]LISTADHERENT!A$5:H$60,3,0) -> YOUMBI EMMANUEL | C23: =IF(E23="ECHEC",0,IF(E23="",0,75000)) -> 75000 | D23: =IF(E23="ESPECES",0,0) -> 0 | E23: BANQUE | K23: =J23 -> 0 | O23: =IF(P23=0,0,($C$36-P23)) -> 0
A24: AS201647 | B24: =VLOOKUP(A24,[1]LISTADHERENT!A$5:H$60,3,0) -> YOUMBI EMMANUEL | C24: =IF(E24="ECHEC",0,IF(E24="",0,75000)) -> 75000 | D24: =IF(E24="ESPECES",0,0) -> 0 | E24: BANQUE | K24: =J24 -> 0 | O24: =IF(P24=0,0,($C$36-P24)) -> 0
A26: TOTAL | C26: =SUM(C6:C24) -> 1350000 | D26: =SUM(D6:D24) -> 0 | F26: =SUM(F6:F24) -> 350000 | G26: =SUM(G6:G24) -> 7000 | I26: =SUM(I6:I24) -> 0 | J26: =SUM(J6:J24) -> 0 | K26: =SUM(K6:K24) -> 0 | M26: =SUM(M6:M24) -> 0 | N26: =SUM(N6:N24) -> 0 | O26: =SUM(O6:O24) -> 1000000 | P26: =SUM(P6:P24) -> 200000
C28: TONTINE | D28: REMBOURSEMENT PETIT LOT | E28: VENTE PETIT LOT | F28: VENTE LOT PRINCIPAL | G28: SOLDE EN CAISSE | I28: TONTINE + REMB + INTERET VENTE | J28: =(C33+D33+P26) -> 1550000
I29: VENTE LOT | J29: =IF(J28>=2000000,120000*2,1200000) -> 1200000
B30: ESPECES | C30: =SUMIFS(C6:C24,E6:E24,"ESPECES") -> 0 | D30: =SUMIFS(J6:J24,L6:L24,"ESPECES") -> 0 | E30: =SUMIFS(F6:F24,H6:H24,"ESPECES") -> 0 | F30: =SUMIFS(M6:M24,L6:L24,"ESPECES") -> 0 | G30: =C30+D30-E30-F30 -> 0
B31: BANQUE | C31: =SUMIFS(C6:C24,E6:E24,"BANQUE") -> 1350000 | D31: =SUMIFS(K6:K24,L6:L24,"BANQUE") -> 0 | E31: =SUMIFS(F6:F24,H6:H24,"BANQUE") -> 0 | F31: =SUMIFS(M6:M24,L6:L24,"BANQUE") -> 0 | G31: =C31+D31-E31-F31 -> 1350000 | I31: PETIT LOT | J31: =IF(J28>0,J28-J29,0) -> 350000
B33: TOTAL | C33: =C30+C31 -> 1350000 | D33: =D30+D31 -> 0 | E33: =E30+E31 -> 0 | F33: =F30+F31 -> 0 | G33: =G30+G31 -> 1350000 | I33: RESTE | J33: =J31-F26 -> 0
B36: MONTANT TONTINE | C36: 1200000

Sheet TONTAOUT
A1: ASSOCIATION | B1: ASELBY
A2: ANNEE | B2: 2019/2020
A3: TONTINE | B3: 75000
C4: 44059
A5: MATRICULE | B5: NOM ET PRENOM | C5: MONTANT TONTINE | D5: PENALITE | E5: MODE VERSEMENT TONTINE | F5: VENTE PETIT LOT | G5: INTERET PETIT LOT | H5: MODE VERSEMENT VENTE PETIT LOT | I5: NUMERO CHEQUE | J5: MONTANT REMBOURSE | K5: MONTANT A REMBOURSER | L5: MODE VERSEMENT REMBOURSEMENT | M5: MODE VERSEMENT TONTINE PRINCIPAL | N5: NUMERO CHEQUE | O5: MONTANT TONTINE LOT PRINCIPAL | P5: INTERET LOT PRINCIPAL
A6: AS201602 | B6: =VLOOKUP(A6,[1]LISTADHERENT!A$5:H$60,3,0) -> BOUTCHOUANG WILLIAM | C6: =IF(E6="ECHEC",0,IF(E6="",0,75000)) -> 75000 | D6: =IF(E6="ESPECES",0,0) -> 0 | E6: BANQUE | J6: =K6 -> 0 | K6: =+TONTJUIL!F6+TONTJUIL!G6 -> 0 | O6: =IF(P6=0,0,($C$36-P6)) -> 0
A7: AS201603 | B7: =VLOOKUP(A7,[1]LISTADHERENT!A$5:H$60,3,0) -> CHINGUE FABRICE | C7: =IF(E7="ECHEC",0,IF(E7="",0,75000)) -> 0 | D7: =IF(E7="ESPECES",0,0) -> 0 | E7: ECHEC | J7: =K7 -> 0 | K7: =+TONTJUIL!F7+TONTJUIL!G7 -> 0 | O7: =IF(P7=0,0,($C$36-P7)) -> 0
A8: AS201604 | B8: =VLOOKUP(A8,[1]LISTADHERENT!A$5:H$60,3,0) -> DJOMO JEAN PAUL | C8: =IF(E8="ECHEC",0,IF(E8="",0,75000)) -> 75000 | D8: =IF(E8="ESPECES",0,0) -> 0 | E8: BANQUE | F8: 100000 | G8: 2000 | J8: =K8 -> 102000 | K8: =+TONTJUIL!F8+TONTJUIL!G8 -> 102000 | L8: ESPECES | O8: =IF(P8=0,0,($C$36-P8)) -> 0
A9: AS201605 | B9: =VLOOKUP(A9,[1]LISTADHERENT!A$5:H$60,3,0) -> DJOUKWE NANGUEN GUY BLAISE | C9: =IF(E9="ECHEC",0,IF(E9="",0,75000)) -> 75000 | D9: =IF(E9="ESPECES",0,0) -> 0 | E9: BANQUE | F9: 100000 | G9: 2000 | J9: =K9 -> 0 | K9: =+TONTJUIL!F9+TONTJUIL!G9 -> 0 | O9: =IF(P9=0,0,($C$36-P9)) -> 0
A10: AS201613 | B10: =VLOOKUP(A10,[1]LISTADHERENT!A$5:H$60,3,0) -> HOTCHO BENJAMIN | C10: =IF(E10="ECHEC",0,IF(E10="",0,75000)) -> 75000 | D10: =IF(E10="ESPECES",0,0) -> 0 | E10: BANQUE | J10: =K10 -> 0 | K10: =+TONTJUIL!F10+TONTJUIL!G10 -> 0 | O10: =IF(P10=0,0,($C$36-P10)) -> 0
A11: AS201611 | B11: =VLOOKUP(A11,[1]LISTADHERENT!A$5:H$60,3,0) -> HENGUE PAUL OMER | C11: =IF(E11="ECHEC",0,IF(E11="",0,75000)) -> 75000 | D11: =IF(E11="ESPECES",0,0) -> 0 | E11: BANQUE | J11: =K11 -> 0 | K11: =+TONTJUIL!F11+TONTJUIL!G11 -> 0 | O11: =IF(P11=0,0,($C$36-P11)) -> 0
A12: AS201619 | B12: =VLOOKUP(A12,[1]LISTADHERENT!A$5:H$60,3,0) -> KOUATCHO MESSACK | C12: =IF(E12="ECHEC",0,IF(E12="",0,75000)) -> 75000 | D12: =IF(E12="ESPECES",0,0) -> 0 | E12: BANQUE | J12: =K12 -> 102000 | K12: =+TONTJUIL!F12+TONTJUIL!G12 -> 102000 | O12: =IF(P12=0,0,($C$36-P12)) -> 0
A13: AS201621 | B13: =VLOOKUP(A13,[1]LISTADHERENT!A$5:H$60,3,0) -> NANKAM APPOLINAIRE | C13: =IF(E13="ECHEC",0,IF(E13="",0,75000)) -> 75000 | D13: =IF(E13="ESPECES",0,0) -> 0 | E13: BANQUE | J13: =K13 -> 0 | K13: =+TONTJUIL!F13+TONTJUIL!G13 -> 0 | O13: =IF(P13=0,0,($C$36-P13)) -> 0
A14: AS201649 | B14: =VLOOKUP(A14,[1]LISTADHERENT!A$5:H$60,3,0) -> MBOGNING TUGMA GUY | C14: =IF(E14="ECHEC",0,IF(E14="",0,75000)) -> 75000 | D14: =IF(E14="ESPECES",0,0) -> 0 | E14: BANQUE | F14: 100000 | G14: 2000 | J14: =K14 -> 102000 | K14: =+TONTJUIL!F14+TONTJUIL!G14 -> 102000 | L14: BANQUE | O14: =IF(P14=0,0,($C$36-P14)) -> 1040000 | P14: 160000
A15: AS201649 | B15: =VLOOKUP(A15,[1]LISTADHERENT!A$5:H$60,3,0) -> MBOGNING TUGMA GUY | C15: =IF(E15="ECHEC",0,IF(E15="",0,75000)) -> 75000 | D15: =IF(E15="ESPECES",0,0) -> 0 | E15: BANQUE | J15: =K15 -> 0 | K15: =+TONTJUIL!F15+TONTJUIL!G15 -> 0 | O15: =IF(P15=0,0,($C$36-P15)) -> 0
A16: AS201649 | B16: =VLOOKUP(A16,[1]LISTADHERENT!A$5:H$60,3,0) -> MBOGNING TUGMA GUY | C16: =IF(E16="ECHEC",0,IF(E16="",0,75000)) -> 75000 | D16: =IF(E16="ESPECES",0,0) -> 0 | E16: BANQUE | J16: =K16 -> 0 | K16: =+TONTJUIL!F16+TONTJUIL!G16 -> 0 | O16: =IF(P16=0,0,($C$36-P16)) -> 0
A17: AS201626 | B17: =VLOOKUP(A17,[1]LISTADHERENT!A$5:H$60,3,0) -> NGUIEMEGNI MATHIEU BLAISE | C17: =IF(E17="ECHEC",0,IF(E17="",0,75000)) -> 75000 | D17: =IF(E17="ESPECES",0,0) -> 0 | E17: BANQUE | F17: 100000 | G17: 2000 | J17: =K17 -> 0 | K17: =+TONTJUIL!F17+TONTJUIL!G17 -> 0 | O17: =IF(P17=0,0,($C$36-P17)) -> 0
A18: AS201626 | B18: =VLOOKUP(A18,[1]LISTADHERENT!A$5:H$60,3,0) -> NGUIEMEGNI MATHIEU BLAISE | C18: =IF(E18="ECHEC",0,IF(E18="",0,75000)) -> 75000 | D18: =IF(E18="ESPECES",0,0) -> 0 | E18: BANQUE | J18: =K18 -> 0 | K18: =+TONTJUIL!F18+TONTJUIL!G18 -> 0 | O18: =IF(P18=0,0,($C$36-P18)) -> 0
A19: AS201628 | B19: =VLOOKUP(A19,[1]LISTADHERENT!A$5:H$60,3,0) -> NKAMGANG JUSTIN DEJOLIE | C19: =IF(E19="ECHEC",0,IF(E19="",0,75000)) -> 75000 | D19: =IF(E19="ESPECES",0,0) -> 0 | E19: ESPECES | F19: 100000 | G19: 2000 | J19: =K19 -> 51000 | K19: =+TONTJUIL!F19+TONTJUIL!G19 -> 51000 | L19: ESPECES | O19: =IF(P19=0,0,($C$36-P19)) -> 0
A20: AS201633 | B20: =VLOOKUP(A20,[1]LISTADHERENT!A$5:H$60,3,0) -> PATEGO NJOSSU GUSTAVE | C20: =IF(E20="ECHEC",0,IF(E20="",0,75000)) -> 75000 | D20: =IF(E20="ESPECES",0,0) -> 0 | E20: BANQUE | J20: =K20 -> 0 | K20: =+TONTJUIL!F20+TONTJUIL!G20 -> 0 | O20: =IF(P20=0,0,($C$36-P20)) -> 0
A21: AS201638 | B21: =VLOOKUP(A21,[1]LISTADHERENT!A$5:H$60,3,0) -> SIMO PIERRE | C21: =IF(E21="ECHEC",0,IF(E21="",0,75000)) -> 75000 | D21: =IF(E21="ESPECES",0,0) -> 0 | E21: BANQUE | J21: =K21 -> 0 | K21: =+TONTJUIL!F21+TONTJUIL!G21 -> 0 | O21: =IF(P21=0,0,($C$36-P21)) -> 0
A22: AS201655 | B22: =VLOOKUP(A22,[1]LISTADHERENT!A$5:H$60,3,0) -> TCHEMHOU EMMANUEL | C22: 161500 | D22: =IF(E22="ESPECES",0,0) -> 0 | E22: ESPECES | J22: =K22 -> 0 | K22: =+TONTJUIL!F21+TONTJUIL!G21 -> 0 | O22: =IF(P22=0,0,($C$36-P22)) -> 0
A23: AS201647 | B23: =VLOOKUP(A23,[1]LISTADHERENT!A$5:H$60,3,0) -> YOUMBI EMMANUEL | C23: =IF(E23="ECHEC",0,IF(E23="",0,75000)) -> 75000 | D23: =IF(E23="ESPECES",0,0) -> 0 | E23: BANQUE | J23: =K23 -> 0 | K23: =+TONTJUIL!F23+TONTJUIL!G23 -> 0 | O23: =IF(P23=0,0,($C$36-P23)) -> 0
A24: AS201647 | B24: =VLOOKUP(A24,[1]LISTADHERENT!A$5:H$60,3,0) -> YOUMBI EMMANUEL | C24: =IF(E24="ECHEC",0,IF(E24="",0,75000)) -> 75000 | D24: =IF(E24="ESPECES",0,0) -> 0 | E24: BANQUE | J24: =K24 -> 0 | K24: =+TONTJUIL!F24+TONTJUIL!G24 -> 0 | O24: =IF(P24=0,0,($C$36-P24)) -> 0
A26: TOTAL | C26: =SUM(C6:C24) -> 1436500 | D26: =SUM(D6:D24) -> 0 | F26: =SUM(F6:F24) -> 500000 | G26: =SUM(G6:G24) -> 10000 | I26: =SUM(I6:I24) -> 0 | J26: =SUM(J6:J24) -> 357000 | K26: =SUM(K6:K24) -> 357000 | M26: =SUM(M6:M24) -> 0 | N26: =SUM(N6:N24) -> 0 | O26: =SUM(O6:O24) -> 1040000 | P26: =SUM(P6:P24) -> 160000
C28: TONTINE | D28: REMBOURSEMENT PETIT LOT | E28: VENTE PETIT LOT | F28: VENTE LOT PRINCIPAL | G28: SOLDE EN CAISSE | I28: TONTINE + REMB + INTERET VENTE | J28: =(C33+D33+P26) -> 1851500
I29: VENTE LOT | J29: =IF(J28>=2000000,1200000*2,1200000) -> 1200000
B30: ESPECES | C30: =SUMIFS(C6:C24,E6:E24,"ESPECES") -> 236500 | D30: =SUMIFS(J6:J24,L6:L24,"ESPECES") -> 153000 | E30: =SUMIFS(F6:F24,H6:H24,"ESPECES") -> 0 | F30: =SUMIFS(M6:M24,L6:L24,"ESPECES") -> 0 | G30: =C30+D30-E30-F30 -> 389500
B31: BANQUE | C31: =SUMIFS(C6:C24,E6:E24,"BANQUE") -> 1200000 | D31: =SUMIFS(J6:J24,L6:L24,"BANQUE") -> 102000 | E31: =SUMIFS(F6:F24,H6:H24,"BANQUE") -> 0 | F31: =SUMIFS(M6:M24,L6:L24,"BANQUE") -> 0 | G31: =C31+D31-E31-F31 -> 1302000 | I31: PETIT LOT | J31: =IF(J28>0,J28-J29,0) -> 651500
B33: TOTAL | C33: =C30+C31 -> 1436500 | D33: =D30+D31 -> 255000 | E33: =E30+E31 -> 0 | F33: =F30+F31 -> 0 | G33: =G30+G31 -> 1691500 | I33: RESTE | J33: =J31-F26+TONTJUIL!J33 -> 151500 | K33: EN CAISSE
B36: MONTANT TONTINE | C36: 1200000

Sheet TONTSEPT
A1: ASSOCIATION | B1: ASELBY
A2: ANNEE | B2: 2019/2020
A3: TONTINE | B3: 75000
C4: 44094
A5: MATRICULE | B5: NOM ET PRENOM | C5: MONTANT TONTINE | D5: PENALITE | E5: MODE VERSEMENT TONTINE | F5: VENTE PETIT LOT | G5: INTERET PETIT LOT | H5: MODE VERSEMENT VENTE PETIT LOT | I5: NUMERO CHEQUE | J5: MONTANT REMBOURSE | K5: MONTANT A REMBOURSER | L5: MODE VERSEMENT REMBOURSEMENT | M5: MODE VERSEMENT TONTINE PRINCIPAL | N5: NUMERO CHEQUE | O5: MONTANT TONTINE LOT PRINCIPAL | P5: INTERET LOT PRINCIPAL
A6: AS201602 | B6: =VLOOKUP(A6,[1]LISTADHERENT!A$5:H$60,3,0) -> BOUTCHOUANG WILLIAM | C6: =IF(E6="ECHEC",0,IF(E6="",0,75000)) -> 75000 | D6: =IF(E6="ESPECES",0,0) -> 0 | E6: BANQUE | J6: =K6 -> 0 | K6: =+TONTAOUT!F6+TONTAOUT!G6 -> 0 | O6: =IF(P6=0,0,($C$36-P6)) -> 0
A7: AS201603 | B7: =VLOOKUP(A7,[1]LISTADHERENT!A$5:H$60,3,0) -> CHINGUE FABRICE | C7: =IF(E7="ECHEC",0,IF(E7="",0,75000)) -> 0 | D7: =IF(E7="ESPECES",0,0) -> 0 | E7: ECHEC | J7: =K7 -> 0 | K7: =+TONTAOUT!F7+TONTAOUT!G7 -> 0 | O7: =IF(P7=0,0,($C$36-P7)) -> 0
A8: AS201604 | B8: =VLOOKUP(A8,[1]LISTADHERENT!A$5:H$60,3,0) -> DJOMO JEAN PAUL | C8: =IF(E8="ECHEC",0,IF(E8="",0,75000)) -> 75000 | D8: =IF(E8="ESPECES",0,0) -> 0 | E8: BANQUE | F8: 50000 | G8: 1000 | J8: =K8 -> 102000 | K8: =+TONTAOUT!F8+TONTAOUT!G8 -> 102000 | L8: BANQUE | O8: =IF(P8=0,0,($C$36-P8)) -> 0
A9: AS201605 | B9: =VLOOKUP(A9,[1]LISTADHERENT!A$5:H$60,3,0) -> DJOUKWE NANGUEN GUY BLAISE | C9: =IF(E9="ECHEC",0,IF(E9="",0,75000)) -> 75000 | D9: =IF(E9="ESPECES",0,0) -> 0 | E9: BANQUE | F9: 150000 | G9: 3000 | J9: =K9 -> 102000 | K9: =+TONTAOUT!F9+TONTAOUT!G9 -> 102000 | L9: BANQUE | O9: =IF(P9=0,0,($C$36-P9)) -> 0
A10: AS201613 | B10: =VLOOKUP(A10,[1]LISTADHERENT!A$5:H$60,3,0) -> HOTCHO BENJAMIN | C10: =IF(E10="ECHEC",0,IF(E10="",0,75000)) -> 75000 | D10: =IF(E10="ESPECES",0,0) -> 0 | E10: BANQUE | J10: =K10 -> 0 | K10: =+TONTAOUT!F10+TONTAOUT!G10 -> 0 | O10: =IF(P10=0,0,($C$36-P10)) -> 0
A11: AS201611 | B11: =VLOOKUP(A11,[1]LISTADHERENT!A$5:H$60,3,0) -> HENGUE PAUL OMER | C11: =IF(E11="ECHEC",0,IF(E11="",0,75000)) -> 75000 | D11: =IF(E11="ESPECES",0,0) -> 0 | E11: BANQUE | J11: =K11 -> 0 | K11: =+TONTAOUT!F11+TONTAOUT!G11 -> 0 | O11: =IF(P11=0,0,($C$36-P11)) -> 0
A12: AS201619 | B12: =VLOOKUP(A12,[1]LISTADHERENT!A$5:H$60,3,0) -> KOUATCHO MESSACK | C12: =IF(E12="ECHEC",0,IF(E12="",0,75000)) -> 75000 | D12: =IF(E12="ESPECES",0,0) -> 0 | E12: BANQUE | F12: 100000 | G12: 2000 | J12: =K12 -> 0 | K12: =+TONTAOUT!F12+TONTAOUT!G12 -> 0 | O12: =IF(P12=0,0,($C$36-P12)) -> 0
A13: AS201621 | B13: =VLOOKUP(A13,[1]LISTADHERENT!A$5:H$60,3,0) -> NANKAM APPOLINAIRE | C13: =IF(E13="ECHEC",0,IF(E13="",0,75000)) -> 75000 | D13: =IF(E13="ESPECES",0,0) -> 0 | E13: BANQUE | J13: =K13 -> 0 | K13: =+TONTAOUT!F13+TONTAOUT!G13 -> 0 | O13: =IF(P13=0,0,($C$36-P13)) -> 0
A14: AS201649 | B14: =VLOOKUP(A14,[1]LISTADHERENT!A$5:H$60,3,0) -> MBOGNING TUGMA GUY | C14: =IF(E14="ECHEC",0,IF(E14="",0,75000)) -> 75000 | D14: =IF(E14="ESPECES",0,0) -> 0 | E14: BANQUE | F14: 100000 | G14: 2000 | J14: =K14 -> 102000 | K14: =+TONTAOUT!F14+TONTAOUT!G14 -> 102000 | L14: BANQUE | O14: =IF(P14=0,0,($C$36-P14)) -> 0
A15: AS201649 | B15: =VLOOKUP(A15,[1]LISTADHERENT!A$5:H$60,3,0) -> MBOGNING TUGMA GUY | C15: =IF(E15="ECHEC",0,IF(E15="",0,75000)) -> 75000 | D15: =IF(E15="ESPECES",0,0) -> 0 | E15: BANQUE | J15: =K15 -> 0 | K15: =+TONTAOUT!F15+TONTAOUT!G15 -> 0 | O15: =IF(P15=0,0,($C$36-P15)) -> 0
A16: AS201649 | B16: =VLOOKUP(A16,[1]LISTADHERENT!A$5:H$60,3,0) -> MBOGNING TUGMA GUY | C16: =IF(E16="ECHEC",0,IF(E16="",0,75000)) -> 75000 | D16: =IF(E16="ESPECES",0,0) -> 0 | E16: BANQUE | J16: =K16 -> 0 | K16: =+TONTAOUT!F16+TONTAOUT!G16 -> 0 | O16: =IF(P16=0,0,($C$36-P16)) -> 0
A17: AS201626 | B17: =VLOOKUP(A17,[1]LISTADHERENT!A$5:H$60,3,0) -> NGUIEMEGNI MATHIEU BLAISE | C17: =IF(E17="ECHEC",0,IF(E17="",0,75000)) -> 75000 | D17: =IF(E17="ESPECES",0,0) -> 0 | E17: BANQUE | F17: 102000 | G17: 4000 | H17: ECHEC | J17: =K17 -> 102000 | K17: =+TONTAOUT!F17+TONTAOUT!G17 -> 102000 | L17: ECHEC | O17: =IF(P17=0,0,($C$36-P17)) -> 0
A18: AS201626 | B18: =VLOOKUP(A18,[1]LISTADHERENT!A$5:H$60,3,0) -> NGUIEMEGNI MATHIEU BLAISE | C18: =IF(E18="ECHEC",0,IF(E18="",0,75000)) -> 75000 | D18: =IF(E18="ESPECES",0,0) -> 0 | E18: BANQUE | J18: =K18 -> 0 | K18: =+TONTAOUT!F18+TONTAOUT!G18 -> 0 | O18: =IF(P18=0,0,($C$36-P18)) -> 0
A19: AS201628 | B19: =VLOOKUP(A19,[1]LISTADHERENT!A$5:H$60,3,0) -> NKAMGANG JUSTIN DEJOLIE | C19: =IF(E19="ECHEC",0,IF(E19="",0,75000)) -> 75000 | D19: =IF(E19="ESPECES",0,0) -> 0 | E19: ESPECES | F19: 100000 | G19: 2000 | J19: =K19 -> 102000 | K19: =+TONTAOUT!F19+TONTAOUT!G19 -> 102000 | L19: ESPECES | O19: =IF(P19=0,0,($C$36-P19)) -> 1115000 | P19: 85000
A20: AS201633 | B20: =VLOOKUP(A20,[1]LISTADHERENT!A$5:H$60,3,0) -> PATEGO NJOSSU GUSTAVE | C20: =IF(E20="ECHEC",0,IF(E20="",0,75000)) -> 75000 | D20: =IF(E20="ESPECES",0,0) -> 0 | E20: BANQUE | J20: =K20 -> 0 | K20: =+TONTAOUT!F20+TONTAOUT!G20 -> 0 | O20: =IF(P20=0,0,($C$36-P20)) -> 0
A21: AS201638 | B21: =VLOOKUP(A21,[1]LISTADHERENT!A$5:H$60,3,0) -> SIMO PIERRE | C21: =IF(E21="ECHEC",0,IF(E21="",0,75000)) -> 75000 | D21: =IF(E21="ESPECES",0,0) -> 0 | E21: BANQUE | J21: =K21 -> 0 | K21: =+TONTAOUT!F21+TONTAOUT!G21 -> 0 | O21: =IF(P21=0,0,($C$36-P21)) -> 0
A22: AS201655 | B22: =VLOOKUP(A22,[1]LISTADHERENT!A$5:H$60,3,0) -> TCHEMHOU EMMANUEL | C22: =IF(E22="ECHEC",0,IF(E22="",0,75000)) -> 75000 | D22: =IF(E22="ESPECES",0,0) -> 0 | E22: BANQUE | J22: =K22 -> 0 | K22: =+TONTAOUT!F22+TONTAOUT!G22 -> 0 | O22: =IF(P22=0,0,($C$36-P22)) -> 0
A23: AS201647 | B23: =VLOOKUP(A23,[1]LISTADHERENT!A$5:H$60,3,0) -> YOUMBI EMMANUEL | C23: =IF(E23="ECHEC",0,IF(E23="",0,75000)) -> 75000 | D23: =IF(E23="ESPECES",0,0) -> 0 | E23: BANQUE | J23: =K23 -> 0 | K23: =+TONTAOUT!F23+TONTAOUT!G23 -> 0 | O23: =IF(P23=0,0,($C$36-P23)) -> 0
A24: AS201647 | B24: =VLOOKUP(A24,[1]LISTADHERENT!A$5:H$60,3,0) -> YOUMBI EMMANUEL | C24: =IF(E24="ECHEC",0,IF(E24="",0,75000)) -> 75000 | D24: =IF(E24="ESPECES",0,0) -> 0 | E24: BANQUE | J24: =K24 -> 0 | K24: =+TONTAOUT!F24+TONTAOUT!G24 -> 0 | O24: =IF(P24=0,0,($C$36-P24)) -> 0
A26: TOTAL | C26: =SUM(C6:C24) -> 1350000 | D26: =SUM(D6:D24) -> 0 | F26: =SUM(F6:F24) -> 602000 | G26: =SUM(G6:G24) -> 14000 | I26: =SUM(I6:I24) -> 0 | J26: =SUM(J6:J24) -> 510000 | K26: =SUM(K6:K24) -> 510000 | M26: =SUM(M6:M24) -> 0 | N26: =SUM(N6:N24) -> 0 | O26: =SUM(O6:O24) -> 1115000 | P26: =SUM(P6:P24) -> 85000
C28: TONTINE | D28: REMBOURSEMENT PETIT LOT | E28: VENTE PETIT LOT | F28: VENTE LOT PRINCIPAL | G28: SOLDE EN CAISSE | I28: TONTINE + REMB + INTERET VENTE | J28: =(C33+D33+P26) -> 1843000
I29: VENTE LOT | J29: =IF(J28>=2000000,1200000*2,1200000) -> 1200000
B30: ESPECES | C30: =SUMIFS(C6:C24,E6:E24,"ESPECES") -> 75000 | D30: =SUMIFS(J6:J24,L6:L24,"ESPECES") -> 102000 | E30: =SUMIFS(F6:F24,H6:H24,"ESPECES") -> 0 | F30: =SUMIFS(M6:M24,L6:L24,"ESPECES") -> 0 | G30: =C30+D30-E30-F30 -> 177000
B31: BANQUE | C31: =SUMIFS(C6:C24,E6:E24,"BANQUE") -> 1275000 | D31: =SUMIFS(J6:J24,L6:L24,"BANQUE") -> 306000 | E31: =SUMIFS(F6:F24,H6:H24,"BANQUE") -> 0 | F31: =SUMIFS(M6:M24,L6:L24,"BANQUE") -> 0 | G31: =C31+D31-E31-F31 -> 1581000 | I31: PETIT LOT | J31: =IF(J28>0,J28-J29,0) -> 643000
B33: TOTAL | C33: =C30+C31 -> 1350000 | D33: =D30+D31 -> 408000 | E33: =E30+E31 -> 0 | F33: =F30+F31 -> 0 | G33: =G30+G31 -> 1758000 | I33: RESTE | J33: =J31-F26+TONTAOUT!J33 -> 192500
I35: ECHEC TONTINE | J35: 0
B36: MONTANT TONTINE | C36: 1200000 | I36: ECHEC REMBOURSEMENT | J36: =106000+53000 -> 159000 | K36: NGUIEMENI/MBONING

Sheet TONTOCT
A1: ASSOCIATION | B1: ASELBY
A2: ANNEE | B2: 2019/2020
A3: TONTINE | B3: 75000
C4: 44122
A5: MATRICULE | B5: NOM ET PRENOM | C5: MONTANT TONTINE | D5: PENALITE | E5: MODE VERSEMENT TONTINE | F5: VENTE PETIT LOT | G5: INTERET PETIT LOT | H5: MODE VERSEMENT VENTE PETIT LOT | I5: NUMERO CHEQUE | J5: MONTANT REMBOURSE | K5: MONTANT A REMBOURSER | L5: MODE VERSEMENT REMBOURSEMENT | M5: MODE VERSEMENT TONTINE PRINCIPAL | N5: NUMERO CHEQUE | O5: MONTANT TONTINE LOT PRINCIPAL | P5: INTERET LOT PRINCIPAL
A6: AS201602 | B6: =VLOOKUP(A6,[1]LISTADHERENT!A$5:H$60,3,0) -> BOUTCHOUANG WILLIAM | C6: =IF(E6="ECHEC",0,IF(E6="",0,75000)) -> 75000 | D6: =IF(E6="ESPECES",0,0) -> 0 | E6: BANQUE | J6: =K6 -> 0 | K6: =TONTSEPT!F6+TONTSEPT!G6 -> 0 | O6: =IF(P6=0,0,($C$36-P6)) -> 0
A7: AS201603 | B7: =VLOOKUP(A7,[1]LISTADHERENT!A$5:H$60,3,0) -> CHINGUE FABRICE | C7: =IF(E7="ECHEC",0,IF(E7="",0,75000)) -> 0 | D7: =IF(E7="ESPECES",0,0) -> 0 | E7: ECHEC | J7: =K7 -> 0 | K7: =TONTSEPT!F7+TONTSEPT!G7 -> 0 | O7: =IF(P7=0,0,($C$36-P7)) -> 0
A8: AS201604 | B8: =VLOOKUP(A8,[1]LISTADHERENT!A$5:H$60,3,0) -> DJOMO JEAN PAUL | C8: =IF(E8="ECHEC",0,IF(E8="",0,75000)) -> 75000 | D8: =IF(E8="ESPECES",0,0) -> 0 | E8: BANQUE | J8: =K8 -> 51000 | K8: =TONTSEPT!F8+TONTSEPT!G8 -> 51000 | L8: BANQUE | O8: =IF(P8=0,0,($C$36-P8)) -> 0
A9: AS201605 | B9: =VLOOKUP(A9,[1]LISTADHERENT!A$5:H$60,3,0) -> DJOUKWE NANGUEN GUY BLAISE | C9: =IF(E9="ECHEC",0,IF(E9="",0,75000)) -> 75000 | D9: =IF(E9="ESPECES",0,0) -> 0 | E9: BANQUE | J9: =K9 -> 153000 | K9: =TONTSEPT!F9+TONTSEPT!G9 -> 153000 | L9: BANQUE | O9: =IF(P9=0,0,($C$36-P9)) -> 0
A10: AS201613 | B10: =VLOOKUP(A10,[1]LISTADHERENT!A$5:H$60,3,0) -> HOTCHO BENJAMIN | C10: =IF(E10="ECHEC",0,IF(E10="",0,75000)) -> 75000 | D10: =IF(E10="ESPECES",0,0) -> 0 | E10: BANQUE | J10: =K10 -> 0 | K10: =TONTSEPT!F10+TONTSEPT!G10 -> 0 | O10: =IF(P10=0,0,($C$36-P10)) -> 1125000 | P10: 75000
A11: AS201611 | B11: =VLOOKUP(A11,[1]LISTADHERENT!A$5:H$60,3,0) -> HENGUE PAUL OMER | C11: =IF(E11="ECHEC",0,IF(E11="",0,75000)) -> 75000 | D11: =IF(E11="ESPECES",0,0) -> 0 | E11: BANQUE | J11: =K11 -> 0 | K11: =TONTSEPT!F11+TONTSEPT!G11 -> 0 | O11: =IF(P11=0,0,($C$36-P11)) -> 0
A12: AS201619 | B12: =VLOOKUP(A12,[1]LISTADHERENT!A$5:H$60,3,0) -> KOUATCHO MESSACK | C12: =IF(E12="ECHEC",0,IF(E12="",0,75000)) -> 75000 | D12: =IF(E12="ESPECES",0,0) -> 0 | E12: BANQUE | J12: =K12 -> 102000 | K12: =TONTSEPT!F12+TONTSEPT!G12 -> 102000 | L12: BANQUE | O12: =IF(P12=0,0,($C$36-P12)) -> 0
A13: AS201621 | B13: =VLOOKUP(A13,[1]LISTADHERENT!A$5:H$60,3,0) -> NANKAM APPOLINAIRE | C13: =IF(E13="ECHEC",0,IF(E13="",0,75000)) -> 75000 | D13: =IF(E13="ESPECES",0,0) -> 0 | E13: BANQUE | J13: =K13 -> 0 | K13: =TONTSEPT!F13+TONTSEPT!G13 -> 0 | O13: =IF(P13=0,0,($C$36-P13)) -> 0
A14: AS201649 | B14: =VLOOKUP(A14,[1]LISTADHERENT!A$5:H$60,3,0) -> MBOGNING TUGMA GUY | C14: =IF(E14="ECHEC",0,IF(E14="",0,75000)) -> 75000 | D14: =IF(E14="ESPECES",0,0) -> 0 | E14: BANQUE | J14: =K14 -> 102000 | K14: =TONTSEPT!F14+TONTSEPT!G14 -> 102000 | L14: BANQUE | O14: =IF(P14=0,0,($C$36-P14)) -> 0
A15: AS201649 | B15: =VLOOKUP(A15,[1]LISTADHERENT!A$5:H$60,3,0) -> MBOGNING TUGMA GUY | C15: =IF(E15="ECHEC",0,IF(E15="",0,75000)) -> 75000 | D15: =IF(E15="ESPECES",0,0) -> 0 | E15: BANQUE | J15: =K15 -> 0 | K15: =TONTSEPT!F15+TONTSEPT!G15 -> 0 | O15: =IF(P15=0,0,($C$36-P15)) -> 0
A16: AS201649 | B16: =VLOOKUP(A16,[1]LISTADHERENT!A$5:H$60,3,0) -> MBOGNING TUGMA GUY | C16: =IF(E16="ECHEC",0,IF(E16="",0,75000)) -> 75000 | D16: =IF(E16="ESPECES",0,0) -> 0 | E16: BANQUE | J16: =K16 -> 0 | K16: =TONTSEPT!F16+TONTSEPT!G16 -> 0 | O16: =IF(P16=0,0,($C$36-P16)) -> 0
A17: AS201626 | B17: =VLOOKUP(A17,[1]LISTADHERENT!A$5:H$60,3,0) -> NGUIEMEGNI MATHIEU BLAISE | C17: =IF(E17="ECHEC",0,IF(E17="",0,75000)) -> 75000 | D17: =IF(E17="ESPECES",0,0) -> 0 | E17: BANQUE | J17: =K17 -> 106000 | K17: =TONTSEPT!F17+TONTSEPT!G17 -> 106000 | L17: BANQUE | O17: =IF(P17=0,0,($C$36-P17)) -> 0
A18: AS201626 | B18: =VLOOKUP(A18,[1]LISTADHERENT!A$5:H$60,3,0) -> NGUIEMEGNI MATHIEU BLAISE | C18: =IF(E18="ECHEC",0,IF(E18="",0,75000)) -> 75000 | D18: =IF(E18="ESPECES",0,0) -> 0 | E18: BANQUE | J18: =K18 -> 0 | K18: =TONTSEPT!F18+TONTSEPT!G18 -> 0 | O18: =IF(P18=0,0,($C$36-P18)) -> 0
A19: AS201628 | B19: =VLOOKUP(A19,[1]LISTADHERENT!A$5:H$60,3,0) -> NKAMGANG JUSTIN DEJOLIE | C19: =IF(E19="ECHEC",0,IF(E19="",0,75000)) -> 75000 | D19: =IF(E19="ESPECES",0,0) -> 0 | E19: ESPECES | J19: =K19 -> 102000 | K19: =TONTSEPT!F19+TONTSEPT!G19 -> 102000 | L19: ESPECES | O19: =IF(P19=0,0,($C$36-P19)) -> 0
A20: AS201633 | B20: =VLOOKUP(A20,[1]LISTADHERENT!A$5:H$60,3,0) -> PATEGO NJOSSU GUSTAVE | C20: =IF(E20="ECHEC",0,IF(E20="",0,75000)) -> 75000 | D20: =IF(E20="ESPECES",0,0) -> 0 | E20: BANQUE | J20: =K20 -> 0 | K20: =TONTSEPT!F20+TONTSEPT!G20 -> 0 | O20: =IF(P20=0,0,($C$36-P20)) -> 0
A21: AS201638 | B21: =VLOOKUP(A21,[1]LISTADHERENT!A$5:H$60,3,0) -> SIMO PIERRE | C21: =IF(E21="ECHEC",0,IF(E21="",0,75000)) -> 75000 | D21: =IF(E21="ESPECES",0,0) -> 0 | E21: BANQUE | J21: =K21 -> 0 | K21: =TONTSEPT!F21+TONTSEPT!G21 -> 0 | O21: =IF(P21=0,0,($C$36-P21)) -> 0
A22: AS201655 | B22: =VLOOKUP(A22,[1]LISTADHERENT!A$5:H$60,3,0) -> TCHEMHOU EMMANUEL | C22: =IF(E22="ECHEC",0,IF(E22="",0,75000)) -> 75000 | D22: =IF(E22="ESPECES",0,0) -> 0 | E22: BANQUE | J22: =K22 -> 0 | K22: =TONTSEPT!F22+TONTSEPT!G22 -> 0 | O22: =IF(P22=0,0,($C$36-P22)) -> 0
A23: AS201647 | B23: =VLOOKUP(A23,[1]LISTADHERENT!A$5:H$60,3,0) -> YOUMBI EMMANUEL | C23: =IF(E23="ECHEC",0,IF(E23="",0,75000)) -> 75000 | D23: =IF(E23="ESPECES",0,0) -> 0 | E23: BANQUE | J23: =K23 -> 0 | K23: =TONTSEPT!F23+TONTSEPT!G23 -> 0 | O23: =IF(P23=0,0,($C$36-P23)) -> 1125000 | P23: 75000
A24: AS201647 | B24: =VLOOKUP(A24,[1]LISTADHERENT!A$5:H$60,3,0) -> YOUMBI EMMANUEL | C24: =IF(E24="ECHEC",0,IF(E24="",0,75000)) -> 75000 | D24: =IF(E24="ESPECES",0,0) -> 0 | E24: BANQUE | J24: =K24 -> 0 | K24: =TONTSEPT!F24+TONTSEPT!G24 -> 0 | O24: =IF(P24=0,0,($C$36-P24)) -> 0
A26: TOTAL | C26: =SUM(C6:C24) -> 1350000 | D26: =SUM(D6:D24) -> 0 | F26: =SUM(F6:F24) -> 0 | G26: =SUM(G6:G24) -> 0 | I26: =SUM(I6:I24) -> 0 | J26: =SUM(J6:J24) -> 616000 | K26: =SUM(K6:K24) -> 616000 | M26: =SUM(M6:M24) -> 0 | N26: =SUM(N6:N24) -> 0 | O26: =SUM(O6:O24) -> 2250000 | P26: =SUM(P6:P24) -> 150000
C28: TONTINE | D28: REMBOURSEMENT PETIT LOT | E28: VENTE PETIT LOT | F28: VENTE LOT PRINCIPAL | G28: SOLDE EN CAISSE | I28: TONTINE + REMB + INTERET VENTE | J28: =(C33+D33+P26) -> 2116000
I29: VENTE LOT | J29: =IF(J28>=2000000,1200000*2,1200000) -> 2400000
B30: ESPECES | C30: =SUMIFS(C6:C24,E6:E24,"ESPECES") -> 75000 | D30: =SUMIFS(K6:K24,L6:L24,"ESPECES") -> 102000 | E30: =SUMIFS(F6:F24,H6:H24,"ESPECES") -> 0 | F30: =SUMIFS(M6:M24,L6:L24,"ESPECES") -> 0 | G30: =C30+D30-E30-F30 -> 177000
B31: BANQUE | C31: =SUMIFS(C6:C24,E6:E24,"BANQUE") -> 1275000 | D31: =SUMIFS(K6:K24,L6:L24,"BANQUE") -> 514000 | E31: =SUMIFS(F6:F24,H6:H24,"BANQUE") -> 0 | F31: =SUMIFS(M6:M24,L6:L24,"BANQUE") -> 0 | G31: =C31+D31-E31-F31 -> 1789000 | I31: PETIT LOT | J31: =IF(J28>0,J28-J29,0) -> -284000
B33: TOTAL | C33: =C30+C31 -> 1350000 | D33: =D30+D31 -> 616000 | E33: =E30+E31 -> 0 | F33: =F30+F31 -> 0 | G33: =G30+G31 -> 1966000 | I33: RESTE | J33: =J31-F26+TONTSEPT!J33 -> -91500
B36: MONTANT TONTINE | C36: 1200000

Sheet TONTNOV
A1: ASSOCIATION | B1: ASELBY
A2: ANNEE | B2: 2019/2020
A3: TONTINE | B3: 75000
C4: 44150
A5: MATRICULE | B5: NOM ET PRENOM | C5: MONTANT TONTINE | D5: PENALITE | E5: MODE VERSEMENT TONTINE | F5: VENTE PETIT LOT | G5: INTERET PETIT LOT | H5: MODE VERSEMENT VENTE PETIT LOT | I5: NUMERO CHEQUE | J5: MONTANT REMBOURSE | K5: MONTANT A REMBOURSER | L5: MODE VERSEMENT REMBOURSEMENT | M5: MODE VERSEMENT TONTINE PRINCIPAL | N5: NUMERO CHEQUE | O5: MONTANT TONTINE LOT PRINCIPAL | P5: INTERET LOT PRINCIPAL
A6: AS201602 | B6: =VLOOKUP(A6,[1]LISTADHERENT!A$5:H$60,3,0) -> BOUTCHOUANG WILLIAM | C6: =IF(E6="ECHEC",0,IF(E6="",0,75000)) -> 0 | D6: =IF(E6="ESPECES",0,0) -> 0 | E6: ECHEC | J6: =K6 -> 0 | K6: =+TONTOCT!F6+TONTOCT!G6 -> 0 | O6: =IF(P6=0,0,($C$36-P6)) -> 0
A7: AS201603 | B7: =VLOOKUP(A7,[1]LISTADHERENT!A$5:H$60,3,0) -> CHINGUE FABRICE | C7: =IF(E7="ECHEC",0,IF(E7="",0,75000)) -> 0 | D7: =IF(E7="ESPECES",0,0) -> 0 | E7: ECHEC | J7: =K7 -> 0 | K7: =+TONTOCT!F7+TONTOCT!G7 -> 0 | O7: =IF(P7=0,0,($C$36-P7)) -> 0
A8: AS201604 | B8: =VLOOKUP(A8,[1]LISTADHERENT!A$5:H$60,3,0) -> DJOMO JEAN PAUL | C8: =IF(E8="ECHEC",0,IF(E8="",0,75000)) -> 0 | D8: =IF(E8="ESPECES",0,0) -> 0 | E8: ECHEC | J8: =K8 -> 0 | K8: =+TONTOCT!F8+TONTOCT!G8 -> 0 | O8: =IF(P8=0,0,($C$36-P8)) -> 0
A9: AS201605 | B9: =VLOOKUP(A9,[1]LISTADHERENT!A$5:H$60,3,0) -> DJOUKWE NANGUEN GUY BLAISE | C9: =IF(E9="ECHEC",0,IF(E9="",0,75000)) -> 0 | D9: =IF(E9="ESPECES",0,0) -> 0 | E9: ECHEC | J9: =K9 -> 0 | K9: =+TONTOCT!F9+TONTOCT!G9 -> 0 | O9: =IF(P9=0,0,($C$36-P9)) -> 0
A10: AS201613 | B10: =VLOOKUP(A10,[1]LISTADHERENT!A$5:H$60,3,0) -> HOTCHO BENJAMIN | C10: =IF(E10="ECHEC",0,IF(E10="",0,75000)) -> 0 | D10: =IF(E10="ESPECES",0,0) -> 0 | E10: ECHEC | J10: =K10 -> 0 | K10: =+TONTOCT!F10+TONTOCT!G10 -> 0 | O10: =IF(P10=0,0,($C$36-P10)) -> 0
A11: AS201611 | B11: =VLOOKUP(A11,[1]LISTADHERENT!A$5:H$60,3,0) -> HENGUE PAUL OMER | C11: =IF(E11="ECHEC",0,IF(E11="",0,75000)) -> 0 | D11: =IF(E11="ESPECES",0,0) -> 0 | E11: ECHEC | J11: =K11 -> 0 | K11: =+TONTOCT!F11+TONTOCT!G11 -> 0 | O11: =IF(P11=0,0,($C$36-P11)) -> 0
A12: AS201619 | B12: =VLOOKUP(A12,[1]LISTADHERENT!A$5:H$60,3,0) -> KOUATCHO MESSACK | C12: =IF(E12="ECHEC",0,IF(E12="",0,75000)) -> 0 | D12: =IF(E12="ESPECES",0,0) -> 0 | E12: ECHEC | J12: =K12 -> 0 | K12: =+TONTOCT!F12+TONTOCT!G12 -> 0 | O12: =IF(P12=0,0,($C$36-P12)) -> 0
A13: AS201621 | B13: =VLOOKUP(A13,[1]LISTADHERENT!A$5:H$60,3,0) -> NANKAM APPOLINAIRE | C13: =IF(E13="ECHEC",0,IF(E13="",0,75000)) -> 0 | D13: =IF(E13="ESPECES",0,0) -> 0 | E13: ECHEC | J13: =K13 -> 0 | K13: =+TONTOCT!F13+TONTOCT!G13 -> 0 | O13: =IF(P13=0,0,($C$36-P13)) -> 0
A14: AS201649 | B14: =VLOOKUP(A14,[1]LISTADHERENT!A$5:H$60,3,0) -> MBOGNING TUGMA GUY | C14: =IF(E14="ECHEC",0,IF(E14="",0,75000)) -> 0 | D14: =IF(E14="ESPECES",0,0) -> 0 | E14: ECHEC | J14: =K14 -> 0 | K14: =+TONTOCT!F14+TONTOCT!G14 -> 0 | O14: =IF(P14=0,0,($C$36-P14)) -> 0
A15: AS201649 | B15: =VLOOKUP(A15,[1]LISTADHERENT!A$5:H$60,3,0) -> MBOGNING TUGMA GUY | C15: =IF(E15="ECHEC",0,IF(E15="",0,75000)) -> 0 | D15: =IF(E15="ESPECES",0,0) -> 0 | E15: ECHEC | J15: =K15 -> 0 | K15: =+TONTOCT!F15+TONTOCT!G15 -> 0 | O15: =IF(P15=0,0,($C$36-P15)) -> 0
A16: AS201649 | B16: =VLOOKUP(A16,[1]LISTADHERENT!A$5:H$60,3,0) -> MBOGNING TUGMA GUY | C16: =IF(E16="ECHEC",0,IF(E16="",0,75000)) -> 0 | D16: =IF(E16="ESPECES",0,0) -> 0 | E16: ECHEC | J16: =K16 -> 0 | K16: =+TONTOCT!F16+TONTOCT!G16 -> 0 | O16: =IF(P16=0,0,($C$36-P16)) -> 0
A17: AS201626 | B17: =VLOOKUP(A17,[1]LISTADHERENT!A$5:H$60,3,0) -> NGUIEMEGNI MATHIEU BLAISE | C17: =IF(E17="ECHEC",0,IF(E17="",0,75000)) -> 0 | D17: =IF(E17="ESPECES",0,0) -> 0 | E17: ECHEC | J17: =K17 -> 0 | K17: =+TONTOCT!F17+TONTOCT!G17 -> 0 | O17: =IF(P17=0,0,($C$36-P17)) -> 0
... A24: AS201647 | B24: =VLOOKUP(A24,[1]LISTADHERENT!A$5:H$60,3,0) -> YOUMBI EMMANUEL | C24: =IF(E24="ECHEC",0,IF(E24="",0,75000)) -> 0 | D24: =IF(E24="ESPECES",0,0) -> 0 | E24: ECHEC | J24: =K24 -> 0 | K24: =+TONTOCT!F24+TONTOCT!G24 -> 0 | O24: =IF(P24=0,0,($C$36-P24)) -> 0
A26: TOTAL | C26: =SUM(C6:C24) -> 0 | D26: =SUM(D6:D24) -> 0 | F26: =SUM(F6:F24) -> 0 | G26: =SUM(G6:G24) -> 0 | I26: =SUM(I6:I24) -> 0 | J26: =SUM(J6:J24) -> 0 | K26: =SUM(K6:K24) -> 0 | M26: =SUM(M6:M24) -> 0 | N26: =SUM(N6:N24) -> 0 | O26: =SUM(O6:O24) -> 0 | P26: =SUM(P6:P24) -> 0
C28: TONTINE | D28: REMBOURSEMENT PETIT LOT | E28: VENTE PETIT LOT | F28: VENTE LOT PRINCIPAL | G28: SOLDE EN CAISSE | I28: TONTINE + REMB + INTERET VENTE | J28: =(C33+D33+P26) -> 0
I29: VENTE LOT | J29: =IF(J28>=2000000,1200000*2,1200000) -> 1200000
B30: ESPECES | C30: =SUMIFS(C6:C24,E6:E24,"ESPECES") -> 0 | D30: =SUMIFS(J6:J24,L6:L24,"ESPECES") -> 0 | E30: =SUMIFS(F6:F24,H6:H24,"ESPECES") -> 0 | F30: =SUMIFS(M6:M24,L6:L24,"ESPECES") -> 0 | G30: =C30+D30-E30-F30 -> 0
B31: BANQUE | C31: =SUMIFS(C6:C24,E6:E24,"BANQUE") -> 0 | D31: =SUMIFS(J6:J24,L6:L24,"BANQUE") -> 0 | E31: =SUMIFS(F6:F24,H6:H24,"BANQUE") -> 0 | F31: =SUMIFS(M6:M24,L6:L24,"BANQUE") -> 0 | G31: =C31+D31-E31-F31 -> 0 | I31: PETIT LOT | J31: =IF(J28>0,J28-J29,0) -> 0
B33: TOTAL | C33: =C30+C31 -> 0 | D33: =D30+D31 -> 0 | E33: =E30+E31 -> 0 | F33: =F30+F31 -> 0 | G33: =G30+G31 -> 0 | I33: RESTE | J33: =J31-F26+TONTOCT!J33 -> -91500
B36: MONTANT TONTINE | C36: 1200000

Sheet TONTDEC
A1: ASSOCIATION | B1: ASELBY
A2: ANNEE | B2: 2019/2020
A3: TONTINE | B3: 75000
C4: 44185
A5: MATRICULE | B5: NOM ET PRENOM | C5: MONTANT TONTINE | D5: PENALITE | E5: MODE VERSEMENT TONTINE | F5: VENTE PETIT LOT | G5: INTERET PETIT LOT | H5: MODE VERSEMENT VENTE PETIT LOT | I5: NUMERO CHEQUE | J5: MONTANT REMBOURSE | K5: MONTANT A REMBOURSER | L5: MODE VERSEMENT REMBOURSEMENT | M5: MODE VERSEMENT TONTINE PRINCIPAL | N5: NUMERO CHEQUE | O5: MONTANT TONTINE LOT PRINCIPAL | P5: INTERET LOT PRINCIPAL
A6: AS201602 | B6: =VLOOKUP(A6,[1]LISTADHERENT!A$5:H$60,3,0) -> BOUTCHOUANG WILLIAM | C6: =IF(E6="ECHEC",0,IF(E6="",0,75000)) -> 0 | D6: =IF(E6="ESPECES",0,0) -> 0 | E6: ECHEC | J6: =K6 -> 0 | K6: =+TONTNOV!F6+TONTNOV!G6 -> 0 | O6: =IF(P6=0,0,($C$36-P6)) -> 0
A7: AS201603 | B7: =VLOOKUP(A7,[1]LISTADHERENT!A$5:H$60,3,0) -> CHINGUE FABRICE | C7: =IF(E7="ECHEC",0,IF(E7="",0,75000)) -> 0 | D7: =IF(E7="ESPECES",0,0) -> 0 | E7: ECHEC | J7: =K7 -> 0 | K7: =+TONTNOV!F7+TONTNOV!G7 -> 0 | O7: =IF(P7=0,0,($C$36-P7)) -> 0
A8: AS201604 | B8: =VLOOKUP(A8,[1]LISTADHERENT!A$5:H$60,3,0) -> DJOMO JEAN PAUL | C8: =IF(E8="ECHEC",0,IF(E8="",0,75000)) -> 0 | D8: =IF(E8="ESPECES",0,0) -> 0 | E8: ECHEC | J8: =K8 -> 0 | K8: =+TONTNOV!F8+TONTNOV!G8 -> 0 | O8: =IF(P8=0,0,($C$36-P8)) -> 0
A9: AS201605 | B9: =VLOOKUP(A9,[1]LISTADHERENT!A$5:H$60,3,0) -> DJOUKWE NANGUEN GUY BLAISE | C9: =IF(E9="ECHEC",0,IF(E9="",0,75000)) -> 0 | D9: =IF(E9="ESPECES",0,0) -> 0 | E9: ECHEC | J9: =K9 -> 0 | K9: =+TONTNOV!F9+TONTNOV!G9 -> 0 | O9: =IF(P9=0,0,($C$36-P9)) -> 0
A10: AS201613 | B10: =VLOOKUP(A10,[1]LISTADHERENT!A$5:H$60,3,0) -> HOTCHO BENJAMIN | C10: =IF(E10="ECHEC",0,IF(E10="",0,75000)) -> 0 | D10: =IF(E10="ESPECES",0,0) -> 0 | E10: ECHEC | J10: =K10 -> 0 | K10: =+TONTNOV!F10+TONTNOV!G10 -> 0 | O10: =IF(P10=0,0,($C$36-P10)) -> 0
A11: AS201611 | B11: =VLOOKUP(A11,[1]LISTADHERENT!A$5:H$60,3,0) -> HENGUE PAUL OMER | C11: =IF(E11="ECHEC",0,IF(E11="",0,75000)) -> 0 | D11: =IF(E11="ESPECES",0,0) -> 0 | E11: ECHEC | J11: =K11 -> 0 | K11: =+TONTNOV!F11+TONTNOV!G11 -> 0 | O11: =IF(P11=0,0,($C$36-P11)) -> 0
A12: AS201619 | B12: =VLOOKUP(A12,[1]LISTADHERENT!A$5:H$60,3,0) -> KOUATCHO MESSACK | C12: =IF(E12="ECHEC",0,IF(E12="",0,75000)) -> 0 | D12: =IF(E12="ESPECES",0,0) -> 0 | E12: ECHEC | J12: =K12 -> 0 | K12: =+TONTNOV!F12+TONTNOV!G12 -> 0 | O12: =IF(P12=0,0,($C$36-P12)) -> 0
A13: AS201621 | B13: =VLOOKUP(A13,[1]LISTADHERENT!A$5:H$60,3,0) -> NANKAM APPOLINAIRE | C13: =IF(E13="ECHEC",0,IF(E13="",0,75000)) -> 0 | D13: =IF(E13="ESPECES",0,0) -> 0 | E13: ECHEC | J13: =K13 -> 0 | K13: =+TONTNOV!F13+TONTNOV!G13 -> 0 | O13: =IF(P13=0,0,($C$36-P13)) -> 0
A14: AS201649 | B14: =VLOOKUP(A14,[1]LISTADHERENT!A$5:H$60,3,0) -> MBOGNING TUGMA GUY | C14: =IF(E14="ECHEC",0,IF(E14="",0,75000)) -> 0 | D14: =IF(E14="ESPECES",0,0) -> 0 | E14: ECHEC | J14: =K14 -> 0 | K14: =+TONTNOV!F14+TONTNOV!G14 -> 0 | O14: =IF(P14=0,0,($C$36-P14)) -> 0
A15: AS201649 | B15: =VLOOKUP(A15,[1]LISTADHERENT!A$5:H$60,3,0) -> MBOGNING TUGMA GUY | C15: =IF(E15="ECHEC",0,IF(E15="",0,75000)) -> 0 | D15: =IF(E15="ESPECES",0,0) -> 0 | E15: ECHEC | J15: =K15 -> 0 | K15: =+TONTNOV!F15+TONTNOV!G15 -> 0 | O15: =IF(P15=0,0,($C$36-P15)) -> 0
A16: AS201649 | B16: =VLOOKUP(A16,[1]LISTADHERENT!A$5:H$60,3,0) -> MBOGNING TUGMA GUY | C16: =IF(E16="ECHEC",0,IF(E16="",0,75000)) -> 0 | D16: =IF(E16="ESPECES",0,0) -> 0 | E16: ECHEC | J16: =K16 -> 0 | K16: =+TONTNOV!F16+TONTNOV!G16 -> 0 | O16: =IF(P16=0,0,($C$36-P16)) -> 0
A17: AS201626 | B17: =VLOOKUP(A17,[1]LISTADHERENT!A$5:H$60,3,0) -> NGUIEMEGNI MATHIEU BLAISE | C17: =IF(E17="ECHEC",0,IF(E17="",0,75000)) -> 0 | D17: =IF(E17="ESPECES",0,0) -> 0 | E17: ECHEC | J17: =K17 -> 0 | K17: =+TONTNOV!F17+TONTNOV!G17 -> 0 | O17: =IF(P17=0,0,($C$36-P17)) -> 0
... A24: AS201647 | B24: =VLOOKUP(A24,[1]LISTADHERENT!A$5:H$60,3,0) -> YOUMBI EMMANUEL | C24: =IF(E24="ECHEC",0,IF(E24="",0,75000)) -> 0 | D24: =IF(E24="ESPECES",0,0) -> 0 | E24: ECHEC | J24: =K24 -> 0 | K24: =+TONTNOV!F24+TONTNOV!G24 -> 0 | O24: =IF(P24=0,0,($C$36-P24)) -> 0
A26: TOTAL | C26: =SUM(C6:C24) -> 0 | D26: =SUM(D6:D24) -> 0 | F26: =SUM(F6:F24) -> 0 | G26: =SUM(G6:G24) -> 0 | I26: =SUM(I6:I24) -> 0 | J26: =SUM(J6:J24) -> 0 | K26: =SUM(K6:K24) -> 0 | M26: =SUM(M6:M24) -> 0 | N26: =SUM(N6:N24) -> 0 | O26: =SUM(O6:O24) -> 0 | P26: =SUM(P6:P24) -> 0
C28: TONTINE | D28: REMBOURSEMENT PETIT LOT | E28: VENTE PETIT LOT | F28: VENTE LOT PRINCIPAL | G28: SOLDE EN CAISSE | I28: TONTINE + REMB + INTERET VENTE | J28: =(C33+D33+P26) -> 0
I29: VENTE LOT | J29: =IF(J28>=2000000,1200000*2,1200000) -> 1200000
B30: ESPECES | C30: =SUMIFS(C6:C24,E6:E24,"ESPECES") -> 0 | D30: =SUMIFS(J6:J24,L6:L24,"ESPECES") -> 0 | E30: =SUMIFS(F6:F24,H6:H24,"ESPECES") -> 0 | F30: =SUMIFS(M6:M24,L6:L24,"ESPECES") -> 0 | G30: =C30+D30-E30-F30 -> 0
B31: BANQUE | C31: =SUMIFS(C6:C24,E6:E24,"BANQUE") -> 0 | D31: =SUMIFS(J6:J24,L6:L24,"BANQUE") -> 0 | E31: =SUMIFS(F6:F24,H6:H24,"BANQUE") -> 0 | F31: =SUMIFS(M6:M24,L6:L24,"BANQUE") -> 0 | G31: =C31+D31-E31-F31 -> 0 | I31: PETIT LOT | J31: =IF(J28>0,J28-J29,0) -> 0
B33: TOTAL | C33: =C30+C31 -> 0 | D33: =D30+D31 -> 0 | E33: =E30+E31 -> 0 | F33: =F30+F31 -> 0 | G33: =G30+G31 -> 0 | I33: RESTE | J33: =J31-F26+TONTNOV!J33 -> -91500
B36: MONTANT TONTINE | C36: 1200000

Sheet TONTJANV
A1: ASSOCIATION | B1: ASELBY
A2: ANNEE | B2: 2019/2020
A3: TONTINE | B3: 75000
C4: 44213
A5: MATRICULE | B5: NOM ET PRENOM | C5: MONTANT TONTINE | D5: PENALITE | E5: MODE VERSEMENT TONTINE | F5: VENTE PETIT LOT | G5: INTERET PETIT LOT | H5: MODE VERSEMENT VENTE PETIT LOT | I5: NUMERO CHEQUE | J5: MONTANT REMBOURSE | K5: MONTANT A REMBOURSER | L5: MODE VERSEMENT REMBOURSEMENT | M5: MODE VERSEMENT TONTINE PRINCIPAL | N5: NUMERO CHEQUE | O5: MONTANT TONTINE LOT PRINCIPAL | P5: INTERET LOT PRINCIPAL
A6: AS201602 | B6: =VLOOKUP(A6,[1]LISTADHERENT!A$5:H$60,3,0) -> BOUTCHOUANG WILLIAM | C6: =IF(E6="ECHEC",0,IF(E6="",0,75000)) -> 0 | D6: =IF(E6="ESPECES",0,0) -> 0 | E6: ECHEC | J6: =K6 -> 0 | K6: =+TONTDEC!F6+TONTDEC!G6 -> 0 | O6: =IF(P6=0,0,($C$36-P6)) -> 0
A7: AS201603 | B7: =VLOOKUP(A7,[1]LISTADHERENT!A$5:H$60,3,0) -> CHINGUE FABRICE | C7: =IF(E7="ECHEC",0,IF(E7="",0,75000)) -> 0 | D7: =IF(E7="ESPECES",0,0) -> 0 | E7: ECHEC | J7: =K7 -> 0 | K7: =+TONTDEC!F7+TONTDEC!G7 -> 0 | O7: =IF(P7=0,0,($C$36-P7)) -> 0
A8: AS201604 | B8: =VLOOKUP(A8,[1]LISTADHERENT!A$5:H$60,3,0) -> DJOMO JEAN PAUL | C8: =IF(E8="ECHEC",0,IF(E8="",0,75000)) -> 0 | D8: =IF(E8="ESPECES",0,0) -> 0 | E8: ECHEC | J8: =K8 -> 0 | K8: =+TONTDEC!F8+TONTDEC!G8 -> 0 | O8: =IF(P8=0,0,($C$36-P8)) -> 0
A9: AS201605 | B9: =VLOOKUP(A9,[1]LISTADHERENT!A$5:H$60,3,0) -> DJOUKWE NANGUEN GUY BLAISE | C9: =IF(E9="ECHEC",0,IF(E9="",0,75000)) -> 0 | D9: =IF(E9="ESPECES",0,0) -> 0 | E9: ECHEC | J9: =K9 -> 0 | K9: =+TONTDEC!F9+TONTDEC!G9 -> 0 | O9: =IF(P9=0,0,($C$36-P9)) -> 0
A10: AS201613 | B10: =VLOOKUP(A10,[1]LISTADHERENT!A$5:H$60,3,0) -> HOTCHO BENJAMIN | C10: =IF(E10="ECHEC",0,IF(E10="",0,75000)) -> 0 | D10: =IF(E10="ESPECES",0,0) -> 0 | E10: ECHEC | J10: =K10 -> 0 | K10: =+TONTDEC!F10+TONTDEC!G10 -> 0 | O10: =IF(P10=0,0,($C$36-P10)) -> 0
A11: AS201611 | B11: =VLOOKUP(A11,[1]LISTADHERENT!A$5:H$60,3,0) -> HENGUE PAUL OMER | C11: =IF(E11="ECHEC",0,IF(E11="",0,75000)) -> 0 | D11: =IF(E11="ESPECES",0,0) -> 0 | E11: ECHEC | J11: =K11 -> 0 | K11: =+TONTDEC!F11+TONTDEC!G11 -> 0 | O11: =IF(P11=0,0,($C$36-P11)) -> 0
A12: AS201619 | B12: =VLOOKUP(A12,[1]LISTADHERENT!A$5:H$60,3,0) -> KOUATCHO MESSACK | C12: =IF(E12="ECHEC",0,IF(E12="",0,75000)) -> 0 | D12: =IF(E12="ESPECES",0,0) -> 0 | E12: ECHEC | J12: =K12 -> 0 | K12: =+TONTDEC!F12+TONTDEC!G12 -> 0 | O12: =IF(P12=0,0,($C$36-P12)) -> 0
A13: AS201621 | B13: =VLOOKUP(A13,[1]LISTADHERENT!A$5:H$60,3,0) -> NANKAM APPOLINAIRE | C13: =IF(E13="ECHEC",0,IF(E13="",0,75000)) -> 0 | D13: =IF(E13="ESPECES",0,0) -> 0 | E13: ECHEC | J13: =K13 -> 0 | K13: =+TONTDEC!F13+TONTDEC!G13 -> 0 | O13: =IF(P13=0,0,($C$36-P13)) -> 0
A14: AS201649 | B14: =VLOOKUP(A14,[1]LISTADHERENT!A$5:H$60,3,0) -> MBOGNING TUGMA GUY | C14: =IF(E14="ECHEC",0,IF(E14="",0,75000)) -> 0 | D14: =IF(E14="ESPECES",0,0) -> 0 | E14: ECHEC | J14: =K14 -> 0 | K14: =+TONTDEC!F14+TONTDEC!G14 -> 0 | O14: =IF(P14=0,0,($C$36-P14)) -> 0
A15: AS201649 | B15: =VLOOKUP(A15,[1]LISTADHERENT!A$5:H$60,3,0) -> MBOGNING TUGMA GUY | C15: =IF(E15="ECHEC",0,IF(E15="",0,75000)) -> 0 | D15: =IF(E15="ESPECES",0,0) -> 0 | E15: ECHEC | J15: =K15 -> 0 | K15: =+TONTDEC!F15+TONTDEC!G15 -> 0 | O15: =IF(P15=0,0,($C$36-P15)) -> 0
A16: AS201649 | B16: =VLOOKUP(A16,[1]LISTADHERENT!A$5:H$60,3,0) -> MBOGNING TUGMA GUY | C16: =IF(E16="ECHEC",0,IF(E16="",0,75000)) -> 0 | D16: =IF(E16="ESPECES",0,0) -> 0 | E16: ECHEC | J16: =K16 -> 0 | K16: =+TONTDEC!F16+TONTDEC!G16 -> 0 | O16: =IF(P16=0,0,($C$36-P16)) -> 0
A17: AS201626 | B17: =VLOOKUP(A17,[1]LISTADHERENT!A$5:H$60,3,0) -> NGUIEMEGNI MATHIEU BLAISE | C17: =IF(E17="ECHEC",0,IF(E17="",0,75000)) -> 0 | D17: =IF(E17="ESPECES",0,0) -> 0 | E17: ECHEC | J17: =K17 -> 0 | K17: =+TONTDEC!F17+TONTDEC!G17 -> 0 | O17: =IF(P17=0,0,($C$36-P17)) -> 0
... A24: AS201647 | B24: =VLOOKUP(A24,[1]LISTADHERENT!A$5:H$60,3,0) -> YOUMBI EMMANUEL | C24: =IF(E24="ECHEC",0,IF(E24="",0,75000)) -> 0 | D24: =IF(E24="ESPECES",0,0) -> 0 | E24: ECHEC | J24: =K24 -> 0 | K24: =+TONTDEC!F24+TONTDEC!G24 -> 0 | O24: =IF(P24=0,0,($C$36-P24)) -> 0
A26: TOTAL | C26: =SUM(C6:C24) -> 0 | D26: =SUM(D6:D24) -> 0 | F26: =SUM(F6:F24) -> 0 | G26: =SUM(G6:G24) -> 0 | I26: =SUM(I6:I24) -> 0 | J26: =SUM(J6:J24) -> 0 | K26: =SUM(K6:K24) -> 0 | M26: =SUM(M6:M24) -> 0 | N26: =SUM(N6:N24) -> 0 | O26: =SUM(O6:O24) -> 0 | P26: =SUM(P6:P24) -> 0
C28: TONTINE | D28: REMBOURSEMENT PETIT LOT | E28: VENTE PETIT LOT | F28: VENTE LOT PRINCIPAL | G28: SOLDE EN CAISSE | I28: TONTINE + REMB + INTERET VENTE | J28: =(C33+D33+P26) -> 0
I29: VENTE LOT | J29: =IF(J28>=2000000,1200000*2,1200000) -> 1200000
B30: ESPECES | C30: =SUMIFS(C6:C24,E6:E24,"ESPECES") -> 0 | D30: =SUMIFS(J6:J24,L6:L24,"ESPECES") -> 0 | E30: =SUMIFS(F6:F24,H6:H24,"ESPECES") -> 0 | F30: =SUMIFS(M6:M24,L6:L24,"ESPECES") -> 0 | G30: =C30+D30-E30-F30 -> 0
B31: BANQUE | C31: =SUMIFS(C6:C24,E6:E24,"BANQUE") -> 0 | D31: =SUMIFS(J6:J24,L6:L24,"BANQUE") -> 0 | E31: =SUMIFS(F6:F24,H6:H24,"BANQUE") -> 0 | F31: =SUMIFS(M6:M24,L6:L24,"BANQUE") -> 0 | G31: =C31+D31-E31-F31 -> 0 | I31: PETIT LOT | J31: =IF(J28>0,J28-J29,0) -> 0
B33: TOTAL | C33: =C30+C31 -> 0 | D33: =D30+D31 -> 0 | E33: =E30+E31 -> 0 | F33: =F30+F31 -> 0 | G33: =G30+G31 -> 0 | I33: RESTE | J33: =J31-F26+TONTDEC!J33 -> -91500
B36: MONTANT TONTINE | C36: 1200000

Sheet TONTFEV
A1: ASSOCIATION | B1: ASELBY
A2: ANNEE | B2: 2019/2020
A3: TONTINE | B3: 75000
C4: 44248
A5: MATRICULE | B5: NOM ET PRENOM | C5: MONTANT TONTINE | D5: PENALITE | E5: MODE VERSEMENT TONTINE | F5: VENTE PETIT LOT | G5: INTERET PETIT LOT | H5: MODE VERSEMENT VENTE PETIT LOT | I5: NUMERO CHEQUE | J5: MONTANT REMBOURSE | K5: MONTANT A REMBOURSER | L5: MODE VERSEMENT REMBOURSEMENT | M5: MODE VERSEMENT TONTINE PRINCIPAL | N5: NUMERO CHEQUE | O5: MONTANT TONTINE LOT PRINCIPAL | P5: INTERET LOT PRINCIPAL
A6: AS201602 | B6: =VLOOKUP(A6,[1]LISTADHERENT!A$5:H$60,3,0) -> BOUTCHOUANG WILLIAM | C6: =IF(E6="ECHEC",0,IF(E6="",0,75000)) -> 0 | D6: =IF(E6="ESPECES",0,0) -> 0 | E6: ECHEC | J6: =K6 -> 0 | K6: =+TONTJANV!F6+TONTJANV!G6 -> 0 | O6: =IF(P6=0,0,($C$36-P6)) -> 0
A7: AS201603 | B7: =VLOOKUP(A7,[1]LISTADHERENT!A$5:H$60,3,0) -> CHINGUE FABRICE | C7: =IF(E7="ECHEC",0,IF(E7="",0,75000)) -> 0 | D7: =IF(E7="ESPECES",0,0) -> 0 | E7: ECHEC | J7: =K7 -> 0 | K7: =+TONTJANV!F7+TONTJANV!G7 -> 0 | O7: =IF(P7=0,0,($C$36-P7)) -> 0
A8: AS201604 | B8: =VLOOKUP(A8,[1]LISTADHERENT!A$5:H$60,3,0) -> DJOMO JEAN PAUL | C8: =IF(E8="ECHEC",0,IF(E8="",0,75000)) -> 0 | D8: =IF(E8="ESPECES",0,0) -> 0 | E8: ECHEC | J8: =K8 -> 0 | K8: =+TONTJANV!F8+TONTJANV!G8 -> 0 | O8: =IF(P8=0,0,($C$36-P8)) -> 0
A9: AS201605 | B9: =VLOOKUP(A9,[1]LISTADHERENT!A$5:H$60,3,0) -> DJOUKWE NANGUEN GUY BLAISE | C9: =IF(E9="ECHEC",0,IF(E9="",0,75000)) -> 0 | D9: =IF(E9="ESPECES",0,0) -> 0 | E9: ECHEC | J9: =K9 -> 0 | K9: =+TONTJANV!F9+TONTJANV!G9 -> 0 | O9: =IF(P9=0,0,($C$36-P9)) -> 0
A10: AS201613 | B10: =VLOOKUP(A10,[1]LISTADHERENT!A$5:H$60,3,0) -> HOTCHO BENJAMIN | C10: =IF(E10="ECHEC",0,IF(E10="",0,75000)) -> 0 | D10: =IF(E10="ESPECES",0,0) -> 0 | E10: ECHEC | J10: =K10 -> 0 | K10: =+TONTJANV!F10+TONTJANV!G10 -> 0 | O10: =IF(P10=0,0,($C$36-P10)) -> 0
A11: AS201611 | B11: =VLOOKUP(A11,[1]LISTADHERENT!A$5:H$60,3,0) -> HENGUE PAUL OMER | C11: =IF(E11="ECHEC",0,IF(E11="",0,75000)) -> 0 | D11: =IF(E11="ESPECES",0,0) -> 0 | E11: ECHEC | J11: =K11 -> 0 | K11: =+TONTJANV!F11+TONTJANV!G11 -> 0 | O11: =IF(P11=0,0,($C$36-P11)) -> 0
A12: AS201619 | B12: =VLOOKUP(A12,[1]LISTADHERENT!A$5:H$60,3,0) -> KOUATCHO MESSACK | C12: =IF(E12="ECHEC",0,IF(E12="",0,75000)) -> 0 | D12: =IF(E12="ESPECES",0,0) -> 0 | E12: ECHEC | J12: =K12 -> 0 | K12: =+TONTJANV!F12+TONTJANV!G12 -> 0 | O12: =IF(P12=0,0,($C$36-P12)) -> 0
A13: AS201621 | B13: =VLOOKUP(A13,[1]LISTADHERENT!A$5:H$60,3,0) -> NANKAM APPOLINAIRE | C13: =IF(E13="ECHEC",0,IF(E13="",0,75000)) -> 0 | D13: =IF(E13="ESPECES",0,0) -> 0 | E13: ECHEC | J13: =K13 -> 0 | K13: =+TONTJANV!F13+TONTJANV!G13 -> 0 | O13: =IF(P13=0,0,($C$36-P13)) -> 0
A14: AS201649 | B14: =VLOOKUP(A14,[1]LISTADHERENT!A$5:H$60,3,0) -> MBOGNING TUGMA GUY | C14: =IF(E14="ECHEC",0,IF(E14="",0,75000)) -> 0 | D14: =IF(E14="ESPECES",0,0) -> 0 | E14: ECHEC | J14: =K14 -> 0 | K14: =+TONTJANV!F14+TONTJANV!G14 -> 0 | O14: =IF(P14=0,0,($C$36-P14)) -> 0
A15: AS201649 | B15: =VLOOKUP(A15,[1]LISTADHERENT!A$5:H$60,3,0) -> MBOGNING TUGMA GUY | C15: =IF(E15="ECHEC",0,IF(E15="",0,75000)) -> 0 | D15: =IF(E15="ESPECES",0,0) -> 0 | E15: ECHEC | J15: =K15 -> 0 | K15: =+TONTJANV!F15+TONTJANV!G15 -> 0 | O15: =IF(P15=0,0,($C$36-P15)) -> 0
A16: AS201649 | B16: =VLOOKUP(A16,[1]LISTADHERENT!A$5:H$60,3,0) -> MBOGNING TUGMA GUY | C16: =IF(E16="ECHEC",0,IF(E16="",0,75000)) -> 0 | D16: =IF(E16="ESPECES",0,0) -> 0 | E16: ECHEC | J16: =K16 -> 0 | K16: =+TONTJANV!F16+TONTJANV!G16 -> 0 | O16: =IF(P16=0,0,($C$36-P16)) -> 0
A17: AS201626 | B17: =VLOOKUP(A17,[1]LISTADHERENT!A$5:H$60,3,0) -> NGUIEMEGNI MATHIEU BLAISE | C17: =IF(E17="ECHEC",0,IF(E17="",0,75000)) -> 0 | D17: =IF(E17="ESPECES",0,0) -> 0 | E17: ECHEC | J17: =K17 -> 0 | K17: =+TONTJANV!F17+TONTJANV!G17 -> 0 | O17: =IF(P17=0,0,($C$36-P17)) -> 0
... A24: AS201647 | B24: =VLOOKUP(A24,[1]LISTADHERENT!A$5:H$60,3,0) -> YOUMBI EMMANUEL | C24: =IF(E24="ECHEC",0,IF(E24="",0,75000)) -> 0 | D24: =IF(E24="ESPECES",0,0) -> 0 | E24: ECHEC | J24: =K24 -> 0 | K24: =+TONTJANV!F24+TONTJANV!G24 -> 0 | O24: =IF(P24=0,0,($C$36-P24)) -> 0
A26: TOTAL | C26: =SUM(C6:C24) -> 0 | D26: =SUM(D6:D24) -> 0 | F26: =SUM(F6:F24) -> 0 | G26: =SUM(G6:G24) -> 0 | I26: =SUM(I6:I24) -> 0 | J26: =SUM(J6:J24) -> 0 | K26: =SUM(K6:K24) -> 0 | M26: =SUM(M6:M24) -> 0 | N26: =SUM(N6:N24) -> 0 | O26: =SUM(O6:O24) -> 0 | P26: =SUM(P6:P24) -> 0
C28: TONTINE | D28: REMBOURSEMENT PETIT LOT | E28: VENTE PETIT LOT | F28: VENTE LOT PRINCIPAL | G28: SOLDE EN CAISSE | I28: TONTINE + REMB + INTERET VENTE | J28: =(C33+D33+P26) -> 0
I29: VENTE LOT | J29: =IF(J28>=2000000,1200000*2,1200000) -> 1200000
B30: ESPECES | C30: =SUMIFS(C6:C24,E6:E24,"ESPECES") -> 0 | D30: =SUMIFS(J6:J24,L6:L24,"ESPECES") -> 0 | E30: =SUMIFS(F6:F24,H6:H24,"ESPECES") -> 0 | F30: =SUMIFS(M6:M24,L6:L24,"ESPECES") -> 0 | G30: =C30+D30-E30-F30 -> 0
B31: BANQUE | C31: =SUMIFS(C6:C24,E6:E24,"BANQUE") -> 0 | D31: =SUMIFS(J6:J24,L6:L24,"BANQUE") -> 0 | E31: =SUMIFS(F6:F24,H6:H24,"BANQUE") -> 0 | F31: =SUMIFS(M6:M24,L6:L24,"BANQUE") -> 0 | G31: =C31+D31-E31-F31 -> 0 | I31: PETIT LOT | J31: =IF(J28>0,J28-J29,0) -> 0
B33: TOTAL | C33: =C30+C31 -> 0 | D33: =D30+D31 -> 0 | E33: =E30+E31 -> 0 | F33: =F30+F31 -> 0 | G33: =G30+G31 -> 0 | I33: RESTE | J33: =J31-F26+TONTJANV!J33 -> -91500
B36: MONTANT TONTINE | C36: 1200000

Sheet TONTMARS
A1: ASSOCIATION | B1: ASELBY
A2: ANNEE | B2: 2019/2020
A3: TONTINE | B3: 75000
C4: 44276
A5: MATRICULE | B5: NOM ET PRENOM | C5: MONTANT TONTINE | D5: PENALITE | E5: MODE VERSEMENT TONTINE | F5: VENTE PETIT LOT | G5: INTERET PETIT LOT | H5: MODE VERSEMENT VENTE PETIT LOT | I5: NUMERO CHEQUE | J5: MONTANT REMBOURSE | K5: MONTANT A REMBOURSER | L5: MODE VERSEMENT REMBOURSEMENT | M5: MODE VERSEMENT TONTINE PRINCIPAL | N5: NUMERO CHEQUE | O5: MONTANT TONTINE LOT PRINCIPAL | P5: INTERET LOT PRINCIPAL
A6: AS201602 | B6: =VLOOKUP(A6,[1]LISTADHERENT!A$5:H$60,3,0) -> BOUTCHOUANG WILLIAM | C6: =IF(E6="ECHEC",0,IF(E6="",0,75000)) -> 0 | D6: =IF(E6="ESPECES",0,0) -> 0 | E6: ECHEC | J6: =K6 -> 0 | K6: =+TONTFEV!F6+TONTFEV!G6 -> 0 | O6: =IF(P6=0,0,($C$36-P6)) -> 0
A7: AS201603 | B7: =VLOOKUP(A7,[1]LISTADHERENT!A$5:H$60,3,0) -> CHINGUE FABRICE | C7: =IF(E7="ECHEC",0,IF(E7="",0,75000)) -> 0 | D7: =IF(E7="ESPECES",0,0) -> 0 | E7: ECHEC | J7: =K7 -> 0 | K7: =+TONTFEV!F7+TONTFEV!G7 -> 0 | O7: =IF(P7=0,0,($C$36-P7)) -> 0
A8: AS201604 | B8: =VLOOKUP(A8,[1]LISTADHERENT!A$5:H$60,3,0) -> DJOMO JEAN PAUL | C8: =IF(E8="ECHEC",0,IF(E8="",0,75000)) -> 0 | D8: =IF(E8="ESPECES",0,0) -> 0 | E8: ECHEC | J8: =K8 -> 0 | K8: =+TONTFEV!F8+TONTFEV!G8 -> 0 | O8: =IF(P8=0,0,($C$36-P8)) -> 0
A9: AS201605 | B9: =VLOOKUP(A9,[1]LISTADHERENT!A$5:H$60,3,0) -> DJOUKWE NANGUEN GUY BLAISE | C9: =IF(E9="ECHEC",0,IF(E9="",0,75000)) -> 0 | D9: =IF(E9="ESPECES",0,0) -> 0 | E9: ECHEC | J9: =K9 -> 0 | K9: =+TONTFEV!F9+TONTFEV!G9 -> 0 | O9: =IF(P9=0,0,($C$36-P9)) -> 0
A10: AS201613 | B10: =VLOOKUP(A10,[1]LISTADHERENT!A$5:H$60,3,0) -> HOTCHO BENJAMIN | C10: =IF(E10="ECHEC",0,IF(E10="",0,75000)) -> 0 | D10: =IF(E10="ESPECES",0,0) -> 0 | E10: ECHEC | J10: =K10 -> 0 | K10: =+TONTFEV!F10+TONTFEV!G10 -> 0 | O10: =IF(P10=0,0,($C$36-P10)) -> 0
A11: AS201611 | B11: =VLOOKUP(A11,[1]LISTADHERENT!A$5:H$60,3,0) -> HENGUE PAUL OMER | C11: =IF(E11="ECHEC",0,IF(E11="",0,75000)) -> 0 | D11: =IF(E11="ESPECES",0,0) -> 0 | E11: ECHEC | J11: =K11 -> 0 | K11: =+TONTFEV!F11+TONTFEV!G11 -> 0 | O11: =IF(P11=0,0,($C$36-P11)) -> 0
A12: AS201619 | B12: =VLOOKUP(A12,[1]LISTADHERENT!A$5:H$60,3,0) -> KOUATCHO MESSACK | C12: =IF(E12="ECHEC",0,IF(E12="",0,75000)) -> 0 | D12: =IF(E12="ESPECES",0,0) -> 0 | E12: ECHEC | J12: =K12 -> 0 | K12: =+TONTFEV!F12+TONTFEV!G12 -> 0 | O12: =IF(P12=0,0,($C$36-P12)) -> 0
A13: AS201621 | B13: =VLOOKUP(A13,[1]LISTADHERENT!A$5:H$60,3,0) -> NANKAM APPOLINAIRE | C13: =IF(E13="ECHEC",0,IF(E13="",0,75000)) -> 0 | D13: =IF(E13="ESPECES",0,0) -> 0 | E13: ECHEC | J13: =K13 -> 0 | K13: =+TONTFEV!F13+TONTFEV!G13 -> 0 | O13: =IF(P13=0,0,($C$36-P13)) -> 0
A14: AS201649 | B14: =VLOOKUP(A14,[1]LISTADHERENT!A$5:H$60,3,0) -> MBOGNING TUGMA GUY | C14: =IF(E14="ECHEC",0,IF(E14="",0,75000)) -> 0 | D14: =IF(E14="ESPECES",0,0) -> 0 | E14: ECHEC | J14: =K14 -> 0 | K14: =+TONTFEV!F14+TONTFEV!G14 -> 0 | O14: =IF(P14=0,0,($C$36-P14)) -> 0
A15: AS201649 | B15: =VLOOKUP(A15,[1]LISTADHERENT!A$5:H$60,3,0) -> MBOGNING TUGMA GUY | C15: =IF(E15="ECHEC",0,IF(E15="",0,75000)) -> 0 | D15: =IF(E15="ESPECES",0,0) -> 0 | E15: ECHEC | J15: =K15 -> 0 | K15: =+TONTFEV!F15+TONTFEV!G15 -> 0 | O15: =IF(P15=0,0,($C$36-P15)) -> 0
A16: AS201649 | B16: =VLOOKUP(A16,[1]LISTADHERENT!A$5:H$60,3,0) -> MBOGNING TUGMA GUY | C16: =IF(E16="ECHEC",0,IF(E16="",0,75000)) -> 0 | D16: =IF(E16="ESPECES",0,0) -> 0 | E16: ECHEC | J16: =K16 -> 0 | K16: =+TONTFEV!F16+TONTFEV!G16 -> 0 | O16: =IF(P16=0,0,($C$36-P16)) -> 0
A17: AS201626 | B17: =VLOOKUP(A17,[1]LISTADHERENT!A$5:H$60,3,0) -> NGUIEMEGNI MATHIEU BLAISE | C17: =IF(E17="ECHEC",0,IF(E17="",0,75000)) -> 0 | D17: =IF(E17="ESPECES",0,0) -> 0 | E17: ECHEC | J17: =K17 -> 0 | K17: =+TONTFEV!F17+TONTFEV!G17 -> 0 | O17: =IF(P17=0,0,($C$36-P17)) -> 0
... A24: AS201647 | B24: =VLOOKUP(A24,[1]LISTADHERENT!A$5:H$60,3,0) -> YOUMBI EMMANUEL | C24: =IF(E24="ECHEC",0,IF(E24="",0,75000)) -> 0 | D24: =IF(E24="ESPECES",0,0) -> 0 | E24: ECHEC | J24: =K24 -> 0 | K24: =+TONTFEV!F24+TONTFEV!G24 -> 0 | O24: =IF(P24=0,0,($C$36-P24)) -> 0
A26: TOTAL | C26: =SUM(C6:C24) -> 0 | D26: =SUM(D6:D24) -> 0 | F26: =SUM(F6:F24) -> 0 | G26: =SUM(G6:G24) -> 0 | I26: =SUM(I6:I24) -> 0 | J26: =SUM(J6:J24) -> 0 | K26: =SUM(K6:K24) -> 0 | M26: =SUM(M6:M24) -> 0 | N26: =SUM(N6:N24) -> 0 | O26: =SUM(O6:O24) -> 0 | P26: =SUM(P6:P24) -> 0
C28: TONTINE | D28: REMBOURSEMENT PETIT LOT | E28: VENTE PETIT LOT | F28: VENTE LOT PRINCIPAL | G28: SOLDE EN CAISSE | I28: TONTINE + REMB + INTERET VENTE | J28: =(C33+D33+P26) -> 0
I29: VENTE LOT | J29: =IF(J28>=2000000,1200000*2,1200000) -> 1200000
B30: ESPECES | C30: =SUMIFS(C6:C24,E6:E24,"ESPECES") -> 0 | D30: =SUMIFS(J6:J24,L6:L24,"ESPECES") -> 0 | E30: =SUMIFS(F6:F24,H6:H24,"ESPECES") -> 0 | F30: =SUMIFS(M6:M24,L6:L24,"ESPECES") -> 0 | G30: =C30+D30-E30-F30 -> 0
B31: BANQUE | C31: =SUMIFS(C6:C24,E6:E24,"BANQUE") -> 0 | D31: =SUMIFS(J6:J24,L6:L24,"BANQUE") -> 0 | E31: =SUMIFS(F6:F24,H6:H24,"BANQUE") -> 0 | F31: =SUMIFS(M6:M24,L6:L24,"BANQUE") -> 0 | G31: =C31+D31-E31-F31 -> 0 | I31: PETIT LOT | J31: =IF(J28>0,J28-J29,0) -> 0
B33: TOTAL | C33: =C30+C31 -> 0 | D33: =D30+D31 -> 0 | E33: =E30+E31 -> 0 | F33: =F30+F31 -> 0 | G33: =G30+G31 -> 0 | I33: RESTE | J33: =J31-F26+TONTFEV!J33 -> -91500
B36: MONTANT TONTINE | C36: 1200000

Sheet TONTAVRIL
A1: ASSOCIATION | B1: ASELBY
A2: ANNEE | B2: 2019/2020
A3: TONTINE | B3: 75000
C4: 44304
A5: MATRICULE | B5: NOM ET PRENOM | C5: MONTANT TONTINE | D5: PENALITE | E5: MODE VERSEMENT TONTINE | F5: VENTE PETIT LOT | G5: INTERET PETIT LOT | H5: MODE VERSEMENT VENTE PETIT LOT | I5: NUMERO CHEQUE | J5: MONTANT REMBOURSE | K5: MONTANT A REMBOURSER | L5: MODE VERSEMENT REMBOURSEMENT | M5: MODE VERSEMENT TONTINE PRINCIPAL | N5: NUMERO CHEQUE | O5: MONTANT TONTINE LOT PRINCIPAL | P5: INTERET LOT PRINCIPAL
A6: AS201602 | B6: =VLOOKUP(A6,[1]LISTADHERENT!A$5:H$60,3,0) -> BOUTCHOUANG WILLIAM | C6: =IF(E6="ECHEC",0,IF(E6="",0,75000)) -> 0 | D6: =IF(E6="ESPECES",0,0) -> 0 | E6: ECHEC | J6: =K6 -> 0 | K6: =+TONTMARS!F6+TONTMARS!G6 -> 0 | O6: =IF(P6=0,0,($C$36-P6)) -> 0
A7: AS201603 | B7: =VLOOKUP(A7,[1]LISTADHERENT!A$5:H$60,3,0) -> CHINGUE FABRICE | C7: =IF(E7="ECHEC",0,IF(E7="",0,75000)) -> 0 | D7: =IF(E7="ESPECES",0,0) -> 0 | E7: ECHEC | J7: =K7 -> 0 | K7: =+TONTMARS!F7+TONTMARS!G7 -> 0 | O7: =IF(P7=0,0,($C$36-P7)) -> 0
A8: AS201604 | B8: =VLOOKUP(A8,[1]LISTADHERENT!A$5:H$60,3,0) -> DJOMO JEAN PAUL | C8: =IF(E8="ECHEC",0,IF(E8="",0,75000)) -> 0 | D8: =IF(E8="ESPECES",0,0) -> 0 | E8: ECHEC | J8: =K8 -> 0 | K8: =+TONTMARS!F8+TONTMARS!G8 -> 0 | O8: =IF(P8=0,0,($C$36-P8)) -> 0
A9: AS201605 | B9: =VLOOKUP(A9,[1]LISTADHERENT!A$5:H$60,3,0) -> DJOUKWE NANGUEN GUY BLAISE | C9: =IF(E9="ECHEC",0,IF(E9="",0,75000)) -> 0 | D9: =IF(E9="ESPECES",0,0) -> 0 | E9: ECHEC | J9: =K9 -> 0 | K9: =+TONTMARS!F9+TONTMARS!G9 -> 0 | O9: =IF(P9=0,0,($C$36-P9)) -> 0
A10: AS201613 | B10: =VLOOKUP(A10,[1]LISTADHERENT!A$5:H$60,3,0) -> HOTCHO BENJAMIN | C10: =IF(E10="ECHEC",0,IF(E10="",0,75000)) -> 0 | D10: =IF(E10="ESPECES",0,0) -> 0 | E10: ECHEC | J10: =K10 -> 0 | K10: =+TONTMARS!F10+TONTMARS!G10 -> 0 | O10: =IF(P10=0,0,($C$36-P10)) -> 0
A11: AS201611 | B11: =VLOOKUP(A11,[1]LISTADHERENT!A$5:H$60,3,0) -> HENGUE PAUL OMER | C11: =IF(E11="ECHEC",0,IF(E11="",0,75000)) -> 0 | D11: =IF(E11="ESPECES",0,0) -> 0 | E11: ECHEC | J11: =K11 -> 0 | K11: =+TONTMARS!F11+TONTMARS!G11 -> 0 | O11: =IF(P11=0,0,($C$36-P11)) -> 0
A12: AS201619 | B12: =VLOOKUP(A12,[1]LISTADHERENT!A$5:H$60,3,0) -> KOUATCHO MESSACK | C12: =IF(E12="ECHEC",0,IF(E12="",0,75000)) -> 0 | D12: =IF(E12="ESPECES",0,0) -> 0 | E12: ECHEC | J12: =K12 -> 0 | K12: =+TONTMARS!F12+TONTMARS!G12 -> 0 | O12: =IF(P12=0,0,($C$36-P12)) -> 0
A13: AS201621 | B13: =VLOOKUP(A13,[1]LISTADHERENT!A$5:H$60,3,0) -> NANKAM APPOLINAIRE | C13: =IF(E13="ECHEC",0,IF(E13="",0,75000)) -> 0 | D13: =IF(E13="ESPECES",0,0) -> 0 | E13: ECHEC | J13: =K13 -> 0 | K13: =+TONTMARS!F13+TONTMARS!G13 -> 0 | O13: =IF(P13=0,0,($C$36-P13)) -> 0
A14: AS201649 | B14: =VLOOKUP(A14,[1]LISTADHERENT!A$5:H$60,3,0) -> MBOGNING TUGMA GUY | C14: =IF(E14="ECHEC",0,IF(E14="",0,75000)) -> 0 | D14: =IF(E14="ESPECES",0,0) -> 0 | E14: ECHEC | J14: =K14 -> 0 | K14: =+TONTMARS!F14+TONTMARS!G14 -> 0 | O14: =IF(P14=0,0,($C$36-P14)) -> 0
A15: AS201649 | B15: =VLOOKUP(A15,[1]LISTADHERENT!A$5:H$60,3,0) -> MBOGNING TUGMA GUY | C15: =IF(E15="ECHEC",0,IF(E15="",0,75000)) -> 0 | D15: =IF(E15="ESPECES",0,0) -> 0 | E15: ECHEC | J15: =K15 -> 0 | K15: =+TONTMARS!F15+TONTMARS!G15 -> 0 | O15: =IF(P15=0,0,($C$36-P15)) -> 0
A16: AS201649 | B16: =VLOOKUP(A16,[1]LISTADHERENT!A$5:H$60,3,0) -> MBOGNING TUGMA GUY | C16: =IF(E16="ECHEC",0,IF(E16="",0,75000)) -> 0 | D16: =IF(E16="ESPECES",0,0) -> 0 | E16: ECHEC | J16: =K16 -> 0 | K16: =+TONTMARS!F16+TONTMARS!G16 -> 0 | O16: =IF(P16=0,0,($C$36-P16)) -> 0
A17: AS201626 | B17: =VLOOKUP(A17,[1]LISTADHERENT!A$5:H$60,3,0) -> NGUIEMEGNI MATHIEU BLAISE | C17: =IF(E17="ECHEC",0,IF(E17="",0,75000)) -> 0 | D17: =IF(E17="ESPECES",0,0) -> 0 | E17: ECHEC | J17: =K17 -> 0 | K17: =+TONTMARS!F17+TONTMARS!G17 -> 0 | O17: =IF(P17=0,0,($C$36-P17)) -> 0
... A24: AS201647 | B24: =VLOOKUP(A24,[1]LISTADHERENT!A$5:H$60,3,0) -> YOUMBI EMMANUEL | C24: =IF(E24="ECHEC",0,IF(E24="",0,75000)) -> 0 | D24: =IF(E24="ESPECES",0,0) -> 0 | E24: ECHEC | J24: =K24 -> 0 | K24: =+TONTMARS!F24+TONTMARS!G24 -> 0 | O24: =IF(P24=0,0,($C$36-P24)) -> 0
A26: TOTAL | C26: =SUM(C6:C24) -> 0 | D26: =SUM(D6:D24) -> 0 | F26: =SUM(F6:F24) -> 0 | G26: =SUM(G6:G24) -> 0 | I26: =SUM(I6:I24) -> 0 | J26: =SUM(J6:J24) -> 0 | K26: =SUM(K6:K24) -> 0 | M26: =SUM(M6:M24) -> 0 | N26: =SUM(N6:N24) -> 0 | O26: =SUM(O6:O24) -> 0 | P26: =SUM(P6:P24) -> 0
