Workbook
Name BANQUE: #REF!
Name BANQUE: #REF!
Name BANQUE: #REF!
Name BANQUE: #REF!
Name BANQUE: #REF!
Name BANQUE: #REF!
Name BANQUE: #REF!
Name BANQUE: #REF!
Name BANQUE: #REF!
Name BANQUE: #REF!
Name BANQUE: #REF!
Name BANQUE: #REF!
Name BANQUE: #REF!
Name BANQUE: #REF!
Name BANQUE: #REF!
Name MODEPAID: [1]Feuil2!$A$1:$A$3
Name MODEVERSEMENT: #REF!
Name MODEVERSEMENT: #REF!
Name MODEVERSEMENT: #REF!
Name MODEVERSEMENT: #REF!
Name MODEVERSEMENT: #REF!
Name MODEVERSEMENT: #REF!
Name MODEVERSEMENT: #REF!
Name MODEVERSEMENT: #REF!
Name MODEVERSEMENT: #REF!
Name MODEVERSEMENT: #REF!
Name MODEVERSEMENT: #REF!
Name MODEVERSEMENT: #REF!
Name MODEVERSEMENT: #REF!
Name MODEVERSEMENT: #REF!
Name MODEVERSEMENT: #REF!
Name MODEVERSEMENTS: MODEVERSEMENT!$A$1:$A$3
Name MODPAID: TONT20000ANNUELLE!$H$5
Name MODPAID: TONT20000ANNUELLEBACKUP!$H$5
Name MODPAID: TONT20000AOUT2017!$H$5
Name MODPAID: TONT20000AVRIL2017!$H$5
Name MODPAID: TONT20000FEV2017!$H$5
Name MODPAID: TONT20000JANV2017!$H$5
Name MODPAID: TONT20000JUIL2017!$H$5
Name MODPAID: TONT20000JUIN2017!$H$5
Name MODPAID: TONT20000MAI2017!$H$5
Name MODPAID: TONT20000MARS2017!$H$5
Name MODPAID: TONT20000NOV2017!$H$5
Name MODPAID: TONT20000OCT2017!$H$5
Name MODPAID: TONT20000SEPT2017!$H$5
Name MODPAID: TONTINVENTFINAOUT2017!#REF!
Name MODPAID: TONT20000DEC2016!$J$5

Sheet LISTADHERENT
A1: ASELBY
A2: LISTE DES ADHERENTS 19 JUN 2016
A4: MLE | B4: NOM ET PRENOM | C4: FONCTION | D4: DATE ADHESION | E4: CONTACT | F4: CONTACT 2 | G4: RESIDENCE | H4: DATE RECEPTION
A5: AS201601 | B5: BAKOP ACHILLE | C5: FONCTIONNAIRE DE POLICE | E5: 677841881 | G5: NKOLBISSON | H5: 42887
A6: AS201602 | B6: BOUTCHOUANG WILLIAM | C6: OPERATEUR ECONOMIQUE | E6: 677704694 | G6: EMANA | H6: 43191
A7: AS201603 | B7: CHINGUE FABRICE | C7: OPERATEUR ECONOMIQUE | E7: 677881912 | G7: SANTA BARBARA | H7: 43466
A8: AS201604 | B8: DJOMO JEAN PAUL | C8: RETRAITE | E8: 677986676 | G8: RUE MANGUIERS | H8: 43132
A9: AS201605 | B9: DJOUKWE NANGUEN GUY BLAISE | C9: PROFESSEUR DES LYCEES TECHNIQUE | E9: 675250451 | G9: RUE MANGUIERS | H9: 43313
A10: AS201606 | B10: DJOSSEU JOSUE | C10: PROFESSEUR DES LYCEES TECHNIQUE | E10: 675250451 | G10: RUE MANGUIERS | H10: 43313
A11: AS201607 | B11: DJOUNKEP SAMUEL | C11: COMPTABLE RETRAITE | E11: 697103557 | G11: BIYEM ASSI LYCEE | H11: 42401
A12: AS201608 | B12: DJUOMBESSY ANTOINE | C12: ANALYSTE CONCEPTEUR SI | E12: 677501239 | F12: 699324095 | G12: MESSASSI | H12: 43647
A13: AS201609 | B13: DONHOU DAVID | C13: MAGISTRAT | E13: 699908065 | G13: TONGOLO | H13: 42979
A14: AS201610 | B14: FOTSO THOMAS | C14: CADRE BANQUE | E14: 677910278 | G14: OYOMABANG | H14: 43344
A15: AS201611 | B15: HENGUE PAUL OMER | C15: SOCIOLOGUE | E15: 694468080 | G15: MESSASSI | H15: 42583
A16: AS201612 | B16: HODIEP JULES | C16: CADRE CNPS | E16: 675291170 | G16: NYOM 2 | H16: 43009
A17: AS201613 | B17: HOTCHO BENJAMIN | C17: COMPTABLE | E17: 699956355 | G17: DAMAS | H17: 42614
A18: AS201614 | B18: KEPHE DAVID | C18: OPERATEUR ECONOMIQUE | E18: 677053815 | G18: MESSASSI | H18: 43374
A19: AS201615 | B19: KEPSEU FRANCIS | C19: OFFICIER DE POLICE RETRAITE | E19: 699528700 | G19: SIMBOCK | H19: 43405
A20: AS201616 | B20: KOUAMOU EMMANUEL | C20: OPERATEUR ECONOMIQUE | E20: 699335584 | G20: MONTEE JOUVENCE | H20: 42795
A21: AS201617 | B21: KOUAMOU MOISE | C21: INGENIEUR E-F | E21: 675836725 | G21: DAMAS | H21: 42370
A22: AS201618 | B22: KOUAMO VICTOR PEGUY | C22: S/OFFICIER SUPERIEUR | E22: 696564847 | G22: MESSASSI | H22: 43617
A23: AS201619 | B23: KOUATCHO MESSACK | C23: INSPECTEUR DE TRAVAIL | E23: 677735778 | G23: SANTA BARBARA | H23: 42644
A24: AS201620 | B24: LOWE JEAN | C24: PROFESSEUR DE LYCEE
A25: AS201621 | B25: NANKAM APPOLINAIRE | C25: ENSEIGNANT | E25: 693055118 | G25: DAMAS | H25: 43678
A26: AS201622 | B26: NDJOMO ETIENNE | C26: COMPTABLE | E26: 677553702 | G26: MONTEE JOUVENCE | H26: 42705
A27: AS201623 | B27: NDOMBOU JEAN CLAUDE | C27: ING AGRONOME RETRAITE | E27: 699358350 | G27: ETOUG EBE | H27: 42767
A28: AS201624 | B28: NGONDIEP CLAUDE | C28: DAS(DIRECTEUR ADMINISTRATEUR SOCIETE) | E28: 675249207 | G28: CITE VERTE | H28: 43070
A29: AS201625 | B29: NGONGANG JEAN THEODORE | C29: CHEF ENTREPRISE | E29: 677766503 | G29: RUE MANGUIERS | H29: 42491
A30: AS201626 | B30: NGUIEMEGNI MATHIEU BLAISE | C30: CADRE CADASTRE | E30: 677068360 | G30: MONATELE | H30: 43101
A31: AS201627 | B31: NJEPDJIO MBOUKAM DELUXE | C31: OPERATEUR ECONOMIQUE | E31: 670909070 | G31: MENDONG | H31: 43586
A32: AS201628 | B32: NKAMGANG JUSTIN DEJOLIE | C32: DELEGUE COMMERCIAL | E32: 676659191 | G32: MENDONG | H32: 43497
A33: AS201629 | B33: NKEPSEU DIEUDONNE | C33: OPERATEUR ECONOMIQUE | E33: 677575366 | G33: ESSOS | H33: 42917
A34: AS201630 | B34: NKEPSEU HENANG RENE | C34: CADRE SONEL RETRAITE | E34: 699843118 | G34: BIYEM ASSI LYCEE | H34: 42522
A35: AS201631 | B35: NTEPDIE TUEMAC MZ | C35: OPERATEUR ECONOMIQUE | E35: 677377251 | G35: MONTEE JOUVENCE | H35: 43282
A36: AS201632 | B36: NTOMBOU ADOLPHE | C36: INGENIEUR | E36: 677867173 | G36: BIYEM ASSI LYCEE | H36: 42461
... A51: AS201647 | B51: YOUMBI EMMANUEL | C51: PROFESSEUR DES UNIVERSITES | E51: 677547311 | G51: MENDONG (GUINNESS) | H51: 42675
A52: AS201648 | B52: ASELBY | C52: ASSOCIATION DES ELITES BANGOU DE YAOUNDE

Sheet TRAVAUXINVENTAIRE
A1: ASSOCIATION | B1: ASELBY
A2: ANNEE | B2: 2016/2017
A3: TONTINE | B3: 20 000
A4: MATRICULE | B4: NOM ET PRENOM | C4: FONDS DE CAISSE | D4: RELIQUAT 2015 | E4: RELIQUAT 2016 | F4: CAPITAL DEPART | G4: REPARTITION INTERET | H4: CAPITAL COMPOSE FIN | I4: CAPITAL TOTAL A PERCEVOIR | J4: RETENUE | K4: CAPITAL A DISTRIBUER | L4: MONTANT EFFECTIVEMENT VERSE | M4: COMPLEMENT FONDS | N4: SANCTION | O4: RETOUR EN CAISSE MUTUELLE | P4: FRAIS FIXE A PRELEVER | Q4: MONTANT VERSE | R4: EPARGNE | S4: FONDS DE ROULEMENT | T4: FRAIS EXCEPTIONNEL | U4: COLLATION | V4: MUTUELLE | W4: TONTINE | X4: EMPRUNT | Y4: INTERET EMPRUNT | Z4: REMBOURSEMENT | AA4: PENALITE EMPRUNT | AB4: PENALITE FONDS | AC4: INTERET ACHAT | AD4: DATE ACHAT
A5: AS201648 | B5: =VLOOKUP(A5,[2]LISTADHERENT!A$5:H$52,2,0) -> ASELBY | C5: 0 | D5: 318145 | E5: 355097 | F5: 318145 | G5: 36952 | H5: 355097.52 | I5: 355097 | J5: 0 | K5: 355097 | L5: 0 | M5: 0 | N5: 0 | O5: 0 | P5: 0 | Q5: 0 | R5: 0 | S5: 0 | T5: 0 | U5: 0 | V5: 0 | W5: 0 | X5: 0 | Y5: 0 | Z5: 0 | AA5: 0 | AB5: 0 | AC5: 0
A6: AS201601 | B6: =VLOOKUP(A6,[2]LISTADHERENT!A$5:H$52,2,0) -> BAKOP ACHILLE | C6: 390000 | D6: 33536 | E6: 51993 | F6: 453536 | G6: 51457 | H6: 504993.98 | I6: 114993 | J6: 63000 | K6: 51993 | L6: 0 | M6: 30000 | O6: =25000+25000 -> 50000 | P6: 8000 | Q6: 225000 | R6: 30000 | S6: 5000 | T6: 10000 | U6: 25000 | V6: 25000 | W6: 130000 | X6: 500000 | Y6: 15000 | Z6: 0 | AA6: 0 | AB6: 0 | AC6: 0
A7: AS201602 | B7: =VLOOKUP(A7,[2]LISTADHERENT!A$5:H$52,2,0) -> BOUTCHOUANG WILLIAM | C7: 390000 | D7: 1704 | E7: 2720 | F7: 427704 | G7: 48016 | H7: 475720.56 | I7: 85720 | J7: 80000 | K7: 5720 | L7: 3000 | M7: 30000 | O7: 50000 | P7: 0 | Q7: 240000 | R7: 36000 | S7: 6000 | T7: 12000 | U7: 30000 | V7: 0 | W7: 156000 | X7: 1700000 | Y7: 124000 | Z7: 1000000 | AA7: 0 | AB7: 0 | AC7: 0
A8: AS201603 | B8: =VLOOKUP(A8,[2]LISTADHERENT!A$5:H$52,2,0) -> CHINGUE FABRICE | C8: 390000 | D8: 1842 | E8: 5874 | F8: 427842 | G8: 48032 | H8: 475874.59 | I8: 85874 | J8: 80000 | K8: 5874 | L8: 0 | M8: 30000 | O8: 50000 | P8: 0 | Q8: 240000 | R8: 36000 | S8: 6000 | T8: 12000 | U8: 30000 | V8: 0 | W8: 156000 | X8: 2000000 | Y8: 180000 | Z8: 1000000 | AA8: 0 | AB8: 0 | AC8: 0
A9: AS201604 | B9: =VLOOKUP(A9,[2]LISTADHERENT!A$5:H$52,2,0) -> DJOMO JEAN PAUL | C9: 390000 | D9: 8156 | E9: 2570 | F9: 441156 | G9: 48914 | H9: 490070.36 | I9: 100070 | J9: 80000 | K9: 20070 | L9: 17500 | M9: 30000 | O9: 50000 | P9: 0 | Q9: 247000 | R9: 43000 | S9: 6000 | T9: 12000 | U9: 30000 | V9: 0 | W9: 156000 | X9: 200000 | Y9: 6000 | Z9: 0 | AA9: 0 | AB9: 0 | AC9: 0
A10: AS201605 | B10: =VLOOKUP(A10,[2]LISTADHERENT!A$5:H$52,2,0) -> DJOUKWE GUY | C10: 390000 | D10: 5905 | E10: 2697 | F10: 471905 | G10: 51792 | H10: 523697.05 | I10: 133697 | J10: 80000 | K10: 53697 | L10: 51000 | M10: 30000 | O10: 50000 | P10: 0 | Q10: 280000 | R10: 76000 | S10: 6000 | T10: 12000 | U10: 30000 | V10: 0 | W10: 156000 | X10: 250000 | Y10: 7500 | Z10: 0 | AA10: 0 | AB10: 0 | AC10: 0
A11: AS201606 | B11: =VLOOKUP(A11,[2]LISTADHERENT!A$5:H$52,2,0) -> DJOSSEU JOSUE | E11: 0
A12: AS201607 | B12: =VLOOKUP(A12,[2]LISTADHERENT!A$5:H$52,2,0) -> DJOUNKEP SAMUEL | C12: 390000 | D12: 1055294 | E12: 635540 | F12: 2001294 | G12: 204246 | H12: 2135835.7 | I12: 1815540 | J12: 80000 | K12: 1735540 | L12: 1100000 | M12: 30000 | O12: 50000 | P12: 0 | Q12: 760000 | R12: 556000 | S12: 6000 | T12: 12000 | U12: 30000 | V12: 0 | W12: 156000 | X12: 0 | Y12: 0 | Z12: 0 | AA12: 0 | AB12: 0 | AC12: 0
A13: AS201608 | B13: =VLOOKUP(A13,[2]LISTADHERENT!A$5:H$52,2,0) -> DJUOMBESSY ANTOINE | C13: 390000 | D13: 0 | E13: 2746 | F13: 457560 | G13: 43186 | H13: 500746.25 | I13: 110746 | J13: 80000 | K13: 30746 | L13: 28000 | M13: 30000 | O13: 50000 | P13: 0 | Q13: 271560 | R13: 67560 | S13: 6000 | T13: 12000 | U13: 30000 | V13: 0 | W13: 156000 | X13: 700000 | Y13: 84000 | Z13: 0 | AA13: 0 | AB13: 48440 | AC13: 0
A14: AS201609 | B14: =VLOOKUP(A14,[2]LISTADHERENT!A$5:H$52,2,0) -> DONHOU DAVID | C14: 390000 | D14: 44734 | E14: 53748 | F14: 470734 | G14: 53014 | H14: 523748.49 | I14: 133748 | J14: 80000 | K14: 53748 | L14: 0 | M14: 30000 | O14: 50000 | P14: 0 | Q14: 240000 | R14: 36000 | S14: 6000 | T14: 12000 | U14: 30000 | V14: 0 | W14: 156000 | X14: 0 | Y14: 0 | Z14: 0 | AA14: 0 | AB14: 0 | AC14: 0
A15: AS201610 | B15: =VLOOKUP(A15,[2]LISTADHERENT!A$5:H$52,2,0) -> FOTSO THOMAS | C15: 390000 | D15: 3318 | E15: 2522 | F15: 429318 | G15: 48204 | H15: 477522.03 | I15: 87522 | J15: 80000 | K15: 7522 | L15: 5000 | M15: 30000 | O15: 50000 | P15: 0 | Q15: 240000 | R15: 36000 | S15: 6000 | T15: 12000 | U15: 30000 | V15: 0 | W15: 156000 | X15: 1000000 | Y15: 120000 | Z15: 0 | AA15: 0 | AB15: 0 | AC15: 0
A16: AS201611 | B16: =VLOOKUP(A16,[2]LISTADHERENT!A$5:H$52,2,0) -> HENGUE PAUL OMER | C16: 390000 | E16: -10298 | F16: 420000 | G16: 47702 | H16: 467702.04 | I16: 77702 | J16: 88000 | K16: -10298 | L16: 0 | M16: 30000 | O16: 50000 | P16: 8000 | Q16: 200000 | R16: 30000 | S16: 5000 | T16: 10000 | U16: 25000 | V16: 0 | W16: 130000 | X16: 0 | Y16: 0 | Z16: 0 | AA16: 0 | AB16: 0 | AC16: 0
A17: AS201612 | B17: =VLOOKUP(A17,[2]LISTADHERENT!A$5:H$52,2,0) -> HODIEP JULES | C17: 50000 | D17: 0 | E17: 260 | F17: 58100 | G17: 6252 | H17: 92252.382 | I17: 14352 | J17: 14092 | K17: 260 | L17: 0 | O17: 14092 | P17: 0 | Q17: 240000 | R17: 8100 | S17: 6000 | T17: 12000 | U17: 30000 | V17: 0 | W17: 156000 | X17: 0 | Y17: 0 | Z17: 0 | AA17: 0 | AB17: 0 | AC17: 0
A18: AS201613 | B18: =VLOOKUP(A18,[2]LISTADHERENT!A$5:H$52,2,0) -> HOTCHO BENJAMIN | C18: 390000 | D18: 8723 | E18: 112685 | F18: 482723 | G18: 49962 | H18: 532685.38 | I18: 142685 | J18: 30000 | K18: 112685 | L18: 0 | M18: 30000 | O18: 50000 | P18: 0 | Q18: 338000 | R18: 84000 | S18: 6000 | T18: 12000 | U18: 30000 | V18: 50000 | W18: 156000 | X18: 0 | Y18: 0 | Z18: 0 | AA18: 0 | AB18: 0 | AC18: 0
A19: AS201614 | B19: =VLOOKUP(A19,[2]LISTADHERENT!A$5:H$52,2,0) -> KEPHE DAVID | C19: 0 | D19: 12795 | E19: 177 | F19: 18000 | G19: 4006 | H19: 52801.313 | I19: 22006 | J19: 21829 | K19: 177 | L19: 0 | O19: 21829 | P19: 0 | Q19: 240000 | R19: 5205 | S19: 6000 | T19: 12000 | U19: 30000 | V19: 0 | W19: 156000 | X19: 0 | Y19: 0 | Z19: 0 | AA19: 0 | AB19: 0 | AC19: 0
A20: AS201615 | B20: =VLOOKUP(A20,[2]LISTADHERENT!A$5:H$52,2,0) -> KEPSEU FRANCIS | C20: 390000 | D20: 186997 | E20: 705425 | F20: 1128997 | G20: 117428 | H20: 1246425.8 | I20: 856425 | J20: 80000 | K20: 776425 | L20: 71000 | M20: 30000 | O20: 50000 | P20: 0 | Q20: 756000 | R20: 552000 | S20: 6000 | T20: 12000 | U20: 30000 | V20: 0 | W20: 156000 | X20: 0 | Y20: 0 | Z20: 0 | AA20: 0 | AB20: 0 | AC20: 0
A21: AS201616 | B21: =VLOOKUP(A21,[2]LISTADHERENT!A$5:H$52,2,0) -> KOUAMOU EMMANUEL | C21: 390000 | D21: 2723 | E21: 2357 | F21: 428723 | G21: 48134 | H21: 476857.92 | I21: 86857 | J21: 80000 | K21: 6857 | L21: 4500 | M21: 30000 | O21: 50000 | P21: 0 | Q21: 240000 | R21: 36000 | S21: 6000 | T21: 12000 | U21: 30000 | V21: 0 | W21: 156000 | X21: 1000000 | Y21: 120000 | Z21: 0 | AA21: 0 | AB21: 0 | AC21: 0
A22: AS201617 | B22: =VLOOKUP(A22,[2]LISTADHERENT!A$5:H$52,2,0) -> KOUAMOU MOISE | C22: 390000 | D22: 2099 | E22: 3048 | F22: 428099 | G22: 44949 | H22: 473048.51 | I22: 83048 | J22: 80000 | K22: 3048 | L22: 0 | M22: 30000 | O22: 50000 | P22: 0 | Q22: 240000 | R22: 36000 | S22: 6000 | T22: 12000 | U22: 30000 | V22: 0 | W22: 156000 | X22: 860000 | Y22: 97800 | Z22: 0 | AA22: 0 | AB22: 0 | AC22: 0
A23: AS201618 | B23: =VLOOKUP(A23,[2]LISTADHERENT!A$5:H$52,2,0) -> KOUAMOU VICTOR PEGUY | C23: 390000 | D23: 36629 | E23: 2686 | F23: 461629 | G23: 52057 | H23: 513686.78 | I23: 123686 | J23: 80000 | K23: 43686 | L23: 41000 | M23: 30000 | O23: 50000 | P23: 0 | Q23: 239000 | R23: 35000 | S23: 6000 | T23: 12000 | U23: 30000 | V23: 0 | W23: 156000 | X23: 1800000 | Y23: 128000 | Z23: 1000000 | AA23: 0 | AB23: 0 | AC23: 0
A24: AS201619 | B24: =VLOOKUP(A24,[2]LISTADHERENT!A$5:H$52,2,0) -> KOUATCHO MESSACK | C24: 390000 | D24: 0 | E24: 3818 | F24: 426000 | G24: 47818 | H24: 473818.64 | I24: 83818 | J24: 80000 | K24: 3818 | L24: 0 | M24: 30000 | O24: 50000 | P24: 0 | Q24: 240000 | R24: 36000 | S24: 6000 | T24: 12000 | U24: 30000 | V24: 0 | W24: 156000 | X24: 1600000 | Y24: 192000 | Z24: 0 | AA24: 0 | AB24: 0 | AC24: 0
A25: AS201620 | B25: =VLOOKUP(A25,[2]LISTADHERENT!A$5:H$52,2,0) -> LOWE JEAN | C25: 390000 | D25: 4331 | E25: 2652 | F25: 430331 | G25: 48321 | H25: 478652.69 | I25: 88652 | J25: 80000 | K25: 8652 | L25: 6000 | M25: 30000 | O25: 50000 | P25: 0 | Q25: 240000 | R25: 36000 | S25: 6000 | T25: 12000 | U25: 30000 | V25: 0 | W25: 156000 | X25: 240000 | Y25: 7200 | Z25: 160000 | AA25: 0 | AB25: 0 | AC25: 0
A26: AS201621 | B26: =VLOOKUP(A26,[2]LISTADHERENT!A$5:H$52,2,0) -> NANKAM APPOLINAIRE | C26: 390000 | D26: 4411 | E26: 2741 | F26: 430411 | G26: 48330 | H26: 478741.98 | I26: 88741 | J26: 80000 | K26: 8741 | L26: 6000 | M26: 30000 | O26: 50000 | P26: 0 | Q26: 240000 | R26: 36000 | S26: 6000 | T26: 12000 | U26: 30000 | V26: 0 | W26: 156000 | X26: 1000000 | Y26: 120000 | Z26: 0 | AA26: 0 | AB26: 0 | AC26: 0
A27: AS201622 | B27: =VLOOKUP(A27,[2]LISTADHERENT!A$5:H$52,2,0) -> NDJOMO ETIENNE | C27: 390000 | D27: 2060 | E27: 2818 | F27: 488060 | G27: 52258 | H27: 540318.2 | I27: 150318 | J27: 80000 | K27: 70318 | L27: 67500 | M27: 30000 | O27: 50000 | P27: 0 | Q27: 300000 | R27: 96000 | S27: 6000 | T27: 12000 | U27: 30000 | V27: 0 | W27: 156000 | X27: 1600000 | Y27: 48000 | Z27: 1200000 | AA27: 0 | AB27: 0 | AC27: 0
A28: AS201623 | B28: =VLOOKUP(A28,[2]LISTADHERENT!A$5:H$52,2,0) -> NDOMBOU JEAN CLAUDE | C28: 0 | D28: 0 | E28: 0 | F28: 0 | G28: 0 | H28: 0 | I28: 0 | J28: 0 | K28: 0 | Q28: 0 | R28: 0 | S28: 0 | T28: 0 | U28: 0 | V28: 0 | W28: 0 | X28: 0 | Y28: 0 | Z28: 0 | AA28: 0 | AB28: 0 | AC28: 0
A29: AS201624 | B29: =VLOOKUP(A29,[2]LISTADHERENT!A$5:H$52,2,0) -> NGONDIEP CLAUDE | C29: 390000 | D29: 179574 | E29: 3250 | F29: 605574 | G29: 68676 | H29: 674250.15 | I29: 284250 | J29: 80000 | K29: 204250 | L29: 201000 | M29: 30000 | O29: 50000 | P29: 0 | Q29: 240000 | R29: 36000 | S29: 6000 | T29: 12000 | U29: 30000 | V29: 0 | W29: 156000 | X29: 0 | Y29: 0 | Z29: 0 | AA29: 0 | AB29: 0 | AC29: 0
A30: AS201625 | B30: =VLOOKUP(A30,[2]LISTADHERENT!A$5:H$52,2,0) -> NGONGANG JEAN THEODORE | C30: 0 | D30: 0 | E30: 106 | F30: 17782 | G30: 2520 | H30: 38520.175 | I30: 20302 | J30: 20196 | K30: 106 | L30: 0 | O30: 20196 | P30: 0 | Q30: 240000 | R30: 17782 | S30: 6000 | T30: 12000 | U30: 30000 | V30: 0 | W30: 156000 | X30: 0 | Y30: 0 | Z30: 0 | AA30: 0 | AB30: 0 | AC30: 0
A31: AS201626 | B31: =VLOOKUP(A31,[2]LISTADHERENT!A$5:H$52,2,0) -> NGUIEMEGNI MATHIEU BLAISE | C31: 390000 | D31: 0 | E31: 565188 | F31: 945945 | G31: 39243 | H31: 985188.09 | I31: 595188 | J31: 30000 | K31: 565188 | L31: 0 | M31: 30000 | O31: 50000 | P31: 0 | Q31: 860000 | R31: 555945 | S31: 6000 | T31: 12000 | U31: 30000 | V31: 50000 | W31: 156000 | X31: 0 | Y31: 0 | Z31: 0 | AA31: 0 | AB31: 50055 | AC31: 0
A32: AS201627 | B32: =VLOOKUP(A32,[2]LISTADHERENT!A$5:H$52,2,0) -> NJEPDJIO MBOUKAM DELUXE | C32: 390000 | D32: 1734 | E32: 2773 | F32: 443734 | G32: 49539 | H32: 493273.71 | I32: 103273 | J32: 80000 | K32: 23273 | L32: 20500 | M32: 30000 | O32: 50000 | P32: 0 | Q32: 256000 | R32: 52000 | S32: 6000 | T32: 12000 | U32: 30000 | V32: 0 | W32: 156000 | X32: 2000000 | Y32: 150000 | Z32: 1000000 | AA32: 0 | AB32: 0 | AC32: 0
A33: AS201628 | B33: =VLOOKUP(A33,[2]LISTADHERENT!A$5:H$52,2,0) -> NKAMGANG JUSTIN DEJOLIE | C33: 372800 | D33: 0 | E33: 14208 | F33: 444800 | G33: 22208 | H33: 539008.02 | I33: 94208 | J33: 80000 | K33: 14208 | L33: 0 | M33: 30000 | O33: 50000 | P33: 0 | Q33: 648800 | R33: 72000 | S33: 6000 | T33: 12000 | U33: 30000 | V33: 0 | W33: 156000 | X33: 1000000 | Y33: 120000 | Z33: 0 | AA33: 0 | AB33: 0 | AC33: 0
A34: AS201629 | B34: =VLOOKUP(A34,[2]LISTADHERENT!A$5:H$52,2,0) -> NKEPSEU DIEUDONNE | C34: 390000 | D34: 8739 | E34: 2772 | F34: 494739 | G34: 53033 | H34: 547772.97 | I34: 157772 | J34: 30000 | K34: 127772 | L34: 125000 | M34: 30000 | O34: =25000+25000 -> 50000 | P34: 0 | Q34: 350000 | R34: 96000 | S34: 6000 | T34: 12000 | U34: 30000 | V34: 50000 | W34: 156000 | X34: 600000 | Y34: 72000 | Z34: 0 | AA34: 0 | AB34: 0 | AC34: 0
A35: AS201630 | B35: =VLOOKUP(A35,[2]LISTADHERENT!A$5:H$52,2,0) -> NKEPSEU HENANG RENE | E35: 0
A36: AS201631 | B36: =VLOOKUP(A36,[2]LISTADHERENT!A$5:H$52,2,0) -> NTEPDIE TUEMAC MZ | C36: 0 | D36: 0 | E36: -12105 | F36: 15000 | G36: 895 | H36: 15895.449 | I36: 15895 | J36: 28000 | K36: -12105 | L36: 0 | P36: 28000 | Q36: 100000 | R36: 15000 | S36: 2500 | T36: 5000 | U36: 12500 | V36: 0 | W36: 65000 | X36: 0 | Y36: 0 | Z36: 0 | AA36: 0 | AB36: 0 | AC36: 0
A37: AS201632 | B37: =VLOOKUP(A37,[2]LISTADHERENT!A$5:H$52,2,0) -> NTOMBOU ADOLPHE | E37: 0
A38: AS201633 | B38: =VLOOKUP(A38,[2]LISTADHERENT!A$5:H$52,2,0) -> PATEGO NJOSSU GUSTAVE | C38: 390000 | D38: 140 | E38: 2474 | F38: 426140 | G38: 47834 | H38: 473974.9 | I38: 83974 | J38: 80000 | K38: 3974 | L38: 1500 | M38: 30000 | O38: 50000 | P38: 0 | Q38: 240000 | R38: 36000 | S38: 6000 | T38: 12000 | U38: 30000 | V38: 0 | W38: 156000 | X38: 0 | Y38: 0 | Z38: 0 | AA38: 0 | AB38: 0 | AC38: 0
A39: AS201634 | B39: =VLOOKUP(A39,[2]LISTADHERENT!A$5:H$52,2,0) -> SEUNOU RICHELOT | C39: 390000 | D39: 2632 | E39: 6756 | F39: 428632 | G39: 48124 | H39: 476756.35 | I39: 86756 | J39: 80000 | K39: 6756 | L39: 0 | M39: 30000 | O39: 50000 | P39: 0 | Q39: 240000 | R39: 36000 | S39: 6000 | T39: 12000 | U39: 30000 | V39: 0 | W39: 156000 | X39: 1000000 | Y39: 120000 | Z39: 0 | AA39: 0 | AB39: 0 | AC39: 0
A40: AS201635 | B40: =VLOOKUP(A40,[2]LISTADHERENT!A$5:H$52,2,0) -> SIME ABEL | C40: 390000 | D40: 0 | E40: 488 | F40: 398873 | G40: 15621 | H40: 441621.35 | I40: 24494 | J40: 24006 | K40: 488 | L40: 0 | O40: 24006 | P40: 0 | Q40: 240000 | R40: 8873 | S40: 6000 | T40: 12000 | U40: 30000 | V40: 0 | W40: 156000 | X40: 0 | Y40: 0 | Z40: 0 | AA40: 0 | AB40: 0 | AC40: 0
...

Sheet FONDSDECAISSE
A1: ASSOCIATION | B1: ASELBY
A2: ANNEE | B2: 2016/2017
A3: TONTINE | B3: 20 000
A4: MATRICULE | B4: NOM ET PRENOM | C4: DECEMBRE | D4: JANVIER | E4: FÉVRIER | F4: MARS | G4: AVRIL | H4: MAI | I4: JUIN | J4: JUILLET | K4: AOÛT | L4: SEPTEMBRE | M4: OCTOBRE | N4: NOVEMBRE | O4: TOTAL
A5: AS201648 | B5: =VLOOKUP(A5,LISTADHERENT!A$5:H$52,2,0) -> ASELBY | C5: 0 | O5: =SUM(C5:N5) -> 0
A6: AS201601 | B6: =VLOOKUP(A6,LISTADHERENT!A$5:H$52,2,0) -> BAKOP ACHILLE | C6: 420000 | O6: =SUM(C6:N6) -> 420000
A7: AS201602 | B7: =VLOOKUP(A7,LISTADHERENT!A$5:H$52,2,0) -> BOUTCHOUANG WILLIAM | C7: 420000 | O7: =SUM(C7:N7) -> 420000
A8: AS201603 | B8: =VLOOKUP(A8,LISTADHERENT!A$5:H$52,2,0) -> CHINGUE FABRICE | C8: 420000 | O8: =SUM(C8:N8) -> 420000
A9: AS201604 | B9: =VLOOKUP(A9,LISTADHERENT!A$5:H$52,2,0) -> DJOMO JEAN PAUL | C9: 420000 | O9: =SUM(C9:N9) -> 420000
A10: AS201605 | B10: =VLOOKUP(A10,LISTADHERENT!A$5:H$52,2,0) -> DJOUKWE NANGUEN GUY BLAISE | C10: 420000 | O10: =SUM(C10:N10) -> 420000
A11: AS201606 | B11: =VLOOKUP(A11,LISTADHERENT!A$5:H$52,2,0) -> DJOSSEU JOSUE | C11: 0 | O11: =SUM(C11:N11) -> 0
A12: AS201607 | B12: =VLOOKUP(A12,LISTADHERENT!A$5:H$52,2,0) -> DJOUNKEP SAMUEL | C12: 420000 | O12: =SUM(C12:N12) -> 420000
A13: AS201608 | B13: =VLOOKUP(A13,LISTADHERENT!A$5:H$52,2,0) -> DJUOMBESSY ANTOINE | C13: 420000 | O13: =SUM(C13:N13) -> 420000
A14: AS201609 | B14: =VLOOKUP(A14,LISTADHERENT!A$5:H$52,2,0) -> DONHOU DAVID | C14: 420000 | O14: =SUM(C14:N14) -> 420000
A15: AS201610 | B15: =VLOOKUP(A15,LISTADHERENT!A$5:H$52,2,0) -> FOTSO THOMAS | C15: 420000 | O15: =SUM(C15:N15) -> 420000
A16: AS201611 | B16: =VLOOKUP(A16,LISTADHERENT!A$5:H$52,2,0) -> HENGUE PAUL OMER | C16: 420000 | O16: =SUM(C16:N16) -> 420000
... A18: AS201613 | B18: =VLOOKUP(A18,LISTADHERENT!A$5:H$52,2,0) -> HOTCHO BENJAMIN | C18: 420000 | O18: =SUM(C18:N18) -> 420000
A19: AS201614 | B19: =VLOOKUP(A19,LISTADHERENT!A$5:H$52,2,0) -> KEPHE DAVID | C19: 0 | K19: 100000 | O19: =SUM(C19:N19) -> 100000
A20: AS201615 | B20: =VLOOKUP(A20,LISTADHERENT!A$5:H$52,2,0) -> KEPSEU FRANCIS | C20: 420000 | O20: =SUM(C20:N20) -> 420000
A21: AS201616 | B21: =VLOOKUP(A21,LISTADHERENT!A$5:H$52,2,0) -> KOUAMOU EMMANUEL | C21: 420000 | O21: =SUM(C21:N21) -> 420000
A22: AS201617 | B22: =VLOOKUP(A22,LISTADHERENT!A$5:H$52,2,0) -> KOUAMOU MOISE | C22: 420000 | O22: =SUM(C22:N22) -> 420000
A23: AS201618 | B23: =VLOOKUP(A23,LISTADHERENT!A$5:H$52,2,0) -> KOUAMO VICTOR PEGUY | C23: 420000 | O23: =SUM(C23:N23) -> 420000
A24: AS201619 | B24: =VLOOKUP(A24,LISTADHERENT!A$5:H$52,2,0) -> KOUATCHO MESSACK | C24: 420000 | O24: =SUM(C24:N24) -> 420000
A25: AS201620 | B25: =VLOOKUP(A25,LISTADHERENT!A$5:H$52,2,0) -> LOWE JEAN | C25: 420000 | O25: =SUM(C25:N25) -> 420000
A26: AS201621 | B26: =VLOOKUP(A26,LISTADHERENT!A$5:H$52,2,0) -> NANKAM APPOLINAIRE | C26: 420000 | O26: =SUM(C26:N26) -> 420000
A27: AS201622 | B27: =VLOOKUP(A27,LISTADHERENT!A$5:H$52,2,0) -> NDJOMO ETIENNE | C27: 420000 | O27: =SUM(C27:N27) -> 420000
A28: AS201623 | B28: =VLOOKUP(A28,LISTADHERENT!A$5:H$52,2,0) -> NDOMBOU JEAN CLAUDE | C28: 0 | F28: 420000 | O28: =SUM(C28:N28) -> 420000
A29: AS201624 | B29: =VLOOKUP(A29,LISTADHERENT!A$5:H$52,2,0) -> NGONDIEP CLAUDE | C29: 420000 | O29: =SUM(C29:N29) -> 420000
A30: AS201625 | B30: =VLOOKUP(A30,LISTADHERENT!A$5:H$52,2,0) -> NGONGANG JEAN THEODORE | C30: 0 | O30: =SUM(C30:N30) -> 0
A31: AS201626 | B31: =VLOOKUP(A31,LISTADHERENT!A$5:H$52,2,0) -> NGUIEMEGNI MATHIEU BLAISE | C31: 420000 | O31: =SUM(C31:N31) -> 420000
A32: AS201627 | B32: =VLOOKUP(A32,LISTADHERENT!A$5:H$52,2,0) -> NJEPDJIO MBOUKAM DELUXE | C32: 420000 | O32: =SUM(C32:N32) -> 420000
A33: AS201628 | B33: =VLOOKUP(A33,LISTADHERENT!A$5:H$52,2,0) -> NKAMGANG JUSTIN DEJOLIE | C33: 102800 | K33: =372800-55600 -> 317200 | O33: =SUM(C33:N33) -> 420000
A34: AS201629 | B34: =VLOOKUP(A34,LISTADHERENT!A$5:H$52,2,0) -> NKEPSEU DIEUDONNE | C34: 420000 | O34: =SUM(C34:N34) -> 420000
A35: AS201630 | B35: =VLOOKUP(A35,LISTADHERENT!A$5:H$52,2,0) -> NKEPSEU HENANG RENE | O35: =SUM(C35:N35) -> 0
A36: AS201631 | B36: =VLOOKUP(A36,LISTADHERENT!A$5:H$52,2,0) -> NTEPDIE TUEMAC MZ | C36: 0 | O36: =SUM(C36:N36) -> 0
A37: AS201632 | B37: =VLOOKUP(A37,LISTADHERENT!A$5:H$52,2,0) -> NTOMBOU ADOLPHE | C37: 0 | O37: =SUM(C37:N37) -> 0
A38: AS201633 | B38: =VLOOKUP(A38,LISTADHERENT!A$5:H$52,2,0) -> PATEGO NJOSSU GUSTAVE | C38: 420000 | O38: =SUM(C38:N38) -> 420000
A39: AS201634 | B39: =VLOOKUP(A39,LISTADHERENT!A$5:H$52,2,0) -> SEUNOU RICHELOT | C39: 420000 | O39: =SUM(C39:N39) -> 420000
A40: AS201635 | B40: =VLOOKUP(A40,LISTADHERENT!A$5:H$52,2,0) -> SIME ABEL | C40: 390000 | O40: =SUM(C40:N40) -> 390000
A41: AS201636 | B41: =VLOOKUP(A41,LISTADHERENT!A$5:H$52,2,0) -> SIME FONGANG ERIC | C41: 420000 | O41: =SUM(C41:N41) -> 420000
...

Sheet TONT20000DEC2016
A1: ASSOCIATION | B1: ASELBY
A2: ANNEE | B2: 2016/2017
A3: TONTINE | B3: 20 000
A4: MATRICULE | B4: NOM ET PRENOM | C4: FONDS DE CAISSE | D4: RELIQUAT 2016 | E4: REPARTITION INTERET | F4: CAPITAL COMPOSE | G4: SANCTION | H4: MONTANT TONTINE | I4: PENALITE | J4: MODE VERSEMENT | K4: MONTANT VERSE | L4: EPARGNE | M4: FONDS DE ROULEMENT | N4: FRAIS EXCEPTIONNEL | O4: COLLATION | P4: MUTUELLE | Q4: EMPRUNT | R4: INTERET EMPRUNT | S4: REMBOURSEMENT | T4: PENALITE EMPRUNT | U4: PENALITE FONDS | V4: INTERET ACHAT | W4: DATE ACHAT | X4: AVALISTE
A5: AS201648 | B5: =VLOOKUP(A5,LISTADHERENT!A$5:H$52,2,0) -> ASELBY | C5: =VLOOKUP(A5,FONDSDECAISSE!A$5:O$52,15,0) -> 0 | D5: 355097 | E5: =$R$56/$F$56*F5 -> 204.20954 | F5: =C5+D5+L5 -> 355097
A6: AS201601 | B6: =VLOOKUP(A6,LISTADHERENT!A$5:H$52,2,0) -> BAKOP ACHILLE | C6: =VLOOKUP(A6,FONDSDECAISSE!A$5:O$52,15,0) -> 420000 | D6: 51993 | E6: =$R$56/$F$56*F6 -> 271.4342 | F6: =C6+D6+L6 -> 471993 | H6: =IF(J6="ECHEC",0,13000) -> 0 | I6: =IF(J6="ESPECES",1000,0) -> 0 | J6: ECHEC | K6: =IF(H6=0,0,L6+M6+N6+O6+P6+#REF!) -> 0 | R6: =IF(Q6<=500000,(Q6*1*3/100),(Q6*12/100)) -> 0 | S6: =Q6+R6 -> 0
A7: AS201602 | B7: =VLOOKUP(A7,LISTADHERENT!A$5:H$51,2) -> BOUTCHOUANG WILLIAM | C7: =VLOOKUP(A7,FONDSDECAISSE!A$5:O$52,15,0) -> 420000 | D7: 2720 | E7: =$R$56/$F$56*F7 -> 244.82348 | F7: =C7+D7+L7 -> 425720 | H7: =IF(J7="ECHEC",0,13000) -> 13000 | I7: =IF(J7="ESPECES",1000,0) -> 1000 | J7: ESPECES | K7: =IF(H7=0,0,H7+L7+M7+N7+O7+P7) -> 20000 | L7: 3000 | M7: 500 | N7: 1000 | O7: 2500 | R7: =IF(Q7<=500000,(Q7*1*3/100),(Q7*12/100)) -> 0 | S7: =Q7+R7 -> 0
A8: AS201603 | B8: =VLOOKUP(A8,LISTADHERENT!A$5:H$51,2) -> CHINGUE FABRICE | C8: =VLOOKUP(A8,FONDSDECAISSE!A$5:O$52,15,0) -> 420000 | D8: 5874 | E8: =$R$56/$F$56*F8 -> 246.63729 | F8: =C8+D8+L8 -> 428874 | H8: =IF(J8="ECHEC",0,13000) -> 13000 | I8: =IF(J8="ESPECES",1000,0) -> 1000 | J8: ESPECES | K8: =IF(H8=0,0,H8+L8+M8+N8+O8+P8) -> 20000 | L8: 3000 | M8: 500 | N8: 1000 | O8: 2500 | R8: =IF(Q8<=500000,(Q8*1*3/100),(Q8*12/100)) -> 0 | S8: =Q8+R8 -> 0
A9: AS201604 | B9: =VLOOKUP(A9,LISTADHERENT!A$5:H$51,2) -> DJOMO JEAN PAUL | C9: =VLOOKUP(A9,FONDSDECAISSE!A$5:O$52,15,0) -> 420000 | D9: 2570 | E9: =$R$56/$F$56*F9 -> 244.73722 | F9: =C9+D9+L9 -> 425570 | H9: =IF(J9="ECHEC",0,13000) -> 13000 | I9: =IF(J9="ESPECES",1000,0) -> 0 | J9: BANQUE | K9: =IF(H9=0,0,H9+L9+M9+N9+O9+P9) -> 20000 | L9: 3000 | M9: 500 | N9: 1000 | O9: 2500 | R9: =IF(Q9<=500000,(Q9*1*3/100),(Q9*12/100)) -> 0 | S9: =Q9+R9 -> 0 | V9: 11000 | W9: 42723 | X9: KOUAMOU VICTOR PEGUY
A10: AS201605 | B10: =VLOOKUP(A10,LISTADHERENT!A$5:H$51,2) -> DJOUKWE NANGUEN GUY BLAISE | C10: =VLOOKUP(A10,FONDSDECAISSE!A$5:O$52,15,0) -> 420000 | D10: 2697 | E10: =$R$56/$F$56*F10 -> 244.81025 | F10: =C10+D10+L10 -> 425697 | H10: =IF(J10="ECHEC",0,13000) -> 13000 | I10: =IF(J10="ESPECES",1000,0) -> 0 | J10: BANQUE | K10: =IF(H10=0,0,H10+L10+M10+N10+O10+P10) -> 20000 | L10: 3000 | M10: 500 | N10: 1000 | O10: 2500 | R10: =IF(Q10<=500000,(Q10*1*3/100),(Q10*12/100)) -> 0 | S10: =Q10+R10 -> 0
D11: 0 | F11: =C11+D11+L11 -> 0 | R11: =IF(Q11<=500000,(Q11*1*3/100),(Q11*12/100)) -> 0 | S11: =Q11+R11 -> 0
A12: AS201607 | B12: =VLOOKUP(A12,LISTADHERENT!A$5:H$51,2) -> DJOUNKEP SAMUEL | C12: =VLOOKUP(A12,FONDSDECAISSE!A$5:O$52,15,0) -> 420000 | D12: 635540 | E12: =$R$56/$F$56*F12 -> 608.74623 | F12: =C12+D12+L12 -> 1058540 | H12: =IF(J12="ECHEC",0,13000) -> 13000 | I12: =IF(J12="ESPECES",1000,0) -> 0 | J12: BANQUE | K12: =IF(H12=0,0,H12+L12+M12+N12+O12+P12) -> 20000 | L12: 3000 | M12: 500 | N12: 1000 | O12: 2500 | R12: =IF(Q12<=500000,(Q12*1*3/100),(Q12*12/100)) -> 0 | S12: =Q12+R12 -> 0
A13: AS201608 | B13: =VLOOKUP(A13,LISTADHERENT!A$5:H$51,2) -> DJUOMBESSY ANTOINE | C13: =VLOOKUP(A13,FONDSDECAISSE!A$5:O$52,15,0) -> 420000 | D13: 2746 | E13: =$R$56/$F$56*F13 -> 244.83843 | F13: =C13+D13+L13 -> 425746 | H13: =IF(J13="ECHEC",0,13000) -> 13000 | I13: =IF(J13="ESPECES",1000,0) -> 0 | J13: BANQUE | K13: =IF(H13=0,0,H13+L13+M13+N13+O13+P13) -> 20000 | L13: 3000 | M13: 500 | N13: 1000 | O13: 2500 | R13: =IF(Q13<=500000,(Q13*1*3/100),(Q13*12/100)) -> 0 | S13: =Q13+R13 -> 0
A14: AS201609 | B14: =VLOOKUP(A14,LISTADHERENT!A$5:H$51,2) -> DONHOU DAVID | C14: =VLOOKUP(A14,FONDSDECAISSE!A$5:O$52,15,0) -> 420000 | D14: 53748 | E14: =$R$56/$F$56*F14 -> 274.16871 | F14: =C14+D14+L14 -> 476748 | H14: =IF(J14="ECHEC",0,13000) -> 13000 | I14: =IF(J14="ESPECES",1000,0) -> 1000 | J14: ESPECES | K14: =IF(H14=0,0,H14+L14+M14+N14+O14+P14) -> 20000 | L14: 3000 | M14: 500 | N14: 1000 | O14: 2500 | R14: =IF(Q14<=500000,(Q14*1*3/100),(Q14*12/100)) -> 0 | S14: =Q14+R14 -> 0
A15: AS201610 | B15: =VLOOKUP(A15,LISTADHERENT!A$5:H$51,2) -> FOTSO THOMAS | C15: =VLOOKUP(A15,FONDSDECAISSE!A$5:O$52,15,0) -> 420000 | D15: 2522 | E15: =$R$56/$F$56*F15 -> 244.70961 | F15: =C15+D15+L15 -> 425522 | H15: =IF(J15="ECHEC",0,13000) -> 13000 | I15: =IF(J15="ESPECES",1000,0) -> 1000 | J15: ESPECES | K15: =IF(H15=0,0,H15+L15+M15+N15+O15+P15) -> 20000 | L15: 3000 | M15: 500 | N15: 1000 | O15: 2500 | R15: =IF(Q15<=500000,(Q15*1*3/100),(Q15*12/100)) -> 0 | S15: =Q15+R15 -> 0
A16: AS201611 | B16: =VLOOKUP(A16,LISTADHERENT!A$5:H$51,2) -> HENGUE PAUL OMER | C16: =VLOOKUP(A16,FONDSDECAISSE!A$5:O$52,15,0) -> 420000 | E16: =$R$56/$F$56*F16 -> 281.21461 | F16: =C16+D16+L16 -> 489000 | H16: 39000 | I16: =IF(J16="ESPECES",1000,0) -> 0 | J16: BANQUE | K16: =IF(H16=0,0,H16+L16+M16+N16+O16+P16) -> 120000 | L16: 69000 | M16: 1500 | N16: 3000 | O16: 7500 | R16: =IF(Q16<=500000,(Q16*1*3/100),(Q16*12/100)) -> 0 | S16: =Q16+R16 -> 0
A17: AS201612 | B17: =VLOOKUP(A17,LISTADHERENT!A$5:H$51,2) -> HODIEP JULES | C17: =VLOOKUP(A17,FONDSDECAISSE!A$5:O$52,15,0) -> 50000 | D17: 260 | E17: =$R$56/$F$56*F17 -> 28.903571 | F17: =C17+D17+L17 -> 50260 | H17: =IF(J17="ECHEC",0,13000) -> 0 | I17: =IF(J17="ESPECES",1000,0) -> 0 | J17: ECHEC | K17: =IF(H17=0,0,H17+L17+M17+N17+O17+P17) -> 0 | R17: =IF(Q17<=500000,(Q17*1*3/100),(Q17*12/100)) -> 0 | S17: =Q17+R17 -> 0
A18: AS201613 | B18: =VLOOKUP(A18,LISTADHERENT!A$5:H$51,2) -> HOTCHO BENJAMIN | C18: =VLOOKUP(A18,FONDSDECAISSE!A$5:O$52,15,0) -> 420000 | D18: 112685 | E18: =$R$56/$F$56*F18 -> 308.06226 | F18: =C18+D18+L18 -> 535685 | H18: =IF(J18="ECHEC",0,13000) -> 13000 | I18: =IF(J18="ESPECES",1000,0) -> 0 | J18: BANQUE | K18: =IF(H18=0,0,H18+L18+M18+N18+O18+P18) -> 20000 | L18: 3000 | M18: 500 | N18: 1000 | O18: 2500 | R18: =IF(Q18<=500000,(Q18*1*3/100),(Q18*12/100)) -> 0 | S18: =Q18+R18 -> 0
A19: AS201614 | B19: =VLOOKUP(A19,LISTADHERENT!A$5:H$51,2) -> KEPHE DAVID | C19: =VLOOKUP(A19,FONDSDECAISSE!A$5:O$52,15,0) -> 100000 | D19: 177 | E19: =$R$56/$F$56*F19 -> 59.335132 | F19: =C19+D19+L19 -> 103177 | H19: =IF(J19="ECHEC",0,13000) -> 13000 | I19: =IF(J19="ESPECES",1000,0) -> 0 | J19: BANQUE | K19: =IF(H19=0,0,H19+L19+M19+N19+O19+P19) -> 20000 | L19: 3000 | M19: 500 | N19: 1000 | O19: 2500 | R19: =IF(Q19<=500000,(Q19*1*3/100),(Q19*12/100)) -> 0 | S19: =Q19+R19 -> 0
A20: AS201615 | B20: =VLOOKUP(A20,LISTADHERENT!A$5:H$51,2) -> KEPSEU FRANCIS | C20: =VLOOKUP(A20,FONDSDECAISSE!A$5:O$52,15,0) -> 420000 | D20: 705425 | E20: =$R$56/$F$56*F20 -> 1225.742 | F20: =C20+D20+L20 -> 2131425 | H20: =IF(J20="ECHEC",0,13000) -> 13000 | I20: =IF(J20="ESPECES",1000,0) -> 0 | J20: BANQUE | K20: =IF(H20=0,0,H20+L20+M20+N20+O20+P20) -> 1023000 | L20: 1006000 | M20: 500 | N20: 1000 | O20: 2500 | R20: =IF(Q20<=500000,(Q20*1*3/100),(Q20*12/100)) -> 0 | S20: =Q20+R20 -> 0
A21: AS201616 | B21: =VLOOKUP(A21,LISTADHERENT!A$5:H$51,2) -> KOUAMOU EMMANUEL | C21: =VLOOKUP(A21,FONDSDECAISSE!A$5:O$52,15,0) -> 420000 | D21: 2357 | E21: =$R$56/$F$56*F21 -> 244.61473 | F21: =C21+D21+L21 -> 425357 | H21: =IF(J21="ECHEC",0,13000) -> 13000 | I21: =IF(J21="ESPECES",1000,0) -> 0 | J21: BANQUE | K21: =IF(H21=0,0,H21+L21+M21+N21+O21+P21) -> 20000 | L21: 3000 | M21: 500 | N21: 1000 | O21: 2500 | R21: =IF(Q21<=500000,(Q21*1*3/100),(Q21*12/100)) -> 0 | S21: =Q21+R21 -> 0
A22: AS201617 | B22: =VLOOKUP(A22,LISTADHERENT!A$5:H$51,2) -> KOUAMOU MOISE | C22: =VLOOKUP(A22,FONDSDECAISSE!A$5:O$52,15,0) -> 420000 | D22: 3048 | E22: =$R$56/$F$56*F22 -> 245.01211 | F22: =C22+D22+L22 -> 426048 | H22: =IF(J22="ECHEC",0,13000) -> 13000 | I22: =IF(J22="ESPECES",1000,0) -> 1000 | J22: ESPECES | K22: =IF(H22=0,0,H22+L22+M22+N22+O22+P22) -> 20000 | L22: 3000 | M22: 500 | N22: 1000 | O22: 2500 | R22: =IF(Q22<=500000,(Q22*1*3/100),(Q22*12/100)) -> 0 | S22: =Q22+R22 -> 0 | V22: 12000 | W22: 42723 | X22: TIEYAM ERNEST
A23: AS201618 | B23: =VLOOKUP(A23,LISTADHERENT!A$5:H$51,2) -> KOUAMO VICTOR PEGUY | C23: =VLOOKUP(A23,FONDSDECAISSE!A$5:O$52,15,0) -> 420000 | D23: 2686 | E23: =$R$56/$F$56*F23 -> 244.80393 | F23: =C23+D23+L23 -> 425686 | H23: =IF(J23="ECHEC",0,13000) -> 13000 | I23: =IF(J23="ESPECES",1000,0) -> 1000 | J23: ESPECES | K23: =IF(H23=0,0,H23+L23+M23+N23+O23+P23) -> 20000 | L23: 3000 | M23: 500 | N23: 1000 | O23: 2500 | R23: =IF(Q23<=500000,(Q23*1*3/100),(Q23*12/100)) -> 0 | S23: =Q23+R23 -> 0 | V23: 12000 | W23: 42723 | X23: NANKAM APPOLINAIRE
A24: AS201619 | B24: =VLOOKUP(A24,LISTADHERENT!A$5:H$51,2) -> KOUATCHO MESSACK | C24: =VLOOKUP(A24,FONDSDECAISSE!A$5:O$52,15,0) -> 420000 | D24: 3818 | E24: =$R$56/$F$56*F24 -> 245.45492 | F24: =C24+D24+L24 -> 426818 | H24: =IF(J24="ECHEC",0,13000) -> 13000 | I24: =IF(J24="ESPECES",1000,0) -> 1000 | J24: ESPECES | K24: =IF(H24=0,0,H24+L24+M24+N24+O24+P24) -> 20000 | L24: 3000 | M24: 500 | N24: 1000 | O24: 2500 | R24: =IF(Q24<=500000,(Q24*1*3/100),(Q24*12/100)) -> 0 | S24: =Q24+R24 -> 0
A25: AS201620 | B25: =VLOOKUP(A25,LISTADHERENT!A$5:H$51,2) -> LOWE JEAN | C25: =VLOOKUP(A25,FONDSDECAISSE!A$5:O$52,15,0) -> 420000 | D25: 2652 | E25: =$R$56/$F$56*F25 -> 244.78437 | F25: =C25+D25+L25 -> 425652 | H25: =IF(J25="ECHEC",0,13000) -> 13000 | I25: =IF(J25="ESPECES",1000,0) -> 0 | J25: BANQUE | K25: =IF(H25=0,0,H25+L25+M25+N25+O25+P25) -> 20000 | L25: 3000 | M25: 500 | N25: 1000 | O25: 2500 | R25: =IF(Q25<=500000,(Q25*1*3/100),(Q25*12/100)) -> 0 | S25: 82400
A26: AS201621 | B26: =VLOOKUP(A26,LISTADHERENT!A$5:H$51,2) -> NANKAM APPOLINAIRE | C26: =VLOOKUP(A26,FONDSDECAISSE!A$5:O$52,15,0) -> 420000 | D26: 2741 | E26: =$R$56/$F$56*F26 -> 244.83556 | F26: =C26+D26+L26 -> 425741 | H26: =IF(J26="ECHEC",0,13000) -> 13000 | I26: =IF(J26="ESPECES",1000,0) -> 0 | J26: BANQUE | K26: =IF(H26=0,0,H26+L26+M26+N26+O26+P26) -> 20000 | L26: 3000 | M26: 500 | N26: 1000 | O26: 2500 | R26: =IF(Q26<=500000,(Q26*1*3/100),(Q26*12/100)) -> 0 | S26: =Q26+R26 -> 0
A27: AS201622 | B27: =VLOOKUP(A27,LISTADHERENT!A$5:H$51,2) -> NDJOMO ETIENNE | C27: =VLOOKUP(A27,FONDSDECAISSE!A$5:O$52,15,0) -> 420000 | D27: 2818 | E27: =$R$56/$F$56*F27 -> 247.75524 | F27: =C27+D27+L27 -> 430818 | H27: =IF(J27="ECHEC",0,13000) -> 13000 | I27: =IF(J27="ESPECES",1000,0) -> 0 | J27: BANQUE | K27: =IF(H27=0,0,H27+L27+M27+N27+O27+P27) -> 25000 | L27: 8000 | M27: 500 | N27: 1000 | O27: 2500 | Q27: 400000 | R27: =IF(Q27<=500000,(Q27*1*3/100),(Q27*12/100)) -> 12000 | S27: 412000
A28: AS201623 | B28: =VLOOKUP(A28,LISTADHERENT!A$5:H$51,2) -> NDOMBOU JEAN CLAUDE | C28: =VLOOKUP(A28,FONDSDECAISSE!A$5:O$52,15,0) -> 420000 | D28: 0 | E28: =$R$56/$F$56*F28 -> 241.53402 | F28: =C28+D28+L28 -> 420000 | R28: =IF(Q28<=500000,(Q28*1*3/100),(Q28*12/100)) -> 0 | S28: =Q28+R28 -> 0
A29: AS201624 | B29: =VLOOKUP(A29,LISTADHERENT!A$5:H$51,2) -> NGONDIEP CLAUDE | C29: =VLOOKUP(A29,FONDSDECAISSE!A$5:O$52,15,0) -> 420000 | D29: 3250 | E29: =$R$56/$F$56*F29 -> 245.12827 | F29: =C29+D29+L29 -> 426250 | H29: =IF(J29="ECHEC",0,13000) -> 13000 | I29: =IF(J29="ESPECES",1000,0) -> 0 | J29: BANQUE | K29: =IF(H29=0,0,H29+L29+M29+N29+O29+P29) -> 20000 | L29: 3000 | M29: 500 | N29: 1000 | O29: 2500 | R29: =IF(Q29<=500000,(Q29*1*3/100),(Q29*12/100)) -> 0 | S29: =Q29+R29 -> 0
A30: AS201625 | B30: =VLOOKUP(A30,LISTADHERENT!A$5:H$51,2) -> NGONGANG JEAN THEODORE | C30: =VLOOKUP(A30,FONDSDECAISSE!A$5:O$52,15,0) -> 0 | D30: 106 | E30: =$R$56/$F$56*F30 -> 1.7862016 | F30: =C30+D30+L30 -> 3106 | H30: =IF(J30="ECHEC",0,13000) -> 13000 | I30: =IF(J30="ESPECES",1000,0) -> 0 | J30: BANQUE | K30: =IF(H30=0,0,H30+L30+M30+N30+O30+P30) -> 20000 | L30: 3000 | M30: 500 | N30: 1000 | O30: 2500 | R30: =IF(Q30<=500000,(Q30*1*3/100),(Q30*12/100)) -> 0 | S30: =Q30+R30 -> 0
A31: AS201626 | B31: =VLOOKUP(A31,LISTADHERENT!A$5:H$51,2) -> NGUIEMEGNI MATHIEU BLAISE | C31: =VLOOKUP(A31,FONDSDECAISSE!A$5:O$52,15,0) -> 420000 | D31: =565188-420000-50000-55055 -> 40133 | E31: =$R$56/$F$56*F31 -> 266.33899 | F31: =C31+D31+L31 -> 463133 | H31: =IF(J31="ECHEC",0,13000) -> 13000 | I31: =IF(J31="ESPECES",1000,0) -> 0 | J31: BANQUE | K31: =IF(H31=0,0,H31+L31+M31+N31+O31+P31) -> 20000 | L31: 3000 | M31: 500 | N31: 1000 | O31: 2500 | R31: =IF(Q31<=500000,(Q31*1*3/100),(Q31*12/100)) -> 0 | S31: =Q31+R31 -> 0
A32: AS201627 | B32: =VLOOKUP(A32,LISTADHERENT!A$5:H$51,2) -> NJEPDJIO MBOUKAM DELUXE | C32: =VLOOKUP(A32,FONDSDECAISSE!A$5:O$52,15,0) -> 420000 | D32: 2773 | E32: =$R$56/$F$56*F32 -> 244.85396 | F32: =C32+D32+L32 -> 425773 | H32: =IF(J32="ECHEC",0,13000) -> 13000 | I32: =IF(J32="ESPECES",1000,0) -> 0 | J32: BANQUE | K32: =IF(H32=0,0,H32+L32+M32+N32+O32+P32) -> 20000 | L32: 3000 | M32: 500 | N32: 1000 | O32: 2500 | R32: =IF(Q32<=500000,(Q32*1*3/100),(Q32*12/100)) -> 0 | S32: =Q32+R32 -> 0
A33: AS201628 | B33: =VLOOKUP(A33,LISTADHERENT!A$5:H$51,2) -> NKAMGANG JUSTIN DEJOLIE | C33: =VLOOKUP(A33,FONDSDECAISSE!A$5:O$52,15,0) -> 420000 | D33: =14208+55600 -> 69808 | E33: =$R$56/$F$56*F33 -> 285.12976 | F33: =C33+D33+L33 -> 495808 | H33: =IF(J33="ECHEC",0,13000) -> 13000 | I33: =IF(J33="ESPECES",1000,0) -> 1000 | J33: ESPECES | K33: =IF(H33=0,0,H33+L33+M33+N33+O33+P33) -> 23000 | L33: =6000 -> 6000 | M33: 500 | N33: 1000 | O33: 2500 | R33: =IF(Q33<=500000,(Q33*1*3/100),(Q33*12/100)) -> 0 | S33: =Q33+R33 -> 0
A34: AS201629 | B34: =VLOOKUP(A34,LISTADHERENT!A$5:H$51,2) -> NKEPSEU DIEUDONNE | C34: =VLOOKUP(A34,FONDSDECAISSE!A$5:O$52,15,0) -> 420000 | D34: 2772 | E34: =$R$56/$F$56*F34 -> 305.23689 | F34: =C34+D34+L34 -> 530772 | H34: =IF(J34="ECHEC",0,13000) -> 13000 | I34: =IF(J34="ESPECES",1000,0) -> 1000 | J34: ESPECES | K34: =IF(H34=0,0,H34+L34+M34+N34+O34+P34) -> 125000 | L34: 108000 | M34: 500 | N34: 1000 | O34: 2500 | R34: =IF(Q34<=500000,(Q34*1*3/100),(Q34*12/100)) -> 0 | S34: =Q34+R34 -> 0
D35: 0 | E35: =$R$56/$F$56*F35 -> 0 | F35: =C35+D35+L35 -> 0 | R35: =IF(Q35<=500000,(Q35*1*3/100),(Q35*12/100)) -> 0 | S35: =Q35+R35 -> 0
A36: AS201631 | B36: =VLOOKUP(A36,LISTADHERENT!A$5:H$51,2) -> NTEPDIE TUEMAC MZ | C36: =VLOOKUP(A36,FONDSDECAISSE!A$5:O$52,15,0) -> 0 | E36: =$R$56/$F$56*F36 -> 0 | F36: =C36+D36+L36 -> 0 | H36: =IF(J36="ECHEC",0,13000) -> 0 | I36: =IF(J36="ESPECES",1000,0) -> 0 | J36: ECHEC | K36: =IF(H36=0,0,H36+L36+M36+N36+O36+P36) -> 0 | R36: =IF(Q36<=500000,(Q36*1*3/100),(Q36*12/100)) -> 0 | S36: =Q36+R36 -> 0
D37: 0 | E37: =$R$56/$F$56*F37 -> 0 | F37: =C37+D37+L37 -> 0 | R37: =IF(Q37<=500000,(Q37*1*3/100),(Q37*12/100)) -> 0 | S37: =Q37+R37 -> 0
A38: AS201633 | B38: =VLOOKUP(A38,LISTADHERENT!A$5:H$51,2) -> PATEGO NJOSSU GUSTAVE | C38: =VLOOKUP(A38,FONDSDECAISSE!A$5:O$52,15,0) -> 420000 | D38: 2474 | E38: =$R$56/$F$56*F38 -> 244.68201 | F38: =C38+D38+L38 -> 425474 | H38: =IF(J38="ECHEC",0,13000) -> 13000 | I38: =IF(J38="ESPECES",1000,0) -> 0 | J38: BANQUE | K38: =IF(H38=0,0,H38+L38+M38+N38+O38+P38) -> 20000 | L38: 3000 | M38: 500 | N38: 1000 | O38: 2500 | R38: =IF(Q38<=500000,(Q38*1*3/100),(Q38*12/100)) -> 0 | S38: =Q38+R38 -> 0
A39: AS201634 | B39: =VLOOKUP(A39,LISTADHERENT!A$5:H$51,2) -> SEUNOU RICHELOT | C39: =VLOOKUP(A39,FONDSDECAISSE!A$5:O$52,15,0) -> 420000 | D39: 6756 | E39: =$R$56/$F$56*F39 -> 247.14451 | F39: =C39+D39+L39 -> 429756 | H39: =IF(J39="ECHEC",0,13000) -> 13000 | I39: =IF(J39="ESPECES",1000,0) -> 1000 | J39: ESPECES | K39: =IF(H39=0,0,H39+L39+M39+N39+O39+P39) -> 20000 | L39: 3000 | M39: 500 | N39: 1000 | O39: 2500 | R39: =IF(Q39<=500000,(Q39*1*3/100),(Q39*12/100)) -> 0 | S39: =Q39+R39 -> 0 | V39: 12000 | W39: 42723 | X39: NDJOMO ETIENNE
A40: AS201635 | B40: =VLOOKUP(A40,LISTADHERENT!A$5:H$51,2) -> SIME ABEL | C40: =VLOOKUP(A40,FONDSDECAISSE!A$5:O$52,15,0) -> 390000 | D40: 488 | E40: =$R$56/$F$56*F40 -> 226.28747 | F40: =C40+D40+L40 -> 393488 | H40: =IF(J40="ECHEC",0,13000) -> 13000 | I40: =IF(J40="ESPECES",1000,0) -> 1000 | J40: ESPECES | K40: =IF(H40=0,0,H40+L40+M40+N40+O40+P40) -> 20000 | L40: 3000 | M40: 500 | N40: 1000 | O40: 2500 | R40: =IF(Q40<=500000,(Q40*1*3/100),(Q40*12/100)) -> 0 | S40: =Q40+R40 -> 0
...

Sheet TONT20000JANV2017
A1: ASSOCIATION | B1: ASELBY
A2: ANNEE | B2: 2016/2017
A3: TONTINE | B3: 20 000
A4: MATRICULE | B4: NOM ET PRENOM | C4: REPARTITION INTERET | D4: CAPITAL COMPOSE | E4: SANCTION | F4: MONTANT TONTINE | G4: PENALITE | H4: MODE VERSEMENT | I4: MONTANT VERSE | J4: EPARGNE | K4: FONDS DE ROULEMENT | L4: FRAIS EXCEPTIONNEL | M4: COLLATION | N4: MUTUELLE | O4: EMPRUNT | P4: INTERET EMPRUNT | Q4: REMBOURSEMENT | R4: PENALITE EMPRUNT | S4: PENALITE FONDS | T4: INTERET ACHAT | U4: DATE ACHAT | V4: AVALISTE
A5: AS201648 | B5: =VLOOKUP(A5,LISTADHERENT!A$5:H$52,2,0) -> ASELBY | C5: =$P$56/$D$56*D5 -> 0 | D5: =TONT20000DEC2016!F5+TONT20000DEC2016!E5+TONT20000JANV2017!J5 -> 355301.21
A6: AS201601 | B6: =VLOOKUP(A6,LISTADHERENT!A$5:H$52,2,0) -> BAKOP ACHILLE | C6: =$P$56/$D$56*D6 -> 0 | D6: =TONT20000DEC2016!F6+TONT20000DEC2016!E6+TONT20000JANV2017!J6 -> 472264.43 | F6: =IF(H6="ECHEC",0,13000) -> 0 | G6: =IF(H6="ESPECES",1000,0) -> 0 | H6: ECHEC | I6: =IF(F6=0,0,J6+K6+L6+M6+N6+#REF!) -> 0 | P6: =IF(O6<=500000,(O6*1*3/100),(O6*12/100)) -> 0
A7: AS201602 | B7: =VLOOKUP(A7,LISTADHERENT!A$5:H$51,2) -> BOUTCHOUANG WILLIAM | C7: =$P$56/$D$56*D7 -> 0 | D7: =TONT20000DEC2016!F7+TONT20000DEC2016!E7+TONT20000JANV2017!J7 -> 428964.82 | F7: =IF(H7="ECHEC",0,13000) -> 13000 | G7: =IF(H7="ESPECES",1000,0) -> 1000 | H7: ESPECES | I7: =IF(F7=0,0,F7+J7+K7+L7+M7+N7) -> 20000 | J7: 3000 | K7: 500 | L7: 1000 | M7: 2500 | P7: =IF(O7<=500000,(O7*1*3/100),(O7*12/100)) -> 0
A8: AS201603 | B8: =VLOOKUP(A8,LISTADHERENT!A$5:H$51,2) -> CHINGUE FABRICE | C8: =$P$56/$D$56*D8 -> 0 | D8: =TONT20000DEC2016!F8+TONT20000DEC2016!E8+TONT20000JANV2017!J8 -> 432120.64 | F8: =IF(H8="ECHEC",0,13000) -> 13000 | G8: =IF(H8="ESPECES",1000,0) -> 1000 | H8: ESPECES | I8: =IF(F8=0,0,F8+J8+K8+L8+M8+N8) -> 20000 | J8: 3000 | K8: 500 | L8: 1000 | M8: 2500 | P8: =IF(O8<=500000,(O8*1*3/100),(O8*12/100)) -> 0
A9: AS201604 | B9: =VLOOKUP(A9,LISTADHERENT!A$5:H$51,2) -> DJOMO JEAN PAUL | C9: =$P$56/$D$56*D9 -> 0 | D9: =TONT20000DEC2016!F9+TONT20000DEC2016!E9+TONT20000JANV2017!J9 -> 428814.74 | F9: =IF(H9="ECHEC",0,13000) -> 13000 | G9: =IF(H9="ESPECES",1000,0) -> 0 | H9: BANQUE | I9: =IF(F9=0,0,F9+J9+K9+L9+M9+N9) -> 20000 | J9: 3000 | K9: 500 | L9: 1000 | M9: 2500 | P9: =IF(O9<=500000,(O9*1*3/100),(O9*12/100)) -> 0
A10: AS201605 | B10: =VLOOKUP(A10,LISTADHERENT!A$5:H$51,2) -> DJOUKWE NANGUEN GUY BLAISE | C10: =$P$56/$D$56*D10 -> 0 | D10: =TONT20000DEC2016!F10+TONT20000DEC2016!E10+TONT20000JANV2017!J10 -> 428941.81 | F10: =IF(H10="ECHEC",0,13000) -> 13000 | G10: =IF(H10="ESPECES",1000,0) -> 1000 | H10: ESPECES | I10: =IF(F10=0,0,F10+J10+K10+L10+M10+N10) -> 20000 | J10: 3000 | K10: 500 | L10: 1000 | M10: 2500 | P10: =IF(O10<=500000,(O10*1*3/100),(O10*12/100)) -> 0
D11: =TONT20000DEC2016!F11+TONT20000DEC2016!E11+TONT20000JANV2017!J11 -> 0
A12: AS201607 | B12: =VLOOKUP(A12,LISTADHERENT!A$5:H$51,2) -> DJOUNKEP SAMUEL | C12: =$P$56/$D$56*D12 -> 0 | D12: =TONT20000DEC2016!F12+TONT20000DEC2016!E12+TONT20000JANV2017!J12 -> 1062148.7 | F12: =IF(H12="ECHEC",0,13000) -> 13000 | G12: =IF(H12="ESPECES",1000,0) -> 0 | H12: BANQUE | I12: =IF(F12=0,0,F12+J12+K12+L12+M12+N12) -> 20000 | J12: 3000 | K12: 500 | L12: 1000 | M12: 2500 | P12: =IF(O12<=500000,(O12*1*3/100),(O12*12/100)) -> 0
A13: AS201608 | B13: =VLOOKUP(A13,LISTADHERENT!A$5:H$51,2) -> DJUOMBESSY ANTOINE | C13: =$P$56/$D$56*D13 -> 0 | D13: =TONT20000DEC2016!F13+TONT20000DEC2016!E13+TONT20000JANV2017!J13 -> 428990.84 | F13: =IF(H13="ECHEC",0,13000) -> 13000 | G13: =IF(H13="ESPECES",1000,0) -> 0 | H13: BANQUE | I13: =IF(F13=0,0,F13+J13+K13+L13+M13+N13) -> 20000 | J13: 3000 | K13: 500 | L13: 1000 | M13: 2500 | P13: =IF(O13<=500000,(O13*1*3/100),(O13*12/100)) -> 0
A14: AS201609 | B14: =VLOOKUP(A14,LISTADHERENT!A$5:H$51,2) -> DONHOU DAVID | C14: =$P$56/$D$56*D14 -> 0 | D14: =TONT20000DEC2016!F14+TONT20000DEC2016!E14+TONT20000JANV2017!J14 -> 480022.17 | F14: =IF(H14="ECHEC",0,13000) -> 13000 | G14: =IF(H14="ESPECES",1000,0) -> 1000 | H14: ESPECES | I14: =IF(F14=0,0,F14+J14+K14+L14+M14+N14) -> 20000 | J14: 3000 | K14: 500 | L14: 1000 | M14: 2500 | P14: =IF(O14<=500000,(O14*1*3/100),(O14*12/100)) -> 0
A15: AS201610 | B15: =VLOOKUP(A15,LISTADHERENT!A$5:H$51,2) -> FOTSO THOMAS | C15: =$P$56/$D$56*D15 -> 0 | D15: =TONT20000DEC2016!F15+TONT20000DEC2016!E15+TONT20000JANV2017!J15 -> 428766.71 | F15: =IF(H15="ECHEC",0,13000) -> 13000 | G15: =IF(H15="ESPECES",1000,0) -> 1000 | H15: ESPECES | I15: =IF(F15=0,0,F15+J15+K15+L15+M15+N15) -> 20000 | J15: 3000 | K15: 500 | L15: 1000 | M15: 2500 | P15: =IF(O15<=500000,(O15*1*3/100),(O15*12/100)) -> 0
A16: AS201611 | B16: =VLOOKUP(A16,LISTADHERENT!A$5:H$51,2) -> HENGUE PAUL OMER | C16: =$P$56/$D$56*D16 -> 0 | D16: =TONT20000DEC2016!F16+TONT20000DEC2016!E16+TONT20000JANV2017!J16 -> 492281.21 | F16: 13000 | G16: =IF(H16="ESPECES",1000,0) -> 1000 | H16: ESPECES | I16: =IF(F16=0,0,F16+J16+K16+L16+M16+N16) -> 20000 | J16: 3000 | K16: 500 | L16: 1000 | M16: 2500 | P16: =IF(O16<=500000,(O16*1*3/100),(O16*12/100)) -> 0
A17: AS201612 | B17: =VLOOKUP(A17,LISTADHERENT!A$5:H$51,2) -> HODIEP JULES | C17: =$P$56/$D$56*D17 -> 0 | D17: =TONT20000DEC2016!F17+TONT20000DEC2016!E17+TONT20000JANV2017!J17 -> 50288.904 | F17: =IF(H17="ECHEC",0,13000) -> 0 | G17: =IF(H17="ESPECES",1000,0) -> 0 | H17: ECHEC | I17: =IF(F17=0,0,F17+J17+K17+L17+M17+N17) -> 0 | P17: =IF(O17<=500000,(O17*1*3/100),(O17*12/100)) -> 0
A18: AS201613 | B18: =VLOOKUP(A18,LISTADHERENT!A$5:H$51,2) -> HOTCHO BENJAMIN | C18: =$P$56/$D$56*D18 -> 0 | D18: =TONT20000DEC2016!F18+TONT20000DEC2016!E18+TONT20000JANV2017!J18 -> 538993.06 | F18: =IF(H18="ECHEC",0,13000) -> 13000 | G18: =IF(H18="ESPECES",1000,0) -> 0 | H18: BANQUE | I18: =IF(F18=0,0,F18+J18+K18+L18+M18+N18) -> 20000 | J18: 3000 | K18: 500 | L18: 1000 | M18: 2500 | P18: =IF(O18<=500000,(O18*1*3/100),(O18*12/100)) -> 0
A19: AS201614 | B19: =VLOOKUP(A19,LISTADHERENT!A$5:H$51,2) -> KEPHE DAVID | C19: =$P$56/$D$56*D19 -> 0 | D19: =TONT20000DEC2016!F19+TONT20000DEC2016!E19+TONT20000JANV2017!J19 -> 106236.34 | F19: =IF(H19="ECHEC",0,13000) -> 13000 | G19: =IF(H19="ESPECES",1000,0) -> 0 | H19: BANQUE | I19: =IF(F19=0,0,F19+J19+K19+L19+M19+N19) -> 20000 | J19: 3000 | K19: 500 | L19: 1000 | M19: 2500 | P19: =IF(O19<=500000,(O19*1*3/100),(O19*12/100)) -> 0
A20: AS201615 | B20: =VLOOKUP(A20,LISTADHERENT!A$5:H$51,2) -> KEPSEU FRANCIS | C20: =$P$56/$D$56*D20 -> 0 | D20: =TONT20000DEC2016!F20+TONT20000DEC2016!E20+TONT20000JANV2017!J20 -> 2138650.7 | F20: =IF(H20="ECHEC",0,13000) -> 13000 | G20: =IF(H20="ESPECES",1000,0) -> 0 | H20: BANQUE | I20: =IF(F20=0,0,F20+J20+K20+L20+M20+N20) -> 23000 | J20: 6000 | K20: 500 | L20: 1000 | M20: 2500 | P20: =IF(O20<=500000,(O20*1*3/100),(O20*12/100)) -> 0
A21: AS201616 | B21: =VLOOKUP(A21,LISTADHERENT!A$5:H$51,2) -> KOUAMOU EMMANUEL | C21: =$P$56/$D$56*D21 -> 0 | D21: =TONT20000DEC2016!F21+TONT20000DEC2016!E21+TONT20000JANV2017!J21 -> 428601.61 | F21: =IF(H21="ECHEC",0,13000) -> 13000 | G21: =IF(H21="ESPECES",1000,0) -> 0 | H21: BANQUE | I21: =IF(F21=0,0,F21+J21+K21+L21+M21+N21) -> 20000 | J21: 3000 | K21: 500 | L21: 1000 | M21: 2500 | P21: =IF(O21<=500000,(O21*1*3/100),(O21*12/100)) -> 0
A22: AS201617 | B22: =VLOOKUP(A22,LISTADHERENT!A$5:H$51,2) -> KOUAMOU MOISE | C22: =$P$56/$D$56*D22 -> 0 | D22: =TONT20000DEC2016!F22+TONT20000DEC2016!E22+TONT20000JANV2017!J22 -> 429293.01 | F22: =IF(H22="ECHEC",0,13000) -> 13000 | G22: =IF(H22="ESPECES",1000,0) -> 0 | H22: BANQUE | I22: =IF(F22=0,0,F22+J22+K22+L22+M22+N22) -> 20000 | J22: 3000 | K22: 500 | L22: 1000 | M22: 2500 | P22: =IF(O22<=500000,(O22*1*3/100),(O22*12/100)) -> 0
A23: AS201618 | B23: =VLOOKUP(A23,LISTADHERENT!A$5:H$51,2) -> KOUAMO VICTOR PEGUY | C23: =$P$56/$D$56*D23 -> 0 | D23: =TONT20000DEC2016!F23+TONT20000DEC2016!E23+TONT20000JANV2017!J23 -> 428930.8 | F23: =IF(H23="ECHEC",0,13000) -> 13000 | G23: =IF(H23="ESPECES",1000,0) -> 1000 | H23: ESPECES | I23: =IF(F23=0,0,F23+J23+K23+L23+M23+N23) -> 20000 | J23: 3000 | K23: 500 | L23: 1000 | M23: 2500 | P23: =IF(O23<=500000,(O23*1*3/100),(O23*12/100)) -> 0
A24: AS201619 | B24: =VLOOKUP(A24,LISTADHERENT!A$5:H$51,2) -> KOUATCHO MESSACK | C24: =$P$56/$D$56*D24 -> 0 | D24: =TONT20000DEC2016!F24+TONT20000DEC2016!E24+TONT20000JANV2017!J24 -> 430063.45 | F24: =IF(H24="ECHEC",0,13000) -> 13000 | G24: =IF(H24="ESPECES",1000,0) -> 1000 | H24: ESPECES | I24: =IF(F24=0,0,F24+J24+K24+L24+M24+N24) -> 20000 | J24: 3000 | K24: 500 | L24: 1000 | M24: 2500 | P24: =IF(O24<=500000,(O24*1*3/100),(O24*12/100)) -> 0
A25: AS201620 | B25: =VLOOKUP(A25,LISTADHERENT!A$5:H$51,2) -> LOWE JEAN | C25: =$P$56/$D$56*D25 -> 0 | D25: =TONT20000DEC2016!F25+TONT20000DEC2016!E25+TONT20000JANV2017!J25 -> 428896.78 | F25: =IF(H25="ECHEC",0,13000) -> 13000 | G25: =IF(H25="ESPECES",1000,0) -> 0 | H25: BANQUE | I25: =IF(F25=0,0,F25+J25+K25+L25+M25+N25) -> 20000 | J25: 3000 | K25: 500 | L25: 1000 | M25: 2500 | P25: =IF(O25<=500000,(O25*1*3/100),(O25*12/100)) -> 0
A26: AS201621 | B26: =VLOOKUP(A26,LISTADHERENT!A$5:H$51,2) -> NANKAM APPOLINAIRE | C26: =$P$56/$D$56*D26 -> 0 | D26: =TONT20000DEC2016!F26+TONT20000DEC2016!E26+TONT20000JANV2017!J26 -> 428985.84 | F26: =IF(H26="ECHEC",0,13000) -> 13000 | G26: =IF(H26="ESPECES",1000,0) -> 0 | H26: BANQUE | I26: =IF(F26=0,0,F26+J26+K26+L26+M26+N26) -> 20000 | J26: 3000 | K26: 500 | L26: 1000 | M26: 2500 | P26: =IF(O26<=500000,(O26*1*3/100),(O26*12/100)) -> 0
A27: AS201622 | B27: =VLOOKUP(A27,LISTADHERENT!A$5:H$51,2) -> NDJOMO ETIENNE | C27: =$P$56/$D$56*D27 -> 0 | D27: =TONT20000DEC2016!F27+TONT20000DEC2016!E27+TONT20000JANV2017!J27 -> 439065.76 | F27: =IF(H27="ECHEC",0,13000) -> 13000 | G27: =IF(H27="ESPECES",1000,0) -> 0 | H27: BANQUE | I27: =IF(F27=0,0,F27+J27+K27+L27+M27+N27) -> 25000 | J27: 8000 | K27: 500 | L27: 1000 | M27: 2500 | P27: =IF(O27<=500000,(O27*1*3/100),(O27*12/100)) -> 0
A28: AS201623 | B28: =VLOOKUP(A28,LISTADHERENT!A$5:H$51,2) -> NDOMBOU JEAN CLAUDE | C28: =$P$56/$D$56*D28 -> 0 | D28: =TONT20000DEC2016!F28+TONT20000DEC2016!E28+TONT20000JANV2017!J28 -> 420241.53
A29: AS201624 | B29: =VLOOKUP(A29,LISTADHERENT!A$5:H$51,2) -> NGONDIEP CLAUDE | C29: =$P$56/$D$56*D29 -> 0 | D29: =TONT20000DEC2016!F29+TONT20000DEC2016!E29+TONT20000JANV2017!J29 -> 438495.13 | F29: =IF(H29="ECHEC",0,13000) -> 13000 | G29: =IF(H29="ESPECES",1000,0) -> 0 | H29: BANQUE | I29: =IF(F29=0,0,F29+J29+K29+L29+M29+N29) -> 29000 | J29: 12000 | K29: 500 | L29: 1000 | M29: 2500 | P29: =IF(O29<=500000,(O29*1*3/100),(O29*12/100)) -> 0
A30: AS201625 | B30: =VLOOKUP(A30,LISTADHERENT!A$5:H$51,2) -> NGONGANG JEAN THEODORE | C30: =$P$56/$D$56*D30 -> 0 | D30: =TONT20000DEC2016!F30+TONT20000DEC2016!E30+TONT20000JANV2017!J30 -> 3107.7862 | F30: =IF(H30="ECHEC",0,13000) -> 0 | G30: =IF(H30="ESPECES",1000,0) -> 0 | H30: ECHEC | I30: =IF(F30=0,0,F30+J30+K30+L30+M30+N30) -> 0 | P30: =IF(O30<=500000,(O30*1*3/100),(O30*12/100)) -> 0
A31: AS201626 | B31: =VLOOKUP(A31,LISTADHERENT!A$5:H$51,2) -> NGUIEMEGNI MATHIEU BLAISE | C31: =$P$56/$D$56*D31 -> 0 | D31: =TONT20000DEC2016!F31+TONT20000DEC2016!E31+TONT20000JANV2017!J31 -> 466399.34 | F31: =IF(H31="ECHEC",0,13000) -> 13000 | G31: =IF(H31="ESPECES",1000,0) -> 0 | H31: BANQUE | I31: =IF(F31=0,0,F31+J31+K31+L31+M31+N31) -> 20000 | J31: 3000 | K31: 500 | L31: 1000 | M31: 2500 | P31: =IF(O31<=500000,(O31*1*3/100),(O31*12/100)) -> 0
A32: AS201627 | B32: =VLOOKUP(A32,LISTADHERENT!A$5:H$51,2) -> NJEPDJIO MBOUKAM DELUXE | C32: =$P$56/$D$56*D32 -> 0 | D32: =TONT20000DEC2016!F32+TONT20000DEC2016!E32+TONT20000JANV2017!J32 -> 434017.85 | F32: =IF(H32="ECHEC",0,13000) -> 13000 | G32: =IF(H32="ESPECES",1000,0) -> 1000 | H32: ESPECES | I32: =IF(F32=0,0,F32+J32+K32+L32+M32+N32) -> 25000 | J32: 8000 | K32: 500 | L32: 1000 | M32: 2500 | P32: =IF(O32<=500000,(O32*1*3/100),(O32*12/100)) -> 0
A33: AS201628 | B33: =VLOOKUP(A33,LISTADHERENT!A$5:H$51,2) -> NKAMGANG JUSTIN DEJOLIE | C33: =$P$56/$D$56*D33 -> 0 | D33: =TONT20000DEC2016!F33+TONT20000DEC2016!E33+TONT20000JANV2017!J33 -> 504093.13 | F33: =IF(H33="ECHEC",0,13000) -> 13000 | G33: =IF(H33="ESPECES",1000,0) -> 1000 | H33: ESPECES | I33: =IF(F33=0,0,F33+J33+K33+L33+M33+N33) -> 25000 | J33: 8000 | K33: 500 | L33: 1000 | M33: 2500 | P33: =IF(O33<=500000,(O33*1*3/100),(O33*12/100)) -> 0
A34: AS201629 | B34: =VLOOKUP(A34,LISTADHERENT!A$5:H$51,2) -> NKEPSEU DIEUDONNE | C34: =$P$56/$D$56*D34 -> 0 | D34: =TONT20000DEC2016!F34+TONT20000DEC2016!E34+TONT20000JANV2017!J34 -> 539077.24 | F34: =IF(H34="ECHEC",0,13000) -> 13000 | G34: =IF(H34="ESPECES",1000,0) -> 1000 | H34: ESPECES | I34: =IF(F34=0,0,F34+J34+K34+L34+M34+N34) -> 25000 | J34: 8000 | K34: 500 | L34: 1000 | M34: 2500 | P34: =IF(O34<=500000,(O34*1*3/100),(O34*12/100)) -> 0
D35: =TONT20000DEC2016!F35+TONT20000DEC2016!E35+TONT20000JANV2017!J35 -> 0
A36: AS201631 | B36: =VLOOKUP(A36,LISTADHERENT!A$5:H$51,2) -> NTEPDIE TUEMAC MZ | C36: =$P$56/$D$56*D36 -> 0 | D36: =TONT20000DEC2016!F36+TONT20000DEC2016!E36+TONT20000JANV2017!J36 -> 0 | F36: =IF(H36="ECHEC",0,13000) -> 0 | G36: =IF(H36="ESPECES",1000,0) -> 0 | H36: ECHEC | I36: =IF(F36=0,0,F36+J36+K36+L36+M36+N36) -> 0 | P36: =IF(O36<=500000,(O36*1*3/100),(O36*12/100)) -> 0
D37: =TONT20000DEC2016!F37+TONT20000DEC2016!E37+TONT20000JANV2017!J37 -> 0
A38: AS201633 | B38: =VLOOKUP(A38,LISTADHERENT!A$5:H$51,2) -> PATEGO NJOSSU GUSTAVE | C38: =$P$56/$D$56*D38 -> 0 | D38: =TONT20000DEC2016!F38+TONT20000DEC2016!E38+TONT20000JANV2017!J38 -> 428718.68 | F38: =IF(H38="ECHEC",0,13000) -> 13000 | G38: =IF(H38="ESPECES",1000,0) -> 0 | H38: BANQUE | I38: =IF(F38=0,0,F38+J38+K38+L38+M38+N38) -> 20000 | J38: 3000 | K38: 500 | L38: 1000 | M38: 2500 | P38: =IF(O38<=500000,(O38*1*3/100),(O38*12/100)) -> 0
A39: AS201634 | B39: =VLOOKUP(A39,LISTADHERENT!A$5:H$51,2) -> SEUNOU RICHELOT | C39: =$P$56/$D$56*D39 -> 0 | D39: =TONT20000DEC2016!F39+TONT20000DEC2016!E39+TONT20000JANV2017!J39 -> 433003.14 | F39: =IF(H39="ECHEC",0,13000) -> 13000 | G39: =IF(H39="ESPECES",1000,0) -> 1000 | H39: ESPECES | I39: =IF(F39=0,0,F39+J39+K39+L39+M39+N39) -> 20000 | J39: 3000 | K39: 500 | L39: 1000 | M39: 2500 | P39: =IF(O39<=500000,(O39*1*3/100),(O39*12/100)) -> 0
A40: AS201635 | B40: =VLOOKUP(A40,LISTADHERENT!A$5:H$51,2) -> SIME ABEL | C40: =$P$56/$D$56*D40 -> 0 | D40: =TONT20000DEC2016!F40+TONT20000DEC2016!E40+TONT20000JANV2017!J40 -> 396714.29 | F40: =IF(H40="ECHEC",0,13000) -> 13000 | G40: =IF(H40="ESPECES",1000,0) -> 1000 | H40: ESPECES | I40: =IF(F40=0,0,F40+J40+K40+L40+M40+N40) -> 20000 | J40: 3000 | K40: 500 | L40: 1000 | M40: 2500 | P40: =IF(O40<=500000,(O40*1*3/100),(O40*12/100)) -> 0
...

Sheet TONT20000FEV2017
A1: ASSOCIATION | B1: ASELBY
A2: ANNEE | B2: 2016/2017
A3: TONTINE | B3: 20 000
A4: MATRICULE | B4: NOM ET PRENOM | C4: REPARTITION INTERET | D4: CAPITAL COMPOSE | E4: SANCTION | F4: MONTANT TONTINE | G4: PENALITE | H4: MODE VERSEMENT | I4: MONTANT VERSE | J4: EPARGNE | K4: FONDS DE ROULEMENT | L4: FRAIS EXCEPTIONNEL | M4: COLLATION | N4: MUTUELLE | O4: EMPRUNT | P4: INTERET EMPRUNT | Q4: REMBOURSEMENT | R4: PENALITE EMPRUNT | S4: PENALITE FONDS | T4: INTERET ACHAT | U4: DATE ACHAT | V4: AVALISTE
A5: AS201648 | B5: =VLOOKUP(A5,LISTADHERENT!A$5:H$52,2,0) -> ASELBY | C5: =$P$56/$D$56*D5 -> 3977.6928 | D5: =TONT20000JANV2017!C5+TONT20000JANV2017!D5+TONT20000FEV2017!J5 -> 355301.21
A6: AS201601 | B6: =VLOOKUP(A6,LISTADHERENT!A$5:H$52,2,0) -> BAKOP ACHILLE | C6: =$P$56/$D$56*D6 -> 5287.1276 | D6: =TONT20000JANV2017!C6+TONT20000JANV2017!D6+TONT20000FEV2017!J6 -> 472264.43 | F6: =IF(H6="ECHEC",0,13000) -> 0 | G6: =IF(H6="ESPECES",1000,0) -> 0 | H6: ECHEC | I6: =IF(F6=0,0,J6+K6+L6+M6+N6) -> 0 | J6: =IF($F6>=13000,3000,0) -> 0 | K6: =IF($F6>=13000,500,0) -> 0 | L6: =IF($F6>=13000,1000,0) -> 0 | M6: =IF($F6>=13000,2500,0) -> 0 | P6: =IF(O6<=500000,(O6*1*3/100),(O6*12/100)) -> 0
A7: AS201602 | B7: =VLOOKUP(A7,LISTADHERENT!A$5:H$51,2) -> BOUTCHOUANG WILLIAM | C7: =$P$56/$D$56*D7 -> 4835.9626 | D7: =TONT20000JANV2017!C7+TONT20000JANV2017!D7+TONT20000FEV2017!J7 -> 431964.82 | F7: =IF(H7="ECHEC",0,13000) -> 13000 | G7: =IF(H7="ESPECES",1000,0) -> 1000 | H7: ESPECES | I7: =IF(F7=0,0,F7+J7+K7+L7+M7+N7) -> 20000 | J7: =IF($F7>=13000,3000,0) -> 3000 | K7: =IF($F7>=13000,500,0) -> 500 | L7: =IF($F7>=13000,1000,0) -> 1000 | M7: =IF($F7>=13000,2500,0) -> 2500 | P7: =IF(O7<=500000,(O7*1*3/100),(O7*12/100)) -> 0
A8: AS201603 | B8: =VLOOKUP(A8,LISTADHERENT!A$5:H$51,2) -> CHINGUE FABRICE | C8: =$P$56/$D$56*D8 -> 4871.2928 | D8: =TONT20000JANV2017!C8+TONT20000JANV2017!D8+TONT20000FEV2017!J8 -> 435120.64 | F8: =IF(H8="ECHEC",0,13000) -> 13000 | G8: =IF(H8="ESPECES",1000,0) -> 1000 | H8: ESPECES | I8: =IF(F8=0,0,F8+J8+K8+L8+M8+N8) -> 20000 | J8: =IF($F8>=13000,3000,0) -> 3000 | K8: =IF($F8>=13000,500,0) -> 500 | L8: =IF($F8>=13000,1000,0) -> 1000 | M8: =IF($F8>=13000,2500,0) -> 2500 | P8: =IF(O8<=500000,(O8*1*3/100),(O8*12/100)) -> 0
A9: AS201604 | B9: =VLOOKUP(A9,LISTADHERENT!A$5:H$51,2) -> DJOMO JEAN PAUL | C9: =$P$56/$D$56*D9 -> 4912.6492 | D9: =TONT20000JANV2017!C9+TONT20000JANV2017!D9+TONT20000FEV2017!J9 -> 438814.74 | F9: =IF(H9="ECHEC",0,13000) -> 13000 | G9: =IF(H9="ESPECES",1000,0) -> 0 | H9: BANQUE | I9: =IF(F9=0,0,F9+J9+K9+L9+M9+N9) -> 27000 | J9: 10000 | K9: =IF($F9>=13000,500,0) -> 500 | L9: =IF($F9>=13000,1000,0) -> 1000 | M9: =IF($F9>=13000,2500,0) -> 2500 | O9: 1000000 | P9: =IF(O9<=500000,(O9*1*3/100),(O9*12/100)) -> 120000 | Q9: 103000
A10: AS201605 | B10: =VLOOKUP(A10,LISTADHERENT!A$5:H$51,2) -> DJOUKWE NANGUEN GUY BLAISE | C10: =$P$56/$D$56*D10 -> 4880.486 | D10: =TONT20000JANV2017!C10+TONT20000JANV2017!D10+TONT20000FEV2017!J10 -> 435941.81 | F10: =IF(H10="ECHEC",0,13000) -> 13000 | G10: =IF(H10="ESPECES",1000,0) -> 1000 | H10: ESPECES | I10: =IF(F10=0,0,F10+J10+K10+L10+M10+N10) -> 24000 | J10: 7000 | K10: =IF($F10>=13000,500,0) -> 500 | L10: =IF($F10>=13000,1000,0) -> 1000 | M10: =IF($F10>=13000,2500,0) -> 2500 | P10: =IF(O10<=500000,(O10*1*3/100),(O10*12/100)) -> 0
D11: =TONT20000JANV2017!C11+TONT20000JANV2017!D11+TONT20000FEV2017!J11 -> 0 | P11: =IF(O11<=500000,(O11*1*3/100),(O11*12/100)) -> 0
A12: AS201607 | B12: =VLOOKUP(A12,LISTADHERENT!A$5:H$51,2) -> DJOUNKEP SAMUEL | C12: =$P$56/$D$56*D12 -> 11924.627 | D12: =TONT20000JANV2017!C12+TONT20000JANV2017!D12+TONT20000FEV2017!J12 -> 1065148.7 | F12: =IF(H12="ECHEC",0,13000) -> 13000 | G12: =IF(H12="ESPECES",1000,0) -> 0 | H12: BANQUE | I12: =IF(F12=0,0,F12+J12+K12+L12+M12+N12) -> 20000 | J12: 3000 | K12: =IF($F12>=13000,500,0) -> 500 | L12: =IF($F12>=13000,1000,0) -> 1000 | M12: =IF($F12>=13000,2500,0) -> 2500 | P12: =IF(O12<=500000,(O12*1*3/100),(O12*12/100)) -> 0
A13: AS201608 | B13: =VLOOKUP(A13,LISTADHERENT!A$5:H$51,2) -> DJUOMBESSY ANTOINE | C13: =$P$56/$D$56*D13 -> 4836.2538 | D13: =TONT20000JANV2017!C13+TONT20000JANV2017!D13+TONT20000FEV2017!J13 -> 431990.84 | F13: =IF(H13="ECHEC",0,13000) -> 13000 | G13: =IF(H13="ESPECES",1000,0) -> 1000 | H13: ESPECES | I13: =IF(F13=0,0,F13+J13+K13+L13+M13+N13) -> 20000 | J13: =IF($F13>=13000,3000,0) -> 3000 | K13: =IF($F13>=13000,500,0) -> 500 | L13: =IF($F13>=13000,1000,0) -> 1000 | M13: =IF($F13>=13000,2500,0) -> 2500 | P13: =IF(O13<=500000,(O13*1*3/100),(O13*12/100)) -> 0 | Q13: 70000 | T13: 11000 | U13: 42785 | V13: HOTCHO
