Workbook
Name MODEPAID: MODEPAID!$A$1:$A$3
Name MODEPAID: #REF!
Name MODEPAID: #REF!
Name MODEPAID: #REF!
Name MODEPAID: #REF!
Name MODEPAID: #REF!
Name MODEPAID: #REF!
Name MODEPAID: #REF!
Name MODEPAID: #REF!
Name MODEPAID: #REF!
Name MODEPAID: #REF!
Name VALMODEPAID: MODEPAID!$A$1:$A$3

Sheet MODEPAID
A1: BANQUE
A2: ESPECES
A3: ECHEC

Sheet TONTDEC2016
A1: ASSOCIATION | B1: ASELBY
A2: ANNEE | B2: 2016/2017
A3: TONTINE | B3: 100000
C4: 42723
A5: MATRICULE | B5: NOM ET PRENOM | C5: MONTANT TONTINE | D5: PENALITE | E5: MODE VERSEMENT | F5: PRÊT | G5: INTERET PRÊT | H5: REMBOURSEMENT | I5: STATUT PRÊT | J5: INTERET ACHAT | K5: DATE ACHAT
A6: AS201602 | B6: =VLOOKUP(A6,[1]LISTADHERENT!A$5:H$49,2) -> BOUTCHOUANG WILLIAM | C6: =IF(E6="ECHEC",0,100000) -> 100000 | D6: =IF(E6="ESPECES",1000,0) -> 1000 | E6: ESPECES | J6: 200000 | K6: 42694
A7: AS201606 | B7: =VLOOKUP(A7,[1]LISTADHERENT!A$5:H$49,2) -> DJOUNKEP SAMUEL | C7: =IF(E7="ECHEC",0,100000) -> 100000 | D7: =IF(E7="ESPECES",1000,0) -> 0 | E7: BANQUE
A8: AS201607 | B8: =VLOOKUP(A8,[1]LISTADHERENT!A$5:H$49,2) -> DJUOMBESSY ANTOINE | C8: =IF(E8="ECHEC",0,100000) -> 100000 | D8: =IF(E8="ESPECES",1000,0) -> 0 | E8: BANQUE | J8: 155000 | K8: 42723
A9: AS201609 | B9: =VLOOKUP(A9,[1]LISTADHERENT!A$5:H$49,2) -> FOTSO THOMAS | C9: =IF(E9="ECHEC",0,100000) -> 100000 | D9: =IF(E9="ESPECES",1000,0) -> 1000 | E9: ESPECES | F9: 200000 | G9: 2500 | J9: 191000 | K9: 42603
A10: AS201612 | B10: =VLOOKUP(A10,[1]LISTADHERENT!A$5:H$49,2) -> HOTCHO BENJAMIN | C10: 100000 | D10: =IF(E10="ESPECES",1000,0) -> 0 | E10: BANQUE | J10: 195000 | K10: 42694
A11: AS201612 | B11: =VLOOKUP(A11,[1]LISTADHERENT!A$5:H$49,2) -> HOTCHO BENJAMIN | C11: 100000 | D11: =IF(E11="ESPECES",1000,0) -> 0 | E11: BANQUE
A12: AS201614 | B12: =VLOOKUP(A12,[1]LISTADHERENT!A$5:H$49,2) -> KEPSEU FRANCIS | C12: =IF(E12="ECHEC",0,100000) -> 100000 | D12: =IF(E12="ESPECES",1000,0) -> 0 | E12: BANQUE
A13: AS201617 | B13: =VLOOKUP(A13,[1]LISTADHERENT!A$5:H$49,2) -> KOUAMOU MOISE | C13: =IF(E13="ECHEC",0,100000) -> 100000 | D13: =IF(E13="ESPECES",1000,0) -> 1000 | E13: ESPECES | F13: 100000 | G13: 1000
A14: AS201618 | B14: =VLOOKUP(A14,[1]LISTADHERENT!A$5:H$49,2) -> KOUAMOU VICTOR PEGUY | C14: =IF(E14="ECHEC",0,100000) -> 100000 | D14: =IF(E14="ESPECES",1000,0) -> 1000 | E14: ESPECES | J14: 136000 | K14: 42659
A15: AS201619 | B15: =VLOOKUP(A15,[1]LISTADHERENT!A$5:H$49,2) -> KOUATCHO MESSACK | C15: =IF(E15="ECHEC",0,100000) -> 100000 | D15: =IF(E15="ESPECES",1000,0) -> 1000 | E15: ESPECES | F15: 200000 | G15: 2000 | J15: 136000 | K15: 42659
A16: AS201621 | B16: =VLOOKUP(A16,[1]LISTADHERENT!A$5:H$49,2) -> NANKAM APPOLINAIRE | C16: =IF(E16="ECHEC",0,100000) -> 100000 | D16: =IF(E16="ESPECES",1000,0) -> 0 | E16: BANQUE | J16: 157000 | K16: 42632
A17: AS201622 | B17: =VLOOKUP(A17,[1]LISTADHERENT!A$5:H$49,2) -> NDJOMO ETIENNE | C17: =IF(E17="ECHEC",0,100000) -> 100000 | D17: =IF(E17="ESPECES",1000,0) -> 1000 | E17: ESPECES
A18: AS201624 | B18: =VLOOKUP(A18,[1]LISTADHERENT!A$5:H$49,2) -> NGONDIEP CLAUDE | C18: =IF(E18="ECHEC",0,100000) -> 100000 | D18: =IF(E18="ESPECES",1000,0) -> 0 | E18: BANQUE | F18: 100000 | G18: 1000
A19: AS201628 | B19: =VLOOKUP(A19,[1]LISTADHERENT!A$5:H$49,2) -> NKAMGANG JUSTIN DEJOLIE | C19: =IF(E19="ECHEC",0,100000) -> 100000 | D19: =IF(E19="ESPECES",1000,0) -> 1000 | E19: ESPECES | F19: 200000 | G19: 2000 | J19: 200000 | K19: 42603
A20: AS201628 | B20: =VLOOKUP(A20,[1]LISTADHERENT!A$5:H$49,2) -> NKAMGANG JUSTIN DEJOLIE | C20: =IF(E20="ECHEC",0,100000) -> 100000 | D20: =IF(E20="ESPECES",1000,0) -> 1000 | E20: ESPECES | J20: 127000 | K20: 42750
A21: AS201628 | B21: =VLOOKUP(A21,[1]LISTADHERENT!A$5:H$49,2) -> NKAMGANG JUSTIN DEJOLIE | C21: =IF(E21="ECHEC",0,100000) -> 100000 | D21: =IF(E21="ESPECES",1000,0) -> 1000 | E21: ESPECES
A22: AS201629 | B22: =VLOOKUP(A22,[1]LISTADHERENT!A$5:H$49,2) -> NKEPSEU DIEUDONNE | C22: =IF(E22="ECHEC",0,100000) -> 100000 | D22: =IF(E22="ESPECES",1000,0) -> 1000 | E22: ESPECES | J22: 127000 | K22: 42750
A23: AS201633 | B23: =VLOOKUP(A23,[1]LISTADHERENT!A$5:H$49,2) -> SEUNOU RICHELOT | C23: =IF(E23="ECHEC",0,100000) -> 100000 | D23: =IF(E23="ESPECES",1000,0) -> 1000 | E23: ESPECES | F23: 200000 | G23: 2000 | J23: 265000 | K23: 42568
A24: AS201633 | B24: =VLOOKUP(A24,[1]LISTADHERENT!A$5:H$49,2) -> SEUNOU RICHELOT | C24: =IF(E24="ECHEC",0,100000) -> 100000 | D24: =IF(E24="ESPECES",1000,0) -> 0 | E24: BANQUE
A25: AS201635 | B25: =VLOOKUP(A25,[1]LISTADHERENT!A$5:H$49,2) -> SIME FONGANG ERIC | C25: =IF(E25="ECHEC",0,100000) -> 100000 | D25: =IF(E25="ESPECES",1000,0) -> 0 | E25: BANQUE
A26: AS201636 | B26: =VLOOKUP(A26,[1]LISTADHERENT!A$5:H$49,2) -> SIME MATHIEU | C26: =IF(E26="ECHEC",0,100000) -> 100000 | D26: =IF(E26="ESPECES",1000,0) -> 1000 | E26: ESPECES | J26: 147000 | K26: 42632
A27: AS201636 | B27: =VLOOKUP(A27,[1]LISTADHERENT!A$5:H$49,2) -> SIME MATHIEU | C27: =IF(E27="ECHEC",0,100000) -> 100000 | D27: =IF(E27="ESPECES",1000,0) -> 1000 | E27: ESPECES | J27: 155000 | K27: 42785
A28: AS201639 | B28: =VLOOKUP(A28,[1]LISTADHERENT!A$5:H$49,2) -> TCHOUAMOU MATHIEU | C28: =IF(E28="ECHEC",0,100000) -> 100000 | D28: =IF(E28="ESPECES",1000,0) -> 0 | E28: BANQUE
A29: AS201642 | B29: =VLOOKUP(A29,[1]LISTADHERENT!A$5:H$49,2) -> TIEYAM ERNEST | C29: =IF(E29="ECHEC",0,100000) -> 100000 | D29: =IF(E29="ESPECES",1000,0) -> 0 | E29: BANQUE | J29: 270000 | K29: 42568
A30: AS201642 | B30: =VLOOKUP(A30,[1]LISTADHERENT!A$5:H$49,2) -> TIEYAM ERNEST | C30: =IF(E30="ECHEC",0,100000) -> 100000 | D30: =IF(E30="ESPECES",1000,0) -> 0 | E30: BANQUE | J30: 170000 | K30: 42785
A31: AS201645 | B31: =VLOOKUP(A31,[1]LISTADHERENT!A$5:H$49,2) -> YOUMBI EMMANUEL | C31: =IF(E31="ECHEC",0,100000) -> 100000 | D31: =IF(E31="ESPECES",1000,0) -> 0 | E31: BANQUE
A33: TOTAL | C33: =SUM(C6:C32) -> 2600000 | D33: =SUM(D6:D32) -> 13000 | F33: =SUM(F6:F32) -> 1000000 | G33: =SUM(G6:G32) -> 10500 | H33: =SUM(H6:H32) -> 0 | I33: =SUM(I6:I32) -> 0

Sheet TONTJANV
A1: ASSOCIATION | B1: ASELBY
A2: ANNEE | B2: 2016/2017
A3: TONTINE | B3: 100000
C4: 42754
A5: MATRICULE | B5: NOM ET PRENOM | C5: MONTANT TONTINE | D5: PENALITE | E5: MODE VERSEMENT | F5: PRÊT | G5: INTERET PRÊT | H5: REMBOURSEMENT | I5: STATUT PRÊT | J5: INTERET ACHAT | K5: DATE ACHAT | L5: AVALISTE
A6: AS201602 | B6: =VLOOKUP(A6,[1]LISTADHERENT!A$5:H$49,2) -> BOUTCHOUANG WILLIAM | C6: =IF(E6="ECHEC",0,100000) -> 100000 | D6: =IF(E6="ESPECES",0,0) -> 0 | E6: ESPECES | J6: 200000 | K6: 42694
A7: AS201606 | B7: =VLOOKUP(A7,[1]LISTADHERENT!A$5:H$49,2) -> DJOUNKEP SAMUEL | C7: =IF(E7="ECHEC",0,100000) -> 100000 | D7: =IF(E7="ESPECES",0,0) -> 0 | E7: BANQUE
A8: AS201607 | B8: =VLOOKUP(A8,[1]LISTADHERENT!A$5:H$49,2) -> DJUOMBESSY ANTOINE | C8: =IF(E8="ECHEC",0,100000) -> 100000 | D8: =IF(E8="ESPECES",0,0) -> 0 | E8: BANQUE | J8: 155000 | K8: 42723
A9: AS201609 | B9: =VLOOKUP(A9,[1]LISTADHERENT!A$5:H$49,2) -> FOTSO THOMAS | C9: =IF(E9="ECHEC",0,100000) -> 100000 | D9: =IF(E9="ESPECES",0,0) -> 0 | E9: ESPECES | F9: 200000 | G9: 4000 | J9: 191000 | K9: 42603
A10: AS201612 | B10: =VLOOKUP(A10,[1]LISTADHERENT!A$5:H$49,2) -> HOTCHO BENJAMIN | C10: 100000 | D10: =IF(E10="ESPECES",0,0) -> 0 | E10: BANQUE | J10: 195000 | K10: 42694
A11: AS201612 | B11: =VLOOKUP(A11,[1]LISTADHERENT!A$5:H$49,2) -> HOTCHO BENJAMIN | C11: 100000 | D11: =IF(E11="ESPECES",0,0) -> 0 | E11: BANQUE
A12: AS201614 | B12: =VLOOKUP(A12,[1]LISTADHERENT!A$5:H$49,2) -> KEPSEU FRANCIS | C12: =IF(E12="ECHEC",0,100000) -> 100000 | D12: =IF(E12="ESPECES",0,0) -> 0 | E12: BANQUE
A13: AS201617 | B13: =VLOOKUP(A13,[1]LISTADHERENT!A$5:H$49,2) -> KOUAMOU MOISE | C13: =IF(E13="ECHEC",0,100000) -> 100000 | D13: =IF(E13="ESPECES",0,0) -> 0 | E13: ESPECES
A14: AS201618 | B14: =VLOOKUP(A14,[1]LISTADHERENT!A$5:H$49,2) -> KOUAMOU VICTOR PEGUY | C14: =IF(E14="ECHEC",0,100000) -> 100000 | D14: =IF(E14="ESPECES",0,0) -> 0 | E14: ESPECES | F14: 100000 | G14: 1500 | J14: 136000 | K14: 42659
A15: AS201619 | B15: =VLOOKUP(A15,[1]LISTADHERENT!A$5:H$49,2) -> KOUATCHO MESSACK | C15: =IF(E15="ECHEC",0,100000) -> 100000 | D15: =IF(E15="ESPECES",0,0) -> 0 | E15: ESPECES | F15: 100000 | G15: 1500 | J15: 136000 | K15: 42659
A16: AS201621 | B16: =VLOOKUP(A16,[1]LISTADHERENT!A$5:H$49,2) -> NANKAM APPOLINAIRE | C16: =IF(E16="ECHEC",0,100000) -> 100000 | D16: =IF(E16="ESPECES",0,0) -> 0 | E16: BANQUE | J16: 157000 | K16: 42632
A17: AS201622 | B17: =VLOOKUP(A17,[1]LISTADHERENT!A$5:H$49,2) -> NDJOMO ETIENNE | C17: =IF(E17="ECHEC",0,100000) -> 100000 | D17: =IF(E17="ESPECES",0,0) -> 0 | E17: ESPECES | F17: 100000 | G17: 1000
A18: AS201624 | B18: =VLOOKUP(A18,[1]LISTADHERENT!A$5:H$49,2) -> NGONDIEP CLAUDE | C18: =IF(E18="ECHEC",0,100000) -> 100000 | D18: =IF(E18="ESPECES",0,0) -> 0 | E18: BANQUE
A19: AS201628 | B19: =VLOOKUP(A19,[1]LISTADHERENT!A$5:H$49,2) -> NKAMGANG JUSTIN DEJOLIE | C19: =IF(E19="ECHEC",0,100000) -> 100000 | D19: =IF(E19="ESPECES",0,0) -> 0 | E19: ESPECES | F19: 83000 | G19: 1000 | J19: 200000 | K19: 42603
A20: AS201628 | B20: =VLOOKUP(A20,[1]LISTADHERENT!A$5:H$49,2) -> NKAMGANG JUSTIN DEJOLIE | C20: =IF(E20="ECHEC",0,100000) -> 100000 | D20: =IF(E20="ESPECES",0,0) -> 0 | E20: ESPECES | J20: 127000 | K20: 42750
A21: AS201628 | B21: =VLOOKUP(A21,[1]LISTADHERENT!A$5:H$49,2) -> NKAMGANG JUSTIN DEJOLIE | C21: =IF(E21="ECHEC",0,100000) -> 100000 | D21: =IF(E21="ESPECES",0,0) -> 0 | E21: ESPECES
A22: AS201629 | B22: =VLOOKUP(A22,[1]LISTADHERENT!A$5:H$49,2) -> NKEPSEU DIEUDONNE | C22: =IF(E22="ECHEC",0,100000) -> 100000 | D22: =IF(E22="ESPECES",0,0) -> 0 | E22: ESPECES | F22: 100000 | G22: 1000 | J22: 127000 | K22: 42750
A23: AS201633 | B23: =VLOOKUP(A23,[1]LISTADHERENT!A$5:H$49,2) -> SEUNOU RICHELOT | C23: =IF(E23="ECHEC",0,100000) -> 100000 | D23: =IF(E23="ESPECES",0,0) -> 0 | E23: ESPECES | F23: 200000 | G23: 3500 | J23: 265000 | K23: 42568
A24: AS201633 | B24: =VLOOKUP(A24,[1]LISTADHERENT!A$5:H$49,2) -> SEUNOU RICHELOT | C24: =IF(E24="ECHEC",0,100000) -> 100000 | D24: =IF(E24="ESPECES",0,0) -> 0 | E24: BANQUE
A25: AS201635 | B25: =VLOOKUP(A25,[1]LISTADHERENT!A$5:H$49,2) -> SIME FONGANG ERIC | C25: =IF(E25="ECHEC",0,100000) -> 100000 | D25: =IF(E25="ESPECES",0,0) -> 0 | E25: BANQUE
A26: AS201636 | B26: =VLOOKUP(A26,[1]LISTADHERENT!A$5:H$49,2) -> SIME MATHIEU | C26: =IF(E26="ECHEC",0,100000) -> 100000 | D26: =IF(E26="ESPECES",0,0) -> 0 | E26: ESPECES | J26: 147000 | K26: 42632
A27: AS201636 | B27: =VLOOKUP(A27,[1]LISTADHERENT!A$5:H$49,2) -> SIME MATHIEU | C27: =IF(E27="ECHEC",0,100000) -> 100000 | D27: =IF(E27="ESPECES",0,0) -> 0 | E27: ESPECES | J27: 155000 | K27: 42785
A28: AS201639 | B28: =VLOOKUP(A28,[1]LISTADHERENT!A$5:H$49,2) -> TCHOUAMOU MATHIEU | C28: =IF(E28="ECHEC",0,100000) -> 100000 | D28: =IF(E28="ESPECES",0,0) -> 0 | E28: BANQUE
A29: AS201642 | B29: =VLOOKUP(A29,[1]LISTADHERENT!A$5:H$49,2) -> TIEYAM ERNEST | C29: =IF(E29="ECHEC",0,100000) -> 100000 | D29: =IF(E29="ESPECES",0,0) -> 0 | E29: BANQUE | F29: 200000 | G29: 5000 | J29: 270000 | K29: 42568
A30: AS201642 | B30: =VLOOKUP(A30,[1]LISTADHERENT!A$5:H$49,2) -> TIEYAM ERNEST | C30: =IF(E30="ECHEC",0,100000) -> 100000 | D30: =IF(E30="ESPECES",0,0) -> 0 | E30: BANQUE | J30: 170000 | K30: 42785
A31: AS201645 | B31: =VLOOKUP(A31,[1]LISTADHERENT!A$5:H$49,2) -> YOUMBI EMMANUEL | C31: =IF(E31="ECHEC",0,100000) -> 100000 | D31: =IF(E31="ESPECES",0,0) -> 0 | E31: BANQUE
A33: TOTAL | C33: =SUM(C6:C32) -> 2600000 | D33: =SUM(D6:D32) -> 0 | F33: =SUM(F6:F32) -> 1083000 | G33: =SUM(G6:G32) -> 18500 | H33: =SUM(H6:H32) -> 0 | I33: =SUM(I6:I32) -> 0

Sheet TONTFEV
A1: ASSOCIATION | B1: ASELBY
A2: ANNEE | B2: 2016/2017
A3: TONTINE | B3: 100000
C4: 42785
A5: MATRICULE | B5: NOM ET PRENOM | C5: MONTANT TONTINE | D5: PENALITE | E5: MODE VERSEMENT | F5: PRÊT | G5: INTERET PRÊT | H5: REMBOURSEMENT | I5: STATUT PRÊT | J5: INTERET ACHAT | K5: DATE ACHAT | L5: AVALISTE
A6: AS201602 | B6: =VLOOKUP(A6,[1]LISTADHERENT!A$5:H$49,2) -> BOUTCHOUANG WILLIAM | C6: =IF(E6="ECHEC",0,100000) -> 100000 | D6: =IF(E6="ESPECES",1000,0) -> 0 | E6: BANQUE | H6: =TONTJANV!F6+TONTJANV!G6 -> 0 | J6: 200000 | K6: 42694
A7: AS201606 | B7: =VLOOKUP(A7,[1]LISTADHERENT!A$5:H$49,2) -> DJOUNKEP SAMUEL | C7: =IF(E7="ECHEC",0,100000) -> 100000 | D7: =IF(E7="ESPECES",1000,0) -> 0 | E7: BANQUE | H7: =TONTJANV!F7+TONTJANV!G7 -> 0
A8: AS201607 | B8: =VLOOKUP(A8,[1]LISTADHERENT!A$5:H$49,2) -> DJUOMBESSY ANTOINE | C8: =IF(E8="ECHEC",0,100000) -> 100000 | D8: =IF(E8="ESPECES",1000,0) -> 0 | E8: BANQUE | H8: =TONTJANV!F8+TONTJANV!G8 -> 0 | J8: 155000 | K8: 42723
A9: AS201609 | B9: =VLOOKUP(A9,[1]LISTADHERENT!A$5:H$49,2) -> FOTSO THOMAS | C9: =IF(E9="ECHEC",0,100000) -> 100000 | D9: =IF(E9="ESPECES",1000,0) -> 0 | E9: BANQUE | F9: =100000+100000 -> 200000 | G9: =1000+2000 -> 3000 | H9: =TONTJANV!F9+TONTJANV!G9 -> 204000 | J9: 191000 | K9: 42603
A10: AS201612 | B10: =VLOOKUP(A10,[1]LISTADHERENT!A$5:H$49,2) -> HOTCHO BENJAMIN | C10: 100000 | D10: =IF(E10="ESPECES",1000,0) -> 0 | E10: BANQUE | H10: =TONTJANV!F10+TONTJANV!G10 -> 0 | J10: 195000 | K10: 42694
A11: AS201612 | B11: =VLOOKUP(A11,[1]LISTADHERENT!A$5:H$49,2) -> HOTCHO BENJAMIN | C11: 100000 | D11: =IF(E11="ESPECES",1000,0) -> 0 | E11: BANQUE | H11: =TONTJANV!F11+TONTJANV!G11 -> 0
A12: AS201614 | B12: =VLOOKUP(A12,[1]LISTADHERENT!A$5:H$49,2) -> KEPSEU FRANCIS | C12: =IF(E12="ECHEC",0,100000) -> 100000 | D12: =IF(E12="ESPECES",1000,0) -> 0 | E12: BANQUE | H12: =TONTJANV!F12+TONTJANV!G12 -> 0
A13: AS201617 | B13: =VLOOKUP(A13,[1]LISTADHERENT!A$5:H$49,2) -> KOUAMOU MOISE | C13: =IF(E13="ECHEC",0,100000) -> 100000 | D13: =IF(E13="ESPECES",1000,0) -> 0 | E13: BANQUE | H13: =TONTJANV!F13+TONTJANV!G13 -> 0
A14: AS201618 | B14: =VLOOKUP(A14,[1]LISTADHERENT!A$5:H$49,2) -> KOUAMOU VICTOR PEGUY | C14: =IF(E14="ECHEC",0,100000) -> 100000 | D14: =IF(E14="ESPECES",1000,0) -> 0 | E14: BANQUE | F14: =100000+100000 -> 200000 | G14: =1500+1500 -> 3000 | H14: =TONTJANV!F14+TONTJANV!G14 -> 101500 | J14: 136000 | K14: 42659
A15: AS201619 | B15: =VLOOKUP(A15,[1]LISTADHERENT!A$5:H$49,2) -> KOUATCHO MESSACK | C15: =IF(E15="ECHEC",0,100000) -> 100000 | D15: =IF(E15="ESPECES",1000,0) -> 0 | E15: BANQUE | F15: =100000+100000 -> 200000 | G15: =2000+1500 -> 3500 | H15: =TONTJANV!F15+TONTJANV!G15 -> 101500 | J15: 136000 | K15: 42659
A16: AS201621 | B16: =VLOOKUP(A16,[1]LISTADHERENT!A$5:H$49,2) -> NANKAM APPOLINAIRE | C16: =IF(E16="ECHEC",0,100000) -> 100000 | D16: =IF(E16="ESPECES",1000,0) -> 0 | E16: BANQUE | H16: =TONTJANV!F16+TONTJANV!G16 -> 0 | J16: 157000 | K16: 42632
A17: AS201622 | B17: =VLOOKUP(A17,[1]LISTADHERENT!A$5:H$49,2) -> NDJOMO ETIENNE | C17: =IF(E17="ECHEC",0,100000) -> 100000 | D17: =IF(E17="ESPECES",1000,0) -> 0 | E17: BANQUE | H17: =TONTJANV!F17+TONTJANV!G17 -> 101000
A18: AS201624 | B18: =VLOOKUP(A18,[1]LISTADHERENT!A$5:H$49,2) -> NGONDIEP CLAUDE | C18: =IF(E18="ECHEC",0,100000) -> 100000 | D18: =IF(E18="ESPECES",1000,0) -> 0 | E18: BANQUE | H18: =TONTJANV!F18+TONTJANV!G18 -> 0
A19: AS201628 | B19: =VLOOKUP(A19,[1]LISTADHERENT!A$5:H$49,2) -> NKAMGANG JUSTIN DEJOLIE | C19: =IF(E19="ECHEC",0,100000) -> 100000 | D19: =IF(E19="ESPECES",1000,0) -> 0 | E19: BANQUE | F19: =100000+100000 -> 200000 | G19: =2000+1500 -> 3500 | H19: =TONTJANV!F19+TONTJANV!G19 -> 84000 | J19: 200000 | K19: 42603
A20: AS201628 | B20: =VLOOKUP(A20,[1]LISTADHERENT!A$5:H$49,2) -> NKAMGANG JUSTIN DEJOLIE | C20: =IF(E20="ECHEC",0,100000) -> 100000 | D20: =IF(E20="ESPECES",1000,0) -> 0 | E20: BANQUE | H20: =TONTJANV!F20+TONTJANV!G20 -> 0 | J20: 127000 | K20: 42750
A21: AS201628 | B21: =VLOOKUP(A21,[1]LISTADHERENT!A$5:H$49,2) -> NKAMGANG JUSTIN DEJOLIE | C21: =IF(E21="ECHEC",0,100000) -> 100000 | D21: =IF(E21="ESPECES",1000,0) -> 0 | E21: BANQUE | H21: =TONTJANV!F21+TONTJANV!G21 -> 0
A22: AS201629 | B22: =VLOOKUP(A22,[1]LISTADHERENT!A$5:H$49,2) -> NKEPSEU DIEUDONNE | C22: =IF(E22="ECHEC",0,100000) -> 100000 | D22: =IF(E22="ESPECES",1000,0) -> 0 | E22: BANQUE | H22: =TONTJANV!F22+TONTJANV!G22 -> 101000 | J22: 127000 | K22: 42750
A23: AS201633 | B23: =VLOOKUP(A23,[1]LISTADHERENT!A$5:H$49,2) -> SEUNOU RICHELOT | C23: =IF(E23="ECHEC",0,100000) -> 100000 | D23: =IF(E23="ESPECES",1000,0) -> 0 | E23: BANQUE | F23: 126500 | G23: 2000 | H23: =TONTJANV!F23+TONTJANV!G23 -> 203500 | J23: 265000 | K23: 42568
A24: AS201633 | B24: =VLOOKUP(A24,[1]LISTADHERENT!A$5:H$49,2) -> SEUNOU RICHELOT | C24: =IF(E24="ECHEC",0,100000) -> 100000 | D24: =IF(E24="ESPECES",1000,0) -> 0 | E24: BANQUE | H24: =TONTJANV!F24+TONTJANV!G24 -> 0
A25: AS201635 | B25: =VLOOKUP(A25,[1]LISTADHERENT!A$5:H$49,2) -> SIME FONGANG ERIC | C25: =IF(E25="ECHEC",0,100000) -> 100000 | D25: =IF(E25="ESPECES",1000,0) -> 0 | E25: BANQUE | H25: =TONTJANV!F25+TONTJANV!G25 -> 0
A26: AS201636 | B26: =VLOOKUP(A26,[1]LISTADHERENT!A$5:H$49,2) -> SIME MATHIEU | C26: =IF(E26="ECHEC",0,100000) -> 100000 | D26: =IF(E26="ESPECES",1000,0) -> 0 | E26: BANQUE | H26: =TONTJANV!F26+TONTJANV!G26 -> 0 | J26: 147000 | K26: 42632
A27: AS201636 | B27: =VLOOKUP(A27,[1]LISTADHERENT!A$5:H$49,2) -> SIME MATHIEU | C27: =IF(E27="ECHEC",0,100000) -> 100000 | D27: =IF(E27="ESPECES",1000,0) -> 0 | E27: BANQUE | H27: =TONTJANV!F27+TONTJANV!G27 -> 0 | J27: 155000 | K27: 42785 | L27: HOTCHO BENJAMIN
A28: AS201639 | B28: =VLOOKUP(A28,[1]LISTADHERENT!A$5:H$49,2) -> TCHOUAMOU MATHIEU | C28: =IF(E28="ECHEC",0,100000) -> 100000 | D28: =IF(E28="ESPECES",1000,0) -> 0 | E28: BANQUE | H28: =TONTJANV!F28+TONTJANV!G28 -> 0
A29: AS201642 | B29: =VLOOKUP(A29,[1]LISTADHERENT!A$5:H$49,2) -> TIEYAM ERNEST | C29: =IF(E29="ECHEC",0,100000) -> 100000 | D29: =IF(E29="ESPECES",1000,0) -> 0 | E29: BANQUE | F29: 100000 | G29: 1500 | H29: =TONTJANV!F29+TONTJANV!G29 -> 205000 | J29: 270000 | K29: 42568
A30: AS201642 | B30: =VLOOKUP(A30,[1]LISTADHERENT!A$5:H$49,2) -> TIEYAM ERNEST | C30: =IF(E30="ECHEC",0,100000) -> 100000 | D30: =IF(E30="ESPECES",1000,0) -> 0 | E30: BANQUE | H30: =TONTJANV!F30+TONTJANV!G30 -> 0 | J30: 170000 | K30: 42785 | L30: SIME MATHIEU
A31: AS201645 | B31: =VLOOKUP(A31,[1]LISTADHERENT!A$5:H$49,2) -> YOUMBI EMMANUEL | C31: =IF(E31="ECHEC",0,100000) -> 100000 | D31: =IF(E31="ESPECES",1000,0) -> 0 | E31: BANQUE | H31: =TONTJANV!F31+TONTJANV!G31 -> 0
A33: TOTAL | C33: =SUM(C6:C32) -> 2600000 | D33: =SUM(D6:D32) -> 0 | F33: =SUM(F6:F32) -> 1026500 | G33: =SUM(G6:G32) -> 16500 | H33: =SUM(H6:H32) -> 1101500 | I33: =SUM(I6:I32) -> 0
B36: ESPECES
B37: BANQUE | C37: =C33-C36 -> 2600000
B38: REMBOURSEMENT | C38: =H33 -> 1101500

Sheet TONTMARS
A1: ASSOCIATION | B1: ASELBY
A2: ANNEE | B2: 2016/2017
A3: TONTINE | B3: 100000
C4: 42813
A5: MATRICULE | B5: NOM ET PRENOM | C5: MONTANT TONTINE | D5: PENALITE | E5: MODE VERSEMENT | F5: PRÊT | G5: INTERET PRÊT | H5: REMBOURSEMENT | I5: STATUT PRÊT | J5: INTERET ACHAT | K5: DATE ACHAT | L5: AVALISTE
A6: AS201602 | B6: =VLOOKUP(A6,[1]LISTADHERENT!A$5:H$49,2) -> BOUTCHOUANG WILLIAM | C6: =IF(E6="ECHEC",0,100000) -> 100000 | D6: =IF(E6="ESPECES",0,0) -> 0 | E6: ESPECES | H6: =TONTJANV!F6+TONTJANV!G6 -> 0 | J6: 200000 | K6: 42694
A7: AS201606 | B7: =VLOOKUP(A7,[1]LISTADHERENT!A$5:H$49,2) -> DJOUNKEP SAMUEL | C7: =IF(E7="ECHEC",0,100000) -> 100000 | D7: =IF(E7="ESPECES",0,0) -> 0 | E7: BANQUE | H7: =TONTJANV!F7+TONTJANV!G7 -> 0
A8: AS201607 | B8: =VLOOKUP(A8,[1]LISTADHERENT!A$5:H$49,2) -> DJUOMBESSY ANTOINE | C8: =IF(E8="ECHEC",0,100000) -> 100000 | D8: =IF(E8="ESPECES",0,0) -> 0 | E8: BANQUE | H8: =TONTJANV!F8+TONTJANV!G8 -> 0 | J8: 155000 | K8: 42723
A9: AS201609 | B9: =VLOOKUP(A9,[1]LISTADHERENT!A$5:H$49,2) -> FOTSO THOMAS | C9: =IF(E9="ECHEC",0,100000) -> 100000 | D9: =IF(E9="ESPECES",0,0) -> 0 | E9: ESPECES | F9: 200000 | G9: 5500 | H9: =TONTJANV!F9+TONTJANV!G9 -> 204000 | J9: 191000 | K9: 42603
A10: AS201612 | B10: =VLOOKUP(A10,[1]LISTADHERENT!A$5:H$49,2) -> HOTCHO BENJAMIN | C10: 100000 | D10: =IF(E10="ESPECES",0,0) -> 0 | E10: BANQUE | H10: =TONTJANV!F10+TONTJANV!G10 -> 0 | J10: 195000 | K10: 42694
A11: AS201612 | B11: =VLOOKUP(A11,[1]LISTADHERENT!A$5:H$49,2) -> HOTCHO BENJAMIN | C11: 100000 | D11: =IF(E11="ESPECES",0,0) -> 0 | E11: BANQUE | H11: =TONTJANV!F11+TONTJANV!G11 -> 0
A12: AS201614 | B12: =VLOOKUP(A12,[1]LISTADHERENT!A$5:H$49,2) -> KEPSEU FRANCIS | C12: =IF(E12="ECHEC",0,100000) -> 100000 | D12: =IF(E12="ESPECES",0,0) -> 0 | E12: BANQUE | H12: =TONTJANV!F12+TONTJANV!G12 -> 0
A13: AS201617 | B13: =VLOOKUP(A13,[1]LISTADHERENT!A$5:H$49,2) -> KOUAMOU MOISE | C13: =IF(E13="ECHEC",0,100000) -> 100000 | D13: =IF(E13="ESPECES",0,0) -> 0 | E13: BANQUE | H13: =TONTJANV!F13+TONTJANV!G13 -> 0 | J13: 110000 | K13: 42448
A14: AS201618 | B14: =VLOOKUP(A14,[1]LISTADHERENT!A$5:H$49,2) -> KOUAMOU VICTOR PEGUY | C14: =IF(E14="ECHEC",0,100000) -> 100000 | D14: =IF(E14="ESPECES",0,0) -> 0 | E14: ESPECES | F14: 200000 | G14: 7000 | H14: =TONTJANV!F14+TONTJANV!G14 -> 101500 | J14: 136000 | K14: 42659
A15: AS201619 | B15: =VLOOKUP(A15,[1]LISTADHERENT!A$5:H$49,2) -> KOUATCHO MESSACK | C15: =IF(E15="ECHEC",0,100000) -> 100000 | D15: =IF(E15="ESPECES",0,0) -> 0 | E15: BANQUE | H15: =TONTJANV!F15+TONTJANV!G15 -> 101500 | J15: 136000 | K15: 42659
A16: AS201621 | B16: =VLOOKUP(A16,[1]LISTADHERENT!A$5:H$49,2) -> NANKAM APPOLINAIRE | C16: =IF(E16="ECHEC",0,100000) -> 100000 | D16: =IF(E16="ESPECES",0,0) -> 0 | E16: ESPECES | H16: =TONTJANV!F16+TONTJANV!G16 -> 0 | J16: 157000 | K16: 42632
A17: AS201622 | B17: =VLOOKUP(A17,[1]LISTADHERENT!A$5:H$49,2) -> NDJOMO ETIENNE | C17: =IF(E17="ECHEC",0,100000) -> 100000 | D17: =IF(E17="ESPECES",0,0) -> 0 | E17: ESPECES | H17: =TONTJANV!F17+TONTJANV!G17 -> 101000
A18: AS201624 | B18: =VLOOKUP(A18,[1]LISTADHERENT!A$5:H$49,2) -> NGONDIEP CLAUDE | C18: =IF(E18="ECHEC",0,100000) -> 100000 | D18: =IF(E18="ESPECES",0,0) -> 0 | E18: ESPECES | H18: =TONTJANV!F18+TONTJANV!G18 -> 0
A19: AS201628 | B19: =VLOOKUP(A19,[1]LISTADHERENT!A$5:H$49,2) -> NKAMGANG JUSTIN DEJOLIE | C19: =IF(E19="ECHEC",0,100000) -> 100000 | D19: =IF(E19="ESPECES",0,0) -> 0 | E19: BANQUE | F19: 100000 | G19: 2000 | H19: =TONTJANV!F19+TONTJANV!G19 -> 84000 | J19: 200000 | K19: 42603
A20: AS201628 | B20: =VLOOKUP(A20,[1]LISTADHERENT!A$5:H$49,2) -> NKAMGANG JUSTIN DEJOLIE | C20: =IF(E20="ECHEC",0,100000) -> 100000 | D20: =IF(E20="ESPECES",0,0) -> 0 | E20: ESPECES | H20: =TONTJANV!F20+TONTJANV!G20 -> 0 | J20: 127000 | K20: 42750
A21: AS201628 | B21: =VLOOKUP(A21,[1]LISTADHERENT!A$5:H$49,2) -> NKAMGANG JUSTIN DEJOLIE | C21: =IF(E21="ECHEC",0,100000) -> 100000 | D21: =IF(E21="ESPECES",0,0) -> 0 | E21: ESPECES | H21: =TONTJANV!F21+TONTJANV!G21 -> 0
A22: AS201629 | B22: =VLOOKUP(A22,[1]LISTADHERENT!A$5:H$49,2) -> NKEPSEU DIEUDONNE | C22: =IF(E22="ECHEC",0,100000) -> 100000 | D22: =IF(E22="ESPECES",0,0) -> 0 | E22: ESPECES | H22: =TONTJANV!F22+TONTJANV!G22 -> 101000 | J22: 127000 | K22: 42750
A23: AS201633 | B23: =VLOOKUP(A23,[1]LISTADHERENT!A$5:H$49,2) -> SEUNOU RICHELOT | C23: =IF(E23="ECHEC",0,100000) -> 100000 | D23: =IF(E23="ESPECES",0,0) -> 0 | E23: ESPECES | H23: =TONTJANV!F23+TONTJANV!G23 -> 203500 | J23: 265000 | K23: 42568
A24: AS201633 | B24: =VLOOKUP(A24,[1]LISTADHERENT!A$5:H$49,2) -> SEUNOU RICHELOT | C24: =IF(E24="ECHEC",0,100000) -> 100000 | D24: =IF(E24="ESPECES",0,0) -> 0 | E24: ESPECES | H24: =TONTJANV!F24+TONTJANV!G24 -> 0 | J24: 111000 | K24: 42813
A25: AS201635 | B25: =VLOOKUP(A25,[1]LISTADHERENT!A$5:H$49,2) -> SIME FONGANG ERIC | C25: =IF(E25="ECHEC",0,100000) -> 100000 | D25: =IF(E25="ESPECES",0,0) -> 0 | E25: ESPECES | H25: =TONTJANV!F25+TONTJANV!G25 -> 0
A26: AS201636 | B26: =VLOOKUP(A26,[1]LISTADHERENT!A$5:H$49,2) -> SIME MATHIEU | C26: =IF(E26="ECHEC",0,100000) -> 100000 | D26: =IF(E26="ESPECES",0,0) -> 0 | E26: BANQUE | F26: 164000 | G26: 5500 | H26: =TONTJANV!F26+TONTJANV!G26 -> 0 | J26: 147000 | K26: 42632
A27: AS201636 | B27: =VLOOKUP(A27,[1]LISTADHERENT!A$5:H$49,2) -> SIME MATHIEU | C27: =IF(E27="ECHEC",0,100000) -> 100000 | D27: =IF(E27="ESPECES",0,0) -> 0 | E27: BANQUE | H27: =TONTJANV!F27+TONTJANV!G27 -> 0 | J27: 155000 | K27: 42785 | L27: HOTCHO BENJAMIN
A28: AS201639 | B28: =VLOOKUP(A28,[1]LISTADHERENT!A$5:H$49,2) -> TCHOUAMOU MATHIEU | C28: =IF(E28="ECHEC",0,100000) -> 100000 | D28: =IF(E28="ESPECES",0,0) -> 0 | E28: BANQUE | H28: =TONTJANV!F28+TONTJANV!G28 -> 0
A29: AS201642 | B29: =VLOOKUP(A29,[1]LISTADHERENT!A$5:H$49,2) -> TIEYAM ERNEST | C29: =IF(E29="ECHEC",0,100000) -> 100000 | D29: =IF(E29="ESPECES",0,0) -> 0 | E29: BANQUE | F29: 200000 | G29: 6000 | H29: =TONTJANV!F29+TONTJANV!G29 -> 205000 | J29: 270000 | K29: 42568
A30: AS201642 | B30: =VLOOKUP(A30,[1]LISTADHERENT!A$5:H$49,2) -> TIEYAM ERNEST | C30: =IF(E30="ECHEC",0,100000) -> 100000 | D30: =IF(E30="ESPECES",0,0) -> 0 | E30: BANQUE | H30: =TONTJANV!F30+TONTJANV!G30 -> 0 | J30: 170000 | K30: 42785 | L30: SIME MATHIEU
A31: AS201645 | B31: =VLOOKUP(A31,[1]LISTADHERENT!A$5:H$49,2) -> YOUMBI EMMANUEL | C31: =IF(E31="ECHEC",0,100000) -> 100000 | D31: =IF(E31="ESPECES",0,0) -> 0 | E31: BANQUE | H31: =TONTJANV!F31+TONTJANV!G31 -> 0
A33: TOTAL | C33: =SUM(C6:C32) -> 2600000 | D33: =SUM(D6:D32) -> 0 | F33: =SUM(F6:F32) -> 864000 | G33: =SUM(G6:G32) -> 26000 | H33: =SUM(H6:H32) -> 1101500 | I33: =SUM(I6:I32) -> 0
B36: ESPECES | C36: =C33-C37 -> 1200000
B37: BANQUE | C37: 1400000
B38: REMBOURSEMENT | C38: =H33 -> 1101500

Sheet TONTAVRIL
A1: ASSOCIATION | B1: ASELBY
A2: ANNEE | B2: 2016/2017
A3: TONTINE | B3: 100000
C4: 42841
A5: MATRICULE | B5: NOM ET PRENOM | C5: MONTANT TONTINE | D5: PENALITE | E5: MODE VERSEMENT | F5: PRÊT | G5: INTERET PRÊT | H5: REMBOURSEMENT | I5: STATUT PRÊT | J5: INTERET ACHAT | K5: DATE ACHAT | L5: AVALISTE
A6: AS201602 | B6: =VLOOKUP(A6,[1]LISTADHERENT!A$5:H$49,2) -> BOUTCHOUANG WILLIAM | C6: =IF(E6="ECHEC",0,100000) -> 100000 | D6: =IF(E6="ESPECES",0,0) -> 0 | E6: ESPECES | H6: =TONTMARS!F6+TONTMARS!G6 -> 0 | J6: 200000 | K6: 42694
A7: AS201606 | B7: =VLOOKUP(A7,[1]LISTADHERENT!A$5:H$49,2) -> DJOUNKEP SAMUEL | C7: =IF(E7="ECHEC",0,100000) -> 100000 | D7: =IF(E7="ESPECES",0,0) -> 0 | E7: BANQUE | H7: =TONTMARS!F7+TONTMARS!G7 -> 0
A8: AS201607 | B8: =VLOOKUP(A8,[1]LISTADHERENT!A$5:H$49,2) -> DJUOMBESSY ANTOINE | C8: =IF(E8="ECHEC",0,100000) -> 100000 | D8: =IF(E8="ESPECES",0,0) -> 0 | E8: BANQUE | H8: =TONTMARS!F8+TONTMARS!G8 -> 0 | J8: 155000 | K8: 42723
A9: AS201609 | B9: =VLOOKUP(A9,[1]LISTADHERENT!A$5:H$49,2) -> FOTSO THOMAS | C9: =IF(E9="ECHEC",0,100000) -> 100000 | D9: =IF(E9="ESPECES",0,0) -> 0 | E9: ESPECES | F9: =100000+110000 -> 210000 | G9: =4000+11500 -> 15500 | H9: =TONTMARS!F9+TONTMARS!G9 -> 205500 | I9: OK | J9: 191000 | K9: 42603
A10: AS201612 | B10: =VLOOKUP(A10,[1]LISTADHERENT!A$5:H$49,2) -> HOTCHO BENJAMIN | C10: =IF(E10="ECHEC",0,100000) -> 100000 | D10: =IF(E10="ESPECES",0,0) -> 0 | E10: BANQUE | H10: =TONTMARS!F10+TONTMARS!G10 -> 0 | J10: 195000 | K10: 42694
A11: AS201612 | B11: =VLOOKUP(A11,[1]LISTADHERENT!A$5:H$49,2) -> HOTCHO BENJAMIN | C11: =IF(E11="ECHEC",0,100000) -> 100000 | D11: =IF(E11="ESPECES",0,0) -> 0 | E11: BANQUE | H11: =TONTMARS!F11+TONTMARS!G11 -> 0 | J11: 110000 | K11: 42476
A12: AS201614 | B12: =VLOOKUP(A12,[1]LISTADHERENT!A$5:H$49,2) -> KEPSEU FRANCIS | C12: =IF(E12="ECHEC",0,100000) -> 100000 | D12: =IF(E12="ESPECES",0,0) -> 0 | E12: BANQUE | H12: =TONTMARS!F12+TONTMARS!G12 -> 0
A13: AS201617 | B13: =VLOOKUP(A13,[1]LISTADHERENT!A$5:H$49,2) -> KOUAMOU MOISE | C13: =IF(E13="ECHEC",0,100000) -> 100000 | D13: =IF(E13="ESPECES",0,0) -> 0 | E13: BANQUE | H13: =TONTMARS!F13+TONTMARS!G13 -> 0 | J13: 110000 | K13: 42448
A14: AS201618 | B14: =VLOOKUP(A14,[1]LISTADHERENT!A$5:H$49,2) -> KOUAMOU VICTOR PEGUY | C14: =IF(E14="ECHEC",0,100000) -> 100000 | D14: =IF(E14="ESPECES",0,0) -> 0 | E14: ESPECES | F14: =100000+100000 -> 200000 | G14: =7000+11000 -> 18000 | H14: =TONTMARS!F14+TONTMARS!G14 -> 207000 | I14: OK | J14: 136000 | K14: 42659
A15: AS201619 | B15: =VLOOKUP(A15,[1]LISTADHERENT!A$5:H$49,2) -> KOUATCHO MESSACK | C15: =IF(E15="ECHEC",0,100000) -> 100000 | D15: =IF(E15="ESPECES",0,0) -> 0 | E15: ESPECES | H15: =TONTMARS!F15+TONTMARS!G15 -> 0 | J15: 136000 | K15: 42659
A16: AS201621 | B16: =VLOOKUP(A16,[1]LISTADHERENT!A$5:H$49,2) -> NANKAM APPOLINAIRE | C16: =IF(E16="ECHEC",0,100000) -> 100000 | D16: =IF(E16="ESPECES",0,0) -> 0 | E16: BANQUE | H16: =TONTMARS!F16+TONTMARS!G16 -> 0 | J16: 157000 | K16: 42632
A17: AS201622 | B17: =VLOOKUP(A17,[1]LISTADHERENT!A$5:H$49,2) -> NDJOMO ETIENNE | C17: =IF(E17="ECHEC",0,100000) -> 100000 | D17: =IF(E17="ESPECES",0,0) -> 0 | E17: BANQUE | H17: =TONTMARS!F17+TONTMARS!G17 -> 0
A18: AS201624 | B18: =VLOOKUP(A18,[1]LISTADHERENT!A$5:H$49,2) -> NGONDIEP CLAUDE | C18: =IF(E18="ECHEC",0,100000) -> 100000 | D18: =IF(E18="ESPECES",0,0) -> 0 | E18: BANQUE | H18: =TONTMARS!F18+TONTMARS!G18 -> 0
A19: AS201628 | B19: =VLOOKUP(A19,[1]LISTADHERENT!A$5:H$49,2) -> NKAMGANG JUSTIN DEJOLIE | C19: =IF(E19="ECHEC",0,100000) -> 100000 | D19: =IF(E19="ESPECES",0,0) -> 0 | E19: ESPECES | H19: =TONTMARS!F19+TONTMARS!G19 -> 102000 | I19: OK | J19: 200000 | K19: 42603
A20: AS201628 | B20: =VLOOKUP(A20,[1]LISTADHERENT!A$5:H$49,2) -> NKAMGANG JUSTIN DEJOLIE | C20: =IF(E20="ECHEC",0,100000) -> 100000 | D20: =IF(E20="ESPECES",0,0) -> 0 | E20: ESPECES | H20: =TONTMARS!F20+TONTMARS!G20 -> 0 | J20: 127000 | K20: 42750
A21: AS201628 | B21: =VLOOKUP(A21,[1]LISTADHERENT!A$5:H$49,2) -> NKAMGANG JUSTIN DEJOLIE | C21: =IF(E21="ECHEC",0,100000) -> 100000 | D21: =IF(E21="ESPECES",0,0) -> 0 | E21: ESPECES | H21: =TONTMARS!F21+TONTMARS!G21 -> 0 | J21: 110000 | K21: 42841
A22: AS201629 | B22: =VLOOKUP(A22,[1]LISTADHERENT!A$5:H$49,2) -> NKEPSEU DIEUDONNE | C22: =IF(E22="ECHEC",0,100000) -> 100000 | D22: =IF(E22="ESPECES",0,0) -> 0 | E22: ESPECES | H22: =TONTMARS!F22+TONTMARS!G22 -> 0 | J22: 127000 | K22: 42750
A23: AS201633 | B23: =VLOOKUP(A23,[1]LISTADHERENT!A$5:H$49,2) -> SEUNOU RICHELOT | C23: =IF(E23="ECHEC",0,100000) -> 100000 | D23: =IF(E23="ESPECES",0,0) -> 0 | E23: ESPECES | F23: 100000 | G23: 7500 | H23: =TONTMARS!F23+TONTMARS!G23 -> 0 | J23: 265000 | K23: 42568
A24: AS201633 | B24: =VLOOKUP(A24,[1]LISTADHERENT!A$5:H$49,2) -> SEUNOU RICHELOT | C24: =IF(E24="ECHEC",0,100000) -> 100000 | D24: =IF(E24="ESPECES",0,0) -> 0 | E24: ESPECES | H24: =TONTMARS!F24+TONTMARS!G24 -> 0 | J24: 111000 | K24: 42813
A25: AS201635 | B25: =VLOOKUP(A25,[1]LISTADHERENT!A$5:H$49,2) -> SIME FONGANG ERIC | C25: =IF(E25="ECHEC",0,100000) -> 100000 | D25: =IF(E25="ESPECES",0,0) -> 0 | E25: BANQUE | H25: =TONTMARS!F25+TONTMARS!G25 -> 0
A26: AS201636 | B26: =VLOOKUP(A26,[1]LISTADHERENT!A$5:H$49,2) -> SIME MATHIEU | C26: =IF(E26="ECHEC",0,100000) -> 100000 | D26: =IF(E26="ESPECES",0,0) -> 0 | E26: BANQUE | H26: =TONTMARS!F26+TONTMARS!G26 -> 169500 | I26: OK | J26: 147000 | K26: 42632
A27: AS201636 | B27: =VLOOKUP(A27,[1]LISTADHERENT!A$5:H$49,2) -> SIME MATHIEU | C27: =IF(E27="ECHEC",0,100000) -> 100000 | D27: =IF(E27="ESPECES",0,0) -> 0 | E27: BANQUE | H27: =TONTMARS!F27+TONTMARS!G27 -> 0 | J27: 155000 | K27: 42785 | L27: HOTCHO BENJAMIN
A28: AS201639 | B28: =VLOOKUP(A28,[1]LISTADHERENT!A$5:H$49,2) -> TCHOUAMOU MATHIEU | C28: =IF(E28="ECHEC",0,100000) -> 100000 | D28: =IF(E28="ESPECES",0,0) -> 0 | E28: BANQUE | H28: =TONTMARS!F28+TONTMARS!G28 -> 0
A29: AS201642 | B29: =VLOOKUP(A29,[1]LISTADHERENT!A$5:H$49,2) -> TIEYAM ERNEST | C29: =IF(E29="ECHEC",0,100000) -> 100000 | D29: =IF(E29="ESPECES",0,0) -> 0 | E29: ESPECES | F29: =100000+100000 -> 200000 | G29: =5000+7000 -> 12000 | H29: =TONTMARS!F29+TONTMARS!G29 -> 206000 | I29: OK | J29: 270000 | K29: 42568
A30: AS201642 | B30: =VLOOKUP(A30,[1]LISTADHERENT!A$5:H$49,2) -> TIEYAM ERNEST | C30: =IF(E30="ECHEC",0,100000) -> 100000 | D30: =IF(E30="ESPECES",0,0) -> 0 | E30: ESPECES | H30: =TONTMARS!F30+TONTMARS!G30 -> 0 | J30: 170000 | K30: 42785 | L30: SIME MATHIEU
A31: AS201645 | B31: =VLOOKUP(A31,[1]LISTADHERENT!A$5:H$49,2) -> YOUMBI EMMANUEL | C31: =IF(E31="ECHEC",0,100000) -> 100000 | D31: =IF(E31="ESPECES",0,0) -> 0 | E31: BANQUE | H31: =TONTMARS!F31+TONTMARS!G31 -> 0
A33: TOTAL | C33: =SUM(C6:C32) -> 2600000 | D33: =SUM(D6:D32) -> 0 | F33: =SUM(F6:F32) -> 710000 | G33: =SUM(G6:G32) -> 53000 | H33: =SUM(H6:H32) -> 890000 | I33: =SUM(I6:I32) -> 0
B36: ESPECES | C36: =SUMIFS(C6:C31,E6:E31,"ESPECES") -> 1200000
B37: BANQUE | C37: =SUMIFS(C6:C31,E6:E31,"BANQUE") -> 1400000
B38: REMBOURSEMENT | C38: =H33 -> 890000

Sheet TONTMAI
A1: ASSOCIATION | B1: ASELBY
A2: ANNEE | B2: 2016/2017
A3: TONTINE | B3: 100000
C4: 42876
A5: MATRICULE | B5: NOM ET PRENOM | C5: MONTANT TONTINE | D5: PENALITE | E5: MODE VERSEMENT | F5: PRÊT | G5: INTERET PRÊT | H5: REMBOURSEMENT | I5: STATUT PRÊT | J5: INTERET ACHAT | K5: DATE ACHAT | L5: AVALISTE
A6: AS201602 | B6: =VLOOKUP(A6,[1]LISTADHERENT!A$5:H$49,2) -> BOUTCHOUANG WILLIAM | C6: =IF(E6="ECHEC",0,100000) -> 100000 | D6: =IF(E6="ESPECES",0,0) -> 0 | E6: ESPECES | H6: =TONTAVRIL!F6+TONTAVRIL!G6 -> 0 | J6: 200000 | K6: 42694
A7: AS201606 | B7: =VLOOKUP(A7,[1]LISTADHERENT!A$5:H$49,2) -> DJOUNKEP SAMUEL | C7: =IF(E7="ECHEC",0,100000) -> 100000 | D7: =IF(E7="ESPECES",0,0) -> 0 | E7: BANQUE | H7: =TONTAVRIL!F7+TONTAVRIL!G7 -> 0
A8: AS201607 | B8: =VLOOKUP(A8,[1]LISTADHERENT!A$5:H$49,2) -> DJUOMBESSY ANTOINE | C8: =IF(E8="ECHEC",0,100000) -> 100000 | D8: =IF(E8="ESPECES",0,0) -> 0 | E8: ESPECES | H8: =TONTAVRIL!F8+TONTAVRIL!G8 -> 0 | J8: 155000 | K8: 42723
A9: AS201609 | B9: =VLOOKUP(A9,[1]LISTADHERENT!A$5:H$49,2) -> FOTSO THOMAS | C9: =IF(E9="ECHEC",0,100000) -> 100000 | D9: =IF(E9="ESPECES",0,0) -> 0 | E9: ESPECES | F9: 100000 | G9: 3000 | H9: =TONTAVRIL!F9+TONTAVRIL!G9 -> 225500 | I9: OK | J9: 191000 | K9: 42603
A10: AS201612 | B10: =VLOOKUP(A10,[1]LISTADHERENT!A$5:H$49,2) -> HOTCHO BENJAMIN | C10: =IF(E10="ECHEC",0,100000) -> 100000 | D10: =IF(E10="ESPECES",0,0) -> 0 | E10: BANQUE | H10: =TONTAVRIL!F10+TONTAVRIL!G10 -> 0 | J10: 195000 | K10: 42694
A11: AS201612 | B11: =VLOOKUP(A11,[1]LISTADHERENT!A$5:H$49,2) -> HOTCHO BENJAMIN | C11: =IF(E11="ECHEC",0,100000) -> 100000 | D11: =IF(E11="ESPECES",0,0) -> 0 | E11: BANQUE | H11: =TONTAVRIL!F11+TONTAVRIL!G11 -> 0 | J11: 110000 | K11: 42476
A12: AS201614 | B12: =VLOOKUP(A12,[1]LISTADHERENT!A$5:H$49,2) -> KEPSEU FRANCIS | C12: =IF(E12="ECHEC",0,100000) -> 100000 | D12: =IF(E12="ESPECES",0,0) -> 0 | E12: BANQUE | H12: =TONTAVRIL!F12+TONTAVRIL!G12 -> 0
A13: AS201617 | B13: =VLOOKUP(A13,[1]LISTADHERENT!A$5:H$49,2) -> KOUAMOU MOISE | C13: =IF(E13="ECHEC",0,100000) -> 100000 | D13: =IF(E13="ESPECES",0,0) -> 0 | E13: BANQUE | H13: =TONTAVRIL!F13+TONTAVRIL!G13 -> 0 | J13: 110000 | K13: 42448
A14: AS201618 | B14: =VLOOKUP(A14,[1]LISTADHERENT!A$5:H$49,2) -> KOUAMOU VICTOR PEGUY | C14: =IF(E14="ECHEC",0,100000) -> 100000 | D14: =IF(E14="ESPECES",0,0) -> 0 | E14: ESPECES | F14: 218000 | G14: 36000 | H14: =TONTAVRIL!F14+TONTAVRIL!G14 -> 218000 | J14: 136000 | K14: 42659
A15: AS201619 | B15: =VLOOKUP(A15,[1]LISTADHERENT!A$5:H$49,2) -> KOUATCHO MESSACK | C15: =IF(E15="ECHEC",0,100000) -> 100000 | D15: =IF(E15="ESPECES",0,0) -> 0 | E15: BANQUE | H15: =TONTAVRIL!F15+TONTAVRIL!G15 -> 0 | J15: 136000 | K15: 42659
A16: AS201621 | B16: =VLOOKUP(A16,[1]LISTADHERENT!A$5:H$49,2) -> NANKAM APPOLINAIRE | C16: =IF(E16="ECHEC",0,100000) -> 100000 | D16: =IF(E16="ESPECES",0,0) -> 0 | E16: BANQUE | H16: =TONTAVRIL!F16+TONTAVRIL!G16 -> 0 | J16: 157000 | K16: 42632
A17: AS201622 | B17: =VLOOKUP(A17,[1]LISTADHERENT!A$5:H$49,2) -> NDJOMO ETIENNE | C17: =IF(E17="ECHEC",0,100000) -> 100000 | D17: =IF(E17="ESPECES",0,0) -> 0 | E17: BANQUE | H17: =TONTAVRIL!F17+TONTAVRIL!G17 -> 0
A18: AS201624 | B18: =VLOOKUP(A18,[1]LISTADHERENT!A$5:H$49,2) -> NGONDIEP CLAUDE | C18: =IF(E18="ECHEC",0,100000) -> 100000 | D18: =IF(E18="ESPECES",0,0) -> 0 | E18: BANQUE | H18: =TONTAVRIL!F18+TONTAVRIL!G18 -> 0
A19: AS201628 | B19: =VLOOKUP(A19,[1]LISTADHERENT!A$5:H$49,2) -> NKAMGANG JUSTIN DEJOLIE | C19: =IF(E19="ECHEC",0,100000) -> 100000 | D19: =IF(E19="ESPECES",0,0) -> 0 | E19: BANQUE | H19: =TONTAVRIL!F19+TONTAVRIL!G19 -> 0 | J19: 200000 | K19: 42603
A20: AS201628 | B20: =VLOOKUP(A20,[1]LISTADHERENT!A$5:H$49,2) -> NKAMGANG JUSTIN DEJOLIE | C20: =IF(E20="ECHEC",0,100000) -> 100000 | D20: =IF(E20="ESPECES",0,0) -> 0 | E20: ESPECES | H20: =TONTAVRIL!F20+TONTAVRIL!G20 -> 0 | J20: 127000 | K20: 42750
A21: AS201628 | B21: =VLOOKUP(A21,[1]LISTADHERENT!A$5:H$49,2) -> NKAMGANG JUSTIN DEJOLIE | C21: =IF(E21="ECHEC",0,100000) -> 100000 | D21: =IF(E21="ESPECES",0,0) -> 0 | E21: ESPECES | F21: 38000 | G21: 1000 | H21: =TONTAVRIL!F21+TONTAVRIL!G21 -> 0 | J21: 110000 | K21: 42841
A22: AS201629 | B22: =VLOOKUP(A22,[1]LISTADHERENT!A$5:H$49,2) -> NKEPSEU DIEUDONNE | C22: =IF(E22="ECHEC",0,100000) -> 100000 | D22: =IF(E22="ESPECES",0,0) -> 0 | E22: ESPECES | H22: =TONTAVRIL!F22+TONTAVRIL!G22 -> 0 | J22: 127000 | K22: 42750
A23: AS201633 | B23: =VLOOKUP(A23,[1]LISTADHERENT!A$5:H$49,2) -> SEUNOU RICHELOT | C23: =IF(E23="ECHEC",0,100000) -> 100000 | D23: =IF(E23="ESPECES",0,0) -> 0 | E23: ESPECES | H23: =TONTAVRIL!F23+TONTAVRIL!G23 -> 107500 | I23: OK | J23: 265000 | K23: 42568
A24: AS201633 | B24: =VLOOKUP(A24,[1]LISTADHERENT!A$5:H$49,2) -> SEUNOU RICHELOT | C24: =IF(E24="ECHEC",0,100000) -> 100000 | D24: =IF(E24="ESPECES",0,0) -> 0 | E24: ESPECES | H24: =TONTAVRIL!F24+TONTAVRIL!G24 -> 0 | J24: 111000 | K24: 42813
A25: AS201635 | B25: =VLOOKUP(A25,[1]LISTADHERENT!A$5:H$49,2) -> SIME FONGANG ERIC | C25: =IF(E25="ECHEC",0,100000) -> 100000 | D25: =IF(E25="ESPECES",0,0) -> 0 | E25: ESPECES | H25: =TONTAVRIL!F25+TONTAVRIL!G25 -> 0 | J25: 100000 | K25: 42876 | L25: FOTSO THOMAS
A26: AS201636 | B26: =VLOOKUP(A26,[1]LISTADHERENT!A$5:H$49,2) -> SIME MATHIEU | C26: =IF(E26="ECHEC",0,100000) -> 100000 | D26: =IF(E26="ESPECES",0,0) -> 0 | E26: BANQUE | H26: =TONTAVRIL!F26+TONTAVRIL!G26 -> 0 | J26: 147000 | K26: 42632
A27: AS201636 | B27: =VLOOKUP(A27,[1]LISTADHERENT!A$5:H$49,2) -> SIME MATHIEU | C27: =IF(E27="ECHEC",0,100000) -> 100000 | D27: =IF(E27="ESPECES",0,0) -> 0 | E27: BANQUE | H27: =TONTAVRIL!F27+TONTAVRIL!G27 -> 0 | J27: 155000 | K27: 42785 | L27: HOTCHO BENJAMIN
A28: AS201639 | B28: =VLOOKUP(A28,[1]LISTADHERENT!A$5:H$49,2) -> TCHOUAMOU MATHIEU | C28: =IF(E28="ECHEC",0,100000) -> 100000 | D28: =IF(E28="ESPECES",0,0) -> 0 | E28: BANQUE | H28: =TONTAVRIL!F28+TONTAVRIL!G28 -> 0 | J28: 100000 | K28: 42876 | L28: NDJOMO ETIENNE
A29: AS201642 | B29: =VLOOKUP(A29,[1]LISTADHERENT!A$5:H$49,2) -> TIEYAM ERNEST | C29: =IF(E29="ECHEC",0,100000) -> 100000 | D29: =IF(E29="ESPECES",0,0) -> 0 | E29: BANQUE | F29: =100000+100000 -> 200000 | G29: =10000+10000 -> 20000 | H29: =TONTAVRIL!F29+TONTAVRIL!G29 -> 212000 | I29: OK | J29: 270000 | K29: 42568
A30: AS201642 | B30: =VLOOKUP(A30,[1]LISTADHERENT!A$5:H$49,2) -> TIEYAM ERNEST | C30: =IF(E30="ECHEC",0,100000) -> 100000 | D30: =IF(E30="ESPECES",0,0) -> 0 | E30: BANQUE | H30: =TONTAVRIL!F30+TONTAVRIL!G30 -> 0 | J30: 170000 | K30: 42785 | L30: SIME MATHIEU
A31: AS201645 | B31: =VLOOKUP(A31,[1]LISTADHERENT!A$5:H$49,2) -> YOUMBI EMMANUEL | C31: =IF(E31="ECHEC",0,100000) -> 100000 | D31: =IF(E31="ESPECES",0,0) -> 0 | E31: BANQUE | H31: =TONTAVRIL!F31+TONTAVRIL!G31 -> 0
A33: TOTAL | C33: =SUM(C6:C32) -> 2600000 | D33: =SUM(D6:D32) -> 0 | F33: =SUM(F6:F32) -> 556000 | G33: =SUM(G6:G32) -> 60000 | H33: =SUM(H6:H32) -> 763000 | I33: =SUM(I6:I32) -> 0
B36: ESPECES | C36: =SUMIFS(C6:C31,E6:E31,"ESPECES") -> 1000000
B37: BANQUE | C37: =SUMIFS(C6:C31,E6:E31,"BANQUE") -> 1600000
B38: REMBOURSEMENT | C38: =H33 -> 763000

Sheet TONTJUIN
A1: ASSOCIATION | B1: ASELBY
A2: ANNEE | B2: 2016/2017
A3: TONTINE | B3: 100000
C4: 42904
A5: MATRICULE | B5: NOM ET PRENOM | C5: MONTANT TONTINE | D5: PENALITE | E5: MODE VERSEMENT | F5: PRÊT | G5: INTERET PRÊT | H5: REMBOURSEMENT | I5: STATUT PRÊT | J5: INTERET ACHAT | K5: DATE ACHAT | L5: AVALISTE
A6: AS201602 | B6: =VLOOKUP(A6,[1]LISTADHERENT!A$5:H$49,2) -> BOUTCHOUANG WILLIAM | C6: =IF(E6="ECHEC",0,100000) -> 100000 | D6: =IF(E6="ESPECES",0,0) -> 0 | E6: ESPECES | H6: =TONTMAI!F6+TONTMAI!G6 -> 0 | J6: 200000 | K6: 42694
A7: AS201606 | B7: =VLOOKUP(A7,[1]LISTADHERENT!A$5:H$49,2) -> DJOUNKEP SAMUEL | C7: =IF(E7="ECHEC",0,100000) -> 100000 | D7: =IF(E7="ESPECES",0,0) -> 0 | E7: BANQUE | H7: =TONTMAI!F7+TONTMAI!G7 -> 0
A8: AS201607 | B8: =VLOOKUP(A8,[1]LISTADHERENT!A$5:H$49,2) -> DJUOMBESSY ANTOINE | C8: =IF(E8="ECHEC",0,100000) -> 100000 | D8: =IF(E8="ESPECES",0,0) -> 0 | E8: BANQUE | H8: =TONTMAI!F8+TONTMAI!G8 -> 0 | J8: 155000 | K8: 42723
A9: AS201609 | B9: =VLOOKUP(A9,[1]LISTADHERENT!A$5:H$49,2) -> FOTSO THOMAS | C9: =IF(E9="ECHEC",0,100000) -> 100000 | D9: =IF(E9="ESPECES",0,0) -> 0 | E9: ESPECES | H9: =TONTMAI!F9+TONTMAI!G9 -> 103000 | I9: OK | J9: 191000 | K9: 42603
A10: AS201612 | B10: =VLOOKUP(A10,[1]LISTADHERENT!A$5:H$49,2) -> HOTCHO BENJAMIN | C10: =IF(E10="ECHEC",0,100000) -> 100000 | D10: =IF(E10="ESPECES",0,0) -> 0 | E10: BANQUE | H10: =TONTMAI!F10+TONTMAI!G10 -> 0 | J10: 195000 | K10: 42694
A11: AS201612 | B11: =VLOOKUP(A11,[1]LISTADHERENT!A$5:H$49,2) -> HOTCHO BENJAMIN | C11: =IF(E11="ECHEC",0,100000) -> 100000 | D11: =IF(E11="ESPECES",0,0) -> 0 | E11: BANQUE | H11: =TONTMAI!F11+TONTMAI!G11 -> 0 | J11: 110000 | K11: 42476
A12: AS201614 | B12: =VLOOKUP(A12,[1]LISTADHERENT!A$5:H$49,2) -> KEPSEU FRANCIS | C12: =IF(E12="ECHEC",0,100000) -> 100000 | D12: =IF(E12="ESPECES",0,0) -> 0 | E12: BANQUE | H12: =TONTMAI!F12+TONTMAI!G12 -> 0 | J12: 126000 | K12: 42904 | L12: NANKAM APPOLINAIRE
A13: AS201617 | B13: =VLOOKUP(A13,[1]LISTADHERENT!A$5:H$49,2) -> KOUAMOU MOISE | C13: =IF(E13="ECHEC",0,100000) -> 100000 | D13: =IF(E13="ESPECES",0,0) -> 0 | E13: BANQUE | F13: 31000 | G13: 500 | H13: =TONTMAI!F13+TONTMAI!G13 -> 0 | J13: 110000 | K13: 42448
A14: AS201618 | B14: =VLOOKUP(A14,[1]LISTADHERENT!A$5:H$49,2) -> KOUAMOU VICTOR PEGUY | C14: =IF(E14="ECHEC",0,100000) -> 100000 | D14: =IF(E14="ESPECES",0,0) -> 0 | E14: BANQUE | H14: 218000 | I14: RESTE 36000 | J14: 136000 | K14: 42659
A15: AS201619 | B15: =VLOOKUP(A15,[1]LISTADHERENT!A$5:H$49,2) -> KOUATCHO MESSACK | C15: =IF(E15="ECHEC",0,100000) -> 100000 | D15: =IF(E15="ESPECES",0,0) -> 0 | E15: BANQUE | H15: =TONTMAI!F15+TONTMAI!G15 -> 0 | J15: 136000 | K15: 42659
A16: AS201621 | B16: =VLOOKUP(A16,[1]LISTADHERENT!A$5:H$49,2) -> NANKAM APPOLINAIRE | C16: =IF(E16="ECHEC",0,100000) -> 100000 | D16: =IF(E16="ESPECES",0,0) -> 0 | E16: BANQUE | H16: =TONTMAI!F16+TONTMAI!G16 -> 0 | J16: 157000 | K16: 42632
A17: AS201622 | B17: =VLOOKUP(A17,[1]LISTADHERENT!A$5:H$49,2) -> NDJOMO ETIENNE | C17: =IF(E17="ECHEC",0,100000) -> 100000 | D17: =IF(E17="ESPECES",0,0) -> 0 | E17: BANQUE | H17: =TONTMAI!F17+TONTMAI!G17 -> 0
A18: AS201624 | B18: =VLOOKUP(A18,[1]LISTADHERENT!A$5:H$49,2) -> NGONDIEP CLAUDE | C18: =IF(E18="ECHEC",0,100000) -> 100000 | D18: =IF(E18="ESPECES",0,0) -> 0 | E18: BANQUE | H18: =TONTMAI!F18+TONTMAI!G18 -> 0 | J18: 125000 | K18: 42904 | L18: TIEYAM ERNEST
A19: AS201628 | B19: =VLOOKUP(A19,[1]LISTADHERENT!A$5:H$49,2) -> NKAMGANG JUSTIN DEJOLIE | C19: =IF(E19="ECHEC",0,100000) -> 100000 | D19: =IF(E19="ESPECES",0,0) -> 0 | E19: BANQUE | F19: =100000+100000 -> 200000 | G19: =2000+2000 -> 4000 | H19: =TONTMAI!F19+TONTMAI!G19 -> 0 | J19: 200000 | K19: 42603
A20: AS201628 | B20: =VLOOKUP(A20,[1]LISTADHERENT!A$5:H$49,2) -> NKAMGANG JUSTIN DEJOLIE | C20: =IF(E20="ECHEC",0,100000) -> 100000 | D20: =IF(E20="ESPECES",0,0) -> 0 | E20: BANQUE | H20: =TONTMAI!F20+TONTMAI!G20 -> 0 | J20: 127000 | K20: 42750
A21: AS201628 | B21: =VLOOKUP(A21,[1]LISTADHERENT!A$5:H$49,2) -> NKAMGANG JUSTIN DEJOLIE | C21: =IF(E21="ECHEC",0,100000) -> 100000 | D21: =IF(E21="ESPECES",0,0) -> 0 | E21: BANQUE | H21: =TONTMAI!F21+TONTMAI!G21 -> 39000 | I21: OK | J21: 110000 | K21: 42841
A22: AS201629 | B22: =VLOOKUP(A22,[1]LISTADHERENT!A$5:H$49,2) -> NKEPSEU DIEUDONNE | C22: =IF(E22="ECHEC",0,100000) -> 100000 | D22: =IF(E22="ESPECES",0,0) -> 0 | E22: ESPECES | H22: =TONTMAI!F22+TONTMAI!G22 -> 0 | J22: 127000 | K22: 42750
A23: AS201633 | B23: =VLOOKUP(A23,[1]LISTADHERENT!A$5:H$49,2) -> SEUNOU RICHELOT | C23: =IF(E23="ECHEC",0,100000) -> 100000 | D23: =IF(E23="ESPECES",0,0) -> 0 | E23: ESPECES | H23: =TONTMAI!F23+TONTMAI!G23 -> 0 | J23: 265000 | K23: 42568
A24: AS201633 | B24: =VLOOKUP(A24,[1]LISTADHERENT!A$5:H$49,2) -> SEUNOU RICHELOT | C24: =IF(E24="ECHEC",0,100000) -> 100000 | D24: =IF(E24="ESPECES",0,0) -> 0 | E24: ESPECES | H24: =TONTMAI!F24+TONTMAI!G24 -> 0 | J24: 111000 | K24: 42813
A25: AS201635 | B25: =VLOOKUP(A25,[1]LISTADHERENT!A$5:H$49,2) -> SIME FONGANG ERIC | C25: =IF(E25="ECHEC",0,100000) -> 100000 | D25: =IF(E25="ESPECES",0,0) -> 0 | E25: BANQUE | H25: =TONTMAI!F25+TONTMAI!G25 -> 0 | J25: 100000 | K25: 42876 | L25: FOTSO THOMAS
A26: AS201636 | B26: =VLOOKUP(A26,[1]LISTADHERENT!A$5:H$49,2) -> SIME MATHIEU | C26: =IF(E26="ECHEC",0,100000) -> 100000 | D26: =IF(E26="ESPECES",0,0) -> 0 | E26: BANQUE | H26: =TONTMAI!F26+TONTMAI!G26 -> 0 | J26: 147000 | K26: 42632
A27: AS201636 | B27: =VLOOKUP(A27,[1]LISTADHERENT!A$5:H$49,2) -> SIME MATHIEU | C27: =IF(E27="ECHEC",0,100000) -> 100000 | D27: =IF(E27="ESPECES",0,0) -> 0 | E27: BANQUE | H27: =TONTMAI!F27+TONTMAI!G27 -> 0 | J27: 155000 | K27: 42785 | L27: HOTCHO BENJAMIN
A28: AS201639 | B28: =VLOOKUP(A28,[1]LISTADHERENT!A$5:H$49,2) -> TCHOUAMOU MATHIEU | C28: =IF(E28="ECHEC",0,100000) -> 100000 | D28: =IF(E28="ESPECES",0,0) -> 0 | E28: BANQUE | H28: =TONTMAI!F28+TONTMAI!G28 -> 0 | J28: 100000 | K28: 42876 | L28: NDJOMO ETIENNE
A29: AS201642 | B29: =VLOOKUP(A29,[1]LISTADHERENT!A$5:H$49,2) -> TIEYAM ERNEST | C29: =IF(E29="ECHEC",0,100000) -> 100000 | D29: =IF(E29="ESPECES",0,0) -> 0 | E29: BANQUE | F29: =100000+100000 -> 200000 | G29: =4000+3000 -> 7000 | H29: =TONTMAI!F29+TONTMAI!G29 -> 220000 | I29: OK | J29: 270000 | K29: 42568
A30: AS201642 | B30: =VLOOKUP(A30,[1]LISTADHERENT!A$5:H$49,2) -> TIEYAM ERNEST | C30: =IF(E30="ECHEC",0,100000) -> 100000 | D30: =IF(E30="ESPECES",0,0) -> 0 | E30: BANQUE | H30: =TONTMAI!F30+TONTMAI!G30 -> 0 | J30: 170000 | K30: 42785 | L30: SIME MATHIEU
A31: AS201645 | B31: =VLOOKUP(A31,[1]LISTADHERENT!A$5:H$49,2) -> YOUMBI EMMANUEL | C31: =IF(E31="ECHEC",0,100000) -> 100000 | D31: =IF(E31="ESPECES",0,0) -> 0 | E31: BANQUE | H31: =TONTMAI!F31+TONTMAI!G31 -> 0
A33: TOTAL | C33: =SUM(C6:C32) -> 2600000 | D33: =SUM(D6:D32) -> 0 | F33: =SUM(F6:F32) -> 431000 | G33: =SUM(G6:G32) -> 11500 | H33: =SUM(H6:H32) -> 580000 | I33: =SUM(I6:I32) -> 0
B36: ESPECES | C36: =SUMIFS(C6:C31,E6:E31,"ESPECES") -> 500000 | E36: 375000 | F36: =C36+E36 -> 875000
B37: BANQUE | C37: =SUMIFS(C6:C31,E6:E31,"BANQUE") -> 2100000 | E37: 205000 | F37: =C37+E37 -> 2305000
B38: REMBOURSEMENT | C38: =H33 -> 580000

Sheet TONTJUIL
A1: ASSOCIATION | B1: ASELBY
A2: ANNEE | B2: 2016/2017
A3: TONTINE | B3: 100000
C4: 42932
A5: MATRICULE | B5: NOM ET PRENOM | C5: MONTANT TONTINE | D5: PENALITE | E5: MODE VERSEMENT | F5: PRÊT | G5: INTERET PRÊT | H5: REMBOURSEMENT | I5: STATUT PRÊT | J5: INTERET ACHAT | K5: DATE ACHAT | L5: AVALISTE
A6: AS201602 | B6: =VLOOKUP(A6,[1]LISTADHERENT!A$5:H$49,2) -> BOUTCHOUANG WILLIAM | C6: =IF(E6="ECHEC",0,100000) -> 100000 | D6: =IF(E6="ESPECES",0,0) -> 0 | E6: ESPECES | H6: =TONTJUIN!F6+TONTJUIN!G6 -> 0 | J6: 200000 | K6: 42694
A7: AS201606 | B7: =VLOOKUP(A7,[1]LISTADHERENT!A$5:H$49,2) -> DJOUNKEP SAMUEL | C7: =IF(E7="ECHEC",0,100000) -> 100000 | D7: =IF(E7="ESPECES",0,0) -> 0 | E7: BANQUE | H7: =TONTJUIN!F7+TONTJUIN!G7 -> 0
A8: AS201607 | B8: =VLOOKUP(A8,[1]LISTADHERENT!A$5:H$49,2) -> DJUOMBESSY ANTOINE | C8: =IF(E8="ECHEC",0,100000) -> 100000 | D8: =IF(E8="ESPECES",0,0) -> 0 | E8: BANQUE | H8: =TONTJUIN!F8+TONTJUIN!G8 -> 0 | J8: 155000 | K8: 42723
A9: AS201609 | B9: =VLOOKUP(A9,[1]LISTADHERENT!A$5:H$49,2) -> FOTSO THOMAS | C9: =IF(E9="ECHEC",0,100000) -> 100000 | D9: =IF(E9="ESPECES",0,0) -> 0 | E9: BANQUE | H9: =TONTJUIN!F9+TONTJUIN!G9 -> 0 | J9: 191000 | K9: 42603
A10: AS201612 | B10: =VLOOKUP(A10,[1]LISTADHERENT!A$5:H$49,2) -> HOTCHO BENJAMIN | C10: =IF(E10="ECHEC",0,100000) -> 100000 | D10: =IF(E10="ESPECES",0,0) -> 0 | E10: BANQUE | H10: =TONTJUIN!F10+TONTJUIN!G10 -> 0 | J10: 195000 | K10: 42694
A11: AS201612 | B11: =VLOOKUP(A11,[1]LISTADHERENT!A$5:H$49,2) -> HOTCHO BENJAMIN | C11: =IF(E11="ECHEC",0,100000) -> 100000 | D11: =IF(E11="ESPECES",0,0) -> 0 | E11: BANQUE | H11: =TONTJUIN!F11+TONTJUIN!G11 -> 0 | J11: 110000 | K11: 42476
A12: AS201614 | B12: =VLOOKUP(A12,[1]LISTADHERENT!A$5:H$49,2) -> KEPSEU FRANCIS | C12: =IF(E12="ECHEC",0,100000) -> 100000 | D12: =IF(E12="ESPECES",0,0) -> 0 | E12: BANQUE | H12: =TONTJUIN!F12+TONTJUIN!G12 -> 0 | J12: 126000 | K12: 42904 | L12: NANKAM APPOLINAIRE
A13: AS201617 | B13: =VLOOKUP(A13,[1]LISTADHERENT!A$5:H$49,2) -> KOUAMOU MOISE | C13: =IF(E13="ECHEC",0,100000) -> 100000 | D13: =IF(E13="ESPECES",0,0) -> 0 | E13: BANQUE | F13: 79500 | G13: 5000 | H13: =TONTJUIN!F13+TONTJUIN!G13 -> 31500 | I13: OK ESPECES | J13: 110000 | K13: 42448
A14: AS201618 | B14: =VLOOKUP(A14,[1]LISTADHERENT!A$5:H$49,2) -> KOUAMOU VICTOR PEGUY | C14: =IF(E14="ECHEC",0,100000) -> 100000 | D14: =IF(E14="ESPECES",0,0) -> 0 | E14: BANQUE | H14: =TONTJUIN!F14+TONTJUIN!G14 -> 0 | J14: 136000 | K14: 42659
A15: AS201619 | B15: =VLOOKUP(A15,[1]LISTADHERENT!A$5:H$49,2) -> KOUATCHO MESSACK | C15: =IF(E15="ECHEC",0,100000) -> 100000 | D15: =IF(E15="ESPECES",0,0) -> 0 | E15: BANQUE | H15: =TONTJUIN!F15+TONTJUIN!G15 -> 0 | J15: 136000 | K15: 42659
A16: AS201621 | B16: =VLOOKUP(A16,[1]LISTADHERENT!A$5:H$49,2) -> NANKAM APPOLINAIRE | C16: =IF(E16="ECHEC",0,100000) -> 100000 | D16: =IF(E16="ESPECES",0,0) -> 0 | E16: BANQUE | H16: =TONTJUIN!F16+TONTJUIN!G16 -> 0 | J16: 157000 | K16: 42632
A17: AS201622 | B17: =VLOOKUP(A17,[1]LISTADHERENT!A$5:H$49,2) -> NDJOMO ETIENNE | C17: =IF(E17="ECHEC",0,100000) -> 100000 | D17: =IF(E17="ESPECES",0,0) -> 0 | E17: BANQUE | H17: =TONTJUIN!F17+TONTJUIN!G17 -> 0 | J17: 101000 | K17: 42932
A18: AS201624 | B18: =VLOOKUP(A18,[1]LISTADHERENT!A$5:H$49,2) -> NGONDIEP CLAUDE | C18: =IF(E18="ECHEC",0,100000) -> 100000 | D18: =IF(E18="ESPECES",0,0) -> 0 | E18: BANQUE | H18: =TONTJUIN!F18+TONTJUIN!G18 -> 0 | J18: 125000 | K18: 42904 | L18: TIEYAM ERNEST
A19: AS201628 | B19: =VLOOKUP(A19,[1]LISTADHERENT!A$5:H$49,2) -> NKAMGANG JUSTIN DEJOLIE | C19: =IF(E19="ECHEC",0,100000) -> 100000 | D19: =IF(E19="ESPECES",0,0) -> 0 | E19: ESPECES | F19: 100000 | G19: 9000 | H19: =TONTJUIN!F19+TONTJUIN!G19 -> 204000 | I19: OK ESPECES | J19: 200000 | K19: 42603
A20: AS201628 | B20: =VLOOKUP(A20,[1]LISTADHERENT!A$5:H$49,2) -> NKAMGANG JUSTIN DEJOLIE | C20: =IF(E20="ECHEC",0,100000) -> 100000 | D20: =IF(E20="ESPECES",0,0) -> 0 | E20: ESPECES | H20: =TONTJUIN!F20+TONTJUIN!G20 -> 0 | J20: 127000 | K20: 42750
A21: AS201628 | B21: =VLOOKUP(A21,[1]LISTADHERENT!A$5:H$49,2) -> NKAMGANG JUSTIN DEJOLIE | C21: =IF(E21="ECHEC",0,100000) -> 100000 | D21: =IF(E21="ESPECES",0,0) -> 0 | E21: ESPECES | H21: =TONTJUIN!F21+TONTJUIN!G21 -> 0 | J21: 110000 | K21: 42841
A22: AS201629 | B22: =VLOOKUP(A22,[1]LISTADHERENT!A$5:H$49,2) -> NKEPSEU DIEUDONNE | C22: =IF(E22="ECHEC",0,100000) -> 100000 | D22: =IF(E22="ESPECES",0,0) -> 0 | E22: BANQUE | H22: =TONTJUIN!F22+TONTJUIN!G22 -> 0 | J22: 127000 | K22: 42750
A23: AS201633 | B23: =VLOOKUP(A23,[1]LISTADHERENT!A$5:H$49,2) -> SEUNOU RICHELOT | C23: =IF(E23="ECHEC",0,100000) -> 100000 | D23: =IF(E23="ESPECES",0,0) -> 0 | E23: ESPECES | H23: =TONTJUIN!F23+TONTJUIN!G23 -> 0 | J23: 265000 | K23: 42568
A24: AS201633 | B24: =VLOOKUP(A24,[1]LISTADHERENT!A$5:H$49,2) -> SEUNOU RICHELOT | C24: =IF(E24="ECHEC",0,100000) -> 100000 | D24: =IF(E24="ESPECES",0,0) -> 0 | E24: ESPECES | H24: =TONTJUIN!F24+TONTJUIN!G24 -> 0 | J24: 111000 | K24: 42813
A25: AS201635 | B25: =VLOOKUP(A25,[1]LISTADHERENT!A$5:H$49,2) -> SIME FONGANG ERIC | C25: =IF(E25="ECHEC",0,100000) -> 100000 | D25: =IF(E25="ESPECES",0,0) -> 0 | E25: ESPECES | H25: =TONTJUIN!F25+TONTJUIN!G25 -> 0 | J25: 100000 | K25: 42876 | L25: FOTSO THOMAS
A26: AS201636 | B26: =VLOOKUP(A26,[1]LISTADHERENT!A$5:H$49,2) -> SIME MATHIEU | C26: =IF(E26="ECHEC",0,100000) -> 100000 | D26: =IF(E26="ESPECES",0,0) -> 0 | E26: BANQUE | H26: =TONTJUIN!F26+TONTJUIN!G26 -> 0 | J26: 147000 | K26: 42632
A27: AS201636 | B27: =VLOOKUP(A27,[1]LISTADHERENT!A$5:H$49,2) -> SIME MATHIEU | C27: =IF(E27="ECHEC",0,100000) -> 100000 | D27: =IF(E27="ESPECES",0,0) -> 0 | E27: BANQUE | H27: =TONTJUIN!F27+TONTJUIN!G27 -> 0 | J27: 155000 | K27: 42785 | L27: HOTCHO BENJAMIN
A28: AS201639 | B28: =VLOOKUP(A28,[1]LISTADHERENT!A$5:H$49,2) -> TCHOUAMOU MATHIEU | C28: =IF(E28="ECHEC",0,100000) -> 100000 | D28: =IF(E28="ESPECES",0,0) -> 0 | E28: BANQUE | H28: =TONTJUIN!F28+TONTJUIN!G28 -> 0 | J28: 100000 | K28: 42876 | L28: NDJOMO ETIENNE
A29: AS201642 | B29: =VLOOKUP(A29,[1]LISTADHERENT!A$5:H$49,2) -> TIEYAM ERNEST | C29: =IF(E29="ECHEC",0,100000) -> 100000 | D29: =IF(E29="ESPECES",0,0) -> 0 | E29: ESPECES | F29: 100000 | G29: 10000 | H29: =TONTJUIN!F29+TONTJUIN!G29 -> 207000 | I29: OK ESPECES | J29: 270000 | K29: 42568
A30: AS201642 | B30: =VLOOKUP(A30,[1]LISTADHERENT!A$5:H$49,2) -> TIEYAM ERNEST | C30: =IF(E30="ECHEC",0,100000) -> 100000 | D30: =IF(E30="ESPECES",0,0) -> 0 | E30: ESPECES | H30: =TONTJUIN!F30+TONTJUIN!G30 -> 0 | J30: 170000 | K30: 42785 | L30: SIME MATHIEU
A31: AS201645 | B31: =VLOOKUP(A31,[1]LISTADHERENT!A$5:H$49,2) -> YOUMBI EMMANUEL | C31: =IF(E31="ECHEC",0,100000) -> 100000 | D31: =IF(E31="ESPECES",0,0) -> 0 | E31: BANQUE | H31: =TONTJUIN!F31+TONTJUIN!G31 -> 0 | J31: 100000 | K31: 42932
A33: TOTAL | C33: =SUM(C6:C32) -> 2600000 | D33: =SUM(D6:D32) -> 0 | F33: =SUM(F6:F32) -> 279500 | G33: =SUM(G6:G32) -> 24000 | H33: =SUM(H6:H32) -> 442500 | I33: =SUM(I6:I32) -> 0
B36: ESPECES | C36: =SUMIFS(C6:C31,E6:E31,"ESPECES") -> 900000 | E36: 375000 | F36: =C36+E36 -> 1275000
B37: BANQUE | C37: =SUMIFS(C6:C31,E6:E31,"BANQUE") -> 1700000 | E37: 205000 | F37: =C37+E37 -> 1905000
B38: REMBOURSEMENT | C38: =H33 -> 442500

Sheet TONTAOUT
A1: ASSOCIATION | B1: ASELBY
A2: ANNEE | B2: 2016/2017
A3: TONTINE | B3: 100000
C4: 42967 | N4: 26
A5: MATRICULE | B5: NOM ET PRENOM | C5: MONTANT TONTINE | D5: PENALITE | E5: MODE VERSEMENT | F5: PRÊT | G5: INTERET PRÊT | H5: REMBOURSEMENT | I5: STATUT PRÊT | J5: INTERET ACHAT | K5: DATE ACHAT | L5: AVALISTE | M5: INTERET | N5: PERCU
A6: AS201602 | B6: =VLOOKUP(A6,[1]LISTADHERENT!A$5:H$49,2) -> BOUTCHOUANG WILLIAM | C6: =IF(E6="ECHEC",0,100000) -> 100000 | D6: =IF(E6="ESPECES",0,0) -> 0 | E6: ESPECES | H6: =TONTJUIL!F6+TONTJUIL!G6 -> 0 | J6: 200000 | K6: 42694 | M6: =$C$42/$N$4 -> 57826.923 | N6: =M6-57000 -> 826.92308
A7: AS201606 | B7: =VLOOKUP(A7,[1]LISTADHERENT!A$5:H$49,2) -> DJOUNKEP SAMUEL | C7: =IF(E7="ECHEC",0,100000) -> 100000 | D7: =IF(E7="ESPECES",0,0) -> 0 | E7: BANQUE | H7: =TONTJUIL!F7+TONTJUIL!G7 -> 0 | J7: 100000 | K7: 42967 | M7: =$C$42/$N$4 -> 57826.923 | N7: =M7-57000 -> 826.92308
A8: AS201607 | B8: =VLOOKUP(A8,[1]LISTADHERENT!A$5:H$49,2) -> DJUOMBESSY ANTOINE | C8: =IF(E8="ECHEC",0,100000) -> 100000 | D8: =IF(E8="ESPECES",0,0) -> 0 | E8: BANQUE | H8: =TONTJUIL!F8+TONTJUIL!G8 -> 0 | J8: 155000 | K8: 42723 | M8: =$C$42/$N$4 -> 57826.923 | N8: =M8-57000 -> 826.92308
A9: AS201609 | B9: =VLOOKUP(A9,[1]LISTADHERENT!A$5:H$49,2) -> FOTSO THOMAS | C9: =IF(E9="ECHEC",0,100000) -> 100000 | D9: =IF(E9="ESPECES",0,0) -> 0 | E9: ESPECES | H9: =TONTJUIL!F9+TONTJUIL!G9 -> 0 | J9: 191000 | K9: 42603 | M9: =$C$42/$N$4 -> 57826.923 | N9: =M9-57000 -> 826.92308
A10: AS201612 | B10: =VLOOKUP(A10,[1]LISTADHERENT!A$5:H$49,2) -> HOTCHO BENJAMIN | C10: =IF(E10="ECHEC",0,100000) -> 100000 | D10: =IF(E10="ESPECES",0,0) -> 0 | E10: BANQUE | H10: =TONTJUIL!F10+TONTJUIL!G10 -> 0 | J10: 195000 | K10: 42694 | M10: =$C$42/$N$4 -> 57826.923 | N10: =M10-57000 -> 826.92308
A11: AS201612 | B11: =VLOOKUP(A11,[1]LISTADHERENT!A$5:H$49,2) -> HOTCHO BENJAMIN | C11: =IF(E11="ECHEC",0,100000) -> 100000 | D11: =IF(E11="ESPECES",0,0) -> 0 | E11: BANQUE | H11: =TONTJUIL!F11+TONTJUIL!G11 -> 0 | J11: 110000 | K11: 42476 | M11: =$C$42/$N$4 -> 57826.923 | N11: =M11-57000 -> 826.92308
A12: AS201614 | B12: =VLOOKUP(A12,[1]LISTADHERENT!A$5:H$49,2) -> KEPSEU FRANCIS | C12: =IF(E12="ECHEC",0,100000) -> 100000 | D12: =IF(E12="ESPECES",0,0) -> 0 | E12: BANQUE | H12: =TONTJUIL!F12+TONTJUIL!G12 -> 0 | J12: 126000 | K12: 42904 | L12: NANKAM APPOLINAIRE | M12: =$C$42/$N$4 -> 57826.923 | N12: =M12-57000 -> 826.92308
A13: AS201617 | B13: =VLOOKUP(A13,[1]LISTADHERENT!A$5:H$49,2) -> KOUAMOU MOISE | C13: =IF(E13="ECHEC",0,100000) -> 100000 | D13: =IF(E13="ESPECES",0,0) -> 0 | E13: BANQUE | H13: =TONTJUIL!F13+TONTJUIL!G13 -> 84500 | I13: OK | J13: 110000 | K13: 42448 | M13: =$C$42/$N$4 -> 57826.923 | N13: =M13-57000 -> 826.92308
A14: AS201618 | B14: =VLOOKUP(A14,[1]LISTADHERENT!A$5:H$49,2) -> KOUAMOU VICTOR PEGUY | C14: =IF(E14="ECHEC",0,100000) -> 100000 | D14: =IF(E14="ESPECES",0,0) -> 0 | E14: ESPECES | H14: =TONTJUIL!F14+TONTJUIL!G14 -> 0 | J14: 136000 | K14: 42659 | M14: =$C$42/$N$4 -> 57826.923 | N14: =M14-57000 -> 826.92308
A15: AS201619 | B15: =VLOOKUP(A15,[1]LISTADHERENT!A$5:H$49,2) -> KOUATCHO MESSACK | C15: =IF(E15="ECHEC",0,100000) -> 100000 | D15: =IF(E15="ESPECES",0,0) -> 0 | E15: ESPECES | H15: =TONTJUIL!F15+TONTJUIL!G15 -> 0 | J15: 136000 | K15: 42659 | M15: =$C$42/$N$4 -> 57826.923 | N15: =M15-57000 -> 826.92308
A16: AS201621 | B16: =VLOOKUP(A16,[1]LISTADHERENT!A$5:H$49,2) -> NANKAM APPOLINAIRE | C16: =IF(E16="ECHEC",0,100000) -> 100000 | D16: =IF(E16="ESPECES",0,0) -> 0 | E16: BANQUE | H16: =TONTJUIL!F16+TONTJUIL!G16 -> 0 | J16: 157000 | K16: 42632 | M16: =$C$42/$N$4 -> 57826.923 | N16: =M16-57000 -> 826.92308
A17: AS201622 | B17: =VLOOKUP(A17,[1]LISTADHERENT!A$5:H$49,2) -> NDJOMO ETIENNE | C17: =IF(E17="ECHEC",0,100000) -> 100000 | D17: =IF(E17="ESPECES",0,0) -> 0 | E17: BANQUE | H17: =TONTJUIL!F17+TONTJUIL!G17 -> 0 | J17: 101000 | K17: 42932 | M17: =$C$42/$N$4 -> 57826.923 | N17: =M17-57000 -> 826.92308
A18: AS201624 | B18: =VLOOKUP(A18,[1]LISTADHERENT!A$5:H$49,2) -> NGONDIEP CLAUDE | C18: =IF(E18="ECHEC",0,100000) -> 100000 | D18: =IF(E18="ESPECES",0,0) -> 0 | E18: BANQUE | H18: =TONTJUIL!F18+TONTJUIL!G18 -> 0 | J18: 125000 | K18: 42904 | L18: TIEYAM ERNEST | M18: =$C$42/$N$4 -> 57826.923 | N18: =M18-57000 -> 826.92308
A19: AS201628 | B19: =VLOOKUP(A19,[1]LISTADHERENT!A$5:H$49,2) -> NKAMGANG JUSTIN DEJOLIE | C19: =IF(E19="ECHEC",0,100000) -> 100000 | D19: =IF(E19="ESPECES",0,0) -> 0 | E19: ESPECES | H19: =TONTJUIL!F19+TONTJUIL!G19 -> 109000 | I19: OK | J19: 200000 | K19: 42603 | M19: =$C$42/$N$4 -> 57826.923 | N19: =M19-57000 -> 826.92308
A20: AS201628 | B20: =VLOOKUP(A20,[1]LISTADHERENT!A$5:H$49,2) -> NKAMGANG JUSTIN DEJOLIE | C20: =IF(E20="ECHEC",0,100000) -> 100000 | D20: =IF(E20="ESPECES",0,0) -> 0 | E20: ESPECES | H20: =TONTJUIL!F20+TONTJUIL!G20 -> 0 | J20: 127000 | K20: 42750 | M20: =$C$42/$N$4 -> 57826.923 | N20: =M20-57000 -> 826.92308
A21: AS201628 | B21: =VLOOKUP(A21,[1]LISTADHERENT!A$5:H$49,2) -> NKAMGANG JUSTIN DEJOLIE | C21: =IF(E21="ECHEC",0,100000) -> 100000 | D21: =IF(E21="ESPECES",0,0) -> 0 | E21: ESPECES | H21: =TONTJUIL!F21+TONTJUIL!G21 -> 0 | J21: 110000 | K21: 42841 | M21: =$C$42/$N$4 -> 57826.923 | N21: =M21-57000 -> 826.92308
A22: AS201629 | B22: =VLOOKUP(A22,[1]LISTADHERENT!A$5:H$49,2) -> NKEPSEU DIEUDONNE | C22: =IF(E22="ECHEC",0,100000) -> 100000 | D22: =IF(E22="ESPECES",0,0) -> 0 | E22: ESPECES | H22: =TONTJUIL!F22+TONTJUIL!G22 -> 0 | J22: 127000 | K22: 42750 | M22: =$C$42/$N$4 -> 57826.923 | N22: =M22-57000 -> 826.92308
A23: AS201633 | B23: =VLOOKUP(A23,[1]LISTADHERENT!A$5:H$49,2) -> SEUNOU RICHELOT | C23: =IF(E23="ECHEC",0,100000) -> 100000 | D23: =IF(E23="ESPECES",0,0) -> 0 | E23: ESPECES | H23: =TONTJUIL!F23+TONTJUIL!G23 -> 0 | J23: 265000 | K23: 42568 | M23: =$C$42/$N$4 -> 57826.923 | N23: =M23-57000 -> 826.92308
A24: AS201633 | B24: =VLOOKUP(A24,[1]LISTADHERENT!A$5:H$49,2) -> SEUNOU RICHELOT | C24: =IF(E24="ECHEC",0,100000) -> 100000 | D24: =IF(E24="ESPECES",0,0) -> 0 | E24: ESPECES | H24: =TONTJUIL!F24+TONTJUIL!G24 -> 0 | J24: 111000 | K24: 42813 | M24: =$C$42/$N$4 -> 57826.923 | N24: =M24-57000 -> 826.92308
A25: AS201635 | B25: =VLOOKUP(A25,[1]LISTADHERENT!A$5:H$49,2) -> SIME FONGANG ERIC | C25: =IF(E25="ECHEC",0,100000) -> 100000 | D25: =IF(E25="ESPECES",0,0) -> 0 | E25: BANQUE | H25: =TONTJUIL!F25+TONTJUIL!G25 -> 0 | J25: 100000 | K25: 42876 | L25: FOTSO THOMAS | M25: =$C$42/$N$4 -> 57826.923 | N25: =M25-57000 -> 826.92308
