Workbook
Name BANQUE: #REF!
Name BANQUE: #REF!
Name BANQUE: #REF!
Name BANQUE: #REF!
Name BANQUE: #REF!
Name BANQUE: #REF!
Name BANQUE: #REF!
Name BANQUE: #REF!
Name BANQUE: #REF!
Name BANQUE: #REF!
Name BANQUE: #REF!
Name BANQUE: #REF!
Name BANQUE: #REF!
Name BANQUE: #REF!
Name BANQUE: #REF!
Name BANQUE: #REF!
Name BANQUE: #REF!
Name BANQUE: #REF!
Name BANQUE: #REF!
Name BANQUE: #REF!
Name BANQUE: #REF!
Name BANQUE: #REF!
Name BANQUE: #REF!
Name BANQUE: #REF!
Name BANQUE: #REF!
Name BANQUE: #REF!
Name BANQUE: #REF!
Name BANQUE: #REF!
Name MODEPAID: MODEPAID!$A$1:$A$3
Name MODEPAID: [1]Feuil2!$A$1:$A$3
Name MODEPAID: [1]Feuil2!$A$1:$A$3
Name MODEPAID: [1]Feuil2!$A$1:$A$3
Name MODEPAID: [1]Feuil2!$A$1:$A$3
Name MODEPAID: [1]Feuil2!$A$1:$A$3
Name MODEPAID: [1]Feuil2!$A$1:$A$3
Name MODEPAID: [1]Feuil2!$A$1:$A$3
Name MODEPAID: [1]Feuil2!$A$1:$A$3
Name MODEPAID: [1]Feuil2!$A$1:$A$3
Name MODEPAID: [1]Feuil2!$A$1:$A$3
Name MODEPAID: [1]Feuil2!$A$1:$A$3
Name MODEPAID: [1]Feuil2!$A$1:$A$3
Name MODEPAID: [1]Feuil2!$A$1:$A$3
Name MODEPAID: [1]Feuil2!$A$1:$A$3
Name MODEPAID: [1]Feuil2!$A$1:$A$3
Name MODEPAID: [1]Feuil2!$A$1:$A$3
Name MODEPAID: [1]Feuil2!$A$1:$A$3
Name MODEPAID: [1]Feuil2!$A$1:$A$3
Name MODEPAID: [1]Feuil2!$A$1:$A$3
Name MODEPAID: [1]Feuil2!$A$1:$A$3
Name MODEPAID: [1]Feuil2!$A$1:$A$3
Name MODEPAID: [1]Feuil2!$A$1:$A$3
Name MODEPAID: [1]Feuil2!$A$1:$A$3
Name MODEPAID: [1]Feuil2!$A$1:$A$3
Name MODEPAID: [1]Feuil2!$A$1:$A$3
Name MODEPAID: [1]Feuil2!$A$1:$A$3
Name MODEPAID: [1]Feuil2!$A$1:$A$3
Name MODEPAID: #REF!
Name MODET25000: [2]MODEVERSEMENT!$A$1:$A$3
Name MODEVERSEMENT: #REF!
Name MODEVERSEMENT: #REF!

Sheet MODEPAID
A1: BANQUE
A2: ESPECES
A3: ECHEC

Sheet TONTJANV25
A1: ASSOCIATION | B1: ASELBY
A2: ANNEE | B2: 2025 | C2: TONIINE | D2: NBRE PART
A3: TAUX TONTINE | B3: 75000 | C3: =B3*12 -> 900000 | D3: =ROUNDDOWN(K22/C3,0) -> 1
C4: 45670
A5: MATRICULE | B5: NBREPART | C5: NOM ET PRENOM | D5: MONTANT TONTINE | E5: MODE VERSEMENT | F5: VENTE PETIT LOT | G5: INTERET PETIT LOT | H5: MODE VERSEMENT VENTE PETIT LOT | I5: NUMERO CHEQUE | J5: MONTANT A REMBOURSER PETIT LOT | K5: REMBOURSEMENT PETIT LOT | L5: MODE VERSEMENT REMBOURSEMENT | M5: MODE VERSEMENTLOT PRINCIPAL | N5: NUMERO CHEQUE | O5: MONTANT LOT PRINCIPAL | P5: INTERET LOT PRINCIPAL
A6: AS201648 | B6: =IF(D6=0,0,VLOOKUP($A6,[6]HISTOJANV25!$A$6:$BB$47,12,0)) -> 2 | C6: =VLOOKUP(A6,[7]LISTADHERENT!A$5:H$60,3,0) -> ASELBY | D6: =IF(E6="ECHEC",0,VLOOKUP($A6,[6]HISTOJANV25!$A$6:$AR$47,13,0)) -> 150000 | E6: =VLOOKUP($A6,[6]HISTOJANV25!$A$6:$AV$47,9,0) -> BANQUE | F6: =VLOOKUP($A6,[6]HISTOJANV25!$A$6:$AV$47,36,0) -> 0 | G6: =VLOOKUP($A6,[6]HISTOJANV25!$A$6:$AV$47,39,0) -> 0 | H6: =IF(G6=0,"",VLOOKUP($A6,[6]HISTOFEV25!$A$6:$AV$47,42,0)) | I6: =VLOOKUP($A6,[6]HISTOJANV25!$A$6:$AV$47,41,0) -> 0 | K6: =VLOOKUP($A6,[6]HISTOJANV25!$A$6:$AV$47,17,0) -> 0 | L6: =IF(K6<>0,VLOOKUP($A6,[6]HISTOJANV25!$A$6:$BB$47,9,0),"ECHEC") -> ECHEC | M6: =IF(P6=0,0,VLOOKUP($A6,[6]HISTOJANV25!$A$6:$AV$47,32,0)) -> 0 | N6: =VLOOKUP($A6,[6]HISTOJANV25!$A$6:$AV$47,33,0) -> 0 | O6: =IF(P6=0,0,($C$3-P6)) -> 0 | P6: =VLOOKUP($A6,[6]HISTOJANV25!$A$6:$AV$47,30,0) -> 0
A7: AS201602 | B7: =IF(D7=0,0,VLOOKUP($A7,[6]HISTOJANV25!$A$6:$BB$47,12,0)) -> 1 | C7: =VLOOKUP(A7,[7]LISTADHERENT!A$5:H$60,3,0) -> BOUTCHOUANG WILLIAM | D7: =IF(E7="ECHEC",0,VLOOKUP($A7,[6]HISTOJANV25!$A$6:$AR$47,13,0)) -> 75000 | E7: =VLOOKUP($A7,[6]HISTOJANV25!$A$6:$AV$47,9,0) -> BANQUE | F7: =VLOOKUP($A7,[6]HISTOJANV25!$A$6:$AV$47,36,0) -> 0 | G7: =VLOOKUP($A7,[6]HISTOJANV25!$A$6:$AV$47,39,0) -> 0 | H7: =IF(G7=0,"",VLOOKUP($A7,[6]HISTOFEV25!$A$6:$AV$47,42,0)) | I7: =VLOOKUP($A7,[6]HISTOJANV25!$A$6:$AV$47,41,0) -> 0 | K7: =VLOOKUP($A7,[6]HISTOJANV25!$A$6:$AV$47,17,0) -> 0 | L7: =IF(K7<>0,VLOOKUP($A7,[6]HISTOJANV25!$A$6:$BB$47,9,0),"ECHEC") -> ECHEC | M7: =IF(P7=0,0,VLOOKUP($A7,[6]HISTOJANV25!$A$6:$AV$47,32,0)) -> 0 | N7: =VLOOKUP($A7,[6]HISTOJANV25!$A$6:$AV$47,33,0) -> 0 | O7: =IF(P7=0,0,($C$3-P7)) -> 0 | P7: =VLOOKUP($A7,[6]HISTOJANV25!$A$6:$AV$47,30,0) -> 0
A8: AS201613 | B8: =IF(D8=0,0,VLOOKUP($A8,[6]HISTOJANV25!$A$6:$BB$47,12,0)) -> 1 | C8: =VLOOKUP(A8,[7]LISTADHERENT!A$5:H$60,3,0) -> HOTCHO BENJAMIN | D8: =IF(E8="ECHEC",0,VLOOKUP($A8,[6]HISTOJANV25!$A$6:$AR$47,13,0)) -> 75000 | E8: =VLOOKUP($A8,[6]HISTOJANV25!$A$6:$AV$47,9,0) -> BANQUE | F8: =VLOOKUP($A8,[6]HISTOJANV25!$A$6:$AV$47,36,0) -> 0 | G8: =VLOOKUP($A8,[6]HISTOJANV25!$A$6:$AV$47,39,0) -> 0 | H8: =IF(G8=0,"",VLOOKUP($A8,[6]HISTOFEV25!$A$6:$AV$47,42,0)) | I8: =VLOOKUP($A8,[6]HISTOJANV25!$A$6:$AV$47,41,0) -> 0 | K8: =VLOOKUP($A8,[6]HISTOJANV25!$A$6:$AV$47,17,0) -> 0 | L8: =IF(K8<>0,VLOOKUP($A8,[6]HISTOJANV25!$A$6:$BB$47,9,0),"ECHEC") -> ECHEC | M8: =IF(P8=0,0,VLOOKUP($A8,[6]HISTOJANV25!$A$6:$AV$47,32,0)) -> 0 | N8: =VLOOKUP($A8,[6]HISTOJANV25!$A$6:$AV$47,33,0) -> 0 | O8: =IF(P8=0,0,($C$3-P8)) -> 0 | P8: =VLOOKUP($A8,[6]HISTOJANV25!$A$6:$AV$47,30,0) -> 0
A9: AS201619 | B9: =IF(D9=0,0,VLOOKUP($A9,[6]HISTOJANV25!$A$6:$BB$47,12,0)) -> 1 | C9: =VLOOKUP(A9,[7]LISTADHERENT!A$5:H$60,3,0) -> KOUATCHO MESSACK | D9: =IF(E9="ECHEC",0,VLOOKUP($A9,[6]HISTOJANV25!$A$6:$AR$47,13,0)) -> 75000 | E9: =VLOOKUP($A9,[6]HISTOJANV25!$A$6:$AV$47,9,0) -> BANQUE | F9: =VLOOKUP($A9,[6]HISTOJANV25!$A$6:$AV$47,36,0) -> 0 | G9: =VLOOKUP($A9,[6]HISTOJANV25!$A$6:$AV$47,39,0) -> 0 | H9: =IF(G9=0,"",VLOOKUP($A9,[6]HISTOFEV25!$A$6:$AV$47,42,0)) | I9: =VLOOKUP($A9,[6]HISTOJANV25!$A$6:$AV$47,41,0) -> 0 | K9: =VLOOKUP($A9,[6]HISTOJANV25!$A$6:$AV$47,17,0) -> 0 | L9: =IF(K9<>0,VLOOKUP($A9,[6]HISTOJANV25!$A$6:$BB$47,9,0),"ECHEC") -> ECHEC | M9: =IF(P9=0,0,VLOOKUP($A9,[6]HISTOJANV25!$A$6:$AV$47,32,0)) -> 0 | N9: =VLOOKUP($A9,[6]HISTOJANV25!$A$6:$AV$47,33,0) -> 0 | O9: =IF(P9=0,0,($C$3-P9)) -> 0 | P9: =VLOOKUP($A9,[6]HISTOJANV25!$A$6:$AV$47,30,0) -> 0
A10: AS201611 | B10: =IF(D10=0,0,VLOOKUP($A10,[6]HISTOJANV25!$A$6:$BB$47,12,0)) -> 1 | C10: =VLOOKUP(A10,[7]LISTADHERENT!A$5:H$60,3,0) -> HENGUE PAUL OMER | D10: =IF(E10="ECHEC",0,VLOOKUP($A10,[6]HISTOJANV25!$A$6:$AR$47,13,0)) -> 75000 | E10: =VLOOKUP($A10,[6]HISTOJANV25!$A$6:$AV$47,9,0) -> BANQUE | F10: =VLOOKUP($A10,[6]HISTOJANV25!$A$6:$AV$47,36,0) -> 0 | G10: =VLOOKUP($A10,[6]HISTOJANV25!$A$6:$AV$47,39,0) -> 0 | H10: =IF(G10=0,"",VLOOKUP($A10,[6]HISTOFEV25!$A$6:$AV$47,42,0)) | I10: =VLOOKUP($A10,[6]HISTOJANV25!$A$6:$AV$47,41,0) -> 0 | K10: =VLOOKUP($A10,[6]HISTOJANV25!$A$6:$AV$47,17,0) -> 0 | L10: =IF(K10<>0,VLOOKUP($A10,[6]HISTOJANV25!$A$6:$BB$47,9,0),"ECHEC") -> ECHEC | M10: =IF(P10=0,0,VLOOKUP($A10,[6]HISTOJANV25!$A$6:$AV$47,32,0)) -> 0 | N10: =VLOOKUP($A10,[6]HISTOJANV25!$A$6:$AV$47,33,0) -> 0 | O10: =IF(P10=0,0,($C$3-P10)) -> 0 | P10: =VLOOKUP($A10,[6]HISTOJANV25!$A$6:$AV$47,30,0) -> 0
A11: AS201649 | B11: =IF(D11=0,0,VLOOKUP($A11,[6]HISTOJANV25!$A$6:$BB$47,12,0)) -> 1 | C11: =VLOOKUP(A11,[7]LISTADHERENT!A$5:H$60,3,0) -> MBOGNING TUGMA GUY | D11: =IF(E11="ECHEC",0,VLOOKUP($A11,[6]HISTOJANV25!$A$6:$AR$47,13,0)) -> 75000 | E11: =VLOOKUP($A11,[6]HISTOJANV25!$A$6:$AV$47,9,0) -> BANQUE | F11: =VLOOKUP($A11,[6]HISTOJANV25!$A$6:$AV$47,36,0) -> 0 | G11: =VLOOKUP($A11,[6]HISTOJANV25!$A$6:$AV$47,39,0) -> 0 | H11: =IF(G11=0,"",VLOOKUP($A11,[6]HISTOFEV25!$A$6:$AV$47,42,0)) | I11: =VLOOKUP($A11,[6]HISTOJANV25!$A$6:$AV$47,41,0) -> 0 | K11: =VLOOKUP($A11,[6]HISTOJANV25!$A$6:$AV$47,17,0) -> 0 | L11: =IF(K11<>0,VLOOKUP($A11,[6]HISTOJANV25!$A$6:$BB$47,9,0),"ECHEC") -> ECHEC | M11: =IF(P11=0,0,VLOOKUP($A11,[6]HISTOJANV25!$A$6:$AV$47,32,0)) -> 0 | N11: =VLOOKUP($A11,[6]HISTOJANV25!$A$6:$AV$47,33,0) -> 0 | O11: =IF(P11=0,0,($C$3-P11)) -> 0 | P11: =VLOOKUP($A11,[6]HISTOJANV25!$A$6:$AV$47,30,0) -> 0
A12: AS201621 | B12: =IF(D12=0,0,VLOOKUP($A12,[6]HISTOJANV25!$A$6:$BB$47,12,0)) -> 1 | C12: =VLOOKUP(A12,[7]LISTADHERENT!A$5:H$60,3,0) -> NANKAM APPOLINAIRE | D12: =IF(E12="ECHEC",0,VLOOKUP($A12,[6]HISTOJANV25!$A$6:$AR$47,13,0)) -> 75000 | E12: =VLOOKUP($A12,[6]HISTOJANV25!$A$6:$AV$47,9,0) -> BANQUE | F12: =VLOOKUP($A12,[6]HISTOJANV25!$A$6:$AV$47,36,0) -> 0 | G12: =VLOOKUP($A12,[6]HISTOJANV25!$A$6:$AV$47,39,0) -> 0 | H12: =IF(G12=0,"",VLOOKUP($A12,[6]HISTOFEV25!$A$6:$AV$47,42,0)) | I12: =VLOOKUP($A12,[6]HISTOJANV25!$A$6:$AV$47,41,0) -> 0 | K12: =VLOOKUP($A12,[6]HISTOJANV25!$A$6:$AV$47,17,0) -> 0 | L12: =IF(K12<>0,VLOOKUP($A12,[6]HISTOJANV25!$A$6:$BB$47,9,0),"ECHEC") -> ECHEC | M12: =IF(P12=0,0,VLOOKUP($A12,[6]HISTOJANV25!$A$6:$AV$47,32,0)) -> BANQUE | N12: =VLOOKUP($A12,[6]HISTOJANV25!$A$6:$AV$47,33,0) -> 0 | O12: =IF(P12=0,0,($C$3-P12)) -> 892500 | P12: =VLOOKUP($A12,[6]HISTOJANV25!$A$6:$AV$47,30,0) -> 7500
A13: AS201624 | B13: =IF(D13=0,0,VLOOKUP($A13,[6]HISTOJANV25!$A$6:$BB$47,12,0)) -> 1 | C13: =VLOOKUP(A13,[7]LISTADHERENT!A$5:H$60,3,0) -> NGONDIEP CLAUDE | D13: =IF(E13="ECHEC",0,VLOOKUP($A13,[6]HISTOJANV25!$A$6:$AR$47,13,0)) -> 75000 | E13: =VLOOKUP($A13,[6]HISTOJANV25!$A$6:$AV$47,9,0) -> BANQUE | F13: =VLOOKUP($A13,[6]HISTOJANV25!$A$6:$AV$47,36,0) -> 0 | G13: =VLOOKUP($A13,[6]HISTOJANV25!$A$6:$AV$47,39,0) -> 0 | H13: =IF(G13=0,"",VLOOKUP($A13,[6]HISTOFEV25!$A$6:$AV$47,42,0)) | I13: =VLOOKUP($A13,[6]HISTOJANV25!$A$6:$AV$47,41,0) -> 0 | K13: =VLOOKUP($A13,[6]HISTOJANV25!$A$6:$AV$47,17,0) -> 0 | L13: =IF(K13<>0,VLOOKUP($A13,[6]HISTOJANV25!$A$6:$BB$47,9,0),"ECHEC") -> ECHEC | M13: =IF(P13=0,0,VLOOKUP($A13,[6]HISTOJANV25!$A$6:$AV$47,32,0)) -> 0 | N13: =VLOOKUP($A13,[6]HISTOJANV25!$A$6:$AV$47,33,0) -> 0 | O13: =IF(P13=0,0,($C$3-P13)) -> 0 | P13: =VLOOKUP($A13,[6]HISTOJANV25!$A$6:$AV$47,30,0) -> 0
A14: AS201633 | B14: =IF(D14=0,0,VLOOKUP($A14,[6]HISTOJANV25!$A$6:$BB$47,12,0)) -> 1 | C14: =VLOOKUP(A14,[7]LISTADHERENT!A$5:H$60,3,0) -> PATEGO NJOSSU GUSTAVE | D14: =IF(E14="ECHEC",0,VLOOKUP($A14,[6]HISTOJANV25!$A$6:$AR$47,13,0)) -> 75000 | E14: =VLOOKUP($A14,[6]HISTOJANV25!$A$6:$AV$47,9,0) -> BANQUE | F14: =VLOOKUP($A14,[6]HISTOJANV25!$A$6:$AV$47,36,0) -> 0 | G14: =VLOOKUP($A14,[6]HISTOJANV25!$A$6:$AV$47,39,0) -> 0 | H14: =IF(G14=0,"",VLOOKUP($A14,[6]HISTOFEV25!$A$6:$AV$47,42,0)) | I14: =VLOOKUP($A14,[6]HISTOJANV25!$A$6:$AV$47,41,0) -> 0 | K14: =VLOOKUP($A14,[6]HISTOJANV25!$A$6:$AV$47,17,0) -> 0 | L14: =IF(K14<>0,VLOOKUP($A14,[6]HISTOJANV25!$A$6:$BB$47,9,0),"ECHEC") -> ECHEC | M14: =IF(P14=0,0,VLOOKUP($A14,[6]HISTOJANV25!$A$6:$AV$47,32,0)) -> 0 | N14: =VLOOKUP($A14,[6]HISTOJANV25!$A$6:$AV$47,33,0) -> 0 | O14: =IF(P14=0,0,($C$3-P14)) -> 0 | P14: =VLOOKUP($A14,[6]HISTOJANV25!$A$6:$AV$47,30,0) -> 0
A15: AS201641 | B15: =IF(D15=0,0,VLOOKUP($A15,[6]HISTOJANV25!$A$6:$BB$47,12,0)) -> 1 | C15: =VLOOKUP(A15,[7]LISTADHERENT!A$5:H$60,3,0) -> TCHOUAMOU MATHIEU | D15: =IF(E15="ECHEC",0,VLOOKUP($A15,[6]HISTOJANV25!$A$6:$AR$47,13,0)) -> 75000 | E15: =VLOOKUP($A15,[6]HISTOJANV25!$A$6:$AV$47,9,0) -> BANQUE | F15: =VLOOKUP($A15,[6]HISTOJANV25!$A$6:$AV$47,36,0) -> 0 | G15: =VLOOKUP($A15,[6]HISTOJANV25!$A$6:$AV$47,39,0) -> 0 | H15: =IF(G15=0,"",VLOOKUP($A15,[6]HISTOFEV25!$A$6:$AV$47,42,0)) | I15: =VLOOKUP($A15,[6]HISTOJANV25!$A$6:$AV$47,41,0) -> 0 | K15: =VLOOKUP($A15,[6]HISTOJANV25!$A$6:$AV$47,17,0) -> 0 | L15: =IF(K15<>0,VLOOKUP($A15,[6]HISTOJANV25!$A$6:$BB$47,9,0),"ECHEC") -> ECHEC | M15: =IF(P15=0,0,VLOOKUP($A15,[6]HISTOJANV25!$A$6:$AV$47,32,0)) -> 0 | N15: =VLOOKUP($A15,[6]HISTOJANV25!$A$6:$AV$47,33,0) -> 0 | O15: =IF(P15=0,0,($C$3-P15)) -> 0 | P15: =VLOOKUP($A15,[6]HISTOJANV25!$A$6:$AV$47,30,0) -> 0
A16: AS201658 | B16: =IF(D16=0,0,VLOOKUP($A16,[6]HISTOJANV25!$A$6:$BB$47,12,0)) -> 1 | C16: =VLOOKUP(A16,[7]LISTADHERENT!A$5:H$60,3,0) -> YANTCHOU GERVAIS | D16: =IF(E16="ECHEC",0,VLOOKUP($A16,[6]HISTOJANV25!$A$6:$AR$47,13,0)) -> 75000 | E16: =VLOOKUP($A16,[6]HISTOJANV25!$A$6:$AV$47,9,0) -> BANQUE | F16: =VLOOKUP($A16,[6]HISTOJANV25!$A$6:$AV$47,36,0) -> 0 | G16: =VLOOKUP($A16,[6]HISTOJANV25!$A$6:$AV$47,39,0) -> 0 | H16: =IF(G16=0,"",VLOOKUP($A16,[6]HISTOFEV25!$A$6:$AV$47,42,0)) | I16: =VLOOKUP($A16,[6]HISTOJANV25!$A$6:$AV$47,41,0) -> 0 | K16: =VLOOKUP($A16,[6]HISTOJANV25!$A$6:$AV$47,17,0) -> 0 | L16: =IF(K16<>0,VLOOKUP($A16,[6]HISTOJANV25!$A$6:$BB$47,9,0),"ECHEC") -> ECHEC | M16: =IF(P16=0,0,VLOOKUP($A16,[6]HISTOJANV25!$A$6:$AV$47,32,0)) -> 0 | N16: =VLOOKUP($A16,[6]HISTOJANV25!$A$6:$AV$47,33,0) -> 0 | O16: =IF(P16=0,0,($C$3-P16)) -> 0 | P16: =VLOOKUP($A16,[6]HISTOJANV25!$A$6:$AV$47,30,0) -> 0
A17: AS201647 | B17: =IF(D17=0,0,VLOOKUP($A17,[6]HISTOJANV25!$A$6:$BB$47,12,0)) -> 1 | C17: =VLOOKUP(A17,[7]LISTADHERENT!A$5:H$60,3,0) -> YOUMBI EMMANUEL | D17: =IF(E17="ECHEC",0,VLOOKUP($A17,[6]HISTOJANV25!$A$6:$AR$47,13,0)) -> 75000 | E17: =VLOOKUP($A17,[6]HISTOJANV25!$A$6:$AV$47,9,0) -> BANQUE | F17: =VLOOKUP($A17,[6]HISTOJANV25!$A$6:$AV$47,36,0) -> 0 | G17: =VLOOKUP($A17,[6]HISTOJANV25!$A$6:$AV$47,39,0) -> 0 | H17: =IF(G17=0,"",VLOOKUP($A17,[6]HISTOFEV25!$A$6:$AV$47,42,0)) | I17: =VLOOKUP($A17,[6]HISTOJANV25!$A$6:$AV$47,41,0) -> 0 | K17: =VLOOKUP($A17,[6]HISTOJANV25!$A$6:$AV$47,17,0) -> 0 | L17: =IF(K17<>0,VLOOKUP($A17,[6]HISTOJANV25!$A$6:$BB$47,9,0),"ECHEC") -> ECHEC | M17: =IF(P17=0,0,VLOOKUP($A17,[6]HISTOJANV25!$A$6:$AV$47,32,0)) -> 0 | N17: =VLOOKUP($A17,[6]HISTOJANV25!$A$6:$AV$47,33,0) -> 0 | O17: =IF(P17=0,0,($C$3-P17)) -> 0 | P17: =VLOOKUP($A17,[6]HISTOJANV25!$A$6:$AV$47,30,0) -> 0
A19: TOTAL PART | B19: =SUM(B6:B18) -> 13
A20: NBRE ADHERENT | B20: =COUNT(D6:D18) -> 12 | D20: =SUM(D6:D19) -> 975000 | E20: =SUM(E6:E19) -> 0 | F20: =SUM(F6:F19) -> 0 | G20: =SUM(G6:G19) -> 0 | H20: =SUM(H6:H19) -> 0 | I20: =SUM(I6:I19) -> 0 | J20: =SUM(J6:J19) -> 0 | K20: =SUM(K6:K19) -> 0 | ... P20: =SUM(P6:P19) -> 7500
L21: NBRE PART | M21: PART VENDUE
D22: MONTANT TONTINE | E22: REMBOURSEMENT PETIT LOT | F22: VENTE PETIT LOT | G22: VENTE LOT PRINCIPAL | H22: SOLDE EN CAISSE | J22: TONTINE + REMB + INTERET VENTE+RELIQUAT | K22: =D26+E26+P20 -> 982500
D23: =SUMIFS(D6:D19,E6:E19,"ESPECES") -> 0 | E23: =SUMIFS(K7:K14,L7:L14,"ESPECES") -> 0 | F23: =SUMIFS(F7:F19,H7:H19,"ESPECES") -> 0 | G23: =SUMIFS(O7:O19,M7:M19,"ESPECES") -> 0 | H23: =D23+E23-F23-G23 -> 0 | J23: LOT PRINCIPAL | K23: =C3*COUNTIF(O7:O19,">0") -> 900000 | L23: =D3 -> 1 | M23: =COUNTIF(O7:O14,">0") -> 1
D24: =SUMIFS(D6:D19,E6:E19,"BANQUE") -> 975000 | E24: =SUMIFS(K7:K14,L7:L14,"BANQUE") -> 0 | F24: =SUMIFS(F7:F19,H7:H19,"BANQUE") -> 0 | G24: =SUMIFS(O7:O19,M7:M19,"BANQUE") -> 892500 | H24: =D24+E24-F24-G24 -> 82500
J25: PETIT LOT | K25: =K22-K23 -> 82500
D26: =D23+D24 -> 975000 | E26: =E23+E24 -> 0 | F26: =F23+F24 -> 0 | G26: =G23+G24 -> 892500 | H26: =H23+H24 -> 82500
J27: RELIQUAT | K27: =K25-F20 -> 82500 | M27: =K27 -> 82500 | N27: CUMUL
J29: ECHEC TONTINE MOIS | K29: =COUNTIFS(E7:E18,"ECHEC")*75000 -> 0 | M29: =+K29 -> 0 | N29: CUMUL
J30: ECHEC REMBOURSEMENT MOIS | K30: =J20-E26 -> 0 | M30: =+K30 -> 0 | N30: CUMUL

Sheet TONTFEV25
A1: ASSOCIATION | B1: ASELBY
A2: ANNEE | B2: 2025 | C2: TONIINE | D2: NBRE PART
A3: TAUX TONTINE | B3: 75000 | C3: =B3*12 -> 900000 | D3: =ROUNDDOWN(K22/C3,0) -> 1
C4: 45701
A5: MATRICULE | B5: NBREPART | C5: NOM ET PRENOM | D5: MONTANT TONTINE | E5: MODE VERSEMENT | F5: VENTE PETIT LOT | G5: INTERET PETIT LOT | H5: MODE VERSEMENT VENTE PETIT LOT | I5: NUMERO CHEQUE | J5: MONTANT A REMBOURSER PETIT LOT | K5: REMBOURSEMENT PETIT LOT | L5: MODE VERSEMENT REMBOURSEMENT | M5: MODE VERSEMENTLOT PRINCIPAL | N5: NUMERO CHEQUE | O5: MONTANT LOT PRINCIPAL | P5: INTERET LOT PRINCIPAL
A6: AS201648 | B6: =IF(D6=0,0,VLOOKUP($A6,[6]HISTOFEV25!$A$6:$BB$47,12,0)) -> 2 | C6: =VLOOKUP(A6,[7]LISTADHERENT!A$5:H$60,3,0) -> ASELBY | D6: =IF(E6="ECHEC",0,VLOOKUP($A6,[6]HISTOFEV25!$A$6:$AR$47,13,0)) -> 150000 | E6: =VLOOKUP($A6,[6]HISTOFEV25!$A$6:$AV$47,9,0) -> BANQUE | F6: =VLOOKUP($A6,[6]HISTOFEV25!$A$6:$AV$47,36,0) -> 0 | G6: =VLOOKUP($A6,[6]HISTOFEV25!$A$6:$AV$47,39,0) -> 0 | H6: =IF(G6=0,"",VLOOKUP($A6,[6]HISTOFEV25!$A$6:$AV$47,42,0)) | I6: =VLOOKUP($A6,[6]HISTOFEV25!$A$6:$AV$47,41,0) -> 0 | J6: =+TONTJANV25!F6+TONTJANV25!G6 -> 0 | K6: =VLOOKUP($A6,[6]HISTOFEV25!$A$6:$AV$47,17,0) -> 0 | L6: =IF(K6<>0,VLOOKUP($A6,[6]HISTOFEV25!$A$6:$BB$47,42,0),"ECHEC") -> ECHEC | M6: =IF(P6=0,0,VLOOKUP($A6,[6]HISTOFEV25!$A$6:$AV$47,32,0)) -> 0 | N6: =VLOOKUP($A6,[6]HISTOFEV25!$A$6:$AV$47,33,0) -> 0 | O6: =IF(P6=0,0,($C$3-P6)) -> 0 | P6: =VLOOKUP($A6,[6]HISTOFEV25!$A$6:$AV$47,30,0) -> 0
A7: AS201602 | B7: =IF(D7=0,0,VLOOKUP($A7,[6]HISTOFEV25!$A$6:$BB$47,12,0)) -> 1 | C7: =VLOOKUP(A7,[7]LISTADHERENT!A$5:H$60,3,0) -> BOUTCHOUANG WILLIAM | D7: =IF(E7="ECHEC",0,VLOOKUP($A7,[6]HISTOFEV25!$A$6:$AR$47,13,0)) -> 75000 | E7: =VLOOKUP($A7,[6]HISTOFEV25!$A$6:$AV$47,9,0) -> BANQUE | F7: =VLOOKUP($A7,[6]HISTOFEV25!$A$6:$AV$47,36,0) -> 100000 | G7: =VLOOKUP($A7,[6]HISTOFEV25!$A$6:$AV$47,39,0) -> 3000 | H7: =IF(G7=0,"",VLOOKUP($A7,[6]HISTOFEV25!$A$6:$AV$47,42,0)) -> BANQUE | I7: =VLOOKUP($A7,[6]HISTOFEV25!$A$6:$AV$47,41,0) -> 0 | J7: =+TONTJANV25!F7+TONTJANV25!G7 -> 0 | K7: =VLOOKUP($A7,[6]HISTOFEV25!$A$6:$AV$47,17,0) -> 0 | L7: =IF(K7<>0,VLOOKUP($A7,[6]HISTOFEV25!$A$6:$BB$47,42,0),"ECHEC") -> ECHEC | M7: =IF(P7=0,0,VLOOKUP($A7,[6]HISTOFEV25!$A$6:$AV$47,32,0)) -> 0 | N7: =VLOOKUP($A7,[6]HISTOFEV25!$A$6:$AV$47,33,0) -> 0 | O7: =IF(P7=0,0,($C$3-P7)) -> 0 | P7: =VLOOKUP($A7,[6]HISTOFEV25!$A$6:$AV$47,30,0) -> 0
A8: AS201613 | B8: =IF(D8=0,0,VLOOKUP($A8,[6]HISTOFEV25!$A$6:$BB$47,12,0)) -> 1 | C8: =VLOOKUP(A8,[7]LISTADHERENT!A$5:H$60,3,0) -> HOTCHO BENJAMIN | D8: =IF(E8="ECHEC",0,VLOOKUP($A8,[6]HISTOFEV25!$A$6:$AR$47,13,0)) -> 75000 | E8: =VLOOKUP($A8,[6]HISTOFEV25!$A$6:$AV$47,9,0) -> BANQUE | F8: =VLOOKUP($A8,[6]HISTOFEV25!$A$6:$AV$47,36,0) -> 0 | G8: =VLOOKUP($A8,[6]HISTOFEV25!$A$6:$AV$47,39,0) -> 0 | H8: =IF(G8=0,"",VLOOKUP($A8,[6]HISTOFEV25!$A$6:$AV$47,42,0)) | I8: =VLOOKUP($A8,[6]HISTOFEV25!$A$6:$AV$47,41,0) -> 0 | J8: =+TONTJANV25!F8+TONTJANV25!G8 -> 0 | K8: =VLOOKUP($A8,[6]HISTOFEV25!$A$6:$AV$47,17,0) -> 0 | L8: =IF(K8<>0,VLOOKUP($A8,[6]HISTOFEV25!$A$6:$BB$47,42,0),"ECHEC") -> ECHEC | M8: =IF(P8=0,0,VLOOKUP($A8,[6]HISTOFEV25!$A$6:$AV$47,32,0)) -> 0 | N8: =VLOOKUP($A8,[6]HISTOFEV25!$A$6:$AV$47,33,0) -> 0 | O8: =IF(P8=0,0,($C$3-P8)) -> 0 | P8: =VLOOKUP($A8,[6]HISTOFEV25!$A$6:$AV$47,30,0) -> 0
A9: AS201619 | B9: =IF(D9=0,0,VLOOKUP($A9,[6]HISTOFEV25!$A$6:$BB$47,12,0)) -> 1 | C9: =VLOOKUP(A9,[7]LISTADHERENT!A$5:H$60,3,0) -> KOUATCHO MESSACK | D9: =IF(E9="ECHEC",0,VLOOKUP($A9,[6]HISTOFEV25!$A$6:$AR$47,13,0)) -> 75000 | E9: =VLOOKUP($A9,[6]HISTOFEV25!$A$6:$AV$47,9,0) -> BANQUE | F9: =VLOOKUP($A9,[6]HISTOFEV25!$A$6:$AV$47,36,0) -> 53000 | G9: =VLOOKUP($A9,[6]HISTOFEV25!$A$6:$AV$47,39,0) -> 1500 | H9: =IF(G9=0,"",VLOOKUP($A9,[6]HISTOFEV25!$A$6:$AV$47,42,0)) -> BANQUE | I9: =VLOOKUP($A9,[6]HISTOFEV25!$A$6:$AV$47,41,0) -> 0 | J9: =+TONTJANV25!F9+TONTJANV25!G9 -> 0 | K9: =VLOOKUP($A9,[6]HISTOFEV25!$A$6:$AV$47,17,0) -> 0 | L9: =IF(K9<>0,VLOOKUP($A9,[6]HISTOFEV25!$A$6:$BB$47,42,0),"ECHEC") -> ECHEC | M9: =IF(P9=0,0,VLOOKUP($A9,[6]HISTOFEV25!$A$6:$AV$47,32,0)) -> 0 | N9: =VLOOKUP($A9,[6]HISTOFEV25!$A$6:$AV$47,33,0) -> 0 | O9: =IF(P9=0,0,($C$3-P9)) -> 0 | P9: =VLOOKUP($A9,[6]HISTOFEV25!$A$6:$AV$47,30,0) -> 0
A10: AS201611 | B10: =IF(D10=0,0,VLOOKUP($A10,[6]HISTOFEV25!$A$6:$BB$47,12,0)) -> 1 | C10: =VLOOKUP(A10,[7]LISTADHERENT!A$5:H$60,3,0) -> HENGUE PAUL OMER | D10: =IF(E10="ECHEC",0,VLOOKUP($A10,[6]HISTOFEV25!$A$6:$AR$47,13,0)) -> 75000 | E10: =VLOOKUP($A10,[6]HISTOFEV25!$A$6:$AV$47,9,0) -> BANQUE | F10: =VLOOKUP($A10,[6]HISTOFEV25!$A$6:$AV$47,36,0) -> 0 | G10: =VLOOKUP($A10,[6]HISTOFEV25!$A$6:$AV$47,39,0) -> 0 | H10: =IF(G10=0,"",VLOOKUP($A10,[6]HISTOFEV25!$A$6:$AV$47,42,0)) | I10: =VLOOKUP($A10,[6]HISTOFEV25!$A$6:$AV$47,41,0) -> 0 | J10: =+TONTJANV25!F10+TONTJANV25!G10 -> 0 | K10: =VLOOKUP($A10,[6]HISTOFEV25!$A$6:$AV$47,17,0) -> 0 | L10: =IF(K10<>0,VLOOKUP($A10,[6]HISTOFEV25!$A$6:$BB$47,42,0),"ECHEC") -> ECHEC | M10: =IF(P10=0,0,VLOOKUP($A10,[6]HISTOFEV25!$A$6:$AV$47,32,0)) -> 0 | N10: =VLOOKUP($A10,[6]HISTOFEV25!$A$6:$AV$47,33,0) -> 0 | O10: =IF(P10=0,0,($C$3-P10)) -> 0 | P10: =VLOOKUP($A10,[6]HISTOFEV25!$A$6:$AV$47,30,0) -> 0
A11: AS201649 | B11: =IF(D11=0,0,VLOOKUP($A11,[6]HISTOFEV25!$A$6:$BB$47,12,0)) -> 1 | C11: =VLOOKUP(A11,[7]LISTADHERENT!A$5:H$60,3,0) -> MBOGNING TUGMA GUY | D11: =IF(E11="ECHEC",0,VLOOKUP($A11,[6]HISTOFEV25!$A$6:$AR$47,13,0)) -> 75000 | E11: =VLOOKUP($A11,[6]HISTOFEV25!$A$6:$AV$47,9,0) -> BANQUE | F11: =VLOOKUP($A11,[6]HISTOFEV25!$A$6:$AV$47,36,0) -> 50000 | G11: =VLOOKUP($A11,[6]HISTOFEV25!$A$6:$AV$47,39,0) -> 1000 | H11: =IF(G11=0,"",VLOOKUP($A11,[6]HISTOFEV25!$A$6:$AV$47,42,0)) -> BANQUE | I11: =VLOOKUP($A11,[6]HISTOFEV25!$A$6:$AV$47,41,0) -> 0 | J11: =+TONTJANV25!F11+TONTJANV25!G11 -> 0 | K11: =VLOOKUP($A11,[6]HISTOFEV25!$A$6:$AV$47,17,0) -> 0 | L11: =IF(K11<>0,VLOOKUP($A11,[6]HISTOFEV25!$A$6:$BB$47,42,0),"ECHEC") -> ECHEC | M11: =IF(P11=0,0,VLOOKUP($A11,[6]HISTOFEV25!$A$6:$AV$47,32,0)) -> BANQUE | N11: =VLOOKUP($A11,[6]HISTOFEV25!$A$6:$AV$47,33,0) -> 0 | O11: =IF(P11=0,0,($C$3-P11)) -> 855000 | P11: =VLOOKUP($A11,[6]HISTOFEV25!$A$6:$AV$47,30,0) -> 45000
A12: AS201621 | B12: =IF(D12=0,0,VLOOKUP($A12,[6]HISTOFEV25!$A$6:$BB$47,12,0)) -> 1 | C12: =VLOOKUP(A12,[7]LISTADHERENT!A$5:H$60,3,0) -> NANKAM APPOLINAIRE | D12: =IF(E12="ECHEC",0,VLOOKUP($A12,[6]HISTOFEV25!$A$6:$AR$47,13,0)) -> 75000 | E12: =VLOOKUP($A12,[6]HISTOFEV25!$A$6:$AV$47,9,0) -> BANQUE | F12: =VLOOKUP($A12,[6]HISTOFEV25!$A$6:$AV$47,36,0) -> 0 | G12: =VLOOKUP($A12,[6]HISTOFEV25!$A$6:$AV$47,39,0) -> 0 | H12: =IF(G12=0,"",VLOOKUP($A12,[6]HISTOFEV25!$A$6:$AV$47,42,0)) | I12: =VLOOKUP($A12,[6]HISTOFEV25!$A$6:$AV$47,41,0) -> 0 | J12: =+TONTJANV25!F12+TONTJANV25!G12 -> 0 | K12: =VLOOKUP($A12,[6]HISTOFEV25!$A$6:$AV$47,17,0) -> 0 | L12: =IF(K12<>0,VLOOKUP($A12,[6]HISTOFEV25!$A$6:$BB$47,42,0),"ECHEC") -> ECHEC | M12: =IF(P12=0,0,VLOOKUP($A12,[6]HISTOFEV25!$A$6:$AV$47,32,0)) -> 0 | N12: =VLOOKUP($A12,[6]HISTOFEV25!$A$6:$AV$47,33,0) -> 0 | O12: =IF(P12=0,0,($C$3-P12)) -> 0 | P12: =VLOOKUP($A12,[6]HISTOFEV25!$A$6:$AV$47,30,0) -> 0
A13: AS201624 | B13: =IF(D13=0,0,VLOOKUP($A13,[6]HISTOFEV25!$A$6:$BB$47,12,0)) -> 1 | C13: =VLOOKUP(A13,[7]LISTADHERENT!A$5:H$60,3,0) -> NGONDIEP CLAUDE | D13: =IF(E13="ECHEC",0,VLOOKUP($A13,[6]HISTOFEV25!$A$6:$AR$47,13,0)) -> 75000 | E13: =VLOOKUP($A13,[6]HISTOFEV25!$A$6:$AV$47,9,0) -> BANQUE | F13: =VLOOKUP($A13,[6]HISTOFEV25!$A$6:$AV$47,36,0) -> 0 | G13: =VLOOKUP($A13,[6]HISTOFEV25!$A$6:$AV$47,39,0) -> 0 | H13: =IF(G13=0,"",VLOOKUP($A13,[6]HISTOFEV25!$A$6:$AV$47,42,0)) | I13: =VLOOKUP($A13,[6]HISTOFEV25!$A$6:$AV$47,41,0) -> 0 | J13: =+TONTJANV25!F13+TONTJANV25!G13 -> 0 | K13: =VLOOKUP($A13,[6]HISTOFEV25!$A$6:$AV$47,17,0) -> 0 | L13: =IF(K13<>0,VLOOKUP($A13,[6]HISTOFEV25!$A$6:$BB$47,42,0),"ECHEC") -> ECHEC | M13: =IF(P13=0,0,VLOOKUP($A13,[6]HISTOFEV25!$A$6:$AV$47,32,0)) -> 0 | N13: =VLOOKUP($A13,[6]HISTOFEV25!$A$6:$AV$47,33,0) -> 0 | O13: =IF(P13=0,0,($C$3-P13)) -> 0 | P13: =VLOOKUP($A13,[6]HISTOFEV25!$A$6:$AV$47,30,0) -> 0
A14: AS201633 | B14: =IF(D14=0,0,VLOOKUP($A14,[6]HISTOFEV25!$A$6:$BB$47,12,0)) -> 1 | C14: =VLOOKUP(A14,[7]LISTADHERENT!A$5:H$60,3,0) -> PATEGO NJOSSU GUSTAVE | D14: =IF(E14="ECHEC",0,VLOOKUP($A14,[6]HISTOFEV25!$A$6:$AR$47,13,0)) -> 75000 | E14: =VLOOKUP($A14,[6]HISTOFEV25!$A$6:$AV$47,9,0) -> BANQUE | F14: =VLOOKUP($A14,[6]HISTOFEV25!$A$6:$AV$47,36,0) -> 0 | G14: =VLOOKUP($A14,[6]HISTOFEV25!$A$6:$AV$47,39,0) -> 0 | H14: =IF(G14=0,"",VLOOKUP($A14,[6]HISTOFEV25!$A$6:$AV$47,42,0)) | I14: =VLOOKUP($A14,[6]HISTOFEV25!$A$6:$AV$47,41,0) -> 0 | J14: =+TONTJANV25!F14+TONTJANV25!G14 -> 0 | K14: =VLOOKUP($A14,[6]HISTOFEV25!$A$6:$AV$47,17,0) -> 0 | L14: =IF(K14<>0,VLOOKUP($A14,[6]HISTOFEV25!$A$6:$BB$47,42,0),"ECHEC") -> ECHEC | M14: =IF(P14=0,0,VLOOKUP($A14,[6]HISTOFEV25!$A$6:$AV$47,32,0)) -> 0 | N14: =VLOOKUP($A14,[6]HISTOFEV25!$A$6:$AV$47,33,0) -> 0 | O14: =IF(P14=0,0,($C$3-P14)) -> 0 | P14: =VLOOKUP($A14,[6]HISTOFEV25!$A$6:$AV$47,30,0) -> 0
A15: AS201641 | B15: =IF(D15=0,0,VLOOKUP($A15,[6]HISTOFEV25!$A$6:$BB$47,12,0)) -> 1 | C15: =VLOOKUP(A15,[7]LISTADHERENT!A$5:H$60,3,0) -> TCHOUAMOU MATHIEU | D15: =IF(E15="ECHEC",0,VLOOKUP($A15,[6]HISTOFEV25!$A$6:$AR$47,13,0)) -> 75000 | E15: =VLOOKUP($A15,[6]HISTOFEV25!$A$6:$AV$47,9,0) -> BANQUE | F15: =VLOOKUP($A15,[6]HISTOFEV25!$A$6:$AV$47,36,0) -> 0 | G15: =VLOOKUP($A15,[6]HISTOFEV25!$A$6:$AV$47,39,0) -> 0 | H15: =IF(G15=0,"",VLOOKUP($A15,[6]HISTOFEV25!$A$6:$AV$47,42,0)) | I15: =VLOOKUP($A15,[6]HISTOFEV25!$A$6:$AV$47,41,0) -> 0 | J15: =+TONTJANV25!F15+TONTJANV25!G15 -> 0 | K15: =VLOOKUP($A15,[6]HISTOFEV25!$A$6:$AV$47,17,0) -> 0 | L15: =IF(K15<>0,VLOOKUP($A15,[6]HISTOFEV25!$A$6:$BB$47,42,0),"ECHEC") -> ECHEC | M15: =IF(P15=0,0,VLOOKUP($A15,[6]HISTOFEV25!$A$6:$AV$47,32,0)) -> 0 | N15: =VLOOKUP($A15,[6]HISTOFEV25!$A$6:$AV$47,33,0) -> 0 | O15: =IF(P15=0,0,($C$3-P15)) -> 0 | P15: =VLOOKUP($A15,[6]HISTOFEV25!$A$6:$AV$47,30,0) -> 0
A16: AS201658 | B16: =IF(D16=0,0,VLOOKUP($A16,[6]HISTOFEV25!$A$6:$BB$47,12,0)) -> 1 | C16: =VLOOKUP(A16,[7]LISTADHERENT!A$5:H$60,3,0) -> YANTCHOU GERVAIS | D16: =IF(E16="ECHEC",0,VLOOKUP($A16,[6]HISTOFEV25!$A$6:$AR$47,13,0)) -> 75000 | E16: =VLOOKUP($A16,[6]HISTOFEV25!$A$6:$AV$47,9,0) -> BANQUE | F16: =VLOOKUP($A16,[6]HISTOFEV25!$A$6:$AV$47,36,0) -> 0 | G16: =VLOOKUP($A16,[6]HISTOFEV25!$A$6:$AV$47,39,0) -> 0 | H16: =IF(G16=0,"",VLOOKUP($A16,[6]HISTOFEV25!$A$6:$AV$47,42,0)) | I16: =VLOOKUP($A16,[6]HISTOFEV25!$A$6:$AV$47,41,0) -> 0 | J16: =+TONTJANV25!F16+TONTJANV25!G16 -> 0 | K16: =VLOOKUP($A16,[6]HISTOFEV25!$A$6:$AV$47,17,0) -> 0 | L16: =IF(K16<>0,VLOOKUP($A16,[6]HISTOFEV25!$A$6:$BB$47,42,0),"ECHEC") -> ECHEC | M16: =IF(P16=0,0,VLOOKUP($A16,[6]HISTOFEV25!$A$6:$AV$47,32,0)) -> 0 | N16: =VLOOKUP($A16,[6]HISTOFEV25!$A$6:$AV$47,33,0) -> 0 | O16: =IF(P16=0,0,($C$3-P16)) -> 0 | P16: =VLOOKUP($A16,[6]HISTOFEV25!$A$6:$AV$47,30,0) -> 0
A17: AS201647 | B17: =IF(D17=0,0,VLOOKUP($A17,[6]HISTOFEV25!$A$6:$BB$47,12,0)) -> 1 | C17: =VLOOKUP(A17,[7]LISTADHERENT!A$5:H$60,3,0) -> YOUMBI EMMANUEL | D17: =IF(E17="ECHEC",0,VLOOKUP($A17,[6]HISTOFEV25!$A$6:$AR$47,13,0)) -> 75000 | E17: =VLOOKUP($A17,[6]HISTOFEV25!$A$6:$AV$47,9,0) -> BANQUE | F17: =VLOOKUP($A17,[6]HISTOFEV25!$A$6:$AV$47,36,0) -> 0 | G17: =VLOOKUP($A17,[6]HISTOFEV25!$A$6:$AV$47,39,0) -> 0 | H17: =IF(G17=0,"",VLOOKUP($A17,[6]HISTOFEV25!$A$6:$AV$47,42,0)) | I17: =VLOOKUP($A17,[6]HISTOFEV25!$A$6:$AV$47,41,0) -> 0 | J17: =+TONTJANV25!F17+TONTJANV25!G17 -> 0 | K17: =VLOOKUP($A17,[6]HISTOFEV25!$A$6:$AV$47,17,0) -> 0 | L17: =IF(K17<>0,VLOOKUP($A17,[6]HISTOFEV25!$A$6:$BB$47,42,0),"ECHEC") -> ECHEC | M17: =IF(P17=0,0,VLOOKUP($A17,[6]HISTOFEV25!$A$6:$AV$47,32,0)) -> 0 | N17: =VLOOKUP($A17,[6]HISTOFEV25!$A$6:$AV$47,33,0) -> 0 | O17: =IF(P17=0,0,($C$3-P17)) -> 0 | P17: =VLOOKUP($A17,[6]HISTOFEV25!$A$6:$AV$47,30,0) -> 0
A19: TOTAL PART | B19: =SUM(B6:B18) -> 13
A20: NBRE ADHERENT | B20: =COUNT(D6:D18) -> 12 | D20: =SUM(D6:D19)+75000+625 -> 1050625 | E20: =SUM(E6:E19) -> 0 | F20: =SUM(F6:F19) -> 203000 | G20: =SUM(G6:G19) -> 5500 | H20: =SUM(H6:H19) -> 0 | I20: =SUM(I6:I19) -> 0 | J20: =SUM(J6:J19) -> 0 | K20: =SUM(K6:K19) -> 0 | L20: =SUM(L6:L19) -> 0 | ... P20: =SUM(P6:P19) -> 45000
L21: NBRE PART | M21: PART VENDUE
D22: MONTANT TONTINE | E22: REMBOURSEMENT PETIT LOT | F22: VENTE PETIT LOT | G22: VENTE LOT PRINCIPAL | H22: SOLDE EN CAISSE | J22: TONTINE + REMB + INTERET VENTE+RELIQUAT | K22: =D26+E26+P20+TONTJANV25!M27 -> 1178125
D23: =SUMIFS(D6:D19,E6:E19,"ESPECES") -> 0 | E23: =SUMIFS(K7:K14,L7:L14,"ESPECES") -> 0 | F23: =SUMIFS(F7:F19,H7:H19,"ESPECES") -> 0 | G23: =SUMIFS(O7:O19,M7:M19,"ESPECES") -> 0 | H23: =D23+E23-F23-G23 -> 0 | J23: LOT PRINCIPAL | K23: =C3*COUNTIF(O7:O19,">0") -> 900000 | L23: =D3 -> 1 | M23: =COUNTIF(O7:O14,">0") -> 1
D24: =+D20 -> 1050625 | E24: =SUMIFS(K7:K14,L7:L14,"BANQUE") -> 0 | F24: =SUMIFS(F7:F19,H7:H19,"BANQUE") -> 203000 | G24: =SUMIFS(O7:O19,M7:M19,"BANQUE") -> 855000 | H24: =D24+E24-F24-G24 -> -7375
J25: PETIT LOT | K25: =K22-K23 -> 278125
D26: =D23+D24 -> 1050625 | E26: =E23+E24 -> 0 | F26: =F23+F24 -> 203000 | G26: =G23+G24 -> 855000 | H26: =H23+H24 -> -7375
J27: RELIQUAT | K27: =K25-F20 -> 75125 | M27: -97500 | N27: CUMUL
J29: ECHEC TONTINE MOIS | K29: =COUNTIFS(E7:E18,"ECHEC")*75000 -> 0 | M29: =+K29+TONTJANV25!M29 -> 0 | N29: CUMUL
J30: ECHEC REMBOURSEMENT MOIS | K30: =J20-E26 -> 0 | M30: =+K30+TONTJANV25!M30 -> 0 | N30: CUMUL

Sheet TONTMARS25
A1: ASSOCIATION | B1: ASELBY
A2: ANNEE | B2: 2025 | C2: TONIINE | D2: NBRE PART
A3: TAUX TONTINE | B3: 75000 | C3: =B3*12 -> 900000 | D3: =ROUNDDOWN(K22/C3,0) -> 1
C4: 45729
A5: MATRICULE | B5: NBREPART | C5: NOM ET PRENOM | D5: MONTANT TONTINE | E5: MODE VERSEMENT | F5: VENTE PETIT LOT | G5: INTERET PETIT LOT | H5: MODE VERSEMENT VENTE PETIT LOT | I5: NUMERO CHEQUE | J5: MONTANT A REMBOURSER PETIT LOT | K5: REMBOURSEMENT PETIT LOT | L5: MODE VERSEMENT REMBOURSEMENT | M5: MODE VERSEMENTLOT PRINCIPAL | N5: NUMERO CHEQUE | O5: MONTANT LOT PRINCIPAL | P5: INTERET LOT PRINCIPAL
A6: AS201648 | B6: =IF(D6=0,0,VLOOKUP($A6,[6]HISTOMARS25!$A$6:$BB$47,12,0)) -> 2 | C6: =VLOOKUP(A6,[7]LISTADHERENT!A$5:H$60,3,0) -> ASELBY | D6: =IF(E6="ECHEC",0,VLOOKUP($A6,[6]HISTOMARS25!$A$6:$AR$47,13,0)) -> 150000 | E6: =VLOOKUP($A6,[6]HISTOMARS25!$A$6:$AV$47,9,0) -> BANQUE | F6: =VLOOKUP($A6,[6]HISTOMARS25!$A$6:$AV$47,36,0) -> 0 | G6: =VLOOKUP($A6,[6]HISTOMARS25!$A$6:$AV$47,39,0) -> 0 | H6: =IF(G6=0,"",VLOOKUP($A6,[6]HISTOFEV25!$A$6:$AV$47,42,0)) | I6: =VLOOKUP($A6,[6]HISTOMARS25!$A$6:$AV$47,41,0) -> 0 | J6: =+TONTFEV25!F6+TONTFEV25!G6 -> 0 | K6: =VLOOKUP($A6,[6]HISTOMARS25!$A$6:$AV$47,17,0) -> 0 | L6: =IF(K6<>0,VLOOKUP($A6,[6]HISTOMARS25!$A$6:$BB$47,42,0),"ECHEC") -> ECHEC | M6: =IF(P6=0,0,VLOOKUP($A6,[6]HISTOMARS25!$A$6:$AV$47,32,0)) -> 0 | N6: =VLOOKUP($A6,[6]HISTOMARS25!$A$6:$AV$47,33,0) -> 0 | O6: =IF(P6=0,0,($C$3-P6)) -> 0 | P6: =VLOOKUP($A6,[6]HISTOMARS25!$A$6:$AV$47,30,0) -> 0
A7: AS201602 | B7: =IF(D7=0,0,VLOOKUP($A7,[6]HISTOMARS25!$A$6:$BB$47,12,0)) -> 1 | C7: =VLOOKUP(A7,[7]LISTADHERENT!A$5:H$60,3,0) -> BOUTCHOUANG WILLIAM | D7: =IF(E7="ECHEC",0,VLOOKUP($A7,[6]HISTOMARS25!$A$6:$AR$47,13,0)) -> 75000 | E7: =VLOOKUP($A7,[6]HISTOMARS25!$A$6:$AV$47,9,0) -> BANQUE | F7: =VLOOKUP($A7,[6]HISTOMARS25!$A$6:$AV$47,36,0) -> 0 | G7: =VLOOKUP($A7,[6]HISTOMARS25!$A$6:$AV$47,39,0) -> 0 | H7: =IF(G7=0,"",VLOOKUP($A7,[6]HISTOFEV25!$A$6:$AV$47,42,0)) | I7: =VLOOKUP($A7,[6]HISTOMARS25!$A$6:$AV$47,41,0) -> 0 | J7: =+TONTFEV25!F7+TONTFEV25!G7 -> 103000 | K7: =VLOOKUP($A7,[6]HISTOMARS25!$A$6:$AV$47,17,0) -> 103000 | L7: =IF(K7<>0,VLOOKUP($A7,[6]HISTOMARS25!$A$6:$BB$47,42,0),"ECHEC") -> BANQUE | M7: =IF(P7=0,0,VLOOKUP($A7,[6]HISTOMARS25!$A$6:$AV$47,32,0)) -> 0 | N7: =VLOOKUP($A7,[6]HISTOMARS25!$A$6:$AV$47,33,0) -> 0 | O7: =IF(P7=0,0,($C$3-P7)) -> 0 | P7: =VLOOKUP($A7,[6]HISTOMARS25!$A$6:$AV$47,30,0) -> 0
A8: AS201613 | B8: =IF(D8=0,0,VLOOKUP($A8,[6]HISTOMARS25!$A$6:$BB$47,12,0)) -> 1 | C8: =VLOOKUP(A8,[7]LISTADHERENT!A$5:H$60,3,0) -> HOTCHO BENJAMIN | D8: =IF(E8="ECHEC",0,VLOOKUP($A8,[6]HISTOMARS25!$A$6:$AR$47,13,0)) -> 75000 | E8: =VLOOKUP($A8,[6]HISTOMARS25!$A$6:$AV$47,9,0) -> BANQUE | F8: =VLOOKUP($A8,[6]HISTOMARS25!$A$6:$AV$47,36,0) -> 91125 | G8: =VLOOKUP($A8,[6]HISTOMARS25!$A$6:$AV$47,39,0) -> 2000 | H8: =IF(G8=0,"",VLOOKUP($A8,[6]HISTOFEV25!$A$6:$AV$47,42,0)) -> 0 | I8: =VLOOKUP($A8,[6]HISTOMARS25!$A$6:$AV$47,41,0) -> 0 | J8: =+TONTFEV25!F8+TONTFEV25!G8 -> 0 | K8: =VLOOKUP($A8,[6]HISTOMARS25!$A$6:$AV$47,17,0) -> 0 | L8: =IF(K8<>0,VLOOKUP($A8,[6]HISTOMARS25!$A$6:$BB$47,42,0),"ECHEC") -> ECHEC | M8: =IF(P8=0,0,VLOOKUP($A8,[6]HISTOMARS25!$A$6:$AV$47,32,0)) -> BANQUE | N8: =VLOOKUP($A8,[6]HISTOMARS25!$A$6:$AV$47,33,0) -> 0 | O8: =IF(P8=0,0,($C$3-P8)) -> 892500 | P8: =VLOOKUP($A8,[6]HISTOMARS25!$A$6:$AV$47,30,0) -> 7500
A9: AS201619 | B9: =IF(D9=0,0,VLOOKUP($A9,[6]HISTOMARS25!$A$6:$BB$47,12,0)) -> 1 | C9: =VLOOKUP(A9,[7]LISTADHERENT!A$5:H$60,3,0) -> KOUATCHO MESSACK | D9: =IF(E9="ECHEC",0,VLOOKUP($A9,[6]HISTOMARS25!$A$6:$AR$47,13,0)) -> 75000 | E9: =VLOOKUP($A9,[6]HISTOMARS25!$A$6:$AV$47,9,0) -> BANQUE | F9: =VLOOKUP($A9,[6]HISTOMARS25!$A$6:$AV$47,36,0) -> 0 | G9: =VLOOKUP($A9,[6]HISTOMARS25!$A$6:$AV$47,39,0) -> 0 | H9: =IF(G9=0,"",VLOOKUP($A9,[6]HISTOFEV25!$A$6:$AV$47,42,0)) | I9: =VLOOKUP($A9,[6]HISTOMARS25!$A$6:$AV$47,41,0) -> 0 | J9: =+TONTFEV25!F9+TONTFEV25!G9 -> 54500 | K9: =VLOOKUP($A9,[6]HISTOMARS25!$A$6:$AV$47,17,0) -> 54500 | L9: =IF(K9<>0,VLOOKUP($A9,[6]HISTOMARS25!$A$6:$BB$47,42,0),"ECHEC") -> BANQUE | M9: =IF(P9=0,0,VLOOKUP($A9,[6]HISTOMARS25!$A$6:$AV$47,32,0)) -> 0 | N9: =VLOOKUP($A9,[6]HISTOMARS25!$A$6:$AV$47,33,0) -> 0 | O9: =IF(P9=0,0,($C$3-P9)) -> 0 | P9: =VLOOKUP($A9,[6]HISTOMARS25!$A$6:$AV$47,30,0) -> 0
A10: AS201611 | B10: =IF(D10=0,0,VLOOKUP($A10,[6]HISTOMARS25!$A$6:$BB$47,12,0)) -> 1 | C10: =VLOOKUP(A10,[7]LISTADHERENT!A$5:H$60,3,0) -> HENGUE PAUL OMER | D10: =IF(E10="ECHEC",0,VLOOKUP($A10,[6]HISTOMARS25!$A$6:$AR$47,13,0)) -> 75000 | E10: =VLOOKUP($A10,[6]HISTOMARS25!$A$6:$AV$47,9,0) -> BANQUE | F10: =VLOOKUP($A10,[6]HISTOMARS25!$A$6:$AV$47,36,0) -> 0 | G10: =VLOOKUP($A10,[6]HISTOMARS25!$A$6:$AV$47,39,0) -> 0 | H10: =IF(G10=0,"",VLOOKUP($A10,[6]HISTOFEV25!$A$6:$AV$47,42,0)) | I10: =VLOOKUP($A10,[6]HISTOMARS25!$A$6:$AV$47,41,0) -> 0 | J10: =+TONTFEV25!F10+TONTFEV25!G10 -> 0 | K10: =VLOOKUP($A10,[6]HISTOMARS25!$A$6:$AV$47,17,0) -> 0 | L10: =IF(K10<>0,VLOOKUP($A10,[6]HISTOMARS25!$A$6:$BB$47,42,0),"ECHEC") -> ECHEC | M10: =IF(P10=0,0,VLOOKUP($A10,[6]HISTOMARS25!$A$6:$AV$47,32,0)) -> 0 | N10: =VLOOKUP($A10,[6]HISTOMARS25!$A$6:$AV$47,33,0) -> 0 | O10: =IF(P10=0,0,($C$3-P10)) -> 0 | P10: =VLOOKUP($A10,[6]HISTOMARS25!$A$6:$AV$47,30,0) -> 0
A11: AS201649 | B11: =IF(D11=0,0,VLOOKUP($A11,[6]HISTOMARS25!$A$6:$BB$47,12,0)) -> 1 | C11: =VLOOKUP(A11,[7]LISTADHERENT!A$5:H$60,3,0) -> MBOGNING TUGMA GUY | D11: =IF(E11="ECHEC",0,VLOOKUP($A11,[6]HISTOMARS25!$A$6:$AR$47,13,0)) -> 75000 | E11: =VLOOKUP($A11,[6]HISTOMARS25!$A$6:$AV$47,9,0) -> BANQUE | F11: =VLOOKUP($A11,[6]HISTOMARS25!$A$6:$AV$47,36,0) -> 100000 | G11: =VLOOKUP($A11,[6]HISTOMARS25!$A$6:$AV$47,39,0) -> 2000 | H11: =IF(G11=0,"",VLOOKUP($A11,[6]HISTOFEV25!$A$6:$AV$47,42,0)) -> BANQUE | I11: =VLOOKUP($A11,[6]HISTOMARS25!$A$6:$AV$47,41,0) -> 0 | J11: =+TONTFEV25!F11+TONTFEV25!G11 -> 51000 | K11: =VLOOKUP($A11,[6]HISTOMARS25!$A$6:$AV$47,17,0) -> 51000 | L11: =IF(K11<>0,VLOOKUP($A11,[6]HISTOMARS25!$A$6:$BB$47,42,0),"ECHEC") -> BANQUE | M11: =IF(P11=0,0,VLOOKUP($A11,[6]HISTOMARS25!$A$6:$AV$47,32,0)) -> 0 | N11: =VLOOKUP($A11,[6]HISTOMARS25!$A$6:$AV$47,33,0) -> 0 | O11: =IF(P11=0,0,($C$3-P11)) -> 0 | P11: =VLOOKUP($A11,[6]HISTOMARS25!$A$6:$AV$47,30,0) -> 0
A12: AS201621 | B12: =IF(D12=0,0,VLOOKUP($A12,[6]HISTOMARS25!$A$6:$BB$47,12,0)) -> 1 | C12: =VLOOKUP(A12,[7]LISTADHERENT!A$5:H$60,3,0) -> NANKAM APPOLINAIRE | D12: =IF(E12="ECHEC",0,VLOOKUP($A12,[6]HISTOMARS25!$A$6:$AR$47,13,0)) -> 75000 | E12: =VLOOKUP($A12,[6]HISTOMARS25!$A$6:$AV$47,9,0) -> BANQUE | F12: =VLOOKUP($A12,[6]HISTOMARS25!$A$6:$AV$47,36,0) -> 0 | G12: =VLOOKUP($A12,[6]HISTOMARS25!$A$6:$AV$47,39,0) -> 0 | H12: =IF(G12=0,"",VLOOKUP($A12,[6]HISTOFEV25!$A$6:$AV$47,42,0)) | I12: =VLOOKUP($A12,[6]HISTOMARS25!$A$6:$AV$47,41,0) -> 0 | J12: =+TONTFEV25!F12+TONTFEV25!G12 -> 0 | K12: =VLOOKUP($A12,[6]HISTOMARS25!$A$6:$AV$47,17,0) -> 0 | L12: =IF(K12<>0,VLOOKUP($A12,[6]HISTOMARS25!$A$6:$BB$47,42,0),"ECHEC") -> ECHEC | M12: =IF(P12=0,0,VLOOKUP($A12,[6]HISTOMARS25!$A$6:$AV$47,32,0)) -> 0 | N12: =VLOOKUP($A12,[6]HISTOMARS25!$A$6:$AV$47,33,0) -> 0 | O12: =IF(P12=0,0,($C$3-P12)) -> 0 | P12: =VLOOKUP($A12,[6]HISTOMARS25!$A$6:$AV$47,30,0) -> 0
A13: AS201624 | B13: =IF(D13=0,0,VLOOKUP($A13,[6]HISTOMARS25!$A$6:$BB$47,12,0)) -> 1 | C13: =VLOOKUP(A13,[7]LISTADHERENT!A$5:H$60,3,0) -> NGONDIEP CLAUDE | D13: =IF(E13="ECHEC",0,VLOOKUP($A13,[6]HISTOMARS25!$A$6:$AR$47,13,0)) -> 75000 | E13: =VLOOKUP($A13,[6]HISTOMARS25!$A$6:$AV$47,9,0) -> BANQUE | F13: =VLOOKUP($A13,[6]HISTOMARS25!$A$6:$AV$47,36,0) -> 0 | G13: =VLOOKUP($A13,[6]HISTOMARS25!$A$6:$AV$47,39,0) -> 0 | H13: =IF(G13=0,"",VLOOKUP($A13,[6]HISTOFEV25!$A$6:$AV$47,42,0)) | I13: =VLOOKUP($A13,[6]HISTOMARS25!$A$6:$AV$47,41,0) -> 0 | J13: =+TONTFEV25!F13+TONTFEV25!G13 -> 0 | K13: =VLOOKUP($A13,[6]HISTOMARS25!$A$6:$AV$47,17,0) -> 0 | L13: =IF(K13<>0,VLOOKUP($A13,[6]HISTOMARS25!$A$6:$BB$47,42,0),"ECHEC") -> ECHEC | M13: =IF(P13=0,0,VLOOKUP($A13,[6]HISTOMARS25!$A$6:$AV$47,32,0)) -> 0 | N13: =VLOOKUP($A13,[6]HISTOMARS25!$A$6:$AV$47,33,0) -> 0 | O13: =IF(P13=0,0,($C$3-P13)) -> 0 | P13: =VLOOKUP($A13,[6]HISTOMARS25!$A$6:$AV$47,30,0) -> 0
A14: AS201633 | B14: =IF(D14=0,0,VLOOKUP($A14,[6]HISTOMARS25!$A$6:$BB$47,12,0)) -> 1 | C14: =VLOOKUP(A14,[7]LISTADHERENT!A$5:H$60,3,0) -> PATEGO NJOSSU GUSTAVE | D14: =IF(E14="ECHEC",0,VLOOKUP($A14,[6]HISTOMARS25!$A$6:$AR$47,13,0)) -> 75000 | E14: =VLOOKUP($A14,[6]HISTOMARS25!$A$6:$AV$47,9,0) -> BANQUE | F14: =VLOOKUP($A14,[6]HISTOMARS25!$A$6:$AV$47,36,0) -> 0 | G14: =VLOOKUP($A14,[6]HISTOMARS25!$A$6:$AV$47,39,0) -> 0 | H14: =IF(G14=0,"",VLOOKUP($A14,[6]HISTOFEV25!$A$6:$AV$47,42,0)) | I14: =VLOOKUP($A14,[6]HISTOMARS25!$A$6:$AV$47,41,0) -> 0 | J14: =+TONTFEV25!F14+TONTFEV25!G14 -> 0 | K14: =VLOOKUP($A14,[6]HISTOMARS25!$A$6:$AV$47,17,0) -> 0 | L14: =IF(K14<>0,VLOOKUP($A14,[6]HISTOMARS25!$A$6:$BB$47,42,0),"ECHEC") -> ECHEC | M14: =IF(P14=0,0,VLOOKUP($A14,[6]HISTOMARS25!$A$6:$AV$47,32,0)) -> 0 | N14: =VLOOKUP($A14,[6]HISTOMARS25!$A$6:$AV$47,33,0) -> 0 | O14: =IF(P14=0,0,($C$3-P14)) -> 0 | P14: =VLOOKUP($A14,[6]HISTOMARS25!$A$6:$AV$47,30,0) -> 0
A15: AS201641 | B15: =IF(D15=0,0,VLOOKUP($A15,[6]HISTOMARS25!$A$6:$BB$47,12,0)) -> 1 | C15: =VLOOKUP(A15,[7]LISTADHERENT!A$5:H$60,3,0) -> TCHOUAMOU MATHIEU | D15: =IF(E15="ECHEC",0,VLOOKUP($A15,[6]HISTOMARS25!$A$6:$AR$47,13,0)) -> 75000 | E15: =VLOOKUP($A15,[6]HISTOMARS25!$A$6:$AV$47,9,0) -> BANQUE | F15: =VLOOKUP($A15,[6]HISTOMARS25!$A$6:$AV$47,36,0) -> 100000 | G15: =VLOOKUP($A15,[6]HISTOMARS25!$A$6:$AV$47,39,0) -> 2000 | H15: =IF(G15=0,"",VLOOKUP($A15,[6]HISTOFEV25!$A$6:$AV$47,42,0)) -> 0 | I15: =VLOOKUP($A15,[6]HISTOMARS25!$A$6:$AV$47,41,0) -> 0 | J15: =+TONTFEV25!F15+TONTFEV25!G15 -> 0 | K15: =VLOOKUP($A15,[6]HISTOMARS25!$A$6:$AV$47,17,0) -> 0 | L15: =IF(K15<>0,VLOOKUP($A15,[6]HISTOMARS25!$A$6:$BB$47,42,0),"ECHEC") -> ECHEC | M15: =IF(P15=0,0,VLOOKUP($A15,[6]HISTOMARS25!$A$6:$AV$47,32,0)) -> 0 | N15: =VLOOKUP($A15,[6]HISTOMARS25!$A$6:$AV$47,33,0) -> 0 | O15: =IF(P15=0,0,($C$3-P15)) -> 0 | P15: =VLOOKUP($A15,[6]HISTOMARS25!$A$6:$AV$47,30,0) -> 0
A16: AS201658 | B16: =IF(D16=0,0,VLOOKUP($A16,[6]HISTOMARS25!$A$6:$BB$47,12,0)) -> 1 | C16: =VLOOKUP(A16,[7]LISTADHERENT!A$5:H$60,3,0) -> YANTCHOU GERVAIS | D16: =IF(E16="ECHEC",0,VLOOKUP($A16,[6]HISTOMARS25!$A$6:$AR$47,13,0)) -> 75000 | E16: =VLOOKUP($A16,[6]HISTOMARS25!$A$6:$AV$47,9,0) -> BANQUE | F16: =VLOOKUP($A16,[6]HISTOMARS25!$A$6:$AV$47,36,0) -> 0 | G16: =VLOOKUP($A16,[6]HISTOMARS25!$A$6:$AV$47,39,0) -> 0 | H16: =IF(G16=0,"",VLOOKUP($A16,[6]HISTOFEV25!$A$6:$AV$47,42,0)) | I16: =VLOOKUP($A16,[6]HISTOMARS25!$A$6:$AV$47,41,0) -> 0 | J16: =+TONTFEV25!F16+TONTFEV25!G16 -> 0 | K16: =VLOOKUP($A16,[6]HISTOMARS25!$A$6:$AV$47,17,0) -> 0 | L16: =IF(K16<>0,VLOOKUP($A16,[6]HISTOMARS25!$A$6:$BB$47,42,0),"ECHEC") -> ECHEC | M16: =IF(P16=0,0,VLOOKUP($A16,[6]HISTOMARS25!$A$6:$AV$47,32,0)) -> 0 | N16: =VLOOKUP($A16,[6]HISTOMARS25!$A$6:$AV$47,33,0) -> 0 | O16: =IF(P16=0,0,($C$3-P16)) -> 0 | P16: =VLOOKUP($A16,[6]HISTOMARS25!$A$6:$AV$47,30,0) -> 0
A17: AS201647 | B17: =IF(D17=0,0,VLOOKUP($A17,[6]HISTOMARS25!$A$6:$BB$47,12,0)) -> 1 | C17: =VLOOKUP(A17,[7]LISTADHERENT!A$5:H$60,3,0) -> YOUMBI EMMANUEL | D17: =IF(E17="ECHEC",0,VLOOKUP($A17,[6]HISTOMARS25!$A$6:$AR$47,13,0)) -> 75000 | E17: =VLOOKUP($A17,[6]HISTOMARS25!$A$6:$AV$47,9,0) -> BANQUE | F17: =VLOOKUP($A17,[6]HISTOMARS25!$A$6:$AV$47,36,0) -> 0 | G17: =VLOOKUP($A17,[6]HISTOMARS25!$A$6:$AV$47,39,0) -> 0 | H17: =IF(G17=0,"",VLOOKUP($A17,[6]HISTOFEV25!$A$6:$AV$47,42,0)) | I17: =VLOOKUP($A17,[6]HISTOMARS25!$A$6:$AV$47,41,0) -> 0 | J17: =+TONTFEV25!F17+TONTFEV25!G17 -> 0 | K17: =VLOOKUP($A17,[6]HISTOMARS25!$A$6:$AV$47,17,0) -> 0 | L17: =IF(K17<>0,VLOOKUP($A17,[6]HISTOMARS25!$A$6:$BB$47,42,0),"ECHEC") -> ECHEC | M17: =IF(P17=0,0,VLOOKUP($A17,[6]HISTOMARS25!$A$6:$AV$47,32,0)) -> 0 | N17: =VLOOKUP($A17,[6]HISTOMARS25!$A$6:$AV$47,33,0) -> 0 | O17: =IF(P17=0,0,($C$3-P17)) -> 0 | P17: =VLOOKUP($A17,[6]HISTOMARS25!$A$6:$AV$47,30,0) -> 0
A19: TOTAL PART | B19: =SUM(B6:B18) -> 13
A20: NBRE ADHERENT | B20: =COUNT(D6:D18) -> 12 | D20: =SUM(D6:D19) -> 975000 | E20: =SUM(E6:E19) -> 0 | F20: =SUM(F6:F19) -> 291125 | G20: =SUM(G6:G19) -> 6000 | H20: =SUM(H6:H19) -> 0 | I20: =SUM(I6:I19) -> 0 | J20: =SUM(J6:J19) -> 208500 | K20: =SUM(K6:K19) -> 208500 | ... P20: =SUM(P6:P19) -> 7500
L21: NBRE PART | M21: PART VENDUE
D22: MONTANT TONTINE | E22: REMBOURSEMENT PETIT LOT | F22: VENTE PETIT LOT | G22: VENTE LOT PRINCIPAL | H22: SOLDE EN CAISSE | J22: TONTINE + REMB + INTERET VENTE+RELIQUAT | K22: =D26+E26+P20+TONTFEV25!M27 -> 1093500
D23: =SUMIFS(D6:D19,E6:E19,"ESPECES") -> 0 | E23: =SUMIFS(K7:K14,L7:L14,"ESPECES") -> 0 | F23: =SUMIFS(F7:F19,H7:H19,"ESPECES") -> 0 | G23: =SUMIFS(O7:O19,M7:M19,"ESPECES") -> 0 | H23: =D23+E23-F23-G23 -> 0 | J23: LOT PRINCIPAL | K23: =C3*COUNTIF(O7:O19,">0") -> 900000 | L23: =D3 -> 1 | M23: =COUNTIF(O7:O14,">0") -> 1
D24: =SUMIFS(D6:D19,E6:E19,"BANQUE") -> 975000 | E24: =SUMIFS(K7:K14,L7:L14,"BANQUE") -> 208500 | F24: =SUMIFS(F7:F19,H7:H19,"BANQUE") -> 100000 | G24: =SUMIFS(O7:O19,M7:M19,"BANQUE") -> 892500 | H24: =D24+E24-F24-G24 -> 191000
J25: PETIT LOT | K25: =K22-K23 -> 193500
D26: =D23+D24 -> 975000 | E26: =E23+E24 -> 208500 | F26: =F23+F24 -> 100000 | G26: =G23+G24 -> 892500 | H26: =H23+H24 -> 191000
J27: RELIQUAT | K27: =K25-F20 -> -97625 | M27: =K27 -> -97625 | N27: CUMUL
J29: ECHEC TONTINE MOIS | K29: =COUNTIFS(E7:E18,"ECHEC")*75000 -> 0 | M29: =+K29+TONTFEV25!M29 -> 0 | N29: CUMUL
J30: ECHEC REMBOURSEMENT MOIS | K30: =J20-E26 -> 0 | M30: =+K30+TONTFEV25!M30 -> 0 | N30: CUMUL

Sheet TONTAVRIL25
A1: ASSOCIATION | B1: ASELBY
A2: ANNEE | B2: 2025 | C2: TONIINE | D2: NBRE PART
A3: TAUX TONTINE | B3: 75000 | C3: =B3*12 -> 900000 | D3: =ROUNDDOWN(K22/C3,0) -> 1
C4: 45760
A5: MATRICULE | B5: NBREPART | C5: NOM ET PRENOM | D5: MONTANT TONTINE | E5: MODE VERSEMENT | F5: VENTE PETIT LOT | G5: INTERET PETIT LOT | H5: MODE VERSEMENT VENTE PETIT LOT | I5: NUMERO CHEQUE | J5: MONTANT A REMBOURSER PETIT LOT | K5: REMBOURSEMENT PETIT LOT | L5: MODE VERSEMENT REMBOURSEMENT | M5: MODE VERSEMENTLOT PRINCIPAL | N5: NUMERO CHEQUE | O5: MONTANT LOT PRINCIPAL | P5: INTERET LOT PRINCIPAL
A6: AS201648 | B6: =IF(D6=0,0,VLOOKUP($A6,[6]HISTOAVRIL25!$A$6:$BB$47,12,0)) -> 2 | C6: =VLOOKUP(A6,[7]LISTADHERENT!A$5:H$60,3,0) -> ASELBY | D6: =IF(E6="ECHEC",0,VLOOKUP($A6,[6]HISTOAVRIL25!$A$6:$AR$47,13,0)) -> 150000 | E6: =VLOOKUP($A6,[6]HISTOAVRIL25!$A$6:$AV$47,9,0) -> BANQUE | F6: =VLOOKUP($A6,[6]HISTOAVRIL25!$A$6:$AV$47,36,0) -> 0 | G6: =VLOOKUP($A6,[6]HISTOAVRIL25!$A$6:$AV$47,39,0) -> 0 | H6: =IF(G6=0,"",VLOOKUP($A6,[6]HISTOFEV25!$A$6:$AV$47,42,0)) | I6: =VLOOKUP($A6,[6]HISTOAVRIL25!$A$6:$AV$47,41,0) -> 0 | J6: =+TONTMARS25!F6+TONTMARS25!G6 -> 0 | K6: =VLOOKUP($A6,[6]HISTOAVRIL25!$A$6:$AV$47,17,0) -> 0 | L6: =IF(K6<>0,VLOOKUP($A6,[6]HISTOAVRIL25!$A$6:$BB$47,42,0),"ECHEC") -> ECHEC | M6: =IF(P6=0,0,VLOOKUP($A6,[6]HISTOAVRIL25!$A$6:$AV$47,32,0)) -> 0 | N6: =VLOOKUP($A6,[6]HISTOAVRIL25!$A$6:$AV$47,33,0) -> 0 | O6: =IF(P6=0,0,($C$3-P6)) -> 0 | P6: =VLOOKUP($A6,[6]HISTOAVRIL25!$A$6:$AV$47,30,0) -> 0
A7: AS201602 | B7: =IF(D7=0,0,VLOOKUP($A7,[6]HISTOAVRIL25!$A$6:$BB$47,12,0)) -> 1 | C7: =VLOOKUP(A7,[7]LISTADHERENT!A$5:H$60,3,0) -> BOUTCHOUANG WILLIAM | D7: =IF(E7="ECHEC",0,VLOOKUP($A7,[6]HISTOAVRIL25!$A$6:$AR$47,13,0)) -> 75000 | E7: =VLOOKUP($A7,[6]HISTOAVRIL25!$A$6:$AV$47,9,0) -> BANQUE | F7: =VLOOKUP($A7,[6]HISTOAVRIL25!$A$6:$AV$47,36,0) -> 0 | G7: =VLOOKUP($A7,[6]HISTOAVRIL25!$A$6:$AV$47,39,0) -> 0 | H7: =IF(G7=0,"",VLOOKUP($A7,[6]HISTOFEV25!$A$6:$AV$47,42,0)) | I7: =VLOOKUP($A7,[6]HISTOAVRIL25!$A$6:$AV$47,41,0) -> 0 | J7: =+TONTMARS25!F7+TONTMARS25!G7 -> 0 | K7: =VLOOKUP($A7,[6]HISTOAVRIL25!$A$6:$AV$47,17,0) -> 0 | L7: =IF(K7<>0,VLOOKUP($A7,[6]HISTOAVRIL25!$A$6:$BB$47,42,0),"ECHEC") -> ECHEC | M7: =IF(P7=0,0,VLOOKUP($A7,[6]HISTOAVRIL25!$A$6:$AV$47,32,0)) -> 0 | N7: =VLOOKUP($A7,[6]HISTOAVRIL25!$A$6:$AV$47,33,0) -> 0 | O7: =IF(P7=0,0,($C$3-P7)) -> 0 | P7: =VLOOKUP($A7,[6]HISTOAVRIL25!$A$6:$AV$47,30,0) -> 0
A8: AS201613 | B8: =IF(D8=0,0,VLOOKUP($A8,[6]HISTOAVRIL25!$A$6:$BB$47,12,0)) -> 1 | C8: =VLOOKUP(A8,[7]LISTADHERENT!A$5:H$60,3,0) -> HOTCHO BENJAMIN | D8: =IF(E8="ECHEC",0,VLOOKUP($A8,[6]HISTOAVRIL25!$A$6:$AR$47,13,0)) -> 75000 | E8: =VLOOKUP($A8,[6]HISTOAVRIL25!$A$6:$AV$47,9,0) -> BANQUE | F8: =VLOOKUP($A8,[6]HISTOAVRIL25!$A$6:$AV$47,36,0) -> 50000 | G8: =VLOOKUP($A8,[6]HISTOAVRIL25!$A$6:$AV$47,39,0) -> 1000 | H8: =IF(G8=0,"",VLOOKUP($A8,[6]HISTOFEV25!$A$6:$AV$47,42,0)) -> 0 | I8: =VLOOKUP($A8,[6]HISTOAVRIL25!$A$6:$AV$47,41,0) -> 0 | J8: =+TONTMARS25!F8+TONTMARS25!G8 -> 93125 | K8: =VLOOKUP($A8,[6]HISTOAVRIL25!$A$6:$AV$47,17,0) -> 93125 | L8: =IF(K8<>0,VLOOKUP($A8,[6]HISTOAVRIL25!$A$6:$BB$47,42,0),"ECHEC") -> BANQUE | M8: =IF(P8=0,0,VLOOKUP($A8,[6]HISTOAVRIL25!$A$6:$AV$47,32,0)) -> 0 | N8: =VLOOKUP($A8,[6]HISTOAVRIL25!$A$6:$AV$47,33,0) -> 0 | O8: =IF(P8=0,0,($C$3-P8)) -> 0 | P8: =VLOOKUP($A8,[6]HISTOAVRIL25!$A$6:$AV$47,30,0) -> 0
A9: AS201619 | B9: =IF(D9=0,0,VLOOKUP($A9,[6]HISTOAVRIL25!$A$6:$BB$47,12,0)) -> 1 | C9: =VLOOKUP(A9,[7]LISTADHERENT!A$5:H$60,3,0) -> KOUATCHO MESSACK | D9: =IF(E9="ECHEC",0,VLOOKUP($A9,[6]HISTOAVRIL25!$A$6:$AR$47,13,0)) -> 75000 | E9: =VLOOKUP($A9,[6]HISTOAVRIL25!$A$6:$AV$47,9,0) -> BANQUE | F9: =VLOOKUP($A9,[6]HISTOAVRIL25!$A$6:$AV$47,36,0) -> 0 | G9: =VLOOKUP($A9,[6]HISTOAVRIL25!$A$6:$AV$47,39,0) -> 0 | H9: =IF(G9=0,"",VLOOKUP($A9,[6]HISTOFEV25!$A$6:$AV$47,42,0)) | I9: =VLOOKUP($A9,[6]HISTOAVRIL25!$A$6:$AV$47,41,0) -> 0 | J9: =+TONTMARS25!F9+TONTMARS25!G9 -> 0 | K9: =VLOOKUP($A9,[6]HISTOAVRIL25!$A$6:$AV$47,17,0) -> 0 | L9: =IF(K9<>0,VLOOKUP($A9,[6]HISTOAVRIL25!$A$6:$BB$47,42,0),"ECHEC") -> ECHEC | M9: =IF(P9=0,0,VLOOKUP($A9,[6]HISTOAVRIL25!$A$6:$AV$47,32,0)) -> BANQUE | N9: =VLOOKUP($A9,[6]HISTOAVRIL25!$A$6:$AV$47,33,0) -> 0 | O9: =IF(P9=0,0,($C$3-P9)) -> 892500 | P9: =VLOOKUP($A9,[6]HISTOAVRIL25!$A$6:$AV$47,30,0) -> 7500
A10: AS201611 | B10: =IF(D10=0,0,VLOOKUP($A10,[6]HISTOAVRIL25!$A$6:$BB$47,12,0)) -> 1 | C10: =VLOOKUP(A10,[7]LISTADHERENT!A$5:H$60,3,0) -> HENGUE PAUL OMER | D10: =IF(E10="ECHEC",0,VLOOKUP($A10,[6]HISTOAVRIL25!$A$6:$AR$47,13,0)) -> 75000 | E10: =VLOOKUP($A10,[6]HISTOAVRIL25!$A$6:$AV$47,9,0) -> BANQUE | F10: =VLOOKUP($A10,[6]HISTOAVRIL25!$A$6:$AV$47,36,0) -> 0 | G10: =VLOOKUP($A10,[6]HISTOAVRIL25!$A$6:$AV$47,39,0) -> 0 | H10: =IF(G10=0,"",VLOOKUP($A10,[6]HISTOFEV25!$A$6:$AV$47,42,0)) | I10: =VLOOKUP($A10,[6]HISTOAVRIL25!$A$6:$AV$47,41,0) -> 0 | J10: =+TONTMARS25!F10+TONTMARS25!G10 -> 0 | K10: =VLOOKUP($A10,[6]HISTOAVRIL25!$A$6:$AV$47,17,0) -> 0 | L10: =IF(K10<>0,VLOOKUP($A10,[6]HISTOAVRIL25!$A$6:$BB$47,42,0),"ECHEC") -> ECHEC | M10: =IF(P10=0,0,VLOOKUP($A10,[6]HISTOAVRIL25!$A$6:$AV$47,32,0)) -> 0 | N10: =VLOOKUP($A10,[6]HISTOAVRIL25!$A$6:$AV$47,33,0) -> 0 | O10: =IF(P10=0,0,($C$3-P10)) -> 0 | P10: =VLOOKUP($A10,[6]HISTOAVRIL25!$A$6:$AV$47,30,0) -> 0
A11: AS201649 | B11: =IF(D11=0,0,VLOOKUP($A11,[6]HISTOAVRIL25!$A$6:$BB$47,12,0)) -> 1 | C11: =VLOOKUP(A11,[7]LISTADHERENT!A$5:H$60,3,0) -> MBOGNING TUGMA GUY | D11: =IF(E11="ECHEC",0,VLOOKUP($A11,[6]HISTOAVRIL25!$A$6:$AR$47,13,0)) -> 75000 | E11: =VLOOKUP($A11,[6]HISTOAVRIL25!$A$6:$AV$47,9,0) -> BANQUE | F11: =VLOOKUP($A11,[6]HISTOAVRIL25!$A$6:$AV$47,36,0) -> 100000 | G11: =VLOOKUP($A11,[6]HISTOAVRIL25!$A$6:$AV$47,39,0) -> 2000 | H11: =IF(G11=0,"",VLOOKUP($A11,[6]HISTOFEV25!$A$6:$AV$47,42,0)) -> BANQUE | I11: =VLOOKUP($A11,[6]HISTOAVRIL25!$A$6:$AV$47,41,0) -> 0 | J11: =+TONTMARS25!F11+TONTMARS25!G11 -> 102000 | K11: =VLOOKUP($A11,[6]HISTOAVRIL25!$A$6:$AV$47,17,0) -> 102000 | L11: =IF(K11<>0,VLOOKUP($A11,[6]HISTOAVRIL25!$A$6:$BB$47,42,0),"ECHEC") -> BANQUE | M11: =IF(P11=0,0,VLOOKUP($A11,[6]HISTOAVRIL25!$A$6:$AV$47,32,0)) -> 0 | N11: =VLOOKUP($A11,[6]HISTOAVRIL25!$A$6:$AV$47,33,0) -> 0 | O11: =IF(P11=0,0,($C$3-P11)) -> 0 | P11: =VLOOKUP($A11,[6]HISTOAVRIL25!$A$6:$AV$47,30,0) -> 0
A12: AS201621 | B12: =IF(D12=0,0,VLOOKUP($A12,[6]HISTOAVRIL25!$A$6:$BB$47,12,0)) -> 1 | C12: =VLOOKUP(A12,[7]LISTADHERENT!A$5:H$60,3,0) -> NANKAM APPOLINAIRE | D12: =IF(E12="ECHEC",0,VLOOKUP($A12,[6]HISTOAVRIL25!$A$6:$AR$47,13,0)) -> 75000 | E12: =VLOOKUP($A12,[6]HISTOAVRIL25!$A$6:$AV$47,9,0) -> BANQUE | F12: =VLOOKUP($A12,[6]HISTOAVRIL25!$A$6:$AV$47,36,0) -> 0 | G12: =VLOOKUP($A12,[6]HISTOAVRIL25!$A$6:$AV$47,39,0) -> 0 | H12: =IF(G12=0,"",VLOOKUP($A12,[6]HISTOFEV25!$A$6:$AV$47,42,0)) | I12: =VLOOKUP($A12,[6]HISTOAVRIL25!$A$6:$AV$47,41,0) -> 0 | J12: =+TONTMARS25!F12+TONTMARS25!G12 -> 0 | K12: =VLOOKUP($A12,[6]HISTOAVRIL25!$A$6:$AV$47,17,0) -> 0 | L12: =IF(K12<>0,VLOOKUP($A12,[6]HISTOAVRIL25!$A$6:$BB$47,42,0),"ECHEC") -> ECHEC | M12: =IF(P12=0,0,VLOOKUP($A12,[6]HISTOAVRIL25!$A$6:$AV$47,32,0)) -> 0 | N12: =VLOOKUP($A12,[6]HISTOAVRIL25!$A$6:$AV$47,33,0) -> 0 | O12: =IF(P12=0,0,($C$3-P12)) -> 0 | P12: =VLOOKUP($A12,[6]HISTOAVRIL25!$A$6:$AV$47,30,0) -> 0
A13: AS201624 | B13: =IF(D13=0,0,VLOOKUP($A13,[6]HISTOAVRIL25!$A$6:$BB$47,12,0)) -> 1 | C13: =VLOOKUP(A13,[7]LISTADHERENT!A$5:H$60,3,0) -> NGONDIEP CLAUDE | D13: =IF(E13="ECHEC",0,VLOOKUP($A13,[6]HISTOAVRIL25!$A$6:$AR$47,13,0)) -> 75000 | E13: =VLOOKUP($A13,[6]HISTOAVRIL25!$A$6:$AV$47,9,0) -> BANQUE | F13: =VLOOKUP($A13,[6]HISTOAVRIL25!$A$6:$AV$47,36,0) -> 79625 | G13: =VLOOKUP($A13,[6]HISTOAVRIL25!$A$6:$AV$47,39,0) -> 1000 | H13: =IF(G13=0,"",VLOOKUP($A13,[6]HISTOFEV25!$A$6:$AV$47,42,0)) -> 0 | I13: =VLOOKUP($A13,[6]HISTOAVRIL25!$A$6:$AV$47,41,0) -> 0 | J13: =+TONTMARS25!F13+TONTMARS25!G13 -> 0 | K13: =VLOOKUP($A13,[6]HISTOAVRIL25!$A$6:$AV$47,17,0) -> 0 | L13: =IF(K13<>0,VLOOKUP($A13,[6]HISTOAVRIL25!$A$6:$BB$47,42,0),"ECHEC") -> ECHEC | M13: =IF(P13=0,0,VLOOKUP($A13,[6]HISTOAVRIL25!$A$6:$AV$47,32,0)) -> 0 | N13: =VLOOKUP($A13,[6]HISTOAVRIL25!$A$6:$AV$47,33,0) -> 0 | O13: =IF(P13=0,0,($C$3-P13)) -> 0 | P13: =VLOOKUP($A13,[6]HISTOAVRIL25!$A$6:$AV$47,30,0) -> 0
A14: AS201633 | B14: =IF(D14=0,0,VLOOKUP($A14,[6]HISTOAVRIL25!$A$6:$BB$47,12,0)) -> 1 | C14: =VLOOKUP(A14,[7]LISTADHERENT!A$5:H$60,3,0) -> PATEGO NJOSSU GUSTAVE | D14: =IF(E14="ECHEC",0,VLOOKUP($A14,[6]HISTOAVRIL25!$A$6:$AR$47,13,0)) -> 75000 | E14: =VLOOKUP($A14,[6]HISTOAVRIL25!$A$6:$AV$47,9,0) -> BANQUE | F14: =VLOOKUP($A14,[6]HISTOAVRIL25!$A$6:$AV$47,36,0) -> 0 | G14: =VLOOKUP($A14,[6]HISTOAVRIL25!$A$6:$AV$47,39,0) -> 0 | H14: =IF(G14=0,"",VLOOKUP($A14,[6]HISTOFEV25!$A$6:$AV$47,42,0)) | I14: =VLOOKUP($A14,[6]HISTOAVRIL25!$A$6:$AV$47,41,0) -> 0 | J14: =+TONTMARS25!F14+TONTMARS25!G14 -> 0 | K14: =VLOOKUP($A14,[6]HISTOAVRIL25!$A$6:$AV$47,17,0) -> 0 | L14: =IF(K14<>0,VLOOKUP($A14,[6]HISTOAVRIL25!$A$6:$BB$47,42,0),"ECHEC") -> ECHEC | M14: =IF(P14=0,0,VLOOKUP($A14,[6]HISTOAVRIL25!$A$6:$AV$47,32,0)) -> 0 | N14: =VLOOKUP($A14,[6]HISTOAVRIL25!$A$6:$AV$47,33,0) -> 0 | O14: =IF(P14=0,0,($C$3-P14)) -> 0 | P14: =VLOOKUP($A14,[6]HISTOAVRIL25!$A$6:$AV$47,30,0) -> 0
A15: AS201641 | B15: =IF(D15=0,0,VLOOKUP($A15,[6]HISTOAVRIL25!$A$6:$BB$47,12,0)) -> 1 | C15: =VLOOKUP(A15,[7]LISTADHERENT!A$5:H$60,3,0) -> TCHOUAMOU MATHIEU | D15: =IF(E15="ECHEC",0,VLOOKUP($A15,[6]HISTOAVRIL25!$A$6:$AR$47,13,0)) -> 75000 | E15: =VLOOKUP($A15,[6]HISTOAVRIL25!$A$6:$AV$47,9,0) -> BANQUE | F15: =VLOOKUP($A15,[6]HISTOAVRIL25!$A$6:$AV$47,36,0) -> 50000 | G15: =VLOOKUP($A15,[6]HISTOAVRIL25!$A$6:$AV$47,39,0) -> 1000 | H15: =IF(G15=0,"",VLOOKUP($A15,[6]HISTOFEV25!$A$6:$AV$47,42,0)) -> 0 | I15: =VLOOKUP($A15,[6]HISTOAVRIL25!$A$6:$AV$47,41,0) -> 0 | J15: =+TONTMARS25!F15+TONTMARS25!G15 -> 102000 | K15: =VLOOKUP($A15,[6]HISTOAVRIL25!$A$6:$AV$47,17,0) -> 102000 | L15: =IF(K15<>0,VLOOKUP($A15,[6]HISTOAVRIL25!$A$6:$BB$47,42,0),"ECHEC") -> BANQUE | M15: =IF(P15=0,0,VLOOKUP($A15,[6]HISTOAVRIL25!$A$6:$AV$47,32,0)) -> 0 | N15: =VLOOKUP($A15,[6]HISTOAVRIL25!$A$6:$AV$47,33,0) -> 0 | O15: =IF(P15=0,0,($C$3-P15)) -> 0 | P15: =VLOOKUP($A15,[6]HISTOAVRIL25!$A$6:$AV$47,30,0) -> 0
A16: AS201658 | B16: =IF(D16=0,0,VLOOKUP($A16,[6]HISTOAVRIL25!$A$6:$BB$47,12,0)) -> 1 | C16: =VLOOKUP(A16,[7]LISTADHERENT!A$5:H$60,3,0) -> YANTCHOU GERVAIS | D16: =IF(E16="ECHEC",0,VLOOKUP($A16,[6]HISTOAVRIL25!$A$6:$AR$47,13,0)) -> 75000 | E16: =VLOOKUP($A16,[6]HISTOAVRIL25!$A$6:$AV$47,9,0) -> BANQUE | F16: =VLOOKUP($A16,[6]HISTOAVRIL25!$A$6:$AV$47,36,0) -> 100000 | G16: =VLOOKUP($A16,[6]HISTOAVRIL25!$A$6:$AV$47,39,0) -> 2000 | H16: =IF(G16=0,"",VLOOKUP($A16,[6]HISTOFEV25!$A$6:$AV$47,42,0)) -> 0 | I16: =VLOOKUP($A16,[6]HISTOAVRIL25!$A$6:$AV$47,41,0) -> 0 | J16: =+TONTMARS25!F16+TONTMARS25!G16 -> 0 | K16: =VLOOKUP($A16,[6]HISTOAVRIL25!$A$6:$AV$47,17,0) -> 0 | L16: =IF(K16<>0,VLOOKUP($A16,[6]HISTOAVRIL25!$A$6:$BB$47,42,0),"ECHEC") -> ECHEC | M16: =IF(P16=0,0,VLOOKUP($A16,[6]HISTOAVRIL25!$A$6:$AV$47,32,0)) -> 0 | N16: =VLOOKUP($A16,[6]HISTOAVRIL25!$A$6:$AV$47,33,0) -> 0 | O16: =IF(P16=0,0,($C$3-P16)) -> 0 | P16: =VLOOKUP($A16,[6]HISTOAVRIL25!$A$6:$AV$47,30,0) -> 0
A17: AS201647 | B17: =IF(D17=0,0,VLOOKUP($A17,[6]HISTOAVRIL25!$A$6:$BB$47,12,0)) -> 1 | C17: =VLOOKUP(A17,[7]LISTADHERENT!A$5:H$60,3,0) -> YOUMBI EMMANUEL | D17: =IF(E17="ECHEC",0,VLOOKUP($A17,[6]HISTOAVRIL25!$A$6:$AR$47,13,0)) -> 75000 | E17: =VLOOKUP($A17,[6]HISTOAVRIL25!$A$6:$AV$47,9,0) -> BANQUE | F17: =VLOOKUP($A17,[6]HISTOAVRIL25!$A$6:$AV$47,36,0) -> 0 | G17: =VLOOKUP($A17,[6]HISTOAVRIL25!$A$6:$AV$47,39,0) -> 0 | H17: =IF(G17=0,"",VLOOKUP($A17,[6]HISTOFEV25!$A$6:$AV$47,42,0)) | I17: =VLOOKUP($A17,[6]HISTOAVRIL25!$A$6:$AV$47,41,0) -> 0 | J17: =+TONTMARS25!F17+TONTMARS25!G17 -> 0 | K17: =VLOOKUP($A17,[6]HISTOAVRIL25!$A$6:$AV$47,17,0) -> 0 | L17: =IF(K17<>0,VLOOKUP($A17,[6]HISTOAVRIL25!$A$6:$BB$47,42,0),"ECHEC") -> ECHEC | M17: =IF(P17=0,0,VLOOKUP($A17,[6]HISTOAVRIL25!$A$6:$AV$47,32,0)) -> 0 | N17: =VLOOKUP($A17,[6]HISTOAVRIL25!$A$6:$AV$47,33,0) -> 0 | O17: =IF(P17=0,0,($C$3-P17)) -> 0 | P17: =VLOOKUP($A17,[6]HISTOAVRIL25!$A$6:$AV$47,30,0) -> 0
A19: TOTAL PART | B19: =SUM(B6:B18) -> 13
A20: NBRE ADHERENT | B20: =COUNT(D6:D18) -> 12 | D20: =SUM(D6:D19) -> 975000 | E20: =SUM(E6:E19) -> 0 | F20: =SUM(F6:F19) -> 379625 | G20: =SUM(G6:G19) -> 7000 | H20: =SUM(H6:H19) -> 0 | I20: =SUM(I6:I19) -> 0 | J20: =SUM(J6:J19) -> 297125 | K20: =SUM(K6:K19) -> 297125 | ... P20: =SUM(P6:P19) -> 7500
L21: NBRE PART | M21: PART VENDUE
D22: MONTANT TONTINE | E22: REMBOURSEMENT PETIT LOT | F22: VENTE PETIT LOT | G22: VENTE LOT PRINCIPAL | H22: SOLDE EN CAISSE | J22: TONTINE + REMB + INTERET VENTE+RELIQUAT | K22: =D26+E26+P20+TONTFEV25!M27 -> 1080125
D23: =SUMIFS(D6:D19,E6:E19,"ESPECES") -> 0 | E23: =SUMIFS(K7:K14,L7:L14,"ESPECES") -> 0 | F23: =SUMIFS(F7:F19,H7:H19,"ESPECES") -> 0 | G23: =SUMIFS(O7:O19,M7:M19,"ESPECES") -> 0 | H23: =D23+E23-F23-G23 -> 0 | J23: LOT PRINCIPAL | K23: =C3*COUNTIF(O7:O19,">0") -> 900000 | L23: =D3 -> 1 | M23: =COUNTIF(O7:O14,">0") -> 1
D24: =SUMIFS(D6:D19,E6:E19,"BANQUE") -> 975000 | E24: =SUMIFS(K7:K14,L7:L14,"BANQUE") -> 195125 | F24: =SUMIFS(F7:F19,H7:H19,"BANQUE") -> 100000 | G24: =SUMIFS(O7:O19,M7:M19,"BANQUE") -> 892500 | H24: =D24+E24-F24-G24 -> 177625
J25: PETIT LOT | K25: =K22-K23 -> 180125
D26: =D23+D24 -> 975000 | E26: =E23+E24 -> 195125 | F26: =F23+F24 -> 100000 | G26: =G23+G24 -> 892500 | H26: =H23+H24 -> 177625
J27: RELIQUAT | K27: =K25-F20 -> -199500 | M27: =K27 -> -199500 | N27: CUMUL
J29: ECHEC TONTINE MOIS | K29: =COUNTIFS(E7:E18,"ECHEC")*75000 -> 0 | M29: =+K29+TONTFEV25!M29 -> 0 | N29: CUMUL
J30: ECHEC REMBOURSEMENT MOIS | K30: =J20-E26 -> 102000 | M30: =+K30+TONTFEV25!M30 -> 102000 | N30: CUMUL

Sheet TONTMAI25
A1: ASSOCIATION | B1: ASELBY
A2: ANNEE | B2: 2025 | C2: TONIINE | D2: NBRE PART
A3: TAUX TONTINE | B3: 75000 | C3: =B3*12 -> 900000 | D3: =ROUNDDOWN(K22/C3,0) -> 1
C4: 45790
A5: MATRICULE | B5: NBREPART | C5: NOM ET PRENOM | D5: MONTANT TONTINE | E5: MODE VERSEMENT | F5: VENTE PETIT LOT | G5: INTERET PETIT LOT | H5: MODE VERSEMENT VENTE PETIT LOT | I5: NUMERO CHEQUE | J5: MONTANT A REMBOURSER PETIT LOT | K5: REMBOURSEMENT PETIT LOT | L5: MODE VERSEMENT REMBOURSEMENT | M5: MODE VERSEMENTLOT PRINCIPAL | N5: NUMERO CHEQUE | O5: MONTANT LOT PRINCIPAL | P5: INTERET LOT PRINCIPAL
A6: AS201648 | B6: =IF(D6=0,0,VLOOKUP($A6,[6]HISTOMAI25!$A$6:$BB$47,12,0)) -> 2 | C6: =VLOOKUP(A6,[7]LISTADHERENT!A$5:H$60,3,0) -> ASELBY | D6: =IF(E6="ECHEC",0,VLOOKUP($A6,[6]HISTOMAI25!$A$6:$AR$47,13,0)) -> 150000 | E6: =VLOOKUP($A6,[6]HISTOMAI25!$A$6:$AV$47,9,0) -> BANQUE | F6: =VLOOKUP($A6,[6]HISTOMAI25!$A$6:$AV$47,36,0) -> 0 | G6: =VLOOKUP($A6,[6]HISTOMAI25!$A$6:$AV$47,39,0) -> 0 | H6: =IF(G6=0,"",VLOOKUP($A6,[6]HISTOFEV25!$A$6:$AV$47,42,0)) | I6: =VLOOKUP($A6,[6]HISTOMAI25!$A$6:$AV$47,41,0) -> 0 | J6: =+TONTAVRIL25!F6+TONTAVRIL25!G6 -> 0 | K6: =VLOOKUP($A6,[6]HISTOMAI25!$A$6:$AV$47,17,0) -> 0 | L6: =IF(K6<>0,VLOOKUP($A6,[6]HISTOMAI25!$A$6:$BB$47,42,0),"ECHEC") -> ECHEC | M6: =IF(P6=0,0,VLOOKUP($A6,[6]HISTOMAI25!$A$6:$AV$47,32,0)) -> 0 | N6: =VLOOKUP($A6,[6]HISTOMAI25!$A$6:$AV$47,33,0) -> 0 | O6: =IF(P6=0,0,($C$3-P6)) -> 0 | P6: =VLOOKUP($A6,[6]HISTOMAI25!$A$6:$AV$47,30,0) -> 0
A7: AS201602 | B7: =IF(D7=0,0,VLOOKUP($A7,[6]HISTOMAI25!$A$6:$BB$47,12,0)) -> 1 | C7: =VLOOKUP(A7,[7]LISTADHERENT!A$5:H$60,3,0) -> BOUTCHOUANG WILLIAM | D7: =IF(E7="ECHEC",0,VLOOKUP($A7,[6]HISTOMAI25!$A$6:$AR$47,13,0)) -> 75000 | E7: =VLOOKUP($A7,[6]HISTOMAI25!$A$6:$AV$47,9,0) -> BANQUE | F7: =VLOOKUP($A7,[6]HISTOMAI25!$A$6:$AV$47,36,0) -> 0 | G7: =VLOOKUP($A7,[6]HISTOMAI25!$A$6:$AV$47,39,0) -> 0 | H7: =IF(G7=0,"",VLOOKUP($A7,[6]HISTOFEV25!$A$6:$AV$47,42,0)) | I7: =VLOOKUP($A7,[6]HISTOMAI25!$A$6:$AV$47,41,0) -> 0 | J7: =+TONTAVRIL25!F7+TONTAVRIL25!G7 -> 0 | K7: =VLOOKUP($A7,[6]HISTOMAI25!$A$6:$AV$47,17,0) -> 0 | L7: =IF(K7<>0,VLOOKUP($A7,[6]HISTOMAI25!$A$6:$BB$47,42,0),"ECHEC") -> ECHEC | M7: =IF(P7=0,0,VLOOKUP($A7,[6]HISTOMAI25!$A$6:$AV$47,32,0)) -> 0 | N7: =VLOOKUP($A7,[6]HISTOMAI25!$A$6:$AV$47,33,0) -> 0 | O7: =IF(P7=0,0,($C$3-P7)) -> 0 | P7: =VLOOKUP($A7,[6]HISTOMAI25!$A$6:$AV$47,30,0) -> 0
A8: AS201613 | B8: =IF(D8=0,0,VLOOKUP($A8,[6]HISTOMAI25!$A$6:$BB$47,12,0)) -> 1 | C8: =VLOOKUP(A8,[7]LISTADHERENT!A$5:H$60,3,0) -> HOTCHO BENJAMIN | D8: =IF(E8="ECHEC",0,VLOOKUP($A8,[6]HISTOMAI25!$A$6:$AR$47,13,0)) -> 75000 | E8: =VLOOKUP($A8,[6]HISTOMAI25!$A$6:$AV$47,9,0) -> BANQUE | F8: =VLOOKUP($A8,[6]HISTOMAI25!$A$6:$AV$47,36,0) -> 50000 | G8: =VLOOKUP($A8,[6]HISTOMAI25!$A$6:$AV$47,39,0) -> 1000 | H8: =IF(G8=0,"",VLOOKUP($A8,[6]HISTOFEV25!$A$6:$AV$47,42,0)) -> 0 | I8: =VLOOKUP($A8,[6]HISTOMAI25!$A$6:$AV$47,41,0) -> 0 | J8: =+TONTAVRIL25!F8+TONTAVRIL25!G8 -> 51000 | K8: =VLOOKUP($A8,[6]HISTOMAI25!$A$6:$AV$47,17,0) -> 51000 | L8: =IF(K8<>0,VLOOKUP($A8,[6]HISTOMAI25!$A$6:$BB$47,42,0),"ECHEC") -> BANQUE | M8: =IF(P8=0,0,VLOOKUP($A8,[6]HISTOMAI25!$A$6:$AV$47,32,0)) -> 0 | N8: =VLOOKUP($A8,[6]HISTOMAI25!$A$6:$AV$47,33,0) -> 0 | O8: =IF(P8=0,0,($C$3-P8)) -> 0 | P8: =VLOOKUP($A8,[6]HISTOMAI25!$A$6:$AV$47,30,0) -> 0
A9: AS201619 | B9: =IF(D9=0,0,VLOOKUP($A9,[6]HISTOMAI25!$A$6:$BB$47,12,0)) -> 1 | C9: =VLOOKUP(A9,[7]LISTADHERENT!A$5:H$60,3,0) -> KOUATCHO MESSACK | D9: =IF(E9="ECHEC",0,VLOOKUP($A9,[6]HISTOMAI25!$A$6:$AR$47,13,0)) -> 75000 | E9: =VLOOKUP($A9,[6]HISTOMAI25!$A$6:$AV$47,9,0) -> BANQUE | F9: =VLOOKUP($A9,[6]HISTOMAI25!$A$6:$AV$47,36,0) -> 0 | G9: =VLOOKUP($A9,[6]HISTOMAI25!$A$6:$AV$47,39,0) -> 0 | H9: =IF(G9=0,"",VLOOKUP($A9,[6]HISTOFEV25!$A$6:$AV$47,42,0)) | I9: =VLOOKUP($A9,[6]HISTOMAI25!$A$6:$AV$47,41,0) -> 0 | J9: =+TONTAVRIL25!F9+TONTAVRIL25!G9 -> 0 | K9: =VLOOKUP($A9,[6]HISTOMAI25!$A$6:$AV$47,17,0) -> 0 | L9: =IF(K9<>0,VLOOKUP($A9,[6]HISTOMAI25!$A$6:$BB$47,42,0),"ECHEC") -> ECHEC | M9: =IF(P9=0,0,VLOOKUP($A9,[6]HISTOMAI25!$A$6:$AV$47,32,0)) -> 0 | N9: =VLOOKUP($A9,[6]HISTOMAI25!$A$6:$AV$47,33,0) -> 0 | O9: =IF(P9=0,0,($C$3-P9)) -> 0 | P9: =VLOOKUP($A9,[6]HISTOMAI25!$A$6:$AV$47,30,0) -> 0
