Workbook
Name BANQUE: #REF!
Name BANQUE: #REF!
Name BANQUE: #REF!
Name BANQUE: #REF!
Name BANQUE: #REF!
Name BANQUE: #REF!
Name BANQUE: #REF!
Name BANQUE: #REF!
Name BANQUE: #REF!
Name BANQUE: #REF!
Name BANQUE: #REF!
Name BANQUE: #REF!
Name BANQUE: #REF!
Name BANQUE: #REF!
Name BANQUE: #REF!
Name BANQUE: #REF!
Name BANQUE: #REF!
Name BANQUE: #REF!
Name BANQUE: #REF!
Name BANQUE: #REF!
Name BANQUE: #REF!
Name BANQUE: #REF!
Name BANQUE: #REF!
Name BANQUE: #REF!
Name BANQUE: #REF!
Name BANQUE: #REF!
Name BANQUE: #REF!
Name BANQUE: #REF!
Name MODEPAID: MODEPAID!$A$1:$A$3
Name MODEPAID: [1]Feuil2!$A$1:$A$3
Name MODEPAID: [1]Feuil2!$A$1:$A$3
Name MODEPAID: [1]Feuil2!$A$1:$A$3
Name MODEPAID: [1]Feuil2!$A$1:$A$3
Name MODEPAID: [1]Feuil2!$A$1:$A$3
Name MODEPAID: [1]Feuil2!$A$1:$A$3
Name MODEPAID: [1]Feuil2!$A$1:$A$3
Name MODEPAID: [1]Feuil2!$A$1:$A$3
Name MODEPAID: [1]Feuil2!$A$1:$A$3
Name MODEPAID: [1]Feuil2!$A$1:$A$3
Name MODEPAID: [1]Feuil2!$A$1:$A$3
Name MODEPAID: [1]Feuil2!$A$1:$A$3
Name MODEPAID: [1]Feuil2!$A$1:$A$3
Name MODEPAID: [1]Feuil2!$A$1:$A$3
Name MODEPAID: [1]Feuil2!$A$1:$A$3
Name MODEPAID: [1]Feuil2!$A$1:$A$3
Name MODEPAID: [1]Feuil2!$A$1:$A$3
Name MODEPAID: [1]Feuil2!$A$1:$A$3
Name MODEPAID: [1]Feuil2!$A$1:$A$3
Name MODEPAID: [1]Feuil2!$A$1:$A$3
Name MODEPAID: [1]Feuil2!$A$1:$A$3
Name MODEPAID: [1]Feuil2!$A$1:$A$3
Name MODEPAID: [1]Feuil2!$A$1:$A$3
Name MODEPAID: [1]Feuil2!$A$1:$A$3
Name MODEPAID: [1]Feuil2!$A$1:$A$3
Name MODEPAID: [1]Feuil2!$A$1:$A$3
Name MODEPAID: [1]Feuil2!$A$1:$A$3
Name MODEPAID: #REF!
Name MODET25000: [2]MODEVERSEMENT!$A$1:$A$3
Name MODEVERSEMENT: #REF!
Name MODEVERSEMENT: #REF!

Sheet MODEPAID
A1: BANQUE
A2: ESPECES
A3: ECHEC

Sheet TONTJANV25
A1: ASSOCIATION | B1: ASELBY
A2: ANNEE | B2: 2025 | C2: TONIINE | D2: NBRE PART
A3: TAUX TONTINE | B3: 100000 | C3: =B3*12 -> 1200000 | D3: =ROUNDDOWN(L27/C3,0) -> 2
C4: 45670
A5: MATRICULE | B5: NBREPART | C5: NOM ET PRENOM | D5: MONTANT TONTINE | E5: MODE VERSEMENT | F5: VENTE PETIT LOT | G5: INTERET PETIT LOT | H5: MODE VERSEMENT VENTE PETIT LOT | I5: NUMERO CHEQUE | J5: MONTANT A REMBOURSER PETIT LOT | K5: REMBOURSEMENT PETIT LOT | L5: MODE VERSEMENT REMBOURSEMENT | M5: MODE VERSEMENTLOT PRINCIPAL | N5: NUMERO CHEQUE | O5: MONTANT LOT PRINCIPAL | P5: INTERET LOT PRINCIPAL
A6: AS201648 | B6: =IF(D6=0,0,VLOOKUP($A6,[6]HISTOJANV25!$A$6:$BQ$47,14,0)) -> 1 | C6: =VLOOKUP(A6,[7]LISTADHERENT!A$5:H$60,3,0) -> ASELBY | D6: =IF(E6="ECHEC",0,VLOOKUP($A6,[6]HISTOJANV25!$A$6:$BB$47,15,0)) -> 100000 | E6: =VLOOKUP($A6,[6]HISTOJANV25!$A$6:$BB$47,9,0) -> BANQUE | F6: =VLOOKUP($A6,[6]HISTOJANV25!$A$6:$BB$47,37,0) -> 0 | G6: =VLOOKUP($A6,[6]HISTOJANV25!$A$6:$BB$47,40,0) -> 0 | H6: =IF(G6=0,"",VLOOKUP($A6,[6]HISTOFEV25!$A$6:$AV$47,42,0)) | I6: =VLOOKUP($A6,[6]HISTOJANV25!$A$6:$BB$47,41,0) -> 0 | K6: =VLOOKUP($A6,[6]HISTOJANV25!$A$6:$BB$47,18,0) -> 0 | L6: =IF(K6<>0,VLOOKUP($A6,[6]HISTOJANV25!$A$6:$BB$47,42,0),"ECHEC") -> ECHEC | M6: =IF(P6<>0,VLOOKUP($A6,[6]HISTOJANV25!$A$6:$BB$47,32,0),"ECHEC") -> ECHEC | N6: =VLOOKUP($A6,[6]HISTOJANV25!$A$6:$BB$47,33,0) -> 0 | O6: =IF(P6=0,0,($C$3-P6)) -> 0 | P6: =VLOOKUP($A6,[6]HISTOJANV25!$A$6:$BB$47,31,0) -> 0
A7: AS201604 | B7: =IF(D7=0,0,VLOOKUP($A7,[6]HISTOJANV25!$A$6:$BQ$47,14,0)) -> 2 | C7: =VLOOKUP(A7,[7]LISTADHERENT!A$5:H$60,3,0) -> DJOMO JEAN PAUL | D7: =IF(E7="ECHEC",0,VLOOKUP($A7,[6]HISTOJANV25!$A$6:$BB$47,15,0)) -> 200000 | E7: =VLOOKUP($A7,[6]HISTOJANV25!$A$6:$BB$47,9,0) -> BANQUE | F7: =VLOOKUP($A7,[6]HISTOJANV25!$A$6:$BB$47,37,0) -> 0 | G7: =VLOOKUP($A7,[6]HISTOJANV25!$A$6:$BB$47,40,0) -> 0 | H7: =IF(G7=0,"",VLOOKUP($A7,[6]HISTOFEV25!$A$6:$AV$47,42,0)) | I7: =VLOOKUP($A7,[6]HISTOJANV25!$A$6:$BB$47,41,0) -> 0 | K7: =VLOOKUP($A7,[6]HISTOJANV25!$A$6:$BB$47,18,0) -> 0 | L7: =IF(K7<>0,VLOOKUP($A7,[6]HISTOJANV25!$A$6:$BB$47,42,0),"ECHEC") -> ECHEC | M7: =IF(P7<>0,VLOOKUP($A7,[6]HISTOJANV25!$A$6:$BB$47,32,0),"ECHEC") -> ECHEC | N7: =VLOOKUP($A7,[6]HISTOJANV25!$A$6:$BB$47,33,0) -> 0 | O7: =IF(P7=0,0,($C$3-P7)) -> 0 | P7: =VLOOKUP($A7,[6]HISTOJANV25!$A$6:$BB$47,31,0) -> 0
A8: AS201605 | B8: =IF(D8=0,0,VLOOKUP($A8,[6]HISTOJANV25!$A$6:$BQ$47,14,0)) -> 1 | C8: =VLOOKUP(A8,[7]LISTADHERENT!A$5:H$60,3,0) -> DJOUKWE NANGUEN GUY BLAISE | D8: =IF(E8="ECHEC",0,VLOOKUP($A8,[6]HISTOJANV25!$A$6:$BB$47,15,0)) -> 100000 | E8: =VLOOKUP($A8,[6]HISTOJANV25!$A$6:$BB$47,9,0) -> BANQUE | F8: =VLOOKUP($A8,[6]HISTOJANV25!$A$6:$BB$47,37,0) -> 0 | G8: =VLOOKUP($A8,[6]HISTOJANV25!$A$6:$BB$47,40,0) -> 0 | H8: =IF(G8=0,"",VLOOKUP($A8,[6]HISTOFEV25!$A$6:$AV$47,42,0)) | I8: =VLOOKUP($A8,[6]HISTOJANV25!$A$6:$BB$47,41,0) -> 0 | K8: =VLOOKUP($A8,[6]HISTOJANV25!$A$6:$BB$47,18,0) -> 0 | L8: =IF(K8<>0,VLOOKUP($A8,[6]HISTOJANV25!$A$6:$BB$47,42,0),"ECHEC") -> ECHEC | M8: =IF(P8<>0,VLOOKUP($A8,[6]HISTOJANV25!$A$6:$BB$47,32,0),"ECHEC") -> ECHEC | N8: =VLOOKUP($A8,[6]HISTOJANV25!$A$6:$BB$47,33,0) -> 0 | O8: =IF(P8=0,0,($C$3-P8)) -> 0 | P8: =VLOOKUP($A8,[6]HISTOJANV25!$A$6:$BB$47,31,0) -> 0
A9: AS201608 | B9: =IF(D9=0,0,VLOOKUP($A9,[6]HISTOJANV25!$A$6:$BQ$47,14,0)) -> 2 | C9: =VLOOKUP(A9,[7]LISTADHERENT!A$5:H$60,3,0) -> DJUOMBESSY ANTOINE | D9: =IF(E9="ECHEC",0,VLOOKUP($A9,[6]HISTOJANV25!$A$6:$BB$47,15,0)) -> 200000 | E9: =VLOOKUP($A9,[6]HISTOJANV25!$A$6:$BB$47,9,0) -> BANQUE | F9: =VLOOKUP($A9,[6]HISTOJANV25!$A$6:$BB$47,37,0) -> 0 | G9: =VLOOKUP($A9,[6]HISTOJANV25!$A$6:$BB$47,40,0) -> 0 | H9: =IF(G9=0,"",VLOOKUP($A9,[6]HISTOFEV25!$A$6:$AV$47,42,0)) | I9: =VLOOKUP($A9,[6]HISTOJANV25!$A$6:$BB$47,41,0) -> 0 | K9: =VLOOKUP($A9,[6]HISTOJANV25!$A$6:$BB$47,18,0) -> 0 | L9: =IF(K9<>0,VLOOKUP($A9,[6]HISTOJANV25!$A$6:$BB$47,42,0),"ECHEC") -> ECHEC | M9: =IF(P9<>0,VLOOKUP($A9,[6]HISTOJANV25!$A$6:$BB$47,32,0),"ECHEC") -> ECHEC | N9: =VLOOKUP($A9,[6]HISTOJANV25!$A$6:$BB$47,33,0) -> 0 | O9: =IF(P9=0,0,($C$3-P9)) -> 0 | P9: =VLOOKUP($A9,[6]HISTOJANV25!$A$6:$BB$47,31,0) -> 0
A10: AS201663 | B10: =IF(D10=0,0,VLOOKUP($A10,[6]HISTOJANV25!$A$6:$BQ$47,14,0)) -> 0 | C10: =VLOOKUP(A10,[7]LISTADHERENT!A$5:H$60,3,0) -> FAMPOU PAUL | D10: =IF(E10="ECHEC",0,VLOOKUP($A10,[6]HISTOJANV25!$A$6:$BB$47,15,0)) -> 0 | E10: =VLOOKUP($A10,[6]HISTOJANV25!$A$6:$BB$47,9,0) -> ECHEC | F10: =VLOOKUP($A10,[6]HISTOJANV25!$A$6:$BB$47,37,0) -> 0 | G10: =VLOOKUP($A10,[6]HISTOJANV25!$A$6:$BB$47,40,0) -> 0 | H10: =IF(G10=0,"",VLOOKUP($A10,[6]HISTOFEV25!$A$6:$AV$47,42,0)) | I10: =VLOOKUP($A10,[6]HISTOJANV25!$A$6:$BB$47,41,0) -> 0 | K10: =VLOOKUP($A10,[6]HISTOJANV25!$A$6:$BB$47,18,0) -> 0 | L10: =IF(K10<>0,VLOOKUP($A10,[6]HISTOJANV25!$A$6:$BB$47,42,0),"ECHEC") -> ECHEC | M10: =IF(P10<>0,VLOOKUP($A10,[6]HISTOJANV25!$A$6:$BB$47,32,0),"ECHEC") -> ECHEC | N10: =VLOOKUP($A10,[6]HISTOJANV25!$A$6:$BB$47,33,0) -> 0 | O10: =IF(P10=0,0,($C$3-P10)) -> 0 | P10: =VLOOKUP($A10,[6]HISTOJANV25!$A$6:$BB$47,31,0) -> 0
A11: AS201613 | B11: =IF(D11=0,0,VLOOKUP($A11,[6]HISTOJANV25!$A$6:$BQ$47,14,0)) -> 1 | C11: =VLOOKUP(A11,[7]LISTADHERENT!A$5:H$60,3,0) -> HOTCHO BENJAMIN | D11: =IF(E11="ECHEC",0,VLOOKUP($A11,[6]HISTOJANV25!$A$6:$BB$47,15,0)) -> 100000 | E11: =VLOOKUP($A11,[6]HISTOJANV25!$A$6:$BB$47,9,0) -> BANQUE | F11: =VLOOKUP($A11,[6]HISTOJANV25!$A$6:$BB$47,37,0) -> 0 | G11: =VLOOKUP($A11,[6]HISTOJANV25!$A$6:$BB$47,40,0) -> 0 | H11: =IF(G11=0,"",VLOOKUP($A11,[6]HISTOFEV25!$A$6:$AV$47,42,0)) | I11: =VLOOKUP($A11,[6]HISTOJANV25!$A$6:$BB$47,41,0) -> 0 | K11: =VLOOKUP($A11,[6]HISTOJANV25!$A$6:$BB$47,18,0) -> 0 | L11: =IF(K11<>0,VLOOKUP($A11,[6]HISTOJANV25!$A$6:$BB$47,42,0),"ECHEC") -> ECHEC | M11: =IF(P11<>0,VLOOKUP($A11,[6]HISTOJANV25!$A$6:$BB$47,32,0),"ECHEC") -> ECHEC | N11: =VLOOKUP($A11,[6]HISTOJANV25!$A$6:$BB$47,33,0) -> 0 | O11: =IF(P11=0,0,($C$3-P11)) -> 0 | P11: =VLOOKUP($A11,[6]HISTOJANV25!$A$6:$BB$47,31,0) -> 0
A12: AS201617 | B12: =IF(D12=0,0,VLOOKUP($A12,[6]HISTOJANV25!$A$6:$BQ$47,14,0)) -> 1 | C12: =VLOOKUP(A12,[7]LISTADHERENT!A$5:H$60,3,0) -> KOUAMOU MOISE | D12: =IF(E12="ECHEC",0,VLOOKUP($A12,[6]HISTOJANV25!$A$6:$BB$47,15,0)) -> 100000 | E12: =VLOOKUP($A12,[6]HISTOJANV25!$A$6:$BB$47,9,0) -> BANQUE | F12: =VLOOKUP($A12,[6]HISTOJANV25!$A$6:$BB$47,37,0) -> 0 | G12: =VLOOKUP($A12,[6]HISTOJANV25!$A$6:$BB$47,40,0) -> 0 | H12: =IF(G12=0,"",VLOOKUP($A12,[6]HISTOFEV25!$A$6:$AV$47,42,0)) | I12: =VLOOKUP($A12,[6]HISTOJANV25!$A$6:$BB$47,41,0) -> 0 | K12: =VLOOKUP($A12,[6]HISTOJANV25!$A$6:$BB$47,18,0) -> 0 | L12: =IF(K12<>0,VLOOKUP($A12,[6]HISTOJANV25!$A$6:$BB$47,42,0),"ECHEC") -> ECHEC | M12: =IF(P12<>0,VLOOKUP($A12,[6]HISTOJANV25!$A$6:$BB$47,32,0),"ECHEC") -> BANQUE | N12: =VLOOKUP($A12,[6]HISTOJANV25!$A$6:$BB$47,33,0) -> 0 | O12: =IF(P12=0,0,($C$3-P12)) -> 1085000 | P12: =VLOOKUP($A12,[6]HISTOJANV25!$A$6:$BB$47,31,0) -> 115000
A13: AS201619 | B13: =IF(D13=0,0,VLOOKUP($A13,[6]HISTOJANV25!$A$6:$BQ$47,14,0)) -> 1 | C13: =VLOOKUP(A13,[7]LISTADHERENT!A$5:H$60,3,0) -> KOUATCHO MESSACK | D13: =IF(E13="ECHEC",0,VLOOKUP($A13,[6]HISTOJANV25!$A$6:$BB$47,15,0)) -> 100000 | E13: =VLOOKUP($A13,[6]HISTOJANV25!$A$6:$BB$47,9,0) -> BANQUE | F13: =VLOOKUP($A13,[6]HISTOJANV25!$A$6:$BB$47,37,0) -> 0 | G13: =VLOOKUP($A13,[6]HISTOJANV25!$A$6:$BB$47,40,0) -> 0 | H13: =IF(G13=0,"",VLOOKUP($A13,[6]HISTOFEV25!$A$6:$AV$47,42,0)) | I13: =VLOOKUP($A13,[6]HISTOJANV25!$A$6:$BB$47,41,0) -> 0 | K13: =VLOOKUP($A13,[6]HISTOJANV25!$A$6:$BB$47,18,0) -> 0 | L13: =IF(K13<>0,VLOOKUP($A13,[6]HISTOJANV25!$A$6:$BB$47,42,0),"ECHEC") -> ECHEC | M13: =IF(P13<>0,VLOOKUP($A13,[6]HISTOJANV25!$A$6:$BB$47,32,0),"ECHEC") -> BANQUE | N13: =VLOOKUP($A13,[6]HISTOJANV25!$A$6:$BB$47,33,0) -> 0 | O13: =IF(P13=0,0,($C$3-P13)) -> 1095000 | P13: =VLOOKUP($A13,[6]HISTOJANV25!$A$6:$BB$47,31,0) -> 105000
A14: AS201649 | B14: =IF(D14=0,0,VLOOKUP($A14,[6]HISTOJANV25!$A$6:$BQ$47,14,0)) -> 2 | C14: =VLOOKUP(A14,[7]LISTADHERENT!A$5:H$60,3,0) -> MBOGNING TUGMA GUY | D14: =IF(E14="ECHEC",0,VLOOKUP($A14,[6]HISTOJANV25!$A$6:$BB$47,15,0)) -> 200000 | E14: =VLOOKUP($A14,[6]HISTOJANV25!$A$6:$BB$47,9,0) -> BANQUE | F14: =VLOOKUP($A14,[6]HISTOJANV25!$A$6:$BB$47,37,0) -> 0 | G14: =VLOOKUP($A14,[6]HISTOJANV25!$A$6:$BB$47,40,0) -> 0 | H14: =IF(G14=0,"",VLOOKUP($A14,[6]HISTOFEV25!$A$6:$AV$47,42,0)) | I14: =VLOOKUP($A14,[6]HISTOJANV25!$A$6:$BB$47,41,0) -> 0 | K14: =VLOOKUP($A14,[6]HISTOJANV25!$A$6:$BB$47,18,0) -> 0 | L14: =IF(K14<>0,VLOOKUP($A14,[6]HISTOJANV25!$A$6:$BB$47,42,0),"ECHEC") -> ECHEC | M14: =IF(P14<>0,VLOOKUP($A14,[6]HISTOJANV25!$A$6:$BB$47,32,0),"ECHEC") -> ECHEC | N14: =VLOOKUP($A14,[6]HISTOJANV25!$A$6:$BB$47,33,0) -> 0 | O14: =IF(P14=0,0,($C$3-P14)) -> 0 | P14: =VLOOKUP($A14,[6]HISTOJANV25!$A$6:$BB$47,31,0) -> 0
A15: AS201622 | B15: =IF(D15=0,0,VLOOKUP($A15,[6]HISTOJANV25!$A$6:$BQ$47,14,0)) -> 2 | C15: =VLOOKUP(A15,[7]LISTADHERENT!A$5:H$60,3,0) -> NDJOMO ETIENNE | D15: =IF(E15="ECHEC",0,VLOOKUP($A15,[6]HISTOJANV25!$A$6:$BB$47,15,0)) -> 200000 | E15: =VLOOKUP($A15,[6]HISTOJANV25!$A$6:$BB$47,9,0) -> BANQUE | F15: =VLOOKUP($A15,[6]HISTOJANV25!$A$6:$BB$47,37,0) -> 0 | G15: =VLOOKUP($A15,[6]HISTOJANV25!$A$6:$BB$47,40,0) -> 0 | H15: =IF(G15=0,"",VLOOKUP($A15,[6]HISTOFEV25!$A$6:$AV$47,42,0)) | I15: =VLOOKUP($A15,[6]HISTOJANV25!$A$6:$BB$47,41,0) -> 0 | K15: =VLOOKUP($A15,[6]HISTOJANV25!$A$6:$BB$47,18,0) -> 0 | L15: =IF(K15<>0,VLOOKUP($A15,[6]HISTOJANV25!$A$6:$BB$47,42,0),"ECHEC") -> ECHEC | M15: =IF(P15<>0,VLOOKUP($A15,[6]HISTOJANV25!$A$6:$BB$47,32,0),"ECHEC") -> ECHEC | N15: =VLOOKUP($A15,[6]HISTOJANV25!$A$6:$BB$47,33,0) -> 0 | O15: =IF(P15=0,0,($C$3-P15)) -> 0 | P15: =VLOOKUP($A15,[6]HISTOJANV25!$A$6:$BB$47,31,0) -> 0
A16: AS201624 | B16: =IF(D16=0,0,VLOOKUP($A16,[6]HISTOJANV25!$A$6:$BQ$47,14,0)) -> 1 | C16: =VLOOKUP(A16,[7]LISTADHERENT!A$5:H$60,3,0) -> NGONDIEP CLAUDE | D16: =IF(E16="ECHEC",0,VLOOKUP($A16,[6]HISTOJANV25!$A$6:$BB$47,15,0)) -> 100000 | E16: =VLOOKUP($A16,[6]HISTOJANV25!$A$6:$BB$47,9,0) -> BANQUE | F16: =VLOOKUP($A16,[6]HISTOJANV25!$A$6:$BB$47,37,0) -> 0 | G16: =VLOOKUP($A16,[6]HISTOJANV25!$A$6:$BB$47,40,0) -> 0 | H16: =IF(G16=0,"",VLOOKUP($A16,[6]HISTOFEV25!$A$6:$AV$47,42,0)) | I16: =VLOOKUP($A16,[6]HISTOJANV25!$A$6:$BB$47,41,0) -> 0 | K16: =VLOOKUP($A16,[6]HISTOJANV25!$A$6:$BB$47,18,0) -> 0 | L16: =IF(K16<>0,VLOOKUP($A16,[6]HISTOJANV25!$A$6:$BB$47,42,0),"ECHEC") -> ECHEC | M16: =IF(P16<>0,VLOOKUP($A16,[6]HISTOJANV25!$A$6:$BB$47,32,0),"ECHEC") -> ECHEC | N16: =VLOOKUP($A16,[6]HISTOJANV25!$A$6:$BB$47,33,0) -> 0 | O16: =IF(P16=0,0,($C$3-P16)) -> 0 | P16: =VLOOKUP($A16,[6]HISTOJANV25!$A$6:$BB$47,31,0) -> 0
A17: AS201626 | B17: =IF(D17=0,0,VLOOKUP($A17,[6]HISTOJANV25!$A$6:$BQ$47,14,0)) -> 2 | C17: =VLOOKUP(A17,[7]LISTADHERENT!A$5:H$60,3,0) -> NGUIEMEGNI MATHIEU BLAISE | D17: =IF(E17="ECHEC",0,VLOOKUP($A17,[6]HISTOJANV25!$A$6:$BB$47,15,0)) -> 200000 | E17: =VLOOKUP($A17,[6]HISTOJANV25!$A$6:$BB$47,9,0) -> BANQUE | F17: =VLOOKUP($A17,[6]HISTOJANV25!$A$6:$BB$47,37,0) -> 0 | G17: =VLOOKUP($A17,[6]HISTOJANV25!$A$6:$BB$47,40,0) -> 0 | H17: =IF(G17=0,"",VLOOKUP($A17,[6]HISTOFEV25!$A$6:$AV$47,42,0)) | I17: =VLOOKUP($A17,[6]HISTOJANV25!$A$6:$BB$47,41,0) -> 0 | K17: =VLOOKUP($A17,[6]HISTOJANV25!$A$6:$BB$47,18,0) -> 0 | L17: =IF(K17<>0,VLOOKUP($A17,[6]HISTOJANV25!$A$6:$BB$47,42,0),"ECHEC") -> ECHEC | M17: =IF(P17<>0,VLOOKUP($A17,[6]HISTOJANV25!$A$6:$BB$47,32,0),"ECHEC") -> BANQUE | N17: =VLOOKUP($A17,[6]HISTOJANV25!$A$6:$BB$47,33,0) -> 0 | O17: =IF(P17=0,0,($C$3-P17)) -> 1080000 | P17: =VLOOKUP($A17,[6]HISTOJANV25!$A$6:$BB$47,31,0) -> 120000
... A22: AS201647 | B22: =IF(D22=0,0,VLOOKUP($A22,[6]HISTOJANV25!$A$6:$BQ$47,14,0)) -> 1 | C22: =VLOOKUP(A22,[7]LISTADHERENT!A$5:H$60,3,0) -> YOUMBI EMMANUEL | D22: =IF(E22="ECHEC",0,VLOOKUP($A22,[6]HISTOJANV25!$A$6:$BB$47,15,0)) -> 100000 | E22: =VLOOKUP($A22,[6]HISTOJANV25!$A$6:$BB$47,9,0) -> BANQUE | F22: =VLOOKUP($A22,[6]HISTOJANV25!$A$6:$BB$47,37,0) -> 0 | G22: =VLOOKUP($A22,[6]HISTOJANV25!$A$6:$BB$47,40,0) -> 0 | H22: =IF(G22=0,"",VLOOKUP($A22,[6]HISTOFEV25!$A$6:$AV$47,42,0)) | I22: =VLOOKUP($A22,[6]HISTOJANV25!$A$6:$BB$47,41,0) -> 0 | K22: =VLOOKUP($A22,[6]HISTOJANV25!$A$6:$BB$47,18,0) -> 0 | L22: =IF(K22<>0,VLOOKUP($A22,[6]HISTOJANV25!$A$6:$BB$47,42,0),"ECHEC") -> ECHEC | M22: =IF(P22<>0,VLOOKUP($A22,[6]HISTOJANV25!$A$6:$BB$47,32,0),"ECHEC") -> ECHEC | N22: =VLOOKUP($A22,[6]HISTOJANV25!$A$6:$BB$47,33,0) -> 0 | O22: =IF(P22=0,0,($C$3-P22)) -> 0 | P22: =VLOOKUP($A22,[6]HISTOJANV25!$A$6:$BB$47,31,0) -> 0
A24: TOTAL PART | B24: =SUM(B6:B22) -> 23
A25: NBRE ADHERENT | B25: =+COUNT(D6:D22) -> 17 | D25: =SUM(D6:D22) -> 2300000 | E25: =SUM(E6:E22) -> 0 | F25: =SUM(F6:F22) -> 0 | G25: =SUM(G6:G22) -> 0 | H25: =SUM(H6:H22) -> 0 | I25: =SUM(I6:I22) -> 0 | J25: =SUM(J6:J22) -> 0 | K25: =SUM(K6:K22) -> 0 | ... P25: =SUM(P6:P22) -> 340000
M26: NBRE PART | N26: PART VENDUE
D27: MONTANT TONTINE | E27: REMBOURSEMENT PETIT LOT | F27: VENTE PETIT LOT | G27: VENTE LOT PRINCIPAL | H27: SOLDE EN CAISSE | K27: TONTINE + REMB + INTERET VENTE | L27: =D31+E31+P25 -> 2640000
C28: ESPECES | D28: =SUMIFS(D6:D22,E6:E22,"ESPECES") -> 0 | E28: =SUMIFS(K6:K22,L6:L22,"ESPECES") -> 0 | F28: =SUMIFS(F6:F22,H6:H22,"ESPECES") -> 0 | G28: =SUMIFS(O6:O22,M6:M22,"ESPECES") -> 0 | H28: =D28+E28-F28-G28 -> 0 | K28: LOT PRINCIPAL | L28: =C3*COUNTIF(O6:O22,">0") -> 3600000 | M28: =D3 -> 2 | N28: =COUNTIF(O9:O21,">0") -> 3
C29: BANQUE | D29: =SUMIFS(D6:D22,E6:E22,"BANQUE") -> 2300000 | E29: =SUMIFS(K6:K22,L6:L22,"BANQUE") -> 0 | F29: =SUMIFS(F6:F22,H6:H22,"BANQUE") -> 0 | G29: =SUMIFS(O6:O22,M6:M22,"BANQUE") -> 3260000 | H29: =D29+E29-F29-G29 -> -960000
K30: PETIT LOT | L30: =L27-L28 -> -960000
C31: TOTAL | D31: =D28+D29 -> 2300000 | E31: =E28+E29 -> 0 | F31: =F28+F29 -> 0 | G31: =G28+G29 -> 3260000 | H31: =H28+H29 -> -960000
K32: RELIQUAT | L32: =L30-F25 -> -960000 | N32: =L32 -> -960000 | O32: CUMUL
K34: ECHEC TONTINE MOIS | L34: =COUNTIFS(E6:E29,"ECHEC")*100000 -> 100000 | O34: CUMUL
K35: ECHEC REMBOURSEMENT MOIS | L35: =J25-E31 -> 0 | N35: =L35 -> 0 | O35: CUMUL

Sheet TONTFEV25
A1: ASSOCIATION | B1: ASELBY
A2: ANNEE | B2: 2025 | C2: TONIINE | D2: NBRE PART
A3: TAUX TONTINE | B3: 100000 | C3: =B3*12 -> 1200000 | D3: =ROUNDDOWN(L27/C3,0) -> 1
C4: 45701
A5: MATRICULE | B5: NBREPART | C5: NOM ET PRENOM | D5: MONTANT TONTINE | E5: MODE VERSEMENT | F5: VENTE PETIT LOT | G5: INTERET PETIT LOT | H5: MODE VERSEMENT VENTE PETIT LOT | I5: NUMERO CHEQUE | J5: MONTANT A REMBOURSER PETIT LOT | K5: REMBOURSEMENT PETIT LOT | L5: MODE VERSEMENT REMBOURSEMENT | M5: MODE VERSEMENTLOT PRINCIPAL | N5: NUMERO CHEQUE | O5: MONTANT LOT PRINCIPAL | P5: INTERET LOT PRINCIPAL
A6: AS201648 | B6: =IF(D6=0,0,VLOOKUP($A6,[6]HISTOFEV25!$A$6:$BQ$47,14,0)) -> 1 | C6: =VLOOKUP(A6,[7]LISTADHERENT!A$5:H$60,3,0) -> ASELBY | D6: =IF(E6="ECHEC",0,VLOOKUP($A6,[6]HISTOFEV25!$A$6:$BB$47,15,0)) -> 100000 | E6: =VLOOKUP($A6,[6]HISTOFEV25!$A$6:$BB$47,9,0) -> BANQUE | F6: =VLOOKUP($A6,[6]HISTOFEV25!$A$6:$BB$47,37,0) -> 0 | G6: =VLOOKUP($A6,[6]HISTOFEV25!$A$6:$BB$47,40,0) -> 0 | H6: =IF(G6=0,"",VLOOKUP($A6,[6]HISTOFEV25!$A$6:$AV$47,42,0)) | I6: =VLOOKUP($A6,[6]HISTOFEV25!$A$6:$BB$47,41,0) -> 0 | J6: =TONTJANV25!F6+TONTJANV25!G6 -> 0 | K6: =VLOOKUP($A6,[6]HISTOFEV25!$A$6:$BB$47,18,0) -> 0 | L6: =IF(K6<>0,VLOOKUP($A6,[6]HISTOFEV25!$A$6:$BB$47,42,0),"ECHEC") -> ECHEC | M6: =IF(P6<>0,VLOOKUP($A6,[6]HISTOFEV25!$A$6:$BB$47,32,0),"ECHEC") -> ECHEC | N6: =VLOOKUP($A6,[6]HISTOFEV25!$A$6:$BB$47,33,0) -> 0 | O6: =IF(P6=0,0,($C$3-P6)) -> 0 | P6: =VLOOKUP($A6,[6]HISTOFEV25!$A$6:$BB$47,31,0) -> 0
A7: AS201604 | B7: =IF(D7=0,0,VLOOKUP($A7,[6]HISTOFEV25!$A$6:$BQ$47,14,0)) -> 2 | C7: =VLOOKUP(A7,[7]LISTADHERENT!A$5:H$60,3,0) -> DJOMO JEAN PAUL | D7: =IF(E7="ECHEC",0,VLOOKUP($A7,[6]HISTOFEV25!$A$6:$BB$47,15,0)) -> 200000 | E7: =VLOOKUP($A7,[6]HISTOFEV25!$A$6:$BB$47,9,0) -> BANQUE | F7: =VLOOKUP($A7,[6]HISTOFEV25!$A$6:$BB$47,37,0) -> 200000 | G7: =VLOOKUP($A7,[6]HISTOFEV25!$A$6:$BB$47,40,0) -> 7500 | H7: =IF(G7=0,"",VLOOKUP($A7,[6]HISTOFEV25!$A$6:$AV$47,42,0)) -> BANQUE | I7: =VLOOKUP($A7,[6]HISTOFEV25!$A$6:$BB$47,41,0) -> 0 | J7: =TONTJANV25!F7+TONTJANV25!G7 -> 0 | K7: =VLOOKUP($A7,[6]HISTOFEV25!$A$6:$BB$47,18,0) -> 0 | L7: =IF(K7<>0,VLOOKUP($A7,[6]HISTOFEV25!$A$6:$BB$47,42,0),"ECHEC") -> ECHEC | M7: =IF(P7<>0,VLOOKUP($A7,[6]HISTOFEV25!$A$6:$BB$47,32,0),"ECHEC") -> BANQUE | N7: =VLOOKUP($A7,[6]HISTOFEV25!$A$6:$BB$47,33,0) -> 0 | O7: =IF(P7=0,0,($C$3-P7)) -> 1120000 | P7: =VLOOKUP($A7,[6]HISTOFEV25!$A$6:$BB$47,31,0) -> 80000
A8: AS201605 | B8: =IF(D8=0,0,VLOOKUP($A8,[6]HISTOFEV25!$A$6:$BQ$47,14,0)) -> 1 | C8: =VLOOKUP(A8,[7]LISTADHERENT!A$5:H$60,3,0) -> DJOUKWE NANGUEN GUY BLAISE | D8: =IF(E8="ECHEC",0,VLOOKUP($A8,[6]HISTOFEV25!$A$6:$BB$47,15,0)) -> 100000 | E8: =VLOOKUP($A8,[6]HISTOFEV25!$A$6:$BB$47,9,0) -> BANQUE | F8: =VLOOKUP($A8,[6]HISTOFEV25!$A$6:$BB$47,37,0) -> 200000 | G8: =VLOOKUP($A8,[6]HISTOFEV25!$A$6:$BB$47,40,0) -> 4500 | H8: =IF(G8=0,"",VLOOKUP($A8,[6]HISTOFEV25!$A$6:$AV$47,42,0)) -> BANQUE | I8: =VLOOKUP($A8,[6]HISTOFEV25!$A$6:$BB$47,41,0) -> 0 | J8: =TONTJANV25!F8+TONTJANV25!G8 -> 0 | K8: =VLOOKUP($A8,[6]HISTOFEV25!$A$6:$BB$47,18,0) -> 0 | L8: =IF(K8<>0,VLOOKUP($A8,[6]HISTOFEV25!$A$6:$BB$47,42,0),"ECHEC") -> ECHEC | M8: =IF(P8<>0,VLOOKUP($A8,[6]HISTOFEV25!$A$6:$BB$47,32,0),"ECHEC") -> ECHEC | N8: =VLOOKUP($A8,[6]HISTOFEV25!$A$6:$BB$47,33,0) -> 0 | O8: =IF(P8=0,0,($C$3-P8)) -> 0 | P8: =VLOOKUP($A8,[6]HISTOFEV25!$A$6:$BB$47,31,0) -> 0
A9: AS201608 | B9: =IF(D9=0,0,VLOOKUP($A9,[6]HISTOFEV25!$A$6:$BQ$47,14,0)) -> 2 | C9: =VLOOKUP(A9,[7]LISTADHERENT!A$5:H$60,3,0) -> DJUOMBESSY ANTOINE | D9: =IF(E9="ECHEC",0,VLOOKUP($A9,[6]HISTOFEV25!$A$6:$BB$47,15,0)) -> 200000 | E9: =VLOOKUP($A9,[6]HISTOFEV25!$A$6:$BB$47,9,0) -> BANQUE | F9: =VLOOKUP($A9,[6]HISTOFEV25!$A$6:$BB$47,37,0) -> 0 | G9: =VLOOKUP($A9,[6]HISTOFEV25!$A$6:$BB$47,40,0) -> 0 | H9: =IF(G9=0,"",VLOOKUP($A9,[6]HISTOFEV25!$A$6:$AV$47,42,0)) | I9: =VLOOKUP($A9,[6]HISTOFEV25!$A$6:$BB$47,41,0) -> 0 | J9: =TONTJANV25!F9+TONTJANV25!G9 -> 0 | K9: =VLOOKUP($A9,[6]HISTOFEV25!$A$6:$BB$47,18,0) -> 0 | L9: =IF(K9<>0,VLOOKUP($A9,[6]HISTOFEV25!$A$6:$BB$47,42,0),"ECHEC") -> ECHEC | M9: =IF(P9<>0,VLOOKUP($A9,[6]HISTOFEV25!$A$6:$BB$47,32,0),"ECHEC") -> ECHEC | N9: =VLOOKUP($A9,[6]HISTOFEV25!$A$6:$BB$47,33,0) -> 0 | O9: =IF(P9=0,0,($C$3-P9)) -> 0 | P9: =VLOOKUP($A9,[6]HISTOFEV25!$A$6:$BB$47,31,0) -> 0
A10: AS201663 | B10: =IF(D10=0,0,VLOOKUP($A10,[6]HISTOFEV25!$A$6:$BQ$47,14,0)) -> 1 | C10: =VLOOKUP(A10,[7]LISTADHERENT!A$5:H$60,3,0) -> FAMPOU PAUL | D10: =IF(E10="ECHEC",0,VLOOKUP($A10,[6]HISTOFEV25!$A$6:$BB$47,15,0)) -> 100000 | E10: =VLOOKUP($A10,[6]HISTOFEV25!$A$6:$BB$47,9,0) -> ESPECES | F10: =VLOOKUP($A10,[6]HISTOFEV25!$A$6:$BB$47,37,0) -> 0 | G10: =VLOOKUP($A10,[6]HISTOFEV25!$A$6:$BB$47,40,0) -> 0 | H10: =IF(G10=0,"",VLOOKUP($A10,[6]HISTOFEV25!$A$6:$AV$47,42,0)) | I10: =VLOOKUP($A10,[6]HISTOFEV25!$A$6:$BB$47,41,0) -> 0 | J10: =TONTJANV25!F10+TONTJANV25!G10 -> 0 | K10: =VLOOKUP($A10,[6]HISTOFEV25!$A$6:$BB$47,18,0) -> 0 | L10: =IF(K10<>0,VLOOKUP($A10,[6]HISTOFEV25!$A$6:$BB$47,42,0),"ECHEC") -> ECHEC | M10: =IF(P10<>0,VLOOKUP($A10,[6]HISTOFEV25!$A$6:$BB$47,32,0),"ECHEC") -> ECHEC | N10: =VLOOKUP($A10,[6]HISTOFEV25!$A$6:$BB$47,33,0) -> 0 | O10: =IF(P10=0,0,($C$3-P10)) -> 0 | P10: =VLOOKUP($A10,[6]HISTOFEV25!$A$6:$BB$47,31,0) -> 0
A11: AS201613 | B11: =IF(D11=0,0,VLOOKUP($A11,[6]HISTOFEV25!$A$6:$BQ$47,14,0)) -> 1 | C11: =VLOOKUP(A11,[7]LISTADHERENT!A$5:H$60,3,0) -> HOTCHO BENJAMIN | D11: =IF(E11="ECHEC",0,VLOOKUP($A11,[6]HISTOFEV25!$A$6:$BB$47,15,0)) -> 100000 | E11: =VLOOKUP($A11,[6]HISTOFEV25!$A$6:$BB$47,9,0) -> BANQUE | F11: =VLOOKUP($A11,[6]HISTOFEV25!$A$6:$BB$47,37,0) -> 0 | G11: =VLOOKUP($A11,[6]HISTOFEV25!$A$6:$BB$47,40,0) -> 0 | H11: =IF(G11=0,"",VLOOKUP($A11,[6]HISTOFEV25!$A$6:$AV$47,42,0)) | I11: =VLOOKUP($A11,[6]HISTOFEV25!$A$6:$BB$47,41,0) -> 0 | J11: =TONTJANV25!F11+TONTJANV25!G11 -> 0 | K11: =VLOOKUP($A11,[6]HISTOFEV25!$A$6:$BB$47,18,0) -> 0 | L11: =IF(K11<>0,VLOOKUP($A11,[6]HISTOFEV25!$A$6:$BB$47,42,0),"ECHEC") -> ECHEC | M11: =IF(P11<>0,VLOOKUP($A11,[6]HISTOFEV25!$A$6:$BB$47,32,0),"ECHEC") -> ECHEC | N11: =VLOOKUP($A11,[6]HISTOFEV25!$A$6:$BB$47,33,0) -> 0 | O11: =IF(P11=0,0,($C$3-P11)) -> 0 | P11: =VLOOKUP($A11,[6]HISTOFEV25!$A$6:$BB$47,31,0) -> 0
A12: AS201617 | B12: =IF(D12=0,0,VLOOKUP($A12,[6]HISTOFEV25!$A$6:$BQ$47,14,0)) -> 1 | C12: =VLOOKUP(A12,[7]LISTADHERENT!A$5:H$60,3,0) -> KOUAMOU MOISE | D12: =IF(E12="ECHEC",0,VLOOKUP($A12,[6]HISTOFEV25!$A$6:$BB$47,15,0)) -> 100000 | E12: =VLOOKUP($A12,[6]HISTOFEV25!$A$6:$BB$47,9,0) -> BANQUE | F12: =VLOOKUP($A12,[6]HISTOFEV25!$A$6:$BB$47,37,0) -> 0 | G12: =VLOOKUP($A12,[6]HISTOFEV25!$A$6:$BB$47,40,0) -> 0 | H12: =IF(G12=0,"",VLOOKUP($A12,[6]HISTOFEV25!$A$6:$AV$47,42,0)) | I12: =VLOOKUP($A12,[6]HISTOFEV25!$A$6:$BB$47,41,0) -> 0 | J12: =TONTJANV25!F12+TONTJANV25!G12 -> 0 | K12: =VLOOKUP($A12,[6]HISTOFEV25!$A$6:$BB$47,18,0) -> 0 | L12: =IF(K12<>0,VLOOKUP($A12,[6]HISTOFEV25!$A$6:$BB$47,42,0),"ECHEC") -> ECHEC | M12: =IF(P12<>0,VLOOKUP($A12,[6]HISTOFEV25!$A$6:$BB$47,32,0),"ECHEC") -> ECHEC | N12: =VLOOKUP($A12,[6]HISTOFEV25!$A$6:$BB$47,33,0) -> 0 | O12: =IF(P12=0,0,($C$3-P12)) -> 0 | P12: =VLOOKUP($A12,[6]HISTOFEV25!$A$6:$BB$47,31,0) -> 0
A13: AS201619 | B13: =IF(D13=0,0,VLOOKUP($A13,[6]HISTOFEV25!$A$6:$BQ$47,14,0)) -> 1 | C13: =VLOOKUP(A13,[7]LISTADHERENT!A$5:H$60,3,0) -> KOUATCHO MESSACK | D13: =IF(E13="ECHEC",0,VLOOKUP($A13,[6]HISTOFEV25!$A$6:$BB$47,15,0)) -> 100000 | E13: =VLOOKUP($A13,[6]HISTOFEV25!$A$6:$BB$47,9,0) -> BANQUE | F13: =VLOOKUP($A13,[6]HISTOFEV25!$A$6:$BB$47,37,0) -> 0 | G13: =VLOOKUP($A13,[6]HISTOFEV25!$A$6:$BB$47,40,0) -> 0 | H13: =IF(G13=0,"",VLOOKUP($A13,[6]HISTOFEV25!$A$6:$AV$47,42,0)) | I13: =VLOOKUP($A13,[6]HISTOFEV25!$A$6:$BB$47,41,0) -> 0 | J13: =TONTJANV25!F13+TONTJANV25!G13 -> 0 | K13: =VLOOKUP($A13,[6]HISTOFEV25!$A$6:$BB$47,18,0) -> 0 | L13: =IF(K13<>0,VLOOKUP($A13,[6]HISTOFEV25!$A$6:$BB$47,42,0),"ECHEC") -> ECHEC | M13: =IF(P13<>0,VLOOKUP($A13,[6]HISTOFEV25!$A$6:$BB$47,32,0),"ECHEC") -> ECHEC | N13: =VLOOKUP($A13,[6]HISTOFEV25!$A$6:$BB$47,33,0) -> 0 | O13: =IF(P13=0,0,($C$3-P13)) -> 0 | P13: =VLOOKUP($A13,[6]HISTOFEV25!$A$6:$BB$47,31,0) -> 0
A14: AS201649 | B14: =IF(D14=0,0,VLOOKUP($A14,[6]HISTOFEV25!$A$6:$BQ$47,14,0)) -> 2 | C14: =VLOOKUP(A14,[7]LISTADHERENT!A$5:H$60,3,0) -> MBOGNING TUGMA GUY | D14: =IF(E14="ECHEC",0,VLOOKUP($A14,[6]HISTOFEV25!$A$6:$BB$47,15,0)) -> 200000 | E14: =VLOOKUP($A14,[6]HISTOFEV25!$A$6:$BB$47,9,0) -> BANQUE | F14: =VLOOKUP($A14,[6]HISTOFEV25!$A$6:$BB$47,37,0) -> 0 | G14: =VLOOKUP($A14,[6]HISTOFEV25!$A$6:$BB$47,40,0) -> 0 | H14: =IF(G14=0,"",VLOOKUP($A14,[6]HISTOFEV25!$A$6:$AV$47,42,0)) | I14: =VLOOKUP($A14,[6]HISTOFEV25!$A$6:$BB$47,41,0) -> 0 | J14: =TONTJANV25!F14+TONTJANV25!G14 -> 0 | K14: =VLOOKUP($A14,[6]HISTOFEV25!$A$6:$BB$47,18,0) -> 0 | L14: =IF(K14<>0,VLOOKUP($A14,[6]HISTOFEV25!$A$6:$BB$47,42,0),"ECHEC") -> ECHEC | M14: =IF(P14<>0,VLOOKUP($A14,[6]HISTOFEV25!$A$6:$BB$47,32,0),"ECHEC") -> BANQUE | N14: =VLOOKUP($A14,[6]HISTOFEV25!$A$6:$BB$47,33,0) -> 0 | O14: =IF(P14=0,0,($C$3-P14)) -> 1115000 | P14: =VLOOKUP($A14,[6]HISTOFEV25!$A$6:$BB$47,31,0) -> 85000
A15: AS201622 | B15: =IF(D15=0,0,VLOOKUP($A15,[6]HISTOFEV25!$A$6:$BQ$47,14,0)) -> 2 | C15: =VLOOKUP(A15,[7]LISTADHERENT!A$5:H$60,3,0) -> NDJOMO ETIENNE | D15: =IF(E15="ECHEC",0,VLOOKUP($A15,[6]HISTOFEV25!$A$6:$BB$47,15,0)) -> 200000 | E15: =VLOOKUP($A15,[6]HISTOFEV25!$A$6:$BB$47,9,0) -> BANQUE | F15: =VLOOKUP($A15,[6]HISTOFEV25!$A$6:$BB$47,37,0) -> 100000 | G15: =VLOOKUP($A15,[6]HISTOFEV25!$A$6:$BB$47,40,0) -> 1000 | H15: =IF(G15=0,"",VLOOKUP($A15,[6]HISTOFEV25!$A$6:$AV$47,42,0)) -> BANQUE | I15: =VLOOKUP($A15,[6]HISTOFEV25!$A$6:$BB$47,41,0) -> 0 | J15: =TONTJANV25!F15+TONTJANV25!G15 -> 0 | K15: =VLOOKUP($A15,[6]HISTOFEV25!$A$6:$BB$47,18,0) -> 0 | L15: =IF(K15<>0,VLOOKUP($A15,[6]HISTOFEV25!$A$6:$BB$47,42,0),"ECHEC") -> ECHEC | M15: =IF(P15<>0,VLOOKUP($A15,[6]HISTOFEV25!$A$6:$BB$47,32,0),"ECHEC") -> ECHEC | N15: =VLOOKUP($A15,[6]HISTOFEV25!$A$6:$BB$47,33,0) -> 0 | O15: =IF(P15=0,0,($C$3-P15)) -> 0 | P15: =VLOOKUP($A15,[6]HISTOFEV25!$A$6:$BB$47,31,0) -> 0
A16: AS201624 | B16: =IF(D16=0,0,VLOOKUP($A16,[6]HISTOFEV25!$A$6:$BQ$47,14,0)) -> 1 | C16: =VLOOKUP(A16,[7]LISTADHERENT!A$5:H$60,3,0) -> NGONDIEP CLAUDE | D16: =IF(E16="ECHEC",0,VLOOKUP($A16,[6]HISTOFEV25!$A$6:$BB$47,15,0)) -> 100000 | E16: =VLOOKUP($A16,[6]HISTOFEV25!$A$6:$BB$47,9,0) -> BANQUE | F16: =VLOOKUP($A16,[6]HISTOFEV25!$A$6:$BB$47,37,0) -> 0 | G16: =VLOOKUP($A16,[6]HISTOFEV25!$A$6:$BB$47,40,0) -> 0 | H16: =IF(G16=0,"",VLOOKUP($A16,[6]HISTOFEV25!$A$6:$AV$47,42,0)) | I16: =VLOOKUP($A16,[6]HISTOFEV25!$A$6:$BB$47,41,0) -> 0 | J16: =TONTJANV25!F16+TONTJANV25!G16 -> 0 | K16: =VLOOKUP($A16,[6]HISTOFEV25!$A$6:$BB$47,18,0) -> 0 | L16: =IF(K16<>0,VLOOKUP($A16,[6]HISTOFEV25!$A$6:$BB$47,42,0),"ECHEC") -> ECHEC | M16: =IF(P16<>0,VLOOKUP($A16,[6]HISTOFEV25!$A$6:$BB$47,32,0),"ECHEC") -> ECHEC | N16: =VLOOKUP($A16,[6]HISTOFEV25!$A$6:$BB$47,33,0) -> 0 | O16: =IF(P16=0,0,($C$3-P16)) -> 0 | P16: =VLOOKUP($A16,[6]HISTOFEV25!$A$6:$BB$47,31,0) -> 0
A17: AS201626 | B17: =IF(D17=0,0,VLOOKUP($A17,[6]HISTOFEV25!$A$6:$BQ$47,14,0)) -> 2 | C17: =VLOOKUP(A17,[7]LISTADHERENT!A$5:H$60,3,0) -> NGUIEMEGNI MATHIEU BLAISE | D17: =IF(E17="ECHEC",0,VLOOKUP($A17,[6]HISTOFEV25!$A$6:$BB$47,15,0)) -> 200000 | E17: =VLOOKUP($A17,[6]HISTOFEV25!$A$6:$BB$47,9,0) -> BANQUE | F17: =VLOOKUP($A17,[6]HISTOFEV25!$A$6:$BB$47,37,0) -> 200000 | G17: =VLOOKUP($A17,[6]HISTOFEV25!$A$6:$BB$47,40,0) -> 6500 | H17: =IF(G17=0,"",VLOOKUP($A17,[6]HISTOFEV25!$A$6:$AV$47,42,0)) -> BANQUE | I17: =VLOOKUP($A17,[6]HISTOFEV25!$A$6:$BB$47,41,0) -> 0 | J17: =TONTJANV25!F17+TONTJANV25!G17 -> 0 | K17: =VLOOKUP($A17,[6]HISTOFEV25!$A$6:$BB$47,18,0) -> 0 | L17: =IF(K17<>0,VLOOKUP($A17,[6]HISTOFEV25!$A$6:$BB$47,42,0),"ECHEC") -> ECHEC | M17: =IF(P17<>0,VLOOKUP($A17,[6]HISTOFEV25!$A$6:$BB$47,32,0),"ECHEC") -> ECHEC | N17: =VLOOKUP($A17,[6]HISTOFEV25!$A$6:$BB$47,33,0) -> 0 | O17: =IF(P17=0,0,($C$3-P17)) -> 0 | P17: =VLOOKUP($A17,[6]HISTOFEV25!$A$6:$BB$47,31,0) -> 0
... A22: AS201647 | B22: =IF(D22=0,0,VLOOKUP($A22,[6]HISTOFEV25!$A$6:$BQ$47,14,0)) -> 1 | C22: =VLOOKUP(A22,[7]LISTADHERENT!A$5:H$60,3,0) -> YOUMBI EMMANUEL | D22: =IF(E22="ECHEC",0,VLOOKUP($A22,[6]HISTOFEV25!$A$6:$BB$47,15,0)) -> 100000 | E22: =VLOOKUP($A22,[6]HISTOFEV25!$A$6:$BB$47,9,0) -> BANQUE | F22: =VLOOKUP($A22,[6]HISTOFEV25!$A$6:$BB$47,37,0) -> 0 | G22: =VLOOKUP($A22,[6]HISTOFEV25!$A$6:$BB$47,40,0) -> 0 | H22: =IF(G22=0,"",VLOOKUP($A22,[6]HISTOFEV25!$A$6:$AV$47,42,0)) | I22: =VLOOKUP($A22,[6]HISTOFEV25!$A$6:$BB$47,41,0) -> 0 | J22: =TONTJANV25!F22+TONTJANV25!G22 -> 0 | K22: =VLOOKUP($A22,[6]HISTOFEV25!$A$6:$BB$47,18,0) -> 0 | L22: =IF(K22<>0,VLOOKUP($A22,[6]HISTOFEV25!$A$6:$BB$47,42,0),"ECHEC") -> ECHEC | M22: =IF(P22<>0,VLOOKUP($A22,[6]HISTOFEV25!$A$6:$BB$47,32,0),"ECHEC") -> ECHEC | N22: =VLOOKUP($A22,[6]HISTOFEV25!$A$6:$BB$47,33,0) -> 0 | O22: =IF(P22=0,0,($C$3-P22)) -> 0 | P22: =VLOOKUP($A22,[6]HISTOFEV25!$A$6:$BB$47,31,0) -> 0
A24: TOTAL PART | B24: =SUM(B6:B22) -> 24
A25: NBRE ADHERENT | B25: =+COUNT(D6:D22) -> 17 | D25: =SUM(D6:D22) -> 2400000 | E25: =SUM(E6:E22) -> 0 | F25: =SUM(F6:F22) -> 700000 | G25: =SUM(G6:G22) -> 19500 | H25: =SUM(H6:H22) -> 0 | I25: =SUM(I6:I22) -> 0 | J25: =SUM(J6:J22) -> 0 | K25: =SUM(K6:K22) -> 0 | ... P25: =SUM(P6:P22) -> 235000
M26: NBRE PART | N26: PART VENDUE
D27: MONTANT TONTINE | E27: REMBOURSEMENT PETIT LOT | F27: VENTE PETIT LOT | G27: VENTE LOT PRINCIPAL | H27: SOLDE EN CAISSE | K27: TONTINE + REMB + INTERET VENTE | L27: =D31+E31+P25+TONTJANV25!N32 -> 1675000
C28: ESPECES | D28: =SUMIFS(D6:D22,E6:E22,"ESPECES") -> 100000 | E28: =SUMIFS(K6:K22,L6:L22,"ESPECES") -> 0 | F28: =SUMIFS(F6:F22,H6:H22,"ESPECES") -> 0 | G28: =SUMIFS(O6:O22,M6:M22,"ESPECES") -> 0 | H28: =D28+E28-F28-G28 -> 100000 | K28: LOT PRINCIPAL | L28: =C3*COUNTIF(O6:O22,">0") -> 3600000 | M28: =D3 -> 1 | N28: =COUNTIF(O9:O21,">0") -> 2
C29: BANQUE | D29: =SUMIFS(D6:D22,E6:E22,"BANQUE") -> 2300000 | E29: =SUMIFS(K6:K22,L6:L22,"BANQUE") -> 0 | F29: =SUMIFS(F6:F22,H6:H22,"BANQUE") -> 700000 | G29: =SUMIFS(O6:O22,M6:M22,"BANQUE") -> 3365000 | H29: =D29+E29-F29-G29 -> -1765000
K30: PETIT LOT | L30: =L27-L28 -> -1925000
C31: TOTAL | D31: =D28+D29 -> 2400000 | E31: =E28+E29 -> 0 | F31: =F28+F29 -> 700000 | G31: =G28+G29 -> 3365000 | H31: =H28+H29 -> -1665000
K32: RELIQUAT | L32: =L30-F25 -> -2625000 | N32: =L32 -> -2625000 | O32: CUMUL
K34: ECHEC TONTINE MOIS | L34: =COUNTIFS(E6:E29,"ECHEC")*100000 -> 0 | N34: =L34+TONTJANV25!N34 -> 0 | O34: CUMUL
K35: ECHEC REMBOURSEMENT MOIS | L35: =J25-E31 -> 0 | N35: =L35+TONTJANV25!N35 -> 0 | O35: CUMUL

Sheet TONTMARS25
A1: ASSOCIATION | B1: ASELBY
A2: ANNEE | B2: 2025 | C2: TONIINE | D2: NBRE PART
A3: TAUX TONTINE | B3: 100000 | C3: =B3*12 -> 1200000 | D3: =ROUNDDOWN(L27/C3,0) -> 2
C4: 45729
A5: MATRICULE | B5: NBREPART | C5: NOM ET PRENOM | D5: MONTANT TONTINE | E5: MODE VERSEMENT | F5: VENTE PETIT LOT | G5: INTERET PETIT LOT | H5: MODE VERSEMENT VENTE PETIT LOT | I5: NUMERO CHEQUE | J5: MONTANT A REMBOURSER PETIT LOT | K5: REMBOURSEMENT PETIT LOT | L5: MODE VERSEMENT REMBOURSEMENT | M5: MODE VERSEMENTLOT PRINCIPAL | N5: NUMERO CHEQUE | O5: MONTANT LOT PRINCIPAL | P5: INTERET LOT PRINCIPAL
A6: AS201648 | B6: =IF(D6=0,0,VLOOKUP($A6,[6]HISTOMARS25!$A$6:$BQ$47,14,0)) -> 1 | C6: =VLOOKUP(A6,[7]LISTADHERENT!A$5:H$60,3,0) -> ASELBY | D6: =IF(E6="ECHEC",0,VLOOKUP($A6,[6]HISTOMARS25!$A$6:$BB$47,15,0)) -> 100000 | E6: =VLOOKUP($A6,[6]HISTOMARS25!$A$6:$BB$47,9,0) -> BANQUE | F6: =VLOOKUP($A6,[6]HISTOMARS25!$A$6:$BB$47,37,0) -> 0 | G6: =VLOOKUP($A6,[6]HISTOMARS25!$A$6:$BB$47,40,0) -> 0 | H6: =IF(G6=0,"",VLOOKUP($A6,[6]HISTOFEV25!$A$6:$AV$47,42,0)) | I6: =VLOOKUP($A6,[6]HISTOMARS25!$A$6:$BB$47,41,0) -> 0 | J6: =+TONTFEV25!F6+TONTFEV25!G6 -> 0 | K6: =VLOOKUP($A6,[6]HISTOMARS25!$A$6:$BB$47,18,0) -> 0 | L6: =IF(K6<>0,VLOOKUP($A6,[6]HISTOMARS25!$A$6:$BB$47,42,0),"ECHEC") -> ECHEC | M6: =IF(P6<>0,VLOOKUP($A6,[6]HISTOMARS25!$A$6:$BB$47,32,0),"ECHEC") -> ECHEC | N6: =VLOOKUP($A6,[6]HISTOMARS25!$A$6:$BB$47,33,0) -> 0 | O6: =IF(P6=0,0,($C$3-P6)) -> 0 | P6: =VLOOKUP($A6,[6]HISTOMARS25!$A$6:$BB$47,31,0) -> 0
A7: AS201604 | B7: =IF(D7=0,0,VLOOKUP($A7,[6]HISTOMARS25!$A$6:$BQ$47,14,0)) -> 2 | C7: =VLOOKUP(A7,[7]LISTADHERENT!A$5:H$60,3,0) -> DJOMO JEAN PAUL | D7: =IF(E7="ECHEC",0,VLOOKUP($A7,[6]HISTOMARS25!$A$6:$BB$47,15,0)) -> 200000 | E7: =VLOOKUP($A7,[6]HISTOMARS25!$A$6:$BB$47,9,0) -> BANQUE | F7: =VLOOKUP($A7,[6]HISTOMARS25!$A$6:$BB$47,37,0) -> 200000 | G7: =VLOOKUP($A7,[6]HISTOMARS25!$A$6:$BB$47,40,0) -> 3500 | H7: =IF(G7=0,"",VLOOKUP($A7,[6]HISTOFEV25!$A$6:$AV$47,42,0)) -> BANQUE | I7: =VLOOKUP($A7,[6]HISTOMARS25!$A$6:$BB$47,41,0) -> 0 | J7: =+TONTFEV25!F7+TONTFEV25!G7 -> 207500 | K7: =VLOOKUP($A7,[6]HISTOMARS25!$A$6:$BB$47,18,0) -> 207500 | L7: =IF(K7<>0,VLOOKUP($A7,[6]HISTOMARS25!$A$6:$BB$47,42,0),"ECHEC") -> BANQUE | M7: =IF(P7<>0,VLOOKUP($A7,[6]HISTOMARS25!$A$6:$BB$47,32,0),"ECHEC") -> ECHEC | N7: =VLOOKUP($A7,[6]HISTOMARS25!$A$6:$BB$47,33,0) -> 0 | O7: =IF(P7=0,0,($C$3-P7)) -> 0 | P7: =VLOOKUP($A7,[6]HISTOMARS25!$A$6:$BB$47,31,0) -> 0
A8: AS201605 | B8: =IF(D8=0,0,VLOOKUP($A8,[6]HISTOMARS25!$A$6:$BQ$47,14,0)) -> 1 | C8: =VLOOKUP(A8,[7]LISTADHERENT!A$5:H$60,3,0) -> DJOUKWE NANGUEN GUY BLAISE | D8: =IF(E8="ECHEC",0,VLOOKUP($A8,[6]HISTOMARS25!$A$6:$BB$47,15,0)) -> 100000 | E8: =VLOOKUP($A8,[6]HISTOMARS25!$A$6:$BB$47,9,0) -> BANQUE | F8: =VLOOKUP($A8,[6]HISTOMARS25!$A$6:$BB$47,37,0) -> 0 | G8: =VLOOKUP($A8,[6]HISTOMARS25!$A$6:$BB$47,40,0) -> 0 | H8: =IF(G8=0,"",VLOOKUP($A8,[6]HISTOFEV25!$A$6:$AV$47,42,0)) | I8: =VLOOKUP($A8,[6]HISTOMARS25!$A$6:$BB$47,41,0) -> 0 | J8: =+TONTFEV25!F8+TONTFEV25!G8 -> 204500 | K8: =VLOOKUP($A8,[6]HISTOMARS25!$A$6:$BB$47,18,0) -> 204500 | L8: =IF(K8<>0,VLOOKUP($A8,[6]HISTOMARS25!$A$6:$BB$47,42,0),"ECHEC") -> BANQUE | M8: =IF(P8<>0,VLOOKUP($A8,[6]HISTOMARS25!$A$6:$BB$47,32,0),"ECHEC") -> BANQUE | N8: =VLOOKUP($A8,[6]HISTOMARS25!$A$6:$BB$47,33,0) -> 0 | O8: =IF(P8=0,0,($C$3-P8)) -> 1165000 | P8: =VLOOKUP($A8,[6]HISTOMARS25!$A$6:$BB$47,31,0) -> 35000
A9: AS201608 | B9: =IF(D9=0,0,VLOOKUP($A9,[6]HISTOMARS25!$A$6:$BQ$47,14,0)) -> 2 | C9: =VLOOKUP(A9,[7]LISTADHERENT!A$5:H$60,3,0) -> DJUOMBESSY ANTOINE | D9: =IF(E9="ECHEC",0,VLOOKUP($A9,[6]HISTOMARS25!$A$6:$BB$47,15,0)) -> 200000 | E9: =VLOOKUP($A9,[6]HISTOMARS25!$A$6:$BB$47,9,0) -> BANQUE | F9: =VLOOKUP($A9,[6]HISTOMARS25!$A$6:$BB$47,37,0) -> 0 | G9: =VLOOKUP($A9,[6]HISTOMARS25!$A$6:$BB$47,40,0) -> 0 | H9: =IF(G9=0,"",VLOOKUP($A9,[6]HISTOFEV25!$A$6:$AV$47,42,0)) | I9: =VLOOKUP($A9,[6]HISTOMARS25!$A$6:$BB$47,41,0) -> 0 | J9: =+TONTFEV25!F9+TONTFEV25!G9 -> 0 | K9: =VLOOKUP($A9,[6]HISTOMARS25!$A$6:$BB$47,18,0) -> 0 | L9: =IF(K9<>0,VLOOKUP($A9,[6]HISTOMARS25!$A$6:$BB$47,42,0),"ECHEC") -> ECHEC | M9: =IF(P9<>0,VLOOKUP($A9,[6]HISTOMARS25!$A$6:$BB$47,32,0),"ECHEC") -> BANQUE | N9: =VLOOKUP($A9,[6]HISTOMARS25!$A$6:$BB$47,33,0) -> 0 | O9: =IF(P9=0,0,($C$3-P9)) -> 1170000 | P9: =VLOOKUP($A9,[6]HISTOMARS25!$A$6:$BB$47,31,0) -> 30000
A10: AS201663 | B10: =IF(D10=0,0,VLOOKUP($A10,[6]HISTOMARS25!$A$6:$BQ$47,14,0)) -> 1 | C10: =VLOOKUP(A10,[7]LISTADHERENT!A$5:H$60,3,0) -> FAMPOU PAUL | D10: =IF(E10="ECHEC",0,VLOOKUP($A10,[6]HISTOMARS25!$A$6:$BB$47,15,0)) -> 100000 | E10: =VLOOKUP($A10,[6]HISTOMARS25!$A$6:$BB$47,9,0) -> BANQUE | F10: =VLOOKUP($A10,[6]HISTOMARS25!$A$6:$BB$47,37,0) -> 0 | G10: =VLOOKUP($A10,[6]HISTOMARS25!$A$6:$BB$47,40,0)+26000 -> 26000 | H10: =IF(G10=0,"",VLOOKUP($A10,[6]HISTOFEV25!$A$6:$AV$47,42,0)) -> 0 | I10: =VLOOKUP($A10,[6]HISTOMARS25!$A$6:$BB$47,41,0) -> 0 | J10: =+TONTFEV25!F10+TONTFEV25!G10 -> 0 | K10: =VLOOKUP($A10,[6]HISTOMARS25!$A$6:$BB$47,18,0) -> 0 | L10: =IF(K10<>0,VLOOKUP($A10,[6]HISTOMARS25!$A$6:$BB$47,42,0),"ECHEC") -> ECHEC | M10: =IF(P10<>0,VLOOKUP($A10,[6]HISTOMARS25!$A$6:$BB$47,32,0),"ECHEC") -> ECHEC | N10: =VLOOKUP($A10,[6]HISTOMARS25!$A$6:$BB$47,33,0) -> 0 | O10: =IF(P10=0,0,($C$3-P10)) -> 0 | P10: =VLOOKUP($A10,[6]HISTOMARS25!$A$6:$BB$47,31,0) -> 0
A11: AS201613 | B11: =IF(D11=0,0,VLOOKUP($A11,[6]HISTOMARS25!$A$6:$BQ$47,14,0)) -> 1 | C11: =VLOOKUP(A11,[7]LISTADHERENT!A$5:H$60,3,0) -> HOTCHO BENJAMIN | D11: =IF(E11="ECHEC",0,VLOOKUP($A11,[6]HISTOMARS25!$A$6:$BB$47,15,0)) -> 100000 | E11: =VLOOKUP($A11,[6]HISTOMARS25!$A$6:$BB$47,9,0) -> BANQUE | F11: =VLOOKUP($A11,[6]HISTOMARS25!$A$6:$BB$47,37,0) -> 0 | G11: =VLOOKUP($A11,[6]HISTOMARS25!$A$6:$BB$47,40,0) -> 0 | H11: =IF(G11=0,"",VLOOKUP($A11,[6]HISTOFEV25!$A$6:$AV$47,42,0)) | I11: =VLOOKUP($A11,[6]HISTOMARS25!$A$6:$BB$47,41,0) -> 0 | J11: =+TONTFEV25!F11+TONTFEV25!G11 -> 0 | K11: =VLOOKUP($A11,[6]HISTOMARS25!$A$6:$BB$47,18,0) -> 0 | L11: =IF(K11<>0,VLOOKUP($A11,[6]HISTOMARS25!$A$6:$BB$47,42,0),"ECHEC") -> ECHEC | M11: =IF(P11<>0,VLOOKUP($A11,[6]HISTOMARS25!$A$6:$BB$47,32,0),"ECHEC") -> ECHEC | N11: =VLOOKUP($A11,[6]HISTOMARS25!$A$6:$BB$47,33,0) -> 0 | O11: =IF(P11=0,0,($C$3-P11)) -> 0 | P11: =VLOOKUP($A11,[6]HISTOMARS25!$A$6:$BB$47,31,0) -> 0
A12: AS201617 | B12: =IF(D12=0,0,VLOOKUP($A12,[6]HISTOMARS25!$A$6:$BQ$47,14,0)) -> 1 | C12: =VLOOKUP(A12,[7]LISTADHERENT!A$5:H$60,3,0) -> KOUAMOU MOISE | D12: =IF(E12="ECHEC",0,VLOOKUP($A12,[6]HISTOMARS25!$A$6:$BB$47,15,0)) -> 100000 | E12: =VLOOKUP($A12,[6]HISTOMARS25!$A$6:$BB$47,9,0) -> BANQUE | F12: =VLOOKUP($A12,[6]HISTOMARS25!$A$6:$BB$47,37,0) -> 0 | G12: =VLOOKUP($A12,[6]HISTOMARS25!$A$6:$BB$47,40,0) -> 0 | H12: =IF(G12=0,"",VLOOKUP($A12,[6]HISTOFEV25!$A$6:$AV$47,42,0)) | I12: =VLOOKUP($A12,[6]HISTOMARS25!$A$6:$BB$47,41,0) -> 0 | J12: =+TONTFEV25!F12+TONTFEV25!G12 -> 0 | K12: =VLOOKUP($A12,[6]HISTOMARS25!$A$6:$BB$47,18,0) -> 0 | L12: =IF(K12<>0,VLOOKUP($A12,[6]HISTOMARS25!$A$6:$BB$47,42,0),"ECHEC") -> ECHEC | M12: =IF(P12<>0,VLOOKUP($A12,[6]HISTOMARS25!$A$6:$BB$47,32,0),"ECHEC") -> ECHEC | N12: =VLOOKUP($A12,[6]HISTOMARS25!$A$6:$BB$47,33,0) -> 0 | O12: =IF(P12=0,0,($C$3-P12)) -> 0 | P12: =VLOOKUP($A12,[6]HISTOMARS25!$A$6:$BB$47,31,0) -> 0
A13: AS201619 | B13: =IF(D13=0,0,VLOOKUP($A13,[6]HISTOMARS25!$A$6:$BQ$47,14,0)) -> 1 | C13: =VLOOKUP(A13,[7]LISTADHERENT!A$5:H$60,3,0) -> KOUATCHO MESSACK | D13: =IF(E13="ECHEC",0,VLOOKUP($A13,[6]HISTOMARS25!$A$6:$BB$47,15,0)) -> 100000 | E13: =VLOOKUP($A13,[6]HISTOMARS25!$A$6:$BB$47,9,0) -> BANQUE | F13: =VLOOKUP($A13,[6]HISTOMARS25!$A$6:$BB$47,37,0) -> 205500 | G13: =VLOOKUP($A13,[6]HISTOMARS25!$A$6:$BB$47,40,0) -> 2000 | H13: =IF(G13=0,"",VLOOKUP($A13,[6]HISTOFEV25!$A$6:$AV$47,42,0)) -> BANQUE | I13: =VLOOKUP($A13,[6]HISTOMARS25!$A$6:$BB$47,41,0) -> 0 | J13: =+TONTFEV25!F13+TONTFEV25!G13 -> 0 | K13: =VLOOKUP($A13,[6]HISTOMARS25!$A$6:$BB$47,18,0) -> 0 | L13: =IF(K13<>0,VLOOKUP($A13,[6]HISTOMARS25!$A$6:$BB$47,42,0),"ECHEC") -> ECHEC | M13: =IF(P13<>0,VLOOKUP($A13,[6]HISTOMARS25!$A$6:$BB$47,32,0),"ECHEC") -> ECHEC | N13: =VLOOKUP($A13,[6]HISTOMARS25!$A$6:$BB$47,33,0) -> 0 | O13: =IF(P13=0,0,($C$3-P13)) -> 0 | P13: =VLOOKUP($A13,[6]HISTOMARS25!$A$6:$BB$47,31,0) -> 0
A14: AS201649 | B14: =IF(D14=0,0,VLOOKUP($A14,[6]HISTOMARS25!$A$6:$BQ$47,14,0)) -> 2 | C14: =VLOOKUP(A14,[7]LISTADHERENT!A$5:H$60,3,0) -> MBOGNING TUGMA GUY | D14: =IF(E14="ECHEC",0,VLOOKUP($A14,[6]HISTOMARS25!$A$6:$BB$47,15,0)) -> 200000 | E14: =VLOOKUP($A14,[6]HISTOMARS25!$A$6:$BB$47,9,0) -> BANQUE | F14: =VLOOKUP($A14,[6]HISTOMARS25!$A$6:$BB$47,37,0) -> 200000 | G14: =VLOOKUP($A14,[6]HISTOMARS25!$A$6:$BB$47,40,0) -> 2000 | H14: =IF(G14=0,"",VLOOKUP($A14,[6]HISTOFEV25!$A$6:$AV$47,42,0)) -> BANQUE | I14: =VLOOKUP($A14,[6]HISTOMARS25!$A$6:$BB$47,41,0) -> 0 | J14: =+TONTFEV25!F14+TONTFEV25!G14 -> 0 | K14: =VLOOKUP($A14,[6]HISTOMARS25!$A$6:$BB$47,18,0) -> 0 | L14: =IF(K14<>0,VLOOKUP($A14,[6]HISTOMARS25!$A$6:$BB$47,42,0),"ECHEC") -> ECHEC | M14: =IF(P14<>0,VLOOKUP($A14,[6]HISTOMARS25!$A$6:$BB$47,32,0),"ECHEC") -> ECHEC | N14: =VLOOKUP($A14,[6]HISTOMARS25!$A$6:$BB$47,33,0) -> 0 | O14: =IF(P14=0,0,($C$3-P14)) -> 0 | P14: =VLOOKUP($A14,[6]HISTOMARS25!$A$6:$BB$47,31,0) -> 0
A15: AS201622 | B15: =IF(D15=0,0,VLOOKUP($A15,[6]HISTOMARS25!$A$6:$BQ$47,14,0)) -> 2 | C15: =VLOOKUP(A15,[7]LISTADHERENT!A$5:H$60,3,0) -> NDJOMO ETIENNE | D15: =IF(E15="ECHEC",0,VLOOKUP($A15,[6]HISTOMARS25!$A$6:$BB$47,15,0)) -> 200000 | E15: =VLOOKUP($A15,[6]HISTOMARS25!$A$6:$BB$47,9,0) -> BANQUE | F15: =VLOOKUP($A15,[6]HISTOMARS25!$A$6:$BB$47,37,0) -> 100000 | G15: =VLOOKUP($A15,[6]HISTOMARS25!$A$6:$BB$47,40,0) -> 1000 | H15: =IF(G15=0,"",VLOOKUP($A15,[6]HISTOFEV25!$A$6:$AV$47,42,0)) -> BANQUE | I15: =VLOOKUP($A15,[6]HISTOMARS25!$A$6:$BB$47,41,0) -> 0 | J15: =+TONTFEV25!F15+TONTFEV25!G15 -> 101000 | K15: =VLOOKUP($A15,[6]HISTOMARS25!$A$6:$BB$47,18,0) -> 101000 | L15: =IF(K15<>0,VLOOKUP($A15,[6]HISTOMARS25!$A$6:$BB$47,42,0),"ECHEC") -> BANQUE | M15: =IF(P15<>0,VLOOKUP($A15,[6]HISTOMARS25!$A$6:$BB$47,32,0),"ECHEC") -> ECHEC | N15: =VLOOKUP($A15,[6]HISTOMARS25!$A$6:$BB$47,33,0) -> 0 | O15: =IF(P15=0,0,($C$3-P15)) -> 0 | P15: =VLOOKUP($A15,[6]HISTOMARS25!$A$6:$BB$47,31,0) -> 0
A16: AS201624 | B16: =IF(D16=0,0,VLOOKUP($A16,[6]HISTOMARS25!$A$6:$BQ$47,14,0)) -> 1 | C16: =VLOOKUP(A16,[7]LISTADHERENT!A$5:H$60,3,0) -> NGONDIEP CLAUDE | D16: =IF(E16="ECHEC",0,VLOOKUP($A16,[6]HISTOMARS25!$A$6:$BB$47,15,0)) -> 100000 | E16: =VLOOKUP($A16,[6]HISTOMARS25!$A$6:$BB$47,9,0) -> BANQUE | F16: =VLOOKUP($A16,[6]HISTOMARS25!$A$6:$BB$47,37,0) -> 0 | G16: =VLOOKUP($A16,[6]HISTOMARS25!$A$6:$BB$47,40,0) -> 0 | H16: =IF(G16=0,"",VLOOKUP($A16,[6]HISTOFEV25!$A$6:$AV$47,42,0)) | I16: =VLOOKUP($A16,[6]HISTOMARS25!$A$6:$BB$47,41,0) -> 0 | J16: =+TONTFEV25!F16+TONTFEV25!G16 -> 0 | K16: =VLOOKUP($A16,[6]HISTOMARS25!$A$6:$BB$47,18,0) -> 0 | L16: =IF(K16<>0,VLOOKUP($A16,[6]HISTOMARS25!$A$6:$BB$47,42,0),"ECHEC") -> ECHEC | M16: =IF(P16<>0,VLOOKUP($A16,[6]HISTOMARS25!$A$6:$BB$47,32,0),"ECHEC") -> ECHEC | N16: =VLOOKUP($A16,[6]HISTOMARS25!$A$6:$BB$47,33,0) -> 0 | O16: =IF(P16=0,0,($C$3-P16)) -> 0 | P16: =VLOOKUP($A16,[6]HISTOMARS25!$A$6:$BB$47,31,0) -> 0
A17: AS201626 | B17: =IF(D17=0,0,VLOOKUP($A17,[6]HISTOMARS25!$A$6:$BQ$47,14,0)) -> 2 | C17: =VLOOKUP(A17,[7]LISTADHERENT!A$5:H$60,3,0) -> NGUIEMEGNI MATHIEU BLAISE | D17: =IF(E17="ECHEC",0,VLOOKUP($A17,[6]HISTOMARS25!$A$6:$BB$47,15,0)) -> 200000 | E17: =VLOOKUP($A17,[6]HISTOMARS25!$A$6:$BB$47,9,0) -> BANQUE | F17: =VLOOKUP($A17,[6]HISTOMARS25!$A$6:$BB$47,37,0) -> 200000 | G17: =VLOOKUP($A17,[6]HISTOMARS25!$A$6:$BB$47,40,0) -> 2500 | H17: =IF(G17=0,"",VLOOKUP($A17,[6]HISTOFEV25!$A$6:$AV$47,42,0)) -> BANQUE | I17: =VLOOKUP($A17,[6]HISTOMARS25!$A$6:$BB$47,41,0) -> 0 | J17: =+TONTFEV25!F17+TONTFEV25!G17 -> 206500 | K17: =VLOOKUP($A17,[6]HISTOMARS25!$A$6:$BB$47,18,0) -> 206500 | L17: =IF(K17<>0,VLOOKUP($A17,[6]HISTOMARS25!$A$6:$BB$47,42,0),"ECHEC") -> BANQUE | M17: =IF(P17<>0,VLOOKUP($A17,[6]HISTOMARS25!$A$6:$BB$47,32,0),"ECHEC") -> ECHEC | N17: =VLOOKUP($A17,[6]HISTOMARS25!$A$6:$BB$47,33,0) -> 0 | O17: =IF(P17=0,0,($C$3-P17)) -> 0 | P17: =VLOOKUP($A17,[6]HISTOMARS25!$A$6:$BB$47,31,0) -> 0
A18: AS201653 | B18: =IF(D18=0,0,VLOOKUP($A18,[6]HISTOMARS25!$A$6:$BQ$47,14,0)) -> 2 | C18: =VLOOKUP(A18,[7]LISTADHERENT!A$5:H$60,3,0) -> SIME BRICE | D18: =IF(E18="ECHEC",0,VLOOKUP($A18,[6]HISTOMARS25!$A$6:$BB$47,15,0)) -> 200000 | E18: =VLOOKUP($A18,[6]HISTOMARS25!$A$6:$BB$47,9,0) -> ESPECES | F18: =VLOOKUP($A18,[6]HISTOMARS25!$A$6:$BB$47,37,0) -> 0 | G18: =VLOOKUP($A18,[6]HISTOMARS25!$A$6:$BB$47,40,0) -> 0 | H18: =IF(G18=0,"",VLOOKUP($A18,[6]HISTOFEV25!$A$6:$AV$47,42,0)) | I18: =VLOOKUP($A18,[6]HISTOMARS25!$A$6:$BB$47,41,0) -> 0 | J18: =+TONTFEV25!F18+TONTFEV25!G18 -> 0 | K18: =VLOOKUP($A18,[6]HISTOMARS25!$A$6:$BB$47,18,0) -> 0 | L18: =IF(K18<>0,VLOOKUP($A18,[6]HISTOMARS25!$A$6:$BB$47,42,0),"ECHEC") -> ECHEC | M18: =IF(P18<>0,VLOOKUP($A18,[6]HISTOMARS25!$A$6:$BB$47,32,0),"ECHEC") -> ECHEC | N18: =VLOOKUP($A18,[6]HISTOMARS25!$A$6:$BB$47,33,0) -> 0 | O18: =IF(P18=0,0,($C$3-P18)) -> 0 | P18: =VLOOKUP($A18,[6]HISTOMARS25!$A$6:$BB$47,31,0) -> 0
A19: AS201660 | B19: =IF(D19=0,0,VLOOKUP($A19,[6]HISTOMARS25!$A$6:$BQ$47,14,0)) -> 1 | C19: =VLOOKUP(A19,[7]LISTADHERENT!A$5:H$60,3,0) -> TCHOUATEU AUGUSTIN | D19: =IF(E19="ECHEC",0,VLOOKUP($A19,[6]HISTOMARS25!$A$6:$BB$47,15,0)) -> 100000 | E19: =VLOOKUP($A19,[6]HISTOMARS25!$A$6:$BB$47,9,0) -> BANQUE | F19: =VLOOKUP($A19,[6]HISTOMARS25!$A$6:$BB$47,37,0) -> 0 | G19: =VLOOKUP($A19,[6]HISTOMARS25!$A$6:$BB$47,40,0) -> 0 | H19: =IF(G19=0,"",VLOOKUP($A19,[6]HISTOFEV25!$A$6:$AV$47,42,0)) | I19: =VLOOKUP($A19,[6]HISTOMARS25!$A$6:$BB$47,41,0) -> 0 | J19: =+TONTFEV25!F19+TONTFEV25!G19 -> 0 | K19: =VLOOKUP($A19,[6]HISTOMARS25!$A$6:$BB$47,18,0) -> 0 | L19: =IF(K19<>0,VLOOKUP($A19,[6]HISTOMARS25!$A$6:$BB$47,42,0),"ECHEC") -> ECHEC | M19: =IF(P19<>0,VLOOKUP($A19,[6]HISTOMARS25!$A$6:$BB$47,32,0),"ECHEC") -> ECHEC | N19: =VLOOKUP($A19,[6]HISTOMARS25!$A$6:$BB$47,33,0) -> 0 | O19: =IF(P19=0,0,($C$3-P19)) -> 0 | P19: =VLOOKUP($A19,[6]HISTOMARS25!$A$6:$BB$47,31,0) -> 0
A20: AS201638 | B20: =IF(D20=0,0,VLOOKUP($A20,[6]HISTOMARS25!$A$6:$BQ$47,14,0)) -> 1 | C20: =VLOOKUP(A20,[7]LISTADHERENT!A$5:H$60,3,0) -> SIMO PIERRE | D20: =IF(E20="ECHEC",0,VLOOKUP($A20,[6]HISTOMARS25!$A$6:$BB$47,15,0)) -> 100000 | E20: =VLOOKUP($A20,[6]HISTOMARS25!$A$6:$BB$47,9,0) -> BANQUE | F20: =VLOOKUP($A20,[6]HISTOMARS25!$A$6:$BB$47,37,0) -> 0 | G20: =VLOOKUP($A20,[6]HISTOMARS25!$A$6:$BB$47,40,0) -> 0 | H20: =IF(G20=0,"",VLOOKUP($A20,[6]HISTOFEV25!$A$6:$AV$47,42,0)) | I20: =VLOOKUP($A20,[6]HISTOMARS25!$A$6:$BB$47,41,0) -> 0 | J20: =+TONTFEV25!F20+TONTFEV25!G20 -> 0 | K20: =VLOOKUP($A20,[6]HISTOMARS25!$A$6:$BB$47,18,0) -> 0 | L20: =IF(K20<>0,VLOOKUP($A20,[6]HISTOMARS25!$A$6:$BB$47,42,0),"ECHEC") -> ECHEC | M20: =IF(P20<>0,VLOOKUP($A20,[6]HISTOMARS25!$A$6:$BB$47,32,0),"ECHEC") -> ECHEC | N20: =VLOOKUP($A20,[6]HISTOMARS25!$A$6:$BB$47,33,0) -> 0 | O20: =IF(P20=0,0,($C$3-P20)) -> 0 | P20: =VLOOKUP($A20,[6]HISTOMARS25!$A$6:$BB$47,31,0) -> 0
A21: AS201659 | B21: =IF(D21=0,0,VLOOKUP($A21,[6]HISTOMARS25!$A$6:$BQ$47,14,0)) -> 2 | C21: =VLOOKUP(A21,[7]LISTADHERENT!A$5:H$60,3,0) -> YIALA ALAIN OSCAR | D21: =IF(E21="ECHEC",0,VLOOKUP($A21,[6]HISTOMARS25!$A$6:$BB$47,15,0)) -> 200000 | E21: =VLOOKUP($A21,[6]HISTOMARS25!$A$6:$BB$47,9,0) -> ESPECES | F21: =VLOOKUP($A21,[6]HISTOMARS25!$A$6:$BB$47,37,0) -> 0 | G21: =VLOOKUP($A21,[6]HISTOMARS25!$A$6:$BB$47,40,0) -> 0 | H21: =IF(G21=0,"",VLOOKUP($A21,[6]HISTOFEV25!$A$6:$AV$47,42,0)) | I21: =VLOOKUP($A21,[6]HISTOMARS25!$A$6:$BB$47,41,0) -> 0 | J21: =+TONTFEV25!F21+TONTFEV25!G21 -> 0 | K21: =VLOOKUP($A21,[6]HISTOMARS25!$A$6:$BB$47,18,0) -> 0 | L21: =IF(K21<>0,VLOOKUP($A21,[6]HISTOMARS25!$A$6:$BB$47,42,0),"ECHEC") -> ECHEC | M21: =IF(P21<>0,VLOOKUP($A21,[6]HISTOMARS25!$A$6:$BB$47,32,0),"ECHEC") -> ECHEC | N21: =VLOOKUP($A21,[6]HISTOMARS25!$A$6:$BB$47,33,0) -> 0 | O21: =IF(P21=0,0,($C$3-P21)) -> 0 | P21: =VLOOKUP($A21,[6]HISTOMARS25!$A$6:$BB$47,31,0) -> 0
A22: AS201647 | B22: =IF(D22=0,0,VLOOKUP($A22,[6]HISTOMARS25!$A$6:$BQ$47,14,0)) -> 1 | C22: =VLOOKUP(A22,[7]LISTADHERENT!A$5:H$60,3,0) -> YOUMBI EMMANUEL | D22: =IF(E22="ECHEC",0,VLOOKUP($A22,[6]HISTOMARS25!$A$6:$BB$47,15,0)) -> 100000 | E22: =VLOOKUP($A22,[6]HISTOMARS25!$A$6:$BB$47,9,0) -> BANQUE | F22: =VLOOKUP($A22,[6]HISTOMARS25!$A$6:$BB$47,37,0) -> 0 | G22: =VLOOKUP($A22,[6]HISTOMARS25!$A$6:$BB$47,40,0) -> 0 | H22: =IF(G22=0,"",VLOOKUP($A22,[6]HISTOFEV25!$A$6:$AV$47,42,0)) | I22: =VLOOKUP($A22,[6]HISTOMARS25!$A$6:$BB$47,41,0) -> 0 | J22: =+TONTFEV25!F22+TONTFEV25!G22 -> 0 | K22: =VLOOKUP($A22,[6]HISTOMARS25!$A$6:$BB$47,18,0) -> 0 | L22: =IF(K22<>0,VLOOKUP($A22,[6]HISTOMARS25!$A$6:$BB$47,42,0),"ECHEC") -> ECHEC | M22: =IF(P22<>0,VLOOKUP($A22,[6]HISTOMARS25!$A$6:$BB$47,32,0),"ECHEC") -> ECHEC | N22: =VLOOKUP($A22,[6]HISTOMARS25!$A$6:$BB$47,33,0) -> 0 | O22: =IF(P22=0,0,($C$3-P22)) -> 0 | P22: =VLOOKUP($A22,[6]HISTOMARS25!$A$6:$BB$47,31,0) -> 0
A24: TOTAL PART | B24: =SUM(B6:B22) -> 24
A25: NBRE ADHERENT | B25: =+COUNT(D6:D22) -> 17 | D25: =SUM(D6:D22) -> 2400000 | E25: =SUM(E6:E22) -> 0 | F25: =SUM(F6:F22) -> 905500 | G25: =SUM(G6:G22) -> 37000 | H25: =SUM(H6:H22) -> 0 | I25: =SUM(I6:I22) -> 0 | J25: =SUM(J6:J22) -> 719500 | K25: =SUM(K6:K22) -> 719500 | ... P25: =SUM(P6:P22) -> 65000
M26: NBRE PART | N26: PART VENDUE
D27: MONTANT TONTINE | E27: REMBOURSEMENT PETIT LOT | F27: VENTE PETIT LOT | G27: VENTE LOT PRINCIPAL | H27: SOLDE EN CAISSE | K27: TONTINE + REMB + INTERET VENTE | L27: =D31+E31+P25+TONTFEV25!N32+2400000 -> 3159500
C28: ESPECES | D28: =SUMIFS(D6:D22,E6:E22,"ESPECES") -> 400000 | E28: =SUMIFS(K6:K22,L6:L22,"ESPECES") -> 0 | F28: =SUMIFS(F6:F22,H6:H22,"ESPECES") -> 0 | G28: =SUMIFS(O6:O22,M6:M22,"ESPECES") -> 0 | H28: =D28+E28-F28-G28 -> 400000 | K28: LOT PRINCIPAL | L28: =C3*COUNTIF(O6:O22,">0") -> 2400000 | M28: =D3 -> 2 | N28: =COUNTIF(O6:O21,">0") -> 2
C29: BANQUE | D29: =SUMIFS(D6:D22,E6:E22,"BANQUE") -> 2000000 | E29: =SUMIFS(K6:K22,L6:L22,"BANQUE") -> 719500 | F29: =SUMIFS(F6:F22,H6:H22,"BANQUE") -> 905500 | G29: =SUMIFS(O6:O22,M6:M22,"BANQUE") -> 2335000 | H29: =D29+E29-F29-G29 -> -521000
K30: PETIT LOT | L30: =+L27-L28+251000 -> 1010500
C31: TOTAL | D31: =D28+D29+200000 -> 2600000 | E31: =E28+E29 -> 719500 | F31: =F28+F29 -> 905500 | G31: =G28+G29 -> 2335000 | H31: =H28+H29 -> -121000
K32: RELIQUAT | L32: =L30-F25 -> 105000 | N32: =L32 -> 105000 | O32: CUMUL
K34: ECHEC TONTINE MOIS | L34: =COUNTIFS(E6:E29,"ECHEC")*100000 -> 0 | N34: =L34+TONTFEV25!N34 -> 0 | O34: CUMUL
K35: ECHEC REMBOURSEMENT MOIS | L35: =J25-E31 -> 0 | N35: =L35+TONTFEV25!N35 -> 0 | O35: CUMUL

Sheet TONTAVRIL25
A1: ASSOCIATION | B1: ASELBY
A2: ANNEE | B2: 2025 | C2: TONIINE | D2: NBRE PART
A3: TAUX TONTINE | B3: 100000 | C3: =B3*12 -> 1200000 | D3: =ROUNDDOWN(L27/C3,0) -> 2
C4: 45760
A5: MATRICULE | B5: NBREPART | C5: NOM ET PRENOM | D5: MONTANT TONTINE | E5: MODE VERSEMENT | F5: VENTE PETIT LOT | G5: INTERET PETIT LOT | H5: MODE VERSEMENT VENTE PETIT LOT | I5: NUMERO CHEQUE | J5: MONTANT A REMBOURSER PETIT LOT | K5: REMBOURSEMENT PETIT LOT | L5: MODE VERSEMENT REMBOURSEMENT | M5: MODE VERSEMENTLOT PRINCIPAL | N5: NUMERO CHEQUE | O5: MONTANT LOT PRINCIPAL | P5: INTERET LOT PRINCIPAL
A6: AS201648 | B6: =IF(D6=0,0,VLOOKUP($A6,[6]HISTOAVRIL25!$A$6:$BQ$47,14,0)) -> 1 | C6: =VLOOKUP(A6,[7]LISTADHERENT!A$5:H$60,3,0) -> ASELBY | D6: =IF(E6="ECHEC",0,VLOOKUP($A6,[6]HISTOAVRIL25!$A$6:$BB$47,15,0)) -> 100000 | E6: =VLOOKUP($A6,[6]HISTOAVRIL25!$A$6:$BB$47,9,0) -> BANQUE | F6: =VLOOKUP($A6,[6]HISTOAVRIL25!$A$6:$BB$47,37,0) -> 0 | G6: =VLOOKUP($A6,[6]HISTOAVRIL25!$A$6:$BB$47,40,0) -> 0 | H6: =IF(G6=0,"",VLOOKUP($A6,[6]HISTOFEV25!$A$6:$AV$47,42,0)) | I6: =VLOOKUP($A6,[6]HISTOAVRIL25!$A$6:$BB$47,41,0) -> 0 | J6: =+TONTMARS25!F6+TONTMARS25!G6 -> 0 | K6: =VLOOKUP($A6,[6]HISTOAVRIL25!$A$6:$BB$47,18,0) -> 0 | L6: =IF(K6<>0,VLOOKUP($A6,[6]HISTOAVRIL25!$A$6:$BB$47,42,0),"ECHEC") -> ECHEC | M6: =IF(P6<>0,VLOOKUP($A6,[6]HISTOAVRIL25!$A$6:$BB$47,32,0),"ECHEC") -> ECHEC | N6: =VLOOKUP($A6,[6]HISTOAVRIL25!$A$6:$BB$47,33,0) -> 0 | O6: =IF(P6=0,0,($C$3-P6)) -> 0 | P6: =VLOOKUP($A6,[6]HISTOAVRIL25!$A$6:$BB$47,31,0) -> 0
A7: AS201604 | B7: =IF(D7=0,0,VLOOKUP($A7,[6]HISTOAVRIL25!$A$6:$BQ$47,14,0)) -> 2 | C7: =VLOOKUP(A7,[7]LISTADHERENT!A$5:H$60,3,0) -> DJOMO JEAN PAUL | D7: =IF(E7="ECHEC",0,VLOOKUP($A7,[6]HISTOAVRIL25!$A$6:$BB$47,15,0)) -> 200000 | E7: =VLOOKUP($A7,[6]HISTOAVRIL25!$A$6:$BB$47,9,0) -> ESPECES | F7: =VLOOKUP($A7,[6]HISTOAVRIL25!$A$6:$BB$47,37,0) -> 200000 | G7: =VLOOKUP($A7,[6]HISTOAVRIL25!$A$6:$BB$47,40,0) -> 2000 | H7: =IF(G7=0,"",VLOOKUP($A7,[6]HISTOFEV25!$A$6:$AV$47,42,0)) -> BANQUE | I7: =VLOOKUP($A7,[6]HISTOAVRIL25!$A$6:$BB$47,41,0) -> 0 | J7: =+TONTMARS25!F7+TONTMARS25!G7 -> 203500 | K7: =VLOOKUP($A7,[6]HISTOAVRIL25!$A$6:$BB$47,18,0) -> 203500 | L7: =IF(K7<>0,VLOOKUP($A7,[6]HISTOAVRIL25!$A$6:$BB$47,42,0),"ECHEC") -> BANQUE | M7: =IF(P7<>0,VLOOKUP($A7,[6]HISTOAVRIL25!$A$6:$BB$47,32,0),"ECHEC") -> ECHEC | N7: =VLOOKUP($A7,[6]HISTOAVRIL25!$A$6:$BB$47,33,0) -> 0 | O7: =IF(P7=0,0,($C$3-P7)) -> 0 | P7: =VLOOKUP($A7,[6]HISTOAVRIL25!$A$6:$BB$47,31,0) -> 0
A8: AS201605 | B8: =IF(D8=0,0,VLOOKUP($A8,[6]HISTOAVRIL25!$A$6:$BQ$47,14,0)) -> 1 | C8: =VLOOKUP(A8,[7]LISTADHERENT!A$5:H$60,3,0) -> DJOUKWE NANGUEN GUY BLAISE | D8: =IF(E8="ECHEC",0,VLOOKUP($A8,[6]HISTOAVRIL25!$A$6:$BB$47,15,0)) -> 100000 | E8: =VLOOKUP($A8,[6]HISTOAVRIL25!$A$6:$BB$47,9,0) -> BANQUE | F8: =VLOOKUP($A8,[6]HISTOAVRIL25!$A$6:$BB$47,37,0) -> 0 | G8: =VLOOKUP($A8,[6]HISTOAVRIL25!$A$6:$BB$47,40,0) -> 0 | H8: =IF(G8=0,"",VLOOKUP($A8,[6]HISTOFEV25!$A$6:$AV$47,42,0)) | I8: =VLOOKUP($A8,[6]HISTOAVRIL25!$A$6:$BB$47,41,0) -> 0 | J8: =+TONTMARS25!F8+TONTMARS25!G8 -> 0 | K8: =VLOOKUP($A8,[6]HISTOAVRIL25!$A$6:$BB$47,18,0) -> 0 | L8: =IF(K8<>0,VLOOKUP($A8,[6]HISTOAVRIL25!$A$6:$BB$47,42,0),"ECHEC") -> ECHEC | M8: =IF(P8<>0,VLOOKUP($A8,[6]HISTOAVRIL25!$A$6:$BB$47,32,0),"ECHEC") -> ECHEC | N8: =VLOOKUP($A8,[6]HISTOAVRIL25!$A$6:$BB$47,33,0) -> 0 | O8: =IF(P8=0,0,($C$3-P8)) -> 0 | P8: =VLOOKUP($A8,[6]HISTOAVRIL25!$A$6:$BB$47,31,0) -> 0
A9: AS201608 | B9: =IF(D9=0,0,VLOOKUP($A9,[6]HISTOAVRIL25!$A$6:$BQ$47,14,0)) -> 2 | C9: =VLOOKUP(A9,[7]LISTADHERENT!A$5:H$60,3,0) -> DJUOMBESSY ANTOINE | D9: =IF(E9="ECHEC",0,VLOOKUP($A9,[6]HISTOAVRIL25!$A$6:$BB$47,15,0)) -> 200000 | E9: =VLOOKUP($A9,[6]HISTOAVRIL25!$A$6:$BB$47,9,0) -> BANQUE | F9: =VLOOKUP($A9,[6]HISTOAVRIL25!$A$6:$BB$47,37,0) -> 0 | G9: =VLOOKUP($A9,[6]HISTOAVRIL25!$A$6:$BB$47,40,0) -> 0 | H9: =IF(G9=0,"",VLOOKUP($A9,[6]HISTOFEV25!$A$6:$AV$47,42,0)) | I9: =VLOOKUP($A9,[6]HISTOAVRIL25!$A$6:$BB$47,41,0) -> 0 | J9: =+TONTMARS25!F9+TONTMARS25!G9 -> 0 | K9: =VLOOKUP($A9,[6]HISTOAVRIL25!$A$6:$BB$47,18,0) -> 0 | L9: =IF(K9<>0,VLOOKUP($A9,[6]HISTOAVRIL25!$A$6:$BB$47,42,0),"ECHEC") -> ECHEC | M9: =IF(P9<>0,VLOOKUP($A9,[6]HISTOAVRIL25!$A$6:$BB$47,32,0),"ECHEC") -> ECHEC | N9: =VLOOKUP($A9,[6]HISTOAVRIL25!$A$6:$BB$47,33,0) -> 0 | O9: =IF(P9=0,0,($C$3-P9)) -> 0 | P9: =VLOOKUP($A9,[6]HISTOAVRIL25!$A$6:$BB$47,31,0) -> 0
A10: AS201663 | B10: =IF(D10=0,0,VLOOKUP($A10,[6]HISTOAVRIL25!$A$6:$BQ$47,14,0)) -> 1 | C10: =VLOOKUP(A10,[7]LISTADHERENT!A$5:H$60,3,0) -> FAMPOU PAUL | D10: =IF(E10="ECHEC",0,VLOOKUP($A10,[6]HISTOAVRIL25!$A$6:$BB$47,15,0)) -> 100000 | E10: =VLOOKUP($A10,[6]HISTOAVRIL25!$A$6:$BB$47,9,0) -> BANQUE | F10: =VLOOKUP($A10,[6]HISTOAVRIL25!$A$6:$BB$47,37,0) -> 0 | G10: =VLOOKUP($A10,[6]HISTOAVRIL25!$A$6:$BB$47,40,0) -> 0 | H10: =IF(G10=0,"",VLOOKUP($A10,[6]HISTOFEV25!$A$6:$AV$47,42,0)) | I10: =VLOOKUP($A10,[6]HISTOAVRIL25!$A$6:$BB$47,41,0) -> 0 | J10: =+TONTMARS25!F10+TONTMARS25!G10 -> 26000 | K10: =VLOOKUP($A10,[6]HISTOAVRIL25!$A$6:$BB$47,18,0) -> 26000 | L10: =IF(K10<>0,VLOOKUP($A10,[6]HISTOAVRIL25!$A$6:$BB$47,42,0),"ECHEC") -> BANQUE | M10: =IF(P10<>0,VLOOKUP($A10,[6]HISTOAVRIL25!$A$6:$BB$47,32,0),"ECHEC") -> ECHEC | N10: =VLOOKUP($A10,[6]HISTOAVRIL25!$A$6:$BB$47,33,0) -> 0 | O10: =IF(P10=0,0,($C$3-P10)) -> 0 | P10: =VLOOKUP($A10,[6]HISTOAVRIL25!$A$6:$BB$47,31,0) -> 0
A11: AS201613 | B11: =IF(D11=0,0,VLOOKUP($A11,[6]HISTOAVRIL25!$A$6:$BQ$47,14,0)) -> 1 | C11: =VLOOKUP(A11,[7]LISTADHERENT!A$5:H$60,3,0) -> HOTCHO BENJAMIN | D11: =IF(E11="ECHEC",0,VLOOKUP($A11,[6]HISTOAVRIL25!$A$6:$BB$47,15,0)) -> 100000 | E11: =VLOOKUP($A11,[6]HISTOAVRIL25!$A$6:$BB$47,9,0) -> BANQUE | F11: =VLOOKUP($A11,[6]HISTOAVRIL25!$A$6:$BB$47,37,0) -> 100000 | G11: =VLOOKUP($A11,[6]HISTOAVRIL25!$A$6:$BB$47,40,0) -> 1000 | H11: =IF(G11=0,"",VLOOKUP($A11,[6]HISTOFEV25!$A$6:$AV$47,42,0)) -> 0 | I11: =VLOOKUP($A11,[6]HISTOAVRIL25!$A$6:$BB$47,41,0) -> 0 | J11: =+TONTMARS25!F11+TONTMARS25!G11 -> 0 | K11: =VLOOKUP($A11,[6]HISTOAVRIL25!$A$6:$BB$47,18,0) -> 0 | L11: =IF(K11<>0,VLOOKUP($A11,[6]HISTOAVRIL25!$A$6:$BB$47,42,0),"ECHEC") -> ECHEC | M11: =IF(P11<>0,VLOOKUP($A11,[6]HISTOAVRIL25!$A$6:$BB$47,32,0),"ECHEC") -> BANQUE | N11: =VLOOKUP($A11,[6]HISTOAVRIL25!$A$6:$BB$47,33,0) -> 0 | O11: =IF(P11=0,0,($C$3-P11)) -> 1170000 | P11: =VLOOKUP($A11,[6]HISTOAVRIL25!$A$6:$BB$47,31,0) -> 30000
A12: AS201617 | B12: =IF(D12=0,0,VLOOKUP($A12,[6]HISTOAVRIL25!$A$6:$BQ$47,14,0)) -> 1 | C12: =VLOOKUP(A12,[7]LISTADHERENT!A$5:H$60,3,0) -> KOUAMOU MOISE | D12: =IF(E12="ECHEC",0,VLOOKUP($A12,[6]HISTOAVRIL25!$A$6:$BB$47,15,0)) -> 100000 | E12: =VLOOKUP($A12,[6]HISTOAVRIL25!$A$6:$BB$47,9,0) -> BANQUE | F12: =VLOOKUP($A12,[6]HISTOAVRIL25!$A$6:$BB$47,37,0) -> 0 | G12: =VLOOKUP($A12,[6]HISTOAVRIL25!$A$6:$BB$47,40,0) -> 0 | H12: =IF(G12=0,"",VLOOKUP($A12,[6]HISTOFEV25!$A$6:$AV$47,42,0)) | I12: =VLOOKUP($A12,[6]HISTOAVRIL25!$A$6:$BB$47,41,0) -> 0 | J12: =+TONTMARS25!F12+TONTMARS25!G12 -> 0 | K12: =VLOOKUP($A12,[6]HISTOAVRIL25!$A$6:$BB$47,18,0) -> 0 | L12: =IF(K12<>0,VLOOKUP($A12,[6]HISTOAVRIL25!$A$6:$BB$47,42,0),"ECHEC") -> ECHEC | M12: =IF(P12<>0,VLOOKUP($A12,[6]HISTOAVRIL25!$A$6:$BB$47,32,0),"ECHEC") -> ECHEC | N12: =VLOOKUP($A12,[6]HISTOAVRIL25!$A$6:$BB$47,33,0) -> 0 | O12: =IF(P12=0,0,($C$3-P12)) -> 0 | P12: =VLOOKUP($A12,[6]HISTOAVRIL25!$A$6:$BB$47,31,0) -> 0
A13: AS201619 | B13: =IF(D13=0,0,VLOOKUP($A13,[6]HISTOAVRIL25!$A$6:$BQ$47,14,0)) -> 1 | C13: =VLOOKUP(A13,[7]LISTADHERENT!A$5:H$60,3,0) -> KOUATCHO MESSACK | D13: =IF(E13="ECHEC",0,VLOOKUP($A13,[6]HISTOAVRIL25!$A$6:$BB$47,15,0)) -> 100000 | E13: =VLOOKUP($A13,[6]HISTOAVRIL25!$A$6:$BB$47,9,0) -> BANQUE | F13: =VLOOKUP($A13,[6]HISTOAVRIL25!$A$6:$BB$47,37,0) -> 100000 | G13: =VLOOKUP($A13,[6]HISTOAVRIL25!$A$6:$BB$47,40,0) -> 1000 | H13: =IF(G13=0,"",VLOOKUP($A13,[6]HISTOFEV25!$A$6:$AV$47,42,0)) -> BANQUE | I13: =VLOOKUP($A13,[6]HISTOAVRIL25!$A$6:$BB$47,41,0) -> 0 | J13: =+TONTMARS25!F13+TONTMARS25!G13 -> 207500 | K13: =VLOOKUP($A13,[6]HISTOAVRIL25!$A$6:$BB$47,18,0) -> 207500 | L13: =IF(K13<>0,VLOOKUP($A13,[6]HISTOAVRIL25!$A$6:$BB$47,42,0),"ECHEC") -> BANQUE | M13: =IF(P13<>0,VLOOKUP($A13,[6]HISTOAVRIL25!$A$6:$BB$47,32,0),"ECHEC") -> ECHEC | N13: =VLOOKUP($A13,[6]HISTOAVRIL25!$A$6:$BB$47,33,0) -> 0 | O13: =IF(P13=0,0,($C$3-P13)) -> 0 | P13: =VLOOKUP($A13,[6]HISTOAVRIL25!$A$6:$BB$47,31,0) -> 0
A14: AS201649 | B14: =IF(D14=0,0,VLOOKUP($A14,[6]HISTOAVRIL25!$A$6:$BQ$47,14,0)) -> 2 | C14: =VLOOKUP(A14,[7]LISTADHERENT!A$5:H$60,3,0) -> MBOGNING TUGMA GUY | D14: =IF(E14="ECHEC",0,VLOOKUP($A14,[6]HISTOAVRIL25!$A$6:$BB$47,15,0)) -> 200000 | E14: =VLOOKUP($A14,[6]HISTOAVRIL25!$A$6:$BB$47,9,0) -> BANQUE | F14: =VLOOKUP($A14,[6]HISTOAVRIL25!$A$6:$BB$47,37,0) -> 200000 | G14: =VLOOKUP($A14,[6]HISTOAVRIL25!$A$6:$BB$47,40,0) -> 2000 | H14: =IF(G14=0,"",VLOOKUP($A14,[6]HISTOFEV25!$A$6:$AV$47,42,0)) -> BANQUE | I14: =VLOOKUP($A14,[6]HISTOAVRIL25!$A$6:$BB$47,41,0) -> 0 | J14: =+TONTMARS25!F14+TONTMARS25!G14 -> 202000 | K14: =VLOOKUP($A14,[6]HISTOAVRIL25!$A$6:$BB$47,18,0) -> 202000 | L14: =IF(K14<>0,VLOOKUP($A14,[6]HISTOAVRIL25!$A$6:$BB$47,42,0),"ECHEC") -> BANQUE | M14: =IF(P14<>0,VLOOKUP($A14,[6]HISTOAVRIL25!$A$6:$BB$47,32,0),"ECHEC") -> ECHEC | N14: =VLOOKUP($A14,[6]HISTOAVRIL25!$A$6:$BB$47,33,0) -> 0 | O14: =IF(P14=0,0,($C$3-P14)) -> 0 | P14: =VLOOKUP($A14,[6]HISTOAVRIL25!$A$6:$BB$47,31,0) -> 0
A15: AS201622 | B15: =IF(D15=0,0,VLOOKUP($A15,[6]HISTOAVRIL25!$A$6:$BQ$47,14,0)) -> 2 | C15: =VLOOKUP(A15,[7]LISTADHERENT!A$5:H$60,3,0) -> NDJOMO ETIENNE | D15: =IF(E15="ECHEC",0,VLOOKUP($A15,[6]HISTOAVRIL25!$A$6:$BB$47,15,0)) -> 200000 | E15: =VLOOKUP($A15,[6]HISTOAVRIL25!$A$6:$BB$47,9,0) -> BANQUE | F15: =VLOOKUP($A15,[6]HISTOAVRIL25!$A$6:$BB$47,37,0) -> 193000 | G15: =VLOOKUP($A15,[6]HISTOAVRIL25!$A$6:$BB$47,40,0) -> 2500 | H15: =IF(G15=0,"",VLOOKUP($A15,[6]HISTOFEV25!$A$6:$AV$47,42,0)) -> BANQUE | I15: =VLOOKUP($A15,[6]HISTOAVRIL25!$A$6:$BB$47,41,0) -> 0 | J15: =+TONTMARS25!F15+TONTMARS25!G15 -> 101000 | K15: =VLOOKUP($A15,[6]HISTOAVRIL25!$A$6:$BB$47,18,0) -> 101000 | L15: =IF(K15<>0,VLOOKUP($A15,[6]HISTOAVRIL25!$A$6:$BB$47,42,0),"ECHEC") -> BANQUE | M15: =IF(P15<>0,VLOOKUP($A15,[6]HISTOAVRIL25!$A$6:$BB$47,32,0),"ECHEC") -> ECHEC | N15: =VLOOKUP($A15,[6]HISTOAVRIL25!$A$6:$BB$47,33,0) -> 0 | O15: =IF(P15=0,0,($C$3-P15)) -> 0 | P15: =VLOOKUP($A15,[6]HISTOAVRIL25!$A$6:$BB$47,31,0) -> 0
