Workbook
Name BANQUE: #REF!
Name BANQUE: #REF!
Name BANQUE: #REF!
Name BANQUE: #REF!
Name BANQUE: #REF!
Name BANQUE: #REF!
Name BANQUE: #REF!
Name BANQUE: #REF!
Name BANQUE: #REF!
Name BANQUE: #REF!
Name BANQUE: #REF!
Name BANQUE: #REF!
Name BANQUE: #REF!
Name BANQUE: #REF!
Name BANQUE: #REF!
Name BANQUE: #REF!
Name BANQUE: #REF!
Name BANQUE: #REF!
Name BANQUE: #REF!
Name BANQUE: #REF!
Name BANQUE: #REF!
Name BANQUE: #REF!
Name BANQUE: #REF!
Name BANQUE: #REF!
Name BANQUE: #REF!
Name BANQUE: #REF!
Name BANQUE: #REF!
Name BANQUE: #REF!
Name BANQUE: #REF!
Name MODEPAID: [1]Feuil2!$A$1:$A$3
Name MODET25000: [2]MODEVERSEMENT!$A$1:$A$3
Name MODEVERSEMENT: #REF!
Name MODEVERSEMENT: #REF!
Name MODEVERSEMENT: #REF!
Name MODEVERSEMENT: #REF!
Name MODEVERSEMENT: #REF!
Name MODEVERSEMENT: #REF!
Name MODEVERSEMENT: #REF!
Name MODEVERSEMENT: #REF!
Name MODEVERSEMENT: #REF!
Name MODEVERSEMENT: #REF!
Name MODEVERSEMENT: #REF!
Name MODEVERSEMENT: #REF!
Name MODEVERSEMENT: #REF!
Name MODEVERSEMENT: #REF!
Name MODEVERSEMENT: #REF!
Name MODEVERSEMENT: #REF!
Name MODEVERSEMENT: #REF!
Name MODEVERSEMENT: #REF!
Name MODEVERSEMENT: #REF!
Name MODEVERSEMENT: #REF!
Name MODEVERSEMENT: #REF!
Name MODEVERSEMENT: #REF!
Name MODEVERSEMENT: #REF!
Name MODEVERSEMENT: #REF!
Name MODEVERSEMENT: #REF!
Name MODEVERSEMENT: #REF!
Name MODEVERSEMENT: #REF!
Name MODEVERSEMENT: #REF!
Name MODEVERSEMENT: #REF!

Sheet MODEVERSEMENT
A2: OK

Sheet COMPTE BANQUE
C1: COMPTE BANQUE | H1: COMPTE CAISSE
A2: ANNEE | C2: 2021 | H2: 2021
A4: MOIS | B4: NUMERO CHEQUE | C4: SORTIE | D4: ENTREE | E4: SOLDE | G4: NUMERO PIECE | H4: ENTREE | I4: SORTIE | J4: SOLDE
A5: REPORT A NOUVEAU | E5: =14283661-6017000 -> 8266661
A6: JANVIER | C6: =#REF! -> #REF! | D6: =#REF! -> #REF! | E6: =IF(D6=0,0,E5+D6-C6) -> #REF!
A7: FÉVRIER | C7: =#REF! -> #REF! | D7: =#REF! -> #REF! | E7: =IF(D7=0,0,E6+D7-C7) -> #REF!
A8: MARS | C8: =#REF! -> #REF! | D8: =#REF! -> #REF! | E8: =IF(D8=0,0,E7+D8-C8) -> #REF!
A9: AVRIL | C9: =#REF! -> #REF! | D9: =#REF! -> #REF! | E9: =IF(D9=0,0,E8+D9-C9) -> #REF!
A10: MAI | C10: =#REF! -> #REF! | D10: =#REF! -> #REF! | E10: =IF(D10=0,0,E9+D10-C10) -> #REF!
A11: JUIN | C11: =#REF! -> #REF! | D11: =#REF! -> #REF! | E11: =IF(D11=0,0,E10+D11-C11) -> #REF!
A12: JUILLET | C12: =#REF! -> #REF! | D12: =#REF! -> #REF! | E12: =IF(D12=0,0,E11+D12-C12) -> #REF!
A13: AOÛT | C13: =#REF! -> #REF! | D13: =#REF! -> #REF! | E13: =IF(D13=0,0,E12+D13-C13) -> #REF!
A14: SEPTEMBRE | C14: =#REF! -> #REF! | D14: =#REF! -> #REF! | E14: =IF(D14=0,0,E13+D14-C14) -> #REF!
A15: OCTOBRE | C15: =#REF! -> #REF! | D15: =#REF! -> #REF! | E15: =IF(D15=0,0,E14+D15-C15) -> #REF!
A16: NOVEMBRE | C16: =#REF! -> #REF! | D16: =#REF! -> #REF! | E16: =IF(D16=0,0,E15+D16-C16) -> #REF!
A17: DÉCEMBRE | C17: =#REF! -> #REF! | D17: =#REF! -> #REF! | E17: =IF(D17=0,0,E16+D17-C17) -> #REF!
A19: TOTAL

Sheet HISTOBQUEJANV25
A1: ASSOCIATION | B1: ASELBY | C1: 45658
A2: ANNEE | B2: 2025
A3: 1 | B3: 2 | C3: 3 | D3: 4 | E3: 5 | F3: 6 | G3: 7
B4: HISTORIQUE BANCAIRE
A5: MATRICULE | B5: NOM ET PRENOM | C5: HISTORIQUE TONTINE | D5: HITORIQUE ESPECES | E5: HITORIQUE BANQUE | F5: AUTRE VERSEMENT | G5: MONTANT ENGAGEMENT | H5: AGIO
A6: AS201648 | B6: =VLOOKUP(A6,[5]LISTADHERENT!$A$4:$J$44,3,0) -> ASELBY | C6: =IF(G6>0,VLOOKUP(A6,[6]HISTOJANV25!$A$6:$BQ$46,25,0),0) -> 250000 | E6: 250000 | G6: =SUM(D6:F6) -> 250000 | H6: =2385+2000+385 -> 4770
A7: AS201601 | B7: =VLOOKUP(A7,[5]LISTADHERENT!$A$4:$J$44,3,0) -> BAKOP ACHILLE | C7: =IF(G7>0,VLOOKUP(A7,[6]HISTOJANV25!$A$6:$BQ$46,25,0),0) -> 50000 | D7: 50000 | G7: =D7+E7+F7 -> 50000
A8: AS201602 | B8: =VLOOKUP(A8,[5]LISTADHERENT!$A$4:$J$44,3,0) -> BOUTCHOUANG WILLIAM | C8: =IF(G8>0,VLOOKUP(A8,[6]HISTOJANV25!$A$6:$BQ$46,25,0),0) -> 125000 | E8: 125000 | G8: =D8+E8+F8 -> 125000
A9: AS201604 | B9: =VLOOKUP(A9,[5]LISTADHERENT!$A$4:$J$44,3,0) -> DJOMO JEAN PAUL | C9: =IF(G9>0,VLOOKUP(A9,[6]HISTOJANV25!$A$6:$BQ$46,25,0),0) -> 250000 | E9: 250000 | G9: =D9+E9+F9 -> 250000
A10: AS201654 | B10: =VLOOKUP(A10,[5]LISTADHERENT!$A$4:$J$44,3,0) -> DJOMOU TCHAPDA | C10: =IF(G10>0,VLOOKUP(A10,[6]HISTOJANV25!$A$6:$BQ$46,25,0),0) -> 50000 | D10: 50000 | G10: =D10+E10+F10 -> 50000
A11: AS201605 | B11: =VLOOKUP(A11,[5]LISTADHERENT!$A$4:$J$44,3,0) -> DJOUKWE NANGUEN GUY BLAISE | C11: =IF(G11>0,VLOOKUP(A11,[6]HISTOJANV25!$A$6:$BQ$46,25,0),0) -> 150000 | E11: 150000 | G11: =D11+E11+F11 -> 150000
A12: AS201608 | B12: =VLOOKUP(A12,[5]LISTADHERENT!$A$4:$J$44,3,0) -> DJUOMBESSY ANTOINE | C12: =IF(G12>0,VLOOKUP(A12,[6]HISTOJANV25!$A$6:$BQ$46,25,0),0) -> 250000 | E12: 260000 | G12: =D12+E12+F12 -> 260000
A13: AS201651 | B13: =VLOOKUP(A13,[5]LISTADHERENT!$A$4:$J$44,3,0) -> DOMOU FABIEN | C13: =IF(G13>0,VLOOKUP(A13,[6]HISTOJANV25!$A$6:$BQ$46,25,0),0) -> 50000 | E13: 50000 | G13: =D13+E13+F13 -> 50000
A14: AS201609 | B14: =VLOOKUP(A14,[5]LISTADHERENT!$A$4:$J$44,3,0) -> DONHOU DAVID | C14: =IF(G14>0,VLOOKUP(A14,[6]HISTOJANV25!$A$6:$BQ$46,25,0),0) -> 50000 | E14: 50000 | G14: =D14+E14+F14 -> 50000
A15: AS201663 | B15: =VLOOKUP(A15,[5]LISTADHERENT!$A$4:$J$44,3,0) -> FAMPOU PAUL | C15: =IF(G15>0,VLOOKUP(A15,[6]HISTOJANV25!$A$6:$BQ$46,25,0),0) -> 0 | G15: =D15+E15+F15 -> 0
A16: AS201611 | B16: =VLOOKUP(A16,[5]LISTADHERENT!$A$4:$J$44,3,0) -> HENGUE PAUL OMER | C16: =IF(G16>0,VLOOKUP(A16,[6]HISTOJANV25!$A$6:$BQ$46,25,0),0) -> 125000 | E16: 125000 | G16: =D16+E16+F16 -> 125000
A17: AS201613 | B17: =VLOOKUP(A17,[5]LISTADHERENT!$A$4:$J$44,3,0) -> HOTCHO BENJAMIN | C17: =IF(G17>0,VLOOKUP(A17,[6]HISTOJANV25!$A$6:$BQ$46,25,0),0) -> 225000 | D17: 25000 | E17: 250000 | G17: =D17+E17+F17 -> 275000
A18: AS201617 | B18: =VLOOKUP(A18,[5]LISTADHERENT!$A$4:$J$44,3,0) -> KOUAMOU MOISE | C18: =IF(G18>0,VLOOKUP(A18,[6]HISTOJANV25!$A$6:$BQ$46,25,0),0) -> 150000 | E18: 150000 | F18: 346500 | G18: =D18+E18+F18 -> 496500
A19: AS201619 | B19: =VLOOKUP(A19,[5]LISTADHERENT!$A$4:$J$44,3,0) -> KOUATCHO MESSACK | C19: =IF(G19>0,VLOOKUP(A19,[6]HISTOJANV25!$A$6:$BQ$46,25,0),0)-75000 -> 150000 | E19: 160000 | G19: =D19+E19+F19 -> 160000
A20: AS201620 | B20: =VLOOKUP(A20,[5]LISTADHERENT!$A$4:$J$44,3,0) -> LOWE JEAN
A21: AS201661 | B21: =VLOOKUP(A21,[5]LISTADHERENT!$A$4:$J$44,3,0) -> MASSEUNGOUE DAGOBERT | C21: =IF(G21>0,VLOOKUP(A21,[6]HISTOJANV25!$A$6:$BQ$46,25,0),0) -> 50000 | E21: 650000 | G21: =D21+E21+F21 -> 650000
A22: AS201649 | B22: =VLOOKUP(A22,[5]LISTADHERENT!$A$4:$J$44,3,0) -> MBOGNING TUGMA GUY | C22: =IF(G22>0,VLOOKUP(A22,[6]HISTOJANV25!$A$6:$BQ$46,25,0),0) -> 325000 | E22: 325000 | G22: =D22+E22+F22 -> 325000
A23: AS201639 | B23: =VLOOKUP(A23,[5]LISTADHERENT!$A$4:$J$44,3,0) -> NANGUEN MARTIN | C23: =IF(G23>0,VLOOKUP(A23,[6]HISTOJANV25!$A$6:$BQ$46,25,0),0) -> 50000 | E23: 50000 | G23: =D23+E23+F23 -> 50000
A24: AS201621 | B24: =VLOOKUP(A24,[5]LISTADHERENT!$A$4:$J$44,3,0) -> NANKAM APPOLINAIRE | C24: =IF(G24>0,VLOOKUP(A24,[6]HISTOJANV25!$A$6:$BQ$46,25,0),0) -> 125000 | E24: 125000 | G24: =D24+E24+F24 -> 125000
A25: AS201622 | B25: =VLOOKUP(A25,[5]LISTADHERENT!$A$4:$J$44,3,0) -> NDJOMO ETIENNE | C25: =IF(G25>0,VLOOKUP(A25,[6]HISTOJANV25!$A$6:$BQ$46,25,0),0) -> 250000 | E25: 260000 | G25: =D25+E25+F25 -> 260000
A26: AS201624 | B26: =VLOOKUP(A26,[5]LISTADHERENT!$A$4:$J$44,3,0) -> NGONDIEP CLAUDE | C26: =IF(G26>0,VLOOKUP(A26,[6]HISTOJANV25!$A$6:$BQ$46,25,0),0) -> 225000 | E26: 240000 | G26: =D26+E26+F26 -> 240000
A27: AS201626 | B27: =VLOOKUP(A27,[5]LISTADHERENT!$A$4:$J$44,3,0) -> NGUIEMEGNI MATHIEU BLAISE | C27: =IF(G27>0,VLOOKUP(A27,[6]HISTOJANV25!$A$6:$BQ$46,25,0),0) -> 250000 | D27: 25000 | E27: 225000 | G27: =D27+E27+F27 -> 250000
A28: AS201628 | B28: =VLOOKUP(A28,[5]LISTADHERENT!$A$4:$J$44,3,0) -> NKAMGANG JUSTIN DEJOLIE | C28: =IF(G28>0,VLOOKUP(A28,[6]HISTOJANV25!$A$6:$BQ$46,25,0),0) -> 50000 | E28: 50000 | G28: =D28+E28+F28 -> 50000
A29: AS201656 | B29: =VLOOKUP(A29,[5]LISTADHERENT!$A$4:$J$44,3,0) -> NOUBE ETIENNE | C29: =IF(G29>0,VLOOKUP(A29,[6]HISTOJANV25!$A$6:$BQ$46,25,0),0) -> 50000 | E29: 50000 | G29: =D29+E29+F29 -> 50000
A30: AS201633 | B30: =VLOOKUP(A30,[5]LISTADHERENT!$A$4:$J$44,3,0) -> PATEGO NJOSSU GUSTAVE | C30: =IF(G30>0,VLOOKUP(A30,[6]HISTOJANV25!$A$6:$BQ$46,25,0),0) -> 125000 | E30: 125000 | G30: =D30+E30+F30 -> 125000
A31: AS201657 | B31: =VLOOKUP(A31,[5]LISTADHERENT!$A$4:$J$44,3,0) -> SEUMO POLYCARPE | C31: =IF(G31>0,VLOOKUP(A31,[6]HISTOJANV25!$A$6:$BQ$46,25,0),0) -> 50000 | E31: 50000 | G31: =D31+E31+F31 -> 50000
A32: AS201653 | B32: =VLOOKUP(A32,[5]LISTADHERENT!$A$4:$J$44,3,0) -> SIME BRICE | C32: =IF(G32>0,VLOOKUP(A32,[6]HISTOJANV25!$A$6:$BQ$46,25,0),0) -> 250000 | E32: 250000 | G32: =D32+E32+F32 -> 250000
A33: AS201629 | B33: =VLOOKUP(A33,[5]LISTADHERENT!$A$4:$J$44,3,0) -> SIMO FONGANG ERIC | C33: =IF(G33>0,VLOOKUP(A33,[6]HISTOJANV25!$A$6:$BQ$46,25,0),0) -> 50000 | E33: 50000 | G33: =D33+E33+F33 -> 50000
A34: AS201638 | B34: =VLOOKUP(A34,[5]LISTADHERENT!$A$4:$J$44,3,0) -> SIMO PIERRE | C34: =IF(G34>0,VLOOKUP(A34,[6]HISTOJANV25!$A$6:$BQ$46,25,0),0) -> 150000 | E34: =100000+50000 -> 150000 | G34: =D34+E34+F34 -> 150000
A35: AS201641 | B35: =VLOOKUP(A35,[5]LISTADHERENT!$A$4:$J$44,3,0) -> TCHOUAMOU MATHIEU | C35: =IF(G35>0,VLOOKUP(A35,[6]HISTOJANV25!$A$6:$BQ$46,25,0),0) -> 125000 | E35: 125000 | G35: =D35+E35+F35 -> 125000
A36: AS201660 | B36: =VLOOKUP(A36,[5]LISTADHERENT!$A$4:$J$44,3,0) -> TCHOUATEU AUGUSTIN | C36: =IF(G36>0,VLOOKUP(A36,[6]HISTOJANV25!$A$6:$BQ$46,25,0),0) -> 150000 | E36: 150000 | G36: =D36+E36+F36 -> 150000
A37: AS201643 | B37: =VLOOKUP(A37,[5]LISTADHERENT!$A$4:$J$44,3,0) -> TCHOUTOU NANA CLAUDE | C37: =IF(G37>0,VLOOKUP(A37,[6]HISTOJANV25!$A$6:$BQ$46,25,0),0) -> 50000 | E37: 50000 | G37: =D37+E37+F37 -> 50000
A38: AS201662 | B38: =VLOOKUP(A38,[5]LISTADHERENT!$A$4:$J$44,3,0) -> TIEYAM ERNEST | C38: =IF(G38>0,VLOOKUP(A38,[6]HISTOJANV25!$A$6:$BQ$46,25,0),0) -> 50000 | D38: 50000 | G38: =D38+E38+F38 -> 50000
A39: AS201658 | B39: =VLOOKUP(A39,[5]LISTADHERENT!$A$4:$J$44,3,0) -> YANTCHOU GERVAIS | C39: =IF(G39>0,VLOOKUP(A39,[6]HISTOJANV25!$A$6:$BQ$46,25,0),0) -> 125000 | D39: 25000 | E39: 100000 | G39: =D39+E39+F39 -> 125000
A40: AS201646 | B40: =VLOOKUP(A40,[5]LISTADHERENT!$A$4:$J$44,3,0) -> YEPMOU JEAN JACQUES | C40: =IF(G40>0,VLOOKUP(A40,[6]HISTOJANV25!$A$6:$BQ$46,25,0),0) -> 50000 | D40: 50000 | G40: =D40+E40+F40 -> 50000
...

Sheet HISTOBQUEFEV25
A1: ASSOCIATION | B1: ASELBY | C1: 45689
A2: ANNEE | B2: 2025
A3: 1 | B3: 2 | C3: 3 | D3: 4 | E3: 5 | F3: 6 | G3: 7
B4: HISTORIQUE BANCAIRE
A5: MATRICULE | B5: NOM ET PRENOM | C5: HISTORIQUE TONTINE | D5: HITORIQUE ESPECES | E5: HITORIQUE BANQUE | F5: AUTRE VERSEMENT | G5: MONTANT ENGAGEMENT | H5: AGIO
A6: AS201648 | B6: =VLOOKUP(A6,[5]LISTADHERENT!$A$4:$J$44,3,0) -> ASELBY | C6: =IF(G6>0,VLOOKUP(A6,[6]HISTOJANV25!$A$6:$BQ$46,25,0),0) -> 250000 | E6: 250000 | G6: =SUM(D6:F6) -> 250000 | H6: 1191
A7: AS201601 | B7: =VLOOKUP(A7,[5]LISTADHERENT!$A$4:$J$44,3,0) -> BAKOP ACHILLE | C7: =IF(G7>0,VLOOKUP(A7,[6]HISTOJANV25!$A$6:$BQ$46,25,0),0) -> 50000 | D7: 50000 | G7: =D7+E7+F7 -> 50000
A8: AS201602 | B8: =VLOOKUP(A8,[5]LISTADHERENT!$A$4:$J$44,3,0) -> BOUTCHOUANG WILLIAM | C8: =IF(G8>0,VLOOKUP(A8,[6]HISTOJANV25!$A$6:$BQ$46,25,0),0) -> 125000 | E8: 125000 | G8: =D8+E8+F8 -> 125000
A9: AS201604 | B9: =VLOOKUP(A9,[5]LISTADHERENT!$A$4:$J$44,3,0) -> DJOMO JEAN PAUL | C9: =IF(G9>0,VLOOKUP(A9,[6]HISTOJANV25!$A$6:$BQ$46,25,0),0) -> 250000 | E9: =100000+150000 -> 250000 | G9: =D9+E9+F9 -> 250000
A10: AS201654 | B10: =VLOOKUP(A10,[5]LISTADHERENT!$A$4:$J$44,3,0) -> DJOMOU TCHAPDA | C10: =IF(G10>0,VLOOKUP(A10,[6]HISTOJANV25!$A$6:$BQ$46,25,0),0) -> 50000 | E10: 50000 | G10: =D10+E10+F10 -> 50000
A11: AS201605 | B11: =VLOOKUP(A11,[5]LISTADHERENT!$A$4:$J$44,3,0) -> DJOUKWE NANGUEN GUY BLAISE | C11: =IF(G11>0,VLOOKUP(A11,[6]HISTOJANV25!$A$6:$BQ$46,25,0),0) -> 150000 | E11: =226000-76000+375 -> 150375 | G11: =D11+E11+F11 -> 150375
A12: AS201608 | B12: =VLOOKUP(A12,[5]LISTADHERENT!$A$4:$J$44,3,0) -> DJUOMBESSY ANTOINE | C12: =IF(G12>0,VLOOKUP(A12,[6]HISTOJANV25!$A$6:$BQ$46,25,0),0) -> 250000 | E12: =600000+310000 -> 910000 | G12: =D12+E12+F12 -> 910000
A13: AS201651 | B13: =VLOOKUP(A13,[5]LISTADHERENT!$A$4:$J$44,3,0) -> DOMOU FABIEN | C13: =IF(G13>0,VLOOKUP(A13,[6]HISTOJANV25!$A$6:$BQ$46,25,0),0) -> 50000 | E13: 50000 | G13: =D13+E13+F13 -> 50000
A14: AS201609 | B14: =VLOOKUP(A14,[5]LISTADHERENT!$A$4:$J$44,3,0) -> DONHOU DAVID | C14: =IF(G14>0,VLOOKUP(A14,[6]HISTOJANV25!$A$6:$BQ$46,25,0),0) -> 50000 | E14: 50000 | G14: =D14+E14+F14 -> 50000
A15: AS201663 | B15: =VLOOKUP(A15,[5]LISTADHERENT!$A$4:$J$44,3,0) -> FAMPOU PAUL | C15: =IF(G15>0,VLOOKUP(A15,[6]HISTOJANV25!$A$6:$BQ$46,25,0),0) -> 0 | D15: 125000 | G15: =D15+E15+F15 -> 125000
A16: AS201611 | B16: =VLOOKUP(A16,[5]LISTADHERENT!$A$4:$J$44,3,0) -> HENGUE PAUL OMER | C16: =IF(G16>0,VLOOKUP(A16,[6]HISTOJANV25!$A$6:$BQ$46,25,0),0) -> 125000 | E16: 125000 | G16: =D16+E16+F16 -> 125000
A17: AS201613 | B17: =VLOOKUP(A17,[5]LISTADHERENT!$A$4:$J$44,3,0) -> HOTCHO BENJAMIN | C17: =IF(G17>0,VLOOKUP(A17,[6]HISTOJANV25!$A$6:$BQ$46,25,0),0) -> 225000 | E17: 260000 | G17: =D17+E17+F17 -> 260000
A18: AS201617 | B18: =VLOOKUP(A18,[5]LISTADHERENT!$A$4:$J$44,3,0) -> KOUAMOU MOISE | C18: =IF(G18>0,VLOOKUP(A18,[6]HISTOJANV25!$A$6:$BQ$46,25,0),0) -> 150000 | E18: 150000 | G18: =D18+E18+F18 -> 150000
A19: AS201619 | B19: =VLOOKUP(A19,[5]LISTADHERENT!$A$4:$J$44,3,0) -> KOUATCHO MESSACK | C19: =IF(G19>0,VLOOKUP(A19,[6]HISTOJANV25!$A$6:$BQ$46,25,0),0) -> 225000 | E19: =235000+75000 -> 310000 | G19: =D19+E19+F19 -> 310000
A20: AS201620 | B20: =VLOOKUP(A20,[5]LISTADHERENT!$A$4:$J$44,3,0) -> LOWE JEAN
A21: AS201661 | B21: =VLOOKUP(A21,[5]LISTADHERENT!$A$4:$J$44,3,0) -> MASSEUNGOUE DAGOBERT | C21: =IF(G21>0,VLOOKUP(A21,[6]HISTOJANV25!$A$6:$BQ$46,25,0),0) -> 50000 | E21: 50000 | G21: =D21+E21+F21 -> 50000
A22: AS201649 | B22: =VLOOKUP(A22,[5]LISTADHERENT!$A$4:$J$44,3,0) -> MBOGNING TUGMA GUY | C22: =IF(G22>0,VLOOKUP(A22,[6]HISTOJANV25!$A$6:$BQ$46,25,0),0) -> 325000 | E22: 325000 | G22: =D22+E22+F22 -> 325000
A23: AS201639 | B23: =VLOOKUP(A23,[5]LISTADHERENT!$A$4:$J$44,3,0) -> NANGUEN MARTIN | C23: =IF(G23>0,VLOOKUP(A23,[6]HISTOJANV25!$A$6:$BQ$46,25,0),0) -> 50000 | E23: 50000 | G23: =D23+E23+F23 -> 50000
A24: AS201621 | B24: =VLOOKUP(A24,[5]LISTADHERENT!$A$4:$J$44,3,0) -> NANKAM APPOLINAIRE | C24: =IF(G24>0,VLOOKUP(A24,[6]HISTOJANV25!$A$6:$BQ$46,25,0),0) -> 125000 | E24: 125000 | F24: 892500 | G24: =D24+E24+F24 -> 1017500
A25: AS201622 | B25: =VLOOKUP(A25,[5]LISTADHERENT!$A$4:$J$44,3,0) -> NDJOMO ETIENNE | C25: =IF(G25>0,VLOOKUP(A25,[6]HISTOJANV25!$A$6:$BQ$46,25,0),0) -> 250000 | E25: 260000 | G25: =D25+E25+F25 -> 260000
A26: AS201624 | B26: =VLOOKUP(A26,[5]LISTADHERENT!$A$4:$J$44,3,0) -> NGONDIEP CLAUDE | C26: =IF(G26>0,VLOOKUP(A26,[6]HISTOJANV25!$A$6:$BQ$46,25,0),0) -> 225000 | E26: 240000 | G26: =D26+E26+F26 -> 240000
A27: AS201626 | B27: =VLOOKUP(A27,[5]LISTADHERENT!$A$4:$J$44,3,0) -> NGUIEMEGNI MATHIEU BLAISE | C27: =IF(G27>0,VLOOKUP(A27,[6]HISTOJANV25!$A$6:$BQ$46,25,0),0) -> 250000 | D27: 25000 | E27: 225000 | G27: =D27+E27+F27 -> 250000
A28: AS201628 | B28: =VLOOKUP(A28,[5]LISTADHERENT!$A$4:$J$44,3,0) -> NKAMGANG JUSTIN DEJOLIE | C28: =IF(G28>0,VLOOKUP(A28,[6]HISTOJANV25!$A$6:$BQ$46,25,0),0) -> 50000 | E28: 100000 | G28: =D28+E28+F28 -> 100000
A29: AS201656 | B29: =VLOOKUP(A29,[5]LISTADHERENT!$A$4:$J$44,3,0) -> NOUBE ETIENNE | C29: =IF(G29>0,VLOOKUP(A29,[6]HISTOJANV25!$A$6:$BQ$46,25,0),0) -> 50000 | E29: 50000 | G29: =D29+E29+F29 -> 50000
A30: AS201633 | B30: =VLOOKUP(A30,[5]LISTADHERENT!$A$4:$J$44,3,0) -> PATEGO NJOSSU GUSTAVE | C30: =IF(G30>0,VLOOKUP(A30,[6]HISTOJANV25!$A$6:$BQ$46,25,0),0) -> 125000 | E30: 125000 | G30: =D30+E30+F30 -> 125000
A31: AS201657 | B31: =VLOOKUP(A31,[5]LISTADHERENT!$A$4:$J$44,3,0) -> SEUMO POLYCARPE | C31: =IF(G31>0,VLOOKUP(A31,[6]HISTOJANV25!$A$6:$BQ$46,25,0),0) -> 50000 | E31: 50000 | G31: =D31+E31+F31 -> 50000
A32: AS201653 | B32: =VLOOKUP(A32,[5]LISTADHERENT!$A$4:$J$44,3,0) -> SIME BRICE | C32: =IF(G32>0,VLOOKUP(A32,[6]HISTOJANV25!$A$6:$BQ$46,25,0),0) -> 250000 | E32: 250000 | G32: =D32+E32+F32 -> 250000
A33: AS201629 | B33: =VLOOKUP(A33,[5]LISTADHERENT!$A$4:$J$44,3,0) -> SIMO FONGANG ERIC | C33: =IF(G33>0,VLOOKUP(A33,[6]HISTOJANV25!$A$6:$BQ$46,25,0),0) -> 50000 | E33: 50000 | G33: =D33+E33+F33 -> 50000
A34: AS201638 | B34: =VLOOKUP(A34,[5]LISTADHERENT!$A$4:$J$44,3,0) -> SIMO PIERRE | C34: =IF(G34>0,VLOOKUP(A34,[6]HISTOJANV25!$A$6:$BQ$46,25,0),0) -> 150000 | E34: =100000+50000 -> 150000 | G34: =D34+E34+F34 -> 150000
A35: AS201641 | B35: =VLOOKUP(A35,[5]LISTADHERENT!$A$4:$J$44,3,0) -> TCHOUAMOU MATHIEU | C35: =IF(G35>0,VLOOKUP(A35,[6]HISTOJANV25!$A$6:$BQ$46,25,0),0) -> 125000 | E35: 125000 | G35: =D35+E35+F35 -> 125000
A36: AS201660 | B36: =VLOOKUP(A36,[5]LISTADHERENT!$A$4:$J$44,3,0) -> TCHOUATEU AUGUSTIN | C36: =IF(G36>0,VLOOKUP(A36,[6]HISTOJANV25!$A$6:$BQ$46,25,0),0) -> 150000 | E36: 150000 | G36: =D36+E36+F36 -> 150000
A37: AS201643 | B37: =VLOOKUP(A37,[5]LISTADHERENT!$A$4:$J$44,3,0) -> TCHOUTOU NANA CLAUDE | C37: =IF(G37>0,VLOOKUP(A37,[6]HISTOJANV25!$A$6:$BQ$46,25,0),0) -> 50000 | E37: 50000 | G37: =D37+E37+F37 -> 50000
A38: AS201662 | B38: =VLOOKUP(A38,[5]LISTADHERENT!$A$4:$J$44,3,0) -> TIEYAM ERNEST | C38: =IF(G38>0,VLOOKUP(A38,[6]HISTOJANV25!$A$6:$BQ$46,25,0),0) -> 50000 | D38: 50000 | G38: =D38+E38+F38 -> 50000
A39: AS201658 | B39: =VLOOKUP(A39,[5]LISTADHERENT!$A$4:$J$44,3,0) -> YANTCHOU GERVAIS | C39: =IF(G39>0,VLOOKUP(A39,[6]HISTOJANV25!$A$6:$BQ$46,25,0),0) -> 125000 | E39: 125000 | G39: =D39+E39+F39 -> 125000
A40: AS201646 | B40: =VLOOKUP(A40,[5]LISTADHERENT!$A$4:$J$44,3,0) -> YEPMOU JEAN JACQUES | C40: =IF(G40>0,VLOOKUP(A40,[6]HISTOJANV25!$A$6:$BQ$46,25,0),0) -> 50000 | D40: 50000 | G40: =D40+E40+F40 -> 50000
...

Sheet HISTOBQUEMARS25
A1: ASSOCIATION | B1: ASELBY | C1: 45717
A2: ANNEE | B2: 2025
A3: 1 | B3: 2 | C3: 3 | D3: 4 | E3: 5 | F3: 6 | G3: 7
B4: HISTORIQUE BANCAIRE
A5: MATRICULE | B5: NOM ET PRENOM | C5: HISTORIQUE TONTINE | D5: HITORIQUE ESPECES | E5: HITORIQUE BANQUE | F5: AUTRE VERSEMENT | G5: MONTANT ENGAGEMENT | H5: AGIO
A6: AS201648 | B6: =VLOOKUP(A6,[5]LISTADHERENT!$A$4:$J$44,3,0) -> ASELBY | C6: =IF(G6>0,VLOOKUP(A6,[6]HISTOJANV25!$A$6:$BQ$46,25,0),0) -> 250000 | E6: 250000 | G6: =SUM(D6:F6) -> 250000 | H6: 2395
A7: AS201601 | B7: =VLOOKUP(A7,[5]LISTADHERENT!$A$4:$J$44,3,0) -> BAKOP ACHILLE | C7: =IF(G7>0,VLOOKUP(A7,[6]HISTOJANV25!$A$6:$BQ$46,25,0),0) -> 50000 | D7: 50000 | G7: =D7+E7+F7 -> 50000
A8: AS201602 | B8: =VLOOKUP(A8,[5]LISTADHERENT!$A$4:$J$44,3,0) -> BOUTCHOUANG WILLIAM | C8: =IF(G8>0,VLOOKUP(A8,[6]HISTOJANV25!$A$6:$BQ$46,25,0),0) -> 125000 | E8: =125000+103000 -> 228000 | G8: =D8+E8+F8 -> 228000
A9: AS201604 | B9: =VLOOKUP(A9,[5]LISTADHERENT!$A$4:$J$44,3,0) -> DJOMO JEAN PAUL | C9: =IF(G9>0,VLOOKUP(A9,[6]HISTOJANV25!$A$6:$BQ$46,25,0),0) -> 250000 | E9: =150000+307500 -> 457500 | G9: =D9+E9+F9 -> 457500
A10: AS201654 | B10: =VLOOKUP(A10,[5]LISTADHERENT!$A$4:$J$44,3,0) -> DJOMOU TCHAPDA | C10: =IF(G10>0,VLOOKUP(A10,[6]HISTOJANV25!$A$6:$BQ$46,25,0),0) -> 50000 | E10: =511000-307500-103000 -> 100500 | G10: =D10+E10+F10 -> 100500
A11: AS201605 | B11: =VLOOKUP(A11,[5]LISTADHERENT!$A$4:$J$44,3,0) -> DJOUKWE NANGUEN GUY BLAISE | C11: =IF(G11>0,VLOOKUP(A11,[6]HISTOJANV25!$A$6:$BQ$46,25,0),0) -> 150000 | E11: =187500-37500 -> 150000 | G11: =D11+E11+F11 -> 150000
A12: AS201608 | B12: =VLOOKUP(A12,[5]LISTADHERENT!$A$4:$J$44,3,0) -> DJUOMBESSY ANTOINE | C12: =IF(G12>0,VLOOKUP(A12,[6]HISTOJANV25!$A$6:$BQ$46,25,0),0) -> 250000 | E12: 260000 | G12: =D12+E12+F12 -> 260000
A13: AS201651 | B13: =VLOOKUP(A13,[5]LISTADHERENT!$A$4:$J$44,3,0) -> DOMOU FABIEN | C13: =IF(G13>0,VLOOKUP(A13,[6]HISTOJANV25!$A$6:$BQ$46,25,0),0) -> 50000 | E13: 50000 | G13: =D13+E13+F13 -> 50000
A14: AS201609 | B14: =VLOOKUP(A14,[5]LISTADHERENT!$A$4:$J$44,3,0) -> DONHOU DAVID | C14: =IF(G14>0,VLOOKUP(A14,[6]HISTOJANV25!$A$6:$BQ$46,25,0),0) -> 50000 | E14: 50000 | G14: =D14+E14+F14 -> 50000
A15: AS201663 | B15: =VLOOKUP(A15,[5]LISTADHERENT!$A$4:$J$44,3,0) -> FAMPOU PAUL | C15: =IF(G15>0,VLOOKUP(A15,[6]HISTOMARS25!$A$6:$BQ$46,25,0),0) -> 150000 | E15: 376000 | G15: =D15+E15+F15 -> 376000
A16: AS201611 | B16: =VLOOKUP(A16,[5]LISTADHERENT!$A$4:$J$44,3,0) -> HENGUE PAUL OMER | C16: =IF(G16>0,VLOOKUP(A16,[6]HISTOJANV25!$A$6:$BQ$46,25,0),0) -> 125000 | E16: =1000000+275000 -> 1275000 | G16: =D16+E16+F16 -> 1275000
A17: AS201613 | B17: =VLOOKUP(A17,[5]LISTADHERENT!$A$4:$J$44,3,0) -> HOTCHO BENJAMIN | C17: =IF(G17>0,VLOOKUP(A17,[6]HISTOJANV25!$A$6:$BQ$46,25,0),0) -> 225000 | E17: =250000 -> 250000 | G17: =D17+E17+F17 -> 250000
A18: AS201617 | B18: =VLOOKUP(A18,[5]LISTADHERENT!$A$4:$J$44,3,0) -> KOUAMOU MOISE | C18: =IF(G18>0,VLOOKUP(A18,[6]HISTOJANV25!$A$6:$BQ$46,25,0),0) -> 150000 | E18: 150000 | G18: =D18+E18+F18 -> 150000
A19: AS201619 | B19: =VLOOKUP(A19,[5]LISTADHERENT!$A$4:$J$44,3,0) -> KOUATCHO MESSACK | C19: =IF(G19>0,VLOOKUP(A19,[6]HISTOJANV25!$A$6:$BQ$46,25,0),0) -> 225000 | E19: =253500+37500 -> 291000 | G19: =D19+E19+F19 -> 291000
A20: AS201620 | B20: =VLOOKUP(A20,[5]LISTADHERENT!$A$4:$J$44,3,0) -> LOWE JEAN
A21: AS201661 | B21: =VLOOKUP(A21,[5]LISTADHERENT!$A$4:$J$44,3,0) -> MASSEUNGOUE DAGOBERT | C21: =IF(G21>0,VLOOKUP(A21,[6]HISTOJANV25!$A$6:$BQ$46,25,0),0) -> 50000 | E21: 50000 | G21: =D21+E21+F21 -> 50000
A22: AS201649 | B22: =VLOOKUP(A22,[5]LISTADHERENT!$A$4:$J$44,3,0) -> MBOGNING TUGMA GUY | C22: =IF(G22>0,VLOOKUP(A22,[6]HISTOJANV25!$A$6:$BQ$46,25,0),0) -> 325000 | E22: 376000 | G22: =D22+E22+F22 -> 376000
A23: AS201639 | B23: =VLOOKUP(A23,[5]LISTADHERENT!$A$4:$J$44,3,0) -> NANGUEN MARTIN | C23: =IF(G23>0,VLOOKUP(A23,[6]HISTOJANV25!$A$6:$BQ$46,25,0),0) -> 50000 | E23: 50000 | G23: =D23+E23+F23 -> 50000
A24: AS201621 | B24: =VLOOKUP(A24,[5]LISTADHERENT!$A$4:$J$44,3,0) -> NANKAM APPOLINAIRE | C24: =IF(G24>0,VLOOKUP(A24,[6]HISTOJANV25!$A$6:$BQ$46,25,0),0) -> 125000 | E24: 125000 | G24: =D24+E24+F24 -> 125000
A25: AS201622 | B25: =VLOOKUP(A25,[5]LISTADHERENT!$A$4:$J$44,3,0) -> NDJOMO ETIENNE | C25: =IF(G25>0,VLOOKUP(A25,[6]HISTOJANV25!$A$6:$BQ$46,25,0),0) -> 250000 | E25: =260000+101000 -> 361000 | G25: =D25+E25+F25 -> 361000
A26: AS201624 | B26: =VLOOKUP(A26,[5]LISTADHERENT!$A$4:$J$44,3,0) -> NGONDIEP CLAUDE | C26: =IF(G26>0,VLOOKUP(A26,[6]HISTOJANV25!$A$6:$BQ$46,25,0),0) -> 225000 | E26: 240000 | G26: =D26+E26+F26 -> 240000
A27: AS201626 | B27: =VLOOKUP(A27,[5]LISTADHERENT!$A$4:$J$44,3,0) -> NGUIEMEGNI MATHIEU BLAISE | C27: =IF(G27>0,VLOOKUP(A27,[6]HISTOJANV25!$A$6:$BQ$46,25,0),0) -> 250000 | E27: =150000+50000+200000+50000 -> 450000 | G27: =D27+E27+F27 -> 450000
A28: AS201628 | B28: =VLOOKUP(A28,[5]LISTADHERENT!$A$4:$J$44,3,0) -> NKAMGANG JUSTIN DEJOLIE | C28: =IF(G28>0,VLOOKUP(A28,[6]HISTOJANV25!$A$6:$BQ$46,25,0),0) -> 50000 | E28: =700000-101000-50000-427000 -> 122000 | G28: =D28+E28+F28 -> 122000
A29: AS201656 | B29: =VLOOKUP(A29,[5]LISTADHERENT!$A$4:$J$44,3,0) -> NOUBE ETIENNE | C29: =IF(G29>0,VLOOKUP(A29,[6]HISTOJANV25!$A$6:$BQ$46,25,0),0) -> 50000 | E29: 50000 | G29: =D29+E29+F29 -> 50000
A30: AS201633 | B30: =VLOOKUP(A30,[5]LISTADHERENT!$A$4:$J$44,3,0) -> PATEGO NJOSSU GUSTAVE | C30: =IF(G30>0,VLOOKUP(A30,[6]HISTOJANV25!$A$6:$BQ$46,25,0),0) -> 125000 | E30: 125000 | G30: =D30+E30+F30 -> 125000
A31: AS201657 | B31: =VLOOKUP(A31,[5]LISTADHERENT!$A$4:$J$44,3,0) -> SEUMO POLYCARPE | C31: =IF(G31>0,VLOOKUP(A31,[6]HISTOJANV25!$A$6:$BQ$46,25,0),0) -> 50000 | E31: 91000 | G31: =D31+E31+F31 -> 91000
A32: AS201653 | B32: =VLOOKUP(A32,[5]LISTADHERENT!$A$4:$J$44,3,0) -> SIME BRICE | C32: =IF(G32>0,VLOOKUP(A32,[6]HISTOJANV25!$A$6:$BQ$46,25,0),0) -> 250000 | D32: 253000 | G32: =D32+E32+F32 -> 253000
A33: AS201629 | B33: =VLOOKUP(A33,[5]LISTADHERENT!$A$4:$J$44,3,0) -> SIMO FONGANG ERIC | C33: =IF(G33>0,VLOOKUP(A33,[6]HISTOJANV25!$A$6:$BQ$46,25,0),0) -> 50000 | E33: 50000 | G33: =D33+E33+F33 -> 50000
A34: AS201638 | B34: =VLOOKUP(A34,[5]LISTADHERENT!$A$4:$J$44,3,0) -> SIMO PIERRE | C34: =IF(G34>0,VLOOKUP(A34,[6]HISTOJANV25!$A$6:$BQ$46,25,0),0) -> 150000 | E34: =100000+50000 -> 150000 | G34: =D34+E34+F34 -> 150000
A35: AS201641 | B35: =VLOOKUP(A35,[5]LISTADHERENT!$A$4:$J$44,3,0) -> TCHOUAMOU MATHIEU | C35: =IF(G35>0,VLOOKUP(A35,[6]HISTOJANV25!$A$6:$BQ$46,25,0),0) -> 125000 | E35: 125000 | G35: =D35+E35+F35 -> 125000
A36: AS201660 | B36: =VLOOKUP(A36,[5]LISTADHERENT!$A$4:$J$44,3,0) -> TCHOUATEU AUGUSTIN | C36: =IF(G36>0,VLOOKUP(A36,[6]HISTOJANV25!$A$6:$BQ$46,25,0),0) -> 150000 | E36: 150000 | G36: =D36+E36+F36 -> 150000
A37: AS201643 | B37: =VLOOKUP(A37,[5]LISTADHERENT!$A$4:$J$44,3,0) -> TCHOUTOU NANA CLAUDE | C37: =IF(G37>0,VLOOKUP(A37,[6]HISTOJANV25!$A$6:$BQ$46,25,0),0) -> 50000 | E37: 50000 | G37: =D37+E37+F37 -> 50000
A38: AS201662 | B38: =VLOOKUP(A38,[5]LISTADHERENT!$A$4:$J$44,3,0) -> TIEYAM ERNEST | C38: =IF(G38>0,VLOOKUP(A38,[6]HISTOJANV25!$A$6:$BQ$46,25,0),0) -> 50000 | D38: 50000 | G38: =D38+E38+F38 -> 50000
A39: AS201658 | B39: =VLOOKUP(A39,[5]LISTADHERENT!$A$4:$J$44,3,0) -> YANTCHOU GERVAIS | C39: =IF(G39>0,VLOOKUP(A39,[6]HISTOJANV25!$A$6:$BQ$46,25,0),0) -> 125000 | E39: 130000 | G39: =D39+E39+F39 -> 130000
A40: AS201646 | B40: =VLOOKUP(A40,[5]LISTADHERENT!$A$4:$J$44,3,0) -> YEPMOU JEAN JACQUES | C40: =IF(G40>0,VLOOKUP(A40,[6]HISTOJANV25!$A$6:$BQ$46,25,0),0) -> 50000 | E40: =50000 -> 50000 | G40: =D40+E40+F40 -> 50000
...

Sheet HISTOBQUEAVRIL25
A1: ASSOCIATION | B1: ASELBY | C1: 45748
A2: ANNEE | B2: 2025
A3: 1 | B3: 2 | C3: 3 | D3: 4 | E3: 5 | F3: 6 | G3: 7
B4: HISTORIQUE BANCAIRE
A5: MATRICULE | B5: NOM ET PRENOM | C5: HISTORIQUE TONTINE | D5: HITORIQUE ESPECES | E5: HITORIQUE BANQUE | F5: AUTRE VERSEMENT | G5: MONTANT ENGAGEMENT | H5: AGIO
A6: AS201648 | B6: =VLOOKUP(A6,[5]LISTADHERENT!$A$4:$J$44,3,0) -> ASELBY | C6: =IF(G6>0,VLOOKUP(A6,[6]HISTOJANV25!$A$6:$BQ$46,25,0),0) -> 250000 | E6: 250000 | G6: =SUM(D6:F6) -> 250000 | H6: 2385
A7: AS201601 | B7: =VLOOKUP(A7,[5]LISTADHERENT!$A$4:$J$44,3,0) -> BAKOP ACHILLE | C7: =IF(G7>0,VLOOKUP(A7,[6]HISTOJANV25!$A$6:$BQ$46,25,0),0) -> 0 | G7: =D7+E7+F7 -> 0
A8: AS201602 | B8: =VLOOKUP(A8,[5]LISTADHERENT!$A$4:$J$44,3,0) -> BOUTCHOUANG WILLIAM | C8: =IF(G8>0,VLOOKUP(A8,[6]HISTOJANV25!$A$6:$BQ$46,25,0),0) -> 125000 | E8: 125000 | G8: =D8+E8+F8 -> 125000
A9: AS201604 | B9: =VLOOKUP(A9,[5]LISTADHERENT!$A$4:$J$44,3,0) -> DJOMO JEAN PAUL | C9: =IF(G9>0,VLOOKUP(A9,[6]HISTOJANV25!$A$6:$BQ$46,25,0),0) -> 250000 | D9: =102000+101500+50000 -> 253500 | G9: =D9+E9+F9 -> 253500
A10: AS201654 | B10: =VLOOKUP(A10,[5]LISTADHERENT!$A$4:$J$44,3,0) -> DJOMOU TCHAPDA | C10: =IF(G10>0,VLOOKUP(A10,[6]HISTOJANV25!$A$6:$BQ$46,25,0),0) -> 50000 | E10: 50000 | G10: =D10+E10+F10 -> 50000
A11: AS201605 | B11: =VLOOKUP(A11,[5]LISTADHERENT!$A$4:$J$44,3,0) -> DJOUKWE NANGUEN GUY BLAISE | C11: =IF(G11>0,VLOOKUP(A11,[6]HISTOJANV25!$A$6:$BQ$46,25,0),0) -> 150000 | D11: 100000 | E11: 50000 | G11: =D11+E11+F11 -> 150000
A12: AS201608 | B12: =VLOOKUP(A12,[5]LISTADHERENT!$A$4:$J$44,3,0) -> DJUOMBESSY ANTOINE | C12: =IF(G12>0,VLOOKUP(A12,[6]HISTOJANV25!$A$6:$BQ$46,25,0),0) -> 250000 | E12: 260000 | G12: =D12+E12+F12 -> 260000
A13: AS201651 | B13: =VLOOKUP(A13,[5]LISTADHERENT!$A$4:$J$44,3,0) -> DOMOU FABIEN | C13: =IF(G13>0,VLOOKUP(A13,[6]HISTOJANV25!$A$6:$BQ$46,25,0),0) -> 50000 | E13: 50000 | G13: =D13+E13+F13 -> 50000
A14: AS201609 | B14: =VLOOKUP(A14,[5]LISTADHERENT!$A$4:$J$44,3,0) -> DONHOU DAVID | C14: =IF(G14>0,VLOOKUP(A14,[6]HISTOJANV25!$A$6:$BQ$46,25,0),0) -> 50000 | E14: 50000 | G14: =D14+E14+F14 -> 50000
A15: AS201663 | B15: =VLOOKUP(A15,[5]LISTADHERENT!$A$4:$J$44,3,0) -> FAMPOU PAUL | C15: =IF(G15>0,VLOOKUP(A15,[6]HISTOMARS25!$A$6:$BQ$46,25,0),0) -> 150000 | E15: 150000 | G15: =D15+E15+F15 -> 150000
A16: AS201611 | B16: =VLOOKUP(A16,[5]LISTADHERENT!$A$4:$J$44,3,0) -> HENGUE PAUL OMER | C16: =IF(G16>0,VLOOKUP(A16,[6]HISTOJANV25!$A$6:$BQ$46,25,0),0) -> 125000 | E16: 125000 | G16: =D16+E16+F16 -> 125000
A17: AS201613 | B17: =VLOOKUP(A17,[5]LISTADHERENT!$A$4:$J$44,3,0) -> HOTCHO BENJAMIN | C17: =IF(G17>0,VLOOKUP(A17,[6]HISTOJANV25!$A$6:$BQ$46,25,0),0) -> 225000 | E17: 220000 | G17: =D17+E17+F17 -> 220000
A18: AS201617 | B18: =VLOOKUP(A18,[5]LISTADHERENT!$A$4:$J$44,3,0) -> KOUAMOU MOISE | C18: =IF(G18>0,VLOOKUP(A18,[6]HISTOJANV25!$A$6:$BQ$46,25,0),0) -> 150000 | E18: 150000 | G18: =D18+E18+F18 -> 150000
A19: AS201619 | B19: =VLOOKUP(A19,[5]LISTADHERENT!$A$4:$J$44,3,0) -> KOUATCHO MESSACK | C19: =IF(G19>0,VLOOKUP(A19,[6]HISTOJANV25!$A$6:$BQ$46,25,0),0) -> 225000 | E19: 150000 | G19: =D19+E19+F19 -> 150000
A20: AS201620 | B20: =VLOOKUP(A20,[5]LISTADHERENT!$A$4:$J$44,3,0) -> LOWE JEAN
A21: AS201661 | B21: =VLOOKUP(A21,[5]LISTADHERENT!$A$4:$J$44,3,0) -> MASSEUNGOUE DAGOBERT | C21: =IF(G21>0,VLOOKUP(A21,[6]HISTOJANV25!$A$6:$BQ$46,25,0),0) -> 50000 | E21: 50000 | G21: =D21+E21+F21 -> 50000
A22: AS201649 | B22: =VLOOKUP(A22,[5]LISTADHERENT!$A$4:$J$44,3,0) -> MBOGNING TUGMA GUY | C22: =IF(G22>0,VLOOKUP(A22,[6]HISTOJANV25!$A$6:$BQ$46,25,0),0) -> 325000 | D22: 202000 | E22: 325000 | G22: =D22+E22+F22 -> 527000
A23: AS201639 | B23: =VLOOKUP(A23,[5]LISTADHERENT!$A$4:$J$44,3,0) -> NANGUEN MARTIN | C23: =IF(G23>0,VLOOKUP(A23,[6]HISTOJANV25!$A$6:$BQ$46,25,0),0) -> 50000 | E23: 50000 | G23: =D23+E23+F23 -> 50000
A24: AS201621 | B24: =VLOOKUP(A24,[5]LISTADHERENT!$A$4:$J$44,3,0) -> NANKAM APPOLINAIRE | C24: =IF(G24>0,VLOOKUP(A24,[6]HISTOJANV25!$A$6:$BQ$46,25,0),0) -> 125000 | E24: 125000 | G24: =D24+E24+F24 -> 125000
A25: AS201622 | B25: =VLOOKUP(A25,[5]LISTADHERENT!$A$4:$J$44,3,0) -> NDJOMO ETIENNE | C25: =IF(G25>0,VLOOKUP(A25,[6]HISTOJANV25!$A$6:$BQ$46,25,0),0) -> 250000 | E25: 260000 | G25: =D25+E25+F25 -> 260000
A26: AS201624 | B26: =VLOOKUP(A26,[5]LISTADHERENT!$A$4:$J$44,3,0) -> NGONDIEP CLAUDE | C26: =IF(G26>0,VLOOKUP(A26,[6]HISTOJANV25!$A$6:$BQ$46,25,0),0) -> 225000 | E26: 240000 | G26: =D26+E26+F26 -> 240000
A27: AS201626 | B27: =VLOOKUP(A27,[5]LISTADHERENT!$A$4:$J$44,3,0) -> NGUIEMEGNI MATHIEU BLAISE | C27: =IF(G27>0,VLOOKUP(A27,[6]HISTOJANV25!$A$6:$BQ$46,25,0),0) -> 250000 | D27: 35000 | E27: 300000 | G27: =D27+E27+F27 -> 335000
A28: AS201628 | B28: =VLOOKUP(A28,[5]LISTADHERENT!$A$4:$J$44,3,0) -> NKAMGANG JUSTIN DEJOLIE | C28: =IF(G28>0,VLOOKUP(A28,[6]HISTOJANV25!$A$6:$BQ$46,25,0),0) -> 50000 | E28: 50000 | G28: =D28+E28+F28 -> 50000
A29: AS201656 | B29: =VLOOKUP(A29,[5]LISTADHERENT!$A$4:$J$44,3,0) -> NOUBE ETIENNE | C29: =IF(G29>0,VLOOKUP(A29,[6]HISTOJANV25!$A$6:$BQ$46,25,0),0) -> 50000 | E29: 50000 | G29: =D29+E29+F29 -> 50000
A30: AS201633 | B30: =VLOOKUP(A30,[5]LISTADHERENT!$A$4:$J$44,3,0) -> PATEGO NJOSSU GUSTAVE | C30: =IF(G30>0,VLOOKUP(A30,[6]HISTOJANV25!$A$6:$BQ$46,25,0),0) -> 125000 | E30: 125000 | G30: =D30+E30+F30 -> 125000
A31: AS201657 | B31: =VLOOKUP(A31,[5]LISTADHERENT!$A$4:$J$44,3,0) -> SEUMO POLYCARPE | C31: =IF(G31>0,VLOOKUP(A31,[6]HISTOJANV25!$A$6:$BQ$46,25,0),0) -> 50000 | E31: 50000 | G31: =D31+E31+F31 -> 50000
A32: AS201653 | B32: =VLOOKUP(A32,[5]LISTADHERENT!$A$4:$J$44,3,0) -> SIME BRICE | C32: =IF(G32>0,VLOOKUP(A32,[6]HISTOJANV25!$A$6:$BQ$46,25,0),0) -> 250000 | D32: 50000 | E32: 250000 | G32: =D32+E32+F32 -> 300000
A33: AS201629 | B33: =VLOOKUP(A33,[5]LISTADHERENT!$A$4:$J$44,3,0) -> SIMO FONGANG ERIC | C33: =IF(G33>0,VLOOKUP(A33,[6]HISTOJANV25!$A$6:$BQ$46,25,0),0) -> 50000 | D33: 50000 | G33: =D33+E33+F33 -> 50000
A34: AS201638 | B34: =VLOOKUP(A34,[5]LISTADHERENT!$A$4:$J$44,3,0) -> SIMO PIERRE | C34: =IF(G34>0,VLOOKUP(A34,[6]HISTOJANV25!$A$6:$BQ$46,25,0),0) -> 150000 | E34: 100000 | G34: =D34+E34+F34 -> 100000
A35: AS201641 | B35: =VLOOKUP(A35,[5]LISTADHERENT!$A$4:$J$44,3,0) -> TCHOUAMOU MATHIEU | C35: =IF(G35>0,VLOOKUP(A35,[6]HISTOJANV25!$A$6:$BQ$46,25,0),0) -> 125000 | E35: 125000 | G35: =D35+E35+F35 -> 125000
A36: AS201660 | B36: =VLOOKUP(A36,[5]LISTADHERENT!$A$4:$J$44,3,0) -> TCHOUATEU AUGUSTIN | C36: =IF(G36>0,VLOOKUP(A36,[6]HISTOJANV25!$A$6:$BQ$46,25,0),0) -> 150000 | D36: 102000 | E36: 150000 | G36: =D36+E36+F36 -> 252000
A37: AS201643 | B37: =VLOOKUP(A37,[5]LISTADHERENT!$A$4:$J$44,3,0) -> TCHOUTOU NANA CLAUDE | C37: =IF(G37>0,VLOOKUP(A37,[6]HISTOJANV25!$A$6:$BQ$46,25,0),0) -> 50000 | E37: 50000 | G37: =D37+E37+F37 -> 50000
A38: AS201662 | B38: =VLOOKUP(A38,[5]LISTADHERENT!$A$4:$J$44,3,0) -> TIEYAM ERNEST | C38: =IF(G38>0,VLOOKUP(A38,[6]HISTOJANV25!$A$6:$BQ$46,25,0),0) -> 50000 | D38: 50000 | G38: =D38+E38+F38 -> 50000
A39: AS201658 | B39: =VLOOKUP(A39,[5]LISTADHERENT!$A$4:$J$44,3,0) -> YANTCHOU GERVAIS | C39: =IF(G39>0,VLOOKUP(A39,[6]HISTOJANV25!$A$6:$BQ$46,25,0),0) -> 125000 | E39: 125000 | G39: =D39+E39+F39 -> 125000
A40: AS201646 | B40: =VLOOKUP(A40,[5]LISTADHERENT!$A$4:$J$44,3,0) -> YEPMOU JEAN JACQUES | C40: =IF(G40>0,VLOOKUP(A40,[6]HISTOJANV25!$A$6:$BQ$46,25,0),0) -> 50000 | D40: 50000 | G40: =D40+E40+F40 -> 50000
...

Sheet HISTOBQUEMAI25
A1: ASSOCIATION | B1: ASELBY | C1: 45778
A2: ANNEE | B2: 2025
A3: 1 | B3: 2 | C3: 3 | D3: 4 | E3: 5 | F3: 6 | G3: 7
B4: HISTORIQUE BANCAIRE
A5: MATRICULE | B5: NOM ET PRENOM | C5: HISTORIQUE TONTINE | D5: HITORIQUE ESPECES | E5: HITORIQUE BANQUE | F5: AUTRE VERSEMENT | G5: MONTANT ENGAGEMENT | H5: AGIO
A6: AS201648 | B6: =VLOOKUP(A6,[5]LISTADHERENT!$A$4:$J$44,3,0) -> ASELBY | C6: =IF(G6>0,VLOOKUP(A6,[6]HISTOJANV25!$A$6:$BQ$46,25,0),0) -> 250000 | E6: 250000 | G6: =SUM(D6:F6) -> 250000 | H6: 2385
A7: AS201601 | B7: =VLOOKUP(A7,[5]LISTADHERENT!$A$4:$J$44,3,0) -> BAKOP ACHILLE | C7: =IF(G7>0,VLOOKUP(A7,[6]HISTOJANV25!$A$6:$BQ$46,25,0),0) -> 50000 | E7: 100000 | G7: =SUM(D7:F7) -> 100000
A8: AS201602 | B8: =VLOOKUP(A8,[5]LISTADHERENT!$A$4:$J$44,3,0) -> BOUTCHOUANG WILLIAM | C8: =IF(G8>0,VLOOKUP(A8,[6]HISTOJANV25!$A$6:$BQ$46,25,0),0) -> 125000 | E8: 125000 | G8: =SUM(D8:F8) -> 125000
A9: AS201604 | B9: =VLOOKUP(A9,[5]LISTADHERENT!$A$4:$J$44,3,0) -> DJOMO JEAN PAUL | C9: =IF(G9>0,VLOOKUP(A9,[6]HISTOJANV25!$A$6:$BQ$46,25,0),0) -> 250000 | D9: =202000+50000 -> 252000 | E9: 250000 | G9: =SUM(D9:F9) -> 502000
A10: AS201654 | B10: =VLOOKUP(A10,[5]LISTADHERENT!$A$4:$J$44,3,0) -> DJOMOU TCHAPDA | C10: =IF(G10>0,VLOOKUP(A10,[6]HISTOJANV25!$A$6:$BQ$46,25,0),0) -> 50000 | D10: 1500 | E10: =50000+31000 -> 81000 | G10: =SUM(D10:F10) -> 82500
A11: AS201605 | B11: =VLOOKUP(A11,[5]LISTADHERENT!$A$4:$J$44,3,0) -> DJOUKWE NANGUEN GUY BLAISE | C11: =IF(G11>0,VLOOKUP(A11,[6]HISTOJANV25!$A$6:$BQ$46,25,0),0) -> 150000 | E11: 150000 | G11: =SUM(D11:F11) -> 150000
A12: AS201608 | B12: =VLOOKUP(A12,[5]LISTADHERENT!$A$4:$J$44,3,0) -> DJUOMBESSY ANTOINE | C12: =IF(G12>0,VLOOKUP(A12,[6]HISTOJANV25!$A$6:$BQ$46,25,0),0) -> 250000 | E12: 260000 | G12: =SUM(D12:F12) -> 260000
A13: AS201651 | B13: =VLOOKUP(A13,[5]LISTADHERENT!$A$4:$J$44,3,0) -> DOMOU FABIEN | C13: =IF(G13>0,VLOOKUP(A13,[6]HISTOJANV25!$A$6:$BQ$46,25,0),0) -> 50000 | E13: 50000 | G13: =SUM(D13:F13) -> 50000
A14: AS201609 | B14: =VLOOKUP(A14,[5]LISTADHERENT!$A$4:$J$44,3,0) -> DONHOU DAVID | C14: =IF(G14>0,VLOOKUP(A14,[6]HISTOJANV25!$A$6:$BQ$46,25,0),0) -> 50000 | E14: 50000 | G14: =SUM(D14:F14) -> 50000
A15: AS201663 | B15: =VLOOKUP(A15,[5]LISTADHERENT!$A$4:$J$44,3,0) -> FAMPOU PAUL | C15: =IF(G15>0,VLOOKUP(A15,[6]HISTOMARS25!$A$6:$BQ$46,25,0),0) -> 150000 | E15: 150000 | G15: =SUM(D15:F15) -> 150000
A16: AS201611 | B16: =VLOOKUP(A16,[5]LISTADHERENT!$A$4:$J$44,3,0) -> HENGUE PAUL OMER | C16: =IF(G16>0,VLOOKUP(A16,[6]HISTOJANV25!$A$6:$BQ$46,25,0),0) -> 125000 | E16: 125000 | G16: =SUM(D16:F16) -> 125000
A17: AS201613 | B17: =VLOOKUP(A17,[5]LISTADHERENT!$A$4:$J$44,3,0) -> HOTCHO BENJAMIN | C17: =IF(G17>0,VLOOKUP(A17,[6]HISTOJANV25!$A$6:$BQ$46,25,0),0) -> 225000 | E17: 250000 | G17: =SUM(D17:F17) -> 250000
A18: AS201617 | B18: =VLOOKUP(A18,[5]LISTADHERENT!$A$4:$J$44,3,0) -> KOUAMOU MOISE | C18: =IF(G18>0,VLOOKUP(A18,[6]HISTOJANV25!$A$6:$BQ$46,25,0),0) -> 150000 | D18: 102000 | E18: 150000 | G18: =SUM(D18:F18) -> 252000
A19: AS201619 | B19: =VLOOKUP(A19,[5]LISTADHERENT!$A$4:$J$44,3,0) -> KOUATCHO MESSACK | C19: =IF(G19>0,VLOOKUP(A19,[6]HISTOJANV25!$A$6:$BQ$46,25,0),0) -> 225000 | D19: 27000 | E19: 298500 | G19: =SUM(D19:F19) -> 325500
A20: AS201620 | B20: =VLOOKUP(A20,[5]LISTADHERENT!$A$4:$J$44,3,0) -> LOWE JEAN
A21: AS201661 | B21: =VLOOKUP(A21,[5]LISTADHERENT!$A$4:$J$44,3,0) -> MASSEUNGOUE DAGOBERT | C21: =IF(G21>0,VLOOKUP(A21,[6]HISTOJANV25!$A$6:$BQ$46,25,0),0) -> 50000 | E21: 50000 | G21: =SUM(D21:F21) -> 50000
A22: AS201649 | B22: =VLOOKUP(A22,[5]LISTADHERENT!$A$4:$J$44,3,0) -> MBOGNING TUGMA GUY | C22: =IF(G22>0,VLOOKUP(A22,[6]HISTOJANV25!$A$6:$BQ$46,25,0),0) -> 325000 | D22: 202000 | E22: 325000 | G22: =SUM(D22:F22) -> 527000
A23: AS201639 | B23: =VLOOKUP(A23,[5]LISTADHERENT!$A$4:$J$44,3,0) -> NANGUEN MARTIN | C23: =IF(G23>0,VLOOKUP(A23,[6]HISTOJANV25!$A$6:$BQ$46,25,0),0) -> 50000 | D23: 203000 | G23: =SUM(D23:F23) -> 203000
A24: AS201621 | B24: =VLOOKUP(A24,[5]LISTADHERENT!$A$4:$J$44,3,0) -> NANKAM APPOLINAIRE | C24: =IF(G24>0,VLOOKUP(A24,[6]HISTOJANV25!$A$6:$BQ$46,25,0),0) -> 125000 | E24: 125000 | G24: =SUM(D24:F24) -> 125000
A25: AS201622 | B25: =VLOOKUP(A25,[5]LISTADHERENT!$A$4:$J$44,3,0) -> NDJOMO ETIENNE | C25: =IF(G25>0,VLOOKUP(A25,[6]HISTOJANV25!$A$6:$BQ$46,25,0),0) -> 250000 | E25: 260000 | G25: =SUM(D25:F25) -> 260000
A26: AS201624 | B26: =VLOOKUP(A26,[5]LISTADHERENT!$A$4:$J$44,3,0) -> NGONDIEP CLAUDE | C26: =IF(G26>0,VLOOKUP(A26,[6]HISTOJANV25!$A$6:$BQ$46,25,0),0) -> 225000 | D26: =80625+203000 -> 283625 | E26: 240000 | G26: =SUM(D26:F26) -> 523625
A27: AS201626 | B27: =VLOOKUP(A27,[5]LISTADHERENT!$A$4:$J$44,3,0) -> NGUIEMEGNI MATHIEU BLAISE | C27: =IF(G27>0,VLOOKUP(A27,[6]HISTOJANV25!$A$6:$BQ$46,25,0),0) -> 250000 | E27: 250000 | G27: =SUM(D27:F27) -> 250000
A28: AS201628 | B28: =VLOOKUP(A28,[5]LISTADHERENT!$A$4:$J$44,3,0) -> NKAMGANG JUSTIN DEJOLIE | C28: =IF(G28>0,VLOOKUP(A28,[6]HISTOJANV25!$A$6:$BQ$46,25,0),0) -> 50000 | E28: 345000 | G28: =SUM(D28:F28) -> 345000
A29: AS201656 | B29: =VLOOKUP(A29,[5]LISTADHERENT!$A$4:$J$44,3,0) -> NOUBE ETIENNE | C29: =IF(G29>0,VLOOKUP(A29,[6]HISTOJANV25!$A$6:$BQ$46,25,0),0) -> 50000 | E29: 50000 | G29: =SUM(D29:F29) -> 50000
A30: AS201633 | B30: =VLOOKUP(A30,[5]LISTADHERENT!$A$4:$J$44,3,0) -> PATEGO NJOSSU GUSTAVE | C30: =IF(G30>0,VLOOKUP(A30,[6]HISTOJANV25!$A$6:$BQ$46,25,0),0) -> 125000 | E30: 125000 | G30: =SUM(D30:F30) -> 125000
A31: AS201657 | B31: =VLOOKUP(A31,[5]LISTADHERENT!$A$4:$J$44,3,0) -> SEUMO POLYCARPE | C31: =IF(G31>0,VLOOKUP(A31,[6]HISTOJANV25!$A$6:$BQ$46,25,0),0) -> 50000 | D31: 30000 | E31: 50000 | G31: =SUM(D31:F31) -> 80000
A32: AS201653 | B32: =VLOOKUP(A32,[5]LISTADHERENT!$A$4:$J$44,3,0) -> SIME BRICE | C32: =IF(G32>0,VLOOKUP(A32,[6]HISTOJANV25!$A$6:$BQ$46,25,0),0) -> 250000 | E32: 250000 | G32: =SUM(D32:F32) -> 250000
A33: AS201629 | B33: =VLOOKUP(A33,[5]LISTADHERENT!$A$4:$J$44,3,0) -> SIMO FONGANG ERIC | C33: =IF(G33>0,VLOOKUP(A33,[6]HISTOJANV25!$A$6:$BQ$46,25,0),0) -> 50000 | D33: 53000 | G33: =SUM(D33:F33) -> 53000
A34: AS201638 | B34: =VLOOKUP(A34,[5]LISTADHERENT!$A$4:$J$44,3,0) -> SIMO PIERRE | C34: =IF(G34>0,VLOOKUP(A34,[6]HISTOJANV25!$A$6:$BQ$46,25,0),0) -> 150000 | E34: =100000+50000 -> 150000 | G34: =SUM(D34:F34) -> 150000
A35: AS201641 | B35: =VLOOKUP(A35,[5]LISTADHERENT!$A$4:$J$44,3,0) -> TCHOUAMOU MATHIEU | C35: =IF(G35>0,VLOOKUP(A35,[6]HISTOJANV25!$A$6:$BQ$46,25,0),0) -> 125000 | E35: 125000 | G35: =SUM(D35:F35) -> 125000
A36: AS201660 | B36: =VLOOKUP(A36,[5]LISTADHERENT!$A$4:$J$44,3,0) -> TCHOUATEU AUGUSTIN | C36: =IF(G36>0,VLOOKUP(A36,[6]HISTOJANV25!$A$6:$BQ$46,25,0),0) -> 150000 | E36: 150000 | G36: =SUM(D36:F36) -> 150000
A37: AS201643 | B37: =VLOOKUP(A37,[5]LISTADHERENT!$A$4:$J$44,3,0) -> TCHOUTOU NANA CLAUDE | C37: =IF(G37>0,VLOOKUP(A37,[6]HISTOJANV25!$A$6:$BQ$46,25,0),0) -> 50000 | E37: 50000 | G37: =SUM(D37:F37) -> 50000
A38: AS201662 | B38: =VLOOKUP(A38,[5]LISTADHERENT!$A$4:$J$44,3,0) -> TIEYAM ERNEST | C38: =IF(G38>0,VLOOKUP(A38,[6]HISTOJANV25!$A$6:$BQ$46,25,0),0) -> 50000 | D38: 50000 | G38: =SUM(D38:F38) -> 50000
A39: AS201658 | B39: =VLOOKUP(A39,[5]LISTADHERENT!$A$4:$J$44,3,0) -> YANTCHOU GERVAIS | C39: =IF(G39>0,VLOOKUP(A39,[6]HISTOJANV25!$A$6:$BQ$46,25,0),0) -> 125000 | E39: 125000 | G39: =SUM(D39:F39) -> 125000
A40: AS201646 | B40: =VLOOKUP(A40,[5]LISTADHERENT!$A$4:$J$44,3,0) -> YEPMOU JEAN JACQUES | C40: =IF(G40>0,VLOOKUP(A40,[6]HISTOJANV25!$A$6:$BQ$46,25,0),0) -> 50000 | E40: 50000 | G40: =SUM(D40:F40) -> 50000
...

Sheet HISTOBQUEJUIN25
A1: ASSOCIATION | B1: ASELBY | C1: 45809
A2: ANNEE | B2: 2025
A3: 1 | B3: 2 | C3: 3 | D3: 4 | E3: 5 | F3: 6 | G3: 7
B4: HISTORIQUE BANCAIRE
A5: MATRICULE | B5: NOM ET PRENOM | C5: HISTORIQUE TONTINE | D5: HITORIQUE ESPECES | E5: HITORIQUE BANQUE | F5: AUTRE VERSEMENT | G5: MONTANT ENGAGEMENT | H5: AGIO
A6: AS201648 | B6: =VLOOKUP(A6,[5]LISTADHERENT!$A$4:$J$44,3,0) -> ASELBY | C6: =IF(G6>0,VLOOKUP(A6,[6]HISTOJANV25!$A$6:$BQ$46,25,0),0) -> 250000 | E6: 250000 | G6: =SUM(D6:F6) -> 250000 | H6: 2385
A7: AS201601 | B7: =VLOOKUP(A7,[5]LISTADHERENT!$A$4:$J$44,3,0) -> BAKOP ACHILLE | C7: =IF(G7>0,VLOOKUP(A7,[6]HISTOJANV25!$A$6:$BQ$46,25,0),0) -> 50000 | D7: 50000 | G7: =SUM(D7:F7) -> 50000
A8: AS201602 | B8: =VLOOKUP(A8,[5]LISTADHERENT!$A$4:$J$44,3,0) -> BOUTCHOUANG WILLIAM | C8: =IF(G8>0,VLOOKUP(A8,[6]HISTOJANV25!$A$6:$BQ$46,25,0),0) -> 125000 | E8: 125000 | G8: =SUM(D8:F8) -> 125000
A9: AS201604 | B9: =VLOOKUP(A9,[5]LISTADHERENT!$A$4:$J$44,3,0) -> DJOMO JEAN PAUL | C9: =IF(G9>0,VLOOKUP(A9,[6]HISTOJANV25!$A$6:$BQ$46,25,0),0) -> 250000 | D9: =200000+101000+50000 -> 351000 | G9: =SUM(D9:F9) -> 351000
A10: AS201654 | B10: =VLOOKUP(A10,[5]LISTADHERENT!$A$4:$J$44,3,0) -> DJOMOU TCHAPDA | C10: =IF(G10>0,VLOOKUP(A10,[6]HISTOJANV25!$A$6:$BQ$46,25,0),0) -> 50000 | E10: 81000 | G10: =SUM(D10:F10) -> 81000
A11: AS201605 | B11: =VLOOKUP(A11,[5]LISTADHERENT!$A$4:$J$44,3,0) -> DJOUKWE NANGUEN GUY BLAISE | C11: =IF(G11>0,VLOOKUP(A11,[6]HISTOJANV25!$A$6:$BQ$46,25,0),0) -> 150000 | E11: 251000 | G11: =SUM(D11:F11) -> 251000
A12: AS201608 | B12: =VLOOKUP(A12,[5]LISTADHERENT!$A$4:$J$44,3,0) -> DJUOMBESSY ANTOINE | C12: =IF(G12>0,VLOOKUP(A12,[6]HISTOJANV25!$A$6:$BQ$46,25,0),0) -> 250000 | E12: 315000 | G12: =SUM(D12:F12) -> 315000
A13: AS201651 | B13: =VLOOKUP(A13,[5]LISTADHERENT!$A$4:$J$44,3,0) -> DOMOU FABIEN | C13: =IF(G13>0,VLOOKUP(A13,[6]HISTOJANV25!$A$6:$BQ$46,25,0),0) -> 50000 | E13: 50000 | G13: =SUM(D13:F13) -> 50000
A14: AS201609 | B14: =VLOOKUP(A14,[5]LISTADHERENT!$A$4:$J$44,3,0) -> DONHOU DAVID | C14: =IF(G14>0,VLOOKUP(A14,[6]HISTOJANV25!$A$6:$BQ$46,25,0),0) -> 50000 | E14: 50000 | G14: =SUM(D14:F14) -> 50000
A15: AS201663 | B15: =VLOOKUP(A15,[5]LISTADHERENT!$A$4:$J$44,3,0) -> FAMPOU PAUL | C15: =IF(G15>0,VLOOKUP(A15,[6]HISTOMARS25!$A$6:$BQ$46,25,0),0) -> 150000 | E15: 150000 | G15: =SUM(D15:F15) -> 150000
A16: AS201611 | B16: =VLOOKUP(A16,[5]LISTADHERENT!$A$4:$J$44,3,0) -> HENGUE PAUL OMER | C16: =IF(G16>0,VLOOKUP(A16,[6]HISTOJANV25!$A$6:$BQ$46,25,0),0) -> 125000 | E16: 125000 | G16: =SUM(D16:F16) -> 125000
A17: AS201613 | B17: =VLOOKUP(A17,[5]LISTADHERENT!$A$4:$J$44,3,0) -> HOTCHO BENJAMIN | C17: =IF(G17>0,VLOOKUP(A17,[6]HISTOJANV25!$A$6:$BQ$46,25,0),0) -> 225000 | E17: =51000+250000 -> 301000 | G17: =SUM(D17:F17) -> 301000
A18: AS201617 | B18: =VLOOKUP(A18,[5]LISTADHERENT!$A$4:$J$44,3,0) -> KOUAMOU MOISE | C18: =IF(G18>0,VLOOKUP(A18,[6]HISTOJANV25!$A$6:$BQ$46,25,0),0) -> 150000 | E18: 150000 | G18: =SUM(D18:F18) -> 150000
A19: AS201619 | B19: =VLOOKUP(A19,[5]LISTADHERENT!$A$4:$J$44,3,0) -> KOUATCHO MESSACK | C19: =IF(G19>0,VLOOKUP(A19,[6]HISTOJANV25!$A$6:$BQ$46,25,0),0) -> 225000 | E19: 235000 | G19: =SUM(D19:F19) -> 235000
A20: AS201620 | B20: =VLOOKUP(A20,[5]LISTADHERENT!$A$4:$J$44,3,0) -> LOWE JEAN
A21: AS201661 | B21: =VLOOKUP(A21,[5]LISTADHERENT!$A$4:$J$44,3,0) -> MASSEUNGOUE DAGOBERT | C21: =IF(G21>0,VLOOKUP(A21,[6]HISTOJANV25!$A$6:$BQ$46,25,0),0) -> 50000 | E21: 50000 | G21: =SUM(D21:F21) -> 50000
A22: AS201649 | B22: =VLOOKUP(A22,[5]LISTADHERENT!$A$4:$J$44,3,0) -> MBOGNING TUGMA GUY | C22: =IF(G22>0,VLOOKUP(A22,[6]HISTOJANV25!$A$6:$BQ$46,25,0),0) -> 325000 | E22: 628000 | G22: =SUM(D22:F22) -> 628000
A23: AS201639 | B23: =VLOOKUP(A23,[5]LISTADHERENT!$A$4:$J$44,3,0) -> NANGUEN MARTIN | C23: =IF(G23>0,VLOOKUP(A23,[6]HISTOJANV25!$A$6:$BQ$46,25,0),0) -> 50000 | E23: 50000 | G23: =SUM(D23:F23) -> 50000
A24: AS201621 | B24: =VLOOKUP(A24,[5]LISTADHERENT!$A$4:$J$44,3,0) -> NANKAM APPOLINAIRE | C24: =IF(G24>0,VLOOKUP(A24,[6]HISTOJANV25!$A$6:$BQ$46,25,0),0) -> 125000 | E24: 125000 | G24: =SUM(D24:F24) -> 125000
A25: AS201622 | B25: =VLOOKUP(A25,[5]LISTADHERENT!$A$4:$J$44,3,0) -> NDJOMO ETIENNE | C25: =IF(G25>0,VLOOKUP(A25,[6]HISTOJANV25!$A$6:$BQ$46,25,0),0) -> 250000 | D25: 202500 | E25: 260000 | G25: =SUM(D25:F25) -> 462500
A26: AS201624 | B26: =VLOOKUP(A26,[5]LISTADHERENT!$A$4:$J$44,3,0) -> NGONDIEP CLAUDE | C26: =IF(G26>0,VLOOKUP(A26,[6]HISTOJANV25!$A$6:$BQ$46,25,0),0) -> 225000 | E26: 240000 | G26: =SUM(D26:F26) -> 240000
A27: AS201626 | B27: =VLOOKUP(A27,[5]LISTADHERENT!$A$4:$J$44,3,0) -> NGUIEMEGNI MATHIEU BLAISE | C27: =IF(G27>0,VLOOKUP(A27,[6]HISTOJANV25!$A$6:$BQ$46,25,0),0) -> 250000 | E27: =100000+285000+65000 -> 450000 | G27: =SUM(D27:F27) -> 450000
A28: AS201628 | B28: =VLOOKUP(A28,[5]LISTADHERENT!$A$4:$J$44,3,0) -> NKAMGANG JUSTIN DEJOLIE | C28: =IF(G28>0,VLOOKUP(A28,[6]HISTOJANV25!$A$6:$BQ$46,25,0),0) -> 50000 | D28: 53000 | G28: =SUM(D28:F28) -> 53000
A29: AS201656 | B29: =VLOOKUP(A29,[5]LISTADHERENT!$A$4:$J$44,3,0) -> NOUBE ETIENNE | C29: =IF(G29>0,VLOOKUP(A29,[6]HISTOJANV25!$A$6:$BQ$46,25,0),0) -> 50000 | E29: 50000 | G29: =SUM(D29:F29) -> 50000
A30: AS201633 | B30: =VLOOKUP(A30,[5]LISTADHERENT!$A$4:$J$44,3,0) -> PATEGO NJOSSU GUSTAVE | C30: =IF(G30>0,VLOOKUP(A30,[6]HISTOJANV25!$A$6:$BQ$46,25,0),0) -> 125000 | E30: 125000 | G30: =SUM(D30:F30) -> 125000
A31: AS201657 | B31: =VLOOKUP(A31,[5]LISTADHERENT!$A$4:$J$44,3,0) -> SEUMO POLYCARPE | C31: =IF(G31>0,VLOOKUP(A31,[6]HISTOJANV25!$A$6:$BQ$46,25,0),0) -> 50000 | E31: 50000 | G31: =SUM(D31:F31) -> 50000
A32: AS201653 | B32: =VLOOKUP(A32,[5]LISTADHERENT!$A$4:$J$44,3,0) -> SIME BRICE | C32: =IF(G32>0,VLOOKUP(A32,[6]HISTOJANV25!$A$6:$BQ$46,25,0),0) -> 250000 | E32: 250000 | G32: =SUM(D32:F32) -> 250000
A33: AS201629 | B33: =VLOOKUP(A33,[5]LISTADHERENT!$A$4:$J$44,3,0) -> SIMO FONGANG ERIC | C33: =IF(G33>0,VLOOKUP(A33,[6]HISTOJANV25!$A$6:$BQ$46,25,0),0) -> 50000 | D33: 50000 | G33: =SUM(D33:F33) -> 50000
A34: AS201638 | B34: =VLOOKUP(A34,[5]LISTADHERENT!$A$4:$J$44,3,0) -> SIMO PIERRE | C34: =IF(G34>0,VLOOKUP(A34,[6]HISTOJANV25!$A$6:$BQ$46,25,0),0) -> 150000 | E34: =51000+130000 -> 181000 | G34: =SUM(D34:F34) -> 181000
A35: AS201641 | B35: =VLOOKUP(A35,[5]LISTADHERENT!$A$4:$J$44,3,0) -> TCHOUAMOU MATHIEU | C35: =IF(G35>0,VLOOKUP(A35,[6]HISTOJANV25!$A$6:$BQ$46,25,0),0) -> 125000 | D35: 102000 | E35: 125000 | G35: =SUM(D35:F35) -> 227000
A36: AS201660 | B36: =VLOOKUP(A36,[5]LISTADHERENT!$A$4:$J$44,3,0) -> TCHOUATEU AUGUSTIN | C36: =IF(G36>0,VLOOKUP(A36,[6]HISTOJANV25!$A$6:$BQ$46,25,0),0) -> 150000 | E36: 150000 | G36: =SUM(D36:F36) -> 150000
A37: AS201643 | B37: =VLOOKUP(A37,[5]LISTADHERENT!$A$4:$J$44,3,0) -> TCHOUTOU NANA CLAUDE | C37: =IF(G37>0,VLOOKUP(A37,[6]HISTOJANV25!$A$6:$BQ$46,25,0),0) -> 50000 | E37: 50000 | G37: =SUM(D37:F37) -> 50000
A38: AS201662 | B38: =VLOOKUP(A38,[5]LISTADHERENT!$A$4:$J$44,3,0) -> TIEYAM ERNEST | C38: =IF(G38>0,VLOOKUP(A38,[6]HISTOJANV25!$A$6:$BQ$46,25,0),0) -> 50000 | D38: 50000 | G38: =SUM(D38:F38) -> 50000
A39: AS201658 | B39: =VLOOKUP(A39,[5]LISTADHERENT!$A$4:$J$44,3,0) -> YANTCHOU GERVAIS | C39: =IF(G39>0,VLOOKUP(A39,[6]HISTOJANV25!$A$6:$BQ$46,25,0),0) -> 125000 | E39: =125000+102000 -> 227000 | G39: =SUM(D39:F39) -> 227000
A40: AS201646 | B40: =VLOOKUP(A40,[5]LISTADHERENT!$A$4:$J$44,3,0) -> YEPMOU JEAN JACQUES | C40: =IF(G40>0,VLOOKUP(A40,[6]HISTOJANV25!$A$6:$BQ$46,25,0),0) -> 50000 | D40: 50000 | G40: =SUM(D40:F40) -> 50000
...

Sheet HISTOBQUEJUIL25
A1: ASSOCIATION | B1: ASELBY | C1: 45839
A2: ANNEE | B2: 2025
A3: 1 | B3: 2 | C3: 3 | D3: 4 | E3: 5 | F3: 6 | G3: 7
B4: HISTORIQUE BANCAIRE
A5: MATRICULE | B5: NOM ET PRENOM | C5: HISTORIQUE TONTINE | D5: HITORIQUE ESPECES | E5: HITORIQUE BANQUE | F5: AUTRE VERSEMENT | G5: MONTANT ENGAGEMENT | H5: AGIO
A6: AS201648 | B6: =VLOOKUP(A6,[5]LISTADHERENT!$A$4:$J$44,3,0) -> ASELBY | C6: =IF(G6>0,VLOOKUP(A6,[6]HISTOJANV25!$A$6:$BQ$46,25,0),0) -> 250000 | E6: 250000 | G6: =SUM(D6:F6) -> 250000 | H6: =2385+2000+385 -> 4770
A7: AS201601 | B7: =VLOOKUP(A7,[5]LISTADHERENT!$A$4:$J$44,3,0) -> BAKOP ACHILLE | C7: =IF(G7>0,VLOOKUP(A7,[6]HISTOJANV25!$A$6:$BQ$46,25,0),0) -> 50000 | D7: 50000 | G7: =SUM(D7:F7) -> 50000
A8: AS201602 | B8: =VLOOKUP(A8,[5]LISTADHERENT!$A$4:$J$44,3,0) -> BOUTCHOUANG WILLIAM | C8: =IF(G8>0,VLOOKUP(A8,[6]HISTOJANV25!$A$6:$BQ$46,25,0),0) -> 125000 | E8: 125000 | G8: =SUM(D8:F8) -> 125000
A9: AS201604 | B9: =VLOOKUP(A9,[5]LISTADHERENT!$A$4:$J$44,3,0) -> DJOMO JEAN PAUL | C9: =IF(G9>0,VLOOKUP(A9,[6]HISTOJANV25!$A$6:$BQ$46,25,0),0) -> 250000 | D9: =250000+41500 -> 291500 | G9: =SUM(D9:F9) -> 291500
A10: AS201654 | B10: =VLOOKUP(A10,[5]LISTADHERENT!$A$4:$J$44,3,0) -> DJOMOU TCHAPDA | C10: =IF(G10>0,VLOOKUP(A10,[6]HISTOJANV25!$A$6:$BQ$46,25,0),0) -> 50000 | E10: 50000 | G10: =SUM(D10:F10) -> 50000
A11: AS201605 | B11: =VLOOKUP(A11,[5]LISTADHERENT!$A$4:$J$44,3,0) -> DJOUKWE NANGUEN GUY BLAISE | C11: =IF(G11>0,VLOOKUP(A11,[6]HISTOJANV25!$A$6:$BQ$46,25,0),0) -> 150000 | E11: 290000 | G11: =SUM(D11:F11) -> 290000
A12: AS201608 | B12: =VLOOKUP(A12,[5]LISTADHERENT!$A$4:$J$44,3,0) -> DJUOMBESSY ANTOINE | C12: =IF(G12>0,VLOOKUP(A12,[6]HISTOJANV25!$A$6:$BQ$46,25,0),0) -> 250000 | D12: 31000 | E12: =365000+101500 -> 466500 | G12: =SUM(D12:F12) -> 497500
A13: AS201651 | B13: =VLOOKUP(A13,[5]LISTADHERENT!$A$4:$J$44,3,0) -> DOMOU FABIEN | C13: =IF(G13>0,VLOOKUP(A13,[6]HISTOJANV25!$A$6:$BQ$46,25,0),0) -> 50000 | E13: 50000 | G13: =SUM(D13:F13) -> 50000
A14: AS201609 | B14: =VLOOKUP(A14,[5]LISTADHERENT!$A$4:$J$44,3,0) -> DONHOU DAVID | C14: =IF(G14>0,VLOOKUP(A14,[6]HISTOJANV25!$A$6:$BQ$46,25,0),0) -> 50000 | E14: 50000 | G14: =SUM(D14:F14) -> 50000
A15: AS201663 | B15: =VLOOKUP(A15,[5]LISTADHERENT!$A$4:$J$44,3,0) -> FAMPOU PAUL | C15: =IF(G15>0,VLOOKUP(A15,[6]HISTOMARS25!$A$6:$BQ$46,25,0),0) -> 150000 | E15: 150000 | G15: =SUM(D15:F15) -> 150000
A16: AS201611 | B16: =VLOOKUP(A16,[5]LISTADHERENT!$A$4:$J$44,3,0) -> HENGUE PAUL OMER | C16: =IF(G16>0,VLOOKUP(A16,[6]HISTOJANV25!$A$6:$BQ$46,25,0),0) -> 125000 | E16: 125000 | G16: =SUM(D16:F16) -> 125000
A17: AS201613 | B17: =VLOOKUP(A17,[5]LISTADHERENT!$A$4:$J$44,3,0) -> HOTCHO BENJAMIN | C17: =IF(G17>0,VLOOKUP(A17,[6]HISTOJANV25!$A$6:$BQ$46,25,0),0) -> 225000 | E17: 342000 | G17: =SUM(D17:F17) -> 342000
A18: AS201617 | B18: =VLOOKUP(A18,[5]LISTADHERENT!$A$4:$J$44,3,0) -> KOUAMOU MOISE | C18: =IF(G18>0,VLOOKUP(A18,[6]HISTOJANV25!$A$6:$BQ$46,25,0),0) -> 150000 | E18: 180000 | G18: =SUM(D18:F18) -> 180000
A19: AS201619 | B19: =VLOOKUP(A19,[5]LISTADHERENT!$A$4:$J$44,3,0) -> KOUATCHO MESSACK | C19: =IF(G19>0,VLOOKUP(A19,[6]HISTOJANV25!$A$6:$BQ$46,25,0),0) -> 225000 | E19: =201000+175000 -> 376000 | G19: =SUM(D19:F19) -> 376000
A20: AS201620 | B20: =VLOOKUP(A20,[5]LISTADHERENT!$A$4:$J$44,3,0) -> LOWE JEAN
A21: AS201661 | B21: =VLOOKUP(A21,[5]LISTADHERENT!$A$4:$J$44,3,0) -> MASSEUNGOUE DAGOBERT | C21: =IF(G21>0,VLOOKUP(A21,[6]HISTOJANV25!$A$6:$BQ$46,25,0),0) -> 50000 | E21: =50000+25000 -> 75000 | G21: =SUM(D21:F21) -> 75000
A22: AS201649 | B22: =VLOOKUP(A22,[5]LISTADHERENT!$A$4:$J$44,3,0) -> MBOGNING TUGMA GUY | C22: =IF(G22>0,VLOOKUP(A22,[6]HISTOJANV25!$A$6:$BQ$46,25,0),0) -> 325000 | E22: 530000 | G22: =SUM(D22:F22) -> 530000
A23: AS201639 | B23: =VLOOKUP(A23,[5]LISTADHERENT!$A$4:$J$44,3,0) -> NANGUEN MARTIN | C23: =IF(G23>0,VLOOKUP(A23,[6]HISTOJANV25!$A$6:$BQ$46,25,0),0) -> 50000 | E23: 50000 | G23: =SUM(D23:F23) -> 50000
A24: AS201621 | B24: =VLOOKUP(A24,[5]LISTADHERENT!$A$4:$J$44,3,0) -> NANKAM APPOLINAIRE | C24: =IF(G24>0,VLOOKUP(A24,[6]HISTOJANV25!$A$6:$BQ$46,25,0),0) -> 125000 | E24: 125000 | G24: =SUM(D24:F24) -> 125000
A25: AS201622 | B25: =VLOOKUP(A25,[5]LISTADHERENT!$A$4:$J$44,3,0) -> NDJOMO ETIENNE | C25: =IF(G25>0,VLOOKUP(A25,[6]HISTOJANV25!$A$6:$BQ$46,25,0),0) -> 250000 | E25: =275000+206500 -> 481500 | G25: =SUM(D25:F25) -> 481500
A26: AS201624 | B26: =VLOOKUP(A26,[5]LISTADHERENT!$A$4:$J$44,3,0) -> NGONDIEP CLAUDE | C26: =IF(G26>0,VLOOKUP(A26,[6]HISTOJANV25!$A$6:$BQ$46,25,0),0) -> 225000 | E26: 240000 | G26: =SUM(D26:F26) -> 240000
A27: AS201626 | B27: =VLOOKUP(A27,[5]LISTADHERENT!$A$4:$J$44,3,0) -> NGUIEMEGNI MATHIEU BLAISE | C27: =IF(G27>0,VLOOKUP(A27,[6]HISTOJANV25!$A$6:$BQ$46,25,0),0) -> 250000 | E27: =240000+103000 -> 343000 | G27: =SUM(D27:F27) -> 343000
A28: AS201628 | B28: =VLOOKUP(A28,[5]LISTADHERENT!$A$4:$J$44,3,0) -> NKAMGANG JUSTIN DEJOLIE | C28: =IF(G28>0,VLOOKUP(A28,[6]HISTOJANV25!$A$6:$BQ$46,25,0),0) -> 50000 | E28: 50000 | G28: =SUM(D28:F28) -> 50000
A29: AS201656 | B29: =VLOOKUP(A29,[5]LISTADHERENT!$A$4:$J$44,3,0) -> NOUBE ETIENNE | C29: =IF(G29>0,VLOOKUP(A29,[6]HISTOJANV25!$A$6:$BQ$46,25,0),0) -> 50000 | E29: 50000 | G29: =SUM(D29:F29) -> 50000
A30: AS201633 | B30: =VLOOKUP(A30,[5]LISTADHERENT!$A$4:$J$44,3,0) -> PATEGO NJOSSU GUSTAVE | C30: =IF(G30>0,VLOOKUP(A30,[6]HISTOJANV25!$A$6:$BQ$46,25,0),0) -> 125000 | E30: 125000 | G30: =SUM(D30:F30) -> 125000
A31: AS201657 | B31: =VLOOKUP(A31,[5]LISTADHERENT!$A$4:$J$44,3,0) -> SEUMO POLYCARPE | C31: =IF(G31>0,VLOOKUP(A31,[6]HISTOJANV25!$A$6:$BQ$46,25,0),0) -> 50000 | E31: 50000 | G31: =SUM(D31:F31) -> 50000
A32: AS201653 | B32: =VLOOKUP(A32,[5]LISTADHERENT!$A$4:$J$44,3,0) -> SIME BRICE | C32: =IF(G32>0,VLOOKUP(A32,[6]HISTOJANV25!$A$6:$BQ$46,25,0),0) -> 250000 | E32: 250000 | G32: =SUM(D32:F32) -> 250000
A33: AS201629 | B33: =VLOOKUP(A33,[5]LISTADHERENT!$A$4:$J$44,3,0) -> SIMO FONGANG ERIC | C33: =IF(G33>0,VLOOKUP(A33,[6]HISTOJANV25!$A$6:$BQ$46,25,0),0) -> 50000 | D33: 50000 | G33: =SUM(D33:F33) -> 50000
A34: AS201638 | B34: =VLOOKUP(A34,[5]LISTADHERENT!$A$4:$J$44,3,0) -> SIMO PIERRE | C34: =IF(G34>0,VLOOKUP(A34,[6]HISTOJANV25!$A$6:$BQ$46,25,0),0) -> 150000 | E34: =130000+45000 -> 175000 | G34: =SUM(D34:F34) -> 175000
A35: AS201641 | B35: =VLOOKUP(A35,[5]LISTADHERENT!$A$4:$J$44,3,0) -> TCHOUAMOU MATHIEU | C35: =IF(G35>0,VLOOKUP(A35,[6]HISTOJANV25!$A$6:$BQ$46,25,0),0) -> 125000 | E35: =125000+102000 -> 227000 | G35: =SUM(D35:F35) -> 227000
A36: AS201660 | B36: =VLOOKUP(A36,[5]LISTADHERENT!$A$4:$J$44,3,0) -> TCHOUATEU AUGUSTIN | C36: =IF(G36>0,VLOOKUP(A36,[6]HISTOJANV25!$A$6:$BQ$46,25,0),0) -> 150000 | E36: 150000 | G36: =SUM(D36:F36) -> 150000
A37: AS201643 | B37: =VLOOKUP(A37,[5]LISTADHERENT!$A$4:$J$44,3,0) -> TCHOUTOU NANA CLAUDE | C37: =IF(G37>0,VLOOKUP(A37,[6]HISTOJANV25!$A$6:$BQ$46,25,0),0) -> 50000 | E37: 50000 | G37: =SUM(D37:F37) -> 50000
A38: AS201662 | B38: =VLOOKUP(A38,[5]LISTADHERENT!$A$4:$J$44,3,0) -> TIEYAM ERNEST | C38: =IF(G38>0,VLOOKUP(A38,[6]HISTOJANV25!$A$6:$BQ$46,25,0),0) -> 50000 | D38: 53000 | G38: =SUM(D38:F38) -> 53000
A39: AS201658 | B39: =VLOOKUP(A39,[5]LISTADHERENT!$A$4:$J$44,3,0) -> YANTCHOU GERVAIS | C39: =IF(G39>0,VLOOKUP(A39,[6]HISTOJANV25!$A$6:$BQ$46,25,0),0) -> 125000 | E39: 125000 | G39: =SUM(D39:F39) -> 125000
A40: AS201646 | B40: =VLOOKUP(A40,[5]LISTADHERENT!$A$4:$J$44,3,0) -> YEPMOU JEAN JACQUES | C40: =IF(G40>0,VLOOKUP(A40,[6]HISTOJANV25!$A$6:$BQ$46,25,0),0) -> 50000 | E40: 50000 | G40: =SUM(D40:F40) -> 50000
...

Sheet HISTOBQUEAOUT25
A1: ASSOCIATION | B1: ASELBY | C1: 45870
A2: ANNEE | B2: 2025
A3: 1 | B3: 2 | C3: 3 | D3: 4 | E3: 5 | F3: 6 | G3: 7
B4: HISTORIQUE BANCAIRE
A5: MATRICULE | B5: NOM ET PRENOM | C5: HISTORIQUE TONTINE | D5: HITORIQUE ESPECES | E5: HITORIQUE BANQUE | F5: AUTRE VERSEMENT | G5: MONTANT ENGAGEMENT | H5: AGIO
A6: AS201648 | B6: =VLOOKUP(A6,[5]LISTADHERENT!$A$4:$J$44,3,0) -> ASELBY | C6: =IF(G6>0,VLOOKUP(A6,[6]HISTOJANV25!$A$6:$BQ$46,25,0),0) -> 250000 | E6: 250000 | G6: =SUM(D6:F6) -> 250000 | H6: 2385
A7: AS201601 | B7: =VLOOKUP(A7,[5]LISTADHERENT!$A$4:$J$44,3,0) -> BAKOP ACHILLE | C7: =IF(G7>0,VLOOKUP(A7,[6]HISTOJANV25!$A$6:$BQ$46,25,0),0) -> 50000 | D7: 50000 | G7: =SUM(D7:F7) -> 50000
A8: AS201602 | B8: =VLOOKUP(A8,[5]LISTADHERENT!$A$4:$J$44,3,0) -> BOUTCHOUANG WILLIAM | C8: =IF(G8>0,VLOOKUP(A8,[6]HISTOJANV25!$A$6:$BQ$46,25,0),0) -> 125000 | E8: 125000 | G8: =SUM(D8:F8) -> 125000
A9: AS201604 | B9: =VLOOKUP(A9,[5]LISTADHERENT!$A$4:$J$44,3,0) -> DJOMO JEAN PAUL | C9: =IF(G9>0,VLOOKUP(A9,[6]HISTOJANV25!$A$6:$BQ$46,25,0),0) -> 250000 | D9: =351000+102500 -> 453500 | G9: =SUM(D9:F9) -> 453500
A10: AS201654 | B10: =VLOOKUP(A10,[5]LISTADHERENT!$A$4:$J$44,3,0) -> DJOMOU TCHAPDA | C10: =IF(G10>0,VLOOKUP(A10,[6]HISTOJANV25!$A$6:$BQ$46,25,0),0) -> 50000 | E10: 77000 | G10: =SUM(D10:F10) -> 77000
A11: AS201605 | B11: =VLOOKUP(A11,[5]LISTADHERENT!$A$4:$J$44,3,0) -> DJOUKWE NANGUEN GUY BLAISE | C11: =IF(G11>0,VLOOKUP(A11,[6]HISTOJANV25!$A$6:$BQ$46,25,0),0) -> 150000 | E11: 400000 | G11: =SUM(D11:F11) -> 400000
A12: AS201608 | B12: =VLOOKUP(A12,[5]LISTADHERENT!$A$4:$J$44,3,0) -> DJUOMBESSY ANTOINE | C12: =IF(G12>0,VLOOKUP(A12,[6]HISTOJANV25!$A$6:$BQ$46,25,0),0) -> 250000 | E12: =300000+125000+104500 -> 529500 | G12: =SUM(D12:F12) -> 529500
A13: AS201651 | B13: =VLOOKUP(A13,[5]LISTADHERENT!$A$4:$J$44,3,0) -> DOMOU FABIEN | C13: =IF(G13>0,VLOOKUP(A13,[6]HISTOJANV25!$A$6:$BQ$46,25,0),0) -> 50000 | E13: 50000 | G13: =SUM(D13:F13) -> 50000
A14: AS201609 | B14: =VLOOKUP(A14,[5]LISTADHERENT!$A$4:$J$44,3,0) -> DONHOU DAVID | C14: =IF(G14>0,VLOOKUP(A14,[6]HISTOJANV25!$A$6:$BQ$46,25,0),0) -> 50000 | E14: 50000 | G14: =SUM(D14:F14) -> 50000
A15: AS201663 | B15: =VLOOKUP(A15,[5]LISTADHERENT!$A$4:$J$44,3,0) -> FAMPOU PAUL | C15: =IF(G15>0,VLOOKUP(A15,[6]HISTOMARS25!$A$6:$BQ$46,25,0),0) -> 150000 | E15: 251000 | G15: =SUM(D15:F15) -> 251000
A16: AS201611 | B16: =VLOOKUP(A16,[5]LISTADHERENT!$A$4:$J$44,3,0) -> HENGUE PAUL OMER | C16: =IF(G16>0,VLOOKUP(A16,[6]HISTOJANV25!$A$6:$BQ$46,25,0),0) -> 125000 | E16: 125000 | G16: =SUM(D16:F16) -> 125000
A17: AS201613 | B17: =VLOOKUP(A17,[5]LISTADHERENT!$A$4:$J$44,3,0) -> HOTCHO BENJAMIN | C17: =IF(G17>0,VLOOKUP(A17,[6]HISTOJANV25!$A$6:$BQ$46,25,0),0) -> 225000 | E17: 250000 | G17: =SUM(D17:F17) -> 250000
A18: AS201617 | B18: =VLOOKUP(A18,[5]LISTADHERENT!$A$4:$J$44,3,0) -> KOUAMOU MOISE | C18: =IF(G18>0,VLOOKUP(A18,[6]HISTOJANV25!$A$6:$BQ$46,25,0),0) -> 150000 | E18: 150000 | G18: =SUM(D18:F18) -> 150000
A19: AS201619 | B19: =VLOOKUP(A19,[5]LISTADHERENT!$A$4:$J$44,3,0) -> KOUATCHO MESSACK | C19: =IF(G19>0,VLOOKUP(A19,[6]HISTOJANV25!$A$6:$BQ$46,25,0),0) -> 225000 | E19: =235000+135000 -> 370000 | G19: =SUM(D19:F19) -> 370000
A20: AS201620 | B20: =VLOOKUP(A20,[5]LISTADHERENT!$A$4:$J$44,3,0) -> LOWE JEAN
A21: AS201661 | B21: =VLOOKUP(A21,[5]LISTADHERENT!$A$4:$J$44,3,0) -> MASSEUNGOUE DAGOBERT | C21: =IF(G21>0,VLOOKUP(A21,[6]HISTOJANV25!$A$6:$BQ$46,25,0),0) -> 50000 | E21: 50000 | G21: =SUM(D21:F21) -> 50000
A22: AS201649 | B22: =VLOOKUP(A22,[5]LISTADHERENT!$A$4:$J$44,3,0) -> MBOGNING TUGMA GUY | C22: =IF(G22>0,VLOOKUP(A22,[6]HISTOJANV25!$A$6:$BQ$46,25,0),0) -> 325000 | E22: =530000+104500 -> 634500 | G22: =SUM(D22:F22) -> 634500
A23: AS201639 | B23: =VLOOKUP(A23,[5]LISTADHERENT!$A$4:$J$44,3,0) -> NANGUEN MARTIN | C23: =IF(G23>0,VLOOKUP(A23,[6]HISTOJANV25!$A$6:$BQ$46,25,0),0) -> 50000 | E23: 50000 | G23: =SUM(D23:F23) -> 50000
A24: AS201621 | B24: =VLOOKUP(A24,[5]LISTADHERENT!$A$4:$J$44,3,0) -> NANKAM APPOLINAIRE | C24: =IF(G24>0,VLOOKUP(A24,[6]HISTOJANV25!$A$6:$BQ$46,25,0),0) -> 125000 | E24: 125000 | G24: =SUM(D24:F24) -> 125000
A25: AS201622 | B25: =VLOOKUP(A25,[5]LISTADHERENT!$A$4:$J$44,3,0) -> NDJOMO ETIENNE | C25: =IF(G25>0,VLOOKUP(A25,[6]HISTOJANV25!$A$6:$BQ$46,25,0),0) -> 250000 | E25: =260000+206000 -> 466000 | G25: =SUM(D25:F25) -> 466000
A26: AS201624 | B26: =VLOOKUP(A26,[5]LISTADHERENT!$A$4:$J$44,3,0) -> NGONDIEP CLAUDE | C26: =IF(G26>0,VLOOKUP(A26,[6]HISTOJANV25!$A$6:$BQ$46,25,0),0) -> 225000 | E26: =240000+125000 -> 365000 | G26: =SUM(D26:F26) -> 365000
A27: AS201626 | B27: =VLOOKUP(A27,[5]LISTADHERENT!$A$4:$J$44,3,0) -> NGUIEMEGNI MATHIEU BLAISE | C27: =IF(G27>0,VLOOKUP(A27,[6]HISTOJANV25!$A$6:$BQ$46,25,0),0) -> 250000 | E27: =170000+150000 -> 320000 | F27: 133500 | G27: =SUM(D27:F27) -> 453500
