Workbook
Name BANQUE: #REF!
Name BANQUE: #REF!
Name BANQUE: #REF!
Name BANQUE: #REF!
Name BANQUE: #REF!
Name BANQUE: #REF!
Name BANQUE: #REF!
Name BANQUE: #REF!
Name BANQUE: #REF!
Name BANQUE: #REF!
Name BANQUE: #REF!
Name BANQUE: #REF!
Name BANQUE: #REF!
Name BANQUE: #REF!
Name BANQUE: #REF!
Name BANQUE: #REF!
Name BANQUE: #REF!
Name BANQUE: #REF!
Name BANQUE: #REF!
Name BANQUE: #REF!
Name BANQUE: #REF!
Name BANQUE: #REF!
Name BANQUE: #REF!
Name BANQUE: #REF!
Name BANQUE: #REF!
Name BANQUE: #REF!
Name BANQUE: #REF!
Name MODEPAID: [1]Feuil2!$A$1:$A$3
Name MODET25000: [2]MODEVERSEMENT!$A$1:$A$3
Name MODEVERSEMENT: #REF!
Name MODEVERSEMENT: #REF!
Name MODEVERSEMENT: #REF!
Name MODEVERSEMENT: #REF!
Name MODEVERSEMENT: #REF!
Name MODEVERSEMENT: #REF!
Name MODEVERSEMENT: #REF!
Name MODEVERSEMENT: #REF!
Name MODEVERSEMENT: #REF!
Name MODEVERSEMENT: #REF!
Name MODEVERSEMENT: #REF!
Name MODEVERSEMENT: #REF!
Name MODEVERSEMENT: #REF!
Name MODEVERSEMENT: #REF!
Name MODEVERSEMENT: #REF!
Name MODEVERSEMENT: #REF!
Name MODEVERSEMENT: #REF!
Name MODEVERSEMENT: #REF!
Name MODEVERSEMENT: #REF!
Name MODEVERSEMENT: #REF!
Name MODEVERSEMENT: #REF!
Name MODEVERSEMENT: #REF!
Name MODEVERSEMENT: #REF!
Name MODEVERSEMENT: #REF!
Name MODEVERSEMENT: #REF!
Name MODEVERSEMENT: #REF!
Name MODEVERSEMENT: #REF!
Name MODEVERSEMENTS: #REF!
Name MODEVERSEMENTS: #REF!
Name MODEVERSEMENTS: #REF!
Name MODEVERSEMENTS: #REF!

Sheet HISTOJANV25
A1: ASSOCIATION | B1: ASELBY
A2: ANNEE | B2: 2025
A3: MATRICULE | B3: NOM ET PRENOM | G3: TOTAUX
C4: MONTANT CHEQUE | D4: NUM CHEQUE | E4: AGIOS | F4: Extrait de compte
B5: CHEQUE ETABLI | C5: 7134000
A6: AS201648 | B6: =VLOOKUP(A6,[4]LISTADHERENT!A$5:H$50,3,0) -> ASELBY | C6: =VLOOKUP(A6,[5]HISTOJANV25!$A$6:$BQ$45,56,0) -> 571000 | D6: =VLOOKUP(A6,[5]HISTOJANV25!$A$6:$BQ$45,57,0) -> 0 | E6: =+[6]HISTOBQUEJANV25!$H$6 -> 4770 | G6: =SUM(E6:F6) -> 4770
A7: AS201601 | B7: =VLOOKUP(A7,[4]LISTADHERENT!A$5:H$50,3,0) -> BAKOP ACHILLE | C7: =VLOOKUP(A7,[5]HISTOJANV25!$A$6:$BQ$45,56,0) -> 890000 | D7: =VLOOKUP(A7,[5]HISTOJANV25!$A$6:$BQ$45,57,0) -> OK | G7: =SUM(E7:F7) -> 0
A8: AS201602 | B8: =VLOOKUP(A8,[4]LISTADHERENT!A$5:H$50,3,0) -> BOUTCHOUANG WILLIAM | C8: =VLOOKUP(A8,[5]HISTOJANV25!$A$6:$BQ$45,56,0) -> 0 | D8: =VLOOKUP(A8,[5]HISTOJANV25!$A$6:$BQ$45,57,0) -> 0 | G8: =SUM(E8:F8) -> 0
A9: AS201604 | B9: =VLOOKUP(A9,[4]LISTADHERENT!A$5:H$50,3,0) -> DJOMO JEAN PAUL | C9: =VLOOKUP(A9,[5]HISTOJANV25!$A$6:$BQ$45,56,0) -> 269000 | D9: =VLOOKUP(A9,[5]HISTOJANV25!$A$6:$BQ$45,57,0) -> OK | G9: =SUM(E9:F9) -> 0
A10: AS201654 | B10: =VLOOKUP(A10,[4]LISTADHERENT!A$5:H$50,3,0) -> DJOMOU TCHAPDA | C10: =VLOOKUP(A10,[5]HISTOJANV25!$A$6:$BQ$45,56,0) -> 270000 | D10: =VLOOKUP(A10,[5]HISTOJANV25!$A$6:$BQ$45,57,0) -> OK | G10: =SUM(E10:F10) -> 0
A11: AS201605 | B11: =VLOOKUP(A11,[4]LISTADHERENT!A$5:H$50,3,0) -> DJOUKWE NANGUEN GUY BLAISE | C11: =VLOOKUP(A11,[5]HISTOJANV25!$A$6:$BQ$45,56,0) -> 0 | D11: =VLOOKUP(A11,[5]HISTOJANV25!$A$6:$BQ$45,57,0) -> 0 | G11: =SUM(E11:F11) -> 0
A12: AS201608 | B12: =VLOOKUP(A12,[4]LISTADHERENT!A$5:H$50,3,0) -> DJUOMBESSY ANTOINE | C12: =VLOOKUP(A12,[5]HISTOJANV25!$A$6:$BQ$45,56,0) -> 0 | D12: =VLOOKUP(A12,[5]HISTOJANV25!$A$6:$BQ$45,57,0) -> 0 | G12: =SUM(E12:F12) -> 0
A13: AS201651 | B13: =VLOOKUP(A13,[4]LISTADHERENT!A$5:H$50,3,0) -> DOMOU FABIEN | C13: =VLOOKUP(A13,[5]HISTOJANV25!$A$6:$BQ$45,56,0) -> 0 | D13: =VLOOKUP(A13,[5]HISTOJANV25!$A$6:$BQ$45,57,0) -> 0 | G13: =SUM(E13:F13) -> 0
A14: AS201609 | B14: =VLOOKUP(A14,[4]LISTADHERENT!A$5:H$50,3,0) -> DONHOU DAVID | C14: =VLOOKUP(A14,[5]HISTOJANV25!$A$6:$BQ$45,56,0) -> 0 | D14: =VLOOKUP(A14,[5]HISTOJANV25!$A$6:$BQ$45,57,0) -> 0 | G14: =SUM(E14:F14) -> 0
A15: AS201663 | B15: =VLOOKUP(A15,[4]LISTADHERENT!A$5:H$50,3,0) -> FAMPOU PAUL | C15: =VLOOKUP(A15,[5]HISTOJANV25!$A$6:$BQ$45,56,0) -> 0 | D15: =VLOOKUP(A15,[5]HISTOJANV25!$A$6:$BQ$45,57,0) -> 0 | G15: =SUM(E15:F15) -> 0
A16: AS201611 | B16: =VLOOKUP(A16,[4]LISTADHERENT!A$5:H$50,3,0) -> HENGUE PAUL OMER | C16: =VLOOKUP(A16,[5]HISTOJANV25!$A$6:$BQ$45,56,0) -> 0 | D16: =VLOOKUP(A16,[5]HISTOJANV25!$A$6:$BQ$45,57,0) -> 0 | G16: =SUM(E16:F16) -> 0
A17: AS201613 | B17: =VLOOKUP(A17,[4]LISTADHERENT!A$5:H$50,3,0) -> HOTCHO BENJAMIN | C17: =VLOOKUP(A17,[5]HISTOJANV25!$A$6:$BQ$45,56,0) -> 0 | D17: =VLOOKUP(A17,[5]HISTOJANV25!$A$6:$BQ$45,57,0) -> 0 | G17: =SUM(E17:F17) -> 0
A18: AS201617 | B18: =VLOOKUP(A18,[4]LISTADHERENT!A$5:H$50,3,0) -> KOUAMOU MOISE | C18: =VLOOKUP(A18,[5]HISTOJANV25!$A$6:$BQ$45,56,0) -> 738500 | D18: =VLOOKUP(A18,[5]HISTOJANV25!$A$6:$BQ$45,57,0) -> OK | G18: =SUM(E18:F18) -> 0
A19: AS201619 | B19: =VLOOKUP(A19,[4]LISTADHERENT!A$5:H$50,3,0) -> KOUATCHO MESSACK | C19: =VLOOKUP(A19,[5]HISTOJANV25!$A$6:$BQ$45,56,0) -> 1095000 | D19: =VLOOKUP(A19,[5]HISTOJANV25!$A$6:$BQ$45,57,0) -> OK | G19: =SUM(E19:F19) -> 0
A20: AS201620 | B20: =VLOOKUP(A20,[4]LISTADHERENT!A$5:H$50,3,0) -> LOWE JEAN | C20: =VLOOKUP(A20,[5]HISTOJANV25!$A$6:$BQ$45,56,0) -> 0 | D20: =VLOOKUP(A20,[5]HISTOJANV25!$A$6:$BQ$45,57,0) -> 0
A21: AS201661 | B21: =VLOOKUP(A21,[4]LISTADHERENT!A$5:H$50,3,0) -> MASSEUNGOUE DAGOBERT | C21: =VLOOKUP(A21,[5]HISTOJANV25!$A$6:$BQ$45,56,0) -> 0 | D21: =VLOOKUP(A21,[5]HISTOJANV25!$A$6:$BQ$45,57,0) -> 0 | G21: =SUM(E21:F21) -> 0
A22: AS201649 | B22: =VLOOKUP(A22,[4]LISTADHERENT!A$5:H$50,3,0) -> MBOGNING TUGMA GUY | C22: =VLOOKUP(A22,[5]HISTOJANV25!$A$6:$BQ$45,56,0) -> 0 | D22: =VLOOKUP(A22,[5]HISTOJANV25!$A$6:$BQ$45,57,0) -> 0 | G22: =SUM(E22:F22) -> 0
A23: AS201639 | B23: =VLOOKUP(A23,[4]LISTADHERENT!A$5:H$50,3,0) -> NANGUEN MARTIN | C23: =VLOOKUP(A23,[5]HISTOJANV25!$A$6:$BQ$45,56,0) -> 0 | D23: =VLOOKUP(A23,[5]HISTOJANV25!$A$6:$BQ$45,57,0) -> 0 | G23: =SUM(E23:F23) -> 0
A24: AS201621 | B24: =VLOOKUP(A24,[4]LISTADHERENT!A$5:H$50,3,0) -> NANKAM APPOLINAIRE | C24: =VLOOKUP(A24,[5]HISTOJANV25!$A$6:$BQ$45,56,0) -> 860500 | D24: =VLOOKUP(A24,[5]HISTOJANV25!$A$6:$BQ$45,57,0) -> OK | G24: =SUM(E24:F24) -> 0
A25: AS201622 | B25: =VLOOKUP(A25,[4]LISTADHERENT!A$5:H$50,3,0) -> NDJOMO ETIENNE | C25: =VLOOKUP(A25,[5]HISTOJANV25!$A$6:$BQ$45,56,0) -> 0 | D25: =VLOOKUP(A25,[5]HISTOJANV25!$A$6:$BQ$45,57,0) -> 0 | G25: =SUM(E25:F25) -> 0
A26: AS201624 | B26: =VLOOKUP(A26,[4]LISTADHERENT!A$5:H$50,3,0) -> NGONDIEP CLAUDE | C26: =VLOOKUP(A26,[5]HISTOJANV25!$A$6:$BQ$45,56,0) -> 890000 | D26: =VLOOKUP(A26,[5]HISTOJANV25!$A$6:$BQ$45,57,0) -> OK | G26: =SUM(E26:F26) -> 0
A27: AS201626 | B27: =VLOOKUP(A27,[4]LISTADHERENT!A$5:H$50,3,0) -> NGUIEMEGNI MATHIEU BLAISE | C27: =VLOOKUP(A27,[5]HISTOJANV25!$A$6:$BQ$45,56,0) -> 1080000 | D27: =VLOOKUP(A27,[5]HISTOJANV25!$A$6:$BQ$45,57,0) -> OK | G27: =SUM(E27:F27) -> 0
A28: AS201628 | B28: =VLOOKUP(A28,[4]LISTADHERENT!A$5:H$50,3,0) -> NKAMGANG JUSTIN DEJOLIE | C28: =VLOOKUP(A28,[5]HISTOJANV25!$A$6:$BQ$45,56,0) -> 0 | D28: =VLOOKUP(A28,[5]HISTOJANV25!$A$6:$BQ$45,57,0) -> 0 | G28: =SUM(E28:F28) -> 0
A29: AS201656 | B29: =VLOOKUP(A29,[4]LISTADHERENT!A$5:H$50,3,0) -> NOUBE ETIENNE | C29: =VLOOKUP(A29,[5]HISTOJANV25!$A$6:$BQ$45,56,0) -> 0 | D29: =VLOOKUP(A29,[5]HISTOJANV25!$A$6:$BQ$45,57,0) -> 0 | G29: =SUM(E29:F29) -> 0
A30: AS201633 | B30: =VLOOKUP(A30,[4]LISTADHERENT!A$5:H$50,3,0) -> PATEGO NJOSSU GUSTAVE | C30: =VLOOKUP(A30,[5]HISTOJANV25!$A$6:$BQ$45,56,0) -> 0 | D30: =VLOOKUP(A30,[5]HISTOJANV25!$A$6:$BQ$45,57,0) -> 0 | G30: =SUM(E30:F30) -> 0
A31: AS201657 | B31: =VLOOKUP(A31,[4]LISTADHERENT!A$5:H$50,3,0) -> SEUMO POLYCARPE | C31: =VLOOKUP(A31,[5]HISTOJANV25!$A$6:$BQ$45,56,0) -> 270000 | D31: =VLOOKUP(A31,[5]HISTOJANV25!$A$6:$BQ$45,57,0) -> OK | G31: =SUM(E31:F31) -> 0
A32: AS201653 | B32: =VLOOKUP(A32,[4]LISTADHERENT!A$5:H$50,3,0) -> SIME BRICE | C32: =VLOOKUP(A32,[5]HISTOJANV25!$A$6:$BQ$45,56,0) -> 0 | D32: =VLOOKUP(A32,[5]HISTOJANV25!$A$6:$BQ$45,57,0) -> 0 | G32: =SUM(E32:F32) -> 0
... A42: AS201647 | B42: =VLOOKUP(A42,[4]LISTADHERENT!A$5:H$50,3,0) -> YOUMBI EMMANUEL | C42: =VLOOKUP(A42,[5]HISTOJANV25!$A$6:$BQ$45,56,0) -> 0 | D42: =VLOOKUP(A42,[5]HISTOJANV25!$A$6:$BQ$45,57,0) -> 0 | G42: =SUM(E42:F42) -> 0
B43: SOLDE BANQUE | F43: 9304408
B44: TOTAUX | C44: =SUM(C6:C43) -> 7134000 | E44: =SUM(E7:E43) -> 0 | G44: =SUM(G7:G43) -> 0
B46: DIFFERENCE A CHERCHER | C46: =C44-C5 -> 0
B48: COMPTE BANQUE
B50: LIBELLE
B51: REPORT
B52: TONTINE

Sheet HISTOFEV25
A1: ASSOCIATION | B1: ASELBY
A2: ANNEE | B2: 2025
A3: MATRICULE | B3: NOM ET PRENOM | G3: TOTAUX
C4: MONTANT CHEQUE | D4: NUM CHEQUE | E4: AGIOS | F4: Extrait de compte
B5: CHEQUE ETABLI
A6: AS201648 | B6: =VLOOKUP(A6,[4]LISTADHERENT!A$5:H$50,3,0) -> ASELBY | C6: =VLOOKUP(A6,[5]HISTOFEV25!$A$6:$BQ$45,56,0) -> 6000 | D6: =VLOOKUP(A6,[5]HISTOFEV25!$A$6:$BQ$45,57,0) -> OK | E6: =+[6]HISTOBQUEFEV25!$H$6 -> 1191 | G6: =SUM(E6:F6) -> 1191
A7: AS201601 | B7: =VLOOKUP(A7,[4]LISTADHERENT!A$5:H$50,3,0) -> BAKOP ACHILLE | C7: =VLOOKUP(A7,[5]HISTOFEV25!$A$6:$BQ$45,56,0) -> 0 | D7: =VLOOKUP(A7,[5]HISTOFEV25!$A$6:$BQ$45,57,0) -> 0 | G7: =SUM(E7:F7) -> 0
A8: AS201602 | B8: =VLOOKUP(A8,[4]LISTADHERENT!A$5:H$50,3,0) -> BOUTCHOUANG WILLIAM | C8: =VLOOKUP(A8,[5]HISTOFEV25!$A$6:$BQ$45,56,0) -> 100000 | D8: =VLOOKUP(A8,[5]HISTOFEV25!$A$6:$BQ$45,57,0) -> OK | G8: =SUM(E8:F8) -> 0
A9: AS201604 | B9: =VLOOKUP(A9,[4]LISTADHERENT!A$5:H$50,3,0) -> DJOMO JEAN PAUL | C9: =VLOOKUP(A9,[5]HISTOFEV25!$A$6:$BQ$45,56,0) -> 1320000 | D9: =VLOOKUP(A9,[5]HISTOFEV25!$A$6:$BQ$45,57,0) -> OK | G9: =SUM(E9:F9) -> 0
A10: AS201654 | B10: =VLOOKUP(A10,[4]LISTADHERENT!A$5:H$50,3,0) -> DJOMOU TCHAPDA | C10: =VLOOKUP(A10,[5]HISTOFEV25!$A$6:$BQ$45,56,0) -> 0 | D10: =VLOOKUP(A10,[5]HISTOFEV25!$A$6:$BQ$45,57,0) -> 0 | G10: =SUM(E10:F10) -> 0
A11: AS201605 | B11: =VLOOKUP(A11,[4]LISTADHERENT!A$5:H$50,3,0) -> DJOUKWE NANGUEN GUY BLAISE | C11: =VLOOKUP(A11,[5]HISTOFEV25!$A$6:$BQ$45,56,0) -> 51000 | D11: =VLOOKUP(A11,[5]HISTOFEV25!$A$6:$BQ$45,57,0) -> OK | G11: =SUM(E11:F11) -> 0
A12: AS201608 | B12: =VLOOKUP(A12,[4]LISTADHERENT!A$5:H$50,3,0) -> DJUOMBESSY ANTOINE | C12: =VLOOKUP(A12,[5]HISTOFEV25!$A$6:$BQ$45,56,0) -> 0 | D12: =VLOOKUP(A12,[5]HISTOFEV25!$A$6:$BQ$45,57,0) -> 0 | G12: =SUM(E12:F12) -> 0
A13: AS201651 | B13: =VLOOKUP(A13,[4]LISTADHERENT!A$5:H$50,3,0) -> DOMOU FABIEN | C13: =VLOOKUP(A13,[5]HISTOFEV25!$A$6:$BQ$45,56,0) -> 0 | D13: =VLOOKUP(A13,[5]HISTOFEV25!$A$6:$BQ$45,57,0) -> 0 | G13: =SUM(E13:F13) -> 0
A14: AS201609 | B14: =VLOOKUP(A14,[4]LISTADHERENT!A$5:H$50,3,0) -> DONHOU DAVID | C14: =VLOOKUP(A14,[5]HISTOFEV25!$A$6:$BQ$45,56,0) -> 0 | D14: =VLOOKUP(A14,[5]HISTOFEV25!$A$6:$BQ$45,57,0) -> 0 | G14: =SUM(E14:F14) -> 0
A15: AS201663 | B15: =VLOOKUP(A15,[4]LISTADHERENT!A$5:H$50,3,0) -> FAMPOU PAUL | C15: =VLOOKUP(A15,[5]HISTOFEV25!$A$6:$BQ$45,56,0) -> 0 | D15: =VLOOKUP(A15,[5]HISTOFEV25!$A$6:$BQ$45,57,0) -> 0 | G15: =SUM(E15:F15) -> 0
A16: AS201611 | B16: =VLOOKUP(A16,[4]LISTADHERENT!A$5:H$50,3,0) -> HENGUE PAUL OMER | C16: =VLOOKUP(A16,[5]HISTOFEV25!$A$6:$BQ$45,56,0) -> 0 | D16: =VLOOKUP(A16,[5]HISTOFEV25!$A$6:$BQ$45,57,0) -> 0 | G16: =SUM(E16:F16) -> 0
A17: AS201613 | B17: =VLOOKUP(A17,[4]LISTADHERENT!A$5:H$50,3,0) -> HOTCHO BENJAMIN | C17: =VLOOKUP(A17,[5]HISTOFEV25!$A$6:$BQ$45,56,0) -> 0 | D17: =VLOOKUP(A17,[5]HISTOFEV25!$A$6:$BQ$45,57,0) -> 0 | G17: =SUM(E17:F17) -> 0
A18: AS201617 | B18: =VLOOKUP(A18,[4]LISTADHERENT!A$5:H$50,3,0) -> KOUAMOU MOISE | C18: =VLOOKUP(A18,[5]HISTOFEV25!$A$6:$BQ$45,56,0) -> 470000 | D18: =VLOOKUP(A18,[5]HISTOFEV25!$A$6:$BQ$45,57,0) -> OK | G18: =SUM(E18:F18) -> 0
A19: AS201619 | B19: =VLOOKUP(A19,[4]LISTADHERENT!A$5:H$50,3,0) -> KOUATCHO MESSACK | C19: =VLOOKUP(A19,[5]HISTOFEV25!$A$6:$BQ$45,56,0) -> 327000 | D19: =VLOOKUP(A19,[5]HISTOFEV25!$A$6:$BQ$45,57,0) -> OK | G19: =SUM(E19:F19) -> 0
C20: =VLOOKUP(A20,[5]HISTOFEV25!$A$6:$BQ$45,56,0) -> #N/A | D20: =VLOOKUP(A20,[5]HISTOFEV25!$A$6:$BQ$45,57,0) -> #N/A
A21: AS201661 | B21: =VLOOKUP(A21,[4]LISTADHERENT!A$5:H$50,3,0) -> MASSEUNGOUE DAGOBERT | C21: =VLOOKUP(A21,[5]HISTOFEV25!$A$6:$BQ$45,56,0) -> 0 | D21: =VLOOKUP(A21,[5]HISTOFEV25!$A$6:$BQ$45,57,0) -> 0 | G21: =SUM(E21:F21) -> 0
A22: AS201649 | B22: =VLOOKUP(A22,[4]LISTADHERENT!A$5:H$50,3,0) -> MBOGNING TUGMA GUY | C22: =VLOOKUP(A22,[5]HISTOFEV25!$A$6:$BQ$45,56,0) -> 1127500 | D22: =VLOOKUP(A22,[5]HISTOFEV25!$A$6:$BQ$45,57,0) -> OK | G22: =SUM(E22:F22) -> 0
A23: AS201639 | B23: =VLOOKUP(A23,[4]LISTADHERENT!A$5:H$50,3,0) -> NANGUEN MARTIN | C23: =VLOOKUP(A23,[5]HISTOFEV25!$A$6:$BQ$45,56,0) -> 0 | D23: =VLOOKUP(A23,[5]HISTOFEV25!$A$6:$BQ$45,57,0) -> 0 | G23: =SUM(E23:F23) -> 0
A24: AS201621 | B24: =VLOOKUP(A24,[4]LISTADHERENT!A$5:H$50,3,0) -> NANKAM APPOLINAIRE | C24: =VLOOKUP(A24,[5]HISTOFEV25!$A$6:$BQ$45,56,0) -> 600000 | D24: =VLOOKUP(A24,[5]HISTOFEV25!$A$6:$BQ$45,57,0) -> OK | G24: =SUM(E24:F24) -> 0
A25: AS201622 | B25: =VLOOKUP(A25,[4]LISTADHERENT!A$5:H$50,3,0) -> NDJOMO ETIENNE | C25: =VLOOKUP(A25,[5]HISTOFEV25!$A$6:$BQ$45,56,0) -> 100000 | D25: =VLOOKUP(A25,[5]HISTOFEV25!$A$6:$BQ$45,57,0) -> OK | G25: =SUM(E25:F25) -> 0
A26: AS201624 | B26: =VLOOKUP(A26,[4]LISTADHERENT!A$5:H$50,3,0) -> NGONDIEP CLAUDE | C26: =VLOOKUP(A26,[5]HISTOFEV25!$A$6:$BQ$45,56,0) -> 0 | D26: =VLOOKUP(A26,[5]HISTOFEV25!$A$6:$BQ$45,57,0) -> 0 | G26: =SUM(E26:F26) -> 0
A27: AS201626 | B27: =VLOOKUP(A27,[4]LISTADHERENT!A$5:H$50,3,0) -> NGUIEMEGNI MATHIEU BLAISE | C27: =VLOOKUP(A27,[5]HISTOFEV25!$A$6:$BQ$45,56,0) -> 474000 | D27: =VLOOKUP(A27,[5]HISTOFEV25!$A$6:$BQ$45,57,0) -> OK | G27: =SUM(E27:F27) -> 0
A28: AS201628 | B28: =VLOOKUP(A28,[4]LISTADHERENT!A$5:H$50,3,0) -> NKAMGANG JUSTIN DEJOLIE | C28: =VLOOKUP(A28,[5]HISTOFEV25!$A$6:$BQ$45,56,0) -> 273000 | D28: =VLOOKUP(A28,[5]HISTOFEV25!$A$6:$BQ$45,57,0) -> OK | G28: =SUM(E28:F28) -> 0
A29: AS201656 | B29: =VLOOKUP(A29,[4]LISTADHERENT!A$5:H$50,3,0) -> NOUBE ETIENNE | C29: =VLOOKUP(A29,[5]HISTOFEV25!$A$6:$BQ$45,56,0) -> 0 | D29: =VLOOKUP(A29,[5]HISTOFEV25!$A$6:$BQ$45,57,0) -> 0 | G29: =SUM(E29:F29) -> 0
A30: AS201633 | B30: =VLOOKUP(A30,[4]LISTADHERENT!A$5:H$50,3,0) -> PATEGO NJOSSU GUSTAVE | C30: =VLOOKUP(A30,[5]HISTOFEV25!$A$6:$BQ$45,56,0) -> 0 | D30: =VLOOKUP(A30,[5]HISTOFEV25!$A$6:$BQ$45,57,0) -> 0 | G30: =SUM(E30:F30) -> 0
A31: AS201657 | B31: =VLOOKUP(A31,[4]LISTADHERENT!A$5:H$50,3,0) -> SEUMO POLYCARPE | C31: =VLOOKUP(A31,[5]HISTOFEV25!$A$6:$BQ$45,56,0) -> 0 | D31: =VLOOKUP(A31,[5]HISTOFEV25!$A$6:$BQ$45,57,0) -> 0 | G31: =SUM(E31:F31) -> 0
A32: AS201653 | B32: =VLOOKUP(A32,[4]LISTADHERENT!A$5:H$50,3,0) -> SIME BRICE | C32: =VLOOKUP(A32,[5]HISTOFEV25!$A$6:$BQ$45,56,0) -> 0 | D32: =VLOOKUP(A32,[5]HISTOFEV25!$A$6:$BQ$45,57,0) -> 0 | G32: =SUM(E32:F32) -> 0
... A42: AS201647 | B42: =VLOOKUP(A42,[4]LISTADHERENT!A$5:H$50,3,0) -> YOUMBI EMMANUEL | C42: =VLOOKUP(A42,[5]HISTOFEV25!$A$6:$BQ$45,56,0) -> 100000 | D42: =VLOOKUP(A42,[5]HISTOFEV25!$A$6:$BQ$45,57,0) -> OK | G42: =SUM(E42:F42) -> 0
B43: SOLDE BANQUE | F43: 7089215
B44: TOTAUX | C44: =SUM(C6:C43) -> #N/A | E44: =SUM(E7:E43) -> 0 | G44: =SUM(G7:G43) -> 0
B46: DIFFERENCE A CHERCHER | C46: =C44-C5 -> #N/A
B48: COMPTE BANQUE
B50: LIBELLE
B51: REPORT
B52: TONTINE

Sheet HISTOMARS25
A1: ASSOCIATION | B1: ASELBY
A2: ANNEE | B2: 2025
A3: MATRICULE | B3: NOM ET PRENOM | G3: TOTAUX
C4: MONTANT CHEQUE | D4: NUM CHEQUE | E4: AGIOS | F4: Extrait de compte
B5: CHEQUE ETABLI
A6: AS201648 | B6: =VLOOKUP(A6,[4]LISTADHERENT!A$5:H$50,3,0) -> ASELBY | C6: =VLOOKUP(A6,[5]HISTOMARS25!$A$6:$BQ$45,56,0) -> 352000 | D6: =VLOOKUP(A6,[5]HISTOMARS25!$A$6:$BQ$45,57,0) -> 0 | E6: =+[6]HISTOBQUEMARS25!$H$6 -> 2395 | G6: =SUM(E6:F6) -> 2395
A7: AS201601 | B7: =VLOOKUP(A7,[4]LISTADHERENT!A$5:H$50,3,0) -> BAKOP ACHILLE | C7: =VLOOKUP(A7,[5]HISTOMARS25!$A$6:$BQ$45,56,0) -> 0 | D7: =VLOOKUP(A7,[5]HISTOMARS25!$A$6:$BQ$45,57,0) -> 0 | G7: =SUM(E7:F7) -> 0
A8: AS201602 | B8: =VLOOKUP(A8,[4]LISTADHERENT!A$5:H$50,3,0) -> BOUTCHOUANG WILLIAM | C8: =VLOOKUP(A8,[5]HISTOMARS25!$A$6:$BQ$45,56,0) -> 0 | D8: =VLOOKUP(A8,[5]HISTOMARS25!$A$6:$BQ$45,57,0) -> 0 | G8: =SUM(E8:F8) -> 0
A9: AS201604 | B9: =VLOOKUP(A9,[4]LISTADHERENT!A$5:H$50,3,0) -> DJOMO JEAN PAUL | C9: =VLOOKUP(A9,[5]HISTOMARS25!$A$6:$BQ$45,56,0) -> 0 | D9: =VLOOKUP(A9,[5]HISTOMARS25!$A$6:$BQ$45,57,0) -> 0 | G9: =SUM(E9:F9) -> 0
A10: AS201654 | B10: =VLOOKUP(A10,[4]LISTADHERENT!A$5:H$50,3,0) -> DJOMOU TCHAPDA | C10: =VLOOKUP(A10,[5]HISTOMARS25!$A$6:$BQ$45,56,0) -> 0 | D10: =VLOOKUP(A10,[5]HISTOMARS25!$A$6:$BQ$45,57,0) -> 0 | G10: =SUM(E10:F10) -> 0
A11: AS201605 | B11: =VLOOKUP(A11,[4]LISTADHERENT!A$5:H$50,3,0) -> DJOUKWE NANGUEN GUY BLAISE | C11: =VLOOKUP(A11,[5]HISTOMARS25!$A$6:$BQ$45,56,0) -> 894000 | D11: =VLOOKUP(A11,[5]HISTOMARS25!$A$6:$BQ$45,57,0) -> OK | G11: =SUM(E11:F11) -> 0
A12: AS201608 | B12: =VLOOKUP(A12,[4]LISTADHERENT!A$5:H$50,3,0) -> DJUOMBESSY ANTOINE | C12: =VLOOKUP(A12,[5]HISTOMARS25!$A$6:$BQ$45,56,0) -> 1463000 | D12: =VLOOKUP(A12,[5]HISTOMARS25!$A$6:$BQ$45,57,0) -> OK | G12: =SUM(E12:F12) -> 0
A13: AS201651 | B13: =VLOOKUP(A13,[4]LISTADHERENT!A$5:H$50,3,0) -> DOMOU FABIEN | C13: =VLOOKUP(A13,[5]HISTOMARS25!$A$6:$BQ$45,56,0) -> 0 | D13: =VLOOKUP(A13,[5]HISTOMARS25!$A$6:$BQ$45,57,0) -> 0 | G13: =SUM(E13:F13) -> 0
A14: AS201609 | B14: =VLOOKUP(A14,[4]LISTADHERENT!A$5:H$50,3,0) -> DONHOU DAVID | C14: =VLOOKUP(A14,[5]HISTOMARS25!$A$6:$BQ$45,56,0) -> 0 | D14: =VLOOKUP(A14,[5]HISTOMARS25!$A$6:$BQ$45,57,0) -> 0 | G14: =SUM(E14:F14) -> 0
A15: AS201663 | B15: =VLOOKUP(A15,[4]LISTADHERENT!A$5:H$50,3,0) -> FAMPOU PAUL | C15: =VLOOKUP(A15,[5]HISTOMARS25!$A$6:$BQ$45,56,0) -> 0 | D15: =VLOOKUP(A15,[5]HISTOMARS25!$A$6:$BQ$45,57,0) -> 0 | G15: =SUM(E15:F15) -> 0
A16: AS201611 | B16: =VLOOKUP(A16,[4]LISTADHERENT!A$5:H$50,3,0) -> HENGUE PAUL OMER | C16: =VLOOKUP(A16,[5]HISTOMARS25!$A$6:$BQ$45,56,0) -> -55000 | D16: =VLOOKUP(A16,[5]HISTOMARS25!$A$6:$BQ$45,57,0) -> OK | G16: =SUM(E16:F16) -> 0
A17: AS201613 | B17: =VLOOKUP(A17,[4]LISTADHERENT!A$5:H$50,3,0) -> HOTCHO BENJAMIN | C17: =VLOOKUP(A17,[5]HISTOMARS25!$A$6:$BQ$45,56,0) -> 933625 | D17: =VLOOKUP(A17,[5]HISTOMARS25!$A$6:$BQ$45,57,0) -> OK | G17: =SUM(E17:F17) -> 0
A18: AS201617 | B18: =VLOOKUP(A18,[4]LISTADHERENT!A$5:H$50,3,0) -> KOUAMOU MOISE | C18: =VLOOKUP(A18,[5]HISTOMARS25!$A$6:$BQ$45,56,0) -> 0 | D18: =VLOOKUP(A18,[5]HISTOMARS25!$A$6:$BQ$45,57,0) -> OK | G18: =SUM(E18:F18) -> 0
A19: AS201619 | B19: =VLOOKUP(A19,[4]LISTADHERENT!A$5:H$50,3,0) -> KOUATCHO MESSACK | C19: =VLOOKUP(A19,[5]HISTOMARS25!$A$6:$BQ$45,56,0) -> 205500 | D19: =VLOOKUP(A19,[5]HISTOMARS25!$A$6:$BQ$45,57,0) -> OK | G19: =SUM(E19:F19) -> 0
A20: AS201620 | B20: =VLOOKUP(A20,[4]LISTADHERENT!A$5:H$50,3,0) -> LOWE JEAN | C20: =VLOOKUP(A20,[5]HISTOMARS25!$A$6:$BQ$45,56,0) -> 0 | D20: =VLOOKUP(A20,[5]HISTOMARS25!$A$6:$BQ$45,57,0) -> 0
A21: AS201661 | B21: =VLOOKUP(A21,[4]LISTADHERENT!A$5:H$50,3,0) -> MASSEUNGOUE DAGOBERT | C21: =VLOOKUP(A21,[5]HISTOMARS25!$A$6:$BQ$45,56,0) -> 0 | D21: =VLOOKUP(A21,[5]HISTOMARS25!$A$6:$BQ$45,57,0) -> 0 | G21: =SUM(E21:F21) -> 0
A22: AS201649 | B22: =VLOOKUP(A22,[4]LISTADHERENT!A$5:H$50,3,0) -> MBOGNING TUGMA GUY | C22: =VLOOKUP(A22,[5]HISTOMARS25!$A$6:$BQ$45,56,0) -> 426500 | D22: =VLOOKUP(A22,[5]HISTOMARS25!$A$6:$BQ$45,57,0) -> OK | G22: =SUM(E22:F22) -> 0
A23: AS201639 | B23: =VLOOKUP(A23,[4]LISTADHERENT!A$5:H$50,3,0) -> NANGUEN MARTIN | C23: =VLOOKUP(A23,[5]HISTOMARS25!$A$6:$BQ$45,56,0) -> 0 | D23: =VLOOKUP(A23,[5]HISTOMARS25!$A$6:$BQ$45,57,0) -> 0 | G23: =SUM(E23:F23) -> 0
A24: AS201621 | B24: =VLOOKUP(A24,[4]LISTADHERENT!A$5:H$50,3,0) -> NANKAM APPOLINAIRE | C24: =VLOOKUP(A24,[5]HISTOMARS25!$A$6:$BQ$45,56,0) -> 600000 | D24: =VLOOKUP(A24,[5]HISTOMARS25!$A$6:$BQ$45,57,0) -> OK | G24: =SUM(E24:F24) -> 0
A25: AS201622 | B25: =VLOOKUP(A25,[4]LISTADHERENT!A$5:H$50,3,0) -> NDJOMO ETIENNE | C25: =VLOOKUP(A25,[5]HISTOMARS25!$A$6:$BQ$45,56,0) -> 27000 | D25: =VLOOKUP(A25,[5]HISTOMARS25!$A$6:$BQ$45,57,0) -> OK | G25: =SUM(E25:F25) -> 0
A26: AS201624 | B26: =VLOOKUP(A26,[4]LISTADHERENT!A$5:H$50,3,0) -> NGONDIEP CLAUDE | C26: =VLOOKUP(A26,[5]HISTOMARS25!$A$6:$BQ$45,56,0) -> 0 | D26: =VLOOKUP(A26,[5]HISTOMARS25!$A$6:$BQ$45,57,0) -> 0 | G26: =SUM(E26:F26) -> 0
A27: AS201626 | B27: =VLOOKUP(A27,[4]LISTADHERENT!A$5:H$50,3,0) -> NGUIEMEGNI MATHIEU BLAISE | C27: =VLOOKUP(A27,[5]HISTOMARS25!$A$6:$BQ$45,56,0) -> 100000 | D27: =VLOOKUP(A27,[5]HISTOMARS25!$A$6:$BQ$45,57,0) -> OK | G27: =SUM(E27:F27) -> 0
A28: AS201628 | B28: =VLOOKUP(A28,[4]LISTADHERENT!A$5:H$50,3,0) -> NKAMGANG JUSTIN DEJOLIE | C28: =VLOOKUP(A28,[5]HISTOMARS25!$A$6:$BQ$45,56,0) -> 0 | D28: =VLOOKUP(A28,[5]HISTOMARS25!$A$6:$BQ$45,57,0) -> 0 | G28: =SUM(E28:F28) -> 0
A29: AS201656 | B29: =VLOOKUP(A29,[4]LISTADHERENT!A$5:H$50,3,0) -> NOUBE ETIENNE | C29: =VLOOKUP(A29,[5]HISTOMARS25!$A$6:$BQ$45,56,0) -> 136500 | D29: =VLOOKUP(A29,[5]HISTOMARS25!$A$6:$BQ$45,57,0) -> OK | G29: =SUM(E29:F29) -> 0
A30: AS201633 | B30: =VLOOKUP(A30,[4]LISTADHERENT!A$5:H$50,3,0) -> PATEGO NJOSSU GUSTAVE | C30: =VLOOKUP(A30,[5]HISTOMARS25!$A$6:$BQ$45,56,0) -> 0 | D30: =VLOOKUP(A30,[5]HISTOMARS25!$A$6:$BQ$45,57,0) -> 0 | G30: =SUM(E30:F30) -> 0
A31: AS201657 | B31: =VLOOKUP(A31,[4]LISTADHERENT!A$5:H$50,3,0) -> SEUMO POLYCARPE | C31: =VLOOKUP(A31,[5]HISTOMARS25!$A$6:$BQ$45,56,0) -> 0 | D31: =VLOOKUP(A31,[5]HISTOMARS25!$A$6:$BQ$45,57,0) -> 0 | G31: =SUM(E31:F31) -> 0
A32: AS201653 | B32: =VLOOKUP(A32,[4]LISTADHERENT!A$5:H$50,3,0) -> SIME BRICE | C32: =VLOOKUP(A32,[5]HISTOMARS25!$A$6:$BQ$45,56,0) -> 0 | D32: =VLOOKUP(A32,[5]HISTOMARS25!$A$6:$BQ$45,57,0) -> 0 | G32: =SUM(E32:F32) -> 0
... A42: AS201647 | B42: =VLOOKUP(A42,[4]LISTADHERENT!A$5:H$50,3,0) -> YOUMBI EMMANUEL | C42: =VLOOKUP(A42,[5]HISTOMARS25!$A$6:$BQ$45,56,0) -> 0 | D42: =VLOOKUP(A42,[5]HISTOMARS25!$A$6:$BQ$45,57,0) -> 0 | G42: =SUM(E42:F42) -> 0
B43: SOLDE BANQUE | F43: 6776330
B44: TOTAUX | C44: =SUM(C6:C43) -> 5183125 | E44: =SUM(E7:E43) -> 0 | G44: =SUM(G7:G43) -> 0
B46: DIFFERENCE A CHERCHER | C46: =C44-C5 -> 5183125
B48: COMPTE BANQUE
B50: LIBELLE
B51: REPORT
B52: TONTINE

Sheet HISTOAVRIL25
A1: ASSOCIATION | B1: ASELBY
A2: ANNEE | B2: 2025
A3: MATRICULE | B3: NOM ET PRENOM | G3: TOTAUX
C4: MONTANT CHEQUE | D4: NUM CHEQUE | E4: AGIOS | F4: Extrait de compte
B5: CHEQUE ETABLI
A6: AS201648 | B6: =VLOOKUP(A6,[4]LISTADHERENT!A$5:H$50,3,0) -> ASELBY | C6: =VLOOKUP(A6,[5]HISTOAVRIL25!$A$6:$BQ$45,56,0) -> 406000 | D6: =VLOOKUP(A6,[5]HISTOAVRIL25!$A$6:$BQ$45,57,0) -> 0K | E6: =+[6]HISTOBQUEAVRIL25!$H$6 -> 2385 | G6: =SUM(E6:F6) -> 2385
A7: AS201601 | B7: =VLOOKUP(A7,[4]LISTADHERENT!A$5:H$50,3,0) -> BAKOP ACHILLE | C7: =VLOOKUP(A7,[5]HISTOAVRIL25!$A$6:$BQ$45,56,0) -> 0 | D7: =VLOOKUP(A7,[5]HISTOAVRIL25!$A$6:$BQ$45,57,0) -> 0 | G7: =SUM(E7:F7) -> 0
A8: AS201602 | B8: =VLOOKUP(A8,[4]LISTADHERENT!A$5:H$50,3,0) -> BOUTCHOUANG WILLIAM | C8: =VLOOKUP(A8,[5]HISTOAVRIL25!$A$6:$BQ$45,56,0) -> 0 | D8: =VLOOKUP(A8,[5]HISTOAVRIL25!$A$6:$BQ$45,57,0) -> 0 | G8: =SUM(E8:F8) -> 0
A9: AS201604 | B9: =VLOOKUP(A9,[4]LISTADHERENT!A$5:H$50,3,0) -> DJOMO JEAN PAUL | C9: =VLOOKUP(A9,[5]HISTOAVRIL25!$A$6:$BQ$45,56,0) -> 200000 | D9: =VLOOKUP(A9,[5]HISTOAVRIL25!$A$6:$BQ$45,57,0) -> 0 | G9: =SUM(E9:F9) -> 0
A10: AS201654 | B10: =VLOOKUP(A10,[4]LISTADHERENT!A$5:H$50,3,0) -> DJOMOU TCHAPDA | C10: =VLOOKUP(A10,[5]HISTOAVRIL25!$A$6:$BQ$45,56,0) -> 30000 | D10: =VLOOKUP(A10,[5]HISTOAVRIL25!$A$6:$BQ$45,57,0) -> 0 | G10: =SUM(E10:F10) -> 0
A11: AS201605 | B11: =VLOOKUP(A11,[4]LISTADHERENT!A$5:H$50,3,0) -> DJOUKWE NANGUEN GUY BLAISE | C11: =VLOOKUP(A11,[5]HISTOAVRIL25!$A$6:$BQ$45,56,0) -> 0 | D11: =VLOOKUP(A11,[5]HISTOAVRIL25!$A$6:$BQ$45,57,0) -> 0 | G11: =SUM(E11:F11) -> 0
A12: AS201608 | B12: =VLOOKUP(A12,[4]LISTADHERENT!A$5:H$50,3,0) -> DJUOMBESSY ANTOINE | C12: =VLOOKUP(A12,[5]HISTOAVRIL25!$A$6:$BQ$45,56,0) -> 0 | D12: =VLOOKUP(A12,[5]HISTOAVRIL25!$A$6:$BQ$45,57,0) -> 0 | G12: =SUM(E12:F12) -> 0
A13: AS201651 | B13: =VLOOKUP(A13,[4]LISTADHERENT!A$5:H$50,3,0) -> DOMOU FABIEN | C13: =VLOOKUP(A13,[5]HISTOAVRIL25!$A$6:$BQ$45,56,0) -> 0 | D13: =VLOOKUP(A13,[5]HISTOAVRIL25!$A$6:$BQ$45,57,0) -> 0 | G13: =SUM(E13:F13) -> 0
A14: AS201609 | B14: =VLOOKUP(A14,[4]LISTADHERENT!A$5:H$50,3,0) -> DONHOU DAVID | C14: =VLOOKUP(A14,[5]HISTOAVRIL25!$A$6:$BQ$45,56,0) -> 0 | D14: =VLOOKUP(A14,[5]HISTOAVRIL25!$A$6:$BQ$45,57,0) -> 0 | G14: =SUM(E14:F14) -> 0
A15: AS201663 | B15: =VLOOKUP(A15,[4]LISTADHERENT!A$5:H$50,3,0) -> FAMPOU PAUL | C15: =VLOOKUP(A15,[5]HISTOAVRIL25!$A$6:$BQ$45,56,0) -> 0 | D15: =VLOOKUP(A15,[5]HISTOAVRIL25!$A$6:$BQ$45,57,0) -> 0 | G15: =SUM(E15:F15) -> 0
A16: AS201611 | B16: =VLOOKUP(A16,[4]LISTADHERENT!A$5:H$50,3,0) -> HENGUE PAUL OMER | C16: =VLOOKUP(A16,[5]HISTOAVRIL25!$A$6:$BQ$45,56,0) -> 0 | D16: =VLOOKUP(A16,[5]HISTOAVRIL25!$A$6:$BQ$45,57,0) -> 0 | G16: =SUM(E16:F16) -> 0
A17: AS201613 | B17: =VLOOKUP(A17,[4]LISTADHERENT!A$5:H$50,3,0) -> HOTCHO BENJAMIN | C17: =VLOOKUP(A17,[5]HISTOAVRIL25!$A$6:$BQ$45,56,0) -> 1320000 | D17: =VLOOKUP(A17,[5]HISTOAVRIL25!$A$6:$BQ$45,57,0) -> OK | G17: =SUM(E17:F17) -> 0
A18: AS201617 | B18: =VLOOKUP(A18,[4]LISTADHERENT!A$5:H$50,3,0) -> KOUAMOU MOISE | C18: =VLOOKUP(A18,[5]HISTOAVRIL25!$A$6:$BQ$45,56,0) -> 280000 | D18: =VLOOKUP(A18,[5]HISTOAVRIL25!$A$6:$BQ$45,57,0) -> 0 | G18: =SUM(E18:F18) -> 0
A19: AS201619 | B19: =VLOOKUP(A19,[4]LISTADHERENT!A$5:H$50,3,0) -> KOUATCHO MESSACK | C19: =VLOOKUP(A19,[5]HISTOAVRIL25!$A$6:$BQ$45,56,0) -> 992500 | D19: =VLOOKUP(A19,[5]HISTOAVRIL25!$A$6:$BQ$45,57,0) -> OK | G19: =SUM(E19:F19) -> 0
A20: AS201620 | B20: =VLOOKUP(A20,[4]LISTADHERENT!A$5:H$50,3,0) -> LOWE JEAN | C20: =VLOOKUP(A20,[5]HISTOAVRIL25!$A$6:$BQ$45,56,0) -> 0 | D20: =VLOOKUP(A20,[5]HISTOAVRIL25!$A$6:$BQ$45,57,0) -> 0
A21: AS201661 | B21: =VLOOKUP(A21,[4]LISTADHERENT!A$5:H$50,3,0) -> MASSEUNGOUE DAGOBERT | C21: =VLOOKUP(A21,[5]HISTOAVRIL25!$A$6:$BQ$45,56,0) -> 291000 | D21: =VLOOKUP(A21,[5]HISTOAVRIL25!$A$6:$BQ$45,57,0) -> OK | G21: =SUM(E21:F21) -> 0
A22: AS201649 | B22: =VLOOKUP(A22,[4]LISTADHERENT!A$5:H$50,3,0) -> MBOGNING TUGMA GUY | C22: =VLOOKUP(A22,[5]HISTOAVRIL25!$A$6:$BQ$45,56,0) -> 300000 | D22: =VLOOKUP(A22,[5]HISTOAVRIL25!$A$6:$BQ$45,57,0) -> OK | G22: =SUM(E22:F22) -> 0
A23: AS201639 | B23: =VLOOKUP(A23,[4]LISTADHERENT!A$5:H$50,3,0) -> NANGUEN MARTIN | C23: =VLOOKUP(A23,[5]HISTOAVRIL25!$A$6:$BQ$45,56,0) -> 290000 | D23: =VLOOKUP(A23,[5]HISTOAVRIL25!$A$6:$BQ$45,57,0) -> 0 | G23: =SUM(E23:F23) -> 0
A24: AS201621 | B24: =VLOOKUP(A24,[4]LISTADHERENT!A$5:H$50,3,0) -> NANKAM APPOLINAIRE | C24: =VLOOKUP(A24,[5]HISTOAVRIL25!$A$6:$BQ$45,56,0) -> 0 | D24: =VLOOKUP(A24,[5]HISTOAVRIL25!$A$6:$BQ$45,57,0) -> 0 | G24: =SUM(E24:F24) -> 0
A25: AS201622 | B25: =VLOOKUP(A25,[4]LISTADHERENT!A$5:H$50,3,0) -> NDJOMO ETIENNE | C25: =VLOOKUP(A25,[5]HISTOAVRIL25!$A$6:$BQ$45,56,0) -> 193000 | D25: =VLOOKUP(A25,[5]HISTOAVRIL25!$A$6:$BQ$45,57,0) -> OK | G25: =SUM(E25:F25) -> 0
A26: AS201624 | B26: =VLOOKUP(A26,[4]LISTADHERENT!A$5:H$50,3,0) -> NGONDIEP CLAUDE | C26: =VLOOKUP(A26,[5]HISTOAVRIL25!$A$6:$BQ$45,56,0) -> 1439625 | D26: =VLOOKUP(A26,[5]HISTOAVRIL25!$A$6:$BQ$45,57,0) -> OK | G26: =SUM(E26:F26) -> 0
A27: AS201626 | B27: =VLOOKUP(A27,[4]LISTADHERENT!A$5:H$50,3,0) -> NGUIEMEGNI MATHIEU BLAISE | C27: =VLOOKUP(A27,[5]HISTOAVRIL25!$A$6:$BQ$45,56,0) -> 32000 | D27: =VLOOKUP(A27,[5]HISTOAVRIL25!$A$6:$BQ$45,57,0) -> 0 | G27: =SUM(E27:F27) -> 0
A28: AS201628 | B28: =VLOOKUP(A28,[4]LISTADHERENT!A$5:H$50,3,0) -> NKAMGANG JUSTIN DEJOLIE | C28: =VLOOKUP(A28,[5]HISTOAVRIL25!$A$6:$BQ$45,56,0) -> 0 | D28: =VLOOKUP(A28,[5]HISTOAVRIL25!$A$6:$BQ$45,57,0) -> 0 | G28: =SUM(E28:F28) -> 0
A29: AS201656 | B29: =VLOOKUP(A29,[4]LISTADHERENT!A$5:H$50,3,0) -> NOUBE ETIENNE | C29: =VLOOKUP(A29,[5]HISTOAVRIL25!$A$6:$BQ$45,56,0) -> 0 | D29: =VLOOKUP(A29,[5]HISTOAVRIL25!$A$6:$BQ$45,57,0) -> 0 | G29: =SUM(E29:F29) -> 0
A30: AS201633 | B30: =VLOOKUP(A30,[4]LISTADHERENT!A$5:H$50,3,0) -> PATEGO NJOSSU GUSTAVE | C30: =VLOOKUP(A30,[5]HISTOAVRIL25!$A$6:$BQ$45,56,0) -> 0 | D30: =VLOOKUP(A30,[5]HISTOAVRIL25!$A$6:$BQ$45,57,0) -> 0 | G30: =SUM(E30:F30) -> 0
A31: AS201657 | B31: =VLOOKUP(A31,[4]LISTADHERENT!A$5:H$50,3,0) -> SEUMO POLYCARPE | C31: =VLOOKUP(A31,[5]HISTOAVRIL25!$A$6:$BQ$45,56,0) -> 83000 | D31: =VLOOKUP(A31,[5]HISTOAVRIL25!$A$6:$BQ$45,57,0) -> 0 | G31: =SUM(E31:F31) -> 0
A32: AS201653 | B32: =VLOOKUP(A32,[4]LISTADHERENT!A$5:H$50,3,0) -> SIME BRICE | C32: =VLOOKUP(A32,[5]HISTOAVRIL25!$A$6:$BQ$45,56,0) -> 100000 | D32: =VLOOKUP(A32,[5]HISTOAVRIL25!$A$6:$BQ$45,57,0) -> 0K | G32: =SUM(E32:F32) -> 0
... A42: AS201647 | B42: =VLOOKUP(A42,[4]LISTADHERENT!A$5:H$50,3,0) -> YOUMBI EMMANUEL | C42: =VLOOKUP(A42,[5]HISTOAVRIL25!$A$6:$BQ$45,56,0) -> 0 | D42: =VLOOKUP(A42,[5]HISTOAVRIL25!$A$6:$BQ$45,57,0) -> 0 | G42: =SUM(E42:F42) -> 0
B43: SOLDE BANQUE
B44: TOTAUX | C44: =SUM(C6:C43) -> 6467125 | E44: =SUM(E7:E43) -> 0 | G44: =SUM(G7:G43) -> 0
B46: DIFFERENCE A CHERCHER | C46: =C44-C5 -> 6467125
B48: COMPTE BANQUE
B50: LIBELLE
B51: REPORT
B52: TONTINE

Sheet HISTOMAI25
A1: ASSOCIATION | B1: ASELBY
A2: ANNEE | B2: 2025
A3: MATRICULE | B3: NOM ET PRENOM | G3: TOTAUX
C4: MONTANT CHEQUE | D4: NUM CHEQUE | E4: AGIOS | F4: Extrait de compte
B5: CHEQUE ETABLI
A6: AS201648 | B6: =VLOOKUP(A6,[4]LISTADHERENT!A$5:H$50,3,0) -> ASELBY | C6: =VLOOKUP(A6,[5]HISTOMAI25!$A$6:$BQ$45,56,0) -> 6000 | D6: =VLOOKUP(A6,[5]HISTOMAI25!$A$6:$BQ$45,57,0) -> 0 | E6: =+[6]HISTOBQUEMAI25!$H$6 -> 2385 | G6: =SUM(E6:F6) -> 2385
A7: AS201601 | B7: =VLOOKUP(A7,[4]LISTADHERENT!A$5:H$50,3,0) -> BAKOP ACHILLE | C7: =VLOOKUP(A7,[5]HISTOMAI25!$A$6:$BQ$45,56,0) -> 0 | D7: =VLOOKUP(A7,[5]HISTOMAI25!$A$6:$BQ$45,57,0) -> 0 | G7: =SUM(E7:F7) -> 0
A8: AS201602 | B8: =VLOOKUP(A8,[4]LISTADHERENT!A$5:H$50,3,0) -> BOUTCHOUANG WILLIAM | C8: =VLOOKUP(A8,[5]HISTOMAI25!$A$6:$BQ$45,56,0) -> 0 | D8: =VLOOKUP(A8,[5]HISTOMAI25!$A$6:$BQ$45,57,0) -> 0 | G8: =SUM(E8:F8) -> 0
A9: AS201604 | B9: =VLOOKUP(A9,[4]LISTADHERENT!A$5:H$50,3,0) -> DJOMO JEAN PAUL | C9: =VLOOKUP(A9,[5]HISTOMAI25!$A$6:$BQ$45,56,0) -> 100000 | D9: =VLOOKUP(A9,[5]HISTOMAI25!$A$6:$BQ$45,57,0) -> 0 | G9: =SUM(E9:F9) -> 0
A10: AS201654 | B10: =VLOOKUP(A10,[4]LISTADHERENT!A$5:H$50,3,0) -> DJOMOU TCHAPDA | C10: =VLOOKUP(A10,[5]HISTOMAI25!$A$6:$BQ$45,56,0) -> 30000 | D10: =VLOOKUP(A10,[5]HISTOMAI25!$A$6:$BQ$45,57,0) -> 0 | G10: =SUM(E10:F10) -> 0
A11: AS201605 | B11: =VLOOKUP(A11,[4]LISTADHERENT!A$5:H$50,3,0) -> DJOUKWE NANGUEN GUY BLAISE | C11: =VLOOKUP(A11,[5]HISTOMAI25!$A$6:$BQ$45,56,0) -> 100000 | D11: =VLOOKUP(A11,[5]HISTOMAI25!$A$6:$BQ$45,57,0) -> 0 | G11: =SUM(E11:F11) -> 0
A12: AS201608 | B12: =VLOOKUP(A12,[4]LISTADHERENT!A$5:H$50,3,0) -> DJUOMBESSY ANTOINE | C12: =VLOOKUP(A12,[5]HISTOMAI25!$A$6:$BQ$45,56,0) -> 53000 | D12: =VLOOKUP(A12,[5]HISTOMAI25!$A$6:$BQ$45,57,0) -> 0 | G12: =SUM(E12:F12) -> 0
A13: AS201651 | B13: =VLOOKUP(A13,[4]LISTADHERENT!A$5:H$50,3,0) -> DOMOU FABIEN | C13: =VLOOKUP(A13,[5]HISTOMAI25!$A$6:$BQ$45,56,0) -> 294500 | D13: =VLOOKUP(A13,[5]HISTOMAI25!$A$6:$BQ$45,57,0) -> 0 | G13: =SUM(E13:F13) -> 0
A14: AS201609 | B14: =VLOOKUP(A14,[4]LISTADHERENT!A$5:H$50,3,0) -> DONHOU DAVID | C14: =VLOOKUP(A14,[5]HISTOMAI25!$A$6:$BQ$45,56,0) -> 0 | D14: =VLOOKUP(A14,[5]HISTOMAI25!$A$6:$BQ$45,57,0) -> 0 | G14: =SUM(E14:F14) -> 0
A15: AS201663 | B15: =VLOOKUP(A15,[4]LISTADHERENT!A$5:H$50,3,0) -> FAMPOU PAUL | C15: =VLOOKUP(A15,[5]HISTOMAI25!$A$6:$BQ$45,56,0) -> 0 | D15: =VLOOKUP(A15,[5]HISTOMAI25!$A$6:$BQ$45,57,0) -> 0 | G15: =SUM(E15:F15) -> 0
A16: AS201611 | B16: =VLOOKUP(A16,[4]LISTADHERENT!A$5:H$50,3,0) -> HENGUE PAUL OMER | C16: =VLOOKUP(A16,[5]HISTOMAI25!$A$6:$BQ$45,56,0) -> 0 | D16: =VLOOKUP(A16,[5]HISTOMAI25!$A$6:$BQ$45,57,0) -> 0 | G16: =SUM(E16:F16) -> 0
A17: AS201613 | B17: =VLOOKUP(A17,[4]LISTADHERENT!A$5:H$50,3,0) -> HOTCHO BENJAMIN | C17: =VLOOKUP(A17,[5]HISTOMAI25!$A$6:$BQ$45,56,0) -> 345500 | D17: =VLOOKUP(A17,[5]HISTOMAI25!$A$6:$BQ$45,57,0) -> 0 | G17: =SUM(E17:F17) -> 0
A18: AS201617 | B18: =VLOOKUP(A18,[4]LISTADHERENT!A$5:H$50,3,0) -> KOUAMOU MOISE | C18: =VLOOKUP(A18,[5]HISTOMAI25!$A$6:$BQ$45,56,0) -> 100000 | D18: =VLOOKUP(A18,[5]HISTOMAI25!$A$6:$BQ$45,57,0) -> 0 | G18: =SUM(E18:F18) -> 0
A19: AS201619 | B19: =VLOOKUP(A19,[4]LISTADHERENT!A$5:H$50,3,0) -> KOUATCHO MESSACK | C19: =VLOOKUP(A19,[5]HISTOMAI25!$A$6:$BQ$45,56,0) -> 100000 | D19: =VLOOKUP(A19,[5]HISTOMAI25!$A$6:$BQ$45,57,0) -> 0 | G19: =SUM(E19:F19) -> 0
A20: AS201620 | B20: =VLOOKUP(A20,[4]LISTADHERENT!A$5:H$50,3,0) -> LOWE JEAN | C20: =VLOOKUP(A20,[5]HISTOMAI25!$A$6:$BQ$45,56,0) -> 0 | D20: =VLOOKUP(A20,[5]HISTOMAI25!$A$6:$BQ$45,57,0) -> 0
A21: AS201661 | B21: =VLOOKUP(A21,[4]LISTADHERENT!A$5:H$50,3,0) -> MASSEUNGOUE DAGOBERT | C21: =VLOOKUP(A21,[5]HISTOMAI25!$A$6:$BQ$45,56,0) -> 0 | D21: =VLOOKUP(A21,[5]HISTOMAI25!$A$6:$BQ$45,57,0) -> 0 | G21: =SUM(E21:F21) -> 0
A22: AS201649 | B22: =VLOOKUP(A22,[4]LISTADHERENT!A$5:H$50,3,0) -> MBOGNING TUGMA GUY | C22: =VLOOKUP(A22,[5]HISTOMAI25!$A$6:$BQ$45,56,0) -> 300000 | D22: =VLOOKUP(A22,[5]HISTOMAI25!$A$6:$BQ$45,57,0) -> 0 | G22: =SUM(E22:F22) -> 0
A23: AS201639 | B23: =VLOOKUP(A23,[4]LISTADHERENT!A$5:H$50,3,0) -> NANGUEN MARTIN | C23: =VLOOKUP(A23,[5]HISTOMAI25!$A$6:$BQ$45,56,0) -> 0 | D23: =VLOOKUP(A23,[5]HISTOMAI25!$A$6:$BQ$45,57,0) -> 0 | G23: =SUM(E23:F23) -> 0
A24: AS201621 | B24: =VLOOKUP(A24,[4]LISTADHERENT!A$5:H$50,3,0) -> NANKAM APPOLINAIRE | C24: =VLOOKUP(A24,[5]HISTOMAI25!$A$6:$BQ$45,56,0) -> 0 | D24: =VLOOKUP(A24,[5]HISTOMAI25!$A$6:$BQ$45,57,0) -> 0 | G24: =SUM(E24:F24) -> 0
A25: AS201622 | B25: =VLOOKUP(A25,[4]LISTADHERENT!A$5:H$50,3,0) -> NDJOMO ETIENNE | C25: =VLOOKUP(A25,[5]HISTOMAI25!$A$6:$BQ$45,56,0) -> 1390000 | D25: =VLOOKUP(A25,[5]HISTOMAI25!$A$6:$BQ$45,57,0) -> 0 | G25: =SUM(E25:F25) -> 0
A26: AS201624 | B26: =VLOOKUP(A26,[4]LISTADHERENT!A$5:H$50,3,0) -> NGONDIEP CLAUDE | C26: =VLOOKUP(A26,[5]HISTOMAI25!$A$6:$BQ$45,56,0) -> 249625 | D26: =VLOOKUP(A26,[5]HISTOMAI25!$A$6:$BQ$45,57,0) -> 0 | G26: =SUM(E26:F26) -> 0
A27: AS201626 | B27: =VLOOKUP(A27,[4]LISTADHERENT!A$5:H$50,3,0) -> NGUIEMEGNI MATHIEU BLAISE | C27: =VLOOKUP(A27,[5]HISTOMAI25!$A$6:$BQ$45,56,0) -> 300000 | D27: =VLOOKUP(A27,[5]HISTOMAI25!$A$6:$BQ$45,57,0) -> 0 | G27: =SUM(E27:F27) -> 0
A28: AS201628 | B28: =VLOOKUP(A28,[4]LISTADHERENT!A$5:H$50,3,0) -> NKAMGANG JUSTIN DEJOLIE | C28: =VLOOKUP(A28,[5]HISTOMAI25!$A$6:$BQ$45,56,0) -> 0 | D28: =VLOOKUP(A28,[5]HISTOMAI25!$A$6:$BQ$45,57,0) -> 0 | G28: =SUM(E28:F28) -> 0
A29: AS201656 | B29: =VLOOKUP(A29,[4]LISTADHERENT!A$5:H$50,3,0) -> NOUBE ETIENNE | C29: =VLOOKUP(A29,[5]HISTOMAI25!$A$6:$BQ$45,56,0) -> 0 | D29: =VLOOKUP(A29,[5]HISTOMAI25!$A$6:$BQ$45,57,0) -> 0 | G29: =SUM(E29:F29) -> 0
A30: AS201633 | B30: =VLOOKUP(A30,[4]LISTADHERENT!A$5:H$50,3,0) -> PATEGO NJOSSU GUSTAVE | C30: =VLOOKUP(A30,[5]HISTOMAI25!$A$6:$BQ$45,56,0) -> 892500 | D30: =VLOOKUP(A30,[5]HISTOMAI25!$A$6:$BQ$45,57,0) -> 0 | G30: =SUM(E30:F30) -> 0
A31: AS201657 | B31: =VLOOKUP(A31,[4]LISTADHERENT!A$5:H$50,3,0) -> SEUMO POLYCARPE | C31: =VLOOKUP(A31,[5]HISTOMAI25!$A$6:$BQ$45,56,0) -> 59000 | D31: =VLOOKUP(A31,[5]HISTOMAI25!$A$6:$BQ$45,57,0) -> 0 | G31: =SUM(E31:F31) -> 0
A32: AS201653 | B32: =VLOOKUP(A32,[4]LISTADHERENT!A$5:H$50,3,0) -> SIME BRICE | C32: =VLOOKUP(A32,[5]HISTOMAI25!$A$6:$BQ$45,56,0) -> 1479500 | D32: =VLOOKUP(A32,[5]HISTOMAI25!$A$6:$BQ$45,57,0) -> 0 | G32: =SUM(E32:F32) -> 0
... A42: AS201647 | B42: =VLOOKUP(A42,[4]LISTADHERENT!A$5:H$50,3,0) -> YOUMBI EMMANUEL | C42: =VLOOKUP(A42,[5]HISTOMAI25!$A$6:$BQ$45,56,0) -> 0 | D42: =VLOOKUP(A42,[5]HISTOMAI25!$A$6:$BQ$45,57,0) -> 0 | G42: =SUM(E42:F42) -> 0
B43: SOLDE BANQUE | F43: 6401935
B44: TOTAUX | C44: =SUM(C6:C43) -> 6029625 | E44: =SUM(E7:E43) -> 0 | G44: =SUM(G7:G43) -> 0
B46: DIFFERENCE A CHERCHER | C46: =C44-C5 -> 6029625
B48: COMPTE BANQUE
B50: LIBELLE
B51: REPORT
B52: TONTINE

Sheet HISTOJUIN25
A1: ASSOCIATION | B1: ASELBY
A2: ANNEE | B2: 2025
A3: MATRICULE | B3: NOM ET PRENOM | G3: TOTAUX
C4: MONTANT CHEQUE | D4: NUM CHEQUE | E4: AGIOS | F4: Extrait de compte
B5: CHEQUE ETABLI
A6: AS201648 | B6: =VLOOKUP(A6,[4]LISTADHERENT!A$5:H$50,3,0) -> ASELBY | C6: =VLOOKUP(A6,[5]HISTOJUIN25!$A$6:$BQ$45,56,0) -> 2088500 | D6: =VLOOKUP(A6,[5]HISTOJUIN25!$A$6:$BQ$45,57,0) -> 0 | E6: =+[6]HISTOBQUEJUIN25!$H$6 -> 2385 | G6: =SUM(E6:F6) -> 2385
A7: AS201601 | B7: =VLOOKUP(A7,[4]LISTADHERENT!A$5:H$50,3,0) -> BAKOP ACHILLE | C7: =VLOOKUP(A7,[5]HISTOJUIN25!$A$6:$BQ$45,56,0) -> 0 | D7: =VLOOKUP(A7,[5]HISTOJUIN25!$A$6:$BQ$45,57,0) -> 0 | G7: =SUM(E7:F7) -> 0
A8: AS201602 | B8: =VLOOKUP(A8,[4]LISTADHERENT!A$5:H$50,3,0) -> BOUTCHOUANG WILLIAM | C8: =VLOOKUP(A8,[5]HISTOJUIN25!$A$6:$BQ$45,56,0) -> 485000 | D8: =VLOOKUP(A8,[5]HISTOJUIN25!$A$6:$BQ$45,57,0) -> 0 | G8: =SUM(E8:F8) -> 0
A9: AS201604 | B9: =VLOOKUP(A9,[4]LISTADHERENT!A$5:H$50,3,0) -> DJOMO JEAN PAUL | C9: =VLOOKUP(A9,[5]HISTOJUIN25!$A$6:$BQ$45,56,0) -> 0 | D9: =VLOOKUP(A9,[5]HISTOJUIN25!$A$6:$BQ$45,57,0) -> 0 | G9: =SUM(E9:F9) -> 0
A10: AS201654 | B10: =VLOOKUP(A10,[4]LISTADHERENT!A$5:H$50,3,0) -> DJOMOU TCHAPDA | C10: =VLOOKUP(A10,[5]HISTOJUIN25!$A$6:$BQ$45,56,0) -> 0 | D10: =VLOOKUP(A10,[5]HISTOJUIN25!$A$6:$BQ$45,57,0) -> 0 | G10: =SUM(E10:F10) -> 0
A11: AS201605 | B11: =VLOOKUP(A11,[4]LISTADHERENT!A$5:H$50,3,0) -> DJOUKWE NANGUEN GUY BLAISE | C11: =VLOOKUP(A11,[5]HISTOJUIN25!$A$6:$BQ$45,56,0) -> 0 | D11: =VLOOKUP(A11,[5]HISTOJUIN25!$A$6:$BQ$45,57,0) -> 0 | G11: =SUM(E11:F11) -> 0
A12: AS201608 | B12: =VLOOKUP(A12,[4]LISTADHERENT!A$5:H$50,3,0) -> DJUOMBESSY ANTOINE | C12: =VLOOKUP(A12,[5]HISTOJUIN25!$A$6:$BQ$45,56,0) -> 100000 | D12: =VLOOKUP(A12,[5]HISTOJUIN25!$A$6:$BQ$45,57,0) -> 0 | G12: =SUM(E12:F12) -> 0
A13: AS201651 | B13: =VLOOKUP(A13,[4]LISTADHERENT!A$5:H$50,3,0) -> DOMOU FABIEN | C13: =VLOOKUP(A13,[5]HISTOJUIN25!$A$6:$BQ$45,56,0) -> 0 | D13: =VLOOKUP(A13,[5]HISTOJUIN25!$A$6:$BQ$45,57,0) -> 0 | G13: =SUM(E13:F13) -> 0
A14: AS201609 | B14: =VLOOKUP(A14,[4]LISTADHERENT!A$5:H$50,3,0) -> DONHOU DAVID | C14: =VLOOKUP(A14,[5]HISTOJUIN25!$A$6:$BQ$45,56,0) -> 0 | D14: =VLOOKUP(A14,[5]HISTOJUIN25!$A$6:$BQ$45,57,0) -> 0 | G14: =SUM(E14:F14) -> 0
A15: AS201663 | B15: =VLOOKUP(A15,[4]LISTADHERENT!A$5:H$50,3,0) -> FAMPOU PAUL | C15: =VLOOKUP(A15,[5]HISTOJUIN25!$A$6:$BQ$45,56,0) -> 0 | D15: =VLOOKUP(A15,[5]HISTOJUIN25!$A$6:$BQ$45,57,0) -> 0 | G15: =SUM(E15:F15) -> 0
A16: AS201611 | B16: =VLOOKUP(A16,[4]LISTADHERENT!A$5:H$50,3,0) -> HENGUE PAUL OMER | C16: =VLOOKUP(A16,[5]HISTOJUIN25!$A$6:$BQ$45,56,0) -> 0 | D16: =VLOOKUP(A16,[5]HISTOJUIN25!$A$6:$BQ$45,57,0) -> 0 | G16: =SUM(E16:F16) -> 0
A17: AS201613 | B17: =VLOOKUP(A17,[4]LISTADHERENT!A$5:H$50,3,0) -> HOTCHO BENJAMIN | C17: =VLOOKUP(A17,[5]HISTOJUIN25!$A$6:$BQ$45,56,0) -> 75000 | D17: =VLOOKUP(A17,[5]HISTOJUIN25!$A$6:$BQ$45,57,0) -> 0 | G17: =SUM(E17:F17) -> 0
A18: AS201617 | B18: =VLOOKUP(A18,[4]LISTADHERENT!A$5:H$50,3,0) -> KOUAMOU MOISE | C18: =VLOOKUP(A18,[5]HISTOJUIN25!$A$6:$BQ$45,56,0) -> 102000 | D18: =VLOOKUP(A18,[5]HISTOJUIN25!$A$6:$BQ$45,57,0) -> 0 | G18: =SUM(E18:F18) -> 0
A19: AS201619 | B19: =VLOOKUP(A19,[4]LISTADHERENT!A$5:H$50,3,0) -> KOUATCHO MESSACK | C19: =VLOOKUP(A19,[5]HISTOJUIN25!$A$6:$BQ$45,56,0) -> -1000 | D19: =VLOOKUP(A19,[5]HISTOJUIN25!$A$6:$BQ$45,57,0) -> 0 | G19: =SUM(E19:F19) -> 0
A20: AS201620 | B20: =VLOOKUP(A20,[4]LISTADHERENT!A$5:H$50,3,0) -> LOWE JEAN | C20: =VLOOKUP(A20,[5]HISTOJUIN25!$A$6:$BQ$45,56,0) -> 0 | D20: =VLOOKUP(A20,[5]HISTOJUIN25!$A$6:$BQ$45,57,0) -> 0
A21: AS201661 | B21: =VLOOKUP(A21,[4]LISTADHERENT!A$5:H$50,3,0) -> MASSEUNGOUE DAGOBERT | C21: =VLOOKUP(A21,[5]HISTOJUIN25!$A$6:$BQ$45,56,0) -> 0 | D21: =VLOOKUP(A21,[5]HISTOJUIN25!$A$6:$BQ$45,57,0) -> 0 | G21: =SUM(E21:F21) -> 0
A22: AS201649 | B22: =VLOOKUP(A22,[4]LISTADHERENT!A$5:H$50,3,0) -> MBOGNING TUGMA GUY | C22: =VLOOKUP(A22,[5]HISTOJUIN25!$A$6:$BQ$45,56,0) -> 1170000 | D22: =VLOOKUP(A22,[5]HISTOJUIN25!$A$6:$BQ$45,57,0) -> 0 | G22: =SUM(E22:F22) -> 0
A23: AS201639 | B23: =VLOOKUP(A23,[4]LISTADHERENT!A$5:H$50,3,0) -> NANGUEN MARTIN | C23: =VLOOKUP(A23,[5]HISTOJUIN25!$A$6:$BQ$45,56,0) -> 0 | D23: =VLOOKUP(A23,[5]HISTOJUIN25!$A$6:$BQ$45,57,0) -> 0 | G23: =SUM(E23:F23) -> 0
A24: AS201621 | B24: =VLOOKUP(A24,[4]LISTADHERENT!A$5:H$50,3,0) -> NANKAM APPOLINAIRE | C24: =VLOOKUP(A24,[5]HISTOJUIN25!$A$6:$BQ$45,56,0) -> 0 | D24: =VLOOKUP(A24,[5]HISTOJUIN25!$A$6:$BQ$45,57,0) -> 0 | G24: =SUM(E24:F24) -> 0
A25: AS201622 | B25: =VLOOKUP(A25,[4]LISTADHERENT!A$5:H$50,3,0) -> NDJOMO ETIENNE | C25: =VLOOKUP(A25,[5]HISTOJUIN25!$A$6:$BQ$45,56,0) -> 200000 | D25: =VLOOKUP(A25,[5]HISTOJUIN25!$A$6:$BQ$45,57,0) -> 0 | G25: =SUM(E25:F25) -> 0
A26: AS201624 | B26: =VLOOKUP(A26,[4]LISTADHERENT!A$5:H$50,3,0) -> NGONDIEP CLAUDE | C26: =VLOOKUP(A26,[5]HISTOJUIN25!$A$6:$BQ$45,56,0) -> 253625 | D26: =VLOOKUP(A26,[5]HISTOJUIN25!$A$6:$BQ$45,57,0) -> 0 | G26: =SUM(E26:F26) -> 0
A27: AS201626 | B27: =VLOOKUP(A27,[4]LISTADHERENT!A$5:H$50,3,0) -> NGUIEMEGNI MATHIEU BLAISE | C27: =VLOOKUP(A27,[5]HISTOJUIN25!$A$6:$BQ$45,56,0) -> 100000 | D27: =VLOOKUP(A27,[5]HISTOJUIN25!$A$6:$BQ$45,57,0) -> 0 | G27: =SUM(E27:F27) -> 0
A28: AS201628 | B28: =VLOOKUP(A28,[4]LISTADHERENT!A$5:H$50,3,0) -> NKAMGANG JUSTIN DEJOLIE | C28: =VLOOKUP(A28,[5]HISTOJUIN25!$A$6:$BQ$45,56,0) -> 970000 | D28: =VLOOKUP(A28,[5]HISTOJUIN25!$A$6:$BQ$45,57,0) -> 0 | G28: =SUM(E28:F28) -> 0
A29: AS201656 | B29: =VLOOKUP(A29,[4]LISTADHERENT!A$5:H$50,3,0) -> NOUBE ETIENNE | C29: =VLOOKUP(A29,[5]HISTOJUIN25!$A$6:$BQ$45,56,0) -> 0 | D29: =VLOOKUP(A29,[5]HISTOJUIN25!$A$6:$BQ$45,57,0) -> 0 | G29: =SUM(E29:F29) -> 0
A30: AS201633 | B30: =VLOOKUP(A30,[4]LISTADHERENT!A$5:H$50,3,0) -> PATEGO NJOSSU GUSTAVE | C30: =VLOOKUP(A30,[5]HISTOJUIN25!$A$6:$BQ$45,56,0) -> 0 | D30: =VLOOKUP(A30,[5]HISTOJUIN25!$A$6:$BQ$45,57,0) -> 0 | G30: =SUM(E30:F30) -> 0
A31: AS201657 | B31: =VLOOKUP(A31,[4]LISTADHERENT!A$5:H$50,3,0) -> SEUMO POLYCARPE | C31: =VLOOKUP(A31,[5]HISTOJUIN25!$A$6:$BQ$45,56,0) -> 59000 | D31: =VLOOKUP(A31,[5]HISTOJUIN25!$A$6:$BQ$45,57,0) -> 0 | G31: =SUM(E31:F31) -> 0
A32: AS201653 | B32: =VLOOKUP(A32,[4]LISTADHERENT!A$5:H$50,3,0) -> SIME BRICE | C32: =VLOOKUP(A32,[5]HISTOJUIN25!$A$6:$BQ$45,56,0) -> 970000 | D32: =VLOOKUP(A32,[5]HISTOJUIN25!$A$6:$BQ$45,57,0) -> 0 | G32: =SUM(E32:F32) -> 0
... A42: AS201647 | B42: =VLOOKUP(A42,[4]LISTADHERENT!A$5:H$50,3,0) -> YOUMBI EMMANUEL | C42: =VLOOKUP(A42,[5]HISTOJUIN25!$A$6:$BQ$45,56,0) -> 0 | D42: =VLOOKUP(A42,[5]HISTOJUIN25!$A$6:$BQ$45,57,0) -> 0 | G42: =SUM(E42:F42) -> 0
B43: SOLDE BANQUE | F43: 6532050
B44: TOTAUX | C44: =SUM(C6:C43) -> 8652625 | E44: =SUM(E7:E43) -> 0 | G44: =SUM(G7:G43) -> 0
B46: DIFFERENCE A CHERCHER | C46: =C44-C5 -> 8652625
B48: COMPTE BANQUE
B50: LIBELLE
B51: REPORT
B52: TONTINE

Sheet HISTOJUIL25
A1: ASSOCIATION | B1: ASELBY
A2: ANNEE | B2: 2025
A3: MATRICULE | B3: NOM ET PRENOM | G3: TOTAUX
C4: MONTANT CHEQUE | D4: NUM CHEQUE | E4: AGIOS | F4: Extrait de compte
B5: CHEQUE ETABLI
A6: AS201648 | B6: =VLOOKUP(A6,[4]LISTADHERENT!A$5:H$50,3,0) -> ASELBY | C6: =VLOOKUP(A6,[5]HISTOJUIL25!$A$6:$BQ$45,56,0) -> 76000 | D6: =VLOOKUP(A6,[5]HISTOJUIL25!$A$6:$BQ$45,57,0) -> 0 | E6: =+[6]HISTOBQUEJUIL25!$H$6 -> 4770 | F6: 17444 | G6: =SUM(E6:F6) -> 22214
A7: AS201601 | B7: =VLOOKUP(A7,[4]LISTADHERENT!A$5:H$50,3,0) -> BAKOP ACHILLE | C7: =VLOOKUP(A7,[5]HISTOJUIL25!$A$6:$BQ$45,56,0) -> 0 | D7: =VLOOKUP(A7,[5]HISTOJUIL25!$A$6:$BQ$45,57,0) -> 0 | G7: =SUM(E7:F7) -> 0
A8: AS201602 | B8: =VLOOKUP(A8,[4]LISTADHERENT!A$5:H$50,3,0) -> BOUTCHOUANG WILLIAM | C8: =VLOOKUP(A8,[5]HISTOJUIL25!$A$6:$BQ$45,56,0) -> 0 | D8: =VLOOKUP(A8,[5]HISTOJUIL25!$A$6:$BQ$45,57,0) -> 0 | G8: =SUM(E8:F8) -> 0
A9: AS201604 | B9: =VLOOKUP(A9,[4]LISTADHERENT!A$5:H$50,3,0) -> DJOMO JEAN PAUL | C9: =VLOOKUP(A9,[5]HISTOJUIL25!$A$6:$BQ$45,56,0) -> 0 | D9: =VLOOKUP(A9,[5]HISTOJUIL25!$A$6:$BQ$45,57,0) -> 0 | G9: =SUM(E9:F9) -> 0
A10: AS201654 | B10: =VLOOKUP(A10,[4]LISTADHERENT!A$5:H$50,3,0) -> DJOMOU TCHAPDA | C10: =VLOOKUP(A10,[5]HISTOJUIL25!$A$6:$BQ$45,56,0) -> 26000 | D10: =VLOOKUP(A10,[5]HISTOJUIL25!$A$6:$BQ$45,57,0) -> OK | G10: =SUM(E10:F10) -> 0
A11: AS201605 | B11: =VLOOKUP(A11,[4]LISTADHERENT!A$5:H$50,3,0) -> DJOUKWE NANGUEN GUY BLAISE | C11: =VLOOKUP(A11,[5]HISTOJUIL25!$A$6:$BQ$45,56,0) -> 0 | D11: =VLOOKUP(A11,[5]HISTOJUIL25!$A$6:$BQ$45,57,0) -> 0 | G11: =SUM(E11:F11) -> 0
A12: AS201608 | B12: =VLOOKUP(A12,[4]LISTADHERENT!A$5:H$50,3,0) -> DJUOMBESSY ANTOINE | C12: =VLOOKUP(A12,[5]HISTOJUIL25!$A$6:$BQ$45,56,0) -> 180000 | D12: =VLOOKUP(A12,[5]HISTOJUIL25!$A$6:$BQ$45,57,0) -> OK | G12: =SUM(E12:F12) -> 0
A13: AS201651 | B13: =VLOOKUP(A13,[4]LISTADHERENT!A$5:H$50,3,0) -> DOMOU FABIEN | C13: =VLOOKUP(A13,[5]HISTOJUIL25!$A$6:$BQ$45,56,0) -> 0 | D13: =VLOOKUP(A13,[5]HISTOJUIL25!$A$6:$BQ$45,57,0) -> 0 | G13: =SUM(E13:F13) -> 0
A14: AS201609 | B14: =VLOOKUP(A14,[4]LISTADHERENT!A$5:H$50,3,0) -> DONHOU DAVID | C14: =VLOOKUP(A14,[5]HISTOJUIL25!$A$6:$BQ$45,56,0) -> 100000 | D14: =VLOOKUP(A14,[5]HISTOJUIL25!$A$6:$BQ$45,57,0) -> OK | G14: =SUM(E14:F14) -> 0
A15: AS201663 | B15: =VLOOKUP(A15,[4]LISTADHERENT!A$5:H$50,3,0) -> FAMPOU PAUL | C15: =VLOOKUP(A15,[5]HISTOJUIL25!$A$6:$BQ$45,56,0) -> 397500 | D15: =VLOOKUP(A15,[5]HISTOJUIL25!$A$6:$BQ$45,57,0) -> OK | G15: =SUM(E15:F15) -> 0
A16: AS201611 | B16: =VLOOKUP(A16,[4]LISTADHERENT!A$5:H$50,3,0) -> HENGUE PAUL OMER | C16: =VLOOKUP(A16,[5]HISTOJUIL25!$A$6:$BQ$45,56,0) -> 0 | D16: =VLOOKUP(A16,[5]HISTOJUIL25!$A$6:$BQ$45,57,0) -> 0 | G16: =SUM(E16:F16) -> 0
A17: AS201613 | B17: =VLOOKUP(A17,[4]LISTADHERENT!A$5:H$50,3,0) -> HOTCHO BENJAMIN | C17: =VLOOKUP(A17,[5]HISTOJUIL25!$A$6:$BQ$45,56,0) -> 485000 | D17: =VLOOKUP(A17,[5]HISTOJUIL25!$A$6:$BQ$45,57,0) -> OK | G17: =SUM(E17:F17) -> 0
A18: AS201617 | B18: =VLOOKUP(A18,[4]LISTADHERENT!A$5:H$50,3,0) -> KOUAMOU MOISE | C18: =VLOOKUP(A18,[5]HISTOJUIL25!$A$6:$BQ$45,56,0) -> 349000 | D18: =VLOOKUP(A18,[5]HISTOJUIL25!$A$6:$BQ$45,57,0) -> OK | G18: =SUM(E18:F18) -> 0
A19: AS201619 | B19: =VLOOKUP(A19,[4]LISTADHERENT!A$5:H$50,3,0) -> KOUATCHO MESSACK | C19: =VLOOKUP(A19,[5]HISTOJUIL25!$A$6:$BQ$45,56,0) -> 55000 | D19: =VLOOKUP(A19,[5]HISTOJUIL25!$A$6:$BQ$45,57,0) -> OK | G19: =SUM(E19:F19) -> 0
A20: AS201620 | B20: =VLOOKUP(A20,[4]LISTADHERENT!A$5:H$50,3,0) -> LOWE JEAN | C20: =VLOOKUP(A20,[5]HISTOJUIL25!$A$6:$BQ$45,56,0) -> 0 | D20: =VLOOKUP(A20,[5]HISTOJUIL25!$A$6:$BQ$45,57,0) -> 0
A21: AS201661 | B21: =VLOOKUP(A21,[4]LISTADHERENT!A$5:H$50,3,0) -> MASSEUNGOUE DAGOBERT | C21: =VLOOKUP(A21,[5]HISTOJUIL25!$A$6:$BQ$45,56,0) -> 0 | D21: =VLOOKUP(A21,[5]HISTOJUIL25!$A$6:$BQ$45,57,0) -> 0 | G21: =SUM(E21:F21) -> 0
A22: AS201649 | B22: =VLOOKUP(A22,[4]LISTADHERENT!A$5:H$50,3,0) -> MBOGNING TUGMA GUY | C22: =VLOOKUP(A22,[5]HISTOJUIL25!$A$6:$BQ$45,56,0) -> 1040000 | D22: =VLOOKUP(A22,[5]HISTOJUIL25!$A$6:$BQ$45,57,0) -> OK | G22: =SUM(E22:F22) -> 0
A23: AS201639 | B23: =VLOOKUP(A23,[4]LISTADHERENT!A$5:H$50,3,0) -> NANGUEN MARTIN | C23: =VLOOKUP(A23,[5]HISTOJUIL25!$A$6:$BQ$45,56,0) -> 0 | D23: =VLOOKUP(A23,[5]HISTOJUIL25!$A$6:$BQ$45,57,0) -> 0 | G23: =SUM(E23:F23) -> 0
A24: AS201621 | B24: =VLOOKUP(A24,[4]LISTADHERENT!A$5:H$50,3,0) -> NANKAM APPOLINAIRE | C24: =VLOOKUP(A24,[5]HISTOJUIL25!$A$6:$BQ$45,56,0) -> 0 | D24: =VLOOKUP(A24,[5]HISTOJUIL25!$A$6:$BQ$45,57,0) -> 0 | G24: =SUM(E24:F24) -> 0
A25: AS201622 | B25: =VLOOKUP(A25,[4]LISTADHERENT!A$5:H$50,3,0) -> NDJOMO ETIENNE | C25: =VLOOKUP(A25,[5]HISTOJUIL25!$A$6:$BQ$45,56,0) -> 497500 | D25: =VLOOKUP(A25,[5]HISTOJUIL25!$A$6:$BQ$45,57,0) -> OK | G25: =SUM(E25:F25) -> 0
A26: AS201624 | B26: =VLOOKUP(A26,[4]LISTADHERENT!A$5:H$50,3,0) -> NGONDIEP CLAUDE | C26: =VLOOKUP(A26,[5]HISTOJUIL25!$A$6:$BQ$45,56,0) -> 0 | D26: =VLOOKUP(A26,[5]HISTOJUIL25!$A$6:$BQ$45,57,0) -> 0 | G26: =SUM(E26:F26) -> 0
A27: AS201626 | B27: =VLOOKUP(A27,[4]LISTADHERENT!A$5:H$50,3,0) -> NGUIEMEGNI MATHIEU BLAISE | C27: =VLOOKUP(A27,[5]HISTOJUIL25!$A$6:$BQ$45,56,0) -> 200000 | D27: =VLOOKUP(A27,[5]HISTOJUIL25!$A$6:$BQ$45,57,0) -> OK | G27: =SUM(E27:F27) -> 0
A28: AS201628 | B28: =VLOOKUP(A28,[4]LISTADHERENT!A$5:H$50,3,0) -> NKAMGANG JUSTIN DEJOLIE | C28: =VLOOKUP(A28,[5]HISTOJUIL25!$A$6:$BQ$45,56,0) -> 0 | D28: =VLOOKUP(A28,[5]HISTOJUIL25!$A$6:$BQ$45,57,0) -> 0 | G28: =SUM(E28:F28) -> 0
A29: AS201656 | B29: =VLOOKUP(A29,[4]LISTADHERENT!A$5:H$50,3,0) -> NOUBE ETIENNE | C29: =VLOOKUP(A29,[5]HISTOJUIL25!$A$6:$BQ$45,56,0) -> 0 | D29: =VLOOKUP(A29,[5]HISTOJUIL25!$A$6:$BQ$45,57,0) -> 0 | G29: =SUM(E29:F29) -> 0
A30: AS201633 | B30: =VLOOKUP(A30,[4]LISTADHERENT!A$5:H$50,3,0) -> PATEGO NJOSSU GUSTAVE | C30: =VLOOKUP(A30,[5]HISTOJUIL25!$A$6:$BQ$45,56,0) -> 0 | D30: =VLOOKUP(A30,[5]HISTOJUIL25!$A$6:$BQ$45,57,0) -> 0 | G30: =SUM(E30:F30) -> 0
A31: AS201657 | B31: =VLOOKUP(A31,[4]LISTADHERENT!A$5:H$50,3,0) -> SEUMO POLYCARPE | C31: =VLOOKUP(A31,[5]HISTOJUIL25!$A$6:$BQ$45,56,0) -> 59000 | D31: =VLOOKUP(A31,[5]HISTOJUIL25!$A$6:$BQ$45,57,0) -> 0 | G31: =SUM(E31:F31) -> 0
A32: AS201653 | B32: =VLOOKUP(A32,[4]LISTADHERENT!A$5:H$50,3,0) -> SIME BRICE | C32: =VLOOKUP(A32,[5]HISTOJUIL25!$A$6:$BQ$45,56,0) -> 0 | D32: =VLOOKUP(A32,[5]HISTOJUIL25!$A$6:$BQ$45,57,0) -> 0 | G32: =SUM(E32:F32) -> 0
... A42: AS201647 | B42: =VLOOKUP(A42,[4]LISTADHERENT!A$5:H$50,3,0) -> YOUMBI EMMANUEL | C42: =VLOOKUP(A42,[5]HISTOJUIL25!$A$6:$BQ$45,56,0) -> 0 | D42: =VLOOKUP(A42,[5]HISTOJUIL25!$A$6:$BQ$45,57,0) -> 0 | G42: =SUM(E42:F42) -> 0
B43: SOLDE BANQUE | F43: 5656224
B44: TOTAUX | C44: =SUM(C6:C43) -> 5870000 | E44: =SUM(E7:E43) -> 0 | G44: =SUM(G7:G43) -> 0
B46: DIFFERENCE A CHERCHER | C46: =C44-C5 -> 5870000
B48: COMPTE BANQUE
B50: LIBELLE
B51: REPORT
B52: TONTINE

Sheet HISTOAOUT25
A1: ASSOCIATION | B1: ASELBY
A2: ANNEE | B2: 2025
A3: MATRICULE | B3: NOM ET PRENOM | G3: TOTAUX
C4: MONTANT CHEQUE | D4: NUM CHEQUE | E4: AGIOS | F4: Extrait de compte
B5: CHEQUE ETABLI
A6: AS201648 | B6: =VLOOKUP(A6,[4]LISTADHERENT!A$5:H$50,3,0) -> ASELBY | C6: =VLOOKUP(A6,[5]HISTOAOUT25!$A$6:$BQ$45,56,0) -> 560000 | D6: =VLOOKUP(A6,[5]HISTOAOUT25!$A$6:$BQ$45,57,0) -> 0 | E6: =+[6]HISTOBQUEAOUT25!$H$6 -> 2385 | G6: =SUM(E6:F6) -> 2385
A7: AS201601 | B7: =VLOOKUP(A7,[4]LISTADHERENT!A$5:H$50,3,0) -> BAKOP ACHILLE | C7: =VLOOKUP(A7,[5]HISTOAOUT25!$A$6:$BQ$45,56,0) -> 297500 | D7: =VLOOKUP(A7,[5]HISTOAOUT25!$A$6:$BQ$45,57,0) -> 0 | G7: =SUM(E7:F7) -> 0
A8: AS201602 | B8: =VLOOKUP(A8,[4]LISTADHERENT!A$5:H$50,3,0) -> BOUTCHOUANG WILLIAM | C8: =VLOOKUP(A8,[5]HISTOAOUT25!$A$6:$BQ$45,56,0) -> 0 | D8: =VLOOKUP(A8,[5]HISTOAOUT25!$A$6:$BQ$45,57,0) -> 0 | G8: =SUM(E8:F8) -> 0
A9: AS201604 | B9: =VLOOKUP(A9,[4]LISTADHERENT!A$5:H$50,3,0) -> DJOMO JEAN PAUL | C9: =VLOOKUP(A9,[5]HISTOAOUT25!$A$6:$BQ$45,56,0) -> 1320000 | D9: =VLOOKUP(A9,[5]HISTOAOUT25!$A$6:$BQ$45,57,0) -> 0 | G9: =SUM(E9:F9) -> 0
A10: AS201654 | B10: =VLOOKUP(A10,[4]LISTADHERENT!A$5:H$50,3,0) -> DJOMOU TCHAPDA | C10: =VLOOKUP(A10,[5]HISTOAOUT25!$A$6:$BQ$45,56,0) -> 0 | D10: =VLOOKUP(A10,[5]HISTOAOUT25!$A$6:$BQ$45,57,0) -> 0 | G10: =SUM(E10:F10) -> 0
A11: AS201605 | B11: =VLOOKUP(A11,[4]LISTADHERENT!A$5:H$50,3,0) -> DJOUKWE NANGUEN GUY BLAISE | C11: =VLOOKUP(A11,[5]HISTOAOUT25!$A$6:$BQ$45,56,0) -> 0 | D11: =VLOOKUP(A11,[5]HISTOAOUT25!$A$6:$BQ$45,57,0) -> 0 | G11: =SUM(E11:F11) -> 0
A12: AS201608 | B12: =VLOOKUP(A12,[4]LISTADHERENT!A$5:H$50,3,0) -> DJUOMBESSY ANTOINE | C12: =VLOOKUP(A12,[5]HISTOAOUT25!$A$6:$BQ$45,56,0) -> 1100000 | D12: =VLOOKUP(A12,[5]HISTOAOUT25!$A$6:$BQ$45,57,0) -> 0 | G12: =SUM(E12:F12) -> 0
A13: AS201651 | B13: =VLOOKUP(A13,[4]LISTADHERENT!A$5:H$50,3,0) -> DOMOU FABIEN | C13: =VLOOKUP(A13,[5]HISTOAOUT25!$A$6:$BQ$45,56,0) -> 0 | D13: =VLOOKUP(A13,[5]HISTOAOUT25!$A$6:$BQ$45,57,0) -> 0 | G13: =SUM(E13:F13) -> 0
A14: AS201609 | B14: =VLOOKUP(A14,[4]LISTADHERENT!A$5:H$50,3,0) -> DONHOU DAVID | C14: =VLOOKUP(A14,[5]HISTOAOUT25!$A$6:$BQ$45,56,0) -> 0 | D14: =VLOOKUP(A14,[5]HISTOAOUT25!$A$6:$BQ$45,57,0) -> 0 | G14: =SUM(E14:F14) -> 0
A15: AS201663 | B15: =VLOOKUP(A15,[4]LISTADHERENT!A$5:H$50,3,0) -> FAMPOU PAUL | C15: =VLOOKUP(A15,[5]HISTOAOUT25!$A$6:$BQ$45,56,0) -> 0 | D15: =VLOOKUP(A15,[5]HISTOAOUT25!$A$6:$BQ$45,57,0) -> 0 | G15: =SUM(E15:F15) -> 0
A16: AS201611 | B16: =VLOOKUP(A16,[4]LISTADHERENT!A$5:H$50,3,0) -> HENGUE PAUL OMER | C16: =VLOOKUP(A16,[5]HISTOAOUT25!$A$6:$BQ$45,56,0) -> 296500 | D16: =VLOOKUP(A16,[5]HISTOAOUT25!$A$6:$BQ$45,57,0) -> 0 | G16: =SUM(E16:F16) -> 0
A17: AS201613 | B17: =VLOOKUP(A17,[4]LISTADHERENT!A$5:H$50,3,0) -> HOTCHO BENJAMIN | C17: =VLOOKUP(A17,[5]HISTOAOUT25!$A$6:$BQ$45,56,0) -> 100000 | D17: =VLOOKUP(A17,[5]HISTOAOUT25!$A$6:$BQ$45,57,0) -> 0 | G17: =SUM(E17:F17) -> 0
A18: AS201617 | B18: =VLOOKUP(A18,[4]LISTADHERENT!A$5:H$50,3,0) -> KOUAMOU MOISE | C18: =VLOOKUP(A18,[5]HISTOAOUT25!$A$6:$BQ$45,56,0) -> 0 | D18: =VLOOKUP(A18,[5]HISTOAOUT25!$A$6:$BQ$45,57,0) -> 0 | G18: =SUM(E18:F18) -> 0
A19: AS201619 | B19: =VLOOKUP(A19,[4]LISTADHERENT!A$5:H$50,3,0) -> KOUATCHO MESSACK | C19: =VLOOKUP(A19,[5]HISTOAOUT25!$A$6:$BQ$45,56,0) -> 0 | D19: =VLOOKUP(A19,[5]HISTOAOUT25!$A$6:$BQ$45,57,0) -> 0 | G19: =SUM(E19:F19) -> 0
A20: AS201620 | B20: =VLOOKUP(A20,[4]LISTADHERENT!A$5:H$50,3,0) -> LOWE JEAN | C20: =VLOOKUP(A20,[5]HISTOAOUT25!$A$6:$BQ$45,56,0) -> 0 | D20: =VLOOKUP(A20,[5]HISTOAOUT25!$A$6:$BQ$45,57,0) -> 0
A21: AS201661 | B21: =VLOOKUP(A21,[4]LISTADHERENT!A$5:H$50,3,0) -> MASSEUNGOUE DAGOBERT | C21: =VLOOKUP(A21,[5]HISTOAOUT25!$A$6:$BQ$45,56,0) -> 0 | D21: =VLOOKUP(A21,[5]HISTOAOUT25!$A$6:$BQ$45,57,0) -> 0 | G21: =SUM(E21:F21) -> 0
A22: AS201649 | B22: =VLOOKUP(A22,[4]LISTADHERENT!A$5:H$50,3,0) -> MBOGNING TUGMA GUY | C22: =VLOOKUP(A22,[5]HISTOAOUT25!$A$6:$BQ$45,56,0) -> 400000 | D22: =VLOOKUP(A22,[5]HISTOAOUT25!$A$6:$BQ$45,57,0) -> 0 | G22: =SUM(E22:F22) -> 0
A23: AS201639 | B23: =VLOOKUP(A23,[4]LISTADHERENT!A$5:H$50,3,0) -> NANGUEN MARTIN | C23: =VLOOKUP(A23,[5]HISTOAOUT25!$A$6:$BQ$45,56,0) -> 0 | D23: =VLOOKUP(A23,[5]HISTOAOUT25!$A$6:$BQ$45,57,0) -> 0 | G23: =SUM(E23:F23) -> 0
A24: AS201621 | B24: =VLOOKUP(A24,[4]LISTADHERENT!A$5:H$50,3,0) -> NANKAM APPOLINAIRE | C24: =VLOOKUP(A24,[5]HISTOAOUT25!$A$6:$BQ$45,56,0) -> 0 | D24: =VLOOKUP(A24,[5]HISTOAOUT25!$A$6:$BQ$45,57,0) -> 0 | G24: =SUM(E24:F24) -> 0
A25: AS201622 | B25: =VLOOKUP(A25,[4]LISTADHERENT!A$5:H$50,3,0) -> NDJOMO ETIENNE | C25: =VLOOKUP(A25,[5]HISTOAOUT25!$A$6:$BQ$45,56,0) -> 200000 | D25: =VLOOKUP(A25,[5]HISTOAOUT25!$A$6:$BQ$45,57,0) -> 0 | G25: =SUM(E25:F25) -> 0
A26: AS201624 | B26: =VLOOKUP(A26,[4]LISTADHERENT!A$5:H$50,3,0) -> NGONDIEP CLAUDE | C26: =VLOOKUP(A26,[5]HISTOAOUT25!$A$6:$BQ$45,56,0) -> 936500 | D26: =VLOOKUP(A26,[5]HISTOAOUT25!$A$6:$BQ$45,57,0) -> 0 | G26: =SUM(E26:F26) -> 0
A27: AS201626 | B27: =VLOOKUP(A27,[4]LISTADHERENT!A$5:H$50,3,0) -> NGUIEMEGNI MATHIEU BLAISE | C27: =VLOOKUP(A27,[5]HISTOAOUT25!$A$6:$BQ$45,56,0) -> 1151500 | D27: =VLOOKUP(A27,[5]HISTOAOUT25!$A$6:$BQ$45,57,0) -> 0 | G27: =SUM(E27:F27) -> 0
A28: AS201628 | B28: =VLOOKUP(A28,[4]LISTADHERENT!A$5:H$50,3,0) -> NKAMGANG JUSTIN DEJOLIE | C28: =VLOOKUP(A28,[5]HISTOAOUT25!$A$6:$BQ$45,56,0) -> 0 | D28: =VLOOKUP(A28,[5]HISTOAOUT25!$A$6:$BQ$45,57,0) -> 0 | G28: =SUM(E28:F28) -> 0
A29: AS201656 | B29: =VLOOKUP(A29,[4]LISTADHERENT!A$5:H$50,3,0) -> NOUBE ETIENNE | C29: =VLOOKUP(A29,[5]HISTOAOUT25!$A$6:$BQ$45,56,0) -> 0 | D29: =VLOOKUP(A29,[5]HISTOAOUT25!$A$6:$BQ$45,57,0) -> 0 | G29: =SUM(E29:F29) -> 0
A30: AS201633 | B30: =VLOOKUP(A30,[4]LISTADHERENT!A$5:H$50,3,0) -> PATEGO NJOSSU GUSTAVE | C30: =VLOOKUP(A30,[5]HISTOAOUT25!$A$6:$BQ$45,56,0) -> 0 | D30: =VLOOKUP(A30,[5]HISTOAOUT25!$A$6:$BQ$45,57,0) -> 0 | G30: =SUM(E30:F30) -> 0
A31: AS201657 | B31: =VLOOKUP(A31,[4]LISTADHERENT!A$5:H$50,3,0) -> SEUMO POLYCARPE | C31: =VLOOKUP(A31,[5]HISTOAOUT25!$A$6:$BQ$45,56,0) -> 59000 | D31: =VLOOKUP(A31,[5]HISTOAOUT25!$A$6:$BQ$45,57,0) -> 0 | G31: =SUM(E31:F31) -> 0
A32: AS201653 | B32: =VLOOKUP(A32,[4]LISTADHERENT!A$5:H$50,3,0) -> SIME BRICE | C32: =VLOOKUP(A32,[5]HISTOAOUT25!$A$6:$BQ$45,56,0) -> 0 | D32: =VLOOKUP(A32,[5]HISTOAOUT25!$A$6:$BQ$45,57,0) -> 0 | G32: =SUM(E32:F32) -> 0
... A42: AS201647 | B42: =VLOOKUP(A42,[4]LISTADHERENT!A$5:H$50,3,0) -> YOUMBI EMMANUEL | C42: =VLOOKUP(A42,[5]HISTOAOUT25!$A$6:$BQ$45,56,0) -> 0 | D42: =VLOOKUP(A42,[5]HISTOAOUT25!$A$6:$BQ$45,57,0) -> 0 | G42: =SUM(E42:F42) -> 0
B43: SOLDE BANQUE | F43: 4294839
B44: TOTAUX | C44: =SUM(C6:C43) -> 6724000 | E44: =SUM(E7:E43) -> 0 | G44: =SUM(G7:G43) -> 0
B46: DIFFERENCE A CHERCHER | C46: =C44-C5 -> 6724000
B48: COMPTE BANQUE
B50: LIBELLE
B51: REPORT
B52: TONTINE

Sheet HISTOSEPT25
A1: ASSOCIATION | B1: ASELBY
A2: ANNEE | B2: 2025
A3: MATRICULE | B3: NOM ET PRENOM | G3: TOTAUX
C4: MONTANT CHEQUE | D4: NUM CHEQUE | E4: AGIOS | F4: Extrait de compte
B5: CHEQUE ETABLI
A6: AS201648 | B6: =VLOOKUP(A6,[4]LISTADHERENT!A$5:H$50,3,0) -> ASELBY | C6: =VLOOKUP(A6,[5]HISTOSEPT25!$A$6:$BQ$45,56,0) -> 12000 | D6: =VLOOKUP(A6,[5]HISTOSEPT25!$A$6:$BQ$45,57,0) -> 0 | E6: =+[6]HISTOBQUESEPT25!$H$6 -> 1193 | G6: =SUM(E6:F6) -> 1193
A7: AS201601 | B7: =VLOOKUP(A7,[4]LISTADHERENT!A$5:H$50,3,0) -> BAKOP ACHILLE | C7: =VLOOKUP(A7,[5]HISTOSEPT25!$A$6:$BQ$45,56,0) -> 0 | D7: =VLOOKUP(A7,[5]HISTOSEPT25!$A$6:$BQ$45,57,0) -> 0 | G7: =SUM(E7:F7) -> 0
A8: AS201602 | B8: =VLOOKUP(A8,[4]LISTADHERENT!A$5:H$50,3,0) -> BOUTCHOUANG WILLIAM | C8: =VLOOKUP(A8,[5]HISTOSEPT25!$A$6:$BQ$45,56,0) -> 297500 | D8: =VLOOKUP(A8,[5]HISTOSEPT25!$A$6:$BQ$45,57,0) -> 0 | G8: =SUM(E8:F8) -> 0
A9: AS201604 | B9: =VLOOKUP(A9,[4]LISTADHERENT!A$5:H$50,3,0) -> DJOMO JEAN PAUL | C9: =VLOOKUP(A9,[5]HISTOSEPT25!$A$6:$BQ$45,56,0) -> 0 | D9: =VLOOKUP(A9,[5]HISTOSEPT25!$A$6:$BQ$45,57,0) -> 0 | G9: =SUM(E9:F9) -> 0
A10: AS201654 | B10: =VLOOKUP(A10,[4]LISTADHERENT!A$5:H$50,3,0) -> DJOMOU TCHAPDA | C10: =VLOOKUP(A10,[5]HISTOSEPT25!$A$6:$BQ$45,56,0) -> 0 | D10: =VLOOKUP(A10,[5]HISTOSEPT25!$A$6:$BQ$45,57,0) -> 0 | G10: =SUM(E10:F10) -> 0
A11: AS201605 | B11: =VLOOKUP(A11,[4]LISTADHERENT!A$5:H$50,3,0) -> DJOUKWE NANGUEN GUY BLAISE | C11: =VLOOKUP(A11,[5]HISTOSEPT25!$A$6:$BQ$45,56,0) -> 200000 | D11: =VLOOKUP(A11,[5]HISTOSEPT25!$A$6:$BQ$45,57,0) -> 0 | G11: =SUM(E11:F11) -> 0
A12: AS201608 | B12: =VLOOKUP(A12,[4]LISTADHERENT!A$5:H$50,3,0) -> DJUOMBESSY ANTOINE | C12: =VLOOKUP(A12,[5]HISTOSEPT25!$A$6:$BQ$45,56,0) -> 1185000 | D12: =VLOOKUP(A12,[5]HISTOSEPT25!$A$6:$BQ$45,57,0) -> 0 | G12: =SUM(E12:F12) -> 0
A13: AS201651 | B13: =VLOOKUP(A13,[4]LISTADHERENT!A$5:H$50,3,0) -> DOMOU FABIEN | C13: =VLOOKUP(A13,[5]HISTOSEPT25!$A$6:$BQ$45,56,0) -> 0 | D13: =VLOOKUP(A13,[5]HISTOSEPT25!$A$6:$BQ$45,57,0) -> 0 | G13: =SUM(E13:F13) -> 0
A14: AS201609 | B14: =VLOOKUP(A14,[4]LISTADHERENT!A$5:H$50,3,0) -> DONHOU DAVID | C14: =VLOOKUP(A14,[5]HISTOSEPT25!$A$6:$BQ$45,56,0) -> 0 | D14: =VLOOKUP(A14,[5]HISTOSEPT25!$A$6:$BQ$45,57,0) -> 0 | G14: =SUM(E14:F14) -> 0
A15: AS201663 | B15: =VLOOKUP(A15,[4]LISTADHERENT!A$5:H$50,3,0) -> FAMPOU PAUL | C15: =VLOOKUP(A15,[5]HISTOSEPT25!$A$6:$BQ$45,56,0) -> 0 | D15: =VLOOKUP(A15,[5]HISTOSEPT25!$A$6:$BQ$45,57,0) -> 0 | G15: =SUM(E15:F15) -> 0
A16: AS201611 | B16: =VLOOKUP(A16,[4]LISTADHERENT!A$5:H$50,3,0) -> HENGUE PAUL OMER | C16: =VLOOKUP(A16,[5]HISTOSEPT25!$A$6:$BQ$45,56,0) -> 891500 | D16: =VLOOKUP(A16,[5]HISTOSEPT25!$A$6:$BQ$45,57,0) -> 0 | G16: =SUM(E16:F16) -> 0
A17: AS201613 | B17: =VLOOKUP(A17,[4]LISTADHERENT!A$5:H$50,3,0) -> HOTCHO BENJAMIN | C17: =VLOOKUP(A17,[5]HISTOSEPT25!$A$6:$BQ$45,56,0) -> 100000 | D17: =VLOOKUP(A17,[5]HISTOSEPT25!$A$6:$BQ$45,57,0) -> 0 | G17: =SUM(E17:F17) -> 0
A18: AS201617 | B18: =VLOOKUP(A18,[4]LISTADHERENT!A$5:H$50,3,0) -> KOUAMOU MOISE | C18: =VLOOKUP(A18,[5]HISTOSEPT25!$A$6:$BQ$45,56,0) -> 0 | D18: =VLOOKUP(A18,[5]HISTOSEPT25!$A$6:$BQ$45,57,0) -> 0 | G18: =SUM(E18:F18) -> 0
A19: AS201619 | B19: =VLOOKUP(A19,[4]LISTADHERENT!A$5:H$50,3,0) -> KOUATCHO MESSACK | C19: =VLOOKUP(A19,[5]HISTOSEPT25!$A$6:$BQ$45,56,0) -> 100000 | D19: =VLOOKUP(A19,[5]HISTOSEPT25!$A$6:$BQ$45,57,0) -> 0 | G19: =SUM(E19:F19) -> 0
A20: AS201620 | B20: =VLOOKUP(A20,[4]LISTADHERENT!A$5:H$50,3,0) -> LOWE JEAN | C20: =VLOOKUP(A20,[5]HISTOSEPT25!$A$6:$BQ$45,56,0) -> 0 | D20: =VLOOKUP(A20,[5]HISTOSEPT25!$A$6:$BQ$45,57,0) -> 0
A21: AS201661 | B21: =VLOOKUP(A21,[4]LISTADHERENT!A$5:H$50,3,0) -> MASSEUNGOUE DAGOBERT | C21: =VLOOKUP(A21,[5]HISTOSEPT25!$A$6:$BQ$45,56,0) -> 282500 | D21: =VLOOKUP(A21,[5]HISTOSEPT25!$A$6:$BQ$45,57,0) -> 0 | G21: =SUM(E21:F21) -> 0
A22: AS201649 | B22: =VLOOKUP(A22,[4]LISTADHERENT!A$5:H$50,3,0) -> MBOGNING TUGMA GUY | C22: =VLOOKUP(A22,[5]HISTOSEPT25!$A$6:$BQ$45,56,0) -> 100000 | D22: =VLOOKUP(A22,[5]HISTOSEPT25!$A$6:$BQ$45,57,0) -> 0 | G22: =SUM(E22:F22) -> 0
