Workbook
Name BANQUE: #REF!
Name BANQUE: #REF!
Name BANQUE: #REF!
Name BANQUE: #REF!
Name BANQUE: #REF!
Name BANQUE: #REF!
Name BANQUE: #REF!
Name BANQUE: #REF!
Name BANQUE: #REF!
Name BANQUE: #REF!
Name BANQUE: #REF!
Name BANQUE: #REF!
Name BANQUE: #REF!
Name BANQUE: #REF!
Name BANQUE: #REF!
Name BANQUE: #REF!
Name MODEPAID: #REF!
Name MODEPAID: [1]Feuil2!$A$1:$A$3
Name MODET25000: [2]MODEVERSEMENT!$A$1:$A$3
Name MODEVERSEMENT: #REF!
Name MODEVERSEMENT: #REF!
Name MODEVERSEMENT: #REF!
Name MODEVERSEMENT: #REF!
Name MODEVERSEMENT: #REF!
Name MODEVERSEMENT: #REF!
Name MODEVERSEMENT: #REF!
Name MODEVERSEMENT: #REF!
Name MODEVERSEMENT: #REF!
Name MODEVERSEMENT: #REF!
Name MODEVERSEMENT: #REF!
Name MODEVERSEMENT: #REF!
Name MODEVERSEMENT: #REF!
Name MODEVERSEMENT: #REF!
Name MODEVERSEMENT: #REF!
Name MODEVERSEMENT: #REF!
Name MODEVERSEMENTS: [3]MODEVERSEMENT!$A$1:$A$3
Name MODEVERSEMENTS: [3]MODEVERSEMENT!$A$1:$A$3
Name MODEVERSEMENTS: [3]MODEVERSEMENT!$A$1:$A$3
Name MODEVERSEMENTS: [3]MODEVERSEMENT!$A$1:$A$3
Name MODEVERSEMENTS: [3]MODEVERSEMENT!$A$1:$A$3
Name MODEVERSEMENTS: [3]MODEVERSEMENT!$A$1:$A$3
Name MODEVERSEMENTS: [3]MODEVERSEMENT!$A$1:$A$3
Name MODEVERSEMENTS: [3]MODEVERSEMENT!$A$1:$A$3
Name MODEVERSEMENTS: [3]MODEVERSEMENT!$A$1:$A$3
Name MODEVERSEMENTS: [3]MODEVERSEMENT!$A$1:$A$3
Name MODEVERSEMENTS: [3]MODEVERSEMENT!$A$1:$A$3
Name MODEVERSEMENTS: [3]MODEVERSEMENT!$A$1:$A$3
Name MODEVERSEMENTS: [3]MODEVERSEMENT!$A$1:$A$3
Name MODEVERSEMENTS: [3]MODEVERSEMENT!$A$1:$A$3
Name MODEVERSEMENTS: MODEVERSEMENT!$A$1:$A$3
Name MODPAID: TONTAOUT24!#REF!
Name MODPAID: TONTAVRIL24!#REF!
Name MODPAID: TONTDEC24!#REF!
Name MODPAID: TONTFEV24!#REF!
Name MODPAID: TONTJANV24!#REF!
Name MODPAID: TONTJUIL24!#REF!
Name MODPAID: TONTJUIN24!#REF!
Name MODPAID: TONTMAI24!#REF!
Name MODPAID: TONTMARS24!#REF!
Name MODPAID: TONTNOV24!#REF!

Sheet MODEVERSEMENT
A1: BANQUE
A2: ESPECES
A3: ECHEC

Sheet TONTJANV24
A1: ASSOCIATION | B1: ASELBY
A2: ANNEE | B2: 2024 | C2: TONIINE | D2: NBRE PART
A3: TAUX TONTINE | B3: 25000 | C3: =B3*12 -> 300000 | D3: =ROUNDDOWN(M42/C3,0) -> 2
C4: 45304
A5: MATRICULE | B5: NBREPART | C5: NOM ET PRENOM | D5: MONTANT TONTINE | E5: MONTANT VERSE | F5: PENALITE VERSEMENT ESPECES | G5: MODE VERSEMENT | H5: VENTE PETIT LOT | I5: INTERET PETIT LOT | J5: MODE VERSEMENT VENTE PETIT LOT | K5: NUMERO CHEQUE | L5: MONTANT A REMBOURSER PETIT LOT | M5: REMBOURSEMENT PETIT LOT | N5: MODE VERSEMENT REMBOURSEMENT | O5: MODE VERSEMENTLOT PRINCIPAL | P5: NUMERO CHEQUE | Q5: MONTANT LOT PRINCIPAL | R5: INTERET LOT PRINCIPAL
A6: AS201601 | B6: =IF(D6=0,0,VLOOKUP($A6,[6]HISTOJANV24!$A$6:$BP$44,10,0)) -> 1 | C6: =VLOOKUP(A6,[7]LISTADHERENT!A$5:H$60,3,0) -> BAKOP ACHILLE | D6: =IF(G6="ECHEC",0,B$3) -> 25000 | E6: =D6+VLOOKUP($A6,[6]HISTOJANV24!$A$7:$AU$42,45,0)+F6 -> 50000 | F6: =VLOOKUP($A6,[6]HISTOJANV24!$A$6:$AV$48,7,0) -> 0 | G6: =VLOOKUP($A6,[6]HISTOJANV24!$A$6:$AV$49,8,0) -> BANQUE | H6: =VLOOKUP($A6,[6]HISTOJANV24!$A$6:$AV$49,35,0) -> 0 | I6: =VLOOKUP($A6,[6]HISTOJANV24!$A$6:$AV$49,38,0) -> 0 | J6: =IF(H6=0,0,VLOOKUP($A6,[6]HISTOJANV24!$A$6:$AV$49,42,0)) -> 0 | K6: =VLOOKUP($A6,[6]HISTOJANV24!$A$6:$AV$49,41,0) -> 0 | M6: =VLOOKUP($A6,[6]HISTOJANV24!$A$6:$AV$49,16,0) -> 0 | N6: =IF(M6<>0,VLOOKUP($A6,[6]HISTOJANV24!$A$6:$AV$49,8,0),"ECHEC") -> ECHEC | O6: =IF(R6=0,0,VLOOKUP($A6,[6]HISTOJANV24!$A$6:$AV$49,32,0)) -> 0 | P6: =VLOOKUP($A6,[6]HISTOJANV24!$A$6:$AV$49,33,0) -> 0 | Q6: =IF(R6=0,0,($C$3-R6)) -> 0 | R6: =VLOOKUP($A6,[6]HISTOJANV24!$A$6:$AV$49,29,0) -> 0
A7: AS201602 | B7: =IF(D7=0,0,VLOOKUP($A7,[6]HISTOJANV24!$A$6:$BP$44,10,0)) -> 1 | C7: =VLOOKUP(A7,[7]LISTADHERENT!A$5:H$60,3,0) -> BOUTCHOUANG WILLIAM | D7: =IF(G7="ECHEC",0,B$3) -> 25000 | E7: =D7+VLOOKUP($A7,[6]HISTOJANV24!$A$7:$AU$42,45,0)+F7 -> 50000 | F7: =VLOOKUP($A7,[6]HISTOJANV24!$A$6:$AV$48,7,0) -> 0 | G7: =VLOOKUP($A7,[6]HISTOJANV24!$A$6:$AV$49,8,0) -> BANQUE | H7: =VLOOKUP($A7,[6]HISTOJANV24!$A$6:$AV$49,35,0) -> 0 | I7: =VLOOKUP($A7,[6]HISTOJANV24!$A$6:$AV$49,38,0) -> 0 | J7: =IF(H7=0,0,VLOOKUP($A7,[6]HISTOJANV24!$A$6:$AV$49,42,0)) -> 0 | K7: =VLOOKUP($A7,[6]HISTOJANV24!$A$6:$AV$49,41,0) -> 0 | M7: =VLOOKUP($A7,[6]HISTOJANV24!$A$6:$AV$49,16,0) -> 0 | N7: =IF(M7<>0,VLOOKUP($A7,[6]HISTOJANV24!$A$6:$AV$49,8,0),"ECHEC") -> ECHEC | O7: =IF(R7=0,0,VLOOKUP($A7,[6]HISTOJANV24!$A$6:$AV$49,32,0)) -> 0 | P7: =VLOOKUP($A7,[6]HISTOJANV24!$A$6:$AV$49,33,0) -> 0 | Q7: =IF(R7=0,0,($C$3-R7)) -> 0 | R7: =VLOOKUP($A7,[6]HISTOJANV24!$A$6:$AV$49,29,0) -> 0
A8: AS201604 | B8: =IF(D8=0,0,VLOOKUP($A8,[6]HISTOJANV24!$A$6:$BP$44,10,0)) -> 1 | C8: =VLOOKUP(A8,[7]LISTADHERENT!A$5:H$60,3,0) -> DJOMO JEAN PAUL | D8: =IF(G8="ECHEC",0,B$3) -> 25000 | E8: =D8+VLOOKUP($A8,[6]HISTOJANV24!$A$7:$AU$42,45,0)+F8 -> 50000 | F8: =VLOOKUP($A8,[6]HISTOJANV24!$A$6:$AV$48,7,0) -> 0 | G8: =VLOOKUP($A8,[6]HISTOJANV24!$A$6:$AV$49,8,0) -> BANQUE | H8: =VLOOKUP($A8,[6]HISTOJANV24!$A$6:$AV$49,35,0) -> 0 | I8: =VLOOKUP($A8,[6]HISTOJANV24!$A$6:$AV$49,38,0) -> 0 | J8: =IF(H8=0,0,VLOOKUP($A8,[6]HISTOJANV24!$A$6:$AV$49,42,0)) -> 0 | K8: =VLOOKUP($A8,[6]HISTOJANV24!$A$6:$AV$49,41,0) -> 0 | M8: =VLOOKUP($A8,[6]HISTOJANV24!$A$6:$AV$49,16,0) -> 0 | N8: =IF(M8<>0,VLOOKUP($A8,[6]HISTOJANV24!$A$6:$AV$49,8,0),"ECHEC") -> ECHEC | O8: =IF(R8=0,0,VLOOKUP($A8,[6]HISTOJANV24!$A$6:$AV$49,32,0)) -> 0 | P8: =VLOOKUP($A8,[6]HISTOJANV24!$A$6:$AV$49,33,0) -> 0 | Q8: =IF(R8=0,0,($C$3-R8)) -> 0 | R8: =VLOOKUP($A8,[6]HISTOJANV24!$A$6:$AV$49,29,0) -> 0
A9: AS201654 | B9: =IF(D9=0,0,VLOOKUP($A9,[6]HISTOJANV24!$A$6:$BP$44,10,0)) -> 1 | C9: =VLOOKUP(A9,[7]LISTADHERENT!A$5:H$60,3,0) -> DJOMOU TCHAPDA | D9: =IF(G9="ECHEC",0,B$3) -> 25000 | E9: =D9+VLOOKUP($A9,[6]HISTOJANV24!$A$7:$AU$42,45,0)+F9 -> 50000 | F9: =VLOOKUP($A9,[6]HISTOJANV24!$A$6:$AV$48,7,0) -> 0 | G9: =VLOOKUP($A9,[6]HISTOJANV24!$A$6:$AV$49,8,0) -> BANQUE | H9: =VLOOKUP($A9,[6]HISTOJANV24!$A$6:$AV$49,35,0) -> 0 | I9: =VLOOKUP($A9,[6]HISTOJANV24!$A$6:$AV$49,38,0) -> 0 | J9: =IF(H9=0,0,VLOOKUP($A9,[6]HISTOJANV24!$A$6:$AV$49,42,0)) -> 0 | K9: =VLOOKUP($A9,[6]HISTOJANV24!$A$6:$AV$49,41,0) -> 0 | M9: =VLOOKUP($A9,[6]HISTOJANV24!$A$6:$AV$49,16,0) -> 0 | N9: =IF(M9<>0,VLOOKUP($A9,[6]HISTOJANV24!$A$6:$AV$49,8,0),"ECHEC") -> ECHEC | O9: =IF(R9=0,0,VLOOKUP($A9,[6]HISTOJANV24!$A$6:$AV$49,32,0)) -> 0 | P9: =VLOOKUP($A9,[6]HISTOJANV24!$A$6:$AV$49,33,0) -> 0 | Q9: =IF(R9=0,0,($C$3-R9)) -> 0 | R9: =VLOOKUP($A9,[6]HISTOJANV24!$A$6:$AV$49,29,0) -> 0
A10: AS201605 | B10: =IF(D10=0,0,VLOOKUP($A10,[6]HISTOJANV24!$A$6:$BP$44,10,0)) -> 1 | C10: =VLOOKUP(A10,[7]LISTADHERENT!A$5:H$60,3,0) -> DJOUKWE NANGUEN GUY BLAISE | D10: =IF(G10="ECHEC",0,B$3) -> 25000 | E10: =D10+VLOOKUP($A10,[6]HISTOJANV24!$A$7:$AU$42,45,0)+F10 -> 50000 | F10: =VLOOKUP($A10,[6]HISTOJANV24!$A$6:$AV$48,7,0) -> 0 | G10: =VLOOKUP($A10,[6]HISTOJANV24!$A$6:$AV$49,8,0) -> BANQUE | H10: =VLOOKUP($A10,[6]HISTOJANV24!$A$6:$AV$49,35,0) -> 0 | I10: =VLOOKUP($A10,[6]HISTOJANV24!$A$6:$AV$49,38,0) -> 0 | J10: =IF(H10=0,0,VLOOKUP($A10,[6]HISTOJANV24!$A$6:$AV$49,42,0)) -> 0 | K10: =VLOOKUP($A10,[6]HISTOJANV24!$A$6:$AV$49,41,0) -> 0 | M10: =VLOOKUP($A10,[6]HISTOJANV24!$A$6:$AV$49,16,0) -> 0 | N10: =IF(M10<>0,VLOOKUP($A10,[6]HISTOJANV24!$A$6:$AV$49,8,0),"ECHEC") -> ECHEC | O10: =IF(R10=0,0,VLOOKUP($A10,[6]HISTOJANV24!$A$6:$AV$49,32,0)) -> 0 | P10: =VLOOKUP($A10,[6]HISTOJANV24!$A$6:$AV$49,33,0) -> 0 | Q10: =IF(R10=0,0,($C$3-R10)) -> 0 | R10: =VLOOKUP($A10,[6]HISTOJANV24!$A$6:$AV$49,29,0) -> 0
A11: AS201608 | B11: =IF(D11=0,0,VLOOKUP($A11,[6]HISTOJANV24!$A$6:$BP$44,10,0)) -> 1 | C11: =VLOOKUP(A11,[7]LISTADHERENT!A$5:H$60,3,0) -> DJUOMBESSY ANTOINE | D11: =IF(G11="ECHEC",0,B$3) -> 25000 | E11: =D11+VLOOKUP($A11,[6]HISTOJANV24!$A$7:$AU$42,45,0)+F11 -> 55000 | F11: =VLOOKUP($A11,[6]HISTOJANV24!$A$6:$AV$48,7,0) -> 0 | G11: =VLOOKUP($A11,[6]HISTOJANV24!$A$6:$AV$49,8,0) -> BANQUE | H11: =VLOOKUP($A11,[6]HISTOJANV24!$A$6:$AV$49,35,0) -> 0 | I11: =VLOOKUP($A11,[6]HISTOJANV24!$A$6:$AV$49,38,0) -> 0 | J11: =IF(H11=0,0,VLOOKUP($A11,[6]HISTOJANV24!$A$6:$AV$49,42,0)) -> 0 | K11: =VLOOKUP($A11,[6]HISTOJANV24!$A$6:$AV$49,41,0) -> 0 | M11: =VLOOKUP($A11,[6]HISTOJANV24!$A$6:$AV$49,16,0) -> 0 | N11: =IF(M11<>0,VLOOKUP($A11,[6]HISTOJANV24!$A$6:$AV$49,8,0),"ECHEC") -> ECHEC | O11: =IF(R11=0,0,VLOOKUP($A11,[6]HISTOJANV24!$A$6:$AV$49,32,0)) -> 0 | P11: =VLOOKUP($A11,[6]HISTOJANV24!$A$6:$AV$49,33,0) -> 0 | Q11: =IF(R11=0,0,($C$3-R11)) -> 0 | R11: =VLOOKUP($A11,[6]HISTOJANV24!$A$6:$AV$49,29,0) -> 0
A12: AS201651 | B12: =IF(D12=0,0,VLOOKUP($A12,[6]HISTOJANV24!$A$6:$BP$44,10,0)) -> 1 | C12: =VLOOKUP(A12,[7]LISTADHERENT!A$5:H$60,3,0) -> DOMOU FABIEN | D12: =IF(G12="ECHEC",0,B$3) -> 25000 | E12: =D12+VLOOKUP($A12,[6]HISTOJANV24!$A$7:$AU$42,45,0)+F12 -> 50000 | F12: =VLOOKUP($A12,[6]HISTOJANV24!$A$6:$AV$48,7,0) -> 0 | G12: =VLOOKUP($A12,[6]HISTOJANV24!$A$6:$AV$49,8,0) -> BANQUE | H12: =VLOOKUP($A12,[6]HISTOJANV24!$A$6:$AV$49,35,0) -> 0 | I12: =VLOOKUP($A12,[6]HISTOJANV24!$A$6:$AV$49,38,0) -> 0 | J12: =IF(H12=0,0,VLOOKUP($A12,[6]HISTOJANV24!$A$6:$AV$49,42,0)) -> 0 | K12: =VLOOKUP($A12,[6]HISTOJANV24!$A$6:$AV$49,41,0) -> 0 | M12: =VLOOKUP($A12,[6]HISTOJANV24!$A$6:$AV$49,16,0) -> 0 | N12: =IF(M12<>0,VLOOKUP($A12,[6]HISTOJANV24!$A$6:$AV$49,8,0),"ECHEC") -> ECHEC | O12: =IF(R12=0,0,VLOOKUP($A12,[6]HISTOJANV24!$A$6:$AV$49,32,0)) -> 0 | P12: =VLOOKUP($A12,[6]HISTOJANV24!$A$6:$AV$49,33,0) -> 0 | Q12: =IF(R12=0,0,($C$3-R12)) -> 0 | R12: =VLOOKUP($A12,[6]HISTOJANV24!$A$6:$AV$49,29,0) -> 0
A13: AS201609 | B13: =IF(D13=0,0,VLOOKUP($A13,[6]HISTOJANV24!$A$6:$BP$44,10,0)) -> 1 | C13: =VLOOKUP(A13,[7]LISTADHERENT!A$5:H$60,3,0) -> DONHOU DAVID | D13: =IF(G13="ECHEC",0,B$3) -> 25000 | E13: =D13+VLOOKUP($A13,[6]HISTOJANV24!$A$7:$AU$42,45,0)+F13 -> 50000 | F13: =VLOOKUP($A13,[6]HISTOJANV24!$A$6:$AV$48,7,0) -> 0 | G13: =VLOOKUP($A13,[6]HISTOJANV24!$A$6:$AV$49,8,0) -> ESPECES | H13: =VLOOKUP($A13,[6]HISTOJANV24!$A$6:$AV$49,35,0) -> 0 | I13: =VLOOKUP($A13,[6]HISTOJANV24!$A$6:$AV$49,38,0) -> 0 | J13: =IF(H13=0,0,VLOOKUP($A13,[6]HISTOJANV24!$A$6:$AV$49,42,0)) -> 0 | K13: =VLOOKUP($A13,[6]HISTOJANV24!$A$6:$AV$49,41,0) -> 0 | M13: =VLOOKUP($A13,[6]HISTOJANV24!$A$6:$AV$49,16,0) -> 0 | N13: =IF(M13<>0,VLOOKUP($A13,[6]HISTOJANV24!$A$6:$AV$49,8,0),"ECHEC") -> ECHEC | O13: =IF(R13=0,0,VLOOKUP($A13,[6]HISTOJANV24!$A$6:$AV$49,32,0)) -> 0 | P13: =VLOOKUP($A13,[6]HISTOJANV24!$A$6:$AV$49,33,0) -> 0 | Q13: =IF(R13=0,0,($C$3-R13)) -> 0 | R13: =VLOOKUP($A13,[6]HISTOJANV24!$A$6:$AV$49,29,0) -> 0
A14: AS201611 | B14: =IF(D14=0,0,VLOOKUP($A14,[6]HISTOJANV24!$A$6:$BP$44,10,0)) -> 1 | C14: =VLOOKUP(A14,[7]LISTADHERENT!A$5:H$60,3,0) -> HENGUE PAUL OMER | D14: =IF(G14="ECHEC",0,B$3) -> 25000 | E14: =D14+VLOOKUP($A14,[6]HISTOJANV24!$A$7:$AU$42,45,0)+F14 -> 50000 | F14: =VLOOKUP($A14,[6]HISTOJANV24!$A$6:$AV$48,7,0) -> 0 | G14: =VLOOKUP($A14,[6]HISTOJANV24!$A$6:$AV$49,8,0) -> BANQUE | H14: =VLOOKUP($A14,[6]HISTOJANV24!$A$6:$AV$49,35,0) -> 0 | I14: =VLOOKUP($A14,[6]HISTOJANV24!$A$6:$AV$49,38,0) -> 0 | J14: =IF(H14=0,0,VLOOKUP($A14,[6]HISTOJANV24!$A$6:$AV$49,42,0)) -> 0 | K14: =VLOOKUP($A14,[6]HISTOJANV24!$A$6:$AV$49,41,0) -> 0 | M14: =VLOOKUP($A14,[6]HISTOJANV24!$A$6:$AV$49,16,0) -> 0 | N14: =IF(M14<>0,VLOOKUP($A14,[6]HISTOJANV24!$A$6:$AV$49,8,0),"ECHEC") -> ECHEC | O14: =IF(R14=0,0,VLOOKUP($A14,[6]HISTOJANV24!$A$6:$AV$49,32,0)) -> 0 | P14: =VLOOKUP($A14,[6]HISTOJANV24!$A$6:$AV$49,33,0) -> 0 | Q14: =IF(R14=0,0,($C$3-R14)) -> 0 | R14: =VLOOKUP($A14,[6]HISTOJANV24!$A$6:$AV$49,29,0) -> 0
A15: AS201613 | B15: =IF(D15=0,0,VLOOKUP($A15,[6]HISTOJANV24!$A$6:$BP$44,10,0)) -> 1 | C15: =VLOOKUP(A15,[7]LISTADHERENT!A$5:H$60,3,0) -> HOTCHO BENJAMIN | D15: =IF(G15="ECHEC",0,B$3) -> 25000 | E15: =D15+VLOOKUP($A15,[6]HISTOJANV24!$A$7:$AU$42,45,0)+F15 -> 85000 | F15: =VLOOKUP($A15,[6]HISTOJANV24!$A$6:$AV$48,7,0) -> 0 | G15: =VLOOKUP($A15,[6]HISTOJANV24!$A$6:$AV$49,8,0) -> BANQUE | H15: =VLOOKUP($A15,[6]HISTOJANV24!$A$6:$AV$49,35,0) -> 0 | I15: =VLOOKUP($A15,[6]HISTOJANV24!$A$6:$AV$49,38,0) -> 0 | J15: =IF(H15=0,0,VLOOKUP($A15,[6]HISTOJANV24!$A$6:$AV$49,42,0)) -> 0 | K15: =VLOOKUP($A15,[6]HISTOJANV24!$A$6:$AV$49,41,0) -> 0 | M15: =VLOOKUP($A15,[6]HISTOJANV24!$A$6:$AV$49,16,0) -> 0 | N15: =IF(M15<>0,VLOOKUP($A15,[6]HISTOJANV24!$A$6:$AV$49,8,0),"ECHEC") -> ECHEC | O15: =IF(R15=0,0,VLOOKUP($A15,[6]HISTOJANV24!$A$6:$AV$49,32,0)) -> BANQUE | P15: =VLOOKUP($A15,[6]HISTOJANV24!$A$6:$AV$49,33,0) -> 0 | Q15: =IF(R15=0,0,($C$3-R15)) -> 288000 | R15: =VLOOKUP($A15,[6]HISTOJANV24!$A$6:$AV$49,29,0) -> 12000
A16: AS201617 | B16: =IF(D16=0,0,VLOOKUP($A16,[6]HISTOJANV24!$A$6:$BP$44,10,0)) -> 1 | C16: =VLOOKUP(A16,[7]LISTADHERENT!A$5:H$60,3,0) -> KOUAMOU MOISE | D16: =IF(G16="ECHEC",0,B$3) -> 25000 | E16: =D16+VLOOKUP($A16,[6]HISTOJANV24!$A$7:$AU$42,45,0)+F16 -> 50000 | F16: =VLOOKUP($A16,[6]HISTOJANV24!$A$6:$AV$48,7,0) -> 0 | G16: =VLOOKUP($A16,[6]HISTOJANV24!$A$6:$AV$49,8,0) -> BANQUE | H16: =VLOOKUP($A16,[6]HISTOJANV24!$A$6:$AV$49,35,0) -> 0 | I16: =VLOOKUP($A16,[6]HISTOJANV24!$A$6:$AV$49,38,0) -> 0 | J16: =IF(H16=0,0,VLOOKUP($A16,[6]HISTOJANV24!$A$6:$AV$49,42,0)) -> 0 | K16: =VLOOKUP($A16,[6]HISTOJANV24!$A$6:$AV$49,41,0) -> 0 | M16: =VLOOKUP($A16,[6]HISTOJANV24!$A$6:$AV$49,16,0) -> 0 | N16: =IF(M16<>0,VLOOKUP($A16,[6]HISTOJANV24!$A$6:$AV$49,8,0),"ECHEC") -> ECHEC | O16: =IF(R16=0,0,VLOOKUP($A16,[6]HISTOJANV24!$A$6:$AV$49,32,0)) -> 0 | P16: =VLOOKUP($A16,[6]HISTOJANV24!$A$6:$AV$49,33,0) -> 0 | Q16: =IF(R16=0,0,($C$3-R16)) -> 0 | R16: =VLOOKUP($A16,[6]HISTOJANV24!$A$6:$AV$49,29,0) -> 0
A17: AS201619 | B17: =IF(D17=0,0,VLOOKUP($A17,[6]HISTOJANV24!$A$6:$BP$44,10,0)) -> 1 | C17: =VLOOKUP(A17,[7]LISTADHERENT!A$5:H$60,3,0) -> KOUATCHO MESSACK | D17: =IF(G17="ECHEC",0,B$3) -> 25000 | E17: =D17+VLOOKUP($A17,[6]HISTOJANV24!$A$7:$AU$42,45,0)+F17 -> 50000 | F17: =VLOOKUP($A17,[6]HISTOJANV24!$A$6:$AV$48,7,0) -> 0 | G17: =VLOOKUP($A17,[6]HISTOJANV24!$A$6:$AV$49,8,0) -> BANQUE | H17: =VLOOKUP($A17,[6]HISTOJANV24!$A$6:$AV$49,35,0) -> 0 | I17: =VLOOKUP($A17,[6]HISTOJANV24!$A$6:$AV$49,38,0) -> 0 | J17: =IF(H17=0,0,VLOOKUP($A17,[6]HISTOJANV24!$A$6:$AV$49,42,0)) -> 0 | K17: =VLOOKUP($A17,[6]HISTOJANV24!$A$6:$AV$49,41,0) -> 0 | M17: =VLOOKUP($A17,[6]HISTOJANV24!$A$6:$AV$49,16,0) -> 0 | N17: =IF(M17<>0,VLOOKUP($A17,[6]HISTOJANV24!$A$6:$AV$49,8,0),"ECHEC") -> ECHEC | O17: =IF(R17=0,0,VLOOKUP($A17,[6]HISTOJANV24!$A$6:$AV$49,32,0)) -> BANQUE | P17: =VLOOKUP($A17,[6]HISTOJANV24!$A$6:$AV$49,33,0) -> 0 | Q17: =IF(R17=0,0,($C$3-R17)) -> 287000 | R17: =VLOOKUP($A17,[6]HISTOJANV24!$A$6:$AV$49,29,0) -> 13000
... A37: AS201647 | B37: =IF(D37=0,0,VLOOKUP($A37,[6]HISTOJANV24!$A$6:$BP$44,10,0)) -> 1 | C37: =VLOOKUP(A37,[7]LISTADHERENT!A$5:H$60,3,0) -> YOUMBI EMMANUEL | D37: =IF(G37="ECHEC",0,B$3) -> 25000 | E37: =D37+VLOOKUP($A37,[6]HISTOJANV24!$A$7:$AU$42,45,0)+F37 -> 50000 | F37: =VLOOKUP($A37,[6]HISTOJANV24!$A$6:$AV$48,7,0) -> 0 | G37: =VLOOKUP($A37,[6]HISTOJANV24!$A$6:$AV$49,8,0) -> BANQUE | H37: =VLOOKUP($A37,[6]HISTOJANV24!$A$6:$AV$49,35,0) -> 0 | I37: =VLOOKUP($A37,[6]HISTOJANV24!$A$6:$AV$49,38,0) -> 0 | J37: =IF(H37=0,0,VLOOKUP($A37,[6]HISTOJANV24!$A$6:$AV$49,42,0)) -> 0 | K37: =VLOOKUP($A37,[6]HISTOJANV24!$A$6:$AV$49,41,0) -> 0 | M37: =VLOOKUP($A37,[6]HISTOJANV24!$A$6:$AV$49,16,0) -> 0 | N37: =IF(M37<>0,VLOOKUP($A37,[6]HISTOJANV24!$A$6:$AV$49,8,0),"ECHEC") -> ECHEC | O37: =IF(R37=0,0,VLOOKUP($A37,[6]HISTOJANV24!$A$6:$AV$49,32,0)) -> 0 | P37: =VLOOKUP($A37,[6]HISTOJANV24!$A$6:$AV$49,33,0) -> 0 | Q37: =IF(R37=0,0,($C$3-R37)) -> 0 | R37: =VLOOKUP($A37,[6]HISTOJANV24!$A$6:$AV$49,29,0) -> 0
A39: TOTAL PART | B39: =SUM(B6:B38) -> 32
A40: NBRE ADHERENT | B40: =COUNT(D6:D38) -> 32 | D40: =SUM(D6:D39) -> 800000 | F40: =SUM(F6:F39) -> -3000 | G40: =SUM(G6:G39) -> 0 | H40: =SUM(H6:H39) -> 0 | I40: =SUM(I6:I39) -> 0 | J40: =SUM(J6:J39) -> 0 | K40: =SUM(K6:K39) -> 0 | L40: =SUM(L6:L39) -> 0 | M40: =SUM(M6:M39) -> 0 | ... R40: =SUM(R6:R39) -> 38000
N41: NBRE PART | O41: PART VENDUE
D42: MONTANT TONTINE | G42: REMBOURSEMENT PETIT LOT | H42: VENTE PETIT LOT | I42: VENTE LOT PRINCIPAL | J42: SOLDE EN CAISSE | L42: TONTINE + REMB + INTERET VENTE | M42: =D46+G46+R40 -> 838000
D43: =SUMIFS(D6:D39,G6:G39,"ESPECES") -> 25000 | F43: ESPECES | G43: =SUMIFS(M6:M33,N6:N33,"ESPECES") -> 0 | H43: =SUMIFS(H6:H39,J6:J39,"ESPECES") -> 0 | I43: =SUMIFS(Q6:Q39,O6:O39,"ESPECES") -> 0 | J43: =D43+G43-H43-I43 -> 25000 | L43: LOT PRINCIPAL | M43: =C3*COUNTIF(Q7:Q39,">0") -> 900000 | N43: =D3 -> 2 | O43: =COUNTIF(Q7:Q33,">0") -> 3
D44: =SUMIFS(D6:D39,G6:G39,"BANQUE") -> 775000 | F44: BANQUE | G44: =SUMIFS(M6:M33,N6:N33,"BANQUE") -> 0 | H44: =SUMIFS(H6:H39,J6:J39,"BANQUE") -> 0 | I44: =SUMIFS(Q6:Q39,O6:O39,"BANQUE") -> 862000 | J44: =D44+G44-H44-I44 -> -87000
L45: PETIT LOT | M45: =M42-M43 -> -62000
D46: =D43+D44 -> 800000 | F46: TOTAL | G46: =G43+G44 -> 0 | H46: =H43+H44 -> 0 | I46: =I43+I44 -> 862000 | J46: =J43+J44 -> -62000
F47: TOTAL+DEPOT | L47: RELIQUAT | M47: =M45-H40 -> -62000 | O47: =M47 -> -62000 | P47: CUMUL
L49: ECHEC TONTINE MOIS | M49: =COUNTIFS(G7:G38,"ECHEC")*23000 -> 0 | P49: CUMUL
L50: ECHEC REMBOURSEMENT MOIS | M50: =L40-G46 -> 0 | P50: CUMUL

Sheet TONTFEV24
A1: ASSOCIATION | B1: ASELBY
A2: ANNEE | B2: 2024 | C2: TONIINE | D2: NBRE PART
A3: TAUX TONTINE | B3: 25000 | C3: =B3*12 -> 300000 | D3: =ROUNDDOWN(M42/C3,0) -> 2
C4: 45335
A5: MATRICULE | B5: NBREPART | C5: NOM ET PRENOM | D5: MONTANT TONTINE | E5: MONTANT VERSE | F5: PENALITE VERSEMENT ESPECES | G5: MODE VERSEMENT | H5: VENTE PETIT LOT | I5: INTERET PETIT LOT | J5: MODE VERSEMENT VENTE PETIT LOT | K5: NUMERO CHEQUE | L5: MONTANT A REMBOURSER PETIT LOT | M5: REMBOURSEMENT PETIT LOT | N5: MODE VERSEMENT REMBOURSEMENT | O5: MODE VERSEMENTLOT PRINCIPAL | P5: NUMERO CHEQUE | Q5: MONTANT LOT PRINCIPAL | R5: INTERET LOT PRINCIPAL
A6: AS201601 | B6: =IF(D6=0,0,VLOOKUP($A6,[6]HISTOFEV24!$A$6:$BP$44,10,0)) -> 1 | C6: =VLOOKUP(A6,[7]LISTADHERENT!A$5:H$60,3,0) -> BAKOP ACHILLE | D6: =IF(G6="ECHEC",0,B$3) -> 25000 | E6: =D6+VLOOKUP($A6,[6]HISTOFEV24!$A$7:$AU$42,45,0)+F6 -> 50000 | F6: =VLOOKUP($A6,[6]HISTOFEV24!$A$6:$AV$48,7,0) -> 0 | G6: =VLOOKUP($A6,[6]HISTOFEV24!$A$6:$AV$49,8,0) -> BANQUE | H6: =VLOOKUP($A6,[6]HISTOFEV24!$A$6:$AV$49,35,0) -> 60000 | I6: =VLOOKUP($A6,[6]HISTOFEV24!$A$6:$AV$49,38,0) -> 1000 | J6: =IF(H6=0,0,VLOOKUP($A6,[6]HISTOFEV24!$A$6:$AV$49,42,0)) -> 0 | K6: =VLOOKUP($A6,[6]HISTOFEV24!$A$6:$AV$49,41,0) -> 0 | L6: =TONTJANV24!H6+TONTJANV24!I6 -> 0 | M6: =VLOOKUP($A6,[6]HISTOFEV24!$A$6:$AV$49,16,0) -> 0 | N6: =IF(M6<>0,VLOOKUP($A6,[6]HISTOFEV24!$A$6:$AV$49,8,0),"ECHEC") -> ECHEC | O6: =IF(R6=0,0,VLOOKUP($A6,[6]HISTOFEV24!$A$6:$AV$49,32,0)) -> 0 | P6: =VLOOKUP($A6,[6]HISTOFEV24!$A$6:$AV$49,33,0) -> 0 | Q6: =IF(R6=0,0,($C$3-R6)) -> 0 | R6: =VLOOKUP($A6,[6]HISTOFEV24!$A$6:$AV$49,29,0) -> 0
A7: AS201602 | B7: =IF(D7=0,0,VLOOKUP($A7,[6]HISTOFEV24!$A$6:$BP$44,10,0)) -> 1 | C7: =VLOOKUP(A7,[7]LISTADHERENT!A$5:H$60,3,0) -> BOUTCHOUANG WILLIAM | D7: =IF(G7="ECHEC",0,B$3) -> 25000 | E7: =D7+VLOOKUP($A7,[6]HISTOFEV24!$A$7:$AU$42,45,0)+F7 -> 50000 | F7: =VLOOKUP($A7,[6]HISTOFEV24!$A$6:$AV$48,7,0) -> 3000 | G7: =VLOOKUP($A7,[6]HISTOFEV24!$A$6:$AV$49,8,0) -> BANQUE | H7: =VLOOKUP($A7,[6]HISTOFEV24!$A$6:$AV$49,35,0) -> 0 | I7: =VLOOKUP($A7,[6]HISTOFEV24!$A$6:$AV$49,38,0) -> 0 | J7: =IF(H7=0,0,VLOOKUP($A7,[6]HISTOFEV24!$A$6:$AV$49,42,0)) -> 0 | K7: =VLOOKUP($A7,[6]HISTOFEV24!$A$6:$AV$49,41,0) -> 0 | L7: =TONTJANV24!H7+TONTJANV24!I7 -> 0 | M7: =VLOOKUP($A7,[6]HISTOFEV24!$A$6:$AV$49,16,0) -> 0 | N7: =IF(M7<>0,VLOOKUP($A7,[6]HISTOFEV24!$A$6:$AV$49,8,0),"ECHEC") -> ECHEC | O7: =IF(R7=0,0,VLOOKUP($A7,[6]HISTOFEV24!$A$6:$AV$49,32,0)) -> 0 | P7: =VLOOKUP($A7,[6]HISTOFEV24!$A$6:$AV$49,33,0) -> 0 | Q7: =IF(R7=0,0,($C$3-R7)) -> 0 | R7: =VLOOKUP($A7,[6]HISTOFEV24!$A$6:$AV$49,29,0) -> 0
A8: AS201604 | B8: =IF(D8=0,0,VLOOKUP($A8,[6]HISTOFEV24!$A$6:$BP$44,10,0)) -> 1 | C8: =VLOOKUP(A8,[7]LISTADHERENT!A$5:H$60,3,0) -> DJOMO JEAN PAUL | D8: =IF(G8="ECHEC",0,B$3) -> 25000 | E8: =D8+VLOOKUP($A8,[6]HISTOFEV24!$A$7:$AU$42,45,0)+F8 -> 50000 | F8: =VLOOKUP($A8,[6]HISTOFEV24!$A$6:$AV$48,7,0) -> 0 | G8: =VLOOKUP($A8,[6]HISTOFEV24!$A$6:$AV$49,8,0) -> BANQUE | H8: =VLOOKUP($A8,[6]HISTOFEV24!$A$6:$AV$49,35,0) -> 0 | I8: =VLOOKUP($A8,[6]HISTOFEV24!$A$6:$AV$49,38,0) -> 0 | J8: =IF(H8=0,0,VLOOKUP($A8,[6]HISTOFEV24!$A$6:$AV$49,42,0)) -> 0 | K8: =VLOOKUP($A8,[6]HISTOFEV24!$A$6:$AV$49,41,0) -> 0 | L8: =TONTJANV24!H8+TONTJANV24!I8 -> 0 | M8: =VLOOKUP($A8,[6]HISTOFEV24!$A$6:$AV$49,16,0) -> 0 | N8: =IF(M8<>0,VLOOKUP($A8,[6]HISTOFEV24!$A$6:$AV$49,8,0),"ECHEC") -> ECHEC | O8: =IF(R8=0,0,VLOOKUP($A8,[6]HISTOFEV24!$A$6:$AV$49,32,0)) -> 0 | P8: =VLOOKUP($A8,[6]HISTOFEV24!$A$6:$AV$49,33,0) -> 0 | Q8: =IF(R8=0,0,($C$3-R8)) -> 0 | R8: =VLOOKUP($A8,[6]HISTOFEV24!$A$6:$AV$49,29,0) -> 0
A9: AS201654 | B9: =IF(D9=0,0,VLOOKUP($A9,[6]HISTOFEV24!$A$6:$BP$44,10,0)) -> 1 | C9: =VLOOKUP(A9,[7]LISTADHERENT!A$5:H$60,3,0) -> DJOMOU TCHAPDA | D9: =IF(G9="ECHEC",0,B$3) -> 25000 | E9: =D9+VLOOKUP($A9,[6]HISTOFEV24!$A$7:$AU$42,45,0)+F9 -> 53000 | F9: =VLOOKUP($A9,[6]HISTOFEV24!$A$6:$AV$48,7,0) -> 3000 | G9: =VLOOKUP($A9,[6]HISTOFEV24!$A$6:$AV$49,8,0) -> BANQUE | H9: =VLOOKUP($A9,[6]HISTOFEV24!$A$6:$AV$49,35,0) -> 60000 | I9: =VLOOKUP($A9,[6]HISTOFEV24!$A$6:$AV$49,38,0) -> 1000 | J9: =IF(H9=0,0,VLOOKUP($A9,[6]HISTOFEV24!$A$6:$AV$49,42,0)) -> BANQUE | K9: =VLOOKUP($A9,[6]HISTOFEV24!$A$6:$AV$49,41,0) -> 0 | L9: =TONTJANV24!H9+TONTJANV24!I9 -> 0 | M9: =VLOOKUP($A9,[6]HISTOFEV24!$A$6:$AV$49,16,0) -> 0 | N9: =IF(M9<>0,VLOOKUP($A9,[6]HISTOFEV24!$A$6:$AV$49,8,0),"ECHEC") -> ECHEC | O9: =IF(R9=0,0,VLOOKUP($A9,[6]HISTOFEV24!$A$6:$AV$49,32,0)) -> 0 | P9: =VLOOKUP($A9,[6]HISTOFEV24!$A$6:$AV$49,33,0) -> 0 | Q9: =IF(R9=0,0,($C$3-R9)) -> 0 | R9: =VLOOKUP($A9,[6]HISTOFEV24!$A$6:$AV$49,29,0) -> 0
A10: AS201605 | B10: =IF(D10=0,0,VLOOKUP($A10,[6]HISTOFEV24!$A$6:$BP$44,10,0)) -> 1 | C10: =VLOOKUP(A10,[7]LISTADHERENT!A$5:H$60,3,0) -> DJOUKWE NANGUEN GUY BLAISE | D10: =IF(G10="ECHEC",0,B$3) -> 25000 | E10: =D10+VLOOKUP($A10,[6]HISTOFEV24!$A$7:$AU$42,45,0)+F10 -> 50000 | F10: =VLOOKUP($A10,[6]HISTOFEV24!$A$6:$AV$48,7,0) -> 0 | G10: =VLOOKUP($A10,[6]HISTOFEV24!$A$6:$AV$49,8,0) -> BANQUE | H10: =VLOOKUP($A10,[6]HISTOFEV24!$A$6:$AV$49,35,0) -> 0 | I10: =VLOOKUP($A10,[6]HISTOFEV24!$A$6:$AV$49,38,0) -> 0 | J10: =IF(H10=0,0,VLOOKUP($A10,[6]HISTOFEV24!$A$6:$AV$49,42,0)) -> 0 | K10: =VLOOKUP($A10,[6]HISTOFEV24!$A$6:$AV$49,41,0) -> 0 | L10: =TONTJANV24!H10+TONTJANV24!I10 -> 0 | M10: =VLOOKUP($A10,[6]HISTOFEV24!$A$6:$AV$49,16,0) -> 0 | N10: =IF(M10<>0,VLOOKUP($A10,[6]HISTOFEV24!$A$6:$AV$49,8,0),"ECHEC") -> ECHEC | O10: =IF(R10=0,0,VLOOKUP($A10,[6]HISTOFEV24!$A$6:$AV$49,32,0)) -> BANQUE | P10: =VLOOKUP($A10,[6]HISTOFEV24!$A$6:$AV$49,33,0) -> 0 | Q10: =IF(R10=0,0,($C$3-R10)) -> 284000 | R10: =VLOOKUP($A10,[6]HISTOFEV24!$A$6:$AV$49,29,0) -> 16000
A11: AS201608 | B11: =IF(D11=0,0,VLOOKUP($A11,[6]HISTOFEV24!$A$6:$BP$44,10,0)) -> 1 | C11: =VLOOKUP(A11,[7]LISTADHERENT!A$5:H$60,3,0) -> DJUOMBESSY ANTOINE | D11: =IF(G11="ECHEC",0,B$3) -> 25000 | E11: =D11+VLOOKUP($A11,[6]HISTOFEV24!$A$7:$AU$42,45,0)+F11 -> 55000 | F11: =VLOOKUP($A11,[6]HISTOFEV24!$A$6:$AV$48,7,0) -> 0 | G11: =VLOOKUP($A11,[6]HISTOFEV24!$A$6:$AV$49,8,0) -> BANQUE | H11: =VLOOKUP($A11,[6]HISTOFEV24!$A$6:$AV$49,35,0) -> 0 | I11: =VLOOKUP($A11,[6]HISTOFEV24!$A$6:$AV$49,38,0) -> 0 | J11: =IF(H11=0,0,VLOOKUP($A11,[6]HISTOFEV24!$A$6:$AV$49,42,0)) -> 0 | K11: =VLOOKUP($A11,[6]HISTOFEV24!$A$6:$AV$49,41,0) -> 0 | L11: =TONTJANV24!H11+TONTJANV24!I11 -> 0 | M11: =VLOOKUP($A11,[6]HISTOFEV24!$A$6:$AV$49,16,0) -> 0 | N11: =IF(M11<>0,VLOOKUP($A11,[6]HISTOFEV24!$A$6:$AV$49,8,0),"ECHEC") -> ECHEC | O11: =IF(R11=0,0,VLOOKUP($A11,[6]HISTOFEV24!$A$6:$AV$49,32,0)) -> 0 | P11: =VLOOKUP($A11,[6]HISTOFEV24!$A$6:$AV$49,33,0) -> 0 | Q11: =IF(R11=0,0,($C$3-R11)) -> 0 | R11: =VLOOKUP($A11,[6]HISTOFEV24!$A$6:$AV$49,29,0) -> 0
A12: AS201651 | B12: =IF(D12=0,0,VLOOKUP($A12,[6]HISTOFEV24!$A$6:$BP$44,10,0)) -> 1 | C12: =VLOOKUP(A12,[7]LISTADHERENT!A$5:H$60,3,0) -> DOMOU FABIEN | D12: =IF(G12="ECHEC",0,B$3) -> 25000 | E12: =D12+VLOOKUP($A12,[6]HISTOFEV24!$A$7:$AU$42,45,0)+F12 -> 50000 | F12: =VLOOKUP($A12,[6]HISTOFEV24!$A$6:$AV$48,7,0) -> 0 | G12: =VLOOKUP($A12,[6]HISTOFEV24!$A$6:$AV$49,8,0) -> BANQUE | H12: =VLOOKUP($A12,[6]HISTOFEV24!$A$6:$AV$49,35,0) -> 0 | I12: =VLOOKUP($A12,[6]HISTOFEV24!$A$6:$AV$49,38,0) -> 0 | J12: =IF(H12=0,0,VLOOKUP($A12,[6]HISTOFEV24!$A$6:$AV$49,42,0)) -> 0 | K12: =VLOOKUP($A12,[6]HISTOFEV24!$A$6:$AV$49,41,0) -> 0 | L12: =TONTJANV24!H12+TONTJANV24!I12 -> 0 | M12: =VLOOKUP($A12,[6]HISTOFEV24!$A$6:$AV$49,16,0) -> 0 | N12: =IF(M12<>0,VLOOKUP($A12,[6]HISTOFEV24!$A$6:$AV$49,8,0),"ECHEC") -> ECHEC | O12: =IF(R12=0,0,VLOOKUP($A12,[6]HISTOFEV24!$A$6:$AV$49,32,0)) -> 0 | P12: =VLOOKUP($A12,[6]HISTOFEV24!$A$6:$AV$49,33,0) -> 0 | Q12: =IF(R12=0,0,($C$3-R12)) -> 0 | R12: =VLOOKUP($A12,[6]HISTOFEV24!$A$6:$AV$49,29,0) -> 0
A13: AS201609 | B13: =IF(D13=0,0,VLOOKUP($A13,[6]HISTOFEV24!$A$6:$BP$44,10,0)) -> 1 | C13: =VLOOKUP(A13,[7]LISTADHERENT!A$5:H$60,3,0) -> DONHOU DAVID | D13: =IF(G13="ECHEC",0,B$3) -> 25000 | E13: =D13+VLOOKUP($A13,[6]HISTOFEV24!$A$7:$AU$42,45,0)+F13 -> 50000 | F13: =VLOOKUP($A13,[6]HISTOFEV24!$A$6:$AV$48,7,0) -> 0 | G13: =VLOOKUP($A13,[6]HISTOFEV24!$A$6:$AV$49,8,0) -> BANQUE | H13: =VLOOKUP($A13,[6]HISTOFEV24!$A$6:$AV$49,35,0) -> 0 | I13: =VLOOKUP($A13,[6]HISTOFEV24!$A$6:$AV$49,38,0) -> 0 | J13: =IF(H13=0,0,VLOOKUP($A13,[6]HISTOFEV24!$A$6:$AV$49,42,0)) -> 0 | K13: =VLOOKUP($A13,[6]HISTOFEV24!$A$6:$AV$49,41,0) -> 0 | L13: =TONTJANV24!H13+TONTJANV24!I13 -> 0 | M13: =VLOOKUP($A13,[6]HISTOFEV24!$A$6:$AV$49,16,0) -> 0 | N13: =IF(M13<>0,VLOOKUP($A13,[6]HISTOFEV24!$A$6:$AV$49,8,0),"ECHEC") -> ECHEC | O13: =IF(R13=0,0,VLOOKUP($A13,[6]HISTOFEV24!$A$6:$AV$49,32,0)) -> 0 | P13: =VLOOKUP($A13,[6]HISTOFEV24!$A$6:$AV$49,33,0) -> 0 | Q13: =IF(R13=0,0,($C$3-R13)) -> 0 | R13: =VLOOKUP($A13,[6]HISTOFEV24!$A$6:$AV$49,29,0) -> 0
A14: AS201611 | B14: =IF(D14=0,0,VLOOKUP($A14,[6]HISTOFEV24!$A$6:$BP$44,10,0)) -> 1 | C14: =VLOOKUP(A14,[7]LISTADHERENT!A$5:H$60,3,0) -> HENGUE PAUL OMER | D14: =IF(G14="ECHEC",0,B$3) -> 25000 | E14: =D14+VLOOKUP($A14,[6]HISTOFEV24!$A$7:$AU$42,45,0)+F14 -> 50000 | F14: =VLOOKUP($A14,[6]HISTOFEV24!$A$6:$AV$48,7,0) -> 0 | G14: =VLOOKUP($A14,[6]HISTOFEV24!$A$6:$AV$49,8,0) -> BANQUE | H14: =VLOOKUP($A14,[6]HISTOFEV24!$A$6:$AV$49,35,0) -> 0 | I14: =VLOOKUP($A14,[6]HISTOFEV24!$A$6:$AV$49,38,0) -> 0 | J14: =IF(H14=0,0,VLOOKUP($A14,[6]HISTOFEV24!$A$6:$AV$49,42,0)) -> 0 | K14: =VLOOKUP($A14,[6]HISTOFEV24!$A$6:$AV$49,41,0) -> 0 | L14: =TONTJANV24!H14+TONTJANV24!I14 -> 0 | M14: =VLOOKUP($A14,[6]HISTOFEV24!$A$6:$AV$49,16,0) -> 0 | N14: =IF(M14<>0,VLOOKUP($A14,[6]HISTOFEV24!$A$6:$AV$49,8,0),"ECHEC") -> ECHEC | O14: =IF(R14=0,0,VLOOKUP($A14,[6]HISTOFEV24!$A$6:$AV$49,32,0)) -> 0 | P14: =VLOOKUP($A14,[6]HISTOFEV24!$A$6:$AV$49,33,0) -> 0 | Q14: =IF(R14=0,0,($C$3-R14)) -> 0 | R14: =VLOOKUP($A14,[6]HISTOFEV24!$A$6:$AV$49,29,0) -> 0
A15: AS201613 | B15: =IF(D15=0,0,VLOOKUP($A15,[6]HISTOFEV24!$A$6:$BP$44,10,0)) -> 1 | C15: =VLOOKUP(A15,[7]LISTADHERENT!A$5:H$60,3,0) -> HOTCHO BENJAMIN | D15: =IF(G15="ECHEC",0,B$3) -> 25000 | E15: =D15+VLOOKUP($A15,[6]HISTOFEV24!$A$7:$AU$42,45,0)+F15 -> 85000 | F15: =VLOOKUP($A15,[6]HISTOFEV24!$A$6:$AV$48,7,0) -> 0 | G15: =VLOOKUP($A15,[6]HISTOFEV24!$A$6:$AV$49,8,0) -> BANQUE | H15: =VLOOKUP($A15,[6]HISTOFEV24!$A$6:$AV$49,35,0) -> 0 | I15: =VLOOKUP($A15,[6]HISTOFEV24!$A$6:$AV$49,38,0) -> 0 | J15: =IF(H15=0,0,VLOOKUP($A15,[6]HISTOFEV24!$A$6:$AV$49,42,0)) -> 0 | K15: =VLOOKUP($A15,[6]HISTOFEV24!$A$6:$AV$49,41,0) -> 0 | L15: =TONTJANV24!H15+TONTJANV24!I15 -> 0 | M15: =VLOOKUP($A15,[6]HISTOFEV24!$A$6:$AV$49,16,0) -> 0 | N15: =IF(M15<>0,VLOOKUP($A15,[6]HISTOFEV24!$A$6:$AV$49,8,0),"ECHEC") -> ECHEC | O15: =IF(R15=0,0,VLOOKUP($A15,[6]HISTOFEV24!$A$6:$AV$49,32,0)) -> 0 | P15: =VLOOKUP($A15,[6]HISTOFEV24!$A$6:$AV$49,33,0) -> 0 | Q15: =IF(R15=0,0,($C$3-R15)) -> 0 | R15: =VLOOKUP($A15,[6]HISTOFEV24!$A$6:$AV$49,29,0) -> 0
A16: AS201617 | B16: =IF(D16=0,0,VLOOKUP($A16,[6]HISTOFEV24!$A$6:$BP$44,10,0)) -> 1 | C16: =VLOOKUP(A16,[7]LISTADHERENT!A$5:H$60,3,0) -> KOUAMOU MOISE | D16: =IF(G16="ECHEC",0,B$3) -> 25000 | E16: =D16+VLOOKUP($A16,[6]HISTOFEV24!$A$7:$AU$42,45,0)+F16 -> 50000 | F16: =VLOOKUP($A16,[6]HISTOFEV24!$A$6:$AV$48,7,0) -> 0 | G16: =VLOOKUP($A16,[6]HISTOFEV24!$A$6:$AV$49,8,0) -> BANQUE | H16: =VLOOKUP($A16,[6]HISTOFEV24!$A$6:$AV$49,35,0) -> 0 | I16: =VLOOKUP($A16,[6]HISTOFEV24!$A$6:$AV$49,38,0) -> 0 | J16: =IF(H16=0,0,VLOOKUP($A16,[6]HISTOFEV24!$A$6:$AV$49,42,0)) -> 0 | K16: =VLOOKUP($A16,[6]HISTOFEV24!$A$6:$AV$49,41,0) -> 0 | L16: =TONTJANV24!H16+TONTJANV24!I16 -> 0 | M16: =VLOOKUP($A16,[6]HISTOFEV24!$A$6:$AV$49,16,0) -> 0 | N16: =IF(M16<>0,VLOOKUP($A16,[6]HISTOFEV24!$A$6:$AV$49,8,0),"ECHEC") -> ECHEC | O16: =IF(R16=0,0,VLOOKUP($A16,[6]HISTOFEV24!$A$6:$AV$49,32,0)) -> BANQUE | P16: =VLOOKUP($A16,[6]HISTOFEV24!$A$6:$AV$49,33,0) -> 0 | Q16: =IF(R16=0,0,($C$3-R16)) -> 283000 | R16: =VLOOKUP($A16,[6]HISTOFEV24!$A$6:$AV$49,29,0) -> 17000
A17: AS201619 | B17: =IF(D17=0,0,VLOOKUP($A17,[6]HISTOFEV24!$A$6:$BP$44,10,0)) -> 1 | C17: =VLOOKUP(A17,[7]LISTADHERENT!A$5:H$60,3,0) -> KOUATCHO MESSACK | D17: =IF(G17="ECHEC",0,B$3) -> 25000 | E17: =D17+VLOOKUP($A17,[6]HISTOFEV24!$A$7:$AU$42,45,0)+F17 -> 60000 | F17: =VLOOKUP($A17,[6]HISTOFEV24!$A$6:$AV$48,7,0) -> 0 | G17: =VLOOKUP($A17,[6]HISTOFEV24!$A$6:$AV$49,8,0) -> BANQUE | H17: =VLOOKUP($A17,[6]HISTOFEV24!$A$6:$AV$49,35,0) -> 0 | I17: =VLOOKUP($A17,[6]HISTOFEV24!$A$6:$AV$49,38,0) -> 0 | J17: =IF(H17=0,0,VLOOKUP($A17,[6]HISTOFEV24!$A$6:$AV$49,42,0)) -> 0 | K17: =VLOOKUP($A17,[6]HISTOFEV24!$A$6:$AV$49,41,0) -> 0 | L17: =TONTJANV24!H17+TONTJANV24!I17 -> 0 | M17: =VLOOKUP($A17,[6]HISTOFEV24!$A$6:$AV$49,16,0) -> 0 | N17: =IF(M17<>0,VLOOKUP($A17,[6]HISTOFEV24!$A$6:$AV$49,8,0),"ECHEC") -> ECHEC | O17: =IF(R17=0,0,VLOOKUP($A17,[6]HISTOFEV24!$A$6:$AV$49,32,0)) -> 0 | P17: =VLOOKUP($A17,[6]HISTOFEV24!$A$6:$AV$49,33,0) -> 0 | Q17: =IF(R17=0,0,($C$3-R17)) -> 0 | R17: =VLOOKUP($A17,[6]HISTOFEV24!$A$6:$AV$49,29,0) -> 0
... A37: AS201647 | B37: =IF(D37=0,0,VLOOKUP($A37,[6]HISTOFEV24!$A$6:$BP$44,10,0)) -> 1 | C37: =VLOOKUP(A37,[7]LISTADHERENT!A$5:H$60,3,0) -> YOUMBI EMMANUEL | D37: =IF(G37="ECHEC",0,B$3) -> 25000 | E37: =D37+VLOOKUP($A37,[6]HISTOFEV24!$A$7:$AU$42,45,0)+F37 -> 50000 | F37: =VLOOKUP($A37,[6]HISTOFEV24!$A$6:$AV$48,7,0) -> 0 | G37: =VLOOKUP($A37,[6]HISTOFEV24!$A$6:$AV$49,8,0) -> BANQUE | H37: =VLOOKUP($A37,[6]HISTOFEV24!$A$6:$AV$49,35,0) -> 0 | I37: =VLOOKUP($A37,[6]HISTOFEV24!$A$6:$AV$49,38,0) -> 0 | J37: =IF(H37=0,0,VLOOKUP($A37,[6]HISTOFEV24!$A$6:$AV$49,42,0)) -> 0 | K37: =VLOOKUP($A37,[6]HISTOFEV24!$A$6:$AV$49,41,0) -> 0 | L37: =TONTJANV24!H37+TONTJANV24!I37 -> 0 | M37: =VLOOKUP($A37,[6]HISTOFEV24!$A$6:$AV$49,16,0) -> 0 | N37: =IF(M37<>0,VLOOKUP($A37,[6]HISTOFEV24!$A$6:$AV$49,8,0),"ECHEC") -> ECHEC | O37: =IF(R37=0,0,VLOOKUP($A37,[6]HISTOFEV24!$A$6:$AV$49,32,0)) -> 0 | P37: =VLOOKUP($A37,[6]HISTOFEV24!$A$6:$AV$49,33,0) -> 0 | Q37: =IF(R37=0,0,($C$3-R37)) -> 0 | R37: =VLOOKUP($A37,[6]HISTOFEV24!$A$6:$AV$49,29,0) -> 0
A39: TOTAL PART | B39: =SUM(B6:B38) -> 32
A40: NBRE ADHERENT | B40: =COUNT(D6:D38) -> 32 | D40: =SUM(D6:D39) -> 800000 | F40: =SUM(F6:F39) -> 9000 | G40: =SUM(G6:G39) -> 0 | H40: =SUM(H6:H39) -> 171000 | I40: =SUM(I6:I39) -> 3000 | J40: =SUM(J6:J39) -> 0 | K40: =SUM(K6:K39) -> 0 | L40: =SUM(L6:L39) -> 0 | M40: =SUM(M6:M39) -> 0 | ... R40: =SUM(R6:R39) -> 33000
N41: NBRE PART | O41: PART VENDUE
D42: MONTANT TONTINE | G42: REMBOURSEMENT PETIT LOT | H42: VENTE PETIT LOT | I42: VENTE LOT PRINCIPAL | J42: SOLDE EN CAISSE | L42: TONTINE + REMB + INTERET VENTE | M42: =D46+G46+R40+TONTJANV24!O47 -> 771000
D43: =SUMIFS(D6:D39,G6:G39,"ESPECES") -> 25000 | F43: ESPECES | G43: =SUMIFS(M6:M33,N6:N33,"ESPECES") -> 0 | H43: =SUMIFS(H6:H39,J6:J39,"ESPECES") -> 0 | I43: =SUMIFS(Q6:Q39,O6:O39,"ESPECES") -> 0 | J43: =D43+G43-H43-I43 -> 25000 | L43: LOT PRINCIPAL | M43: =C3*COUNTIF(Q7:Q39,">0") -> 600000 | N43: =D3 -> 2 | O43: =COUNTIF(Q7:Q33,">0") -> 2
D44: =SUMIFS(D6:D39,G6:G39,"BANQUE") -> 775000 | F44: BANQUE | G44: =SUMIFS(M6:M33,N6:N33,"BANQUE") -> 0 | H44: =SUMIFS(H6:H39,J6:J39,"BANQUE") -> 60000 | I44: =SUMIFS(Q6:Q39,O6:O39,"BANQUE") -> 567000 | J44: =D44+G44-H44-I44 -> 148000
L45: PETIT LOT | M45: =M42-M43 -> 171000
D46: =D43+D44 -> 800000 | F46: TOTAL | G46: =G43+G44 -> 0 | H46: =H43+H44 -> 60000 | I46: =I43+I44 -> 567000 | J46: =J43+J44 -> 173000
F47: TOTAL+DEPOT | L47: RELIQUAT | M47: =M45-H40 -> 0 | O47: =TONTFEV24!M47 -> 0 | P47: CUMUL
L49: ECHEC TONTINE MOIS | M49: =COUNTIFS(G7:G38,"ECHEC")*23000 -> 0 | O49: =TONTFEV24!M49 -> 0 | P49: CUMUL
L50: ECHEC REMBOURSEMENT MOIS | M50: =L40-G46 -> 0 | O50: =TONTFEV24!M50 -> 0 | P50: CUMUL

Sheet TONTMARS24
A1: ASSOCIATION | B1: ASELBY
A2: ANNEE | B2: 2024 | C2: TONIINE | D2: NBRE PART
A3: TAUX TONTINE | B3: 25000 | C3: =B3*12 -> 300000 | D3: =ROUNDDOWN(M42/C3,0) -> 3
C4: 45364
A5: MATRICULE | B5: NBREPART | C5: NOM ET PRENOM | D5: MONTANT TONTINE | E5: MONTANT VERSE | F5: PENALITE VERSEMENT ESPECES | G5: MODE VERSEMENT | H5: VENTE PETIT LOT | I5: INTERET PETIT LOT | J5: MODE VERSEMENT VENTE PETIT LOT | K5: NUMERO CHEQUE | L5: MONTANT A REMBOURSER PETIT LOT | M5: REMBOURSEMENT PETIT LOT | N5: MODE VERSEMENT REMBOURSEMENT | O5: MODE VERSEMENTLOT PRINCIPAL | P5: NUMERO CHEQUE | Q5: MONTANT LOT PRINCIPAL | R5: INTERET LOT PRINCIPAL
A6: AS201601 | B6: =IF(D6=0,0,VLOOKUP($A6,[6]HISTOMARS24!$A$6:$BP$44,10,0)) -> 1 | C6: =VLOOKUP(A6,[7]LISTADHERENT!A$5:H$60,3,0) -> BAKOP ACHILLE | D6: =IF(G6="ECHEC",0,B$3) -> 25000 | E6: =D6+VLOOKUP($A6,[6]HISTOMARS24!$A$7:$AU$42,45,0)+F6 -> 72000 | F6: =VLOOKUP($A6,[6]HISTOMARS24!$A$6:$AV$48,7,0) -> 0 | G6: =VLOOKUP($A6,[6]HISTOMARS24!$A$6:$AV$49,8,0) -> BANQUE | H6: =VLOOKUP($A6,[6]HISTOMARS24!$A$6:$AV$49,35,0) -> 0 | I6: =VLOOKUP($A6,[6]HISTOMARS24!$A$6:$AV$49,38,0) -> 0 | J6: =IF(H6=0,0,VLOOKUP($A6,[6]HISTOMARS24!$A$6:$AV$49,42,0)) -> 0 | K6: =VLOOKUP($A6,[6]HISTOMARS24!$A$6:$AV$49,41,0) -> 0 | L6: =TONTFEV24!H6+TONTFEV24!I6 -> 61000 | M6: =VLOOKUP($A6,[6]HISTOMARS24!$A$6:$AV$49,16,0) -> 61000 | N6: =IF(M6<>0,VLOOKUP($A6,[6]HISTOMARS24!$A$6:$AV$49,8,0),"ECHEC") -> BANQUE | O6: =IF(R6=0,0,VLOOKUP($A6,[6]HISTOMARS24!$A$6:$AV$49,32,0)) -> BANQUE | P6: =VLOOKUP($A6,[6]HISTOMARS24!$A$6:$AV$49,33,0) -> 0 | Q6: =IF(R6=0,0,($C$3-R6)) -> 290000 | R6: =VLOOKUP($A6,[6]HISTOMARS24!$A$6:$AV$49,29,0) -> 10000
A7: AS201602 | B7: =IF(D7=0,0,VLOOKUP($A7,[6]HISTOMARS24!$A$6:$BP$44,10,0)) -> 1 | C7: =VLOOKUP(A7,[7]LISTADHERENT!A$5:H$60,3,0) -> BOUTCHOUANG WILLIAM | D7: =IF(G7="ECHEC",0,B$3) -> 25000 | E7: =D7+VLOOKUP($A7,[6]HISTOMARS24!$A$7:$AU$42,45,0)+F7 -> 50000 | F7: =VLOOKUP($A7,[6]HISTOMARS24!$A$6:$AV$48,7,0) -> 0 | G7: =VLOOKUP($A7,[6]HISTOMARS24!$A$6:$AV$49,8,0) -> BANQUE | H7: =VLOOKUP($A7,[6]HISTOMARS24!$A$6:$AV$49,35,0) -> 0 | I7: =VLOOKUP($A7,[6]HISTOMARS24!$A$6:$AV$49,38,0) -> 0 | J7: =IF(H7=0,0,VLOOKUP($A7,[6]HISTOMARS24!$A$6:$AV$49,42,0)) -> 0 | K7: =VLOOKUP($A7,[6]HISTOMARS24!$A$6:$AV$49,41,0) -> 0 | L7: =TONTFEV24!H7+TONTFEV24!I7 -> 0 | M7: =VLOOKUP($A7,[6]HISTOMARS24!$A$6:$AV$49,16,0) -> 0 | N7: =IF(M7<>0,VLOOKUP($A7,[6]HISTOMARS24!$A$6:$AV$49,8,0),"ECHEC") -> ECHEC | O7: =IF(R7=0,0,VLOOKUP($A7,[6]HISTOMARS24!$A$6:$AV$49,32,0)) -> 0 | P7: =VLOOKUP($A7,[6]HISTOMARS24!$A$6:$AV$49,33,0) -> 0 | Q7: =IF(R7=0,0,($C$3-R7)) -> 0 | R7: =VLOOKUP($A7,[6]HISTOMARS24!$A$6:$AV$49,29,0) -> 0
A8: AS201604 | B8: =IF(D8=0,0,VLOOKUP($A8,[6]HISTOMARS24!$A$6:$BP$44,10,0)) -> 1 | C8: =VLOOKUP(A8,[7]LISTADHERENT!A$5:H$60,3,0) -> DJOMO JEAN PAUL | D8: =IF(G8="ECHEC",0,B$3) -> 25000 | E8: =D8+VLOOKUP($A8,[6]HISTOMARS24!$A$7:$AU$42,45,0)+F8 -> 50000 | F8: =VLOOKUP($A8,[6]HISTOMARS24!$A$6:$AV$48,7,0) -> 0 | G8: =VLOOKUP($A8,[6]HISTOMARS24!$A$6:$AV$49,8,0) -> BANQUE | H8: =VLOOKUP($A8,[6]HISTOMARS24!$A$6:$AV$49,35,0) -> 0 | I8: =VLOOKUP($A8,[6]HISTOMARS24!$A$6:$AV$49,38,0) -> 0 | J8: =IF(H8=0,0,VLOOKUP($A8,[6]HISTOMARS24!$A$6:$AV$49,42,0)) -> 0 | K8: =VLOOKUP($A8,[6]HISTOMARS24!$A$6:$AV$49,41,0) -> 0 | L8: =TONTFEV24!H8+TONTFEV24!I8 -> 0 | M8: =VLOOKUP($A8,[6]HISTOMARS24!$A$6:$AV$49,16,0) -> 0 | N8: =IF(M8<>0,VLOOKUP($A8,[6]HISTOMARS24!$A$6:$AV$49,8,0),"ECHEC") -> ECHEC | O8: =IF(R8=0,0,VLOOKUP($A8,[6]HISTOMARS24!$A$6:$AV$49,32,0)) -> BANQUE | P8: =VLOOKUP($A8,[6]HISTOMARS24!$A$6:$AV$49,33,0) -> 0 | Q8: =IF(R8=0,0,($C$3-R8)) -> 282000 | R8: =VLOOKUP($A8,[6]HISTOMARS24!$A$6:$AV$49,29,0) -> 18000
A9: AS201654 | B9: =IF(D9=0,0,VLOOKUP($A9,[6]HISTOMARS24!$A$6:$BP$44,10,0)) -> 1 | C9: =VLOOKUP(A9,[7]LISTADHERENT!A$5:H$60,3,0) -> DJOMOU TCHAPDA | D9: =IF(G9="ECHEC",0,B$3) -> 25000 | E9: =D9+VLOOKUP($A9,[6]HISTOMARS24!$A$7:$AU$42,45,0)+F9 -> 44000 | F9: =VLOOKUP($A9,[6]HISTOMARS24!$A$6:$AV$48,7,0) -> 0 | G9: =VLOOKUP($A9,[6]HISTOMARS24!$A$6:$AV$49,8,0) -> BANQUE | H9: =VLOOKUP($A9,[6]HISTOMARS24!$A$6:$AV$49,35,0) -> 39000 | I9: =VLOOKUP($A9,[6]HISTOMARS24!$A$6:$AV$49,38,0) -> 1000 | J9: =IF(H9=0,0,VLOOKUP($A9,[6]HISTOMARS24!$A$6:$AV$49,42,0)) -> BANQUE | K9: =VLOOKUP($A9,[6]HISTOMARS24!$A$6:$AV$49,41,0) -> 0 | L9: =TONTFEV24!H9+TONTFEV24!I9 -> 61000 | M9: =VLOOKUP($A9,[6]HISTOMARS24!$A$6:$AV$49,16,0) -> 61000 | N9: =IF(M9<>0,VLOOKUP($A9,[6]HISTOMARS24!$A$6:$AV$49,8,0),"ECHEC") -> BANQUE | O9: =IF(R9=0,0,VLOOKUP($A9,[6]HISTOMARS24!$A$6:$AV$49,32,0)) -> 0 | P9: =VLOOKUP($A9,[6]HISTOMARS24!$A$6:$AV$49,33,0) -> 0 | Q9: =IF(R9=0,0,($C$3-R9)) -> 0 | R9: =VLOOKUP($A9,[6]HISTOMARS24!$A$6:$AV$49,29,0) -> 0
A10: AS201605 | B10: =IF(D10=0,0,VLOOKUP($A10,[6]HISTOMARS24!$A$6:$BP$44,10,0)) -> 1 | C10: =VLOOKUP(A10,[7]LISTADHERENT!A$5:H$60,3,0) -> DJOUKWE NANGUEN GUY BLAISE | D10: =IF(G10="ECHEC",0,B$3) -> 25000 | E10: =D10+VLOOKUP($A10,[6]HISTOMARS24!$A$7:$AU$42,45,0)+F10 -> 50000 | F10: =VLOOKUP($A10,[6]HISTOMARS24!$A$6:$AV$48,7,0) -> 0 | G10: =VLOOKUP($A10,[6]HISTOMARS24!$A$6:$AV$49,8,0) -> BANQUE | H10: =VLOOKUP($A10,[6]HISTOMARS24!$A$6:$AV$49,35,0) -> 40000 | I10: =VLOOKUP($A10,[6]HISTOMARS24!$A$6:$AV$49,38,0) -> 1000 | J10: =IF(H10=0,0,VLOOKUP($A10,[6]HISTOMARS24!$A$6:$AV$49,42,0)) -> BANQUE | K10: =VLOOKUP($A10,[6]HISTOMARS24!$A$6:$AV$49,41,0) -> 0 | L10: =TONTFEV24!H10+TONTFEV24!I10 -> 0 | M10: =VLOOKUP($A10,[6]HISTOMARS24!$A$6:$AV$49,16,0) -> 0 | N10: =IF(M10<>0,VLOOKUP($A10,[6]HISTOMARS24!$A$6:$AV$49,8,0),"ECHEC") -> ECHEC | O10: =IF(R10=0,0,VLOOKUP($A10,[6]HISTOMARS24!$A$6:$AV$49,32,0)) -> 0 | P10: =VLOOKUP($A10,[6]HISTOMARS24!$A$6:$AV$49,33,0) -> 0 | Q10: =IF(R10=0,0,($C$3-R10)) -> 0 | R10: =VLOOKUP($A10,[6]HISTOMARS24!$A$6:$AV$49,29,0) -> 0
A11: AS201608 | B11: =IF(D11=0,0,VLOOKUP($A11,[6]HISTOMARS24!$A$6:$BP$44,10,0)) -> 1 | C11: =VLOOKUP(A11,[7]LISTADHERENT!A$5:H$60,3,0) -> DJUOMBESSY ANTOINE | D11: =IF(G11="ECHEC",0,B$3) -> 25000 | E11: =D11+VLOOKUP($A11,[6]HISTOMARS24!$A$7:$AU$42,45,0)+F11 -> 55000 | F11: =VLOOKUP($A11,[6]HISTOMARS24!$A$6:$AV$48,7,0) -> 0 | G11: =VLOOKUP($A11,[6]HISTOMARS24!$A$6:$AV$49,8,0) -> BANQUE | H11: =VLOOKUP($A11,[6]HISTOMARS24!$A$6:$AV$49,35,0) -> 0 | I11: =VLOOKUP($A11,[6]HISTOMARS24!$A$6:$AV$49,38,0) -> 0 | J11: =IF(H11=0,0,VLOOKUP($A11,[6]HISTOMARS24!$A$6:$AV$49,42,0)) -> 0 | K11: =VLOOKUP($A11,[6]HISTOMARS24!$A$6:$AV$49,41,0) -> 0 | L11: =TONTFEV24!H11+TONTFEV24!I11 -> 0 | M11: =VLOOKUP($A11,[6]HISTOMARS24!$A$6:$AV$49,16,0) -> 0 | N11: =IF(M11<>0,VLOOKUP($A11,[6]HISTOMARS24!$A$6:$AV$49,8,0),"ECHEC") -> ECHEC | O11: =IF(R11=0,0,VLOOKUP($A11,[6]HISTOMARS24!$A$6:$AV$49,32,0)) -> 0 | P11: =VLOOKUP($A11,[6]HISTOMARS24!$A$6:$AV$49,33,0) -> 0 | Q11: =IF(R11=0,0,($C$3-R11)) -> 0 | R11: =VLOOKUP($A11,[6]HISTOMARS24!$A$6:$AV$49,29,0) -> 0
A12: AS201651 | B12: =IF(D12=0,0,VLOOKUP($A12,[6]HISTOMARS24!$A$6:$BP$44,10,0)) -> 1 | C12: =VLOOKUP(A12,[7]LISTADHERENT!A$5:H$60,3,0) -> DOMOU FABIEN | D12: =IF(G12="ECHEC",0,B$3) -> 25000 | E12: =D12+VLOOKUP($A12,[6]HISTOMARS24!$A$7:$AU$42,45,0)+F12 -> 50000 | F12: =VLOOKUP($A12,[6]HISTOMARS24!$A$6:$AV$48,7,0) -> 0 | G12: =VLOOKUP($A12,[6]HISTOMARS24!$A$6:$AV$49,8,0) -> BANQUE | H12: =VLOOKUP($A12,[6]HISTOMARS24!$A$6:$AV$49,35,0) -> 0 | I12: =VLOOKUP($A12,[6]HISTOMARS24!$A$6:$AV$49,38,0) -> 0 | J12: =IF(H12=0,0,VLOOKUP($A12,[6]HISTOMARS24!$A$6:$AV$49,42,0)) -> 0 | K12: =VLOOKUP($A12,[6]HISTOMARS24!$A$6:$AV$49,41,0) -> 0 | L12: =TONTFEV24!H12+TONTFEV24!I12 -> 0 | M12: =VLOOKUP($A12,[6]HISTOMARS24!$A$6:$AV$49,16,0) -> 0 | N12: =IF(M12<>0,VLOOKUP($A12,[6]HISTOMARS24!$A$6:$AV$49,8,0),"ECHEC") -> ECHEC | O12: =IF(R12=0,0,VLOOKUP($A12,[6]HISTOMARS24!$A$6:$AV$49,32,0)) -> 0 | P12: =VLOOKUP($A12,[6]HISTOMARS24!$A$6:$AV$49,33,0) -> 0 | Q12: =IF(R12=0,0,($C$3-R12)) -> 0 | R12: =VLOOKUP($A12,[6]HISTOMARS24!$A$6:$AV$49,29,0) -> 0
A13: AS201609 | B13: =IF(D13=0,0,VLOOKUP($A13,[6]HISTOMARS24!$A$6:$BP$44,10,0)) -> 1 | C13: =VLOOKUP(A13,[7]LISTADHERENT!A$5:H$60,3,0) -> DONHOU DAVID | D13: =IF(G13="ECHEC",0,B$3) -> 25000 | E13: =D13+VLOOKUP($A13,[6]HISTOMARS24!$A$7:$AU$42,45,0)+F13 -> 50000 | F13: =VLOOKUP($A13,[6]HISTOMARS24!$A$6:$AV$48,7,0) -> 0 | G13: =VLOOKUP($A13,[6]HISTOMARS24!$A$6:$AV$49,8,0) -> BANQUE | H13: =VLOOKUP($A13,[6]HISTOMARS24!$A$6:$AV$49,35,0) -> 0 | I13: =VLOOKUP($A13,[6]HISTOMARS24!$A$6:$AV$49,38,0) -> 0 | J13: =IF(H13=0,0,VLOOKUP($A13,[6]HISTOMARS24!$A$6:$AV$49,42,0)) -> 0 | K13: =VLOOKUP($A13,[6]HISTOMARS24!$A$6:$AV$49,41,0) -> 0 | L13: =TONTFEV24!H13+TONTFEV24!I13 -> 0 | M13: =VLOOKUP($A13,[6]HISTOMARS24!$A$6:$AV$49,16,0) -> 0 | N13: =IF(M13<>0,VLOOKUP($A13,[6]HISTOMARS24!$A$6:$AV$49,8,0),"ECHEC") -> ECHEC | O13: =IF(R13=0,0,VLOOKUP($A13,[6]HISTOMARS24!$A$6:$AV$49,32,0)) -> 0 | P13: =VLOOKUP($A13,[6]HISTOMARS24!$A$6:$AV$49,33,0) -> 0 | Q13: =IF(R13=0,0,($C$3-R13)) -> 0 | R13: =VLOOKUP($A13,[6]HISTOMARS24!$A$6:$AV$49,29,0) -> 0
A14: AS201611 | B14: =IF(D14=0,0,VLOOKUP($A14,[6]HISTOMARS24!$A$6:$BP$44,10,0)) -> 1 | C14: =VLOOKUP(A14,[7]LISTADHERENT!A$5:H$60,3,0) -> HENGUE PAUL OMER | D14: =IF(G14="ECHEC",0,B$3) -> 25000 | E14: =D14+VLOOKUP($A14,[6]HISTOMARS24!$A$7:$AU$42,45,0)+F14 -> 50000 | F14: =VLOOKUP($A14,[6]HISTOMARS24!$A$6:$AV$48,7,0) -> 0 | G14: =VLOOKUP($A14,[6]HISTOMARS24!$A$6:$AV$49,8,0) -> BANQUE | H14: =VLOOKUP($A14,[6]HISTOMARS24!$A$6:$AV$49,35,0) -> 0 | I14: =VLOOKUP($A14,[6]HISTOMARS24!$A$6:$AV$49,38,0) -> 0 | J14: =IF(H14=0,0,VLOOKUP($A14,[6]HISTOMARS24!$A$6:$AV$49,42,0)) -> 0 | K14: =VLOOKUP($A14,[6]HISTOMARS24!$A$6:$AV$49,41,0) -> 0 | L14: =TONTFEV24!H14+TONTFEV24!I14 -> 0 | M14: =VLOOKUP($A14,[6]HISTOMARS24!$A$6:$AV$49,16,0) -> 0 | N14: =IF(M14<>0,VLOOKUP($A14,[6]HISTOMARS24!$A$6:$AV$49,8,0),"ECHEC") -> ECHEC | O14: =IF(R14=0,0,VLOOKUP($A14,[6]HISTOMARS24!$A$6:$AV$49,32,0)) -> 0 | P14: =VLOOKUP($A14,[6]HISTOMARS24!$A$6:$AV$49,33,0) -> 0 | Q14: =IF(R14=0,0,($C$3-R14)) -> 0 | R14: =VLOOKUP($A14,[6]HISTOMARS24!$A$6:$AV$49,29,0) -> 0
A15: AS201613 | B15: =IF(D15=0,0,VLOOKUP($A15,[6]HISTOMARS24!$A$6:$BP$44,10,0)) -> 1 | C15: =VLOOKUP(A15,[7]LISTADHERENT!A$5:H$60,3,0) -> HOTCHO BENJAMIN | D15: =IF(G15="ECHEC",0,B$3) -> 25000 | E15: =D15+VLOOKUP($A15,[6]HISTOMARS24!$A$7:$AU$42,45,0)+F15 -> 85000 | F15: =VLOOKUP($A15,[6]HISTOMARS24!$A$6:$AV$48,7,0) -> 0 | G15: =VLOOKUP($A15,[6]HISTOMARS24!$A$6:$AV$49,8,0) -> BANQUE | H15: =VLOOKUP($A15,[6]HISTOMARS24!$A$6:$AV$49,35,0) -> 0 | I15: =VLOOKUP($A15,[6]HISTOMARS24!$A$6:$AV$49,38,0) -> 0 | J15: =IF(H15=0,0,VLOOKUP($A15,[6]HISTOMARS24!$A$6:$AV$49,42,0)) -> 0 | K15: =VLOOKUP($A15,[6]HISTOMARS24!$A$6:$AV$49,41,0) -> 0 | L15: =TONTFEV24!H15+TONTFEV24!I15 -> 0 | M15: =VLOOKUP($A15,[6]HISTOMARS24!$A$6:$AV$49,16,0) -> 0 | N15: =IF(M15<>0,VLOOKUP($A15,[6]HISTOMARS24!$A$6:$AV$49,8,0),"ECHEC") -> ECHEC | O15: =IF(R15=0,0,VLOOKUP($A15,[6]HISTOMARS24!$A$6:$AV$49,32,0)) -> 0 | P15: =VLOOKUP($A15,[6]HISTOMARS24!$A$6:$AV$49,33,0) -> 0 | Q15: =IF(R15=0,0,($C$3-R15)) -> 0 | R15: =VLOOKUP($A15,[6]HISTOMARS24!$A$6:$AV$49,29,0) -> 0
A16: AS201617 | B16: =IF(D16=0,0,VLOOKUP($A16,[6]HISTOMARS24!$A$6:$BP$44,10,0)) -> 1 | C16: =VLOOKUP(A16,[7]LISTADHERENT!A$5:H$60,3,0) -> KOUAMOU MOISE | D16: =IF(G16="ECHEC",0,B$3) -> 25000 | E16: =D16+VLOOKUP($A16,[6]HISTOMARS24!$A$7:$AU$42,45,0)+F16 -> 50000 | F16: =VLOOKUP($A16,[6]HISTOMARS24!$A$6:$AV$48,7,0) -> 0 | G16: =VLOOKUP($A16,[6]HISTOMARS24!$A$6:$AV$49,8,0) -> BANQUE | H16: =VLOOKUP($A16,[6]HISTOMARS24!$A$6:$AV$49,35,0) -> 0 | I16: =VLOOKUP($A16,[6]HISTOMARS24!$A$6:$AV$49,38,0) -> 0 | J16: =IF(H16=0,0,VLOOKUP($A16,[6]HISTOMARS24!$A$6:$AV$49,42,0)) -> 0 | K16: =VLOOKUP($A16,[6]HISTOMARS24!$A$6:$AV$49,41,0) -> 0 | L16: =TONTFEV24!H16+TONTFEV24!I16 -> 0 | M16: =VLOOKUP($A16,[6]HISTOMARS24!$A$6:$AV$49,16,0) -> 0 | N16: =IF(M16<>0,VLOOKUP($A16,[6]HISTOMARS24!$A$6:$AV$49,8,0),"ECHEC") -> ECHEC | O16: =IF(R16=0,0,VLOOKUP($A16,[6]HISTOMARS24!$A$6:$AV$49,32,0)) -> 0 | P16: =VLOOKUP($A16,[6]HISTOMARS24!$A$6:$AV$49,33,0) -> 0 | Q16: =IF(R16=0,0,($C$3-R16)) -> 0 | R16: =VLOOKUP($A16,[6]HISTOMARS24!$A$6:$AV$49,29,0) -> 0
A17: AS201619 | B17: =IF(D17=0,0,VLOOKUP($A17,[6]HISTOMARS24!$A$6:$BP$44,10,0)) -> 1 | C17: =VLOOKUP(A17,[7]LISTADHERENT!A$5:H$60,3,0) -> KOUATCHO MESSACK | D17: =IF(G17="ECHEC",0,B$3) -> 25000 | E17: =D17+VLOOKUP($A17,[6]HISTOMARS24!$A$7:$AU$42,45,0)+F17 -> 60000 | F17: =VLOOKUP($A17,[6]HISTOMARS24!$A$6:$AV$48,7,0) -> 0 | G17: =VLOOKUP($A17,[6]HISTOMARS24!$A$6:$AV$49,8,0) -> BANQUE | H17: =VLOOKUP($A17,[6]HISTOMARS24!$A$6:$AV$49,35,0) -> 0 | I17: =VLOOKUP($A17,[6]HISTOMARS24!$A$6:$AV$49,38,0) -> 0 | J17: =IF(H17=0,0,VLOOKUP($A17,[6]HISTOMARS24!$A$6:$AV$49,42,0)) -> 0 | K17: =VLOOKUP($A17,[6]HISTOMARS24!$A$6:$AV$49,41,0) -> 0 | L17: =TONTFEV24!H17+TONTFEV24!I17 -> 0 | M17: =VLOOKUP($A17,[6]HISTOMARS24!$A$6:$AV$49,16,0) -> 0 | N17: =IF(M17<>0,VLOOKUP($A17,[6]HISTOMARS24!$A$6:$AV$49,8,0),"ECHEC") -> ECHEC | O17: =IF(R17=0,0,VLOOKUP($A17,[6]HISTOMARS24!$A$6:$AV$49,32,0)) -> 0 | P17: =VLOOKUP($A17,[6]HISTOMARS24!$A$6:$AV$49,33,0) -> 0 | Q17: =IF(R17=0,0,($C$3-R17)) -> 0 | R17: =VLOOKUP($A17,[6]HISTOMARS24!$A$6:$AV$49,29,0) -> 0
... A37: AS201647 | B37: =IF(D37=0,0,VLOOKUP($A37,[6]HISTOMARS24!$A$6:$BP$44,10,0)) -> 1 | C37: =VLOOKUP(A37,[7]LISTADHERENT!A$5:H$60,3,0) -> YOUMBI EMMANUEL | D37: =IF(G37="ECHEC",0,B$3) -> 25000 | E37: =D37+VLOOKUP($A37,[6]HISTOMARS24!$A$7:$AU$42,45,0)+F37 -> 50000 | F37: =VLOOKUP($A37,[6]HISTOMARS24!$A$6:$AV$48,7,0) -> 0 | G37: =VLOOKUP($A37,[6]HISTOMARS24!$A$6:$AV$49,8,0) -> BANQUE | H37: =VLOOKUP($A37,[6]HISTOMARS24!$A$6:$AV$49,35,0) -> 0 | I37: =VLOOKUP($A37,[6]HISTOMARS24!$A$6:$AV$49,38,0) -> 0 | J37: =IF(H37=0,0,VLOOKUP($A37,[6]HISTOMARS24!$A$6:$AV$49,42,0)) -> 0 | K37: =VLOOKUP($A37,[6]HISTOMARS24!$A$6:$AV$49,41,0) -> 0 | L37: =TONTFEV24!H37+TONTFEV24!I37 -> 0 | M37: =VLOOKUP($A37,[6]HISTOMARS24!$A$6:$AV$49,16,0) -> 0 | N37: =IF(M37<>0,VLOOKUP($A37,[6]HISTOMARS24!$A$6:$AV$49,8,0),"ECHEC") -> ECHEC | O37: =IF(R37=0,0,VLOOKUP($A37,[6]HISTOMARS24!$A$6:$AV$49,32,0)) -> 0 | P37: =VLOOKUP($A37,[6]HISTOMARS24!$A$6:$AV$49,33,0) -> 0 | Q37: =IF(R37=0,0,($C$3-R37)) -> 0 | R37: =VLOOKUP($A37,[6]HISTOMARS24!$A$6:$AV$49,29,0) -> 0
A39: TOTAL PART | B39: =SUM(B6:B38) -> 32
A40: NBRE ADHERENT | B40: =COUNT(D6:D38) -> 32 | D40: =SUM(D6:D39) -> 800000 | F40: =SUM(F6:F39) -> 6000 | G40: =SUM(G6:G39) -> 0 | H40: =SUM(H6:H39) -> 119000 | I40: =SUM(I6:I39) -> 4500 | J40: =SUM(J6:J39) -> 0 | K40: =SUM(K6:K39) -> 0 | L40: =SUM(L6:L39) -> 174000 | M40: =SUM(M6:M39) -> 174000 | ... R40: =SUM(R6:R39) -> 45000
N41: NBRE PART | O41: PART VENDUE
D42: MONTANT TONTINE | G42: REMBOURSEMENT PETIT LOT | H42: VENTE PETIT LOT | I42: VENTE LOT PRINCIPAL | J42: SOLDE EN CAISSE | L42: TONTINE + REMB + INTERET VENTE | M42: =D46+G46+R40+TONTFEV24!O47 -> 1019000
D43: =SUMIFS(D6:D39,G6:G39,"ESPECES") -> 25000 | F43: ESPECES | G43: =SUMIFS(M6:M33,N6:N33,"ESPECES") -> 0 | H43: =SUMIFS(H6:H39,J6:J39,"ESPECES") -> 0 | I43: =SUMIFS(Q6:Q39,O6:O39,"ESPECES") -> 0 | J43: =D43+G43-H43-I43 -> 25000 | L43: LOT PRINCIPAL | M43: =C3*COUNTIF(Q7:Q39,">0")+300000 -> 900000 | N43: =D3 -> 3 | O43: =COUNTIF(Q6:Q33,">0") -> 3
D44: =SUMIFS(D6:D39,G6:G39,"BANQUE") -> 775000 | F44: BANQUE | G44: =SUMIFS(M6:M33,N6:N33,"BANQUE") -> 174000 | H44: =SUMIFS(H6:H39,J6:J39,"BANQUE") -> 79000 | I44: =SUMIFS(Q6:Q39,O6:O39,"BANQUE") -> 855000 | J44: =D44+G44-H44-I44 -> 15000
L45: PETIT LOT | M45: =M42-M43 -> 119000
D46: =D43+D44 -> 800000 | F46: TOTAL | G46: =G43+G44 -> 174000 | H46: =H43+H44 -> 79000 | I46: =I43+I44 -> 855000 | J46: =J43+J44 -> 40000
F47: TOTAL+DEPOT | L47: RELIQUAT | M47: =M45-H40 -> 0 | O47: =TONTMARS24!M47 -> 0 | P47: CUMUL
L49: ECHEC TONTINE MOIS | M49: =COUNTIFS(G7:G38,"ECHEC")*23000 -> 0 | O49: =TONTMARS24!M49 -> 0 | P49: CUMUL
L50: ECHEC REMBOURSEMENT MOIS | M50: =L40-G46 -> 0 | O50: =TONTMARS24!M50 -> 0 | P50: CUMUL

Sheet TONTAVRIL24
A1: ASSOCIATION | B1: ASELBY
A2: ANNEE | B2: 2024 | C2: TONIINE | D2: NBRE PART
A3: TAUX TONTINE | B3: 25000 | C3: =B3*12 -> 300000 | D3: =ROUNDDOWN(M42/C3,0) -> 3
C4: 45395
A5: MATRICULE | B5: NBREPART | C5: NOM ET PRENOM | D5: MONTANT TONTINE | E5: MONTANT VERSE | F5: PENALITE VERSEMENT ESPECES | G5: MODE VERSEMENT | H5: VENTE PETIT LOT | I5: INTERET PETIT LOT | J5: MODE VERSEMENT VENTE PETIT LOT | K5: NUMERO CHEQUE | L5: MONTANT A REMBOURSER PETIT LOT | M5: REMBOURSEMENT PETIT LOT | N5: MODE VERSEMENT REMBOURSEMENT | O5: MODE VERSEMENTLOT PRINCIPAL | P5: NUMERO CHEQUE | Q5: MONTANT LOT PRINCIPAL | R5: INTERET LOT PRINCIPAL
A6: AS201601 | B6: =IF(D6=0,0,VLOOKUP($A6,[6]HISTOAVRIL24!$A$6:$BP$44,10,0)) -> 1 | C6: =VLOOKUP(A6,[7]LISTADHERENT!A$5:H$60,3,0) -> BAKOP ACHILLE | D6: =IF(G6="ECHEC",0,B$3) -> 25000 | E6: =D6+VLOOKUP($A6,[6]HISTOAVRIL24!$A$7:$AU$42,45,0)+F6 -> 50000 | F6: =VLOOKUP($A6,[6]HISTOAVRIL24!$A$6:$AV$48,7,0) -> 3000 | G6: =VLOOKUP($A6,[6]HISTOAVRIL24!$A$6:$AV$49,8,0) -> ESPECES | H6: =VLOOKUP($A6,[6]HISTOAVRIL24!$A$6:$AV$49,35,0) -> 0 | I6: =VLOOKUP($A6,[6]HISTOAVRIL24!$A$6:$AV$49,38,0) -> 0 | J6: =IF(H6=0,0,VLOOKUP($A6,[6]HISTOAVRIL24!$A$6:$AV$49,42,0)) -> 0 | K6: =VLOOKUP($A6,[6]HISTOAVRIL24!$A$6:$AV$49,41,0) -> 0 | L6: =TONTMARS24!H6+TONTMARS24!I6 -> 0 | M6: =VLOOKUP($A6,[6]HISTOAVRIL24!$A$6:$AV$49,16,0) -> 0 | N6: =IF(M6<>0,VLOOKUP($A6,[6]HISTOAVRIL24!$A$6:$AV$49,8,0),"ECHEC") -> ECHEC | O6: =IF(R6=0,0,VLOOKUP($A6,[6]HISTOAVRIL24!$A$6:$AV$49,32,0)) -> 0 | P6: =VLOOKUP($A6,[6]HISTOAVRIL24!$A$6:$AV$49,33,0) -> 0 | Q6: =IF(R6=0,0,($C$3-R6)) -> 0 | R6: =VLOOKUP($A6,[6]HISTOAVRIL24!$A$6:$AV$49,29,0) -> 0
A7: AS201602 | B7: =IF(D7=0,0,VLOOKUP($A7,[6]HISTOAVRIL24!$A$6:$BP$44,10,0)) -> 1 | C7: =VLOOKUP(A7,[7]LISTADHERENT!A$5:H$60,3,0) -> BOUTCHOUANG WILLIAM | D7: =IF(G7="ECHEC",0,B$3) -> 25000 | E7: =D7+VLOOKUP($A7,[6]HISTOAVRIL24!$A$7:$AU$42,45,0)+F7 -> 50000 | F7: =VLOOKUP($A7,[6]HISTOAVRIL24!$A$6:$AV$48,7,0) -> 0 | G7: =VLOOKUP($A7,[6]HISTOAVRIL24!$A$6:$AV$49,8,0) -> BANQUE | H7: =VLOOKUP($A7,[6]HISTOAVRIL24!$A$6:$AV$49,35,0) -> 0 | I7: =VLOOKUP($A7,[6]HISTOAVRIL24!$A$6:$AV$49,38,0) -> 0 | J7: =IF(H7=0,0,VLOOKUP($A7,[6]HISTOAVRIL24!$A$6:$AV$49,42,0)) -> 0 | K7: =VLOOKUP($A7,[6]HISTOAVRIL24!$A$6:$AV$49,41,0) -> 0 | L7: =TONTMARS24!H7+TONTMARS24!I7 -> 0 | M7: =VLOOKUP($A7,[6]HISTOAVRIL24!$A$6:$AV$49,16,0) -> 0 | N7: =IF(M7<>0,VLOOKUP($A7,[6]HISTOAVRIL24!$A$6:$AV$49,8,0),"ECHEC") -> ECHEC | O7: =IF(R7=0,0,VLOOKUP($A7,[6]HISTOAVRIL24!$A$6:$AV$49,32,0)) -> 0 | P7: =VLOOKUP($A7,[6]HISTOAVRIL24!$A$6:$AV$49,33,0) -> 0 | Q7: =IF(R7=0,0,($C$3-R7)) -> 0 | R7: =VLOOKUP($A7,[6]HISTOAVRIL24!$A$6:$AV$49,29,0) -> 0
A8: AS201604 | B8: =IF(D8=0,0,VLOOKUP($A8,[6]HISTOAVRIL24!$A$6:$BP$44,10,0)) -> 1 | C8: =VLOOKUP(A8,[7]LISTADHERENT!A$5:H$60,3,0) -> DJOMO JEAN PAUL | D8: =IF(G8="ECHEC",0,B$3) -> 25000 | E8: =D8+VLOOKUP($A8,[6]HISTOAVRIL24!$A$7:$AU$42,45,0)+F8 -> 47500 | F8: =VLOOKUP($A8,[6]HISTOAVRIL24!$A$6:$AV$48,7,0) -> 0 | G8: =VLOOKUP($A8,[6]HISTOAVRIL24!$A$6:$AV$49,8,0) -> BANQUE | H8: =VLOOKUP($A8,[6]HISTOAVRIL24!$A$6:$AV$49,35,0) -> 0 | I8: =VLOOKUP($A8,[6]HISTOAVRIL24!$A$6:$AV$49,38,0) -> 0 | J8: =IF(H8=0,0,VLOOKUP($A8,[6]HISTOAVRIL24!$A$6:$AV$49,42,0)) -> 0 | K8: =VLOOKUP($A8,[6]HISTOAVRIL24!$A$6:$AV$49,41,0) -> 0 | L8: =TONTMARS24!H8+TONTMARS24!I8 -> 0 | M8: =VLOOKUP($A8,[6]HISTOAVRIL24!$A$6:$AV$49,16,0) -> 0 | N8: =IF(M8<>0,VLOOKUP($A8,[6]HISTOAVRIL24!$A$6:$AV$49,8,0),"ECHEC") -> ECHEC | O8: =IF(R8=0,0,VLOOKUP($A8,[6]HISTOAVRIL24!$A$6:$AV$49,32,0)) -> 0 | P8: =VLOOKUP($A8,[6]HISTOAVRIL24!$A$6:$AV$49,33,0) -> 0 | Q8: =IF(R8=0,0,($C$3-R8)) -> 0 | R8: =VLOOKUP($A8,[6]HISTOAVRIL24!$A$6:$AV$49,29,0) -> 0
A9: AS201654 | B9: =IF(D9=0,0,VLOOKUP($A9,[6]HISTOAVRIL24!$A$6:$BP$44,10,0)) -> 1 | C9: =VLOOKUP(A9,[7]LISTADHERENT!A$5:H$60,3,0) -> DJOMOU TCHAPDA | D9: =IF(G9="ECHEC",0,B$3) -> 25000 | E9: =D9+VLOOKUP($A9,[6]HISTOAVRIL24!$A$7:$AU$42,45,0)+F9 -> 50000 | F9: =VLOOKUP($A9,[6]HISTOAVRIL24!$A$6:$AV$48,7,0) -> 0 | G9: =VLOOKUP($A9,[6]HISTOAVRIL24!$A$6:$AV$49,8,0) -> BANQUE | H9: =VLOOKUP($A9,[6]HISTOAVRIL24!$A$6:$AV$49,35,0) -> 0 | I9: =VLOOKUP($A9,[6]HISTOAVRIL24!$A$6:$AV$49,38,0) -> 0 | J9: =IF(H9=0,0,VLOOKUP($A9,[6]HISTOAVRIL24!$A$6:$AV$49,42,0)) -> 0 | K9: =VLOOKUP($A9,[6]HISTOAVRIL24!$A$6:$AV$49,41,0) -> 0 | L9: =TONTMARS24!H9+TONTMARS24!I9 -> 40000 | M9: =VLOOKUP($A9,[6]HISTOAVRIL24!$A$6:$AV$49,16,0) -> 40000 | N9: =IF(M9<>0,VLOOKUP($A9,[6]HISTOAVRIL24!$A$6:$AV$49,8,0),"ECHEC") -> BANQUE | O9: =IF(R9=0,0,VLOOKUP($A9,[6]HISTOAVRIL24!$A$6:$AV$49,32,0)) -> 0 | P9: =VLOOKUP($A9,[6]HISTOAVRIL24!$A$6:$AV$49,33,0) -> 0 | Q9: =IF(R9=0,0,($C$3-R9)) -> 0 | R9: =VLOOKUP($A9,[6]HISTOAVRIL24!$A$6:$AV$49,29,0) -> 0
A10: AS201605 | B10: =IF(D10=0,0,VLOOKUP($A10,[6]HISTOAVRIL24!$A$6:$BP$44,10,0)) -> 1 | C10: =VLOOKUP(A10,[7]LISTADHERENT!A$5:H$60,3,0) -> DJOUKWE NANGUEN GUY BLAISE | D10: =IF(G10="ECHEC",0,B$3) -> 25000 | E10: =D10+VLOOKUP($A10,[6]HISTOAVRIL24!$A$7:$AU$42,45,0)+F10 -> 60000 | F10: =VLOOKUP($A10,[6]HISTOAVRIL24!$A$6:$AV$48,7,0) -> 0 | G10: =VLOOKUP($A10,[6]HISTOAVRIL24!$A$6:$AV$49,8,0) -> BANQUE | H10: =VLOOKUP($A10,[6]HISTOAVRIL24!$A$6:$AV$49,35,0) -> 41000 | I10: =VLOOKUP($A10,[6]HISTOAVRIL24!$A$6:$AV$49,38,0) -> 2000 | J10: =IF(H10=0,0,VLOOKUP($A10,[6]HISTOAVRIL24!$A$6:$AV$49,42,0)) -> BANQUE | K10: =VLOOKUP($A10,[6]HISTOAVRIL24!$A$6:$AV$49,41,0) -> 0 | L10: =TONTMARS24!H10+TONTMARS24!I10 -> 41000 | M10: =VLOOKUP($A10,[6]HISTOAVRIL24!$A$6:$AV$49,16,0) -> 41000 | N10: =IF(M10<>0,VLOOKUP($A10,[6]HISTOAVRIL24!$A$6:$AV$49,8,0),"ECHEC") -> BANQUE | O10: =IF(R10=0,0,VLOOKUP($A10,[6]HISTOAVRIL24!$A$6:$AV$49,32,0)) -> 0 | P10: =VLOOKUP($A10,[6]HISTOAVRIL24!$A$6:$AV$49,33,0) -> 0 | Q10: =IF(R10=0,0,($C$3-R10)) -> 0 | R10: =VLOOKUP($A10,[6]HISTOAVRIL24!$A$6:$AV$49,29,0) -> 0
A11: AS201608 | B11: =IF(D11=0,0,VLOOKUP($A11,[6]HISTOAVRIL24!$A$6:$BP$44,10,0)) -> 1 | C11: =VLOOKUP(A11,[7]LISTADHERENT!A$5:H$60,3,0) -> DJUOMBESSY ANTOINE | D11: =IF(G11="ECHEC",0,B$3) -> 25000 | E11: =D11+VLOOKUP($A11,[6]HISTOAVRIL24!$A$7:$AU$42,45,0)+F11 -> 55000 | F11: =VLOOKUP($A11,[6]HISTOAVRIL24!$A$6:$AV$48,7,0) -> 0 | G11: =VLOOKUP($A11,[6]HISTOAVRIL24!$A$6:$AV$49,8,0) -> BANQUE | H11: =VLOOKUP($A11,[6]HISTOAVRIL24!$A$6:$AV$49,35,0) -> 0 | I11: =VLOOKUP($A11,[6]HISTOAVRIL24!$A$6:$AV$49,38,0) -> 0 | J11: =IF(H11=0,0,VLOOKUP($A11,[6]HISTOAVRIL24!$A$6:$AV$49,42,0)) -> 0 | K11: =VLOOKUP($A11,[6]HISTOAVRIL24!$A$6:$AV$49,41,0) -> 0 | L11: =TONTMARS24!H11+TONTMARS24!I11 -> 0 | M11: =VLOOKUP($A11,[6]HISTOAVRIL24!$A$6:$AV$49,16,0) -> 0 | N11: =IF(M11<>0,VLOOKUP($A11,[6]HISTOAVRIL24!$A$6:$AV$49,8,0),"ECHEC") -> ECHEC | O11: =IF(R11=0,0,VLOOKUP($A11,[6]HISTOAVRIL24!$A$6:$AV$49,32,0)) -> 0 | P11: =VLOOKUP($A11,[6]HISTOAVRIL24!$A$6:$AV$49,33,0) -> 0 | Q11: =IF(R11=0,0,($C$3-R11)) -> 0 | R11: =VLOOKUP($A11,[6]HISTOAVRIL24!$A$6:$AV$49,29,0) -> 0
A12: AS201651 | B12: =IF(D12=0,0,VLOOKUP($A12,[6]HISTOAVRIL24!$A$6:$BP$44,10,0)) -> 1 | C12: =VLOOKUP(A12,[7]LISTADHERENT!A$5:H$60,3,0) -> DOMOU FABIEN | D12: =IF(G12="ECHEC",0,B$3) -> 25000 | E12: =D12+VLOOKUP($A12,[6]HISTOAVRIL24!$A$7:$AU$42,45,0)+F12 -> 50000 | F12: =VLOOKUP($A12,[6]HISTOAVRIL24!$A$6:$AV$48,7,0) -> 0 | G12: =VLOOKUP($A12,[6]HISTOAVRIL24!$A$6:$AV$49,8,0) -> BANQUE | H12: =VLOOKUP($A12,[6]HISTOAVRIL24!$A$6:$AV$49,35,0) -> 0 | I12: =VLOOKUP($A12,[6]HISTOAVRIL24!$A$6:$AV$49,38,0) -> 0 | J12: =IF(H12=0,0,VLOOKUP($A12,[6]HISTOAVRIL24!$A$6:$AV$49,42,0)) -> 0 | K12: =VLOOKUP($A12,[6]HISTOAVRIL24!$A$6:$AV$49,41,0) -> 0 | L12: =TONTMARS24!H12+TONTMARS24!I12 -> 0 | M12: =VLOOKUP($A12,[6]HISTOAVRIL24!$A$6:$AV$49,16,0) -> 0 | N12: =IF(M12<>0,VLOOKUP($A12,[6]HISTOAVRIL24!$A$6:$AV$49,8,0),"ECHEC") -> ECHEC | O12: =IF(R12=0,0,VLOOKUP($A12,[6]HISTOAVRIL24!$A$6:$AV$49,32,0)) -> 0 | P12: =VLOOKUP($A12,[6]HISTOAVRIL24!$A$6:$AV$49,33,0) -> 0 | Q12: =IF(R12=0,0,($C$3-R12)) -> 0 | R12: =VLOOKUP($A12,[6]HISTOAVRIL24!$A$6:$AV$49,29,0) -> 0
A13: AS201609 | B13: =IF(D13=0,0,VLOOKUP($A13,[6]HISTOAVRIL24!$A$6:$BP$44,10,0)) -> 1 | C13: =VLOOKUP(A13,[7]LISTADHERENT!A$5:H$60,3,0) -> DONHOU DAVID | D13: =IF(G13="ECHEC",0,B$3) -> 25000 | E13: =D13+VLOOKUP($A13,[6]HISTOAVRIL24!$A$7:$AU$42,45,0)+F13 -> 50000 | F13: =VLOOKUP($A13,[6]HISTOAVRIL24!$A$6:$AV$48,7,0) -> 0 | G13: =VLOOKUP($A13,[6]HISTOAVRIL24!$A$6:$AV$49,8,0) -> BANQUE | H13: =VLOOKUP($A13,[6]HISTOAVRIL24!$A$6:$AV$49,35,0) -> 0 | I13: =VLOOKUP($A13,[6]HISTOAVRIL24!$A$6:$AV$49,38,0) -> 0 | J13: =IF(H13=0,0,VLOOKUP($A13,[6]HISTOAVRIL24!$A$6:$AV$49,42,0)) -> 0 | K13: =VLOOKUP($A13,[6]HISTOAVRIL24!$A$6:$AV$49,41,0) -> 0 | L13: =TONTMARS24!H13+TONTMARS24!I13 -> 0 | M13: =VLOOKUP($A13,[6]HISTOAVRIL24!$A$6:$AV$49,16,0) -> 0 | N13: =IF(M13<>0,VLOOKUP($A13,[6]HISTOAVRIL24!$A$6:$AV$49,8,0),"ECHEC") -> ECHEC | O13: =IF(R13=0,0,VLOOKUP($A13,[6]HISTOAVRIL24!$A$6:$AV$49,32,0)) -> 0 | P13: =VLOOKUP($A13,[6]HISTOAVRIL24!$A$6:$AV$49,33,0) -> 0 | Q13: =IF(R13=0,0,($C$3-R13)) -> 0 | R13: =VLOOKUP($A13,[6]HISTOAVRIL24!$A$6:$AV$49,29,0) -> 0
A14: AS201611 | B14: =IF(D14=0,0,VLOOKUP($A14,[6]HISTOAVRIL24!$A$6:$BP$44,10,0)) -> 1 | C14: =VLOOKUP(A14,[7]LISTADHERENT!A$5:H$60,3,0) -> HENGUE PAUL OMER | D14: =IF(G14="ECHEC",0,B$3) -> 25000 | E14: =D14+VLOOKUP($A14,[6]HISTOAVRIL24!$A$7:$AU$42,45,0)+F14 -> 50000 | F14: =VLOOKUP($A14,[6]HISTOAVRIL24!$A$6:$AV$48,7,0) -> 0 | G14: =VLOOKUP($A14,[6]HISTOAVRIL24!$A$6:$AV$49,8,0) -> BANQUE | H14: =VLOOKUP($A14,[6]HISTOAVRIL24!$A$6:$AV$49,35,0) -> 0 | I14: =VLOOKUP($A14,[6]HISTOAVRIL24!$A$6:$AV$49,38,0) -> 0 | J14: =IF(H14=0,0,VLOOKUP($A14,[6]HISTOAVRIL24!$A$6:$AV$49,42,0)) -> 0 | K14: =VLOOKUP($A14,[6]HISTOAVRIL24!$A$6:$AV$49,41,0) -> 0 | L14: =TONTMARS24!H14+TONTMARS24!I14 -> 0 | M14: =VLOOKUP($A14,[6]HISTOAVRIL24!$A$6:$AV$49,16,0) -> 0 | N14: =IF(M14<>0,VLOOKUP($A14,[6]HISTOAVRIL24!$A$6:$AV$49,8,0),"ECHEC") -> ECHEC | O14: =IF(R14=0,0,VLOOKUP($A14,[6]HISTOAVRIL24!$A$6:$AV$49,32,0)) -> BANQUE | P14: =VLOOKUP($A14,[6]HISTOAVRIL24!$A$6:$AV$49,33,0) -> 0 | Q14: =IF(R14=0,0,($C$3-R14)) -> 290000 | R14: =VLOOKUP($A14,[6]HISTOAVRIL24!$A$6:$AV$49,29,0) -> 10000
A15: AS201613 | B15: =IF(D15=0,0,VLOOKUP($A15,[6]HISTOAVRIL24!$A$6:$BP$44,10,0)) -> 1 | C15: =VLOOKUP(A15,[7]LISTADHERENT!A$5:H$60,3,0) -> HOTCHO BENJAMIN | D15: =IF(G15="ECHEC",0,B$3) -> 25000 | E15: =D15+VLOOKUP($A15,[6]HISTOAVRIL24!$A$7:$AU$42,45,0)+F15 -> 85000 | F15: =VLOOKUP($A15,[6]HISTOAVRIL24!$A$6:$AV$48,7,0) -> 0 | G15: =VLOOKUP($A15,[6]HISTOAVRIL24!$A$6:$AV$49,8,0) -> BANQUE | H15: =VLOOKUP($A15,[6]HISTOAVRIL24!$A$6:$AV$49,35,0) -> 0 | I15: =VLOOKUP($A15,[6]HISTOAVRIL24!$A$6:$AV$49,38,0) -> 0 | J15: =IF(H15=0,0,VLOOKUP($A15,[6]HISTOAVRIL24!$A$6:$AV$49,42,0)) -> 0 | K15: =VLOOKUP($A15,[6]HISTOAVRIL24!$A$6:$AV$49,41,0) -> 0 | L15: =TONTMARS24!H15+TONTMARS24!I15 -> 0 | M15: =VLOOKUP($A15,[6]HISTOAVRIL24!$A$6:$AV$49,16,0) -> 0 | N15: =IF(M15<>0,VLOOKUP($A15,[6]HISTOAVRIL24!$A$6:$AV$49,8,0),"ECHEC") -> ECHEC | O15: =IF(R15=0,0,VLOOKUP($A15,[6]HISTOAVRIL24!$A$6:$AV$49,32,0)) -> 0 | P15: =VLOOKUP($A15,[6]HISTOAVRIL24!$A$6:$AV$49,33,0) -> 0 | Q15: =IF(R15=0,0,($C$3-R15)) -> 0 | R15: =VLOOKUP($A15,[6]HISTOAVRIL24!$A$6:$AV$49,29,0) -> 0
