Workbook
Name BANQUE: #REF!
Name BANQUE: #REF!
Name BANQUE: #REF!
Name BANQUE: #REF!
Name BANQUE: #REF!
Name BANQUE: #REF!
Name BANQUE: #REF!
Name BANQUE: #REF!
Name BANQUE: #REF!
Name BANQUE: #REF!
Name BANQUE: #REF!
Name BANQUE: #REF!
Name BANQUE: #REF!
Name BANQUE: #REF!
Name BANQUE: #REF!
Name BANQUE: #REF!
Name BANQUE: #REF!
Name BANQUE: #REF!
Name BANQUE: #REF!
Name BANQUE: #REF!
Name BANQUE: #REF!
Name BANQUE: #REF!
Name BANQUE: #REF!
Name BANQUE: #REF!
Name BANQUE: #REF!
Name BANQUE: #REF!
Name BANQUE: #REF!
Name BANQUE: #REF!
Name BANQUE: #REF!
Name MODEPAID: #REF!
Name MODEPAID: [1]Feuil2!$A$1:$A$3
Name MODET25000: [2]MODEVERSEMENT!$A$1:$A$3
Name MODEVERSEMENT: #REF!
Name MODEVERSEMENT: #REF!
Name MODEVERSEMENT: #REF!
Name MODEVERSEMENT: #REF!
Name MODEVERSEMENT: #REF!
Name MODEVERSEMENT: #REF!
Name MODEVERSEMENT: #REF!
Name MODEVERSEMENT: #REF!
Name MODEVERSEMENT: #REF!
Name MODEVERSEMENT: #REF!
Name MODEVERSEMENT: #REF!
Name MODEVERSEMENT: #REF!
Name MODEVERSEMENT: #REF!
Name MODEVERSEMENT: #REF!
Name MODEVERSEMENT: #REF!
Name MODEVERSEMENT: #REF!
Name MODEVERSEMENT: #REF!
Name MODEVERSEMENT: #REF!
Name MODEVERSEMENT: #REF!
Name MODEVERSEMENT: #REF!
Name MODEVERSEMENT: #REF!
Name MODEVERSEMENT: #REF!
Name MODEVERSEMENT: #REF!
Name MODEVERSEMENT: #REF!
Name MODEVERSEMENT: #REF!
Name MODEVERSEMENT: #REF!
Name MODEVERSEMENT: #REF!
Name MODEVERSEMENT: #REF!

Sheet MODEVERSEMENT
A1: BANQUE
A2: ESPECES
A3: ECHEC

Sheet TONTJANV25
A1: ASSOCIATION | B1: ASELBY
A2: ANNEE | B2: 2025 | C2: TONIINE | D2: NBRE PART
A3: TAUX TONTINE | B3: 25000 | C3: =B3*12 -> 300000 | D3: =ROUNDDOWN(M45/C3,0) -> 3
C4: 45670
A5: MATRICULE | B5: NBREPART | C5: NOM ET PRENOM | D5: MONTANT TONTINE | E5: MONTANT VERSE | F5: PENALITE VERSEMENT ESPECES | G5: MODE VERSEMENT | H5: VENTE PETIT LOT | I5: INTERET PETIT LOT | J5: MODE VERSEMENT VENTE PETIT LOT | K5: NUMERO CHEQUE | L5: MONTANT A REMBOURSER PETIT LOT | M5: REMBOURSEMENT PETIT LOT | N5: MODE VERSEMENT REMBOURSEMENT | O5: MODE VERSEMENTLOT PRINCIPAL | P5: NUMERO CHEQUE | Q5: MONTANT LOT PRINCIPAL | R5: INTERET LOT PRINCIPAL
A6: AS201601 | B6: =IF(D6=0,0,VLOOKUP($A6,[6]HISTOJANV25!$A$6:$BP$45,10,0)) -> 1 | C6: =VLOOKUP(A6,[7]LISTADHERENT!A$5:H$60,3,0) -> BAKOP ACHILLE | D6: =IF(G6="ECHEC",0,B$3) -> 25000 | E6: =D6+VLOOKUP($A6,[6]HISTOJANV25!$A$7:$AT$43,45,0)+F6 -> 50000 | F6: =VLOOKUP($A6,[6]HISTOJANV25!$A$6:$AU$48,8,0) -> 0 | G6: =VLOOKUP($A6,[6]HISTOJANV25!$A$6:$AU$49,9,0) -> ESPECES | H6: =VLOOKUP($A6,[6]HISTOJANV25!$A$6:$AV$49,35,0) -> 0 | I6: =VLOOKUP($A6,[6]HISTOJANV25!$A$6:$AV$49,38,0) -> 0 | J6: =IF(H6=0,0,VLOOKUP($A6,[6]HISTOJANV25!$A$6:$AV$49,42,0)) -> 0 | K6: =VLOOKUP($A6,[6]HISTOJANV25!$A$6:$AV$49,41,0) -> 0 | M6: =VLOOKUP($A6,[6]HISTOJANV25!$A$6:$AV$49,16,0) -> 0 | N6: =IF(M6<>0,VLOOKUP($A6,[6]HISTOJANV25!$A$6:$AV$49,42,0),"ECHEC") -> ECHEC | O6: =IF(R6=0,0,VLOOKUP($A6,[6]HISTOJANV25!$A$6:$AV$49,32,0)) -> 0 | P6: =VLOOKUP($A6,[6]HISTOJANV25!$A$6:$AV$49,33,0) -> 0 | Q6: =IF(R6=0,0,($C$3-R6)) -> 0 | R6: =VLOOKUP($A6,[6]HISTOJANV25!$A$6:$AV$49,29,0) -> 0
A7: AS201602 | B7: =IF(D7=0,0,VLOOKUP($A7,[6]HISTOJANV25!$A$6:$BP$45,10,0)) -> 1 | C7: =VLOOKUP(A7,[7]LISTADHERENT!A$5:H$60,3,0) -> BOUTCHOUANG WILLIAM | D7: =IF(G7="ECHEC",0,B$3) -> 25000 | E7: =D7+VLOOKUP($A7,[6]HISTOJANV25!$A$7:$AT$43,45,0)+F7 -> 50000 | F7: =VLOOKUP($A7,[6]HISTOJANV25!$A$6:$AU$48,8,0) -> 0 | G7: =VLOOKUP($A7,[6]HISTOJANV25!$A$6:$AU$49,9,0) -> BANQUE | H7: =VLOOKUP($A7,[6]HISTOJANV25!$A$6:$AV$49,35,0) -> 0 | I7: =VLOOKUP($A7,[6]HISTOJANV25!$A$6:$AV$49,38,0) -> 0 | J7: =IF(H7=0,0,VLOOKUP($A7,[6]HISTOJANV25!$A$6:$AV$49,42,0)) -> 0 | K7: =VLOOKUP($A7,[6]HISTOJANV25!$A$6:$AV$49,41,0) -> 0 | M7: =VLOOKUP($A7,[6]HISTOJANV25!$A$6:$AV$49,16,0) -> 0 | N7: =IF(M7<>0,VLOOKUP($A7,[6]HISTOJANV25!$A$6:$AV$49,42,0),"ECHEC") -> ECHEC | O7: =IF(R7=0,0,VLOOKUP($A7,[6]HISTOJANV25!$A$6:$AV$49,32,0)) -> 0 | P7: =VLOOKUP($A7,[6]HISTOJANV25!$A$6:$AV$49,33,0) -> 0 | Q7: =IF(R7=0,0,($C$3-R7)) -> 0 | R7: =VLOOKUP($A7,[6]HISTOJANV25!$A$6:$AV$49,29,0) -> 0
A8: AS201604 | B8: =IF(D8=0,0,VLOOKUP($A8,[6]HISTOJANV25!$A$6:$BP$45,10,0)) -> 1 | C8: =VLOOKUP(A8,[7]LISTADHERENT!A$5:H$60,3,0) -> DJOMO JEAN PAUL | D8: =IF(G8="ECHEC",0,B$3) -> 25000 | E8: =D8+VLOOKUP($A8,[6]HISTOJANV25!$A$7:$AT$43,45,0)+F8 -> 50000 | F8: =VLOOKUP($A8,[6]HISTOJANV25!$A$6:$AU$48,8,0) -> 0 | G8: =VLOOKUP($A8,[6]HISTOJANV25!$A$6:$AU$49,9,0) -> BANQUE | H8: =VLOOKUP($A8,[6]HISTOJANV25!$A$6:$AV$49,35,0) -> 0 | I8: =VLOOKUP($A8,[6]HISTOJANV25!$A$6:$AV$49,38,0) -> 0 | J8: =IF(H8=0,0,VLOOKUP($A8,[6]HISTOJANV25!$A$6:$AV$49,42,0)) -> 0 | K8: =VLOOKUP($A8,[6]HISTOJANV25!$A$6:$AV$49,41,0) -> 0 | M8: =VLOOKUP($A8,[6]HISTOJANV25!$A$6:$AV$49,16,0) -> 0 | N8: =IF(M8<>0,VLOOKUP($A8,[6]HISTOJANV25!$A$6:$AV$49,42,0),"ECHEC") -> ECHEC | O8: =IF(R8=0,0,VLOOKUP($A8,[6]HISTOJANV25!$A$6:$AV$49,32,0)) -> BANQUE | P8: =VLOOKUP($A8,[6]HISTOJANV25!$A$6:$AV$49,33,0) -> 0 | Q8: =IF(R8=0,0,($C$3-R8)) -> 269000 | R8: =VLOOKUP($A8,[6]HISTOJANV25!$A$6:$AV$49,29,0) -> 31000
A9: AS201654 | B9: =IF(D9=0,0,VLOOKUP($A9,[6]HISTOJANV25!$A$6:$BP$45,10,0)) -> 1 | C9: =VLOOKUP(A9,[7]LISTADHERENT!A$5:H$60,3,0) -> DJOMOU TCHAPDA | D9: =IF(G9="ECHEC",0,B$3) -> 25000 | E9: =D9+VLOOKUP($A9,[6]HISTOJANV25!$A$7:$AT$43,45,0)+F9 -> 50000 | F9: =VLOOKUP($A9,[6]HISTOJANV25!$A$6:$AU$48,8,0) -> 0 | G9: =VLOOKUP($A9,[6]HISTOJANV25!$A$6:$AU$49,9,0) -> ESPECES | H9: =VLOOKUP($A9,[6]HISTOJANV25!$A$6:$AV$49,35,0) -> 0 | I9: =VLOOKUP($A9,[6]HISTOJANV25!$A$6:$AV$49,38,0) -> 0 | J9: =IF(H9=0,0,VLOOKUP($A9,[6]HISTOJANV25!$A$6:$AV$49,42,0)) -> 0 | K9: =VLOOKUP($A9,[6]HISTOJANV25!$A$6:$AV$49,41,0) -> 0 | M9: =VLOOKUP($A9,[6]HISTOJANV25!$A$6:$AV$49,16,0) -> 0 | N9: =IF(M9<>0,VLOOKUP($A9,[6]HISTOJANV25!$A$6:$AV$49,42,0),"ECHEC") -> ECHEC | O9: =IF(R9=0,0,VLOOKUP($A9,[6]HISTOJANV25!$A$6:$AV$49,32,0)) -> BANQUE | P9: =VLOOKUP($A9,[6]HISTOJANV25!$A$6:$AV$49,33,0) -> 0 | Q9: =IF(R9=0,0,($C$3-R9)) -> 270000 | R9: =VLOOKUP($A9,[6]HISTOJANV25!$A$6:$AV$49,29,0) -> 30000
A10: AS201605 | B10: =IF(D10=0,0,VLOOKUP($A10,[6]HISTOJANV25!$A$6:$BP$45,10,0)) -> 1 | C10: =VLOOKUP(A10,[7]LISTADHERENT!A$5:H$60,3,0) -> DJOUKWE NANGUEN GUY BLAISE | D10: =IF(G10="ECHEC",0,B$3) -> 25000 | E10: =D10+VLOOKUP($A10,[6]HISTOJANV25!$A$7:$AT$43,45,0)+F10 -> 50000 | F10: =VLOOKUP($A10,[6]HISTOJANV25!$A$6:$AU$48,8,0) -> 0 | G10: =VLOOKUP($A10,[6]HISTOJANV25!$A$6:$AU$49,9,0) -> BANQUE | H10: =VLOOKUP($A10,[6]HISTOJANV25!$A$6:$AV$49,35,0) -> 0 | I10: =VLOOKUP($A10,[6]HISTOJANV25!$A$6:$AV$49,38,0) -> 0 | J10: =IF(H10=0,0,VLOOKUP($A10,[6]HISTOJANV25!$A$6:$AV$49,42,0)) -> 0 | K10: =VLOOKUP($A10,[6]HISTOJANV25!$A$6:$AV$49,41,0) -> 0 | M10: =VLOOKUP($A10,[6]HISTOJANV25!$A$6:$AV$49,16,0) -> 0 | N10: =IF(M10<>0,VLOOKUP($A10,[6]HISTOJANV25!$A$6:$AV$49,42,0),"ECHEC") -> ECHEC | O10: =IF(R10=0,0,VLOOKUP($A10,[6]HISTOJANV25!$A$6:$AV$49,32,0)) -> 0 | P10: =VLOOKUP($A10,[6]HISTOJANV25!$A$6:$AV$49,33,0) -> 0 | Q10: =IF(R10=0,0,($C$3-R10)) -> 0 | R10: =VLOOKUP($A10,[6]HISTOJANV25!$A$6:$AV$49,29,0) -> 0
A11: AS201608 | B11: =IF(D11=0,0,VLOOKUP($A11,[6]HISTOJANV25!$A$6:$BP$45,10,0)) -> 1 | C11: =VLOOKUP(A11,[7]LISTADHERENT!A$5:H$60,3,0) -> DJUOMBESSY ANTOINE | D11: =IF(G11="ECHEC",0,B$3) -> 25000 | E11: =D11+VLOOKUP($A11,[6]HISTOJANV25!$A$7:$AT$43,45,0)+F11 -> 60000 | F11: =VLOOKUP($A11,[6]HISTOJANV25!$A$6:$AU$48,8,0) -> 0 | G11: =VLOOKUP($A11,[6]HISTOJANV25!$A$6:$AU$49,9,0) -> BANQUE | H11: =VLOOKUP($A11,[6]HISTOJANV25!$A$6:$AV$49,35,0) -> 0 | I11: =VLOOKUP($A11,[6]HISTOJANV25!$A$6:$AV$49,38,0) -> 0 | J11: =IF(H11=0,0,VLOOKUP($A11,[6]HISTOJANV25!$A$6:$AV$49,42,0)) -> 0 | K11: =VLOOKUP($A11,[6]HISTOJANV25!$A$6:$AV$49,41,0) -> 0 | M11: =VLOOKUP($A11,[6]HISTOJANV25!$A$6:$AV$49,16,0) -> 0 | N11: =IF(M11<>0,VLOOKUP($A11,[6]HISTOJANV25!$A$6:$AV$49,42,0),"ECHEC") -> ECHEC | O11: =IF(R11=0,0,VLOOKUP($A11,[6]HISTOJANV25!$A$6:$AV$49,32,0)) -> 0 | P11: =VLOOKUP($A11,[6]HISTOJANV25!$A$6:$AV$49,33,0) -> 0 | Q11: =IF(R11=0,0,($C$3-R11)) -> 0 | R11: =VLOOKUP($A11,[6]HISTOJANV25!$A$6:$AV$49,29,0) -> 0
A12: AS201651 | B12: =IF(D12=0,0,VLOOKUP($A12,[6]HISTOJANV25!$A$6:$BP$45,10,0)) -> 1 | C12: =VLOOKUP(A12,[7]LISTADHERENT!A$5:H$60,3,0) -> DOMOU FABIEN | D12: =IF(G12="ECHEC",0,B$3) -> 25000 | E12: =D12+VLOOKUP($A12,[6]HISTOJANV25!$A$7:$AT$43,45,0)+F12 -> 50000 | F12: =VLOOKUP($A12,[6]HISTOJANV25!$A$6:$AU$48,8,0) -> 0 | G12: =VLOOKUP($A12,[6]HISTOJANV25!$A$6:$AU$49,9,0) -> BANQUE | H12: =VLOOKUP($A12,[6]HISTOJANV25!$A$6:$AV$49,35,0) -> 0 | I12: =VLOOKUP($A12,[6]HISTOJANV25!$A$6:$AV$49,38,0) -> 0 | J12: =IF(H12=0,0,VLOOKUP($A12,[6]HISTOJANV25!$A$6:$AV$49,42,0)) -> 0 | K12: =VLOOKUP($A12,[6]HISTOJANV25!$A$6:$AV$49,41,0) -> 0 | M12: =VLOOKUP($A12,[6]HISTOJANV25!$A$6:$AV$49,16,0) -> 0 | N12: =IF(M12<>0,VLOOKUP($A12,[6]HISTOJANV25!$A$6:$AV$49,42,0),"ECHEC") -> ECHEC | O12: =IF(R12=0,0,VLOOKUP($A12,[6]HISTOJANV25!$A$6:$AV$49,32,0)) -> 0 | P12: =VLOOKUP($A12,[6]HISTOJANV25!$A$6:$AV$49,33,0) -> 0 | Q12: =IF(R12=0,0,($C$3-R12)) -> 0 | R12: =VLOOKUP($A12,[6]HISTOJANV25!$A$6:$AV$49,29,0) -> 0
A13: AS201609 | B13: =IF(D13=0,0,VLOOKUP($A13,[6]HISTOJANV25!$A$6:$BP$45,10,0)) -> 1 | C13: =VLOOKUP(A13,[7]LISTADHERENT!A$5:H$60,3,0) -> DONHOU DAVID | D13: =IF(G13="ECHEC",0,B$3) -> 25000 | E13: =D13+VLOOKUP($A13,[6]HISTOJANV25!$A$7:$AT$43,45,0)+F13 -> 50000 | F13: =VLOOKUP($A13,[6]HISTOJANV25!$A$6:$AU$48,8,0) -> 0 | G13: =VLOOKUP($A13,[6]HISTOJANV25!$A$6:$AU$49,9,0) -> BANQUE | H13: =VLOOKUP($A13,[6]HISTOJANV25!$A$6:$AV$49,35,0) -> 0 | I13: =VLOOKUP($A13,[6]HISTOJANV25!$A$6:$AV$49,38,0) -> 0 | J13: =IF(H13=0,0,VLOOKUP($A13,[6]HISTOJANV25!$A$6:$AV$49,42,0)) -> 0 | K13: =VLOOKUP($A13,[6]HISTOJANV25!$A$6:$AV$49,41,0) -> 0 | M13: =VLOOKUP($A13,[6]HISTOJANV25!$A$6:$AV$49,16,0) -> 0 | N13: =IF(M13<>0,VLOOKUP($A13,[6]HISTOJANV25!$A$6:$AV$49,42,0),"ECHEC") -> ECHEC | O13: =IF(R13=0,0,VLOOKUP($A13,[6]HISTOJANV25!$A$6:$AV$49,32,0)) -> 0 | P13: =VLOOKUP($A13,[6]HISTOJANV25!$A$6:$AV$49,33,0) -> 0 | Q13: =IF(R13=0,0,($C$3-R13)) -> 0 | R13: =VLOOKUP($A13,[6]HISTOJANV25!$A$6:$AV$49,29,0) -> 0
A14: AS201663 | B14: =IF(D14=0,0,VLOOKUP($A14,[6]HISTOJANV25!$A$6:$BP$45,10,0)) -> 0 | C14: =VLOOKUP(A14,[7]LISTADHERENT!A$5:H$60,3,0) -> FAMPOU PAUL | D14: =IF(G14="ECHEC",0,B$3) -> 0 | E14: =D14+VLOOKUP($A14,[6]HISTOJANV25!$A$7:$AT$43,45,0)+F14 -> 0 | F14: =VLOOKUP($A14,[6]HISTOJANV25!$A$6:$AU$48,8,0) -> 0 | G14: =VLOOKUP($A14,[6]HISTOJANV25!$A$6:$AU$49,9,0) -> ECHEC | H14: =VLOOKUP($A14,[6]HISTOJANV25!$A$6:$AV$49,35,0) -> 0 | I14: =VLOOKUP($A14,[6]HISTOJANV25!$A$6:$AV$49,38,0) -> 0 | J14: =IF(H14=0,0,VLOOKUP($A14,[6]HISTOJANV25!$A$6:$AV$49,42,0)) -> 0 | K14: =VLOOKUP($A14,[6]HISTOJANV25!$A$6:$AV$49,41,0) -> 0 | M14: =VLOOKUP($A14,[6]HISTOJANV25!$A$6:$AV$49,16,0) -> 0 | N14: =IF(M14<>0,VLOOKUP($A14,[6]HISTOJANV25!$A$6:$AV$49,42,0),"ECHEC") -> ECHEC | O14: =IF(R14=0,0,VLOOKUP($A14,[6]HISTOJANV25!$A$6:$AV$49,32,0)) -> 0 | P14: =VLOOKUP($A14,[6]HISTOJANV25!$A$6:$AV$49,33,0) -> 0 | Q14: =IF(R14=0,0,($C$3-R14)) -> 0 | R14: =VLOOKUP($A14,[6]HISTOJANV25!$A$6:$AV$49,29,0) -> 0
A15: AS201611 | B15: =IF(D15=0,0,VLOOKUP($A15,[6]HISTOJANV25!$A$6:$BP$45,10,0)) -> 1 | C15: =VLOOKUP(A15,[7]LISTADHERENT!A$5:H$60,3,0) -> HENGUE PAUL OMER | D15: =IF(G15="ECHEC",0,B$3) -> 25000 | E15: =D15+VLOOKUP($A15,[6]HISTOJANV25!$A$7:$AT$43,45,0)+F15 -> 50000 | F15: =VLOOKUP($A15,[6]HISTOJANV25!$A$6:$AU$48,8,0) -> 0 | G15: =VLOOKUP($A15,[6]HISTOJANV25!$A$6:$AU$49,9,0) -> BANQUE | H15: =VLOOKUP($A15,[6]HISTOJANV25!$A$6:$AV$49,35,0) -> 0 | I15: =VLOOKUP($A15,[6]HISTOJANV25!$A$6:$AV$49,38,0) -> 0 | J15: =IF(H15=0,0,VLOOKUP($A15,[6]HISTOJANV25!$A$6:$AV$49,42,0)) -> 0 | K15: =VLOOKUP($A15,[6]HISTOJANV25!$A$6:$AV$49,41,0) -> 0 | M15: =VLOOKUP($A15,[6]HISTOJANV25!$A$6:$AV$49,16,0) -> 0 | N15: =IF(M15<>0,VLOOKUP($A15,[6]HISTOJANV25!$A$6:$AV$49,42,0),"ECHEC") -> ECHEC | O15: =IF(R15=0,0,VLOOKUP($A15,[6]HISTOJANV25!$A$6:$AV$49,32,0)) -> 0 | P15: =VLOOKUP($A15,[6]HISTOJANV25!$A$6:$AV$49,33,0) -> 0 | Q15: =IF(R15=0,0,($C$3-R15)) -> 0 | R15: =VLOOKUP($A15,[6]HISTOJANV25!$A$6:$AV$49,29,0) -> 0
A16: AS201613 | B16: =IF(D16=0,0,VLOOKUP($A16,[6]HISTOJANV25!$A$6:$BP$45,10,0)) -> 1 | C16: =VLOOKUP(A16,[7]LISTADHERENT!A$5:H$60,3,0) -> HOTCHO BENJAMIN | D16: =IF(G16="ECHEC",0,B$3) -> 25000 | E16: =D16+VLOOKUP($A16,[6]HISTOJANV25!$A$7:$AT$43,45,0)+F16 -> 100000 | F16: =VLOOKUP($A16,[6]HISTOJANV25!$A$6:$AU$48,8,0) -> 0 | G16: =VLOOKUP($A16,[6]HISTOJANV25!$A$6:$AU$49,9,0) -> BANQUE | H16: =VLOOKUP($A16,[6]HISTOJANV25!$A$6:$AV$49,35,0) -> 0 | I16: =VLOOKUP($A16,[6]HISTOJANV25!$A$6:$AV$49,38,0) -> 0 | J16: =IF(H16=0,0,VLOOKUP($A16,[6]HISTOJANV25!$A$6:$AV$49,42,0)) -> 0 | K16: =VLOOKUP($A16,[6]HISTOJANV25!$A$6:$AV$49,41,0) -> 0 | M16: =VLOOKUP($A16,[6]HISTOJANV25!$A$6:$AV$49,16,0) -> 0 | N16: =IF(M16<>0,VLOOKUP($A16,[6]HISTOJANV25!$A$6:$AV$49,42,0),"ECHEC") -> ECHEC | O16: =IF(R16=0,0,VLOOKUP($A16,[6]HISTOJANV25!$A$6:$AV$49,32,0)) -> 0 | P16: =VLOOKUP($A16,[6]HISTOJANV25!$A$6:$AV$49,33,0) -> 0 | Q16: =IF(R16=0,0,($C$3-R16)) -> 0 | R16: =VLOOKUP($A16,[6]HISTOJANV25!$A$6:$AV$49,29,0) -> 0
A17: AS201617 | B17: =IF(D17=0,0,VLOOKUP($A17,[6]HISTOJANV25!$A$6:$BP$45,10,0)) -> 1 | C17: =VLOOKUP(A17,[7]LISTADHERENT!A$5:H$60,3,0) -> KOUAMOU MOISE | D17: =IF(G17="ECHEC",0,B$3) -> 25000 | E17: =D17+VLOOKUP($A17,[6]HISTOJANV25!$A$7:$AT$43,45,0)+F17 -> 50000 | F17: =VLOOKUP($A17,[6]HISTOJANV25!$A$6:$AU$48,8,0) -> 0 | G17: =VLOOKUP($A17,[6]HISTOJANV25!$A$6:$AU$49,9,0) -> BANQUE | H17: =VLOOKUP($A17,[6]HISTOJANV25!$A$6:$AV$49,35,0) -> 0 | I17: =VLOOKUP($A17,[6]HISTOJANV25!$A$6:$AV$49,38,0) -> 0 | J17: =IF(H17=0,0,VLOOKUP($A17,[6]HISTOJANV25!$A$6:$AV$49,42,0)) -> 0 | K17: =VLOOKUP($A17,[6]HISTOJANV25!$A$6:$AV$49,41,0) -> 0 | M17: =VLOOKUP($A17,[6]HISTOJANV25!$A$6:$AV$49,16,0) -> 0 | N17: =IF(M17<>0,VLOOKUP($A17,[6]HISTOJANV25!$A$6:$AV$49,42,0),"ECHEC") -> ECHEC | O17: =IF(R17=0,0,VLOOKUP($A17,[6]HISTOJANV25!$A$6:$AV$49,32,0)) -> 0 | P17: =VLOOKUP($A17,[6]HISTOJANV25!$A$6:$AV$49,33,0) -> 0 | Q17: =IF(R17=0,0,($C$3-R17)) -> 0 | R17: =VLOOKUP($A17,[6]HISTOJANV25!$A$6:$AV$49,29,0) -> 0
... A40: AS201647 | B40: =IF(D40=0,0,VLOOKUP($A40,[6]HISTOJANV25!$A$6:$BP$45,10,0)) -> 1 | C40: =VLOOKUP(A40,[7]LISTADHERENT!A$5:H$60,3,0) -> YOUMBI EMMANUEL | D40: =IF(G40="ECHEC",0,B$3) -> 25000 | E40: =D40+VLOOKUP($A40,[6]HISTOJANV25!$A$7:$AT$43,45,0)+F40 -> 50000 | F40: =VLOOKUP($A40,[6]HISTOJANV25!$A$6:$AU$48,8,0) -> 0 | G40: =VLOOKUP($A40,[6]HISTOJANV25!$A$6:$AU$49,9,0) -> BANQUE | H40: =VLOOKUP($A40,[6]HISTOJANV25!$A$6:$AV$49,35,0) -> 0 | I40: =VLOOKUP($A40,[6]HISTOJANV25!$A$6:$AV$49,38,0) -> 0 | J40: =IF(H40=0,0,VLOOKUP($A40,[6]HISTOJANV25!$A$6:$AV$49,42,0)) -> 0 | K40: =VLOOKUP($A40,[6]HISTOJANV25!$A$6:$AV$49,41,0) -> 0 | M40: =VLOOKUP($A40,[6]HISTOJANV25!$A$6:$AV$49,16,0) -> 0 | N40: =IF(M40<>0,VLOOKUP($A40,[6]HISTOJANV25!$A$6:$AV$49,42,0),"ECHEC") -> ECHEC | O40: =IF(R40=0,0,VLOOKUP($A40,[6]HISTOJANV25!$A$6:$AV$49,32,0)) -> 0 | P40: =VLOOKUP($A40,[6]HISTOJANV25!$A$6:$AV$49,33,0) -> 0 | Q40: =IF(R40=0,0,($C$3-R40)) -> 0 | R40: =VLOOKUP($A40,[6]HISTOJANV25!$A$6:$AV$49,29,0) -> 0
A42: TOTAL PART | B42: =SUM(B6:B41) -> 34
A43: NBRE ADHERENT | B43: =COUNT(D6:D41) -> 35 | D43: =SUM(D6:D42) -> 850000 | F43: =SUM(F6:F42) -> 0 | G43: =SUM(G6:G42) -> 0 | H43: =SUM(H6:H42) -> 41000 | I43: =SUM(I6:I42) -> 1000 | J43: =SUM(J6:J42) -> 0 | K43: =SUM(K6:K42) -> 0 | L43: =SUM(L6:L42) -> 0 | M43: =SUM(M6:M42) -> 0 | ... R43: =SUM(R6:R42) -> 91000
N44: NBRE PART | O44: PART VENDUE
D45: MONTANT TONTINE | G45: REMBOURSEMENT PETIT LOT | H45: VENTE PETIT LOT | I45: VENTE LOT PRINCIPAL | J45: SOLDE EN CAISSE | L45: TONTINE + REMB + INTERET VENTE | M45: =D49+G49+R43 -> 941000
D46: =SUMIFS(D6:D42,G6:G42,"ESPECES") -> 100000 | F46: ESPECES | G46: =SUMIFS(M6:M35,N6:N35,"ESPECES") -> 0 | H46: =SUMIFS(H6:H42,J6:J42,"ESPECES") -> 0 | I46: =SUMIFS(Q6:Q42,O6:O42,"ESPECES") -> 0 | J46: =D46+G46-H46-I46 -> 100000 | L46: LOT PRINCIPAL | M46: =C3*COUNTIF(Q7:Q42,">0") -> 900000 | N46: =D3 -> 3 | O46: =COUNTIF(Q7:Q35,">0") -> 3
D47: =SUMIFS(D6:D42,G6:G42,"BANQUE") -> 750000 | F47: BANQUE | G47: =SUMIFS(M6:M35,N6:N35,"BANQUE") -> 0 | H47: =SUMIFS(H6:H42,J6:J42,"BANQUE") -> 41000 | I47: =SUMIFS(Q6:Q42,O6:O42,"BANQUE") -> 809000 | J47: =D47+G47-H47-I47 -> -100000
L48: PETIT LOT | M48: =M45-M46 -> 41000
D49: =D46+D47 -> 850000 | F49: TOTAL | G49: =G46+G47 -> 0 | H49: =H46+H47 -> 41000 | I49: =I46+I47 -> 809000 | J49: =J46+J47 -> 0
F50: TOTAL+DEPOT | L50: RELIQUAT | M50: =M48-H43 -> 0 | O50: =M50 -> 0 | P50: CUMUL
L52: ECHEC TONTINE MOIS | M52: =COUNTIFS(G7:G41,"ECHEC")*23000 -> 23000 | P52: CUMUL
L53: ECHEC REMBOURSEMENT MOIS | M53: =L43-G49 -> 0 | P53: CUMUL

Sheet TONTFEV25
A1: ASSOCIATION | B1: ASELBY
A2: ANNEE | B2: 2025 | C2: TONIINE | D2: NBRE PART
A3: TAUX TONTINE | B3: 25000 | C3: =B3*12 -> 300000 | D3: =ROUNDDOWN(M45/C3,0) -> 3
C4: 45701
A5: MATRICULE | B5: NBREPART | C5: NOM ET PRENOM | D5: MONTANT TONTINE | E5: MONTANT VERSE | F5: PENALITE VERSEMENT ESPECES | G5: MODE VERSEMENT | H5: VENTE PETIT LOT | I5: INTERET PETIT LOT | J5: MODE VERSEMENT VENTE PETIT LOT | K5: NUMERO CHEQUE | L5: MONTANT A REMBOURSER PETIT LOT | M5: REMBOURSEMENT PETIT LOT | N5: MODE VERSEMENT REMBOURSEMENT | O5: MODE VERSEMENTLOT PRINCIPAL | P5: NUMERO CHEQUE | Q5: MONTANT LOT PRINCIPAL | R5: INTERET LOT PRINCIPAL
A6: AS201601 | B6: =IF(D6=0,0,VLOOKUP($A6,[6]HISTOFEV25!$A$6:$BP$45,10,0)) -> 1 | C6: =VLOOKUP(A6,[7]LISTADHERENT!A$5:H$60,3,0) -> BAKOP ACHILLE | D6: =IF(G6="ECHEC",0,B$3) -> 25000 | E6: =D6+VLOOKUP($A6,[6]HISTOFEV25!$A$7:$AT$43,45,0)+F6 -> 50000 | F6: =VLOOKUP($A6,[6]HISTOFEV25!$A$6:$AU$48,8,0) -> 0 | G6: =VLOOKUP($A6,[6]HISTOFEV25!$A$6:$AU$49,9,0) -> ESPECES | H6: =VLOOKUP($A6,[6]HISTOFEV25!$A$6:$AV$49,35,0) -> 0 | I6: =VLOOKUP($A6,[6]HISTOFEV25!$A$6:$AV$49,38,0) -> 0 | J6: =IF(I6=0,"",VLOOKUP($A6,[6]HISTOFEV25!$A$6:$AV$47,42,0)) | K6: =VLOOKUP($A6,[6]HISTOFEV25!$A$6:$AV$49,41,0) -> 0 | L6: =TONTJANV25!H6+TONTJANV25!I6 -> 0 | M6: =VLOOKUP($A6,[6]HISTOFEV25!$A$6:$AV$49,16,0) -> 0 | N6: =IF(M6<>0,VLOOKUP($A6,[6]HISTOFEV25!$A$6:$AV$49,42,0),"ECHEC") -> ECHEC | O6: =IF(R6=0,0,VLOOKUP($A6,[6]HISTOFEV25!$A$6:$AV$49,32,0)) -> 0 | P6: =VLOOKUP($A6,[6]HISTOFEV25!$A$6:$AV$49,33,0) -> 0 | Q6: =IF(R6=0,0,($C$3-R6)) -> 0 | R6: =VLOOKUP($A6,[6]HISTOFEV25!$A$6:$AV$49,29,0) -> 0
A7: AS201602 | B7: =IF(D7=0,0,VLOOKUP($A7,[6]HISTOFEV25!$A$6:$BP$45,10,0)) -> 1 | C7: =VLOOKUP(A7,[7]LISTADHERENT!A$5:H$60,3,0) -> BOUTCHOUANG WILLIAM | D7: =IF(G7="ECHEC",0,B$3) -> 25000 | E7: =D7+VLOOKUP($A7,[6]HISTOFEV25!$A$7:$AT$43,45,0)+F7 -> 50000 | F7: =VLOOKUP($A7,[6]HISTOFEV25!$A$6:$AU$48,8,0) -> 0 | G7: =VLOOKUP($A7,[6]HISTOFEV25!$A$6:$AU$49,9,0) -> BANQUE | H7: =VLOOKUP($A7,[6]HISTOFEV25!$A$6:$AV$49,35,0) -> 0 | I7: =VLOOKUP($A7,[6]HISTOFEV25!$A$6:$AV$49,38,0) -> 0 | J7: =IF(I7=0,"",VLOOKUP($A7,[6]HISTOFEV25!$A$6:$AV$47,42,0)) | K7: =VLOOKUP($A7,[6]HISTOFEV25!$A$6:$AV$49,41,0) -> 0 | L7: =TONTJANV25!H7+TONTJANV25!I7 -> 0 | M7: =VLOOKUP($A7,[6]HISTOFEV25!$A$6:$AV$49,16,0) -> 0 | N7: =IF(M7<>0,VLOOKUP($A7,[6]HISTOFEV25!$A$6:$AV$49,42,0),"ECHEC") -> ECHEC | O7: =IF(R7=0,0,VLOOKUP($A7,[6]HISTOFEV25!$A$6:$AV$49,32,0)) -> 0 | P7: =VLOOKUP($A7,[6]HISTOFEV25!$A$6:$AV$49,33,0) -> 0 | Q7: =IF(R7=0,0,($C$3-R7)) -> 0 | R7: =VLOOKUP($A7,[6]HISTOFEV25!$A$6:$AV$49,29,0) -> 0
A8: AS201604 | B8: =IF(D8=0,0,VLOOKUP($A8,[6]HISTOFEV25!$A$6:$BP$45,10,0)) -> 1 | C8: =VLOOKUP(A8,[7]LISTADHERENT!A$5:H$60,3,0) -> DJOMO JEAN PAUL | D8: =IF(G8="ECHEC",0,B$3) -> 25000 | E8: =D8+VLOOKUP($A8,[6]HISTOFEV25!$A$7:$AT$43,45,0)+F8 -> 50000 | F8: =VLOOKUP($A8,[6]HISTOFEV25!$A$6:$AU$48,8,0) -> 0 | G8: =VLOOKUP($A8,[6]HISTOFEV25!$A$6:$AU$49,9,0) -> BANQUE | H8: =VLOOKUP($A8,[6]HISTOFEV25!$A$6:$AV$49,35,0) -> 0 | I8: =VLOOKUP($A8,[6]HISTOFEV25!$A$6:$AV$49,38,0) -> 0 | J8: =IF(I8=0,"",VLOOKUP($A8,[6]HISTOFEV25!$A$6:$AV$47,42,0)) | K8: =VLOOKUP($A8,[6]HISTOFEV25!$A$6:$AV$49,41,0) -> 0 | L8: =TONTJANV25!H8+TONTJANV25!I8 -> 0 | M8: =VLOOKUP($A8,[6]HISTOFEV25!$A$6:$AV$49,16,0) -> 0 | N8: =IF(M8<>0,VLOOKUP($A8,[6]HISTOFEV25!$A$6:$AV$49,42,0),"ECHEC") -> ECHEC | O8: =IF(R8=0,0,VLOOKUP($A8,[6]HISTOFEV25!$A$6:$AV$49,32,0)) -> 0 | P8: =VLOOKUP($A8,[6]HISTOFEV25!$A$6:$AV$49,33,0) -> 0 | Q8: =IF(R8=0,0,($C$3-R8)) -> 0 | R8: =VLOOKUP($A8,[6]HISTOFEV25!$A$6:$AV$49,29,0) -> 0
A9: AS201654 | B9: =IF(D9=0,0,VLOOKUP($A9,[6]HISTOFEV25!$A$6:$BP$45,10,0)) -> 1 | C9: =VLOOKUP(A9,[7]LISTADHERENT!A$5:H$60,3,0) -> DJOMOU TCHAPDA | D9: =IF(G9="ECHEC",0,B$3) -> 25000 | E9: =D9+VLOOKUP($A9,[6]HISTOFEV25!$A$7:$AT$43,45,0)+F9 -> 50000 | F9: =VLOOKUP($A9,[6]HISTOFEV25!$A$6:$AU$48,8,0) -> 0 | G9: =VLOOKUP($A9,[6]HISTOFEV25!$A$6:$AU$49,9,0) -> BANQUE | H9: =VLOOKUP($A9,[6]HISTOFEV25!$A$6:$AV$49,35,0) -> 40000 | I9: =VLOOKUP($A9,[6]HISTOFEV25!$A$6:$AV$49,38,0) -> 1000 | J9: =IF(I9=0,"",VLOOKUP($A9,[6]HISTOFEV25!$A$6:$AV$47,42,0)) -> BANQUE | K9: =VLOOKUP($A9,[6]HISTOFEV25!$A$6:$AV$49,41,0) -> 0 | L9: =TONTJANV25!H9+TONTJANV25!I9 -> 0 | M9: =VLOOKUP($A9,[6]HISTOFEV25!$A$6:$AV$49,16,0) -> 0 | N9: =IF(M9<>0,VLOOKUP($A9,[6]HISTOFEV25!$A$6:$AV$49,42,0),"ECHEC") -> ECHEC | O9: =IF(R9=0,0,VLOOKUP($A9,[6]HISTOFEV25!$A$6:$AV$49,32,0)) -> 0 | P9: =VLOOKUP($A9,[6]HISTOFEV25!$A$6:$AV$49,33,0) -> 0 | Q9: =IF(R9=0,0,($C$3-R9)) -> 0 | R9: =VLOOKUP($A9,[6]HISTOFEV25!$A$6:$AV$49,29,0) -> 0
A10: AS201605 | B10: =IF(D10=0,0,VLOOKUP($A10,[6]HISTOFEV25!$A$6:$BP$45,10,0)) -> 1 | C10: =VLOOKUP(A10,[7]LISTADHERENT!A$5:H$60,3,0) -> DJOUKWE NANGUEN GUY BLAISE | D10: =IF(G10="ECHEC",0,B$3) -> 25000 | E10: =D10+VLOOKUP($A10,[6]HISTOFEV25!$A$7:$AT$43,45,0)+F10 -> 50375 | F10: =VLOOKUP($A10,[6]HISTOFEV25!$A$6:$AU$48,8,0) -> 0 | G10: =VLOOKUP($A10,[6]HISTOFEV25!$A$6:$AU$49,9,0) -> BANQUE | H10: =VLOOKUP($A10,[6]HISTOFEV25!$A$6:$AV$49,35,0) -> 0 | I10: =VLOOKUP($A10,[6]HISTOFEV25!$A$6:$AV$49,38,0) -> 0 | J10: =IF(I10=0,"",VLOOKUP($A10,[6]HISTOFEV25!$A$6:$AV$47,42,0)) | K10: =VLOOKUP($A10,[6]HISTOFEV25!$A$6:$AV$49,41,0) -> 0 | L10: =TONTJANV25!H10+TONTJANV25!I10 -> 0 | M10: =VLOOKUP($A10,[6]HISTOFEV25!$A$6:$AV$49,16,0) -> 0 | N10: =IF(M10<>0,VLOOKUP($A10,[6]HISTOFEV25!$A$6:$AV$49,42,0),"ECHEC") -> ECHEC | O10: =IF(R10=0,0,VLOOKUP($A10,[6]HISTOFEV25!$A$6:$AV$49,32,0)) -> 0 | P10: =VLOOKUP($A10,[6]HISTOFEV25!$A$6:$AV$49,33,0) -> 0 | Q10: =IF(R10=0,0,($C$3-R10)) -> 0 | R10: =VLOOKUP($A10,[6]HISTOFEV25!$A$6:$AV$49,29,0) -> 0
A11: AS201608 | B11: =IF(D11=0,0,VLOOKUP($A11,[6]HISTOFEV25!$A$6:$BP$45,10,0)) -> 1 | C11: =VLOOKUP(A11,[7]LISTADHERENT!A$5:H$60,3,0) -> DJUOMBESSY ANTOINE | D11: =IF(G11="ECHEC",0,B$3) -> 25000 | E11: =D11+VLOOKUP($A11,[6]HISTOFEV25!$A$7:$AT$43,45,0)+F11 -> 710000 | F11: =VLOOKUP($A11,[6]HISTOFEV25!$A$6:$AU$48,8,0) -> 0 | G11: =VLOOKUP($A11,[6]HISTOFEV25!$A$6:$AU$49,9,0) -> BANQUE | H11: =VLOOKUP($A11,[6]HISTOFEV25!$A$6:$AV$49,35,0) -> 0 | I11: =VLOOKUP($A11,[6]HISTOFEV25!$A$6:$AV$49,38,0) -> 0 | J11: =IF(I11=0,"",VLOOKUP($A11,[6]HISTOFEV25!$A$6:$AV$47,42,0)) | K11: =VLOOKUP($A11,[6]HISTOFEV25!$A$6:$AV$49,41,0) -> 0 | L11: =TONTJANV25!H11+TONTJANV25!I11 -> 0 | M11: =VLOOKUP($A11,[6]HISTOFEV25!$A$6:$AV$49,16,0) -> 0 | N11: =IF(M11<>0,VLOOKUP($A11,[6]HISTOFEV25!$A$6:$AV$49,42,0),"ECHEC") -> ECHEC | O11: =IF(R11=0,0,VLOOKUP($A11,[6]HISTOFEV25!$A$6:$AV$49,32,0)) -> 0 | P11: =VLOOKUP($A11,[6]HISTOFEV25!$A$6:$AV$49,33,0) -> 0 | Q11: =IF(R11=0,0,($C$3-R11)) -> 0 | R11: =VLOOKUP($A11,[6]HISTOFEV25!$A$6:$AV$49,29,0) -> 0
A12: AS201651 | B12: =IF(D12=0,0,VLOOKUP($A12,[6]HISTOFEV25!$A$6:$BP$45,10,0)) -> 1 | C12: =VLOOKUP(A12,[7]LISTADHERENT!A$5:H$60,3,0) -> DOMOU FABIEN | D12: =IF(G12="ECHEC",0,B$3) -> 25000 | E12: =D12+VLOOKUP($A12,[6]HISTOFEV25!$A$7:$AT$43,45,0)+F12 -> 50000 | F12: =VLOOKUP($A12,[6]HISTOFEV25!$A$6:$AU$48,8,0) -> 0 | G12: =VLOOKUP($A12,[6]HISTOFEV25!$A$6:$AU$49,9,0) -> BANQUE | H12: =VLOOKUP($A12,[6]HISTOFEV25!$A$6:$AV$49,35,0) -> 0 | I12: =VLOOKUP($A12,[6]HISTOFEV25!$A$6:$AV$49,38,0) -> 0 | J12: =IF(I12=0,"",VLOOKUP($A12,[6]HISTOFEV25!$A$6:$AV$47,42,0)) | K12: =VLOOKUP($A12,[6]HISTOFEV25!$A$6:$AV$49,41,0) -> 0 | L12: =TONTJANV25!H12+TONTJANV25!I12 -> 0 | M12: =VLOOKUP($A12,[6]HISTOFEV25!$A$6:$AV$49,16,0) -> 0 | N12: =IF(M12<>0,VLOOKUP($A12,[6]HISTOFEV25!$A$6:$AV$49,42,0),"ECHEC") -> ECHEC | O12: =IF(R12=0,0,VLOOKUP($A12,[6]HISTOFEV25!$A$6:$AV$49,32,0)) -> 0 | P12: =VLOOKUP($A12,[6]HISTOFEV25!$A$6:$AV$49,33,0) -> 0 | Q12: =IF(R12=0,0,($C$3-R12)) -> 0 | R12: =VLOOKUP($A12,[6]HISTOFEV25!$A$6:$AV$49,29,0) -> 0
A13: AS201609 | B13: =IF(D13=0,0,VLOOKUP($A13,[6]HISTOFEV25!$A$6:$BP$45,10,0)) -> 1 | C13: =VLOOKUP(A13,[7]LISTADHERENT!A$5:H$60,3,0) -> DONHOU DAVID | D13: =IF(G13="ECHEC",0,B$3) -> 25000 | E13: =D13+VLOOKUP($A13,[6]HISTOFEV25!$A$7:$AT$43,45,0)+F13 -> 50000 | F13: =VLOOKUP($A13,[6]HISTOFEV25!$A$6:$AU$48,8,0) -> 0 | G13: =VLOOKUP($A13,[6]HISTOFEV25!$A$6:$AU$49,9,0) -> BANQUE | H13: =VLOOKUP($A13,[6]HISTOFEV25!$A$6:$AV$49,35,0) -> 0 | I13: =VLOOKUP($A13,[6]HISTOFEV25!$A$6:$AV$49,38,0) -> 0 | J13: =IF(I13=0,"",VLOOKUP($A13,[6]HISTOFEV25!$A$6:$AV$47,42,0)) | K13: =VLOOKUP($A13,[6]HISTOFEV25!$A$6:$AV$49,41,0) -> 0 | L13: =TONTJANV25!H13+TONTJANV25!I13 -> 0 | M13: =VLOOKUP($A13,[6]HISTOFEV25!$A$6:$AV$49,16,0) -> 0 | N13: =IF(M13<>0,VLOOKUP($A13,[6]HISTOFEV25!$A$6:$AV$49,42,0),"ECHEC") -> ECHEC | O13: =IF(R13=0,0,VLOOKUP($A13,[6]HISTOFEV25!$A$6:$AV$49,32,0)) -> 0 | P13: =VLOOKUP($A13,[6]HISTOFEV25!$A$6:$AV$49,33,0) -> 0 | Q13: =IF(R13=0,0,($C$3-R13)) -> 0 | R13: =VLOOKUP($A13,[6]HISTOFEV25!$A$6:$AV$49,29,0) -> 0
A14: AS201663 | B14: =IF(D14=0,0,VLOOKUP($A14,[6]HISTOFEV25!$A$6:$BP$45,10,0)) -> 1 | C14: =VLOOKUP(A14,[7]LISTADHERENT!A$5:H$60,3,0) -> FAMPOU PAUL | D14: =IF(G14="ECHEC",0,B$3) -> 25000 | E14: =D14+VLOOKUP($A14,[6]HISTOFEV25!$A$7:$AT$43,45,0)+F14 -> 75000 | F14: =VLOOKUP($A14,[6]HISTOFEV25!$A$6:$AU$48,8,0) -> 0 | G14: =VLOOKUP($A14,[6]HISTOFEV25!$A$6:$AU$49,9,0) -> ESPECES | H14: =VLOOKUP($A14,[6]HISTOFEV25!$A$6:$AV$49,35,0) -> 0 | I14: =VLOOKUP($A14,[6]HISTOFEV25!$A$6:$AV$49,38,0) -> 0 | J14: =IF(I14=0,"",VLOOKUP($A14,[6]HISTOFEV25!$A$6:$AV$47,42,0)) | K14: =VLOOKUP($A14,[6]HISTOFEV25!$A$6:$AV$49,41,0) -> 0 | L14: =TONTJANV25!H14+TONTJANV25!I14 -> 0 | M14: =VLOOKUP($A14,[6]HISTOFEV25!$A$6:$AV$49,16,0) -> 0 | N14: =IF(M14<>0,VLOOKUP($A14,[6]HISTOFEV25!$A$6:$AV$49,42,0),"ECHEC") -> ECHEC | O14: =IF(R14=0,0,VLOOKUP($A14,[6]HISTOFEV25!$A$6:$AV$49,32,0)) -> 0 | P14: =VLOOKUP($A14,[6]HISTOFEV25!$A$6:$AV$49,33,0) -> 0 | Q14: =IF(R14=0,0,($C$3-R14)) -> 0 | R14: =VLOOKUP($A14,[6]HISTOFEV25!$A$6:$AV$49,29,0) -> 0
A15: AS201611 | B15: =IF(D15=0,0,VLOOKUP($A15,[6]HISTOFEV25!$A$6:$BP$45,10,0)) -> 1 | C15: =VLOOKUP(A15,[7]LISTADHERENT!A$5:H$60,3,0) -> HENGUE PAUL OMER | D15: =IF(G15="ECHEC",0,B$3) -> 25000 | E15: =D15+VLOOKUP($A15,[6]HISTOFEV25!$A$7:$AT$43,45,0)+F15 -> 50000 | F15: =VLOOKUP($A15,[6]HISTOFEV25!$A$6:$AU$48,8,0) -> 0 | G15: =VLOOKUP($A15,[6]HISTOFEV25!$A$6:$AU$49,9,0) -> BANQUE | H15: =VLOOKUP($A15,[6]HISTOFEV25!$A$6:$AV$49,35,0) -> 0 | I15: =VLOOKUP($A15,[6]HISTOFEV25!$A$6:$AV$49,38,0) -> 0 | J15: =IF(I15=0,"",VLOOKUP($A15,[6]HISTOFEV25!$A$6:$AV$47,42,0)) | K15: =VLOOKUP($A15,[6]HISTOFEV25!$A$6:$AV$49,41,0) -> 0 | L15: =TONTJANV25!H15+TONTJANV25!I15 -> 0 | M15: =VLOOKUP($A15,[6]HISTOFEV25!$A$6:$AV$49,16,0) -> 0 | N15: =IF(M15<>0,VLOOKUP($A15,[6]HISTOFEV25!$A$6:$AV$49,42,0),"ECHEC") -> ECHEC | O15: =IF(R15=0,0,VLOOKUP($A15,[6]HISTOFEV25!$A$6:$AV$49,32,0)) -> 0 | P15: =VLOOKUP($A15,[6]HISTOFEV25!$A$6:$AV$49,33,0) -> 0 | Q15: =IF(R15=0,0,($C$3-R15)) -> 0 | R15: =VLOOKUP($A15,[6]HISTOFEV25!$A$6:$AV$49,29,0) -> 0
A16: AS201613 | B16: =IF(D16=0,0,VLOOKUP($A16,[6]HISTOFEV25!$A$6:$BP$45,10,0)) -> 1 | C16: =VLOOKUP(A16,[7]LISTADHERENT!A$5:H$60,3,0) -> HOTCHO BENJAMIN | D16: =IF(G16="ECHEC",0,B$3) -> 25000 | E16: =D16+VLOOKUP($A16,[6]HISTOFEV25!$A$7:$AT$43,45,0)+F16 -> 85000 | F16: =VLOOKUP($A16,[6]HISTOFEV25!$A$6:$AU$48,8,0) -> 0 | G16: =VLOOKUP($A16,[6]HISTOFEV25!$A$6:$AU$49,9,0) -> BANQUE | H16: =VLOOKUP($A16,[6]HISTOFEV25!$A$6:$AV$49,35,0) -> 0 | I16: =VLOOKUP($A16,[6]HISTOFEV25!$A$6:$AV$49,38,0) -> 0 | J16: =IF(I16=0,"",VLOOKUP($A16,[6]HISTOFEV25!$A$6:$AV$47,42,0)) | K16: =VLOOKUP($A16,[6]HISTOFEV25!$A$6:$AV$49,41,0) -> 0 | L16: =TONTJANV25!H16+TONTJANV25!I16 -> 0 | M16: =VLOOKUP($A16,[6]HISTOFEV25!$A$6:$AV$49,16,0) -> 0 | N16: =IF(M16<>0,VLOOKUP($A16,[6]HISTOFEV25!$A$6:$AV$49,42,0),"ECHEC") -> ECHEC | O16: =IF(R16=0,0,VLOOKUP($A16,[6]HISTOFEV25!$A$6:$AV$49,32,0)) -> 0 | P16: =VLOOKUP($A16,[6]HISTOFEV25!$A$6:$AV$49,33,0) -> 0 | Q16: =IF(R16=0,0,($C$3-R16)) -> 0 | R16: =VLOOKUP($A16,[6]HISTOFEV25!$A$6:$AV$49,29,0) -> 0
A17: AS201617 | B17: =IF(D17=0,0,VLOOKUP($A17,[6]HISTOFEV25!$A$6:$BP$45,10,0)) -> 1 | C17: =VLOOKUP(A17,[7]LISTADHERENT!A$5:H$60,3,0) -> KOUAMOU MOISE | D17: =IF(G17="ECHEC",0,B$3) -> 25000 | E17: =D17+VLOOKUP($A17,[6]HISTOFEV25!$A$7:$AT$43,45,0)+F17 -> 50000 | F17: =VLOOKUP($A17,[6]HISTOFEV25!$A$6:$AU$48,8,0) -> 0 | G17: =VLOOKUP($A17,[6]HISTOFEV25!$A$6:$AU$49,9,0) -> BANQUE | H17: =VLOOKUP($A17,[6]HISTOFEV25!$A$6:$AV$49,35,0) -> 0 | I17: =VLOOKUP($A17,[6]HISTOFEV25!$A$6:$AV$49,38,0) -> 0 | J17: =IF(I17=0,"",VLOOKUP($A17,[6]HISTOFEV25!$A$6:$AV$47,42,0)) | K17: =VLOOKUP($A17,[6]HISTOFEV25!$A$6:$AV$49,41,0) -> 0 | L17: =TONTJANV25!H17+TONTJANV25!I17 -> 0 | M17: =VLOOKUP($A17,[6]HISTOFEV25!$A$6:$AV$49,16,0) -> 0 | N17: =IF(M17<>0,VLOOKUP($A17,[6]HISTOFEV25!$A$6:$AV$49,42,0),"ECHEC") -> ECHEC | O17: =IF(R17=0,0,VLOOKUP($A17,[6]HISTOFEV25!$A$6:$AV$49,32,0)) -> 0 | P17: =VLOOKUP($A17,[6]HISTOFEV25!$A$6:$AV$49,33,0) -> 0 | Q17: =IF(R17=0,0,($C$3-R17)) -> 0 | R17: =VLOOKUP($A17,[6]HISTOFEV25!$A$6:$AV$49,29,0) -> 0
... A40: AS201647 | B40: =IF(D40=0,0,VLOOKUP($A40,[6]HISTOFEV25!$A$6:$BP$45,10,0)) -> 1 | C40: =VLOOKUP(A40,[7]LISTADHERENT!A$5:H$60,3,0) -> YOUMBI EMMANUEL | D40: =IF(G40="ECHEC",0,B$3) -> 25000 | E40: =D40+VLOOKUP($A40,[6]HISTOFEV25!$A$7:$AT$43,45,0)+F40 -> 50000 | F40: =VLOOKUP($A40,[6]HISTOFEV25!$A$6:$AU$48,8,0) -> 0 | G40: =VLOOKUP($A40,[6]HISTOFEV25!$A$6:$AU$49,9,0) -> BANQUE | H40: =VLOOKUP($A40,[6]HISTOFEV25!$A$6:$AV$49,35,0) -> 0 | I40: =VLOOKUP($A40,[6]HISTOFEV25!$A$6:$AV$49,38,0) -> 0 | J40: =IF(I40=0,"",VLOOKUP($A40,[6]HISTOFEV25!$A$6:$AV$47,42,0)) | K40: =VLOOKUP($A40,[6]HISTOFEV25!$A$6:$AV$49,41,0) -> 0 | L40: =TONTJANV25!H40+TONTJANV25!I40 -> 0 | M40: =VLOOKUP($A40,[6]HISTOFEV25!$A$6:$AV$49,16,0) -> 0 | N40: =IF(M40<>0,VLOOKUP($A40,[6]HISTOFEV25!$A$6:$AV$49,42,0),"ECHEC") -> ECHEC | O40: =IF(R40=0,0,VLOOKUP($A40,[6]HISTOFEV25!$A$6:$AV$49,32,0)) -> 0 | P40: =VLOOKUP($A40,[6]HISTOFEV25!$A$6:$AV$49,33,0) -> 0 | Q40: =IF(R40=0,0,($C$3-R40)) -> 0 | R40: =VLOOKUP($A40,[6]HISTOFEV25!$A$6:$AV$49,29,0) -> 0
A42: TOTAL PART | B42: =SUM(B6:B41) -> 35
A43: NBRE ADHERENT | B43: =COUNT(D6:D41) -> 35 | D43: =SUM(D6:D42) -> 875000 | F43: =SUM(F6:F42) -> 3000 | G43: =SUM(G6:G42) -> 0 | H43: =SUM(H6:H42) -> 121000 | I43: =SUM(I6:I42) -> 3000 | J43: =SUM(J6:J42) -> 0 | K43: =SUM(K6:K42) -> 0 | L43: =SUM(L6:L42) -> 42000 | M43: =SUM(M6:M42) -> 42000 | ... R43: =SUM(R6:R42) -> 79000
N44: NBRE PART | O44: PART VENDUE
D45: MONTANT TONTINE | G45: REMBOURSEMENT PETIT LOT | H45: VENTE PETIT LOT | I45: VENTE LOT PRINCIPAL | J45: SOLDE EN CAISSE | L45: TONTINE + REMB + INTERET VENTE | M45: =D49+G49+R43+42000-17000 -> 1021000
D46: =SUMIFS(D6:D42,G6:G42,"ESPECES") -> 100000 | F46: ESPECES | G46: =SUMIFS(M6:M35,N6:N35,"ESPECES") -> 0 | H46: =SUMIFS(H6:H42,J6:J42,"ESPECES") -> 0 | I46: =SUMIFS(Q6:Q42,O6:O42,"ESPECES") -> 0 | J46: =D46+G46-H46-I46 -> 100000 | L46: LOT PRINCIPAL | M46: =C3*COUNTIF(Q7:Q42,">0") -> 900000 | N46: =D3 -> 3 | O46: =COUNTIF(Q7:Q35,">0") -> 3
D47: =SUMIFS(D6:D42,G6:G42,"BANQUE") -> 775000 | F47: BANQUE | G47: =SUMIFS(M6:M35,N6:N35,"BANQUE") -> 42000 | H47: =SUMIFS(H6:H42,J6:J42,"BANQUE") -> 121000 | I47: =SUMIFS(Q6:Q42,O6:O42,"BANQUE") -> 821000 | J47: =D47+G47-H47-I47 -> -125000
L48: PETIT LOT | M48: =M45-M46 -> 121000
D49: =D46+D47 -> 875000 | F49: TOTAL | G49: =G46+G47 -> 42000 | H49: =H46+H47 -> 121000 | I49: =I46+I47 -> 821000 | J49: =J46+J47 -> -25000
F50: TOTAL+DEPOT | L50: RELIQUAT | M50: =M48-H43 -> 0 | O50: =M50+TONTJANV25!O50 -> 0 | P50: CUMUL
L52: ECHEC TONTINE MOIS | M52: =COUNTIFS(G7:G41,"ECHEC")*23000 -> 0 | O52: =+M52+TONTJANV25!O52 -> 0 | P52: CUMUL
L53: ECHEC REMBOURSEMENT MOIS | M53: =L43-G49 -> 0 | O53: =+TONTJANV25!O53 -> 0 | P53: CUMUL

Sheet TONTMARS25
A1: ASSOCIATION | B1: ASELBY
A2: ANNEE | B2: 2025 | C2: TONIINE | D2: NBRE PART
A3: TAUX TONTINE | B3: 25000 | C3: =B3*12 -> 300000 | D3: =ROUNDDOWN(M45/C3,0) -> 3
C4: 45729
A5: MATRICULE | B5: NBREPART | C5: NOM ET PRENOM | D5: MONTANT TONTINE | E5: MONTANT VERSE | F5: PENALITE VERSEMENT ESPECES | G5: MODE VERSEMENT | H5: VENTE PETIT LOT | I5: INTERET PETIT LOT | J5: MODE VERSEMENT VENTE PETIT LOT | K5: NUMERO CHEQUE | L5: MONTANT A REMBOURSER PETIT LOT | M5: REMBOURSEMENT PETIT LOT | N5: MODE VERSEMENT REMBOURSEMENT | O5: MODE VERSEMENTLOT PRINCIPAL | P5: NUMERO CHEQUE | Q5: MONTANT LOT PRINCIPAL | R5: INTERET LOT PRINCIPAL
A6: AS201601 | B6: =IF(D6=0,0,VLOOKUP($A6,[6]HISTOMARS25!$A$6:$BP$45,10,0)) -> 1 | C6: =VLOOKUP(A6,[7]LISTADHERENT!A$5:H$60,3,0) -> BAKOP ACHILLE | D6: =IF(G6="ECHEC",0,B$3) -> 25000 | E6: =D6+VLOOKUP($A6,[6]HISTOMARS25!$A$7:$AT$43,45,0)+F6 -> 50000 | F6: =VLOOKUP($A6,[6]HISTOMARS25!$A$6:$AU$48,8,0) -> 0 | G6: =VLOOKUP($A6,[6]HISTOMARS25!$A$6:$AU$49,9,0) -> ESPECES | H6: =VLOOKUP($A6,[6]HISTOMARS25!$A$6:$AV$49,35,0) -> 0 | I6: =VLOOKUP($A6,[6]HISTOMARS25!$A$6:$AV$49,38,0) -> 0 | J6: =IF(I6=0,"",VLOOKUP($A6,[6]HISTOMARS25!$A$6:$AV$47,42,0)) | K6: =VLOOKUP($A6,[6]HISTOMARS25!$A$6:$AV$49,41,0) -> 0 | L6: =TONTFEV25!H6+TONTFEV25!I6 -> 0 | M6: =VLOOKUP($A6,[6]HISTOMARS25!$A$6:$AV$49,16,0) -> 0 | N6: =IF(M6<>0,VLOOKUP($A6,[6]HISTOMARS25!$A$6:$AV$49,42,0),"ECHEC") -> ECHEC | O6: =IF(R6=0,0,VLOOKUP($A6,[6]HISTOMARS25!$A$6:$AV$49,32,0)) -> 0 | P6: =VLOOKUP($A6,[6]HISTOMARS25!$A$6:$AV$49,33,0) -> 0 | Q6: =IF(R6=0,0,($C$3-R6)) -> 0 | R6: =VLOOKUP($A6,[6]HISTOMARS25!$A$6:$AV$49,29,0) -> 0
A7: AS201602 | B7: =IF(D7=0,0,VLOOKUP($A7,[6]HISTOMARS25!$A$6:$BP$45,10,0)) -> 1 | C7: =VLOOKUP(A7,[7]LISTADHERENT!A$5:H$60,3,0) -> BOUTCHOUANG WILLIAM | D7: =IF(G7="ECHEC",0,B$3) -> 25000 | E7: =D7+VLOOKUP($A7,[6]HISTOMARS25!$A$7:$AT$43,45,0)+F7 -> 50000 | F7: =VLOOKUP($A7,[6]HISTOMARS25!$A$6:$AU$48,8,0) -> 0 | G7: =VLOOKUP($A7,[6]HISTOMARS25!$A$6:$AU$49,9,0) -> BANQUE | H7: =VLOOKUP($A7,[6]HISTOMARS25!$A$6:$AV$49,35,0) -> 0 | I7: =VLOOKUP($A7,[6]HISTOMARS25!$A$6:$AV$49,38,0) -> 0 | J7: =IF(I7=0,"",VLOOKUP($A7,[6]HISTOMARS25!$A$6:$AV$47,42,0)) | K7: =VLOOKUP($A7,[6]HISTOMARS25!$A$6:$AV$49,41,0) -> 0 | L7: =TONTFEV25!H7+TONTFEV25!I7 -> 0 | M7: =VLOOKUP($A7,[6]HISTOMARS25!$A$6:$AV$49,16,0) -> 0 | N7: =IF(M7<>0,VLOOKUP($A7,[6]HISTOMARS25!$A$6:$AV$49,42,0),"ECHEC") -> ECHEC | O7: =IF(R7=0,0,VLOOKUP($A7,[6]HISTOMARS25!$A$6:$AV$49,32,0)) -> 0 | P7: =VLOOKUP($A7,[6]HISTOMARS25!$A$6:$AV$49,33,0) -> 0 | Q7: =IF(R7=0,0,($C$3-R7)) -> 0 | R7: =VLOOKUP($A7,[6]HISTOMARS25!$A$6:$AV$49,29,0) -> 0
A8: AS201604 | B8: =IF(D8=0,0,VLOOKUP($A8,[6]HISTOMARS25!$A$6:$BP$45,10,0)) -> 1 | C8: =VLOOKUP(A8,[7]LISTADHERENT!A$5:H$60,3,0) -> DJOMO JEAN PAUL | D8: =IF(G8="ECHEC",0,B$3) -> 25000 | E8: =D8+VLOOKUP($A8,[6]HISTOMARS25!$A$7:$AT$43,45,0)+F8 -> 50000 | F8: =VLOOKUP($A8,[6]HISTOMARS25!$A$6:$AU$48,8,0) -> 0 | G8: =VLOOKUP($A8,[6]HISTOMARS25!$A$6:$AU$49,9,0) -> BANQUE | H8: =VLOOKUP($A8,[6]HISTOMARS25!$A$6:$AV$49,35,0) -> 0 | I8: =VLOOKUP($A8,[6]HISTOMARS25!$A$6:$AV$49,38,0) -> 0 | J8: =IF(I8=0,"",VLOOKUP($A8,[6]HISTOMARS25!$A$6:$AV$47,42,0)) | K8: =VLOOKUP($A8,[6]HISTOMARS25!$A$6:$AV$49,41,0) -> 0 | L8: =TONTFEV25!H8+TONTFEV25!I8 -> 0 | M8: =VLOOKUP($A8,[6]HISTOMARS25!$A$6:$AV$49,16,0) -> 0 | N8: =IF(M8<>0,VLOOKUP($A8,[6]HISTOMARS25!$A$6:$AV$49,42,0),"ECHEC") -> ECHEC | O8: =IF(R8=0,0,VLOOKUP($A8,[6]HISTOMARS25!$A$6:$AV$49,32,0)) -> 0 | P8: =VLOOKUP($A8,[6]HISTOMARS25!$A$6:$AV$49,33,0) -> 0 | Q8: =IF(R8=0,0,($C$3-R8)) -> 0 | R8: =VLOOKUP($A8,[6]HISTOMARS25!$A$6:$AV$49,29,0) -> 0
A9: AS201654 | B9: =IF(D9=0,0,VLOOKUP($A9,[6]HISTOMARS25!$A$6:$BP$45,10,0)) -> 1 | C9: =VLOOKUP(A9,[7]LISTADHERENT!A$5:H$60,3,0) -> DJOMOU TCHAPDA | D9: =IF(G9="ECHEC",0,B$3) -> 25000 | E9: =D9+VLOOKUP($A9,[6]HISTOMARS25!$A$7:$AT$43,45,0)+F9 -> 59500 | F9: =VLOOKUP($A9,[6]HISTOMARS25!$A$6:$AU$48,8,0) -> 0 | G9: =VLOOKUP($A9,[6]HISTOMARS25!$A$6:$AU$49,9,0) -> BANQUE | H9: =VLOOKUP($A9,[6]HISTOMARS25!$A$6:$AV$49,35,0) -> 40000 | I9: =VLOOKUP($A9,[6]HISTOMARS25!$A$6:$AV$49,38,0) -> 2000 | J9: =IF(I9=0,"",VLOOKUP($A9,[6]HISTOMARS25!$A$6:$AV$47,42,0)) -> BANQUE | K9: =VLOOKUP($A9,[6]HISTOMARS25!$A$6:$AV$49,41,0) -> 0 | L9: =TONTFEV25!H9+TONTFEV25!I9 -> 41000 | M9: =VLOOKUP($A9,[6]HISTOMARS25!$A$6:$AV$49,16,0) -> 41000 | N9: =IF(M9<>0,VLOOKUP($A9,[6]HISTOMARS25!$A$6:$AV$49,42,0),"ECHEC") -> BANQUE | O9: =IF(R9=0,0,VLOOKUP($A9,[6]HISTOMARS25!$A$6:$AV$49,32,0)) -> 0 | P9: =VLOOKUP($A9,[6]HISTOMARS25!$A$6:$AV$49,33,0) -> 0 | Q9: =IF(R9=0,0,($C$3-R9)) -> 0 | R9: =VLOOKUP($A9,[6]HISTOMARS25!$A$6:$AV$49,29,0) -> 0
A10: AS201605 | B10: =IF(D10=0,0,VLOOKUP($A10,[6]HISTOMARS25!$A$6:$BP$45,10,0)) -> 1 | C10: =VLOOKUP(A10,[7]LISTADHERENT!A$5:H$60,3,0) -> DJOUKWE NANGUEN GUY BLAISE | D10: =IF(G10="ECHEC",0,B$3) -> 25000 | E10: =D10+VLOOKUP($A10,[6]HISTOMARS25!$A$7:$AT$43,45,0)+F10 -> 50000 | F10: =VLOOKUP($A10,[6]HISTOMARS25!$A$6:$AU$48,8,0) -> 0 | G10: =VLOOKUP($A10,[6]HISTOMARS25!$A$6:$AU$49,9,0) -> BANQUE | H10: =VLOOKUP($A10,[6]HISTOMARS25!$A$6:$AV$49,35,0) -> 0 | I10: =VLOOKUP($A10,[6]HISTOMARS25!$A$6:$AV$49,38,0) -> 0 | J10: =IF(I10=0,"",VLOOKUP($A10,[6]HISTOMARS25!$A$6:$AV$47,42,0)) | K10: =VLOOKUP($A10,[6]HISTOMARS25!$A$6:$AV$49,41,0) -> 0 | L10: =TONTFEV25!H10+TONTFEV25!I10 -> 0 | M10: =VLOOKUP($A10,[6]HISTOMARS25!$A$6:$AV$49,16,0) -> 0 | N10: =IF(M10<>0,VLOOKUP($A10,[6]HISTOMARS25!$A$6:$AV$49,42,0),"ECHEC") -> ECHEC | O10: =IF(R10=0,0,VLOOKUP($A10,[6]HISTOMARS25!$A$6:$AV$49,32,0)) -> BANQUE | P10: =VLOOKUP($A10,[6]HISTOMARS25!$A$6:$AV$49,33,0) -> 0 | Q10: =IF(R10=0,0,($C$3-R10)) -> 293500 | R10: =VLOOKUP($A10,[6]HISTOMARS25!$A$6:$AV$49,29,0) -> 6500
A11: AS201608 | B11: =IF(D11=0,0,VLOOKUP($A11,[6]HISTOMARS25!$A$6:$BP$45,10,0)) -> 1 | C11: =VLOOKUP(A11,[7]LISTADHERENT!A$5:H$60,3,0) -> DJUOMBESSY ANTOINE | D11: =IF(G11="ECHEC",0,B$3) -> 25000 | E11: =D11+VLOOKUP($A11,[6]HISTOMARS25!$A$7:$AT$43,45,0)+F11 -> 60000 | F11: =VLOOKUP($A11,[6]HISTOMARS25!$A$6:$AU$48,8,0) -> 0 | G11: =VLOOKUP($A11,[6]HISTOMARS25!$A$6:$AU$49,9,0) -> BANQUE | H11: =VLOOKUP($A11,[6]HISTOMARS25!$A$6:$AV$49,35,0) -> 0 | I11: =VLOOKUP($A11,[6]HISTOMARS25!$A$6:$AV$49,38,0) -> 0 | J11: =IF(I11=0,"",VLOOKUP($A11,[6]HISTOMARS25!$A$6:$AV$47,42,0)) | K11: =VLOOKUP($A11,[6]HISTOMARS25!$A$6:$AV$49,41,0) -> 0 | L11: =TONTFEV25!H11+TONTFEV25!I11 -> 0 | M11: =VLOOKUP($A11,[6]HISTOMARS25!$A$6:$AV$49,16,0) -> 0 | N11: =IF(M11<>0,VLOOKUP($A11,[6]HISTOMARS25!$A$6:$AV$49,42,0),"ECHEC") -> ECHEC | O11: =IF(R11=0,0,VLOOKUP($A11,[6]HISTOMARS25!$A$6:$AV$49,32,0)) -> BANQUE | P11: =VLOOKUP($A11,[6]HISTOMARS25!$A$6:$AV$49,33,0) -> 0 | Q11: =IF(R11=0,0,($C$3-R11)) -> 293000 | R11: =VLOOKUP($A11,[6]HISTOMARS25!$A$6:$AV$49,29,0) -> 7000
A12: AS201651 | B12: =IF(D12=0,0,VLOOKUP($A12,[6]HISTOMARS25!$A$6:$BP$45,10,0)) -> 1 | C12: =VLOOKUP(A12,[7]LISTADHERENT!A$5:H$60,3,0) -> DOMOU FABIEN | D12: =IF(G12="ECHEC",0,B$3) -> 25000 | E12: =D12+VLOOKUP($A12,[6]HISTOMARS25!$A$7:$AT$43,45,0)+F12 -> 50000 | F12: =VLOOKUP($A12,[6]HISTOMARS25!$A$6:$AU$48,8,0) -> 0 | G12: =VLOOKUP($A12,[6]HISTOMARS25!$A$6:$AU$49,9,0) -> BANQUE | H12: =VLOOKUP($A12,[6]HISTOMARS25!$A$6:$AV$49,35,0) -> 0 | I12: =VLOOKUP($A12,[6]HISTOMARS25!$A$6:$AV$49,38,0) -> 0 | J12: =IF(I12=0,"",VLOOKUP($A12,[6]HISTOMARS25!$A$6:$AV$47,42,0)) | K12: =VLOOKUP($A12,[6]HISTOMARS25!$A$6:$AV$49,41,0) -> 0 | L12: =TONTFEV25!H12+TONTFEV25!I12 -> 0 | M12: =VLOOKUP($A12,[6]HISTOMARS25!$A$6:$AV$49,16,0) -> 0 | N12: =IF(M12<>0,VLOOKUP($A12,[6]HISTOMARS25!$A$6:$AV$49,42,0),"ECHEC") -> ECHEC | O12: =IF(R12=0,0,VLOOKUP($A12,[6]HISTOMARS25!$A$6:$AV$49,32,0)) -> 0 | P12: =VLOOKUP($A12,[6]HISTOMARS25!$A$6:$AV$49,33,0) -> 0 | Q12: =IF(R12=0,0,($C$3-R12)) -> 0 | R12: =VLOOKUP($A12,[6]HISTOMARS25!$A$6:$AV$49,29,0) -> 0
A13: AS201609 | B13: =IF(D13=0,0,VLOOKUP($A13,[6]HISTOMARS25!$A$6:$BP$45,10,0)) -> 1 | C13: =VLOOKUP(A13,[7]LISTADHERENT!A$5:H$60,3,0) -> DONHOU DAVID | D13: =IF(G13="ECHEC",0,B$3) -> 25000 | E13: =D13+VLOOKUP($A13,[6]HISTOMARS25!$A$7:$AT$43,45,0)+F13 -> 50000 | F13: =VLOOKUP($A13,[6]HISTOMARS25!$A$6:$AU$48,8,0) -> 0 | G13: =VLOOKUP($A13,[6]HISTOMARS25!$A$6:$AU$49,9,0) -> BANQUE | H13: =VLOOKUP($A13,[6]HISTOMARS25!$A$6:$AV$49,35,0) -> 0 | I13: =VLOOKUP($A13,[6]HISTOMARS25!$A$6:$AV$49,38,0) -> 0 | J13: =IF(I13=0,"",VLOOKUP($A13,[6]HISTOMARS25!$A$6:$AV$47,42,0)) | K13: =VLOOKUP($A13,[6]HISTOMARS25!$A$6:$AV$49,41,0) -> 0 | L13: =TONTFEV25!H13+TONTFEV25!I13 -> 0 | M13: =VLOOKUP($A13,[6]HISTOMARS25!$A$6:$AV$49,16,0) -> 0 | N13: =IF(M13<>0,VLOOKUP($A13,[6]HISTOMARS25!$A$6:$AV$49,42,0),"ECHEC") -> ECHEC | O13: =IF(R13=0,0,VLOOKUP($A13,[6]HISTOMARS25!$A$6:$AV$49,32,0)) -> 0 | P13: =VLOOKUP($A13,[6]HISTOMARS25!$A$6:$AV$49,33,0) -> 0 | Q13: =IF(R13=0,0,($C$3-R13)) -> 0 | R13: =VLOOKUP($A13,[6]HISTOMARS25!$A$6:$AV$49,29,0) -> 0
A14: AS201663 | B14: =IF(D14=0,0,VLOOKUP($A14,[6]HISTOMARS25!$A$6:$BP$45,10,0)) -> 1 | C14: =VLOOKUP(A14,[7]LISTADHERENT!A$5:H$60,3,0) -> FAMPOU PAUL | D14: =IF(G14="ECHEC",0,B$3) -> 25000 | E14: =D14+VLOOKUP($A14,[6]HISTOMARS25!$A$7:$AT$43,45,0)+F14 -> 50000 | F14: =VLOOKUP($A14,[6]HISTOMARS25!$A$6:$AU$48,8,0) -> 0 | G14: =VLOOKUP($A14,[6]HISTOMARS25!$A$6:$AU$49,9,0) -> BANQUE | H14: =VLOOKUP($A14,[6]HISTOMARS25!$A$6:$AV$49,35,0) -> 0 | I14: =VLOOKUP($A14,[6]HISTOMARS25!$A$6:$AV$49,38,0) -> 0 | J14: =IF(I14=0,"",VLOOKUP($A14,[6]HISTOMARS25!$A$6:$AV$47,42,0)) | K14: =VLOOKUP($A14,[6]HISTOMARS25!$A$6:$AV$49,41,0) -> 0 | L14: =TONTFEV25!H14+TONTFEV25!I14 -> 0 | M14: =VLOOKUP($A14,[6]HISTOMARS25!$A$6:$AV$49,16,0) -> 0 | N14: =IF(M14<>0,VLOOKUP($A14,[6]HISTOMARS25!$A$6:$AV$49,42,0),"ECHEC") -> ECHEC | O14: =IF(R14=0,0,VLOOKUP($A14,[6]HISTOMARS25!$A$6:$AV$49,32,0)) -> 0 | P14: =VLOOKUP($A14,[6]HISTOMARS25!$A$6:$AV$49,33,0) -> 0 | Q14: =IF(R14=0,0,($C$3-R14)) -> 0 | R14: =VLOOKUP($A14,[6]HISTOMARS25!$A$6:$AV$49,29,0) -> 0
A15: AS201611 | B15: =IF(D15=0,0,VLOOKUP($A15,[6]HISTOMARS25!$A$6:$BP$45,10,0)) -> 1 | C15: =VLOOKUP(A15,[7]LISTADHERENT!A$5:H$60,3,0) -> HENGUE PAUL OMER | D15: =IF(G15="ECHEC",0,B$3) -> 25000 | E15: =D15+VLOOKUP($A15,[6]HISTOMARS25!$A$7:$AT$43,45,0)+F15 -> 50000 | F15: =VLOOKUP($A15,[6]HISTOMARS25!$A$6:$AU$48,8,0) -> 0 | G15: =VLOOKUP($A15,[6]HISTOMARS25!$A$6:$AU$49,9,0) -> BANQUE | H15: =VLOOKUP($A15,[6]HISTOMARS25!$A$6:$AV$49,35,0) -> 0 | I15: =VLOOKUP($A15,[6]HISTOMARS25!$A$6:$AV$49,38,0) -> 0 | J15: =IF(I15=0,"",VLOOKUP($A15,[6]HISTOMARS25!$A$6:$AV$47,42,0)) | K15: =VLOOKUP($A15,[6]HISTOMARS25!$A$6:$AV$49,41,0) -> 0 | L15: =TONTFEV25!H15+TONTFEV25!I15 -> 0 | M15: =VLOOKUP($A15,[6]HISTOMARS25!$A$6:$AV$49,16,0) -> 0 | N15: =IF(M15<>0,VLOOKUP($A15,[6]HISTOMARS25!$A$6:$AV$49,42,0),"ECHEC") -> ECHEC | O15: =IF(R15=0,0,VLOOKUP($A15,[6]HISTOMARS25!$A$6:$AV$49,32,0)) -> 0 | P15: =VLOOKUP($A15,[6]HISTOMARS25!$A$6:$AV$49,33,0) -> 0 | Q15: =IF(R15=0,0,($C$3-R15)) -> 0 | R15: =VLOOKUP($A15,[6]HISTOMARS25!$A$6:$AV$49,29,0) -> 0
A16: AS201613 | B16: =IF(D16=0,0,VLOOKUP($A16,[6]HISTOMARS25!$A$6:$BP$45,10,0)) -> 1 | C16: =VLOOKUP(A16,[7]LISTADHERENT!A$5:H$60,3,0) -> HOTCHO BENJAMIN | D16: =IF(G16="ECHEC",0,B$3) -> 25000 | E16: =D16+VLOOKUP($A16,[6]HISTOMARS25!$A$7:$AT$43,45,0)+F16 -> 75000 | F16: =VLOOKUP($A16,[6]HISTOMARS25!$A$6:$AU$48,8,0) -> 0 | G16: =VLOOKUP($A16,[6]HISTOMARS25!$A$6:$AU$49,9,0) -> BANQUE | H16: =VLOOKUP($A16,[6]HISTOMARS25!$A$6:$AV$49,35,0) -> 0 | I16: =VLOOKUP($A16,[6]HISTOMARS25!$A$6:$AV$49,38,0) -> 0 | J16: =IF(I16=0,"",VLOOKUP($A16,[6]HISTOMARS25!$A$6:$AV$47,42,0)) | K16: =VLOOKUP($A16,[6]HISTOMARS25!$A$6:$AV$49,41,0) -> 0 | L16: =TONTFEV25!H16+TONTFEV25!I16 -> 0 | M16: =VLOOKUP($A16,[6]HISTOMARS25!$A$6:$AV$49,16,0) -> 0 | N16: =IF(M16<>0,VLOOKUP($A16,[6]HISTOMARS25!$A$6:$AV$49,42,0),"ECHEC") -> ECHEC | O16: =IF(R16=0,0,VLOOKUP($A16,[6]HISTOMARS25!$A$6:$AV$49,32,0)) -> 0 | P16: =VLOOKUP($A16,[6]HISTOMARS25!$A$6:$AV$49,33,0) -> 0 | Q16: =IF(R16=0,0,($C$3-R16)) -> 0 | R16: =VLOOKUP($A16,[6]HISTOMARS25!$A$6:$AV$49,29,0) -> 0
A17: AS201617 | B17: =IF(D17=0,0,VLOOKUP($A17,[6]HISTOMARS25!$A$6:$BP$45,10,0)) -> 1 | C17: =VLOOKUP(A17,[7]LISTADHERENT!A$5:H$60,3,0) -> KOUAMOU MOISE | D17: =IF(G17="ECHEC",0,B$3) -> 25000 | E17: =D17+VLOOKUP($A17,[6]HISTOMARS25!$A$7:$AT$43,45,0)+F17 -> 50000 | F17: =VLOOKUP($A17,[6]HISTOMARS25!$A$6:$AU$48,8,0) -> 0 | G17: =VLOOKUP($A17,[6]HISTOMARS25!$A$6:$AU$49,9,0) -> BANQUE | H17: =VLOOKUP($A17,[6]HISTOMARS25!$A$6:$AV$49,35,0) -> 0 | I17: =VLOOKUP($A17,[6]HISTOMARS25!$A$6:$AV$49,38,0) -> 0 | J17: =IF(I17=0,"",VLOOKUP($A17,[6]HISTOMARS25!$A$6:$AV$47,42,0)) | K17: =VLOOKUP($A17,[6]HISTOMARS25!$A$6:$AV$49,41,0) -> 0 | L17: =TONTFEV25!H17+TONTFEV25!I17 -> 0 | M17: =VLOOKUP($A17,[6]HISTOMARS25!$A$6:$AV$49,16,0) -> 0 | N17: =IF(M17<>0,VLOOKUP($A17,[6]HISTOMARS25!$A$6:$AV$49,42,0),"ECHEC") -> ECHEC | O17: =IF(R17=0,0,VLOOKUP($A17,[6]HISTOMARS25!$A$6:$AV$49,32,0)) -> 0 | P17: =VLOOKUP($A17,[6]HISTOMARS25!$A$6:$AV$49,33,0) -> 0 | Q17: =IF(R17=0,0,($C$3-R17)) -> 0 | R17: =VLOOKUP($A17,[6]HISTOMARS25!$A$6:$AV$49,29,0) -> 0
... A40: AS201647 | B40: =IF(D40=0,0,VLOOKUP($A40,[6]HISTOMARS25!$A$6:$BP$45,10,0)) -> 1 | C40: =VLOOKUP(A40,[7]LISTADHERENT!A$5:H$60,3,0) -> YOUMBI EMMANUEL | D40: =IF(G40="ECHEC",0,B$3) -> 25000 | E40: =D40+VLOOKUP($A40,[6]HISTOMARS25!$A$7:$AT$43,45,0)+F40 -> 50000 | F40: =VLOOKUP($A40,[6]HISTOMARS25!$A$6:$AU$48,8,0) -> 0 | G40: =VLOOKUP($A40,[6]HISTOMARS25!$A$6:$AU$49,9,0) -> BANQUE | H40: =VLOOKUP($A40,[6]HISTOMARS25!$A$6:$AV$49,35,0) -> 0 | I40: =VLOOKUP($A40,[6]HISTOMARS25!$A$6:$AV$49,38,0) -> 0 | J40: =IF(I40=0,"",VLOOKUP($A40,[6]HISTOMARS25!$A$6:$AV$47,42,0)) | K40: =VLOOKUP($A40,[6]HISTOMARS25!$A$6:$AV$49,41,0) -> 0 | L40: =TONTFEV25!H40+TONTFEV25!I40 -> 0 | M40: =VLOOKUP($A40,[6]HISTOMARS25!$A$6:$AV$49,16,0) -> 0 | N40: =IF(M40<>0,VLOOKUP($A40,[6]HISTOMARS25!$A$6:$AV$49,42,0),"ECHEC") -> ECHEC | O40: =IF(R40=0,0,VLOOKUP($A40,[6]HISTOMARS25!$A$6:$AV$49,32,0)) -> 0 | P40: =VLOOKUP($A40,[6]HISTOMARS25!$A$6:$AV$49,33,0) -> 0 | Q40: =IF(R40=0,0,($C$3-R40)) -> 0 | R40: =VLOOKUP($A40,[6]HISTOMARS25!$A$6:$AV$49,29,0) -> 0
A42: TOTAL PART | B42: =SUM(B6:B41) -> 35
A43: NBRE ADHERENT | B43: =COUNT(D6:D41) -> 35 | D43: =SUM(D6:D42) -> 875000 | F43: =SUM(F6:F42) -> 9000 | G43: =SUM(G6:G42) -> 0 | H43: =SUM(H6:H42) -> 120000 | I43: =SUM(I6:I42) -> 5000 | J43: =SUM(J6:J42) -> 0 | K43: =SUM(K6:K42) -> 0 | L43: =SUM(L6:L42) -> 124000 | M43: =SUM(M6:M42) -> 124000 | ... R43: =SUM(R6:R42) -> 21000
N44: NBRE PART | O44: PART VENDUE
D45: MONTANT TONTINE | G45: REMBOURSEMENT PETIT LOT | H45: VENTE PETIT LOT | I45: VENTE LOT PRINCIPAL | J45: SOLDE EN CAISSE | L45: TONTINE + REMB + INTERET VENTE | M45: =D49+G49+R43 -> 1020000
D46: =SUMIFS(D6:D42,G6:G42,"ESPECES") -> 100000 | F46: ESPECES | G46: =SUMIFS(M6:M35,N6:N35,"ESPECES") -> 0 | H46: =SUMIFS(H6:H42,J6:J42,"ESPECES") -> 0 | I46: =SUMIFS(Q6:Q42,O6:O42,"ESPECES") -> 0 | J46: =D46+G46-H46-I46 -> 100000 | L46: LOT PRINCIPAL | M46: =C3*COUNTIF(Q7:Q42,">0") -> 900000 | N46: =D3 -> 3 | O46: =COUNTIF(Q7:Q35,">0") -> 3
D47: =SUMIFS(D6:D42,G6:G42,"BANQUE") -> 775000 | F47: BANQUE | G47: =SUMIFS(M6:M35,N6:N35,"BANQUE") -> 124000 | H47: =SUMIFS(H6:H42,J6:J42,"BANQUE") -> 120000 | I47: =SUMIFS(Q6:Q42,O6:O42,"BANQUE") -> 879000 | J47: =D47+G47-H47-I47 -> -100000
L48: PETIT LOT | M48: =M45-M46 -> 120000
D49: =D46+D47 -> 875000 | F49: TOTAL | G49: =G46+G47 -> 124000 | H49: =H46+H47 -> 120000 | I49: =I46+I47 -> 879000 | J49: =J46+J47 -> 0
F50: TOTAL+DEPOT | L50: RELIQUAT | M50: =M48-H43 -> 0 | O50: =M50+TONTJANV25!O50 -> 0 | P50: CUMUL
L52: ECHEC TONTINE MOIS | M52: =COUNTIFS(G7:G41,"ECHEC")*23000 -> 0 | O52: =+M52+TONTJANV25!O52 -> 0 | P52: CUMUL
L53: ECHEC REMBOURSEMENT MOIS | M53: =L43-G49 -> 0 | O53: =+TONTJANV25!O53 -> 0 | P53: CUMUL

Sheet TONTAVRIL25
A1: ASSOCIATION | B1: ASELBY
A2: ANNEE | B2: 2025 | C2: TONIINE | D2: NBRE PART
A3: TAUX TONTINE | B3: 25000 | C3: =B3*12 -> 300000 | D3: =ROUNDDOWN(M45/C3,0) -> 3
C4: 45760
A5: MATRICULE | B5: NBREPART | C5: NOM ET PRENOM | D5: MONTANT TONTINE | E5: MONTANT VERSE | F5: PENALITE VERSEMENT ESPECES | G5: MODE VERSEMENT | H5: VENTE PETIT LOT | I5: INTERET PETIT LOT | J5: MODE VERSEMENT VENTE PETIT LOT | K5: NUMERO CHEQUE | L5: MONTANT A REMBOURSER PETIT LOT | M5: REMBOURSEMENT PETIT LOT | N5: MODE VERSEMENT REMBOURSEMENT | O5: MODE VERSEMENTLOT PRINCIPAL | P5: NUMERO CHEQUE | Q5: MONTANT LOT PRINCIPAL | R5: INTERET LOT PRINCIPAL
A6: AS201601 | B6: =IF(D6=0,0,VLOOKUP($A6,[6]HISTOAVRIL25!$A$6:$BP$45,10,0)) -> 0 | C6: =VLOOKUP(A6,[7]LISTADHERENT!A$5:H$60,3,0) -> BAKOP ACHILLE | D6: =IF(G6="ECHEC",0,B$3) -> 0 | E6: =D6+VLOOKUP($A6,[6]HISTOAVRIL25!$A$7:$AT$43,45,0)+F6 -> 0 | F6: =VLOOKUP($A6,[6]HISTOAVRIL25!$A$6:$AU$48,8,0) -> 0 | G6: =VLOOKUP($A6,[6]HISTOAVRIL25!$A$6:$AU$49,9,0) -> ECHEC | H6: =VLOOKUP($A6,[6]HISTOAVRIL25!$A$6:$AV$49,35,0) -> 0 | I6: =VLOOKUP($A6,[6]HISTOAVRIL25!$A$6:$AV$49,38,0) -> 0 | J6: =IF(I6=0,"",VLOOKUP($A6,[6]HISTOAVRIL25!$A$6:$AV$47,42,0)) | K6: =VLOOKUP($A6,[6]HISTOAVRIL25!$A$6:$AV$49,41,0) -> 0 | L6: =TONTMARS25!H6+TONTMARS25!I6 -> 0 | M6: =VLOOKUP($A6,[6]HISTOAVRIL25!$A$6:$AV$49,16,0) -> 0 | N6: =IF(M6<>0,VLOOKUP($A6,[6]HISTOAVRIL25!$A$6:$AV$49,42,0),"ECHEC") -> ECHEC | O6: =IF(R6=0,0,VLOOKUP($A6,[6]HISTOAVRIL25!$A$6:$AV$49,32,0)) -> 0 | P6: =VLOOKUP($A6,[6]HISTOAVRIL25!$A$6:$AV$49,33,0) -> 0 | Q6: =IF(R6=0,0,($C$3-R6)) -> 0 | R6: =VLOOKUP($A6,[6]HISTOAVRIL25!$A$6:$AV$49,29,0) -> 0
A7: AS201602 | B7: =IF(D7=0,0,VLOOKUP($A7,[6]HISTOAVRIL25!$A$6:$BP$45,10,0)) -> 1 | C7: =VLOOKUP(A7,[7]LISTADHERENT!A$5:H$60,3,0) -> BOUTCHOUANG WILLIAM | D7: =IF(G7="ECHEC",0,B$3) -> 25000 | E7: =D7+VLOOKUP($A7,[6]HISTOAVRIL25!$A$7:$AT$43,45,0)+F7 -> 50000 | F7: =VLOOKUP($A7,[6]HISTOAVRIL25!$A$6:$AU$48,8,0) -> 0 | G7: =VLOOKUP($A7,[6]HISTOAVRIL25!$A$6:$AU$49,9,0) -> BANQUE | H7: =VLOOKUP($A7,[6]HISTOAVRIL25!$A$6:$AV$49,35,0) -> 0 | I7: =VLOOKUP($A7,[6]HISTOAVRIL25!$A$6:$AV$49,38,0) -> 0 | J7: =IF(I7=0,"",VLOOKUP($A7,[6]HISTOAVRIL25!$A$6:$AV$47,42,0)) | K7: =VLOOKUP($A7,[6]HISTOAVRIL25!$A$6:$AV$49,41,0) -> 0 | L7: =TONTMARS25!H7+TONTMARS25!I7 -> 0 | M7: =VLOOKUP($A7,[6]HISTOAVRIL25!$A$6:$AV$49,16,0) -> 0 | N7: =IF(M7<>0,VLOOKUP($A7,[6]HISTOAVRIL25!$A$6:$AV$49,42,0),"ECHEC") -> ECHEC | O7: =IF(R7=0,0,VLOOKUP($A7,[6]HISTOAVRIL25!$A$6:$AV$49,32,0)) -> 0 | P7: =VLOOKUP($A7,[6]HISTOAVRIL25!$A$6:$AV$49,33,0) -> 0 | Q7: =IF(R7=0,0,($C$3-R7)) -> 0 | R7: =VLOOKUP($A7,[6]HISTOAVRIL25!$A$6:$AV$49,29,0) -> 0
A8: AS201604 | B8: =IF(D8=0,0,VLOOKUP($A8,[6]HISTOAVRIL25!$A$6:$BP$45,10,0)) -> 1 | C8: =VLOOKUP(A8,[7]LISTADHERENT!A$5:H$60,3,0) -> DJOMO JEAN PAUL | D8: =IF(G8="ECHEC",0,B$3) -> 25000 | E8: =D8+VLOOKUP($A8,[6]HISTOAVRIL25!$A$7:$AT$43,45,0)+F8 -> 50000 | F8: =VLOOKUP($A8,[6]HISTOAVRIL25!$A$6:$AU$48,8,0) -> 0 | G8: =VLOOKUP($A8,[6]HISTOAVRIL25!$A$6:$AU$49,9,0) -> ESPECES | H8: =VLOOKUP($A8,[6]HISTOAVRIL25!$A$6:$AV$49,35,0) -> 0 | I8: =VLOOKUP($A8,[6]HISTOAVRIL25!$A$6:$AV$49,38,0) -> 0 | J8: =IF(I8=0,"",VLOOKUP($A8,[6]HISTOAVRIL25!$A$6:$AV$47,42,0)) | K8: =VLOOKUP($A8,[6]HISTOAVRIL25!$A$6:$AV$49,41,0) -> 0 | L8: =TONTMARS25!H8+TONTMARS25!I8 -> 0 | M8: =VLOOKUP($A8,[6]HISTOAVRIL25!$A$6:$AV$49,16,0) -> 0 | N8: =IF(M8<>0,VLOOKUP($A8,[6]HISTOAVRIL25!$A$6:$AV$49,42,0),"ECHEC") -> ECHEC | O8: =IF(R8=0,0,VLOOKUP($A8,[6]HISTOAVRIL25!$A$6:$AV$49,32,0)) -> 0 | P8: =VLOOKUP($A8,[6]HISTOAVRIL25!$A$6:$AV$49,33,0) -> 0 | Q8: =IF(R8=0,0,($C$3-R8)) -> 0 | R8: =VLOOKUP($A8,[6]HISTOAVRIL25!$A$6:$AV$49,29,0) -> 0
A9: AS201654 | B9: =IF(D9=0,0,VLOOKUP($A9,[6]HISTOAVRIL25!$A$6:$BP$45,10,0)) -> 1 | C9: =VLOOKUP(A9,[7]LISTADHERENT!A$5:H$60,3,0) -> DJOMOU TCHAPDA | D9: =IF(G9="ECHEC",0,B$3) -> 25000 | E9: =D9+VLOOKUP($A9,[6]HISTOAVRIL25!$A$7:$AT$43,45,0)+F9 -> 50000 | F9: =VLOOKUP($A9,[6]HISTOAVRIL25!$A$6:$AU$48,8,0) -> 0 | G9: =VLOOKUP($A9,[6]HISTOAVRIL25!$A$6:$AU$49,9,0) -> BANQUE | H9: =VLOOKUP($A9,[6]HISTOAVRIL25!$A$6:$AV$49,35,0) -> 30000 | I9: =VLOOKUP($A9,[6]HISTOAVRIL25!$A$6:$AV$49,38,0) -> 2500 | J9: =IF(I9=0,"",VLOOKUP($A9,[6]HISTOAVRIL25!$A$6:$AV$47,42,0)) -> BANQUE | K9: =VLOOKUP($A9,[6]HISTOAVRIL25!$A$6:$AV$49,41,0) -> 0 | L9: =TONTMARS25!H9+TONTMARS25!I9 -> 42000 | M9: =VLOOKUP($A9,[6]HISTOAVRIL25!$A$6:$AV$49,16,0) -> 42000 | N9: =IF(M9<>0,VLOOKUP($A9,[6]HISTOAVRIL25!$A$6:$AV$49,42,0),"ECHEC") -> BANQUE | O9: =IF(R9=0,0,VLOOKUP($A9,[6]HISTOAVRIL25!$A$6:$AV$49,32,0)) -> 0 | P9: =VLOOKUP($A9,[6]HISTOAVRIL25!$A$6:$AV$49,33,0) -> 0 | Q9: =IF(R9=0,0,($C$3-R9)) -> 0 | R9: =VLOOKUP($A9,[6]HISTOAVRIL25!$A$6:$AV$49,29,0) -> 0
A10: AS201605 | B10: =IF(D10=0,0,VLOOKUP($A10,[6]HISTOAVRIL25!$A$6:$BP$45,10,0)) -> 1 | C10: =VLOOKUP(A10,[7]LISTADHERENT!A$5:H$60,3,0) -> DJOUKWE NANGUEN GUY BLAISE | D10: =IF(G10="ECHEC",0,B$3) -> 25000 | E10: =D10+VLOOKUP($A10,[6]HISTOAVRIL25!$A$7:$AT$43,45,0)+F10 -> 50000 | F10: =VLOOKUP($A10,[6]HISTOAVRIL25!$A$6:$AU$48,8,0) -> 0 | G10: =VLOOKUP($A10,[6]HISTOAVRIL25!$A$6:$AU$49,9,0) -> BANQUE | H10: =VLOOKUP($A10,[6]HISTOAVRIL25!$A$6:$AV$49,35,0) -> 0 | I10: =VLOOKUP($A10,[6]HISTOAVRIL25!$A$6:$AV$49,38,0) -> 0 | J10: =IF(I10=0,"",VLOOKUP($A10,[6]HISTOAVRIL25!$A$6:$AV$47,42,0)) | K10: =VLOOKUP($A10,[6]HISTOAVRIL25!$A$6:$AV$49,41,0) -> 0 | L10: =TONTMARS25!H10+TONTMARS25!I10 -> 0 | M10: =VLOOKUP($A10,[6]HISTOAVRIL25!$A$6:$AV$49,16,0) -> 0 | N10: =IF(M10<>0,VLOOKUP($A10,[6]HISTOAVRIL25!$A$6:$AV$49,42,0),"ECHEC") -> ECHEC | O10: =IF(R10=0,0,VLOOKUP($A10,[6]HISTOAVRIL25!$A$6:$AV$49,32,0)) -> 0 | P10: =VLOOKUP($A10,[6]HISTOAVRIL25!$A$6:$AV$49,33,0) -> 0 | Q10: =IF(R10=0,0,($C$3-R10)) -> 0 | R10: =VLOOKUP($A10,[6]HISTOAVRIL25!$A$6:$AV$49,29,0) -> 0
A11: AS201608 | B11: =IF(D11=0,0,VLOOKUP($A11,[6]HISTOAVRIL25!$A$6:$BP$45,10,0)) -> 1 | C11: =VLOOKUP(A11,[7]LISTADHERENT!A$5:H$60,3,0) -> DJUOMBESSY ANTOINE | D11: =IF(G11="ECHEC",0,B$3) -> 25000 | E11: =D11+VLOOKUP($A11,[6]HISTOAVRIL25!$A$7:$AT$43,45,0)+F11 -> 60000 | F11: =VLOOKUP($A11,[6]HISTOAVRIL25!$A$6:$AU$48,8,0) -> 0 | G11: =VLOOKUP($A11,[6]HISTOAVRIL25!$A$6:$AU$49,9,0) -> BANQUE | H11: =VLOOKUP($A11,[6]HISTOAVRIL25!$A$6:$AV$49,35,0) -> 0 | I11: =VLOOKUP($A11,[6]HISTOAVRIL25!$A$6:$AV$49,38,0) -> 0 | J11: =IF(I11=0,"",VLOOKUP($A11,[6]HISTOAVRIL25!$A$6:$AV$47,42,0)) | K11: =VLOOKUP($A11,[6]HISTOAVRIL25!$A$6:$AV$49,41,0) -> 0 | L11: =TONTMARS25!H11+TONTMARS25!I11 -> 0 | M11: =VLOOKUP($A11,[6]HISTOAVRIL25!$A$6:$AV$49,16,0) -> 0 | N11: =IF(M11<>0,VLOOKUP($A11,[6]HISTOAVRIL25!$A$6:$AV$49,42,0),"ECHEC") -> ECHEC | O11: =IF(R11=0,0,VLOOKUP($A11,[6]HISTOAVRIL25!$A$6:$AV$49,32,0)) -> 0 | P11: =VLOOKUP($A11,[6]HISTOAVRIL25!$A$6:$AV$49,33,0) -> 0 | Q11: =IF(R11=0,0,($C$3-R11)) -> 0 | R11: =VLOOKUP($A11,[6]HISTOAVRIL25!$A$6:$AV$49,29,0) -> 0
A12: AS201651 | B12: =IF(D12=0,0,VLOOKUP($A12,[6]HISTOAVRIL25!$A$6:$BP$45,10,0)) -> 1 | C12: =VLOOKUP(A12,[7]LISTADHERENT!A$5:H$60,3,0) -> DOMOU FABIEN | D12: =IF(G12="ECHEC",0,B$3) -> 25000 | E12: =D12+VLOOKUP($A12,[6]HISTOAVRIL25!$A$7:$AT$43,45,0)+F12 -> 50000 | F12: =VLOOKUP($A12,[6]HISTOAVRIL25!$A$6:$AU$48,8,0) -> 0 | G12: =VLOOKUP($A12,[6]HISTOAVRIL25!$A$6:$AU$49,9,0) -> BANQUE | H12: =VLOOKUP($A12,[6]HISTOAVRIL25!$A$6:$AV$49,35,0) -> 0 | I12: =VLOOKUP($A12,[6]HISTOAVRIL25!$A$6:$AV$49,38,0) -> 0 | J12: =IF(I12=0,"",VLOOKUP($A12,[6]HISTOAVRIL25!$A$6:$AV$47,42,0)) | K12: =VLOOKUP($A12,[6]HISTOAVRIL25!$A$6:$AV$49,41,0) -> 0 | L12: =TONTMARS25!H12+TONTMARS25!I12 -> 0 | M12: =VLOOKUP($A12,[6]HISTOAVRIL25!$A$6:$AV$49,16,0) -> 0 | N12: =IF(M12<>0,VLOOKUP($A12,[6]HISTOAVRIL25!$A$6:$AV$49,42,0),"ECHEC") -> ECHEC | O12: =IF(R12=0,0,VLOOKUP($A12,[6]HISTOAVRIL25!$A$6:$AV$49,32,0)) -> 0 | P12: =VLOOKUP($A12,[6]HISTOAVRIL25!$A$6:$AV$49,33,0) -> 0 | Q12: =IF(R12=0,0,($C$3-R12)) -> 0 | R12: =VLOOKUP($A12,[6]HISTOAVRIL25!$A$6:$AV$49,29,0) -> 0
A13: AS201609 | B13: =IF(D13=0,0,VLOOKUP($A13,[6]HISTOAVRIL25!$A$6:$BP$45,10,0)) -> 1 | C13: =VLOOKUP(A13,[7]LISTADHERENT!A$5:H$60,3,0) -> DONHOU DAVID | D13: =IF(G13="ECHEC",0,B$3) -> 25000 | E13: =D13+VLOOKUP($A13,[6]HISTOAVRIL25!$A$7:$AT$43,45,0)+F13 -> 50000 | F13: =VLOOKUP($A13,[6]HISTOAVRIL25!$A$6:$AU$48,8,0) -> 0 | G13: =VLOOKUP($A13,[6]HISTOAVRIL25!$A$6:$AU$49,9,0) -> BANQUE | H13: =VLOOKUP($A13,[6]HISTOAVRIL25!$A$6:$AV$49,35,0) -> 0 | I13: =VLOOKUP($A13,[6]HISTOAVRIL25!$A$6:$AV$49,38,0) -> 0 | J13: =IF(I13=0,"",VLOOKUP($A13,[6]HISTOAVRIL25!$A$6:$AV$47,42,0)) | K13: =VLOOKUP($A13,[6]HISTOAVRIL25!$A$6:$AV$49,41,0) -> 0 | L13: =TONTMARS25!H13+TONTMARS25!I13 -> 0 | M13: =VLOOKUP($A13,[6]HISTOAVRIL25!$A$6:$AV$49,16,0) -> 0 | N13: =IF(M13<>0,VLOOKUP($A13,[6]HISTOAVRIL25!$A$6:$AV$49,42,0),"ECHEC") -> ECHEC | O13: =IF(R13=0,0,VLOOKUP($A13,[6]HISTOAVRIL25!$A$6:$AV$49,32,0)) -> 0 | P13: =VLOOKUP($A13,[6]HISTOAVRIL25!$A$6:$AV$49,33,0) -> 0 | Q13: =IF(R13=0,0,($C$3-R13)) -> 0 | R13: =VLOOKUP($A13,[6]HISTOAVRIL25!$A$6:$AV$49,29,0) -> 0
A14: AS201663 | B14: =IF(D14=0,0,VLOOKUP($A14,[6]HISTOAVRIL25!$A$6:$BP$45,10,0)) -> 1 | C14: =VLOOKUP(A14,[7]LISTADHERENT!A$5:H$60,3,0) -> FAMPOU PAUL | D14: =IF(G14="ECHEC",0,B$3) -> 25000 | E14: =D14+VLOOKUP($A14,[6]HISTOAVRIL25!$A$7:$AT$43,45,0)+F14 -> 50000 | F14: =VLOOKUP($A14,[6]HISTOAVRIL25!$A$6:$AU$48,8,0) -> 0 | G14: =VLOOKUP($A14,[6]HISTOAVRIL25!$A$6:$AU$49,9,0) -> BANQUE | H14: =VLOOKUP($A14,[6]HISTOAVRIL25!$A$6:$AV$49,35,0) -> 0 | I14: =VLOOKUP($A14,[6]HISTOAVRIL25!$A$6:$AV$49,38,0) -> 0 | J14: =IF(I14=0,"",VLOOKUP($A14,[6]HISTOAVRIL25!$A$6:$AV$47,42,0)) | K14: =VLOOKUP($A14,[6]HISTOAVRIL25!$A$6:$AV$49,41,0) -> 0 | L14: =TONTMARS25!H14+TONTMARS25!I14 -> 0 | M14: =VLOOKUP($A14,[6]HISTOAVRIL25!$A$6:$AV$49,16,0) -> 0 | N14: =IF(M14<>0,VLOOKUP($A14,[6]HISTOAVRIL25!$A$6:$AV$49,42,0),"ECHEC") -> ECHEC | O14: =IF(R14=0,0,VLOOKUP($A14,[6]HISTOAVRIL25!$A$6:$AV$49,32,0)) -> 0 | P14: =VLOOKUP($A14,[6]HISTOAVRIL25!$A$6:$AV$49,33,0) -> 0 | Q14: =IF(R14=0,0,($C$3-R14)) -> 0 | R14: =VLOOKUP($A14,[6]HISTOAVRIL25!$A$6:$AV$49,29,0) -> 0
A15: AS201611 | B15: =IF(D15=0,0,VLOOKUP($A15,[6]HISTOAVRIL25!$A$6:$BP$45,10,0)) -> 1 | C15: =VLOOKUP(A15,[7]LISTADHERENT!A$5:H$60,3,0) -> HENGUE PAUL OMER | D15: =IF(G15="ECHEC",0,B$3) -> 25000 | E15: =D15+VLOOKUP($A15,[6]HISTOAVRIL25!$A$7:$AT$43,45,0)+F15 -> 45000 | F15: =VLOOKUP($A15,[6]HISTOAVRIL25!$A$6:$AU$48,8,0) -> 0 | G15: =VLOOKUP($A15,[6]HISTOAVRIL25!$A$6:$AU$49,9,0) -> BANQUE | H15: =VLOOKUP($A15,[6]HISTOAVRIL25!$A$6:$AV$49,35,0) -> 0 | I15: =VLOOKUP($A15,[6]HISTOAVRIL25!$A$6:$AV$49,38,0) -> 0 | J15: =IF(I15=0,"",VLOOKUP($A15,[6]HISTOAVRIL25!$A$6:$AV$47,42,0)) | K15: =VLOOKUP($A15,[6]HISTOAVRIL25!$A$6:$AV$49,41,0) -> 0 | L15: =TONTMARS25!H15+TONTMARS25!I15 -> 0 | M15: =VLOOKUP($A15,[6]HISTOAVRIL25!$A$6:$AV$49,16,0) -> 0 | N15: =IF(M15<>0,VLOOKUP($A15,[6]HISTOAVRIL25!$A$6:$AV$49,42,0),"ECHEC") -> ECHEC | O15: =IF(R15=0,0,VLOOKUP($A15,[6]HISTOAVRIL25!$A$6:$AV$49,32,0)) -> 0 | P15: =VLOOKUP($A15,[6]HISTOAVRIL25!$A$6:$AV$49,33,0) -> 0 | Q15: =IF(R15=0,0,($C$3-R15)) -> 0 | R15: =VLOOKUP($A15,[6]HISTOAVRIL25!$A$6:$AV$49,29,0) -> 0
A16: AS201613 | B16: =IF(D16=0,0,VLOOKUP($A16,[6]HISTOAVRIL25!$A$6:$BP$45,10,0)) -> 1 | C16: =VLOOKUP(A16,[7]LISTADHERENT!A$5:H$60,3,0) -> HOTCHO BENJAMIN | D16: =IF(G16="ECHEC",0,B$3) -> 25000 | E16: =D16+VLOOKUP($A16,[6]HISTOAVRIL25!$A$7:$AT$43,45,0)+F16 -> 45000 | F16: =VLOOKUP($A16,[6]HISTOAVRIL25!$A$6:$AU$48,8,0) -> 0 | G16: =VLOOKUP($A16,[6]HISTOAVRIL25!$A$6:$AU$49,9,0) -> BANQUE | H16: =VLOOKUP($A16,[6]HISTOAVRIL25!$A$6:$AV$49,35,0) -> 0 | I16: =VLOOKUP($A16,[6]HISTOAVRIL25!$A$6:$AV$49,38,0) -> 0 | J16: =IF(I16=0,"",VLOOKUP($A16,[6]HISTOAVRIL25!$A$6:$AV$47,42,0)) | K16: =VLOOKUP($A16,[6]HISTOAVRIL25!$A$6:$AV$49,41,0) -> 0 | L16: =TONTMARS25!H16+TONTMARS25!I16 -> 0 | M16: =VLOOKUP($A16,[6]HISTOAVRIL25!$A$6:$AV$49,16,0) -> 0 | N16: =IF(M16<>0,VLOOKUP($A16,[6]HISTOAVRIL25!$A$6:$AV$49,42,0),"ECHEC") -> ECHEC | O16: =IF(R16=0,0,VLOOKUP($A16,[6]HISTOAVRIL25!$A$6:$AV$49,32,0)) -> 0 | P16: =VLOOKUP($A16,[6]HISTOAVRIL25!$A$6:$AV$49,33,0) -> 0 | Q16: =IF(R16=0,0,($C$3-R16)) -> 0 | R16: =VLOOKUP($A16,[6]HISTOAVRIL25!$A$6:$AV$49,29,0) -> 0
