Workbook
Name BANQUE: #REF!
Name BANQUE: #REF!
Name BANQUE: #REF!
Name BANQUE: #REF!
Name BANQUE: #REF!
Name BANQUE: #REF!
Name BANQUE: #REF!
Name BANQUE: #REF!
Name BANQUE: #REF!
Name BANQUE: #REF!
Name BANQUE: #REF!
Name BANQUE: #REF!
Name MODEET30000: [1]MODEVERSEMENT!$A$1:$A$3
Name MODEPAID: [2]Feuil2!$A$1:$A$3
Name MODEPAID: [2]Feuil2!$A$1:$A$3
Name MODEPAID: [2]Feuil2!$A$1:$A$3
Name MODEPAID: [3]Feuil2!$A$1:$A$3
Name MODEPAID: [4]Feuil2!$A$1:$A$3
Name MODEPAID30000: DETAILFICHECASSATION!#REF!
Name MODEPAIDOK: [5]MODEVERSEMENT!$A$1:$A$4
Name MODEPAIDOK: [5]MODEVERSEMENT!$A$1:$A$4
Name MODEPAIDS: [1]MODEVERSEMENT!$A$1:$A$3
Name MODET25000: [6]MODEVERSEMENT!$A$1:$A$3
Name MODET3000: [1]MODEVERSEMENT!$A$1:$A$3
Name MODET30000: DETAILFICHECASSATION!#REF!
Name MODEVERSEMENT: #REF!
Name MODEVERSEMENT: #REF!
Name MODEVERSEMENT: #REF!
Name MODEVERSEMENT: #REF!
Name MODEVERSEMENT: #REF!
Name MODEVERSEMENT: #REF!
Name MODEVERSEMENT: #REF!
Name MODEVERSEMENT: #REF!
Name MODEVERSEMENT: #REF!
Name MODEVERSEMENT: #REF!
Name MODEVERSEMENT: #REF!
Name MODEVERSEMENT: #REF!
Name MODEVERSEMENTS: [7]MODEVERSEMENT!$A$1:$A$3
Name MODPAID: DETAILFICHECASSATION!#REF!
Name VALMODEPAID: [8]MODEPAID!$A$1:$A$3

Sheet BILAN 2016
A2: BILAN ALLANT DE LA PERIODE DU 01 DECEMBRE 2015 AU 30 NOVEMBRE 2016
A5: RUBRIQUE | B5: REPORT A NOUVEAU | C5: ENTREES | D5: SORTIES | E5: SOLDE
A7: EPARGNE\RELIQUAT2015 | B7: 29756024 | C7: =[9]TRAVAUXINVENTAIRE!R54+C20+1050000+2230668 -> 7101809 | E7: =B7+C7-D7 -> 36857833
A8: FONDS DE CAISSE | C8: 28382451 | D8: 39386431 | E8: =B8+C8-D8 -> -11003980
A9: FONDS DE ROULEMENT | B9: 3031178 | C9: =[9]TRAVAUXINVENTAIRE!S54 -> 250500 | D9: ='[10]BILAN 2016'!$D$9 -> 224500 | E9: =B9+C9-D9 -> 3057178
A10: FRAIS EXCEPTIONNELS | B10: 1267460 | C10: =[9]TRAVAUXINVENTAIRE!T54 -> 501000 | D10: =[9]TRAVAUXINVENTAIREDEC!B6 -> 1100000 | E10: =B10+C10-D10 -> 668460
A11: COLLATION | B11: 940125 | C11: =[9]TRAVAUXINVENTAIRE!U54 -> 1252500 | D11: =[9]TRAVAUXINVENTAIREDEC!B7 -> 1260000 | E11: =B11+C11-D11 -> 932625
A12: MUTUELLE\COMPLEMENT MUTUEL | B12: =-101500 -> -101500 | C12: =[9]TRAVAUXINVENTAIRE!V54+[9]TRAVAUXINVENTAIRE!O54 -> 1954860 | D12: =[9]TRAVAUXINVENTAIREDEC!B8 -> 2595000 | E12: =B12+C12-D12 -> -741640
A13: INSCRIPTION | B13: 530000 | E13: =B13+C13-D13 -> 530000
A14: FONDS GELE | B14: 54508 | E14: =B14+C14-D14 -> 54508
A15: CHAISE | B15: -164500 | E15: =B15+C15-D15 -> -164500
A16: TENUE | B16: -75000 | E16: =B16+C16-D16 -> -75000
A17: FOYER | E17: =B17+C17-D17 -> 0
A18: RECOUVREMENT POUR LAGWEU GENERAL | C18: =320750+16500 -> 337250 | E18: =B18+C18-D18 -> 337250 | F18: 1711250
A19: AUTRES | E19: =B19+C19-D19 -> 0
A20: INTERET EMPRUNT | E20: =B20+C20-D20 -> 0
A22: EMPRUNT
A24: RELIQUAT 2016
A27: COMPTE CCA
A28: COMPTE AFRILAND
A29: INTERET BQUE AFRILAND | B29: 1779594 | E29: =B29+C29-D29 -> 1779594
A30: COMPTE MC2
A31: ASELBY CAISSE(NDJOMO ETIENNE)
A33: RETRAIT DISTRIBUTION EPARGNE
A35: SOUS TOTAL
A37: MONTANT DISPONIBLE | B37: =SUM(B7:B36) -> 37017889 | C37: =SUM(C7:C36) -> 39780370 | D37: =SUM(D7:D36) -> 44565931 | E37: =B37+C37-D37 -> 32232328

Sheet BILAN 2017
A2: BILAN ALLANT DE LA PERIODE DU 01 DECEMBRE 2016 AU 30 AOUT 2017
A5: RUBRIQUE | B5: REPORT A NOUVEAU | C5: ENTREES | D5: SORTIES | E5: SOLDE
A7: EPARGNE\RELIQUAT2016 | B7: ='BILAN 2016'!E7 -> 36857833 | C7: =[11]BILANFINAOUT2017!E56 -> 3963693 | D7: 13500000 | E7: =B7+C7-D7 -> 27321526
A8: FONDS DE CAISSE | B8: ='BILAN 2016'!E8 -> -11003980 | C8: =[11]BILANFINAOUT2017!C56 -> 16310819 | E8: =B8+C8-D8 -> 5306839
A9: FONDS DE ROULEMENT | B9: ='BILAN 2016'!E9 -> 3057178 | C9: =[11]BILANFINAOUT2017!F56 -> 182000 | D9: =89000+84000+12000+10000+6000+48000+13000+5000 -> 267000 | E9: =B9+C9-D9 -> 2972178
A10: FRAIS EXCEPTIONNELS | B10: ='BILAN 2016'!E10 -> 668460 | C10: =[11]BILANFINAOUT2017!G56 -> 364000 | D10: =200000+345000 -> 545000 | E10: =B10+C10-D10 -> 487460
A11: COLLATION | B11: ='BILAN 2016'!E11 -> 932625 | C11: =[11]BILANFINAOUT2017!H56 -> 910000 | D11: =100000+110000+100000+100000+100000+100000+100000+100000+100000 -> 910000 | E11: =B11+C11-D11 -> 932625
A12: MUTUELLE\COMPLEMENT MUTUEL | B12: ='BILAN 2016'!E12 -> -741640 | C12: =[11]BILANFINAOUT2017!I56 -> 2009927 | D12: =200000+100000+640000 -> 940000 | E12: =B12+C12-D12 -> 328287
A13: PENALITE VERSEMENT EN ESPECES | C13: =[11]BILANFINAOUT2017!R56 -> 125000 | E13: =B13+C13-D13 -> 125000
A14: SANCTION | C14: =+[11]BILANFINAOUT2017!J56 -> 0
A15: INSCRIPTION | B15: ='BILAN 2016'!E13 -> 530000 | E15: =B15+C15-D15 -> 530000
A16: FONDS GELE | B16: ='BILAN 2016'!E14 -> 54508 | E16: =B16+C16-D16 -> 54508
A17: CHAISE | B17: ='BILAN 2016'!E15 -> -164500 | E17: =B17+C17-D17 -> -164500
A18: TENUE | B18: ='BILAN 2016'!E16 -> -75000 | E18: =B18+C18-D18 -> -75000
E19: =B19+C19-D19 -> 0
A20: FOYER | E20: =B20+C20-D20 -> 0
A21: RECOUVREMENT POUR LAGWEU GENERAL | B21: ='BILAN 2016'!E18 -> 337250 | E21: =B21+C21-D21 -> 337250
A22: AUTRES
A23: INTERET EMPRUNT
A25: EMPRUNT | E25: =B25+C25-D25 -> 0
A27: RELIQUAT 2016
A29: INTERET BQUE AFRILAND | B29: 1779594 | E29: =B29+C29-D29 -> 1779594
A30: COMPTE CCA
A31: COMPTE AFRILAND
A32: COMPTE MC2
A33: ASELBY CAISSE(NDJOMO ETIENNE)
A35: RETRAIT DISTRIBUTION EPARGNE
A39: MONTANT DISPONIBLE | B39: =SUM(B7:B38) -> 32232328 | C39: =SUM(C7:C38) -> 23865439 | D39: =SUM(D7:D38) -> 16162000 | E39: =B39+C39-D39 -> 39935767

Sheet BILAN 2022
B1: ASELBY
B2: ANNEE | C2: 2022
B3: SYNTHESE DES COMPTES
A6: NUMERO ORDRE | B6: RUBRIQUE | C6: REPORT A NOUVEAU | D6: ENTREES | E6: SORTIES | F6: SOLDE
A8: 1 | B8: FONDS DE CAISSE ET RELIQUAT | C8: 21791466 | E8: 500000 | F8: 21291466
A9: 2 | B9: FONDS DE ROULEMENT | C9: 2074728 | D9: 156000 | E9: 234500 | F9: 1996228
A10: 3 | B10: FRAIS EXCEPTIONNELS | C10: 1191460 | D10: 312000 | E10: 0 | F10: 1503460
A11: 4 | B11: MUTUELLE\COMPLEMENT MUTUEL | C11: 94762 | D11: 520000 | E11: 0 | F11: =C11+D11 -> 614762
A12: 5 | B12: INSCRIPTION | C12: 680000 | D12: 0 | E12: 0 | F12: 680000
A13: 6 | B13: PENALITES | C13: 1122025 | D13: 96000 | E13: 450000 | F13: 768025
A14: 7 | B14: COLLATION | C14: 1310525 | D14: 780000 | E14: 770000 | F14: 1320525
A15: 8 | B15: TONTINE DE PRESENCE | C15: 94000 | F15: 94000
A16: 9 | B16: RECOUVREMENT POUR LA'AGWEU | F16: 0
A17: 10 | B17: FOYER | C17: 527000 | D17: 1836000 | E17: 1820000 | F17: 543000
A18: 11 | B18: CHAISES | C18: 164500 | E18: 164500 | F18: 0
A19: 12 | B19: DIVERS | C19: 619900 | E19: 619900 | F19: 0
A20: 13 | B20: TENUES | C20: 75000 | E20: 75000 | F20: 0
A21: 14 | B21: FONDS GELES | C21: 54508 | E21: 54508 | F21: 0
A22: 15 | B22: INTERETS ET AUTRES | C22: 2858226 | D22: 3748108 | F22: 6606334
B23: INTERET TONTINE 100 | D23: 28000 | F23: 28000
B25: TOTAL | C25: 32658100 | D25: =SUM(D9:D23) -> 7476108 | E25: 4688408 | F25: =SUM(F8:F23) -> 35445800 | H25: 479000
B27: DISPOSITION DES FONDS
C30: 2021 | D30: 2022
A31: 1 | B31: COMPTE CCA AU 30/12/2022 | C31: 7304779 | D31: 4337431
A32: 2 | B32: COMPTE MC²(NON ACTUALISE) | C32: 630005 | D32: 630005
A33: 3 | B33: COMPTE AFRILAND | C33: 1423702 | D33: 1423702
A34: 4 | B34: DETTE PREFINANCEMENT LA'AGWEU | C34: 744700 | D34: 744700
A35: 5 | B35: DETTE MR KOUATCHO | C35: 275000 | D35: 0
A36: 6 | B36: RESTE A RECUPERE AU CONSEIL | C36: 154000 | D36: 154000
A37: 7 | B37: FONDS EN CIRCULATION | C37: 20515659 | D37: 18658500
A38: 8 | B38: DETTES TONTINES | C38: 1233618 | D38: 656618
B40: TOTAL | C40: 32281463 | D40: 26604956

Sheet BILAN 2023
B1: ASELBY
B2: ANNEE | C2: 2023
B3: SYNTHESE DES COMPTES
A6: NUMERO ORDRE | B6: RUBRIQUE | C6: REPORT A NOUVEAU | D6: ENTREES | E6: SORTIES | F6: SOLDE
A8: 1 | B8: FONDS DE CAISSE ET RECONDUCTION | C8: 21291466 | D8: =DETAILFICHECASSATION!L38+DETAILFICHECASSATION!R38 -> 24118743 | E8: =SORTIE!B22 -> 640700 | F8: =C8+D8-E8 -> 44769509
A9: 2 | B9: FONDS DE ROULEMENT | C9: 1996228 | D9: =+DETAILFPNDSROULT!C40 -> 363000 | E9: =DETAILFPNDSROULT!F40 -> 193000 | F9: =C9+D9-E9 -> 2166228
A10: 3 | B10: FRAIS EXCEPTIONNELS | C10: 1503460 | D10: =DETAILFRAISEXCEPTIONNEL!C40 -> 360000 | E10: =DETAILFRAISEXCEPTIONNEL!F40 -> 825000 | F10: =C10+D10-E10 -> 1038460
A11: 4 | B11: MUTUELLE\COMPLEMENT MUTUEL | C11: 614762 | D11: =DETAILFONDSMUTUEL!C40+DETAILFONDSMUTUEL!D40 -> 1520000 | E11: =DETAILFONDSMUTUEL!H40 -> 1320000 | F11: =C11+D11-E11 -> 814762
A12: 5 | B12: INSCRIPTION | C12: 680000 | D12: =DETAILINSCRIPTION!C40 -> 75000 | E12: =DETAILINSCRIPTION!F40 -> 0 | F12: =C12+D12-E12 -> 755000
A13: 6 | B13: PENALITES PAIEMENT ESPECES | C13: 768025 | D13: =DETAILPENALITES!C40 -> 79000 | E13: =DETAILPENALITES!G40 -> 200000 | F13: =C13+D13-E13 -> 647025
A14: 7 | B14: SANCTION | D14: =DETAILPENALITES!D40 -> 207000
A15: 8 | B15: COLLATION | C15: 1320525 | D15: =DETAILCOLLATION!C40 -> 1440000 | E15: =DETAILCOLLATION!F40 -> 1010000 | F15: =C15+D15-E15 -> 1750525
A16: 9 | B16: TONTINE DE PRESENCE | C16: 94000 | D16: =[12]TONTRESUME23!$D$38 -> 9000000 | E16: =[12]TONTRESUME23!$Q$38 -> 8788000 | F16: =C16+D16-E16 -> 306000
A17: 10 | B17: RECOUVREMENT POUR LA'AGWEU | C17: 0 | F17: =C17+D17-E17 -> 0
A18: 11 | B18: FOYER | C18: 543000 | D18: =DETAILFOYER!C40 -> 2240000 | E18: =DETAILFOYER!F40 -> 1750000 | F18: =C18+D18-E18 -> 1033000
A19: 12 | B19: CHAISES | C19: 0 | F19: =C19+D19-E19 -> 0
A20: 13 | B20: DIVERS | C20: 0 | F20: =C20+D20-E20 -> 0
A21: 14 | B21: TENUES | C21: 0 | F21: =C21+D21-E21 -> 0
A22: 15 | B22: FONDS GELES | C22: 0 | F22: =C22+D22-E22 -> 0
A23: 16 | B23: INTERETS ET AUTRES | C23: 6606334 | F23: =C23+D23-E23 -> 6606334
A24: 17 | B24: INTERET TONTINE | C24: 28000 | D24: =[13]TONTRESUME23!$S$6+[14]TONTRESUME23!$S$6 -> 63707.983 | F24: =C24+D24-E24 -> 91707.983
B26: TOTAL | C26: =SUM(C8:C24) -> 35445800 | D26: =SUM(D8:D24) -> 39466451 | E26: =SUM(E8:E24) -> 14726700 | F26: =SUM(F8:F24) -> 59978551
B28: DISPOSITION DES FONDS
C31: 2022 | D31: 2023
A32: 1 | B32: COMPTE CCA AU 30/12/2022 | C32: 4337431
A33: 2 | B33: COMPTE MC²(NON ACTUALISE) | C33: 630005
A34: 3 | B34: COMPTE AFRILAND | C34: 1423702
A35: 4 | B35: DETTE PREFINANCEMENT LA'AGWEU | C35: 744700
A36: 5 | B36: DETTE MR KOUATCHO | C36: 0
A37: 6 | B37: RESTE A RECUPERE AU CONSEIL | C37: 154000
A38: 7 | B38: FONDS EN CIRCULATION | C38: 18658500 | D38: =[15]MVTRESUME23!$AK$40 -> 14068300
A39: 8 | B39: DETTES TONTINES | C39: 656618
B41: TOTAL | C41: =SUM(C32:C40) -> 26604956 | D41: =SUM(D32:D40) -> 14068300

Sheet ENTREE
D2: ENTREE DES DIFFERENTES RUBRIQUES
A3: ANNEE | E3: 2023
A6: MOIS | B6: FONDS DE CAISSE | C6: RELIQUAT | D6: INTERET | E6: EPARGNE | F6: FONDS DE ROULEMENT | G6: FRAIS EXCEPTIONNEL | H6: COLLATION | I6: PENALITE VST ESPECES | J6: INSCRIPTION | K6: MUTUELLE | L6: REMBOURSEMENT | M6: SANCTION | N6: FOYER | O6: INTERET TONTINE | P6: TOTAL
A7: REPORT | B7: =[15]MVTJANV23!$C$40 -> 15600000 | C7: =[15]MVTJANV23!$D$40 -> 4361558.5
A8: JANVIER | D8: =[15]MVTDEC22!$G$39 -> 1268000 | E8: =[15]MVTJANV23!$K$40 -> 1050000 | F8: =[15]MVTJANV23!$L$40 -> 30000 | G8: =[15]MVTJANV23!$M$40 -> 30000 | H8: =[15]MVTJANV23!$N$40 -> 120000 | I8: =[15]MVTJANV23!$O$40 -> 0 | J8: =[15]MVTJANV23!$P$40 -> 75000 | K8: =[15]MVTJANV23!$Q$40 -> 35000 | L8: =[15]MVTJANV23!$U$40 -> 0 | M8: =[15]MVTJANV23!$I$40 -> 0 | N8: =[15]MVTJANV23!$AD$40 -> 210000 | P8: =SUM(B8:O8) -> 2818000
A9: FÉVRIER | D9: =[15]MVTFEV23!$G$40 -> 30000 | E9: =[15]MVTFEV23!$K$40 -> 328000 | F9: =[15]MVTFEV23!$L$40 -> 30000 | G9: =[15]MVTFEV23!$M$40 -> 30000 | H9: =[15]MVTFEV23!$N$40 -> 120000 | I9: =[15]MVTFEV23!$O$40 -> 0 | J9: =[15]MVTFEV23!$P$40 -> 0 | K9: =[15]MVTFEV23!$Q$40 -> 60000 | L9: =[15]MVTFEV23!$U$40 -> 2500000 | M9: =[15]MVTFEV23!$I$40 -> 0 | N9: =[15]MVTFEV23!$AD$40 -> 210000 | P9: =SUM(B9:O9) -> 3308000
A10: MARS | D10: =[15]MVTMARS23!$G$40 -> 6000 | E10: =[15]MVTMARS23!$K$40 -> 345000 | F10: =[15]MVTMARS23!$L$40 -> 29000 | G10: =[15]MVTMARS23!$M$40 -> 30000 | H10: =[15]MVTMARS23!$N$40 -> 120000 | I10: =[15]MVTMARS23!$O$40 -> 6000 | J10: =[15]MVTMARS23!$P$40 -> 0 | K10: =[15]MVTMARS23!$Q$40 -> 25000 | L10: =[15]MVTMARS23!$U$40 -> 1582500 | M10: =[15]MVTMARS23!$I$40 -> 0 | N10: =[15]MVTMARS23!$AD$40 -> 210000 | P10: =SUM(B10:O10) -> 2353500
A11: AVRIL | D11: =[15]MVTAVRIL23!$G$40 -> 204000 | E11: =[15]MVTAVRIL23!$K$40 -> 386000 | F11: =[15]MVTAVRIL23!$L$40 -> 28000 | G11: =[15]MVTAVRIL23!$M$40 -> 29000 | H11: =[15]MVTAVRIL23!$N$40 -> 116000 | I11: =[15]MVTAVRIL23!$O$40 -> 12000 | J11: =[15]MVTAVRIL23!$P$40 -> 0 | K11: =[15]MVTAVRIL23!$Q$40 -> 120000 | L11: =[15]MVTAVRIL23!$U$40 -> 1357500 | M11: =[15]MVTAVRIL23!$I$40 -> 0 | N11: =[15]MVTAVRIL23!$AD$40 -> 140000 | P11: =SUM(B11:O11) -> 2392500
A12: MAI | D12: =[15]MVTMAI23!$G$40 -> 30000 | E12: =[15]MVTMAI23!$K$40 -> 882000 | F12: =[15]MVTMAI23!$L$40 -> 33000 | G12: =[15]MVTMAI23!$M$40 -> 31000 | H12: =[15]MVTMAI23!$N$40 -> 124000 | I12: =[15]MVTMAI23!$O$40 -> 19000 | J12: =[15]MVTMAI23!$P$40 -> 0 | K12: =[15]MVTMAI23!$Q$40 -> 120000 | L12: =[15]MVTMAI23!$U$40 -> 0 | M12: =[15]MVTMAI23!$I$40 -> 0 | N12: =[15]MVTMAI23!$AD$40 -> 280000 | P12: =SUM(B12:O12) -> 1519000
A13: JUIN | D13: =[15]MVTJUIN23!$G$40 -> 74200 | E13: =[15]MVTJUIN23!$K$40 -> 426500 | F13: =[15]MVTJUIN23!$L$40 -> 30000 | G13: =[15]MVTJUIN23!$M$40 -> 30000 | H13: =[15]MVTJUIN23!$N$40 -> 120000 | I13: =[15]MVTJUIN23!$O$40 -> 3000 | J13: =[15]MVTJUIN23!$P$40 -> 0 | K13: =[15]MVTJUIN23!$Q$40 -> 0 | L13: =[15]MVTJUIN23!$U$40 -> 2500000 | M13: =[15]MVTJUIN23!$I$40 -> 0 | N13: =[15]MVTJUIN23!$AD$40 -> 70000 | P13: =SUM(B13:O13) -> 3253700
A14: JUILLET | D14: =[15]MVTJUIL23!$G$40 -> 50000 | E14: =[15]MVTJUIL23!$K$40 -> 561768 | F14: =[15]MVTJUIL23!$L$40 -> 30000 | G14: =[15]MVTJUIL23!$M$40 -> 30000 | H14: =[15]MVTJUIL23!$N$40 -> 120000 | I14: =[15]MVTJUIL23!$O$40 -> 15000 | J14: =[15]MVTJUIL23!$P$40 -> 0 | K14: =[15]MVTJUIL23!$Q$40 -> 0 | L14: =[15]MVTJUIL23!$U$40 -> 250000 | M14: =[15]MVTJUIL23!$I$40 -> 0 | N14: =[15]MVTJUIL23!$AD$40 -> 280000 | P14: =SUM(B14:O14) -> 1336768
A15: AOÛT | D15: =[15]MVTAOUT23!$G$40 -> 64000 | E15: =[15]MVTAOUT23!$K$40 -> 394000 | F15: =[15]MVTAOUT23!$L$40 -> 32000 | G15: =[15]MVTAOUT23!$M$40 -> 29000 | H15: =[15]MVTAOUT23!$N$40 -> 116000 | I15: =[15]MVTAOUT23!$O$40 -> 3000 | J15: =[15]MVTAOUT23!$P$40 -> 0 | K15: =[15]MVTAOUT23!$Q$40 -> 0 | L15: =[15]MVTAOUT23!$U$40 -> 2150000 | M15: =[15]MVTAOUT23!$I$40 -> 0 | N15: =[15]MVTAOUT23!$AD$40 -> 140000 | P15: =SUM(B15:O15) -> 2928000
A16: SEPTEMBRE | D16: =[15]MVTSEPT23!$G$40 -> 0 | E16: =[15]MVTSEPT23!$K$40 -> 774000 | F16: =[15]MVTSEPT23!$L$40 -> 29000 | G16: =[15]MVTSEPT23!$M$40 -> 29000 | H16: =[15]MVTSEPT23!$N$40 -> 116000 | I16: =[15]MVTSEPT23!$O$40 -> 3000 | J16: =[15]MVTSEPT23!$P$40 -> 0 | K16: =[15]MVTSEPT23!$Q$40 -> 0 | L16: =[15]MVTSEPT23!$U$40 -> 1102500 | M16: =[15]MVTSEPT23!$I$40 -> 0 | N16: =[15]MVTSEPT23!$AD$40 -> 210000 | P16: =SUM(B16:O16) -> 2263500
A17: OCTOBRE | D17: =[15]MVTOCT23!$G$40 -> 20000 | E17: =[15]MVTOCT23!$K$40 -> 596500 | F17: =[15]MVTOCT23!$L$40 -> 29000 | G17: =[15]MVTOCT23!$M$40 -> 29000 | H17: =[15]MVTOCT23!$N$40 -> 116000 | I17: =[15]MVTOCT23!$O$40 -> 0 | J17: =[15]MVTOCT23!$P$40 -> 0 | K17: =[15]MVTOCT23!$Q$40 -> 0 | L17: =[15]MVTOCT23!$U$40 -> 740000 | M17: =[15]MVTOCT23!$I$40 -> 0 | N17: =[15]MVTOCT23!$AD$40 -> 140000 | P17: =SUM(B17:O17) -> 1670500
A18: NOVEMBRE | D18: =[15]MVTNOV23!$G$40 -> 0 | E18: =[15]MVTNOV23!$K$40 -> 372500 | F18: =[15]MVTNOV23!$L$40 -> 32000 | G18: =[15]MVTNOV23!$M$40 -> 32000 | H18: =[15]MVTNOV23!$N$40 -> 128000 | I18: =[15]MVTNOV23!$O$40 -> 18000 | J18: =[15]MVTNOV23!$P$40 -> 0 | K18: =[15]MVTNOV23!$Q$40 -> 0 | L18: =[15]MVTNOV23!$U$40 -> 439500 | M18: =[15]MVTNOV23!$I$40 -> 0 | N18: =[15]MVTNOV23!$AD$40 -> 210000 | P18: =SUM(B18:O18) -> 1232000
A19: DÉCEMBRE | D19: =[15]MVTDEC23!$G$40 -> 0 | E19: =[15]MVTDEC23!$K$40 -> 482800 | F19: =[15]MVTDEC23!$L$40 -> 31000 | G19: =[15]MVTDEC23!$M$40 -> 31000 | H19: =[15]MVTDEC23!$N$40 -> 124000 | I19: =[15]MVTDEC23!$O$40 -> 0 | J19: =[15]MVTDEC23!$P$40 -> 0 | K19: =[15]MVTDEC23!$Q$40 -> 0 | L19: =[15]MVTDEC23!$U$40 -> 13317700 | M19: =[15]MVTDEC23!$I$40 -> 207000 | N19: =[15]MVTDEC23!$AD$40 -> 140000 | O19: =[13]TONTRESUME23!$S$6+[14]TONTRESUME23!$S$6 -> 63707.983 | P19: =SUM(B19:O19) -> 14397208
A21: TOTAL | B21: =SUM(B8:B20) -> 0 | C21: =SUM(C8:C20) -> 0 | D21: =SUM(D8:D20) -> 1746200 | E21: =SUM(E8:E20) -> 6599068 | F21: =SUM(F8:F20) -> 363000 | G21: =SUM(G8:G20) -> 360000 | H21: =SUM(H8:H20) -> 1440000 | I21: =SUM(I8:I20) -> 79000 | ... P21: =SUM(P8:P20) -> 39472676

Sheet SORTIE
C2: SORTIE DES DIFFERENTES RUBRIQUES
A3: ANNEE | B3: 2022-2023
A6: MOIS | B6: FONDS DE CAISSE | C6: EPARGNE | D6: FONDS DE ROULEMENT | E6: FRAIS EXCEPTIONNEL | F6: COLLATION | G6: PENALITE VST ESPECES | H6: INSCRIPTION | I6: MUTUELLE | J6: PRÊT | K6: PENALITE | L6: FOYER | M6: TOTAL
A7: REPORT
A8: JANVIER | D8: =[15]MVTJANV23!$AE$40 -> 6000 | E8: =[15]MVTJANV23!$AF$40 -> 0 | F8: =[15]MVTJANV23!$AH$40 -> 100000 | G8: =[15]MVTJANV23!$AJ$40 -> 0 | I8: =[15]MVTJANV23!$AG$40 -> 0 | J8: =[15]MVTDEC22!$R$39 -> 15600000 | M8: =SUM(C8:K8) -> 15706000
A9: FÉVRIER | B9: 640700 | D9: =[15]MVTFEV23!$AE$40 -> 68500 | E9: =[15]MVTFEV23!$AF$40 -> 0 | F9: =[15]MVTFEV23!$AH$40 -> 0 | G9: =[15]MVTFEV23!$AJ$40 -> 200000 | I9: =[15]MVTFEV23!$AG$40 -> 560000 | J9: =[15]MVTFEV23!$R$40 -> 1000000 | M9: =SUM(C9:K9) -> 1828500
A10: MARS | D10: =[15]MVTMARS23!$AE$40 -> 6000 | E10: =[15]MVTMARS23!$AF$40 -> 0 | F10: =[15]MVTMARS23!$AH$40 -> 100000 | G10: =[15]MVTMARS23!$AJ$40 -> 0 | I10: =[15]MVTMARS23!$AG$40 -> 0 | J10: =[15]MVTMARS23!$R$40 -> 200000 | L10: 1750000 | M10: =SUM(C10:K10) -> 306000
A11: AVRIL | D11: =[15]MVTAVRIL23!$AE$40 -> 6000 | E11: =[15]MVTAVRIL23!$AF$40 -> 0 | F11: =[15]MVTAVRIL23!$AH$40 -> 100000 | G11: =[15]MVTAVRIL23!$AJ$40 -> 0 | I11: =[15]MVTAVRIL23!$AG$40 -> 0 | J11: =[15]MVTAVRIL23!$R$40 -> 3500000 | M11: =SUM(C11:K11) -> 3606000
A12: MAI | D12: =[15]MVTMAI23!$AE$40 -> 6000 | E12: =[15]MVTMAI23!$AF$40 -> 0 | F12: =[15]MVTMAI23!$AH$40 -> 100000 | G12: =[15]MVTMAI23!$AJ$40 -> 0 | I12: =[15]MVTMAI23!$AG$40 -> 200000 | J12: =[15]MVTMAI23!$R$40 -> 0 | M12: =SUM(C12:K12) -> 306000
A13: JUIN | D13: =[15]MVTJUIN23!$AE$40 -> 24000 | E13: =[15]MVTJUIN23!$AF$40 -> 20000 | F13: =[15]MVTJUIN23!$AH$40 -> 100000 | G13: =[15]MVTJUIN23!$AJ$40 -> 0 | I13: =[15]MVTJUIN23!$AG$40 -> 0 | J13: =[15]MVTJUIN23!$R$40 -> 1555000 | M13: =SUM(C13:K13) -> 1699000
A14: JUILLET | D14: =[15]MVTJUIL23!$AE$40 -> 6000 | E14: =[15]MVTJUIL23!$AF$40 -> 50000 | F14: =[15]MVTJUIL23!$AH$40 -> 100000 | G14: =[15]MVTJUIL23!$AJ$40 -> 0 | I14: =[15]MVTJUIL23!$AG$40 -> 0 | J14: =[15]MVTJUIL23!$R$40 -> 1000000 | M14: =SUM(C14:K14) -> 1156000
A15: AOÛT | D15: =[15]MVTAOUT23!$AE$40 -> 45000 | E15: =[15]MVTAOUT23!$AF$40 -> 155000 | F15: =[15]MVTAOUT23!$AH$40 -> 100000 | G15: =[15]MVTAOUT23!$AJ$40 -> 0 | I15: =[15]MVTAOUT23!$AG$40 -> 560000 | J15: =[15]MVTAOUT23!$R$40 -> 1600000 | M15: =SUM(C15:K15) -> 2460000
A16: SEPTEMBRE | D16: =[15]MVTSEPT23!$AE$40 -> 6000 | E16: =[15]MVTSEPT23!$AF$40 -> 0 | F16: =[15]MVTSEPT23!$AH$40 -> 100000 | G16: =[15]MVTSEPT23!$AJ$40 -> 0 | I16: =[15]MVTSEPT23!$AG$40 -> 0 | J16: =[15]MVTSEPT23!$R$40 -> 0 | M16: =SUM(C16:K16) -> 106000
A17: OCTOBRE | D17: =[15]MVTOCT23!$AE$40 -> 13500 | E17: =[15]MVTOCT23!$AF$40 -> 600000 | F17: =[15]MVTOCT23!$AH$40 -> 100000 | G17: =[15]MVTOCT23!$AJ$40 -> 0 | I17: =[15]MVTOCT23!$AG$40 -> 0 | J17: =[15]MVTOCT23!$R$40 -> 1500000 | M17: =SUM(C17:K17) -> 2213500
A18: NOVEMBRE | D18: =[15]MVTNOV23!$AE$40 -> 6000 | E18: =[15]MVTNOV23!$AF$40 -> 0 | F18: =[15]MVTNOV23!$AH$40 -> 110000 | G18: =[15]MVTNOV23!$AJ$40 -> 0 | I18: =[15]MVTNOV23!$AG$40 -> 0 | J18: =[15]MVTNOV23!$R$40 -> 0 | M18: =SUM(C18:K18) -> 116000
A19: DÉCEMBRE | D19: =[15]MVTDEC23!$AE$40 -> 6000 | E19: =[15]MVTDEC23!$AF$40 -> 0 | F19: =[15]MVTDEC23!$AH$40 -> 0 | G19: =[15]MVTDEC23!$AJ$40 -> 0 | I19: =[15]MVTDEC23!$AG$40 -> 0 | J19: =[15]MVTDEC23!$R$40 -> 14310000 | M19: =SUM(C19:K19) -> 14316000
A22: TOTAL | B22: =SUM(B8:B21) -> 640700 | C22: =SUM(C8:C21) -> 0 | D22: =SUM(D8:D21) -> 199000 | E22: =SUM(E8:E21) -> 825000 | F22: =SUM(F8:F21) -> 1010000 | G22: =SUM(G8:G21) -> 200000 | H22: =SUM(H8:H21) -> 0 | I22: =SUM(I8:I21) -> 1320000 | ... M22: =SUM(M8:M21) -> 43819000

Sheet DETAILFICHECASSATION
A1: ASSOCIATION | B1: ASELBY
A2: ANNEE | B2: 2022/2023
A5: MATRICULE | B5: NOM ET PRENOM | C5: FONDS DE CAISSE | D5: RECONDUCTION | E5: REPARTITION INTERET | F5: EPARGNE | G5: REPARTITION PENALITE REMBOURSEMENT PRÊT | H5: REPARTITION COLLATION | I5: TOTAL | J5: SANCTION | K5: COMPLEMENT MUTUELLE | L5: COMPLEMENT FONDS | M5: NUIT DES ELITES | N5: TOTAL RETENU | O5: TOTAL A PERCEVOIR | P5: MONTANT PERCU | Q5: RECONDUCTION 2024 | R5: NOUVEAU FONDS
A6: AS201648 | B6: =VLOOKUP(A6,[16]LISTADHERENT!A$5:H$39,3,0) -> ASELBY | C6: =VLOOKUP($A6,[15]MVTRESUME23!$A$6:$AN$36,3,0) -> 0 | D6: =VLOOKUP(A6,[15]MVTRESUME23!$A$6:$AN$36,4,0) -> 816543.52 | E6: =VLOOKUP(A6,[15]MVTRESUME23!$A$6:$AN$36,7,0) -> 69979.738 | F6: =VLOOKUP($A6,[15]MVTRESUME23!$A$6:$AN$36,11,0) -> 0 | I6: =D6+E6+F6+G6+H6 -> 886523.26 | J6: =VLOOKUP($A6,[15]MVTRESUME23!$A$6:$AN$36,9,0) -> 0 | N6: =J6+K6+L6+M6 -> 0 | O6: =I6-N6 -> 886523.26 | Q6: =O6-P6 -> 886523.26
A7: AS201601 | B7: =VLOOKUP(A7,[16]LISTADHERENT!A$5:H$39,3,0) -> BAKOP ACHILLE | C7: =VLOOKUP(A7,[15]MVTRESUME23!$A$6:$AN$36,3,0) -> 0 | D7: =VLOOKUP(A7,[15]MVTRESUME23!$A$6:$AN$36,4,0) -> 0 | E7: =VLOOKUP(A7,[15]MVTRESUME23!$A$6:$AN$36,7,0) -> 13482.496 | F7: =VLOOKUP($A7,[15]MVTRESUME23!$A$6:$AN$36,11,0) -> 705000 | I7: =D7+E7+F7+G7+H7 -> 718482.5 | J7: =VLOOKUP($A7,[15]MVTRESUME23!$A$6:$AN$36,9,0) -> 0 | K7: 40000 | L7: 700000 | N7: =J7+K7+L7+M7 -> 740000 | O7: =I7-N7 -> -21517.504 | Q7: 678482 | R7: =C7+L7+O7 -> 678482.5
A8: AS201602 | B8: =VLOOKUP(A8,[16]LISTADHERENT!A$5:H$39,3,0) -> BOUTCHOUANG WILLIAM | C8: =VLOOKUP(A8,[15]MVTRESUME23!$A$6:$AN$36,3,0) -> 600000 | D8: =VLOOKUP(A8,[15]MVTRESUME23!$A$6:$AN$36,4,0) -> 7024 | E8: =VLOOKUP(A8,[15]MVTRESUME23!$A$6:$AN$36,7,0) -> 53009.126 | F8: =VLOOKUP($A8,[15]MVTRESUME23!$A$6:$AN$36,11,0) -> 108000 | I8: =D8+E8+F8+G8+H8 -> 168033.13 | J8: =VLOOKUP($A8,[15]MVTRESUME23!$A$6:$AN$36,9,0) -> 19000 | K8: 40000 | L8: 100000 | N8: =J8+K8+L8+M8 -> 159000 | O8: =I8-N8 -> 9033.1263 | P8: 9000 | Q8: =O8-P8 -> 33.126263 | R8: =C8+L8 -> 700000
A9: AS201604 | B9: =VLOOKUP(A9,[16]LISTADHERENT!A$5:H$39,3,0) -> DJOMO JEAN PAUL | C9: =VLOOKUP(A9,[15]MVTRESUME23!$A$6:$AN$36,3,0) -> 600000 | D9: =VLOOKUP(A9,[15]MVTRESUME23!$A$6:$AN$36,4,0) -> 4810 | E9: =VLOOKUP(A9,[15]MVTRESUME23!$A$6:$AN$36,7,0) -> 53547.826 | F9: =VLOOKUP($A9,[15]MVTRESUME23!$A$6:$AN$36,11,0) -> 169000 | I9: =D9+E9+F9+G9+H9 -> 227357.83 | J9: =VLOOKUP($A9,[15]MVTRESUME23!$A$6:$AN$36,9,0) -> 9000 | K9: 40000 | L9: 100000 | M9: 25000 | N9: =J9+K9+L9+M9 -> 174000 | O9: =I9-N9 -> 53357.826 | Q9: =O9-P9 -> 53357.826 | R9: =C9+L9 -> 700000
A10: AS201654 | B10: =VLOOKUP(A10,[16]LISTADHERENT!A$5:H$39,3,0) -> DJOMOU TCHAPDA | C10: =VLOOKUP(A10,[15]MVTRESUME23!$A$6:$AN$36,3,0) -> 600000 | D10: =VLOOKUP(A10,[15]MVTRESUME23!$A$6:$AN$36,4,0) -> 48710 | E10: =VLOOKUP(A10,[15]MVTRESUME23!$A$6:$AN$36,7,0) -> 56584.679 | F10: =VLOOKUP($A10,[15]MVTRESUME23!$A$6:$AN$36,11,0) -> 106000 | I10: =D10+E10+F10+G10+H10 -> 211294.68 | J10: =VLOOKUP($A10,[15]MVTRESUME23!$A$6:$AN$36,9,0) -> 22000 | K10: 40000 | L10: 100000 | N10: =J10+K10+L10+M10 -> 162000 | O10: =I10-N10 -> 49294.679 | P10: 49000 | Q10: =O10-P10 -> 294.6793 | R10: =C10+L10 -> 700000
A11: AS201605 | B11: =VLOOKUP(A11,[16]LISTADHERENT!A$5:H$39,3,0) -> DJOUKWE NANGUEN GUY BLAISE | C11: =VLOOKUP(A11,[15]MVTRESUME23!$A$6:$AN$36,3,0) -> 600000 | D11: =VLOOKUP(A11,[15]MVTRESUME23!$A$6:$AN$36,4,0) -> 4750 | E11: =VLOOKUP(A11,[15]MVTRESUME23!$A$6:$AN$36,7,0) -> 52946.768 | F11: =VLOOKUP($A11,[15]MVTRESUME23!$A$6:$AN$36,11,0) -> 117500 | I11: =D11+E11+F11+G11+H11 -> 175196.77 | J11: =VLOOKUP($A11,[15]MVTRESUME23!$A$6:$AN$36,9,0) -> 0 | K11: 40000 | L11: 100000 | N11: =J11+K11+L11+M11 -> 140000 | O11: =I11-N11 -> 35196.768 | P11: 33000 | Q11: =O11-P11 -> 2196.7679 | R11: =C11+L11 -> 700000
A12: AS201608 | B12: =VLOOKUP(A12,[16]LISTADHERENT!A$5:H$39,3,0) -> DJUOMBESSY ANTOINE | C12: =VLOOKUP(A12,[15]MVTRESUME23!$A$6:$AN$36,3,0) -> 600000 | D12: =VLOOKUP(A12,[15]MVTRESUME23!$A$6:$AN$36,4,0) -> 10719 | E12: =VLOOKUP(A12,[15]MVTRESUME23!$A$6:$AN$36,7,0) -> 55194.277 | F12: =VLOOKUP($A12,[15]MVTRESUME23!$A$6:$AN$36,11,0) -> 309600 | I12: =D12+E12+F12+G12+H12 -> 375513.28 | J12: =VLOOKUP($A12,[15]MVTRESUME23!$A$6:$AN$36,9,0) -> 0 | K12: 40000 | L12: 100000 | M12: 20000 | N12: =J12+K12+L12+M12 -> 160000 | O12: =I12-N12 -> 215513.28 | P12: 201000 | Q12: =O12-P12 -> 14513.277 | R12: =C12+L12 -> 700000
A13: AS201651 | B13: =VLOOKUP(A13,[16]LISTADHERENT!A$5:H$39,3,0) -> DOMOU FABIEN | C13: =VLOOKUP(A13,[15]MVTRESUME23!$A$6:$AN$36,3,0) -> 600000 | D13: =VLOOKUP(A13,[15]MVTRESUME23!$A$6:$AN$36,4,0) -> 584 | E13: =VLOOKUP(A13,[15]MVTRESUME23!$A$6:$AN$36,7,0) -> 52457.236 | F13: =VLOOKUP($A13,[15]MVTRESUME23!$A$6:$AN$36,11,0) -> 108000 | I13: =D13+E13+F13+G13+H13 -> 161041.24 | J13: =VLOOKUP($A13,[15]MVTRESUME23!$A$6:$AN$36,9,0) -> 0 | K13: 40000 | L13: 100000 | N13: =J13+K13+L13+M13 -> 140000 | O13: =I13-N13 -> 21041.236 | P13: 21000 | Q13: =O13-P13 -> 41.235806 | R13: =C13+L13 -> 700000
A14: AS201609 | B14: =VLOOKUP(A14,[16]LISTADHERENT!A$5:H$39,3,0) -> DONHOU DAVID | C14: =VLOOKUP(A14,[15]MVTRESUME23!$A$6:$AN$36,3,0) -> 600000 | D14: =VLOOKUP(A14,[15]MVTRESUME23!$A$6:$AN$36,4,0) -> 458343 | E14: =VLOOKUP(A14,[15]MVTRESUME23!$A$6:$AN$36,7,0) -> 91688.291 | F14: =VLOOKUP($A14,[15]MVTRESUME23!$A$6:$AN$36,11,0) -> 108000 | I14: =D14+E14+F14+G14+H14 -> 658031.29 | J14: =VLOOKUP($A14,[15]MVTRESUME23!$A$6:$AN$36,9,0) -> 0 | K14: 40000 | L14: 100000 | N14: =J14+K14+L14+M14 -> 140000 | O14: =I14-N14 -> 518031.29 | Q14: =O14-P14 -> 518031.29 | R14: =C14+L14 -> 700000
A15: AS201611 | B15: =VLOOKUP(A15,[16]LISTADHERENT!A$5:H$39,3,0) -> HENGUE PAUL OMER | C15: =VLOOKUP(A15,[15]MVTRESUME23!$A$6:$AN$36,3,0) -> 600000 | D15: =VLOOKUP(A15,[15]MVTRESUME23!$A$6:$AN$36,4,0) -> 51112 | E15: =VLOOKUP(A15,[15]MVTRESUME23!$A$6:$AN$36,7,0) -> 56787.604 | F15: =VLOOKUP($A15,[15]MVTRESUME23!$A$6:$AN$36,11,0) -> 108000 | I15: =D15+E15+F15+G15+H15 -> 215899.6 | J15: =VLOOKUP($A15,[15]MVTRESUME23!$A$6:$AN$36,9,0) -> 18000 | K15: 40000 | L15: 100000 | N15: =J15+K15+L15+M15 -> 158000 | O15: =I15-N15 -> 57899.604 | Q15: =O15-P15 -> 57899.604 | R15: =C15+L15 -> 700000
A16: AS201613 | B16: =VLOOKUP(A16,[16]LISTADHERENT!A$5:H$39,3,0) -> HOTCHO BENJAMIN | C16: =VLOOKUP(A16,[15]MVTRESUME23!$A$6:$AN$36,3,0) -> 600000 | D16: =VLOOKUP(A16,[15]MVTRESUME23!$A$6:$AN$36,4,0) -> 16230 | E16: =VLOOKUP(A16,[15]MVTRESUME23!$A$6:$AN$36,7,0) -> 57431.208 | F16: =VLOOKUP($A16,[15]MVTRESUME23!$A$6:$AN$36,11,0) -> 508000 | I16: =D16+E16+F16+G16+H16 -> 581661.21 | J16: =VLOOKUP($A16,[15]MVTRESUME23!$A$6:$AN$36,9,0) -> 12000 | K16: 40000 | L16: 100000 | N16: =J16+K16+L16+M16 -> 152000 | O16: =I16-N16 -> 429661.21 | P16: 400000 | Q16: =O16-P16 -> 29661.208 | R16: =C16+L16 -> 700000
A17: AS201617 | B17: =VLOOKUP(A17,[16]LISTADHERENT!A$5:H$39,3,0) -> KOUAMOU MOISE | C17: =VLOOKUP(A17,[15]MVTRESUME23!$A$6:$AN$36,3,0) -> 600000 | D17: =VLOOKUP(A17,[15]MVTRESUME23!$A$6:$AN$36,4,0) -> 53293 | E17: =VLOOKUP(A17,[15]MVTRESUME23!$A$6:$AN$36,7,0) -> 56974.505 | F17: =VLOOKUP($A17,[15]MVTRESUME23!$A$6:$AN$36,11,0) -> 108000 | I17: =D17+E17+F17+G17+H17 -> 218267.51 | J17: =VLOOKUP($A17,[15]MVTRESUME23!$A$6:$AN$36,9,0) -> 9000 | K17: 40000 | L17: 100000 | N17: =J17+K17+L17+M17 -> 149000 | O17: =I17-N17 -> 69267.505 | P17: 60000 | Q17: =O17-P17 -> 9267.5052 | R17: =C17+L17 -> 700000
A18: AS201619 | B18: =VLOOKUP(A18,[16]LISTADHERENT!A$5:H$39,3,0) -> KOUATCHO MESSACK | C18: =VLOOKUP(A18,[15]MVTRESUME23!$A$6:$AN$36,3,0) -> 600000 | D18: =VLOOKUP(A18,[15]MVTRESUME23!$A$6:$AN$36,4,0) -> 6459 | E18: =VLOOKUP(A18,[15]MVTRESUME23!$A$6:$AN$36,7,0) -> 52969.628 | F18: =VLOOKUP($A18,[15]MVTRESUME23!$A$6:$AN$36,11,0) -> 108000 | I18: =D18+E18+F18+G18+H18 -> 167428.63 | J18: =VLOOKUP($A18,[15]MVTRESUME23!$A$6:$AN$36,9,0) -> 3000 | K18: 40000 | L18: 100000 | N18: =J18+K18+L18+M18 -> 143000 | O18: =I18-N18 -> 24428.628 | Q18: =O18-P18 -> 24428.628 | R18: =C18+L18 -> 700000
A19: AS201620 | B19: =VLOOKUP(A19,[16]LISTADHERENT!A$5:H$39,3,0) -> LOWE JEAN | C19: =VLOOKUP(A19,[15]MVTRESUME23!$A$6:$AN$36,3,0) -> 600000 | D19: =VLOOKUP(A19,[15]MVTRESUME23!$A$6:$AN$36,4,0) -> 746 | E19: =VLOOKUP(A19,[15]MVTRESUME23!$A$6:$AN$36,7,0) -> 52471.131 | F19: =VLOOKUP($A19,[15]MVTRESUME23!$A$6:$AN$36,11,0) -> 108000 | I19: =D19+E19+F19+G19+H19 -> 161217.13 | J19: =VLOOKUP($A19,[15]MVTRESUME23!$A$6:$AN$36,9,0) -> 20000 | K19: 40000 | L19: 100000 | M19: 25000 | N19: =J19+K19+L19+M19 -> 185000 | O19: =I19-N19 -> -23782.869 | Q19: =O19-P19 -> -23782.869 | R19: =C19+L19+O19 -> 676217.13
A20: AS201649 | B20: =VLOOKUP(A20,[16]LISTADHERENT!A$5:H$39,3,0) -> MBOGNING TUGMA GUY | C20: =VLOOKUP(A20,[15]MVTRESUME23!$A$6:$AN$36,3,0) -> 600000 | D20: =VLOOKUP(A20,[15]MVTRESUME23!$A$6:$AN$36,4,0) -> 47746 | E20: =VLOOKUP(A20,[15]MVTRESUME23!$A$6:$AN$36,7,0) -> 56463.397 | F20: =VLOOKUP($A20,[15]MVTRESUME23!$A$6:$AN$36,11,0) -> 108500 | I20: =D20+E20+F20+G20+H20 -> 212709.4 | J20: =VLOOKUP($A20,[15]MVTRESUME23!$A$6:$AN$36,9,0) -> 0 | K20: 40000 | L20: 100000 | N20: =J20+K20+L20+M20 -> 140000 | O20: =I20-N20 -> 72709.397 | P20: 41000 | Q20: =O20-P20 -> 31709.397 | R20: =C20+L20 -> 700000
A21: AS201639 | B21: =VLOOKUP(A21,[16]LISTADHERENT!A$5:H$39,3,0) -> NANGUEN MARTIN | C21: =VLOOKUP(A21,[15]MVTRESUME23!$A$6:$AN$36,3,0) -> 600000 | D21: =VLOOKUP(A21,[15]MVTRESUME23!$A$6:$AN$36,4,0) -> 51343 | E21: =VLOOKUP(A21,[15]MVTRESUME23!$A$6:$AN$36,7,0) -> 56807.362 | F21: =VLOOKUP($A21,[15]MVTRESUME23!$A$6:$AN$36,11,0) -> 108000 | I21: =D21+E21+F21+G21+H21 -> 216150.36 | J21: =VLOOKUP($A21,[15]MVTRESUME23!$A$6:$AN$36,9,0) -> 0 | K21: 40000 | L21: 100000 | M21: 25000 | N21: =J21+K21+L21+M21 -> 165000 | O21: =I21-N21 -> 51150.362 | P21: 50000 | Q21: =O21-P21 -> 1150.3621 | R21: =C21+L21 -> 700000
A22: AS201621 | B22: =VLOOKUP(A22,[16]LISTADHERENT!A$5:H$39,3,0) -> NANKAM APPOLINAIRE | C22: =VLOOKUP(A22,[15]MVTRESUME23!$A$6:$AN$36,3,0) -> 600000 | D22: =VLOOKUP(A22,[15]MVTRESUME23!$A$6:$AN$36,4,0) -> 140918 | E22: =VLOOKUP(A22,[15]MVTRESUME23!$A$6:$AN$36,7,0) -> 64484.234 | F22: =VLOOKUP($A22,[15]MVTRESUME23!$A$6:$AN$36,11,0) -> 108000 | I22: =D22+E22+F22+G22+H22 -> 313402.23 | J22: =VLOOKUP($A22,[15]MVTRESUME23!$A$6:$AN$36,9,0) -> 20000 | K22: 40000 | L22: 100000 | N22: =J22+K22+L22+M22 -> 160000 | O22: =I22-N22 -> 153402.23 | P22: 53000 | Q22: =O22-P22 -> 100402.23 | R22: =C22+L22 -> 700000
A23: AS201622 | B23: =VLOOKUP(A23,[16]LISTADHERENT!A$5:H$39,3,0) -> NDJOMO ETIENNE | C23: =VLOOKUP(A23,[15]MVTRESUME23!$A$6:$AN$36,3,0) -> 600000 | D23: =VLOOKUP(A23,[15]MVTRESUME23!$A$6:$AN$36,4,0) -> 283210 | E23: =VLOOKUP(A23,[15]MVTRESUME23!$A$6:$AN$36,7,0) -> 77760.618 | F23: =VLOOKUP($A23,[15]MVTRESUME23!$A$6:$AN$36,11,0) -> 224000 | I23: =D23+E23+F23+G23+H23 -> 584970.62 | J23: =VLOOKUP($A23,[15]MVTRESUME23!$A$6:$AN$36,9,0) -> 0 | K23: 40000 | L23: 100000 | N23: =J23+K23+L23+M23 -> 140000 | O23: =I23-N23 -> 444970.62 | P23: 220000 | Q23: =O23-P23 -> 224970.62 | R23: =C23+L23 -> 700000
A24: AS201624 | B24: =VLOOKUP(A24,[16]LISTADHERENT!A$5:H$39,3,0) -> NGONDIEP CLAUDE | C24: =VLOOKUP(A24,[15]MVTRESUME23!$A$6:$AN$36,3,0) -> 600000 | D24: =VLOOKUP(A24,[15]MVTRESUME23!$A$6:$AN$36,4,0) -> 39787 | E24: =VLOOKUP(A24,[15]MVTRESUME23!$A$6:$AN$36,7,0) -> 55845.732 | F24: =VLOOKUP($A24,[15]MVTRESUME23!$A$6:$AN$36,11,0) -> 117000 | I24: =D24+E24+F24+G24+H24 -> 212632.73 | J24: =VLOOKUP($A24,[15]MVTRESUME23!$A$6:$AN$36,9,0) -> 15000 | K24: 40000 | L24: 100000 | N24: =J24+K24+L24+M24 -> 155000 | O24: =I24-N24 -> 57632.732 | Q24: =O24-P24 -> 57632.732 | R24: =C24+L24 -> 700000
A25: AS201626 | B25: =VLOOKUP(A25,[16]LISTADHERENT!A$5:H$39,3,0) -> NGUIEMEGNI MATHIEU BLAISE | C25: =VLOOKUP(A25,[15]MVTRESUME23!$A$6:$AN$36,3,0) -> 600000 | D25: =VLOOKUP(A25,[15]MVTRESUME23!$A$6:$AN$36,4,0) -> 13696 | E25: =VLOOKUP(A25,[15]MVTRESUME23!$A$6:$AN$36,7,0) -> 53686.784 | F25: =VLOOKUP($A25,[15]MVTRESUME23!$A$6:$AN$36,11,0) -> 408000 | I25: =D25+E25+F25+G25+H25 -> 475382.78 | J25: =VLOOKUP($A25,[15]MVTRESUME23!$A$6:$AN$36,9,0) -> 15000 | K25: 40000 | L25: 100000 | N25: =J25+K25+L25+M25 -> 155000 | O25: =I25-N25 -> 320382.78 | P25: 300000 | Q25: =O25-P25 -> 20382.784 | R25: =C25+L25 -> 700000
A26: AS201628 | B26: =VLOOKUP(A26,[16]LISTADHERENT!A$5:H$39,3,0) -> NKAMGANG JUSTIN DEJOLIE | C26: =VLOOKUP(A26,[15]MVTRESUME23!$A$6:$AN$36,3,0) -> 600000 | D26: =VLOOKUP(A26,[15]MVTRESUME23!$A$6:$AN$36,4,0) -> 575 | E26: =VLOOKUP(A26,[15]MVTRESUME23!$A$6:$AN$36,7,0) -> 52456.485 | F26: =VLOOKUP($A26,[15]MVTRESUME23!$A$6:$AN$36,11,0) -> 106000 | I26: =D26+E26+F26+G26+H26 -> 159031.48 | J26: =VLOOKUP($A26,[15]MVTRESUME23!$A$6:$AN$36,9,0) -> 0 | K26: 40000 | L26: 100000 | N26: =J26+K26+L26+M26 -> 140000 | O26: =I26-N26 -> 19031.485 | Q26: =O26-P26 -> 19031.485 | R26: =C26+L26 -> 700000
A27: AS201656 | B27: =VLOOKUP(A27,[16]LISTADHERENT!A$5:H$39,3,0) -> NOUBE ETIENNE | C27: =VLOOKUP(A27,[15]MVTRESUME23!$A$6:$AN$36,3,0) -> 0 | D27: =VLOOKUP(A27,[15]MVTRESUME23!$A$6:$AN$36,4,0) -> 0 | E27: =VLOOKUP(A27,[15]MVTRESUME23!$A$6:$AN$36,7,0) -> 518.81693 | F27: =VLOOKUP($A27,[15]MVTRESUME23!$A$6:$AN$36,11,0) -> 720500 | I27: =D27+E27+F27+G27+H27 -> 721018.82 | J27: =VLOOKUP($A27,[15]MVTRESUME23!$A$6:$AN$36,9,0) -> 0 | K27: 40000 | L27: 700000 | M27: 15000 | N27: =J27+K27+L27+M27 -> 755000 | O27: =I27-N27 -> -33981.183 | Q27: =O27-P27 -> -33981.183 | R27: =C27+L27+O27 -> 666018.82
A28: AS201633 | B28: =VLOOKUP(A28,[16]LISTADHERENT!A$5:H$39,3,0) -> PATEGO NJOSSU GUSTAVE | C28: =VLOOKUP(A28,[15]MVTRESUME23!$A$6:$AN$36,3,0) -> 600000 | D28: =VLOOKUP(A28,[15]MVTRESUME23!$A$6:$AN$36,4,0) -> 21452 | E28: =VLOOKUP(A28,[15]MVTRESUME23!$A$6:$AN$36,7,0) -> 54245.666 | F28: =VLOOKUP($A28,[15]MVTRESUME23!$A$6:$AN$36,11,0) -> 108000 | I28: =D28+E28+F28+G28+H28 -> 183697.67 | J28: =VLOOKUP($A28,[15]MVTRESUME23!$A$6:$AN$36,9,0) -> 0 | K28: 40000 | L28: 100000 | N28: =J28+K28+L28+M28 -> 140000 | O28: =I28-N28 -> 43697.666 | Q28: =O28-P28 -> 43697.666 | R28: =C28+L28 -> 700000
A29: AS201657 | B29: =VLOOKUP(A29,[16]LISTADHERENT!A$5:H$39,3,0) -> SEUMO POLYCARPE | C29: =VLOOKUP(A29,[15]MVTRESUME23!$A$6:$AN$36,3,0) -> 0 | D29: =VLOOKUP(A29,[15]MVTRESUME23!$A$6:$AN$36,4,0) -> 0 | E29: =VLOOKUP(A29,[15]MVTRESUME23!$A$6:$AN$36,7,0) -> 0 | F29: =VLOOKUP($A29,[15]MVTRESUME23!$A$6:$AN$36,11,0) -> 285500 | I29: =D29+E29+F29+G29+H29 -> 285500 | J29: =VLOOKUP($A29,[15]MVTRESUME23!$A$6:$AN$36,9,0) -> 0 | K29: 40000 | N29: =J29+K29+L29+M29 -> 40000 | O29: =I29-N29 -> 245500 | Q29: =O29-P29 -> 245500 | R29: =C29+L29 -> 0
A30: AS201653 | B30: =VLOOKUP(A30,[16]LISTADHERENT!A$5:H$39,3,0) -> SIME BRICE | C30: =VLOOKUP(A30,[15]MVTRESUME23!$A$6:$AN$36,3,0) -> 600000 | D30: =VLOOKUP(A30,[15]MVTRESUME23!$A$6:$AN$36,4,0) -> 200752 | E30: =VLOOKUP(A30,[15]MVTRESUME23!$A$6:$AN$36,7,0) -> 69612.151 | F30: =VLOOKUP($A30,[15]MVTRESUME23!$A$6:$AN$36,11,0) -> 108000 | I30: =D30+E30+F30+G30+H30 -> 378364.15 | J30: =VLOOKUP($A30,[15]MVTRESUME23!$A$6:$AN$36,9,0) -> 34000 | K30: 40000 | L30: 100000 | N30: =J30+K30+L30+M30 -> 174000 | O30: =I30-N30 -> 204364.15 | P30: 100000 | Q30: =O30-P30 -> 104364.15 | R30: =C30+L30 -> 700000
A31: AS201638 | B31: =VLOOKUP(A31,[16]LISTADHERENT!A$5:H$39,3,0) -> SIMO PIERRE | C31: =VLOOKUP(A31,[15]MVTRESUME23!$A$6:$AN$36,3,0) -> 600000 | D31: =VLOOKUP(A31,[15]MVTRESUME23!$A$6:$AN$36,4,0) -> 103606 | E31: =VLOOKUP(A31,[15]MVTRESUME23!$A$6:$AN$36,7,0) -> 63580.612 | F31: =VLOOKUP($A31,[15]MVTRESUME23!$A$6:$AN$36,11,0) -> 218500 | I31: =D31+E31+F31+G31+H31 -> 385686.61 | J31: =VLOOKUP($A31,[15]MVTRESUME23!$A$6:$AN$36,9,0) -> 0 | K31: 40000 | L31: 100000 | M31: 15000 | N31: =J31+K31+L31+M31 -> 155000 | O31: =I31-N31 -> 230686.61 | P31: 230000 | Q31: =O31-P31 -> 686.61218 | R31: =C31+L31 -> 700000
A32: AS201641 | B32: =VLOOKUP(A32,[16]LISTADHERENT!A$5:H$39,3,0) -> TCHOUAMOU MATHIEU | C32: =VLOOKUP(A32,[15]MVTRESUME23!$A$6:$AN$36,3,0) -> 600000 | D32: =VLOOKUP(A32,[15]MVTRESUME23!$A$6:$AN$36,4,0) -> 4208 | E32: =VLOOKUP(A32,[15]MVTRESUME23!$A$6:$AN$36,7,0) -> 52767.806 | F32: =VLOOKUP($A32,[15]MVTRESUME23!$A$6:$AN$36,11,0) -> 108000 | I32: =D32+E32+F32+G32+H32 -> 164975.81 | J32: =VLOOKUP($A32,[15]MVTRESUME23!$A$6:$AN$36,9,0) -> 0 | K32: 40000 | L32: 100000 | N32: =J32+K32+L32+M32 -> 140000 | O32: =I32-N32 -> 24975.806 | P32: 24000 | Q32: =O32-P32 -> 975.80621 | R32: =C32+L32 -> 700000
A33: AS201643 | B33: =VLOOKUP(A33,[16]LISTADHERENT!A$5:H$39,3,0) -> TCHOUTOU NANA CLAUDE | C33: =VLOOKUP(A33,[15]MVTRESUME23!$A$6:$AN$36,3,0) -> 0 | D33: =VLOOKUP(A33,[15]MVTRESUME23!$A$6:$AN$36,4,0) -> 0 | E33: =VLOOKUP(A33,[15]MVTRESUME23!$A$6:$AN$36,7,0) -> 0 | F33: =VLOOKUP($A33,[15]MVTRESUME23!$A$6:$AN$36,11,0) -> 103000 | I33: =D33+E33+F33+G33+H33 -> 103000 | J33: =VLOOKUP($A33,[15]MVTRESUME23!$A$6:$AN$36,9,0) -> 0 | N33: =J33+K33+L33+M33 -> 0 | O33: =I33-N33 -> 103000 | Q33: =O33-P33+76000 -> 179000 | R33: =C33+L33 -> 0
A34: AS201658 | B34: =VLOOKUP(A34,[16]LISTADHERENT!A$5:H$39,3,0) -> YANTCHOU GERVAIS | C34: =VLOOKUP(A34,[15]MVTRESUME23!$A$6:$AN$36,3,0) -> 0 | D34: =VLOOKUP(A34,[15]MVTRESUME23!$A$6:$AN$36,4,0) -> 0 | E34: =VLOOKUP(A34,[15]MVTRESUME23!$A$6:$AN$36,7,0) -> 524.13813 | F34: =VLOOKUP($A34,[15]MVTRESUME23!$A$6:$AN$36,11,0) -> 737500 | I34: =D34+E34+F34+G34+H34 -> 738024.14 | J34: =VLOOKUP($A34,[15]MVTRESUME23!$A$6:$AN$36,9,0) -> 0 | K34: 40000 | L34: 700000 | N34: =J34+K34+L34+M34 -> 740000 | O34: =I34-N34 -> -1975.8619 | Q34: =O34-P34 -> -1975.8619 | R34: =C34+L34+O34 -> 698024.14
A35: AS201646 | B35: =VLOOKUP(A35,[16]LISTADHERENT!A$5:H$39,3,0) -> YEPMOU JEAN JACQUES | C35: =VLOOKUP(A35,[15]MVTRESUME23!$A$6:$AN$36,3,0) -> 600000 | D35: =VLOOKUP(A35,[15]MVTRESUME23!$A$6:$AN$36,4,0) -> 914734 | E35: =VLOOKUP(A35,[15]MVTRESUME23!$A$6:$AN$36,7,0) -> 130592.85 | F35: =VLOOKUP($A35,[15]MVTRESUME23!$A$6:$AN$36,11,0) -> 98000 | I35: =D35+E35+F35+G35+H35 -> 1143326.8 | J35: =VLOOKUP($A35,[15]MVTRESUME23!$A$6:$AN$36,9,0) -> 0 | K35: 40000 | L35: 100000 | N35: =J35+K35+L35+M35 -> 140000 | O35: =I35-N35 -> 1003326.8 | Q35: =O35-P35 -> 1003326.8 | R35: =C35+L35 -> 700000
A36: AS201647 | B36: =VLOOKUP(A36,[16]LISTADHERENT!A$5:H$39,3,0) -> YOUMBI EMMANUEL | C36: =VLOOKUP(A36,[15]MVTRESUME23!$A$6:$AN$36,3,0) -> 600000 | D36: =VLOOKUP(A36,[15]MVTRESUME23!$A$6:$AN$36,4,0) -> 1057774 | E36: =VLOOKUP(A36,[15]MVTRESUME23!$A$6:$AN$36,7,0) -> 143060.97 | F36: =VLOOKUP($A36,[15]MVTRESUME23!$A$6:$AN$36,11,0) -> 108000 | I36: =D36+E36+F36+G36+H36 -> 1308835 | J36: =VLOOKUP($A36,[15]MVTRESUME23!$A$6:$AN$36,9,0) -> 11000 | K36: 40000 | L36: 100000 | N36: =J36+K36+L36+M36 -> 151000 | O36: =I36-N36 -> 1157835 | Q36: =O36-P36 -> 1157835 | R36: =C36+L36 -> 700000
A38: TOTAL | C38: =SUM(C6:C36) -> 15000000 | D38: =SUM(D6:D36) -> 4359124.5 | E38: =SUM(E6:E36) -> 1707932.1 | F38: =SUM(F6:F36) -> 6445600 | G38: =SUM(G6:G36) -> 0 | H38: =SUM(H6:H36) -> 0 | I38: =SUM(I6:I36) -> 12512657 | J38: =SUM(J6:J36) -> 207000 | ... R38: =SUM(R6:R36) -> 19518743
A41: AS201612 | B41: =VLOOKUP(A41,[17]LISTADHERENT!A$5:H$60,3,0) -> HODIEP JULES | C41: =VLOOKUP(A41,[18]FONDSCAISSE!$A$2:$H$51,8,0) -> 80000 | R41: =C41 -> 80000
A42: AS201625 | B42: =VLOOKUP(A42,[17]LISTADHERENT!A$5:H$60,3,0) -> NGONGANG JEAN THEODORE | C42: =VLOOKUP(A42,[18]FONDSCAISSE!$A$2:$H$51,8,0) -> 227663 | R42: =C42 -> 227663
A43: AS201623 | B43: =VLOOKUP(A43,[17]LISTADHERENT!A$5:H$60,3,0) -> NDOMBOU JEAN CLAUDE | C43: =VLOOKUP(A43,[18]FONDSCAISSE!$A$2:$H$51,8,0) -> 480000 | R43: =C43 -> 480000
A44: AS201652 | B44: =VLOOKUP(A44,[17]LISTADHERENT!A$5:H$60,3,0) -> NGANHOU JEAN | C44: =VLOOKUP(A44,[18]FONDSCAISSE!$A$2:$H$51,8,0) -> 130000 | R44: =C44 -> 130000
A50: TOTAL | C50: =SUM(C6:C49) -> 30917663 | D50: =SUM(D6:D49) -> 8718249 | E50: =SUM(E6:E49) -> 3415864.3 | F50: =SUM(F6:F49) -> 12891200 | G50: =SUM(G6:G49) -> 0 | H50: =SUM(H6:H49) -> 0 | I50: =SUM(I6:I49) -> 25025313 | J50: =SUM(J6:J49) -> 414000 | ... L50: =SUM(L6:L49) -> 9200000 | N50: =SUM(N6:N49) -> 12184000 | O50: =SUM(O6:O49) -> 12841313 | P50: =SUM(P6:P49) -> 3582000 | Q50: =SUM(Q6:Q49) -> 10811312 | R50: =SUM(R6:R49) -> 39955148

Sheet SITUATION GUY
A1: T75 | B1: T75 | C1: T100
A3: GUY | B3: 154000 | C3: 307000
A4: DJUOMBESSY | C4: 206000
A5: HOTCHO | C5: 206000

Sheet SYNTHESECOMPTE
A1: ASSOCIATION | B1: ASELBY
A2: ANNEE | B2: 2023
A4: SYNTHESE DES COMPTES
A6: NUMERO ORDRE | B6: RUBRIQUE | C6: REPORT A NOUVEAU | D6: ENTREES | E6: SORTIES | F6: SOLDE
A8: ='BILAN 2023'!A8 -> 1 | B8: ='BILAN 2023'!B8 -> FONDS DE CAISSE ET RECONDUCTION | C8: ='BILAN 2023'!C8 -> 21291466 | D8: ='BILAN 2023'!D8 -> 24118743 | E8: ='BILAN 2023'!E8 -> 640700 | F8: =C8+D8-E8 -> 44769509
A9: ='BILAN 2023'!A9 -> 2 | B9: ='BILAN 2023'!B9 -> FONDS DE ROULEMENT | C9: ='BILAN 2023'!C9 -> 1996228 | D9: ='BILAN 2023'!D9 -> 363000 | E9: ='BILAN 2023'!E9 -> 193000 | F9: =C9+D9-E9 -> 2166228
A10: ='BILAN 2023'!A10 -> 3 | B10: ='BILAN 2023'!B10 -> FRAIS EXCEPTIONNELS | C10: ='BILAN 2023'!C10 -> 1503460 | D10: ='BILAN 2023'!D10 -> 360000 | E10: ='BILAN 2023'!E10 -> 825000 | F10: =C10+D10-E10 -> 1038460
A11: ='BILAN 2023'!A11 -> 4 | B11: ='BILAN 2023'!B11 -> MUTUELLE\COMPLEMENT MUTUEL | C11: ='BILAN 2023'!C11 -> 614762 | D11: ='BILAN 2023'!D11 -> 1520000 | E11: ='BILAN 2023'!E11 -> 1320000 | F11: =C11+D11-E11 -> 814762
A12: ='BILAN 2023'!A12 -> 5 | B12: ='BILAN 2023'!B12 -> INSCRIPTION | C12: ='BILAN 2023'!C12 -> 680000 | D12: ='BILAN 2023'!D12 -> 75000 | E12: ='BILAN 2023'!E12 -> 0 | F12: =C12+D12-E12 -> 755000
A13: ='BILAN 2023'!A13 -> 6 | B13: ='BILAN 2023'!B13 -> PENALITES PAIEMENT ESPECES | C13: ='BILAN 2023'!C13 -> 768025 | D13: ='BILAN 2023'!D13 -> 79000 | E13: ='BILAN 2023'!E13 -> 200000 | F13: =C13+D13-E13 -> 647025
A14: ='BILAN 2023'!A14 -> 7 | B14: SANCTION | C14: ='BILAN 2023'!C14 -> 0 | D14: ='BILAN 2023'!D14 -> 207000 | E14: ='BILAN 2023'!E14 -> 0 | F14: =C14+D14-E14 -> 207000
A15: ='BILAN 2023'!A15 -> 8 | B15: ='BILAN 2023'!B15 -> COLLATION | C15: ='BILAN 2023'!C15 -> 1320525 | D15: ='BILAN 2023'!D15 -> 1440000 | E15: ='BILAN 2023'!E15 -> 1010000 | F15: =C15+D15-E15 -> 1750525
A16: ='BILAN 2023'!A16 -> 9 | B16: ='BILAN 2023'!B16 -> TONTINE DE PRESENCE | C16: ='BILAN 2023'!C16 -> 94000 | D16: ='BILAN 2023'!D16 -> 9000000 | E16: ='BILAN 2023'!E16 -> 8788000 | F16: =C16+D16-E16 -> 306000
A17: ='BILAN 2023'!A17 -> 10 | B17: ='BILAN 2023'!B17 -> RECOUVREMENT POUR LA'AGWEU | C17: ='BILAN 2023'!C17 -> 0 | D17: ='BILAN 2023'!D17 -> 0 | E17: ='BILAN 2023'!E17 -> 0 | F17: =C17+D17-E17 -> 0
A18: ='BILAN 2023'!A18 -> 11 | B18: ='BILAN 2023'!B18 -> FOYER | C18: ='BILAN 2023'!C18 -> 543000 | D18: ='BILAN 2023'!D18 -> 2240000 | E18: ='BILAN 2023'!E18 -> 1750000 | F18: =C18+D18-E18 -> 1033000
A19: ='BILAN 2023'!A19 -> 12 | B19: ='BILAN 2023'!B19 -> CHAISES | C19: ='BILAN 2023'!C19 -> 0 | D19: ='BILAN 2023'!D19 -> 0 | E19: ='BILAN 2023'!E19 -> 0 | F19: =C19+D19-E19 -> 0
A20: ='BILAN 2023'!A20 -> 13 | B20: ='BILAN 2023'!B20 -> DIVERS | C20: ='BILAN 2023'!C20 -> 0 | D20: ='BILAN 2023'!D20 -> 0 | E20: ='BILAN 2023'!E20 -> 0 | F20: =C20+D20-E20 -> 0
A21: ='BILAN 2023'!A21 -> 14 | B21: ='BILAN 2023'!B21 -> TENUES | C21: ='BILAN 2023'!C21 -> 0 | D21: ='BILAN 2023'!D21 -> 0 | E21: ='BILAN 2023'!E21 -> 0 | F21: =C21+D21-E21 -> 0
A22: ='BILAN 2023'!A22 -> 15 | B22: ='BILAN 2023'!B22 -> FONDS GELES | C22: ='BILAN 2023'!C22 -> 0 | D22: ='BILAN 2023'!D22 -> 0 | E22: ='BILAN 2023'!E22 -> 0 | F22: =C22+D22-E22 -> 0
A23: ='BILAN 2023'!A23 -> 16 | B23: ='BILAN 2023'!B23 -> INTERETS ET AUTRES | C23: ='BILAN 2023'!C23 -> 6606334 | D23: ='BILAN 2023'!D23 -> 0 | E23: ='BILAN 2023'!E23 -> 0 | F23: =C23+D23-E23 -> 6606334
A24: ='BILAN 2023'!A24 -> 17 | B24: ='BILAN 2023'!B24 -> INTERET TONTINE | C24: ='BILAN 2023'!C24 -> 28000 | D24: ='BILAN 2023'!D24 -> 63707.983 | E24: ='BILAN 2023'!E24 -> 0 | F24: =C24+D24-E24 -> 91707.983
B26: TOTAL | C26: 32658100 | D26: =SUM(D9:D24) -> 15347708 | E26: 4688408 | F26: =SUM(F8:F24) -> 60185551

Sheet DISPOFONDS
A1: ASSOCIATION | B1: ASELBY
A2: ANNEE | B2: 2023
A4: DISPOSITION DES FONDS
A6: NUMERO ORDRE | B6: RUBRIQUE | C6: 2022 | D6: 2023
C7: MONTANT | D7: MONTANT
A8: ='BILAN 2023'!A32 -> 1 | B8: ='BILAN 2023'!B32 -> COMPTE CCA AU 30/12/2022 | C8: ='BILAN 2023'!C32 -> 4337431 | D8: ='BILAN 2023'!D32 -> 0
A9: ='BILAN 2023'!A33 -> 2 | B9: ='BILAN 2023'!B33 -> COMPTE MC²(NON ACTUALISE) | C9: ='BILAN 2023'!C33 -> 630005 | D9: ='BILAN 2023'!D33 -> 0
A10: ='BILAN 2023'!A34 -> 3 | B10: ='BILAN 2023'!B34 -> COMPTE AFRILAND | C10: ='BILAN 2023'!C34 -> 1423702 | D10: ='BILAN 2023'!D34 -> 0
A11: ='BILAN 2023'!A35 -> 4 | B11: ='BILAN 2023'!B35 -> DETTE PREFINANCEMENT LA'AGWEU | C11: ='BILAN 2023'!C35 -> 744700 | D11: ='BILAN 2023'!D35 -> 0
A12: ='BILAN 2023'!A36 -> 5 | B12: ='BILAN 2023'!B36 -> DETTE MR KOUATCHO | C12: ='BILAN 2023'!C36 -> 0 | D12: ='BILAN 2023'!D36 -> 0
A13: ='BILAN 2023'!A37 -> 6 | B13: ='BILAN 2023'!B37 -> RESTE A RECUPERE AU CONSEIL | C13: ='BILAN 2023'!C37 -> 154000 | D13: ='BILAN 2023'!D37 -> 0
A14: ='BILAN 2023'!A38 -> 7 | B14: ='BILAN 2023'!B38 -> FONDS EN CIRCULATION | C14: ='BILAN 2023'!C38 -> 18658500 | D14: ='BILAN 2023'!D38 -> 14068300
A15: ='BILAN 2023'!A39 -> 8 | B15: ='BILAN 2023'!B39 -> DETTES TONTINES | C15: ='BILAN 2023'!C39 -> 656618 | D15: ='BILAN 2023'!D39 -> 0
B17: TOTAL | C17: =SUM(C8:C16) -> 26604956 | D17: =SUM(D8:D16) -> 14068300

Sheet DETAILFPNDSROULT
A1: ASSOCIATION | B1: ASELBY
A2: ANNEE | B2: 2023
A4: FONDS DE ROULEMENT
A6: MATRICULE | B6: NOM ET PRENOM | C6: ENTREE | D6: SORTIE
C7: MONTANT | D7: DATE | E7: LIBELLE | F7: MONTANT
A8: AS201648 | B8: =VLOOKUP(A8,[16]LISTADHERENT!A$5:H$60,3,0) -> ASELBY | C8: =VLOOKUP(A8,[15]MVTRESUME23!$A$6:$AO$36,12,0) -> 3000 | D8: 44927 | E8: TAXI BANQUE | F8: =[19]HISTOJANV23!$BP$16 -> 6000
A9: AS201601 | B9: =VLOOKUP(A9,[16]LISTADHERENT!A$5:H$60,3,0) -> BAKOP ACHILLE | C9: =VLOOKUP(A9,[15]MVTRESUME23!$A$6:$AO$36,12,0) -> 12000 | D9: 44959 | E9: COMMUNICATI ON MBOGNING | F9: =+[19]HISTOFEV23!$BP$8 -> 27500
A10: AS201602 | B10: =VLOOKUP(A10,[16]LISTADHERENT!A$5:H$60,3,0) -> BOUTCHOUANG WILLIAM | C10: =VLOOKUP(A10,[15]MVTRESUME23!$A$6:$AO$36,12,0) -> 12000 | D10: 44959 | E10: PRODUCTION RAPPORT MBOGNING | F10: =[19]HISTOFEV23!$BP$11 -> 35000
A11: AS201604 | B11: =VLOOKUP(A11,[16]LISTADHERENT!A$5:H$60,3,0) -> DJOMO JEAN PAUL | C11: =VLOOKUP(A11,[15]MVTRESUME23!$A$6:$AO$36,12,0) -> 12000 | D11: 44958 | E11: TAXI BANQUE | F11: =[19]HISTOFEV23!$BP$13 -> 6000
A12: AS201654 | B12: =VLOOKUP(A12,[16]LISTADHERENT!A$5:H$60,3,0) -> DJOMOU TCHAPDA | C12: =VLOOKUP(A12,[15]MVTRESUME23!$A$6:$AO$36,12,0) -> 12000 | D12: 44986 | E12: TAXI BANQUE | F12: =[19]HISTOMARS23!$BP$16 -> 6000
A13: AS201605 | B13: =VLOOKUP(A13,[16]LISTADHERENT!A$5:H$60,3,0) -> DJOUKWE NANGUEN GUY BLAISE | C13: =VLOOKUP(A13,[15]MVTRESUME23!$A$6:$AO$36,12,0) -> 12000 | D13: 45018 | E13: TAXI BANQUE | F13: =[19]HISTOAVRIL23!$BP$16 -> 6000
A14: AS201608 | B14: =VLOOKUP(A14,[16]LISTADHERENT!A$5:H$60,3,0) -> DJUOMBESSY ANTOINE | C14: =VLOOKUP(A14,[15]MVTRESUME23!$A$6:$AO$36,12,0) -> 12000 | D14: 45049 | E14: TAXI BANQUE | F14: =[19]HISTOMAI23!$BP$16 -> 6000
A15: AS201651 | B15: =VLOOKUP(A15,[16]LISTADHERENT!A$5:H$60,3,0) -> DOMOU FABIEN | C15: =VLOOKUP(A15,[15]MVTRESUME23!$A$6:$AO$36,12,0) -> 12000 | D15: 45080 | E15: COMMISSION BUREAU | F15: =[19]HISTOJUIN23!$BP$8 -> 15000
A16: AS201609 | B16: =VLOOKUP(A16,[16]LISTADHERENT!A$5:H$60,3,0) -> DONHOU DAVID | C16: =VLOOKUP(A16,[15]MVTRESUME23!$A$6:$AO$36,12,0) -> 12000 | D16: 45080 | E16: PRODUCTION RAPPORT MBOGNING | F16: =[19]HISTOJUIN23!$BP$11 -> 3000
A17: AS201611 | B17: =VLOOKUP(A17,[16]LISTADHERENT!A$5:H$60,3,0) -> HENGUE PAUL OMER | C17: =VLOOKUP(A17,[15]MVTRESUME23!$A$6:$AO$36,12,0) -> 12000 | D17: 45110 | E17: TAXI BANQUE | F17: =[19]HISTOJUIL23!$BP$13 -> 6000
A18: AS201613 | B18: =VLOOKUP(A18,[16]LISTADHERENT!A$5:H$60,3,0) -> HOTCHO BENJAMIN | C18: =VLOOKUP(A18,[15]MVTRESUME23!$A$6:$AO$36,12,0) -> 12000 | D18: 45141 | E18: TAXI BANQUE | F18: =[19]HISTOAOUT23!$BP$13 -> 12000
A19: AS201617 | B19: =VLOOKUP(A19,[16]LISTADHERENT!A$5:H$60,3,0) -> KOUAMOU MOISE | C19: =VLOOKUP(A19,[15]MVTRESUME23!$A$6:$AO$36,12,0) -> 12000 | D19: 45141 | E19: LEGALISATION DOCUMENT | F19: =[19]HISTOAOUT23!$BP$8 -> 33000
A20: AS201619 | B20: =VLOOKUP(A20,[16]LISTADHERENT!A$5:H$60,3,0) -> KOUATCHO MESSACK | C20: =VLOOKUP(A20,[15]MVTRESUME23!$A$6:$AO$36,12,0) -> 12000 | D20: 45172 | E20: TAXI BANQUE | F20: =[19]HISTOSEPT23!$BP$13 -> 6000
A21: AS201620 | B21: =VLOOKUP(A21,[16]LISTADHERENT!A$5:H$60,3,0) -> LOWE JEAN | C21: =VLOOKUP(A21,[15]MVTRESUME23!$A$6:$AO$36,12,0) -> 12000 | D21: 45202 | E21: COMMUNICATI ON MBOUTCHUENG ET HENGUE | F21: =[19]HISTOOCT23!$BP$8 -> 7500
A22: AS201649 | B22: =VLOOKUP(A22,[16]LISTADHERENT!A$5:H$60,3,0) -> MBOGNING TUGMA GUY | C22: =VLOOKUP(A22,[15]MVTRESUME23!$A$6:$AO$36,12,0) -> 12000 | D22: 45202 | E22: TAXI BANQUE | F22: =[19]HISTOOCT23!$BP$13 -> 6000
A23: AS201639 | B23: =VLOOKUP(A23,[16]LISTADHERENT!A$5:H$60,3,0) -> NANGUEN MARTIN | C23: =VLOOKUP(A23,[15]MVTRESUME23!$A$6:$AO$36,12,0) -> 12000 | D23: 45233 | E23: TAXI BANQUE | F23: =[19]HISTONOV23!$BP$16 -> 6000
A24: AS201621 | B24: =VLOOKUP(A24,[16]LISTADHERENT!A$5:H$60,3,0) -> NANKAM APPOLINAIRE | C24: =VLOOKUP(A24,[15]MVTRESUME23!$A$6:$AO$36,12,0) -> 12000 | D24: 45263 | E24: TAXI BANQUE | F24: =[19]HISTODEC23!$BP$13 -> 6000
A25: AS201622 | B25: =VLOOKUP(A25,[16]LISTADHERENT!A$5:H$60,3,0) -> NDJOMO ETIENNE | C25: =VLOOKUP(A25,[15]MVTRESUME23!$A$6:$AO$36,12,0) -> 12000
A26: AS201624 | B26: =VLOOKUP(A26,[16]LISTADHERENT!A$5:H$60,3,0) -> NGONDIEP CLAUDE | C26: =VLOOKUP(A26,[15]MVTRESUME23!$A$6:$AO$36,12,0) -> 12000
A27: AS201626 | B27: =VLOOKUP(A27,[16]LISTADHERENT!A$5:H$60,3,0) -> NGUIEMEGNI MATHIEU BLAISE | C27: =VLOOKUP(A27,[15]MVTRESUME23!$A$6:$AO$36,12,0) -> 12000
A28: AS201628 | B28: =VLOOKUP(A28,[16]LISTADHERENT!A$5:H$60,3,0) -> NKAMGANG JUSTIN DEJOLIE | C28: =VLOOKUP(A28,[15]MVTRESUME23!$A$6:$AO$36,12,0) -> 12000
A29: AS201656 | B29: =VLOOKUP(A29,[16]LISTADHERENT!A$5:H$60,3,0) -> NOUBE ETIENNE | C29: =VLOOKUP(A29,[15]MVTRESUME23!$A$6:$AO$36,12,0) -> 12000
A30: AS201633 | B30: =VLOOKUP(A30,[16]LISTADHERENT!A$5:H$60,3,0) -> PATEGO NJOSSU GUSTAVE | C30: =VLOOKUP(A30,[15]MVTRESUME23!$A$6:$AO$36,12,0) -> 12000
A31: AS201657 | B31: =VLOOKUP(A31,[16]LISTADHERENT!A$5:H$60,3,0) -> SEUMO POLYCARPE | C31: =VLOOKUP(A31,[15]MVTRESUME23!$A$6:$AO$36,12,0) -> 12000
A32: AS201653 | B32: =VLOOKUP(A32,[16]LISTADHERENT!A$5:H$60,3,0) -> SIME BRICE | C32: =VLOOKUP(A32,[15]MVTRESUME23!$A$6:$AO$36,12,0) -> 12000
A33: AS201638 | B33: =VLOOKUP(A33,[16]LISTADHERENT!A$5:H$60,3,0) -> SIMO PIERRE | C33: =VLOOKUP(A33,[15]MVTRESUME23!$A$6:$AO$36,12,0) -> 12000
A34: AS201641 | B34: =VLOOKUP(A34,[16]LISTADHERENT!A$5:H$60,3,0) -> TCHOUAMOU MATHIEU | C34: =VLOOKUP(A34,[15]MVTRESUME23!$A$6:$AO$36,12,0) -> 12000
A35: AS201643 | B35: =VLOOKUP(A35,[16]LISTADHERENT!A$5:H$60,3,0) -> TCHOUTOU NANA CLAUDE | C35: =VLOOKUP(A35,[15]MVTRESUME23!$A$6:$AO$36,12,0) -> 12000
A36: AS201658 | B36: =VLOOKUP(A36,[16]LISTADHERENT!A$5:H$60,3,0) -> YANTCHOU GERVAIS | C36: =VLOOKUP(A36,[15]MVTRESUME23!$A$6:$AO$36,12,0) -> 12000
... A38: AS201647 | B38: =VLOOKUP(A38,[16]LISTADHERENT!A$5:H$60,3,0) -> YOUMBI EMMANUEL | C38: =VLOOKUP(A38,[15]MVTRESUME23!$A$6:$AO$36,12,0) -> 12000
A40: TOTAL | C40: =SUM(C8:C39) -> 363000 | E40: =SUM(E6:E39) -> 0 | F40: =SUM(F6:F39) -> 193000

Sheet DETAILFRAISEXCEPTIONNEL
A1: ASSOCIATION | B1: ASELBY
A2: ANNEE | B2: 2023
A4: FRAIS EXCEPTIONNELLE
A6: MATRICULE | B6: NOM ET PRENOM | C6: ENTREE | D6: SORTIE
C7: MONTANT | D7: DATE | E7: LIBELLE | F7: MONTANT
A8: AS201648 | B8: =VLOOKUP(A8,[16]LISTADHERENT!A$5:H$60,3,0) -> ASELBY | C8: =VLOOKUP(A8,[15]MVTRESUME23!$A$6:$AO$36,13,0) -> 0 | D8: 45078 | E8: NUIT DES ELITES (RECEPTION ET PROJET) | F8: =[19]HISTOJUIN23!$BP$26 -> 20000
A9: AS201601 | B9: =VLOOKUP(A9,[16]LISTADHERENT!A$5:H$60,3,0) -> BAKOP ACHILLE | C9: =VLOOKUP(A9,[15]MVTRESUME23!$A$6:$AO$36,13,0) -> 12000 | D9: 45108 | E9: NUIT DES ELITES (RECEPTION ET PROJET) | F9: =[19]HISTOJUIL23!$BP$26 -> 50000
A10: AS201602 | B10: =VLOOKUP(A10,[16]LISTADHERENT!A$5:H$60,3,0) -> BOUTCHOUANG WILLIAM | C10: =VLOOKUP(A10,[15]MVTRESUME23!$A$6:$AO$36,13,0) -> 12000 | D10: 45139 | E10: CONFECTION ET LAVAGE ECHARGE | F10: =[19]HISTOAOUT23!$BP$26 -> 155000
A11: AS201604 | B11: =VLOOKUP(A11,[16]LISTADHERENT!A$5:H$60,3,0) -> DJOMO JEAN PAUL | C11: =VLOOKUP(A11,[15]MVTRESUME23!$A$6:$AO$36,13,0) -> 12000 | D11: 45200 | E11: NUIT DES ELITES (RECEPTION ET PROJET) | F11: =[19]HISTOOCT23!$BP$25 -> 600000
A12: AS201654 | B12: =VLOOKUP(A12,[16]LISTADHERENT!A$5:H$60,3,0) -> DJOMOU TCHAPDA | C12: =VLOOKUP(A12,[15]MVTRESUME23!$A$6:$AO$36,13,0) -> 12000
A13: AS201605 | B13: =VLOOKUP(A13,[16]LISTADHERENT!A$5:H$60,3,0) -> DJOUKWE NANGUEN GUY BLAISE | C13: =VLOOKUP(A13,[15]MVTRESUME23!$A$6:$AO$36,13,0) -> 12000
A14: AS201608 | B14: =VLOOKUP(A14,[16]LISTADHERENT!A$5:H$60,3,0) -> DJUOMBESSY ANTOINE | C14: =VLOOKUP(A14,[15]MVTRESUME23!$A$6:$AO$36,13,0) -> 12000
A15: AS201651 | B15: =VLOOKUP(A15,[16]LISTADHERENT!A$5:H$60,3,0) -> DOMOU FABIEN | C15: =VLOOKUP(A15,[15]MVTRESUME23!$A$6:$AO$36,13,0) -> 12000
A16: AS201609 | B16: =VLOOKUP(A16,[16]LISTADHERENT!A$5:H$60,3,0) -> DONHOU DAVID | C16: =VLOOKUP(A16,[15]MVTRESUME23!$A$6:$AO$36,13,0) -> 12000
A17: AS201611 | B17: =VLOOKUP(A17,[16]LISTADHERENT!A$5:H$60,3,0) -> HENGUE PAUL OMER | C17: =VLOOKUP(A17,[15]MVTRESUME23!$A$6:$AO$36,13,0) -> 12000
A18: AS201613 | B18: =VLOOKUP(A18,[16]LISTADHERENT!A$5:H$60,3,0) -> HOTCHO BENJAMIN | C18: =VLOOKUP(A18,[15]MVTRESUME23!$A$6:$AO$36,13,0) -> 12000
A19: AS201617 | B19: =VLOOKUP(A19,[16]LISTADHERENT!A$5:H$60,3,0) -> KOUAMOU MOISE | C19: =VLOOKUP(A19,[15]MVTRESUME23!$A$6:$AO$36,13,0) -> 12000
A20: AS201619 | B20: =VLOOKUP(A20,[16]LISTADHERENT!A$5:H$60,3,0) -> KOUATCHO MESSACK | C20: =VLOOKUP(A20,[15]MVTRESUME23!$A$6:$AO$36,13,0) -> 12000
A21: AS201620 | B21: =VLOOKUP(A21,[16]LISTADHERENT!A$5:H$60,3,0) -> LOWE JEAN | C21: =VLOOKUP(A21,[15]MVTRESUME23!$A$6:$AO$36,13,0) -> 12000
A22: AS201649 | B22: =VLOOKUP(A22,[16]LISTADHERENT!A$5:H$60,3,0) -> MBOGNING TUGMA GUY | C22: =VLOOKUP(A22,[15]MVTRESUME23!$A$6:$AO$36,13,0) -> 12000
A23: AS201639 | B23: =VLOOKUP(A23,[16]LISTADHERENT!A$5:H$60,3,0) -> NANGUEN MARTIN | C23: =VLOOKUP(A23,[15]MVTRESUME23!$A$6:$AO$36,13,0) -> 12000
... A38: AS201647 | B38: =VLOOKUP(A38,[16]LISTADHERENT!A$5:H$60,3,0) -> YOUMBI EMMANUEL | C38: =VLOOKUP(A38,[15]MVTRESUME23!$A$6:$AO$36,13,0) -> 12000
A40: TOTAL | C40: =SUM(C8:C39) -> 360000 | E40: =SUM(E6:E39) -> 0 | F40: =SUM(F6:F39) -> 825000

Sheet DETAILFONDSMUTUEL
A1: ASSOCIATION | B1: ASELBY
A2: ANNEE | B2: 2023
A4: FONDS MUTUELLE
A6: MATRICULE | B6: NOM ET PRENOM | C6: ENTREE | F6: SORTIE
C7: MONTANT | D7: COMPLEMENT | E7: TOTAL | F7: DATE | G7: LIBELLE | H7: MONTANT
A8: AS201648 | B8: =VLOOKUP(A8,[16]LISTADHERENT!A$5:H$60,3,0) -> ASELBY | C8: =VLOOKUP(A8,[15]MVTRESUME23!$A$6:$AO$36,17,0) -> 0 | D8: =DETAILFICHECASSATION!K6 -> 0 | E8: =C8+D8 -> 0 | F8: 44958 | G8: OBSEQUES NKEPSEU DIEUDONNE | H8: =[19]HISTOFEV23!$BP$30 -> 560000
A9: AS201601 | B9: =VLOOKUP(A9,[16]LISTADHERENT!A$5:H$60,3,0) -> BAKOP ACHILLE | C9: =VLOOKUP(A9,[15]MVTRESUME23!$A$6:$AO$36,17,0) -> 0 | D9: =DETAILFICHECASSATION!K7 -> 40000 | E9: =C9+D9 -> 40000 | F9: 44958 | G9: TRANSPORT DELEGATION | H9: =[19]HISTOFEV23!$BP$31 -> 0
A10: AS201602 | B10: =VLOOKUP(A10,[16]LISTADHERENT!A$5:H$60,3,0) -> BOUTCHOUANG WILLIAM | C10: =VLOOKUP(A10,[15]MVTRESUME23!$A$6:$AO$36,17,0) -> 0 | D10: =DETAILFICHECASSATION!K8 -> 40000 | E10: =C10+D10 -> 40000 | F10: 45047 | G10: DECES BEAU PÈRE NGUIEMENI | H10: =[19]HISTOMAI23!$BP$30-100000 -> 100000
A11: AS201604 | B11: =VLOOKUP(A11,[16]LISTADHERENT!A$5:H$60,3,0) -> DJOMO JEAN PAUL | C11: =VLOOKUP(A11,[15]MVTRESUME23!$A$6:$AO$36,17,0) -> 0 | D11: =DETAILFICHECASSATION!K9 -> 40000 | E11: =C11+D11 -> 40000 | F11: 45047 | G11: DECES BELLE MERE DJUOMBESSY | H11: =[19]HISTOMAI23!$BP$30-100000 -> 100000
A12: AS201654 | B12: =VLOOKUP(A12,[16]LISTADHERENT!A$5:H$60,3,0) -> DJOMOU TCHAPDA | C12: =VLOOKUP(A12,[15]MVTRESUME23!$A$6:$AO$36,17,0) -> 0 | D12: =DETAILFICHECASSATION!K10 -> 40000 | E12: =C12+D12 -> 40000 | F12: 45139 | G12: OBSEQUES Mme KOUATCHO MESSACK | H12: =[19]HISTOAOUT23!$BP$33 -> 560000
A13: AS201605 | B13: =VLOOKUP(A13,[16]LISTADHERENT!A$5:H$60,3,0) -> DJOUKWE NANGUEN GUY BLAISE | C13: =VLOOKUP(A13,[15]MVTRESUME23!$A$6:$AO$36,17,0) -> 0 | D13: =DETAILFICHECASSATION!K11 -> 40000 | E13: =C13+D13 -> 40000
A14: AS201608 | B14: =VLOOKUP(A14,[16]LISTADHERENT!A$5:H$60,3,0) -> DJUOMBESSY ANTOINE | C14: =VLOOKUP(A14,[15]MVTRESUME23!$A$6:$AO$36,17,0) -> 0 | D14: =DETAILFICHECASSATION!K12 -> 40000 | E14: =C14+D14 -> 40000
A15: AS201651 | B15: =VLOOKUP(A15,[16]LISTADHERENT!A$5:H$60,3,0) -> DOMOU FABIEN | C15: =VLOOKUP(A15,[15]MVTRESUME23!$A$6:$AO$36,17,0) -> 0 | D15: =DETAILFICHECASSATION!K13 -> 40000 | E15: =C15+D15 -> 40000
A16: AS201609 | B16: =VLOOKUP(A16,[16]LISTADHERENT!A$5:H$60,3,0) -> DONHOU DAVID | C16: =VLOOKUP(A16,[15]MVTRESUME23!$A$6:$AO$36,17,0) -> 0 | D16: =DETAILFICHECASSATION!K14 -> 40000 | E16: =C16+D16 -> 40000
A17: AS201611 | B17: =VLOOKUP(A17,[16]LISTADHERENT!A$5:H$60,3,0) -> HENGUE PAUL OMER | C17: =VLOOKUP(A17,[15]MVTRESUME23!$A$6:$AO$36,17,0) -> 0 | D17: =DETAILFICHECASSATION!K15 -> 40000 | E17: =C17+D17 -> 40000
A18: AS201613 | B18: =VLOOKUP(A18,[16]LISTADHERENT!A$5:H$60,3,0) -> HOTCHO BENJAMIN | C18: =VLOOKUP(A18,[15]MVTRESUME23!$A$6:$AO$36,17,0) -> 0 | D18: =DETAILFICHECASSATION!K16 -> 40000 | E18: =C18+D18 -> 40000
A19: AS201617 | B19: =VLOOKUP(A19,[16]LISTADHERENT!A$5:H$60,3,0) -> KOUAMOU MOISE | C19: =VLOOKUP(A19,[15]MVTRESUME23!$A$6:$AO$36,17,0) -> 0 | D19: =DETAILFICHECASSATION!K17 -> 40000 | E19: =C19+D19 -> 40000
A20: AS201619 | B20: =VLOOKUP(A20,[16]LISTADHERENT!A$5:H$60,3,0) -> KOUATCHO MESSACK | C20: =VLOOKUP(A20,[15]MVTRESUME23!$A$6:$AO$36,17,0) -> 0 | D20: =DETAILFICHECASSATION!K18 -> 40000 | E20: =C20+D20 -> 40000
A21: AS201620 | B21: =VLOOKUP(A21,[16]LISTADHERENT!A$5:H$60,3,0) -> LOWE JEAN | C21: =VLOOKUP(A21,[15]MVTRESUME23!$A$6:$AO$36,17,0) -> 0 | D21: =DETAILFICHECASSATION!K19 -> 40000 | E21: =C21+D21 -> 40000
A22: AS201649 | B22: =VLOOKUP(A22,[16]LISTADHERENT!A$5:H$60,3,0) -> MBOGNING TUGMA GUY | C22: =VLOOKUP(A22,[15]MVTRESUME23!$A$6:$AO$36,17,0) -> 0 | D22: =DETAILFICHECASSATION!K20 -> 40000 | E22: =C22+D22 -> 40000
A23: AS201639 | B23: =VLOOKUP(A23,[16]LISTADHERENT!A$5:H$60,3,0) -> NANGUEN MARTIN | C23: =VLOOKUP(A23,[15]MVTRESUME23!$A$6:$AO$36,17,0) -> 0 | D23: =DETAILFICHECASSATION!K21 -> 40000 | E23: =C23+D23 -> 40000
A24: AS201621 | B24: =VLOOKUP(A24,[16]LISTADHERENT!A$5:H$60,3,0) -> NANKAM APPOLINAIRE | C24: =VLOOKUP(A24,[15]MVTRESUME23!$A$6:$AO$36,17,0) -> 0 | D24: =DETAILFICHECASSATION!K22 -> 40000 | E24: =C24+D24 -> 40000
... A38: AS201647 | B38: =VLOOKUP(A38,[16]LISTADHERENT!A$5:H$60,3,0) -> YOUMBI EMMANUEL | C38: =VLOOKUP(A38,[15]MVTRESUME23!$A$6:$AO$36,17,0) -> 0 | D38: =DETAILFICHECASSATION!K36 -> 40000 | E38: =C38+D38 -> 40000
A40: TOTAL | C40: =SUM(C8:C39) -> 360000 | D40: =SUM(D8:D39) -> 1160000 | E40: =SUM(E8:E39) -> 1520000 | G40: =SUM(G6:G39) -> 0 | H40: =SUM(H6:H39) -> 1320000

Sheet DETAILPENALITES
A1: ASSOCIATION | B1: ASELBY
A2: ANNEE | B2: 2023
A4: PENALITES
A6: MATRICULE | B6: NOM ET PRENOM | C6: ENTREE | E6: SORTIE
C7: MONTANT PAIEMENT ESPECES | D7: MONTANT SANCTION | E7: DATE | F7: LIBELLE | G7: MONTANT
A8: AS201648 | B8: =VLOOKUP(A8,[16]LISTADHERENT!A$5:H$60,3,0) -> ASELBY | C8: =VLOOKUP(A8,[15]MVTRESUME23!$A$6:$AO$36,15,0) -> 4000 | D8: =VLOOKUP(A8,[15]MVTRESUME23!$A$6:$AO$36,9,0) -> 0 | E8: 44958 | F8: GRATIFICATION BUREAU 2022 | G8: =[19]HISTOFEV23!$BP$22 -> 200000
A9: AS201601 | B9: =VLOOKUP(A9,[16]LISTADHERENT!A$5:H$60,3,0) -> BAKOP ACHILLE | C9: =VLOOKUP(A9,[15]MVTRESUME23!$A$6:$AO$36,15,0) -> 3000 | D9: =VLOOKUP(A9,[15]MVTRESUME23!$A$6:$AO$36,9,0) -> 0
