Workbook
Name BANQUE: #REF!
Name BANQUE: #REF!
Name BANQUE: #REF!
Name BANQUE: #REF!
Name BANQUE: #REF!
Name BANQUE: #REF!
Name BANQUE: #REF!
Name BANQUE: #REF!
Name BANQUE: #REF!
Name BANQUE: #REF!
Name BANQUE: #REF!
Name BANQUE: #REF!
Name BANQUE: #REF!
Name BANQUE: #REF!
Name BANQUE: #REF!
Name BANQUE: #REF!
Name BANQUE: #REF!
Name MODEET30000: [1]MODEVERSEMENT!$A$1:$A$3
Name MODEPAID: [2]Feuil2!$A$1:$A$3
Name MODEPAID: [2]Feuil2!$A$1:$A$3
Name MODEPAID: [2]Feuil2!$A$1:$A$3
Name MODEPAID: [2]Feuil2!$A$1:$A$3
Name MODEPAID: [3]Feuil2!$A$1:$A$3
Name MODEPAID: [3]Feuil2!$A$1:$A$3
Name MODEPAID: [4]Feuil2!$A$1:$A$3
Name MODEPAID30000: DETAILFICHECASSATION!#REF!
Name MODEPAID30000: 'DETAILFICHECASSATION (2)'!#REF!
Name MODEPAIDOK: [5]MODEVERSEMENT!$A$1:$A$4
Name MODEPAIDOK: [5]MODEVERSEMENT!$A$1:$A$4
Name MODEPAIDS: [1]MODEVERSEMENT!$A$1:$A$3
Name MODET25000: [6]MODEVERSEMENT!$A$1:$A$3
Name MODET3000: [1]MODEVERSEMENT!$A$1:$A$3
Name MODET30000: DETAILFICHECASSATION!#REF!
Name MODET30000: 'DETAILFICHECASSATION (2)'!#REF!
Name MODEVERSEMENT: #REF!
Name MODEVERSEMENT: #REF!
Name MODEVERSEMENT: #REF!
Name MODEVERSEMENT: #REF!
Name MODEVERSEMENT: #REF!
Name MODEVERSEMENT: #REF!
Name MODEVERSEMENT: #REF!
Name MODEVERSEMENT: #REF!
Name MODEVERSEMENT: #REF!
Name MODEVERSEMENT: #REF!
Name MODEVERSEMENT: #REF!
Name MODEVERSEMENT: #REF!
Name MODEVERSEMENT: #REF!
Name MODEVERSEMENT: #REF!
Name MODEVERSEMENT: #REF!
Name MODEVERSEMENT: #REF!
Name MODEVERSEMENT: #REF!
Name MODEVERSEMENTS: [7]MODEVERSEMENT!$A$1:$A$3
Name MODPAID: DETAILFICHECASSATION!#REF!
Name MODPAID: 'DETAILFICHECASSATION (2)'!#REF!
Name VALMODEPAID: [8]MODEPAID!$A$1:$A$3

Sheet BILAN 2016
A2: BILAN ALLANT DE LA PERIODE DU 01 DECEMBRE 2015 AU 30 NOVEMBRE 2016
A5: RUBRIQUE | B5: REPORT A NOUVEAU | C5: ENTREES | D5: SORTIES | E5: SOLDE
A7: EPARGNE\RELIQUAT2015 | B7: 29756024 | C7: =[9]TRAVAUXINVENTAIRE!R54+C20+1050000+2230668 -> 7101809 | E7: =B7+C7-D7 -> 36857833
A8: FONDS DE CAISSE | C8: 28382451 | D8: 39386431 | E8: =B8+C8-D8 -> -11003980
A9: FONDS DE ROULEMENT | B9: 3031178 | C9: =[9]TRAVAUXINVENTAIRE!S54 -> 250500 | D9: ='[10]BILAN 2016'!$D$9 -> 224500 | E9: =B9+C9-D9 -> 3057178
A10: FRAIS EXCEPTIONNELS | B10: 1267460 | C10: =[9]TRAVAUXINVENTAIRE!T54 -> 501000 | D10: =[9]TRAVAUXINVENTAIREDEC!B6 -> 1100000 | E10: =B10+C10-D10 -> 668460
A11: COLLATION | B11: 940125 | C11: =[9]TRAVAUXINVENTAIRE!U54 -> 1252500 | D11: =[9]TRAVAUXINVENTAIREDEC!B7 -> 1260000 | E11: =B11+C11-D11 -> 932625
A12: MUTUELLE\COMPLEMENT MUTUEL | B12: =-101500 -> -101500 | C12: =[9]TRAVAUXINVENTAIRE!V54+[9]TRAVAUXINVENTAIRE!O54 -> 1954860 | D12: =[9]TRAVAUXINVENTAIREDEC!B8 -> 2595000 | E12: =B12+C12-D12 -> -741640
A13: INSCRIPTION | B13: 530000 | E13: =B13+C13-D13 -> 530000
A14: FONDS GELE | B14: 54508 | E14: =B14+C14-D14 -> 54508
A15: CHAISE | B15: -164500 | E15: =B15+C15-D15 -> -164500
A16: TENUE | B16: -75000 | E16: =B16+C16-D16 -> -75000
A17: FOYER | E17: =B17+C17-D17 -> 0
A18: RECOUVREMENT POUR LAGWEU GENERAL | C18: =320750+16500 -> 337250 | E18: =B18+C18-D18 -> 337250 | F18: 1711250
A19: AUTRES | E19: =B19+C19-D19 -> 0
A20: INTERET EMPRUNT | E20: =B20+C20-D20 -> 0
A22: EMPRUNT
A24: RELIQUAT 2016
A27: COMPTE CCA
A28: COMPTE AFRILAND
A29: INTERET BQUE AFRILAND | B29: 1779594 | E29: =B29+C29-D29 -> 1779594
A30: COMPTE MC2
A31: ASELBY CAISSE(NDJOMO ETIENNE)
A33: RETRAIT DISTRIBUTION EPARGNE
A35: SOUS TOTAL
A37: MONTANT DISPONIBLE | B37: =SUM(B7:B36) -> 37017889 | C37: =SUM(C7:C36) -> 39780370 | D37: =SUM(D7:D36) -> 44565931 | E37: =B37+C37-D37 -> 32232328

Sheet BILAN 2017
A2: BILAN ALLANT DE LA PERIODE DU 01 DECEMBRE 2016 AU 30 AOUT 2017
A5: RUBRIQUE | B5: REPORT A NOUVEAU | C5: ENTREES | D5: SORTIES | E5: SOLDE
A7: EPARGNE\RELIQUAT2016 | B7: ='BILAN 2016'!E7 -> 36857833 | C7: =[11]BILANFINAOUT2017!E56 -> 3963693 | D7: 13500000 | E7: =B7+C7-D7 -> 27321526
A8: FONDS DE CAISSE | B8: ='BILAN 2016'!E8 -> -11003980 | C8: =[11]BILANFINAOUT2017!C56 -> 16310819 | E8: =B8+C8-D8 -> 5306839
A9: FONDS DE ROULEMENT | B9: ='BILAN 2016'!E9 -> 3057178 | C9: =[11]BILANFINAOUT2017!F56 -> 182000 | D9: =89000+84000+12000+10000+6000+48000+13000+5000 -> 267000 | E9: =B9+C9-D9 -> 2972178
A10: FRAIS EXCEPTIONNELS | B10: ='BILAN 2016'!E10 -> 668460 | C10: =[11]BILANFINAOUT2017!G56 -> 364000 | D10: =200000+345000 -> 545000 | E10: =B10+C10-D10 -> 487460
A11: COLLATION | B11: ='BILAN 2016'!E11 -> 932625 | C11: =[11]BILANFINAOUT2017!H56 -> 910000 | D11: =100000+110000+100000+100000+100000+100000+100000+100000+100000 -> 910000 | E11: =B11+C11-D11 -> 932625
A12: MUTUELLE\COMPLEMENT MUTUEL | B12: ='BILAN 2016'!E12 -> -741640 | C12: =[11]BILANFINAOUT2017!I56 -> 2009927 | D12: =200000+100000+640000 -> 940000 | E12: =B12+C12-D12 -> 328287
A13: PENALITE VERSEMENT EN ESPECES | C13: =[11]BILANFINAOUT2017!R56 -> 125000 | E13: =B13+C13-D13 -> 125000
A14: SANCTION | C14: =+[11]BILANFINAOUT2017!J56 -> 0
A15: INSCRIPTION | B15: ='BILAN 2016'!E13 -> 530000 | E15: =B15+C15-D15 -> 530000
A16: FONDS GELE | B16: ='BILAN 2016'!E14 -> 54508 | E16: =B16+C16-D16 -> 54508
A17: CHAISE | B17: ='BILAN 2016'!E15 -> -164500 | E17: =B17+C17-D17 -> -164500
A18: TENUE | B18: ='BILAN 2016'!E16 -> -75000 | E18: =B18+C18-D18 -> -75000
E19: =B19+C19-D19 -> 0
A20: FOYER | E20: =B20+C20-D20 -> 0
A21: RECOUVREMENT POUR LAGWEU GENERAL | B21: ='BILAN 2016'!E18 -> 337250 | E21: =B21+C21-D21 -> 337250
A22: AUTRES
A23: INTERET EMPRUNT
A25: EMPRUNT | E25: =B25+C25-D25 -> 0
A27: RELIQUAT 2016
A29: INTERET BQUE AFRILAND | B29: 1779594 | E29: =B29+C29-D29 -> 1779594
A30: COMPTE CCA
A31: COMPTE AFRILAND
A32: COMPTE MC2
A33: ASELBY CAISSE(NDJOMO ETIENNE)
A35: RETRAIT DISTRIBUTION EPARGNE
A39: MONTANT DISPONIBLE | B39: =SUM(B7:B38) -> 32232328 | C39: =SUM(C7:C38) -> 23865439 | D39: =SUM(D7:D38) -> 16162000 | E39: =B39+C39-D39 -> 39935767

Sheet BILAN 2022
B1: ASELBY
B2: ANNEE | C2: 2022
B3: SYNTHESE DES COMPTES
A6: NUMERO ORDRE | B6: RUBRIQUE | C6: REPORT A NOUVEAU | D6: ENTREES | E6: SORTIES | F6: SOLDE
A8: 1 | B8: FONDS DE CAISSE ET RELIQUAT | C8: 21791466 | E8: 500000 | F8: 21291466
A9: 2 | B9: FONDS DE ROULEMENT | C9: 2074728 | D9: 156000 | E9: 234500 | F9: 1996228
A10: 3 | B10: FRAIS EXCEPTIONNELS | C10: 1191460 | D10: 312000 | E10: 0 | F10: 1503460
A11: 4 | B11: MUTUELLE\COMPLEMENT MUTUEL | C11: 94762 | D11: 520000 | E11: 0 | F11: =C11+D11 -> 614762
A12: 5 | B12: INSCRIPTION | C12: 680000 | D12: 0 | E12: 0 | F12: 680000
A13: 6 | B13: PENALITES | C13: 1122025 | D13: 96000 | E13: 450000 | F13: 768025
A14: 7 | B14: COLLATION | C14: 1310525 | D14: 780000 | E14: 770000 | F14: 1320525
A15: 8 | B15: TONTINE DE PRESENCE | C15: 94000 | F15: 94000
A16: 9 | B16: RECOUVREMENT POUR LA'AGWEU | F16: 0
A17: 10 | B17: FOYER | C17: 527000 | D17: 1836000 | E17: 1820000 | F17: 543000
A18: 11 | B18: CHAISES | C18: 164500 | E18: 164500 | F18: 0
A19: 12 | B19: DIVERS | C19: 619900 | E19: 619900 | F19: 0
A20: 13 | B20: TENUES | C20: 75000 | E20: 75000 | F20: 0
A21: 14 | B21: FONDS GELES | C21: 54508 | E21: 54508 | F21: 0
A22: 15 | B22: INTERETS ET AUTRES | C22: 2858226 | D22: 3748108 | F22: 6606334
B23: INTERET TONTINE 100 | D23: 28000 | F23: 28000
B25: TOTAL | C25: 32658100 | D25: =SUM(D9:D23) -> 7476108 | E25: 4688408 | F25: =SUM(F8:F23) -> 35445800 | H25: 479000
B27: DISPOSITION DES FONDS
C30: 2021 | D30: 2022
A31: 1 | B31: COMPTE CCA AU 30/12/2022 | C31: 7304779 | D31: 4337431
A32: 2 | B32: COMPTE MC²(NON ACTUALISE) | C32: 630005 | D32: 630005
A33: 3 | B33: COMPTE AFRILAND | C33: 1423702 | D33: 1423702
A34: 4 | B34: DETTE PREFINANCEMENT LA'AGWEU | C34: 744700 | D34: 744700
A35: 5 | B35: DETTE MR KOUATCHO | C35: 275000 | D35: 0
A36: 6 | B36: RESTE A RECUPERE AU CONSEIL | C36: 154000 | D36: 154000
A37: 7 | B37: FONDS EN CIRCULATION | C37: 20515659 | D37: 18658500
A38: 8 | B38: DETTES TONTINES | C38: 1233618 | D38: 656618
B40: TOTAL | C40: 32281463 | D40: 26604956

Sheet DETAILFICHECASSATION (2)
A1: ASSOCIATION | B1: ASELBY
A2: ANNEE | B2: 2025
A5: MATRICULE | B5: NOM ET PRENOM | C5: FONDS DE CAISSE | D5: RECONDUCTION | E5: REPARTITION INTERET | F5: EPARGNE | G5: REPARTITION PENALITE REMBOURSEMENT PRÊT | H5: REPARTITION COLLATION | I5: TOTAL A DISTRIBUER | J5: SANCTION | K5: COMPLEMENT MUTUELLE | L5: COMPLEMENT FONDS | M5: DETTE PRÊT FONDS | N5: TOTAL RETENU | O5: TOTAL A PERCEVOIR | P5: MONTANT PERCU | Q5: RECONDUCTION 2025 | R5: NOUVEAU FONDS | S5: DONS FOYER | T5: MONTANT PERCU EN ESPECES | U5: MONTANT PERCU CHEQUE | V5: INTERET
A6: AS201648 | B6: =VLOOKUP($A$6,[12]LISTADHERENT!$A$5:$K$43,3,0) -> ASELBY | C6: =VLOOKUP($A6,[13]MVTRESUME25!$A$6:$AL$45,3,0) -> 0 | D6: =VLOOKUP($A6,[13]MVTRESUME25!$A$6:$AL$45,4,0) -> 1023134 | E6: =VLOOKUP($A6,[13]MVTRESUME25!$A$6:$AL$45,8,0) -> 83346.091 | F6: =VLOOKUP($A6,[13]MVTRESUME25!$A$6:$AL$45,12,0) -> 80000 | I6: =+D6+E6+F6+G6+H6 -> 1186480.1 | J6: =VLOOKUP($A6,[13]MVTRESUME25!$A$6:$AL$45,10,0) -> 0 | M6: =VLOOKUP($A6,[13]MVTRESUME25!$A$6:$AL$45,23,0) -> 0 | N6: =J6+K6+L6+M6 -> 0 | O6: =I6-N6-S6 -> 1186480.1 | Q6: =O6-P6-S6 -> 1186480.1 | V6: 82902
A7: AS201601 | B7: =VLOOKUP(A7,[12]LISTADHERENT!$A$5:$K$43,3,0) -> BAKOP ACHILLE | C7: =VLOOKUP($A7,[13]MVTRESUME25!$A$6:$AL$45,3,0) -> 800000 | D7: =VLOOKUP($A7,[13]MVTRESUME25!$A$6:$AL$45,4,0) -> 18598 | E7: =VLOOKUP($A7,[13]MVTRESUME25!$A$6:$AL$45,8,0) -> 68937.111 | F7: =VLOOKUP($A7,[13]MVTRESUME25!$A$6:$AL$45,12,0) -> 223000 | I7: =+D7+E7+F7+G7+H7 -> 310535.11 | J7: =VLOOKUP($A7,[13]MVTRESUME25!$A$6:$AL$45,10,0) -> 0 | K7: 30000 | L7: 100000 | M7: =VLOOKUP($A7,[13]MVTRESUME25!$A$6:$AL$45,23,0) -> 0 | N7: =J7+K7+L7+M7 -> 130000 | O7: =I7-N7 -> 180535.11 | P7: =T7 -> 80000 | Q7: =O7-P7-S7 -> 535.11069 | R7: =C7+L7 -> 900000 | S7: 100000 | T7: 80000 | V7: 68535
A8: AS201602 | B8: =VLOOKUP(A8,[12]LISTADHERENT!$A$5:$K$43,3,0) -> BOUTCHOUANG WILLIAM | C8: =VLOOKUP($A8,[13]MVTRESUME25!$A$6:$AL$45,3,0) -> 800000 | D8: =VLOOKUP($A8,[13]MVTRESUME25!$A$6:$AL$45,4,0) -> 132669 | E8: =VLOOKUP($A8,[13]MVTRESUME25!$A$6:$AL$45,8,0) -> 78276.309 | F8: =VLOOKUP($A8,[13]MVTRESUME25!$A$6:$AL$45,12,0) -> 228000 | I8: =+D8+E8+F8+G8+H8 -> 438945.31 | J8: =VLOOKUP($A8,[13]MVTRESUME25!$A$6:$AL$45,10,0) -> 0 | K8: 30000 | L8: 100000 | M8: =VLOOKUP($A8,[13]MVTRESUME25!$A$6:$AL$45,23,0) -> 0 | N8: =J8+K8+L8+M8 -> 130000 | O8: =I8-N8 -> 308945.31 | P8: =T8 -> 250000 | Q8: =O8-P8-S8 -> 58945.309 | R8: =C8+L8 -> 900000 | T8: 250000 | V8: 77823
A9: AS201604 | B9: =VLOOKUP(A9,[12]LISTADHERENT!$A$5:$K$43,3,0) -> DJOMO JEAN PAUL | C9: =VLOOKUP($A9,[13]MVTRESUME25!$A$6:$AL$45,3,0) -> 800000 | D9: =VLOOKUP($A9,[13]MVTRESUME25!$A$6:$AL$45,4,0) -> 6643 | E9: =VLOOKUP($A9,[13]MVTRESUME25!$A$6:$AL$45,8,0) -> 68010.035 | F9: =VLOOKUP($A9,[13]MVTRESUME25!$A$6:$AL$45,12,0) -> 228000 | I9: =+D9+E9+F9+G9+H9 -> 302653.03 | J9: =VLOOKUP($A9,[13]MVTRESUME25!$A$6:$AL$45,10,0) -> 5000 | K9: 30000 | L9: 100000 | M9: =VLOOKUP($A9,[13]MVTRESUME25!$A$6:$AL$45,23,0) -> 0 | N9: =J9+K9+L9+M9+101000 -> 236000 | O9: =I9-N9 -> 66653.035 | P9: =T9 -> 0 | Q9: =O9-P9-S9 -> 66653.035 | R9: =C9+L9 -> 900000 | V9: 67612
A10: AS201654 | B10: =VLOOKUP(A10,[12]LISTADHERENT!$A$5:$K$43,3,0) -> DJOMOU TCHAPDA | C10: =VLOOKUP($A10,[13]MVTRESUME25!$A$6:$AL$45,3,0) -> 800000 | D10: =VLOOKUP($A10,[13]MVTRESUME25!$A$6:$AL$45,4,0) -> 7246 | E10: =VLOOKUP($A10,[13]MVTRESUME25!$A$6:$AL$45,8,0) -> 68278.203 | F10: =VLOOKUP($A10,[13]MVTRESUME25!$A$6:$AL$45,12,0) -> 235500 | I10: =+D10+E10+F10+G10+H10 -> 311024.2 | J10: =VLOOKUP($A10,[13]MVTRESUME25!$A$6:$AL$45,10,0) -> 0 | K10: 30000 | L10: 100000 | M10: =VLOOKUP($A10,[13]MVTRESUME25!$A$6:$AL$45,23,0) -> 0 | N10: =J10+K10+L10+M10 -> 130000 | O10: =I10-N10 -> 181024.2 | P10: =T10 -> 70000 | Q10: =O10-P10-S10 -> 11024.203 | R10: =C10+L10 -> 900000 | S10: 100000 | T10: 70000 | V10: 67876
A11: AS201605 | B11: =VLOOKUP(A11,[12]LISTADHERENT!$A$5:$K$43,3,0) -> DJOUKWE NANGUEN GUY BLAISE | C11: =VLOOKUP($A11,[13]MVTRESUME25!$A$6:$AL$45,3,0) -> 800000 | D11: =VLOOKUP($A11,[13]MVTRESUME25!$A$6:$AL$45,4,0) -> 6032 | E11: =VLOOKUP($A11,[13]MVTRESUME25!$A$6:$AL$45,8,0) -> 68968.183 | F11: =VLOOKUP($A11,[13]MVTRESUME25!$A$6:$AL$45,12,0) -> 478375 | I11: =+D11+E11+F11+G11+H11 -> 553375.18 | J11: =VLOOKUP($A11,[13]MVTRESUME25!$A$6:$AL$45,10,0) -> 0 | K11: 30000 | L11: 100000 | M11: =VLOOKUP($A11,[13]MVTRESUME25!$A$6:$AL$45,23,0) -> 0 | N11: =J11+K11+L11+M11 -> 130000 | O11: =I11-N11 -> 423375.18 | P11: =T11 -> 400000 | Q11: =O11-P11-S11 -> -17624.817 | R11: =C11+L11 -> 900000 | S11: 41000 | T11: 400000 | V11: 68550
A12: AS201608 | B12: =VLOOKUP(A12,[12]LISTADHERENT!$A$5:$K$43,3,0) -> DJUOMBESSY ANTOINE | C12: =VLOOKUP($A12,[13]MVTRESUME25!$A$6:$AL$45,3,0) -> 800000 | D12: =VLOOKUP($A12,[13]MVTRESUME25!$A$6:$AL$45,4,0) -> 14486 | E12: =VLOOKUP($A12,[13]MVTRESUME25!$A$6:$AL$45,8,0) -> 85780.246 | F12: =VLOOKUP($A12,[13]MVTRESUME25!$A$6:$AL$45,12,0) -> 1208500 | I12: =+D12+E12+F12+G12+H12 -> 1308766.2 | J12: =VLOOKUP($A12,[13]MVTRESUME25!$A$6:$AL$45,10,0) -> 0 | K12: 30000 | L12: 100000 | M12: =VLOOKUP($A12,[13]MVTRESUME25!$A$6:$AL$45,23,0) -> 0 | N12: =J12+K12+L12+M12 -> 130000 | O12: =I12-N12 -> 1178766.2 | P12: 400000 | Q12: =O12-P12-S12 -> 678766.25 | R12: =C12+L12 -> 900000 | S12: 100000 | U12: 400000 | V12: 85054
A13: AS201651 | B13: =VLOOKUP(A13,[12]LISTADHERENT!$A$5:$K$43,3,0) -> DOMOU FABIEN | C13: =VLOOKUP($A13,[13]MVTRESUME25!$A$6:$AL$45,3,0) -> 800000 | D13: =VLOOKUP($A13,[13]MVTRESUME25!$A$6:$AL$45,4,0) -> 6365 | E13: =VLOOKUP($A13,[13]MVTRESUME25!$A$6:$AL$45,8,0) -> 67987.389 | F13: =VLOOKUP($A13,[13]MVTRESUME25!$A$6:$AL$45,12,0) -> 228000 | I13: =+D13+E13+F13+G13+H13 -> 302352.39 | J13: =VLOOKUP($A13,[13]MVTRESUME25!$A$6:$AL$45,10,0) -> 0 | K13: 30000 | L13: 100000 | M13: =VLOOKUP($A13,[13]MVTRESUME25!$A$6:$AL$45,23,0) -> 0 | N13: =J13+K13+L13+M13 -> 130000 | O13: =I13-N13 -> 172352.39 | P13: =+T13 -> 170000 | Q13: =O13-P13-S13 -> 2352.3886 | R13: =C13+L13 -> 900000 | T13: 170000 | V13: 67590
A14: AS201609 | B14: =VLOOKUP(A14,[12]LISTADHERENT!$A$5:$K$43,3,0) -> DONHOU DAVID | C14: =VLOOKUP($A14,[13]MVTRESUME25!$A$6:$AL$45,3,0) -> 800000 | D14: =VLOOKUP($A14,[13]MVTRESUME25!$A$6:$AL$45,4,0) -> 702391 | E14: =VLOOKUP($A14,[13]MVTRESUME25!$A$6:$AL$45,8,0) -> 124677.13 | F14: =VLOOKUP($A14,[13]MVTRESUME25!$A$6:$AL$45,12,0) -> 225000 | I14: =+D14+E14+F14+G14+H14 -> 1052068.1 | J14: =VLOOKUP($A14,[13]MVTRESUME25!$A$6:$AL$45,10,0) -> 0 | K14: 30000 | L14: 100000 | M14: =VLOOKUP($A14,[13]MVTRESUME25!$A$6:$AL$45,23,0) -> 0 | N14: =J14+K14+L14+M14 -> 130000 | O14: =I14-N14 -> 922068.13 | P14: =+T14 -> 0 | Q14: =O14-P14-S14 -> 922068.13 | R14: =C14+L14 -> 900000 | V14: 123976
A15: AS201663 | B15: =VLOOKUP(A15,[12]LISTADHERENT!$A$5:$K$43,3,0) -> FAMPOU PAUL | C15: =VLOOKUP($A15,[13]MVTRESUME25!$A$6:$AL$45,3,0) -> 0 | D15: =VLOOKUP($A15,[13]MVTRESUME25!$A$6:$AL$45,4,0) -> 0 | E15: =VLOOKUP($A15,[13]MVTRESUME25!$A$6:$AL$45,8,0) -> 5255.3359 | F15: =VLOOKUP($A15,[13]MVTRESUME25!$A$6:$AL$45,12,0) -> 1027000 | I15: =+D15+E15+F15+G15+H15 -> 1032255.3 | J15: =VLOOKUP($A15,[13]MVTRESUME25!$A$6:$AL$45,10,0) -> 0 | K15: 30000 | L15: 100000 | M15: =VLOOKUP($A15,[13]MVTRESUME25!$A$6:$AL$45,23,0) -> 0 | N15: =J15+K15+L15+M15 -> 130000 | O15: =I15-N15 -> 902255.34 | P15: =+T15 -> 60000 | Q15: =O15-P15-S15 -> 842255.34 | R15: =C15+L15+800000 -> 900000 | T15: 60000 | V15: 3119
A16: AS201611 | B16: =VLOOKUP(A16,[12]LISTADHERENT!$A$5:$K$43,3,0) -> HENGUE PAUL OMER | C16: =VLOOKUP($A16,[13]MVTRESUME25!$A$6:$AL$45,3,0) -> 800000 | D16: =VLOOKUP($A16,[13]MVTRESUME25!$A$6:$AL$45,4,0) -> 7143 | E16: =VLOOKUP($A16,[13]MVTRESUME25!$A$6:$AL$45,8,0) -> 68007.587 | F16: =VLOOKUP($A16,[13]MVTRESUME25!$A$6:$AL$45,12,0) -> 249000 | I16: =+D16+E16+F16+G16+H16 -> 324150.59 | J16: =VLOOKUP($A16,[13]MVTRESUME25!$A$6:$AL$45,10,0) -> 0 | K16: 30000 | L16: 100000 | M16: =VLOOKUP($A16,[13]MVTRESUME25!$A$6:$AL$45,23,0) -> 0 | N16: =J16+K16+L16+M16 -> 130000 | O16: =I16-N16 -> 194150.59 | P16: =+T16 -> 0 | Q16: =O16-P16-S16 -> 194150.59 | R16: =C16+L16 -> 900000 | V16: 67538
A17: AS201613 | B17: =VLOOKUP(A17,[12]LISTADHERENT!$A$5:$K$43,3,0) -> HOTCHO BENJAMIN | C17: =VLOOKUP($A17,[13]MVTRESUME25!$A$6:$AL$45,3,0) -> 800000 | D17: =VLOOKUP($A17,[13]MVTRESUME25!$A$6:$AL$45,4,0) -> 6301 | E17: =VLOOKUP($A17,[13]MVTRESUME25!$A$6:$AL$45,8,0) -> 71729.526 | F17: =VLOOKUP($A17,[13]MVTRESUME25!$A$6:$AL$45,12,0) -> 512500 | I17: =+D17+E17+F17+G17+H17 -> 590530.53 | J17: =VLOOKUP($A17,[13]MVTRESUME25!$A$6:$AL$45,10,0) -> 0 | K17: 30000 | L17: 100000 | M17: =VLOOKUP($A17,[13]MVTRESUME25!$A$6:$AL$45,23,0) -> 400000 | N17: =J17+K17+L17+M17 -> 530000 | O17: =I17-N17 -> 60530.526 | P17: =+T17 -> 150000 | Q17: =O17-P17-S17 -> -389469.47 | R17: =C17+L17 -> 900000 | S17: 300000 | T17: 150000 | V17: 71266
A18: AS201617 | B18: =VLOOKUP(A18,[12]LISTADHERENT!$A$5:$K$43,3,0) -> KOUAMOU MOISE | C18: =VLOOKUP($A18,[13]MVTRESUME25!$A$6:$AL$45,3,0) -> 800000 | D18: =VLOOKUP($A18,[13]MVTRESUME25!$A$6:$AL$45,4,0) -> 6353 | E18: =VLOOKUP($A18,[13]MVTRESUME25!$A$6:$AL$45,8,0) -> 67985.948 | F18: =VLOOKUP($A18,[13]MVTRESUME25!$A$6:$AL$45,12,0) -> 225000 | I18: =+D18+E18+F18+G18+H18 -> 299338.95 | J18: =VLOOKUP($A18,[13]MVTRESUME25!$A$6:$AL$45,10,0) -> 0 | K18: 30000 | L18: 100000 | M18: =VLOOKUP($A18,[13]MVTRESUME25!$A$6:$AL$45,23,0) -> 525000 | N18: =J18+K18+L18+M18 -> 655000 | O18: =I18-N18+500000 -> 144338.95 | P18: =+T18 -> 25000 | Q18: =O18-P18-S18 -> 119338.95 | R18: =C18+L18 -> 900000 | T18: 25000 | V18: 67588
A19: AS201619 | B19: =VLOOKUP(A19,[12]LISTADHERENT!$A$5:$K$43,3,0) -> KOUATCHO MESSACK | C19: =VLOOKUP($A19,[13]MVTRESUME25!$A$6:$AL$45,3,0) -> 800000 | D19: =VLOOKUP($A19,[13]MVTRESUME25!$A$6:$AL$45,4,0) -> 9944 | E19: =VLOOKUP($A19,[13]MVTRESUME25!$A$6:$AL$45,8,0) -> 69419.782 | F19: =VLOOKUP($A19,[13]MVTRESUME25!$A$6:$AL$45,12,0) -> 333500 | I19: =+D19+E19+F19+G19+H19 -> 412863.78 | J19: =VLOOKUP($A19,[13]MVTRESUME25!$A$6:$AL$45,10,0) -> 0 | K19: 30000 | L19: 100000 | M19: =VLOOKUP($A19,[13]MVTRESUME25!$A$6:$AL$45,23,0) -> 0 | N19: =J19+K19+L19+M19 -> 130000 | O19: =I19-N19 -> 282863.78 | P19: =+T19 -> 0 | Q19: =O19-P19-S19 -> 282863.78 | R19: =C19+L19 -> 900000 | V19: 68999
A20: AS201620 | B20: =VLOOKUP(A20,[12]LISTADHERENT!$A$5:$K$43,3,0) -> LOWE JEAN | C20: =VLOOKUP($A20,[13]MVTRESUME25!$A$6:$AL$45,3,0) -> 0 | D20: =VLOOKUP($A20,[13]MVTRESUME25!$A$6:$AL$45,4,0) -> 676217 | E20: =VLOOKUP($A20,[13]MVTRESUME25!$A$6:$AL$45,8,0)+7138 -> 7138 | F20: =VLOOKUP($A20,[13]MVTRESUME25!$A$6:$AL$45,12,0) -> 500000 | I20: =+D20+E20+F20+G20+H20 -> 1183355 | J20: =VLOOKUP($A20,[13]MVTRESUME25!$A$6:$AL$45,10,0) -> 0 | K20: =20000+30000 -> 50000 | L20: 100000 | M20: =VLOOKUP($A20,[13]MVTRESUME25!$A$6:$AL$45,23,0) -> 0 | N20: =J20+K20+L20+M20 -> 150000 | O20: =I20-N20 -> 1033355 | P20: =+T20 -> 0 | Q20: =O20-P20-S20-800000-70000 -> 163355 | R20: =C20+L20+800000 -> 900000 | V20: 7128
A21: AS201661 | B21: =VLOOKUP(A21,[12]LISTADHERENT!$A$5:$K$43,3,0) -> MASSEUNGOUE DAGOBERT | C21: =VLOOKUP($A21,[13]MVTRESUME25!$A$6:$AL$45,3,0) -> 0 | D21: =VLOOKUP($A21,[13]MVTRESUME25!$A$6:$AL$45,4,0) -> 198625 | E21: =VLOOKUP($A21,[13]MVTRESUME25!$A$6:$AL$45,8,0) -> 34069.066 | F21: =VLOOKUP($A21,[13]MVTRESUME25!$A$6:$AL$45,12,0) -> 1026625 | I21: =+D21+E21+F21+G21+H21 -> 1259319.1 | J21: =VLOOKUP($A21,[13]MVTRESUME25!$A$6:$AL$45,10,0) -> 0 | K21: 30000 | L21: 100000 | M21: =VLOOKUP($A21,[13]MVTRESUME25!$A$6:$AL$45,23,0) -> 0 | N21: =J21+K21+L21+M21 -> 130000 | O21: =I21-N21 -> 1129319.1 | P21: =+T21 -> 50000 | Q21: =O21-P21-S21 -> 1029319.1 | R21: =C21+L21+800000 -> 900000 | S21: 50000 | T21: 50000 | V21: 27363
A22: AS201649 | B22: =VLOOKUP(A22,[12]LISTADHERENT!$A$5:$K$43,3,0) -> MBOGNING TUGMA GUY | C22: =VLOOKUP($A22,[13]MVTRESUME25!$A$6:$AL$45,3,0) -> 800000 | D22: =VLOOKUP($A22,[13]MVTRESUME25!$A$6:$AL$45,4,0) -> 8501 | E22: =VLOOKUP($A22,[13]MVTRESUME25!$A$6:$AL$45,8,0) -> 68173.077 | F22: =VLOOKUP($A22,[13]MVTRESUME25!$A$6:$AL$45,12,0) -> 232900 | I22: =+D22+E22+F22+G22+H22 -> 309574.08 | J22: =VLOOKUP($A22,[13]MVTRESUME25!$A$6:$AL$45,10,0) -> 0 | K22: 30000 | L22: 100000 | M22: =VLOOKUP($A22,[13]MVTRESUME25!$A$6:$AL$45,23,0) -> 0 | N22: =J22+K22+L22+M22 -> 130000 | O22: =I22-N22 -> 179574.08 | P22: =+T22 -> 100000 | Q22: =O22-P22-S22 -> 29574.077 | R22: =C22+L22 -> 900000 | S22: 50000 | T22: 100000 | V22: 67774
A23: AS201639 | B23: =VLOOKUP(A23,[12]LISTADHERENT!$A$5:$K$43,3,0) -> NANGUEN MARTIN | C23: =VLOOKUP($A23,[13]MVTRESUME25!$A$6:$AL$45,3,0) -> 800000 | D23: =VLOOKUP($A23,[13]MVTRESUME25!$A$6:$AL$45,4,0) -> 7819 | E23: =VLOOKUP($A23,[13]MVTRESUME25!$A$6:$AL$45,8,0) -> 68105.834 | F23: =VLOOKUP($A23,[13]MVTRESUME25!$A$6:$AL$45,12,0) -> 228000 | I23: =+D23+E23+F23+G23+H23 -> 303924.83 | J23: =VLOOKUP($A23,[13]MVTRESUME25!$A$6:$AL$45,10,0) -> 0 | K23: 30000 | L23: 100000 | M23: =VLOOKUP($A23,[13]MVTRESUME25!$A$6:$AL$45,23,0) -> 0 | N23: =J23+K23+L23+M23 -> 130000 | O23: =I23-N23 -> 173924.83 | P23: =+T23 -> 100000 | Q23: =O23-P23-S23 -> 73924.834 | R23: =C23+L23 -> 900000 | T23: 100000 | V23: 67707
A24: AS201621 | B24: =VLOOKUP(A24,[12]LISTADHERENT!$A$5:$K$43,3,0) -> NANKAM APPOLINAIRE | C24: =VLOOKUP($A24,[13]MVTRESUME25!$A$6:$AL$45,3,0) -> 800000 | D24: =VLOOKUP($A24,[13]MVTRESUME25!$A$6:$AL$45,4,0) -> 249258 | E24: =VLOOKUP($A24,[13]MVTRESUME25!$A$6:$AL$45,8,0) -> 80837.304 | F24: =VLOOKUP($A24,[13]MVTRESUME25!$A$6:$AL$45,12,0) -> 686500 | I24: =+D24+E24+F24+G24+H24 -> 1016595.3 | J24: =VLOOKUP($A24,[13]MVTRESUME25!$A$6:$AL$45,10,0) -> 0 | K24: 30000 | L24: 100000 | M24: =VLOOKUP($A24,[13]MVTRESUME25!$A$6:$AL$45,23,0) -> 0 | N24: =J24+K24+L24+M24+900000 -> 1030000 | O24: =I24-N24 -> -13404.696 | P24: =+T24 -> 0 | Q24: =O24-P24-S24 -> -13404.696 | R24: =C24+L24 -> 900000 | V24: 94250
A25: AS201622 | B25: =VLOOKUP(A25,[12]LISTADHERENT!$A$5:$K$43,3,0) -> NDJOMO ETIENNE | C25: =VLOOKUP($A25,[13]MVTRESUME25!$A$6:$AL$45,3,0) -> 800000 | D25: =VLOOKUP($A25,[13]MVTRESUME25!$A$6:$AL$45,4,0) -> 256158 | E25: =VLOOKUP($A25,[13]MVTRESUME25!$A$6:$AL$45,8,0) -> 89546.252 | F25: =VLOOKUP($A25,[13]MVTRESUME25!$A$6:$AL$45,12,0) -> 348000 | I25: =+D25+E25+F25+G25+H25 -> 693704.25 | J25: =VLOOKUP($A25,[13]MVTRESUME25!$A$6:$AL$45,10,0) -> 0 | K25: 30000 | L25: 100000 | M25: =VLOOKUP($A25,[13]MVTRESUME25!$A$6:$AL$45,23,0) -> 0 | N25: =J25+K25+L25+M25 -> 130000 | O25: =I25-N25 -> 563704.25 | P25: =+T25 -> 300000 | Q25: =O25-P25-S25 -> 163704.25 | R25: =C25+L25 -> 900000 | S25: 100000 | T25: 300000 | V25: 89015
A26: AS201624 | B26: =VLOOKUP(A26,[12]LISTADHERENT!$A$5:$K$43,3,0) -> NGONDIEP CLAUDE | C26: =VLOOKUP($A26,[13]MVTRESUME25!$A$6:$AL$45,3,0) -> 800000 | D26: =VLOOKUP($A26,[13]MVTRESUME25!$A$6:$AL$45,4,0) -> 353356 | E26: =VLOOKUP($A26,[13]MVTRESUME25!$A$6:$AL$45,8,0) -> 98057.703 | F26: =VLOOKUP($A26,[13]MVTRESUME25!$A$6:$AL$45,12,0) -> 407000 | I26: =+D26+E26+F26+G26+H26 -> 858413.7 | J26: =VLOOKUP($A26,[13]MVTRESUME25!$A$6:$AL$45,10,0) -> 0 | K26: 30000 | L26: 100000 | M26: =VLOOKUP($A26,[13]MVTRESUME25!$A$6:$AL$45,23,0) -> 1000000 | N26: =J26+K26+L26+M26 -> 1130000 | O26: =I26-N26 -> -271586.3 | P26: =+T26 -> 25000 | Q26: =O26-P26-S26 -> -396586.3 | R26: =C26+L26 -> 900000 | S26: 100000 | T26: 25000 | V26: 97473
A27: AS201626 | B27: =VLOOKUP(A27,[12]LISTADHERENT!$A$5:$K$43,3,0) -> NGUIEMEGNI MATHIEU BLAISE | C27: =VLOOKUP($A27,[13]MVTRESUME25!$A$6:$AL$45,3,0) -> 800000 | D27: =VLOOKUP($A27,[13]MVTRESUME25!$A$6:$AL$45,4,0) -> 9175 | E27: =VLOOKUP($A27,[13]MVTRESUME25!$A$6:$AL$45,8,0) -> 68010.819 | F27: =VLOOKUP($A27,[13]MVTRESUME25!$A$6:$AL$45,12,0) -> 215000 | I27: =+D27+E27+F27+G27+H27 -> 292185.82 | J27: =VLOOKUP($A27,[13]MVTRESUME25!$A$6:$AL$45,10,0) -> 0 | K27: 30000 | L27: 100000 | M27: =VLOOKUP($A27,[13]MVTRESUME25!$A$6:$AL$45,23,0) -> 1050000 | N27: =J27+K27+L27+M27 -> 1180000 | O27: =I27-N27+1000000 -> 112185.82 | P27: =+T27 -> 90000 | Q27: =O27-P27-S27 -> -27814.181 | R27: =C27+L27 -> 900000 | S27: 50000 | T27: 90000 | V27: 67616
A28: AS201628 | B28: =VLOOKUP(A28,[12]LISTADHERENT!$A$5:$K$43,3,0) -> NKAMGANG JUSTIN DEJOLIE | C28: =VLOOKUP($A28,[13]MVTRESUME25!$A$6:$AL$45,3,0) -> 800000 | D28: =VLOOKUP($A28,[13]MVTRESUME25!$A$6:$AL$45,4,0) -> 10531 | E28: =VLOOKUP($A28,[13]MVTRESUME25!$A$6:$AL$45,8,0) -> 68521.197 | F28: =VLOOKUP($A28,[13]MVTRESUME25!$A$6:$AL$45,12,0) -> 235000 | I28: =+D28+E28+F28+G28+H28 -> 314052.2 | J28: =VLOOKUP($A28,[13]MVTRESUME25!$A$6:$AL$45,10,0) -> 0 | K28: 30000 | L28: 100000 | M28: =VLOOKUP($A28,[13]MVTRESUME25!$A$6:$AL$45,23,0) -> 0 | N28: =J28+K28+L28+M28 -> 130000 | O28: =I28-N28 -> 184052.2 | P28: =+T28 -> 130000 | Q28: =O28-P28-S28 -> 4052.1974 | R28: =C28+L28 -> 900000 | S28: 50000 | T28: 130000 | V28: 68118
A29: AS201656 | B29: =VLOOKUP(A29,[12]LISTADHERENT!$A$5:$K$43,3,0) -> NOUBE ETIENNE | C29: =VLOOKUP($A29,[13]MVTRESUME25!$A$6:$AL$45,3,0) -> 800000 | D29: =VLOOKUP($A29,[13]MVTRESUME25!$A$6:$AL$45,4,0) -> -17159 | E29: =VLOOKUP($A29,[13]MVTRESUME25!$A$6:$AL$45,8,0) -> 66071.087 | F29: =VLOOKUP($A29,[13]MVTRESUME25!$A$6:$AL$45,12,0) -> 228000 | I29: =+D29+E29+F29+G29+H29 -> 276912.09 | J29: =VLOOKUP($A29,[13]MVTRESUME25!$A$6:$AL$45,10,0) -> 0 | K29: 30000 | L29: 100000 | M29: =VLOOKUP($A29,[13]MVTRESUME25!$A$6:$AL$45,23,0) -> 0 | N29: =J29+K29+L29+M29 -> 130000 | O29: =I29-N29 -> 146912.09 | P29: =+T29 -> 70000 | Q29: =O29-P29-S29 -> 51912.087 | R29: =C29+L29 -> 900000 | S29: 25000 | T29: 70000 | V29: 65684
A30: AS201633 | B30: =VLOOKUP(A30,[12]LISTADHERENT!$A$5:$K$43,3,0) -> PATEGO NJOSSU GUSTAVE | C30: =VLOOKUP($A30,[13]MVTRESUME25!$A$6:$AL$45,3,0) -> 800000 | D30: =VLOOKUP($A30,[13]MVTRESUME25!$A$6:$AL$45,4,0) -> 133342 | E30: =VLOOKUP($A30,[13]MVTRESUME25!$A$6:$AL$45,8,0) -> 78331.133 | F30: =VLOOKUP($A30,[13]MVTRESUME25!$A$6:$AL$45,12,0) -> 228000 | I30: =+D30+E30+F30+G30+H30 -> 439673.13 | J30: =VLOOKUP($A30,[13]MVTRESUME25!$A$6:$AL$45,10,0) -> 0 | K30: 30000 | L30: 100000 | M30: =VLOOKUP($A30,[13]MVTRESUME25!$A$6:$AL$45,23,0) -> 0 | N30: =J30+K30+L30+M30 -> 130000 | O30: =I30-N30 -> 309673.13 | P30: =+T30 -> 0 | Q30: =O30-P30-S30 -> 9673.133 | R30: =C30+L30 -> 900000 | S30: 300000 | V30: 77878
A31: AS201657 | B31: =VLOOKUP(A31,[12]LISTADHERENT!$A$5:$K$43,3,0) -> SEUMO POLYCARPE | C31: =VLOOKUP($A31,[13]MVTRESUME25!$A$6:$AL$45,3,0) -> 800000 | D31: =VLOOKUP($A31,[13]MVTRESUME25!$A$6:$AL$45,4,0) -> -9977 | E31: =VLOOKUP($A31,[13]MVTRESUME25!$A$6:$AL$45,8,0) -> 66656.144 | F31: =VLOOKUP($A31,[13]MVTRESUME25!$A$6:$AL$45,12,0) -> 229000 | I31: =+D31+E31+F31+G31+H31 -> 285679.14 | J31: =VLOOKUP($A31,[13]MVTRESUME25!$A$6:$AL$45,10,0) -> 0 | K31: 30000 | L31: 100000 | M31: =VLOOKUP($A31,[13]MVTRESUME25!$A$6:$AL$45,23,0) -> 955000 | N31: =J31+K31+L31+M31 -> 1085000 | O31: =I31-N31+900000 -> 100679.14 | P31: =+T31 -> 30000 | Q31: =O31-P31-S31 -> 45679.144 | R31: =C31+L31 -> 900000 | S31: 25000 | T31: 30000 | V31: 66266
A32: AS201653 | B32: =VLOOKUP(A32,[12]LISTADHERENT!$A$5:$K$43,3,0) -> SIME BRICE | C32: =VLOOKUP($A32,[13]MVTRESUME25!$A$6:$AL$45,3,0) -> 800000 | D32: =VLOOKUP($A32,[13]MVTRESUME25!$A$6:$AL$45,4,0) -> 79106 | E32: =VLOOKUP($A32,[13]MVTRESUME25!$A$6:$AL$45,8,0) -> 73912.984 | F32: =VLOOKUP($A32,[13]MVTRESUME25!$A$6:$AL$45,12,0) -> 228000 | I32: =+D32+E32+F32+G32+H32 -> 381018.98 | J32: =VLOOKUP($A32,[13]MVTRESUME25!$A$6:$AL$45,10,0) -> 0 | K32: 30000 | L32: 100000 | M32: =VLOOKUP($A32,[13]MVTRESUME25!$A$6:$AL$45,23,0) -> 0 | N32: =J32+K32+L32+M32 -> 130000 | O32: =I32-N32 -> 251018.98 | P32: =+T32 -> 0 | Q32: =O32-P32-S32 -> 251018.98 | R32: =C32+L32 -> 900000 | V32: 73483
A33: AS201629 | B33: =VLOOKUP(A33,[12]LISTADHERENT!$A$5:$K$43,3,0) -> SIMO FONGANG ERIC | C33: =VLOOKUP($A33,[13]MVTRESUME25!$A$6:$AL$45,3,0) -> 0 | D33: =VLOOKUP($A33,[13]MVTRESUME25!$A$6:$AL$45,4,0) -> 153468 | E33: =VLOOKUP($A33,[13]MVTRESUME25!$A$6:$AL$45,8,0) -> 0 | F33: =VLOOKUP($A33,[13]MVTRESUME25!$A$6:$AL$45,12,0) -> 520500 | I33: =+D33+E33+F33+G33+H33 -> 673968 | J33: =VLOOKUP($A33,[13]MVTRESUME25!$A$6:$AL$45,10,0) -> 0 | M33: =VLOOKUP($A33,[13]MVTRESUME25!$A$6:$AL$45,23,0) -> 0 | N33: =J33+K33+L33+M33 -> 0 | O33: =I33-N33 -> 673968 | P33: =+T33 -> 0 | Q33: =O33-P33-S33 -> 673968 | R33: =C33+L33 -> 0 | V33: 0
A34: AS201638 | B34: =VLOOKUP(A34,[12]LISTADHERENT!$A$5:$K$43,3,0) -> SIMO PIERRE | C34: =VLOOKUP($A34,[13]MVTRESUME25!$A$6:$AL$45,3,0) -> 800000 | D34: =VLOOKUP($A34,[13]MVTRESUME25!$A$6:$AL$45,4,0) -> 46691 | E34: =VLOOKUP($A34,[13]MVTRESUME25!$A$6:$AL$45,8,0) -> 71169.79 | F34: =VLOOKUP($A34,[13]MVTRESUME25!$A$6:$AL$45,12,0) -> 215000 | I34: =+D34+E34+F34+G34+H34 -> 332860.79 | J34: =VLOOKUP($A34,[13]MVTRESUME25!$A$6:$AL$45,10,0) -> 0 | M34: 0 | N34: =J34+K34+L34+M34 -> 0 | O34: =I34-N34 -> 332860.79 | P34: =+T34 -> 0 | Q34: =O34-P34-S34 -> 332860.79 | R34: =C34+L34 -> 800000 | V34: 70753
A35: AS201641 | B35: =VLOOKUP(A35,[12]LISTADHERENT!$A$5:$K$43,3,0) -> TCHOUAMOU MATHIEU | C35: =VLOOKUP($A35,[13]MVTRESUME25!$A$6:$AL$45,3,0) -> 800000 | D35: =VLOOKUP($A35,[13]MVTRESUME25!$A$6:$AL$45,4,0) -> 6050 | E35: =VLOOKUP($A35,[13]MVTRESUME25!$A$6:$AL$45,8,0) -> 67961.728 | F35: =VLOOKUP($A35,[13]MVTRESUME25!$A$6:$AL$45,12,0) -> 228000 | I35: =+D35+E35+F35+G35+H35 -> 302011.73 | J35: =VLOOKUP($A35,[13]MVTRESUME25!$A$6:$AL$45,10,0) -> 0 | K35: 30000 | L35: 100000 | M35: 0 | N35: =J35+K35+L35+M35 -> 130000 | O35: =I35-N35 -> 172011.73 | P35: =+T35 -> 140000 | Q35: =O35-P35-S35 -> 7011.7282 | R35: =C35+L35 -> 900000 | S35: 25000 | T35: 140000 | V35: 67564
A36: AS201660 | B36: =VLOOKUP(A36,[12]LISTADHERENT!$A$5:$K$43,3,0) -> TCHOUATEU AUGUSTIN | C36: =VLOOKUP($A36,[13]MVTRESUME25!$A$6:$AL$45,3,0) -> 800000 | D36: =VLOOKUP($A36,[13]MVTRESUME25!$A$6:$AL$45,4,0) -> -3392 | E36: =VLOOKUP($A36,[13]MVTRESUME25!$A$6:$AL$45,8,0) -> 67192.568 | F36: =VLOOKUP($A36,[13]MVTRESUME25!$A$6:$AL$45,12,0) -> 228000 | I36: =+D36+E36+F36+G36+H36 -> 291800.57 | J36: =VLOOKUP($A36,[13]MVTRESUME25!$A$6:$AL$45,10,0) -> 0 | K36: 30000 | L36: 100000 | M36: =VLOOKUP($A36,[13]MVTRESUME25!$A$6:$AL$45,23,0) -> 0 | N36: =J36+K36+L36+M36 -> 130000 | O36: =I36-N36 -> 161800.57 | P36: =+T36 -> 160000 | Q36: =O36-P36-S36 -> 1800.5682 | R36: =C36+L36 -> 900000 | T36: 160000 | V36: 66799
A37: AS201643 | B37: =VLOOKUP(A37,[12]LISTADHERENT!$A$5:$K$43,3,0) -> TCHOUTOU NANA CLAUDE | C37: =VLOOKUP($A37,[13]MVTRESUME25!$A$6:$AL$45,3,0) -> 0 | D37: =VLOOKUP($A37,[13]MVTRESUME25!$A$6:$AL$45,4,0) -> 487750 | E37: =VLOOKUP($A37,[13]MVTRESUME25!$A$6:$AL$45,8,0) -> 0 | F37: =VLOOKUP($A37,[13]MVTRESUME25!$A$6:$AL$45,12,0) -> 442500 | I37: =+D37+E37+F37+G37+H37 -> 930250 | J37: =VLOOKUP($A37,[13]MVTRESUME25!$A$6:$AL$45,10,0) -> 0 | K37: 30000 | L37: 100000 | M37: =VLOOKUP($A37,[13]MVTRESUME25!$A$6:$AL$45,23,0) -> 0 | N37: =J37+K37+L37+M37 -> 130000 | O37: =I37-N37 -> 800250 | P37: =+T37 -> 0 | Q37: =O37-P37-S37 -> 800250 | R37: =C37+L37+800000 -> 900000 | V37: 0
A38: AS201662 | B38: =VLOOKUP(A38,[12]LISTADHERENT!$A$5:$K$43,3,0) -> TIEYAM ERNEST | C38: =VLOOKUP($A38,[13]MVTRESUME25!$A$6:$AL$45,3,0) -> 0 | D38: =VLOOKUP($A38,[13]MVTRESUME25!$A$6:$AL$45,4,0) -> 0 | E38: =VLOOKUP($A38,[13]MVTRESUME25!$A$6:$AL$45,8,0) -> 0 | F38: =VLOOKUP($A38,[13]MVTRESUME25!$A$6:$AL$45,12,0) -> 507500 | I38: =+D38+E38+F38+G38+H38 -> 507500 | J38: =VLOOKUP($A38,[13]MVTRESUME25!$A$6:$AL$45,10,0) -> 0 | M38: =VLOOKUP($A38,[13]MVTRESUME25!$A$6:$AL$45,23,0) -> 0 | N38: =J38+K38+L38+M38 -> 0 | O38: =I38-N38 -> 507500 | P38: =+T38 -> 0 | Q38: =O38-P38-S38 -> 507500 | R38: =C38+L38 -> 0 | V38: 0
A39: AS201658 | B39: =VLOOKUP(A39,[12]LISTADHERENT!$A$5:$K$43,3,0) -> YANTCHOU GERVAIS | C39: =VLOOKUP($A39,[13]MVTRESUME25!$A$6:$AL$45,3,0) -> 800000 | D39: =VLOOKUP($A39,[13]MVTRESUME25!$A$6:$AL$45,4,0) -> -32497 | E39: =VLOOKUP($A39,[13]MVTRESUME25!$A$6:$AL$45,8,0) -> 64954.757 | F39: =VLOOKUP($A39,[13]MVTRESUME25!$A$6:$AL$45,12,0) -> 238000 | I39: =+D39+E39+F39+G39+H39 -> 270457.76 | J39: =VLOOKUP($A39,[13]MVTRESUME25!$A$6:$AL$45,10,0) -> 0 | K39: 30000 | L39: 100000 | M39: =VLOOKUP($A39,[13]MVTRESUME25!$A$6:$AL$45,23,0) -> 0 | N39: =J39+K39+L39+M39 -> 130000 | O39: =I39-N39 -> 140457.76 | P39: =+T39 -> 50000 | Q39: =O39-P39-S39 -> 40457.757 | R39: =C39+L39 -> 900000 | S39: 50000 | T39: 50000 | V39: 64571
A40: AS201646 | B40: =VLOOKUP(A40,[12]LISTADHERENT!$A$5:$K$43,3,0) -> YEPMOU JEAN JACQUES | C40: =VLOOKUP($A40,[13]MVTRESUME25!$A$6:$AL$45,3,0) -> 800000 | D40: =VLOOKUP($A40,[13]MVTRESUME25!$A$6:$AL$45,4,0) -> 739643 | E40: =VLOOKUP($A40,[13]MVTRESUME25!$A$6:$AL$45,8,0) -> 127622.79 | F40: =VLOOKUP($A40,[13]MVTRESUME25!$A$6:$AL$45,12,0) -> 219000 | I40: =+D40+E40+F40+G40+H40 -> 1086265.8 | J40: =VLOOKUP($A40,[13]MVTRESUME25!$A$6:$AL$45,10,0) -> 0 | K40: 30000 | L40: 100000 | M40: =VLOOKUP($A40,[13]MVTRESUME25!$A$6:$AL$45,23,0) -> 0 | N40: =J40+K40+L40+M40 -> 130000 | O40: =I40-N40 -> 956265.79 | P40: =+T40 -> 0 | Q40: =O40-P40-S40 -> 956265.79 | R40: =C40+L40 -> 900000 | V40: 126907
A41: AS201659 | B41: =VLOOKUP(A41,[12]LISTADHERENT!$A$5:$K$43,3,0) -> YIALA ALAIN OSCAR | C41: =VLOOKUP($A41,[13]MVTRESUME25!$A$6:$AL$45,3,0) -> 800000 | D41: =VLOOKUP($A41,[13]MVTRESUME25!$A$6:$AL$45,4,0) -> 241 | E41: =VLOOKUP($A41,[13]MVTRESUME25!$A$6:$AL$45,8,0) -> 67488.518 | F41: =VLOOKUP($A41,[13]MVTRESUME25!$A$6:$AL$45,12,0) -> 228000 | I41: =+D41+E41+F41+G41+H41 -> 295729.52 | J41: =VLOOKUP($A41,[13]MVTRESUME25!$A$6:$AL$45,10,0) -> 0 | K41: 30000 | L41: 100000 | M41: =VLOOKUP($A41,[13]MVTRESUME25!$A$6:$AL$45,23,0) -> 0 | N41: =J41+K41+L41+M41 -> 130000 | O41: =I41-N41 -> 165729.52 | P41: =+T41 -> 70000 | Q41: =O41-P41-S41 -> -4270.482 | R41: =C41+L41 -> 900000 | S41: 100000 | T41: 70000 | V41: 67093
A42: AS201647 | B42: =VLOOKUP(A42,[12]LISTADHERENT!$A$5:$K$43,3,0) -> YOUMBI EMMANUEL | C42: =VLOOKUP($A42,[13]MVTRESUME25!$A$6:$AL$45,3,0) -> 800000 | D42: =VLOOKUP($A42,[13]MVTRESUME25!$A$6:$AL$45,4,0) -> 1296586 | E42: =VLOOKUP($A42,[13]MVTRESUME25!$A$6:$AL$45,8,0) -> 170658.37 | F42: =VLOOKUP($A42,[13]MVTRESUME25!$A$6:$AL$45,12,0) -> 228000 | I42: =+D42+E42+F42+G42+H42 -> 1695244.4 | J42: =VLOOKUP($A42,[13]MVTRESUME25!$A$6:$AL$45,10,0) -> 0 | K42: 30000 | L42: 100000 | M42: =VLOOKUP($A42,[13]MVTRESUME25!$A$6:$AL$45,23,0) -> 0 | N42: =J42+K42+L42+M42 -> 130000 | O42: =I42-N42 -> 1565244.4 | P42: =+T42 -> 0 | Q42: =O42-P42-S42 -> 1565244.4 | R42: =C42+L42 -> 900000 | V42: 172130
...

Sheet BILAN 2024
B1: ASELBY
B2: ANNEE | C2: 2024
B3: SYNTHESE DES COMPTES
A6: NUMERO ORDRE | B6: RUBRIQUE | C6: REPORT A NOUVEAU | D6: ENTREES | E6: SORTIES | F6: SOLDE
A8: ='BILAN 2024'!A8 -> 1 | B8: ='BILAN 2024'!B8 -> FONDS DE CAISSE ET RECONDUCTION | C8: =SYNTHESECOMPTE!C5 -> 30596797 | D8: =800000*6+100000*24 -> 7200000 | E8: =7077869-6896797 -> 181072 | F8: =C8+D8-E8 -> 37615725
A9: ='BILAN 2024'!A9 -> 2 | B9: ='BILAN 2024'!B9 -> FONDS DE ROULEMENT | C9: =SYNTHESECOMPTE!C6 -> 2293228 | D9: ='BILAN 2024'!D9 -> 384000 | E9: ='BILAN 2024'!E9 -> 251000 | F9: =C9+D9-E9 -> 2293228
A10: ='BILAN 2024'!A10 -> 3 | B10: ='BILAN 2024'!B10 -> FRAIS EXCEPTIONNELS | C10: =SYNTHESECOMPTE!C7 -> 462960 | D10: ='BILAN 2024'!D10 -> 384000 | E10: ='BILAN 2024'!E10 -> 0 | F10: =C10+D10-E10 -> 1422460
A11: ='BILAN 2024'!A11 -> 4 | B11: ='BILAN 2024'!B11 -> MUTUELLE\COMPLEMENT MUTUEL | C11: =SYNTHESECOMPTE!C8 -> 1654762 | D11: ='BILAN 2024'!D11 -> 240000 | E11: ='BILAN 2024'!E11 -> 200000 | F11: =C11+D11-E11 -> 854762
A12: ='BILAN 2024'!A12 -> 5 | B12: ='BILAN 2024'!B12 -> INSCRIPTION | C12: =SYNTHESECOMPTE!C9 -> 830000 | D12: ='BILAN 2024'!D12 -> 75000 | E12: ='BILAN 2024'!E12 -> 0 | F12: =C12+D12-E12 -> 830000
A13: ='BILAN 2024'!A13 -> 6 | B13: ='BILAN 2024'!B13 -> PENALITES PAIEMENT ESPECES | C13: =SYNTHESECOMPTE!C10 -> 940025 | D13: ='BILAN 2024'!D13 -> 93000 | E13: ='BILAN 2024'!E13 -> 0 | F13: =C13+D13-E13 -> 940025
A14: ='BILAN 2024'!A14 -> 7 | B14: SANCTION | C14: =SYNTHESECOMPTE!C11 -> 10750 | D14: ='BILAN 2024'!D14 -> 3750 | E14: ='BILAN 2024'!E14 -> 0 | F14: =C14+D14-E14 -> 10750
A15: ='BILAN 2024'!A15 -> 8 | B15: ='BILAN 2024'!B15 -> COLLATION | C15: =SYNTHESECOMPTE!C12 -> 1962525 | D15: ='BILAN 2024'!D15 -> 1536000 | E15: ='BILAN 2024'!E15 -> 1200000 | F15: =C15+D15-E15 -> 1968525
A16: ='BILAN 2024'!A16 -> 9 | B16: INTERET COMPTE AFRILAND | C16: =SYNTHESECOMPTE!C13 -> 135828 | D16: 11701 | F16: =C16+D16-E16 -> 147529
A17: ='BILAN 2024'!A17 -> 10 | B17: ='[16]BILAN 2024'!B18 -> FOYER | C17: =SYNTHESECOMPTE!C14 -> 371000 | D17: ='BILAN 2024'!D18 -> 0 | E17: ='BILAN 2024'!E18 -> 0 | F17: =C17+D17-E17 -> 371000
A18: ='BILAN 2024'!A18 -> 11 | B18: ='[16]BILAN 2024'!B23 -> INTERETS ET AUTRES | C18: =SYNTHESECOMPTE!C17 -> 0 | D18: ='BILAN 2024'!D23 -> 0 | E18: ='BILAN 2024'!E23 -> 0 | F18: =C18+D18-E18 -> 0
A19: 12 | B19: TERRAIN | C19: =SYNTHESECOMPTE!C15 -> -15300000 | E19: 9300000 | F19: =C19+D19-E19 -> -24600000
B27: TOTAL | C27: =SUM(C8:C26) -> 23957875 | D27: =SUM(D8:D26) -> 0
B29: DISPOSITION DES FONDS
C32: 2023 | D32: 2024
A33: 1 | B33: COMPTE CCA AU 30/12/2022 | C33: 4337431
A34: 2 | B34: COMPTE MC²(NON ACTUALISE) | C34: 630005 | D34: =C34+10000 -> 640005
A35: 3 | B35: COMPTE AFRILAND | C35: 1423702 | D35: 5265069
A36: 4 | B36: DETTE PREFINANCEMENT LA'AGWEU | C36: 744700
A37: 5 | B37: DETTE MR KOUATCHO | C37: 0
A38: 6 | B38: RESTE A RECUPERE AU CONSEIL | C38: 154000
A39: 7 | B39: FONDS EN CIRCULATION | C39: 18658500 | D39: ='DETAIL PRETENCIRCULATION'!C46+'DETAIL PRETENCIRCULATION'!C56 -> 19060901
A40: 8 | B40: DETTES TONTINES | C40: 656618
B42: TOTAL | C42: =SUM(C33:C41) -> 26604956 | D42: =SUM(D33:D41) -> 24965975

Sheet BILAN 2025
B1: ASELBY
B2: ANNEE | C2: 2025
B3: SYNTHESE DES COMPTES
A6: NUMERO ORDRE | B6: RUBRIQUE | C6: REPORT A NOUVEAU | D6: ENTREES | E6: SORTIES | F6: SOLDE
A8: ='BILAN 2025'!A8 -> 1 | B8: ='BILAN 2025'!B8 -> FONDS DE CAISSE ET RECONDUCTION | C8: =SYNTHESECOMPTE!C5 -> 30596797 | D8: =DETAILFICHECASSATION!C44+DETAILFICHECASSATION!D44 -> 30596797 | E8: =7077869-6896797 -> 181072 | F8: =C8+D8-E8 -> 61012522
A9: ='BILAN 2025'!A9 -> 2 | B9: ='BILAN 2025'!B9 -> FONDS DE ROULEMENT | C9: =SYNTHESECOMPTE!C6 -> 2293228 | D9: ='BILAN 2025'!D9 -> 384000 | E9: ='BILAN 2025'!E9 -> 251000 | F9: =C9+D9-E9 -> 2293228
A10: ='BILAN 2025'!A10 -> 3 | B10: ='BILAN 2025'!B10 -> FRAIS EXCEPTIONNELS | C10: =SYNTHESECOMPTE!C7 -> 462960 | D10: ='BILAN 2025'!D10 -> 384000 | E10: ='BILAN 2025'!E10 -> 0 | F10: =C10+D10-E10 -> 1422460
A11: ='BILAN 2025'!A11 -> 4 | B11: ='BILAN 2025'!B11 -> MUTUELLE\COMPLEMENT MUTUEL | C11: =SYNTHESECOMPTE!C8 -> 1654762 | D11: ='BILAN 2025'!D11 -> 240000 | E11: ='BILAN 2025'!E11 -> 200000 | F11: =C11+D11-E11 -> 854762
A12: ='BILAN 2025'!A12 -> 5 | B12: ='BILAN 2025'!B12 -> INSCRIPTION | C12: =SYNTHESECOMPTE!C9 -> 830000 | D12: ='BILAN 2025'!D12 -> 75000 | E12: ='BILAN 2025'!E12 -> 0 | F12: =C12+D12-E12 -> 830000
A13: ='BILAN 2025'!A13 -> 6 | B13: ='BILAN 2025'!B13 -> PENALITES PAIEMENT ESPECES | C13: =SYNTHESECOMPTE!C10 -> 940025 | D13: ='BILAN 2025'!D13 -> 93000 | E13: ='BILAN 2025'!E13 -> 0 | F13: =C13+D13-E13 -> 940025
A14: ='BILAN 2025'!A14 -> 7 | B14: SANCTION | C14: =SYNTHESECOMPTE!C11 -> 10750 | D14: ='BILAN 2025'!D14 -> 3750 | E14: ='BILAN 2025'!E14 -> 0 | F14: =C14+D14-E14 -> 10750
A15: ='BILAN 2025'!A15 -> 8 | B15: ='BILAN 2025'!B15 -> COLLATION | C15: =SYNTHESECOMPTE!C12 -> 1962525 | D15: ='BILAN 2025'!D15 -> 1536000 | E15: ='BILAN 2025'!E15 -> 1200000 | F15: =C15+D15-E15 -> 1968525
A16: ='BILAN 2025'!A16 -> 9 | B16: INTERET COMPTE AFRILAND | C16: =SYNTHESECOMPTE!C13 -> 135828 | D16: 11701 | F16: =C16+D16-E16 -> 147529
A17: ='BILAN 2025'!A17 -> 10 | B17: ='[16]BILAN 2024'!B18 -> FOYER | C17: =SYNTHESECOMPTE!C14 -> 371000 | D17: ='BILAN 2025'!D18 -> 0 | E17: ='BILAN 2025'!E18 -> 0 | F17: =C17+D17-E17 -> 371000
A18: ='BILAN 2025'!A18 -> 11 | B18: ='[16]BILAN 2024'!B23 -> INTERETS ET AUTRES | C18: =SYNTHESECOMPTE!C17 -> 0 | D18: ='BILAN 2025'!D23 -> 0 | E18: ='BILAN 2025'!E23 -> 0 | F18: =C18+D18-E18 -> 0
A19: 12 | B19: TERRAIN | C19: =SYNTHESECOMPTE!C15 -> -15300000 | E19: 9300000 | F19: =C19+D19-E19 -> -24600000
B27: TOTAL | C27: =SUM(C8:C26) -> 23957875 | D27: =SUM(D8:D26) -> #N/A
B29: DISPOSITION DES FONDS
C32: 2023 | D32: 2024
A33: 1 | B33: COMPTE CCA AU 30/12/2022 | C33: 4337431
A34: 2 | B34: COMPTE MC²(NON ACTUALISE) | C34: 630005 | D34: =C34+10000 -> 640005
A35: 3 | B35: COMPTE AFRILAND | C35: 1423702 | D35: 5265069
A36: 4 | B36: DETTE PREFINANCEMENT LA'AGWEU | C36: 744700
A37: 5 | B37: DETTE MR KOUATCHO | C37: 0
A38: 6 | B38: RESTE A RECUPERE AU CONSEIL | C38: 154000
A39: 7 | B39: FONDS EN CIRCULATION | C39: 18658500 | D39: ='DETAIL PRETENCIRCULATION'!C46+'DETAIL PRETENCIRCULATION'!C56 -> 19060901
A40: 8 | B40: DETTES TONTINES | C40: 656618
B42: TOTAL | C42: =SUM(C33:C41) -> 26604956 | D42: =SUM(D33:D41) -> 24965975

Sheet ENTREE
D2: ENTREE DES DIFFERENTES RUBRIQUES
A3: ANNEE | E3: 2024
A6: MOIS | B6: FONDS DE CAISSE | C6: RELIQUAT | D6: INTERET | E6: EPARGNE | F6: FONDS DE ROULEMENT | G6: FRAIS EXCEPTIONNEL | H6: COLLATION | I6: PENALITE VST ESPECES | J6: INSCRIPTION | K6: MUTUELLE | L6: REMBOURSEMENT | M6: SANCTION | N6: FOYER | O6: INTERET TONTINE | P6: TOTAL
A7: REPORT | B7: =[17]MVTRESUME24!#REF! -> #REF! | C7: =[17]MVTRESUME24!#REF! -> #REF! | D7: =[17]MVTDEC23!$T$41 -> 1168000
A8: JANVIER | D8: =#REF! -> #REF! | E8: =#REF! -> #REF! | F8: =#REF! -> #REF! | G8: =#REF! -> #REF! | H8: =#REF! -> #REF! | I8: =#REF! -> #REF! | J8: =#REF! -> #REF! | K8: =#REF! -> #REF! | ... N8: =#REF! -> #REF! | P8: =SUM(B8:O8) -> #REF!
A9: FÉVRIER | D9: =[17]MVTFEV24!$T$41 -> 26000 | E9: =[17]MVTFEV24!$L$41 -> 720000 | F9: =[17]MVTFEV24!$M$41 -> 32000 | G9: =[17]MVTFEV24!$N$41 -> 32000 | H9: =[17]MVTFEV24!$O$41 -> 128000 | I9: =[17]MVTFEV24!$P$41 -> 9000 | J9: =[17]MVTFEV24!$Q$41 -> 0 | K9: =[17]MVTFEV24!$R$41 -> 0 | L9: =[17]MVTFEV24!$V$41 -> 1000000 | M9: =[17]MVTFEV24!$J$41 -> 0 | N9: =[17]MVTFEV24!$AE$41 -> 0 | P9: =SUM(B9:O9) -> 1947000
A10: MARS | D10: =[17]MVTMARS24!$T$41 -> 92500 | E10: =[17]MVTMARS24!$L$41 -> 759000 | F10: =[17]MVTMARS24!$M$41 -> 32000 | G10: =[17]MVTMARS24!$N$41 -> 32000 | H10: =[17]MVTMARS24!$O$41 -> 128000 | I10: =[17]MVTMARS24!$P$41 -> 6000 | J10: =[17]MVTMARS24!$Q$41 -> 0 | K10: =[17]MVTMARS24!$R$41 -> 0 | L10: =[17]MVTMARS24!$V$41 -> 750000 | M10: =[17]MVTMARS24!$J$41 -> 0 | N10: =[17]MVTMARS24!$AE$41 -> 0 | P10: =SUM(B10:O10) -> 1799500
A11: AVRIL | D11: =[17]MVTAVRIL24!$T$41 -> 0 | E11: =[17]MVTAVRIL24!$L$41 -> 778500 | F11: =[17]MVTAVRIL24!$M$41 -> 32000 | G11: =[17]MVTAVRIL24!$N$41 -> 32000 | H11: =[17]MVTAVRIL24!$O$41 -> 128000 | I11: =[17]MVTAVRIL24!$P$41 -> 12000 | J11: =[17]MVTAVRIL24!$Q$41 -> 0 | K11: =[17]MVTAVRIL24!$R$41 -> 0 | L11: =[17]MVTAVRIL24!$V$41 -> 0 | M11: =[17]MVTAVRIL24!$J$41 -> 0 | N11: =[17]MVTAVRIL24!$AE$41 -> 0 | P11: =SUM(B11:O11) -> 982500
A12: MAI | D12: =[17]MVTMAI24!$T$41 -> 84000 | E12: =[17]MVTMAI24!$L$41 -> 725000 | F12: =[17]MVTMAI24!$M$41 -> 32000 | G12: =[17]MVTMAI24!$N$41 -> 32000 | H12: =[17]MVTMAI24!$O$41 -> 128000 | I12: =[17]MVTMAI24!$P$41 -> 9000 | J12: =[17]MVTMAI24!$Q$41 -> 0 | K12: =[17]MVTMAI24!$R$41 -> 0 | L12: =[17]MVTMAI24!$V$41 -> 1500000 | M12: =[17]MVTMAI24!$J$41 -> 0 | N12: =[17]MVTMAI24!$AE$41 -> 0 | P12: =SUM(B12:O12) -> 2510000
A13: JUIN | D13: =[17]MVTJUIN24!$T$41 -> 110000 | E13: =[17]MVTJUIN24!$L$41 -> 724500 | F13: =[17]MVTJUIN24!$M$41 -> 32000 | G13: =[17]MVTJUIN24!$N$41 -> 32000 | H13: =[17]MVTJUIN24!$O$41 -> 128000 | I13: =[17]MVTJUIN24!$P$41 -> 6000 | J13: =[17]MVTJUIN24!$Q$41 -> 0 | K13: =[17]MVTJUIN24!$R$41 -> 0 | L13: =[17]MVTJUIN24!$V$41 -> 360000 | M13: =[17]MVTJUIN24!$J$41 -> 0 | N13: =[17]MVTJUIN24!$AE$41 -> 0 | P13: =SUM(B13:O13) -> 1392500
A14: JUILLET | D14: =[17]MVTJUIL24!$T$41 -> 128400 | E14: =[17]MVTJUIL24!$L$41 -> 1698100 | F14: =[17]MVTJUIL24!$M$41 -> 32000 | G14: =[17]MVTJUIL24!$N$41 -> 32000 | H14: =[17]MVTJUIL24!$O$41 -> 128000 | I14: =[17]MVTJUIL24!$P$41 -> 12000 | J14: =[17]MVTJUIL24!$Q$41 -> 0 | K14: =[17]MVTJUIL24!$R$41 -> 0 | L14: =[17]MVTJUIL24!$V$41 -> 1738500 | M14: =[17]MVTJUIL24!$J$41 -> 0 | N14: =[17]MVTJUIL24!$AE$41 -> 0 | P14: =SUM(B14:O14) -> 3769000
A15: AOÛT | D15: =[17]MVTAOUT24!$T$41 -> 20000 | E15: =[17]MVTAOUT24!$L$41 -> 658500 | F15: =[17]MVTAOUT24!$M$41 -> 31000 | G15: =[17]MVTAOUT24!$N$41 -> 31000 | H15: =[17]MVTAOUT24!$O$41 -> 124000 | I15: =[17]MVTAOUT24!$P$41 -> 3000 | J15: =[17]MVTAOUT24!$Q$41 -> 0 | K15: =[17]MVTAOUT24!$R$41 -> 0 | L15: =[17]MVTAOUT24!$V$41 -> 0 | M15: =[17]MVTAOUT24!$J$41 -> 0 | N15: =[17]MVTAOUT24!$AE$41 -> 0 | P15: =SUM(B15:O15) -> 867500
A16: SEPTEMBRE | D16: =[17]MVTSEPT24!$T$41 -> 20000 | E16: =[17]MVTSEPT24!$L$41 -> 1585250 | F16: =[17]MVTSEPT24!$M$41 -> 33000 | G16: =[17]MVTSEPT24!$N$41 -> 33000 | H16: =[17]MVTSEPT24!$O$41 -> 132000 | I16: =[17]MVTSEPT24!$P$41 -> 18000 | J16: =[17]MVTSEPT24!$Q$41 -> 0 | K16: =[17]MVTSEPT24!$R$41 -> 120000 | L16: =[17]MVTSEPT24!$V$41 -> 0 | M16: =[17]MVTSEPT24!$J$41 -> 0 | N16: =[17]MVTSEPT24!$AE$41 -> 380000 | P16: =SUM(B16:O16) -> 2321250
A17: OCTOBRE | D17: =[17]MVTOCT24!$T$41 -> 0 | E17: =[17]MVTOCT24!$L$41 -> 734000 | F17: =[17]MVTOCT24!$M$41 -> 32000 | G17: =[17]MVTOCT24!$N$41 -> 32000 | H17: =[17]MVTOCT24!$O$41 -> 128000 | I17: =[17]MVTOCT24!$P$41 -> 6000 | J17: =[17]MVTOCT24!$Q$41 -> 0 | K17: =[17]MVTOCT24!$R$41 -> 0 | L17: =[17]MVTOCT24!$V$41 -> 100000 | M17: =[17]MVTOCT24!$J$41 -> 0 | N17: =[17]MVTOCT24!$AE$41 -> 20000 | P17: =SUM(B17:O17) -> 1052000
A18: NOVEMBRE | D18: =[17]MVTNOV24!$T$41 -> 10000 | E18: =[17]MVTNOV24!$L$41 -> 678500 | F18: =[17]MVTNOV24!$M$41 -> 32000 | G18: =[17]MVTNOV24!$N$41 -> 32000 | H18: =[17]MVTNOV24!$O$41 -> 128000 | I18: =[17]MVTNOV24!$P$41 -> 15000 | J18: =[17]MVTNOV24!$Q$41 -> 0 | K18: =[17]MVTNOV24!$R$41 -> 0 | L18: =[17]MVTNOV24!$V$41 -> 1190000 | M18: =[17]MVTNOV24!$J$41 -> 0 | N18: =[17]MVTNOV24!$AE$41 -> 0 | P18: =SUM(B18:O18) -> 2085500
A19: DÉCEMBRE | D19: =[17]MVTDEC24!$T$41 -> 147250 | E19: =[17]MVTDEC24!$L$41 -> 1337500 | F19: =[17]MVTDEC24!$M$41 -> 32000 | G19: =[17]MVTDEC24!$N$41 -> 32000 | H19: =[17]MVTDEC24!$O$41 -> 128000 | I19: =[17]MVTDEC24!$P$41 -> 0 | J19: =[17]MVTDEC24!$Q$41 -> 0 | K19: =[17]MVTDEC24!$R$41 -> 0 | L19: =[17]MVTDEC24!$V$41 -> 11817500 | M19: =[17]MVTDEC24!$J$41 -> 0 | N19: =[17]MVTDEC24!$AE$41 -> 371700 | O19: =[18]TONTRESUME23!$S$6+[19]TONTRESUME23!$S$6 -> 63707.983 | P19: =SUM(B19:O19) -> 13929658
A21: TOTAL | B21: =SUM(B8:B20) -> 0 | C21: =SUM(C8:C20) -> 0 | D21: =SUM(D7:D20) -> #REF! | E21: =SUM(E8:E20) -> #REF! | F21: =SUM(F8:F20) -> #REF! | G21: =SUM(G8:G20) -> #REF! | H21: =SUM(H8:H20) -> #REF! | I21: =SUM(I8:I20) -> #REF! | J21: =SUM(J8:J20) -> #REF! | K21: =SUM(K8:K20) -> #REF! | L21: =SUM(L8:L20) -> #REF! | ... P21: =SUM(P8:P20) -> #REF!

Sheet SORTIE
C2: SORTIE DES DIFFERENTES RUBRIQUES
A3: ANNEE | B3: 2023-2024
A6: MOIS | B6: FONDS DE CAISSE | C6: EPARGNE | D6: FONDS DE ROULEMENT | E6: FRAIS EXCEPTIONNEL | F6: COLLATION | G6: PENALITE VST ESPECES | H6: INSCRIPTION | I6: MUTUELLE | J6: PRÊT | K6: PENALITE | L6: FOYER | M6: TOTAL
A7: REPORT | J7: =[17]MVTDEC23!$S$41 -> 15088500
A8: JANVIER | D8: =#REF! -> #REF! | E8: =#REF! -> #REF! | F8: =#REF! -> #REF! | G8: =#REF! -> #REF! | I8: =#REF! -> #REF! | J8: =#REF! -> #REF! | M8: =SUM(C8:K8) -> #REF!
A9: FÉVRIER | D9: =[17]MVTFEV24!$AF$41 -> 27000 | E9: =[17]MVTFEV24!$AG$41 -> 0 | F9: =[17]MVTFEV24!$AI$41 -> 100000 | G9: =[17]MVTFEV24!$AA$41 -> 0 | I9: =[17]MVTFEV24!$AH$41 -> 100000 | J9: =[17]MVTFEV24!$V$41 -> 1000000 | M9: =SUM(C9:K9) -> 1227000
A10: MARS | D10: =[17]MVTMARS24!$AF$41 -> 48000 | E10: =[17]MVTMARS24!$AG$41 -> 0 | F10: =[17]MVTMARS24!$AI$41 -> 100000 | G10: =[17]MVTMARS24!$AA$41 -> 0 | I10: =[17]MVTMARS24!$AH$41 -> 0 | J10: =[17]MVTMARS24!$V$41 -> 750000 | M10: =SUM(C10:K10) -> 898000
A11: AVRIL | D11: =[17]MVTAVRIL24!$AF$41 -> 21000 | E11: =[17]MVTAVRIL24!$AG$41 -> 100000 | F11: =[17]MVTAVRIL24!$AI$41 -> 100000 | G11: =[17]MVTAVRIL24!$AA$41 -> 0 | I11: =[17]MVTAVRIL24!$AH$41 -> 0 | J11: =[17]MVTAVRIL24!$V$41 -> 0 | M11: =SUM(C11:K11) -> 221000
A12: MAI | D12: =[17]MVTMAI24!$AF$41 -> 19000 | E12: =[17]MVTMAI24!$AG$41 -> 0 | F12: =[17]MVTMAI24!$AI$41 -> 100000 | G12: =[17]MVTMAI24!$AA$41 -> 0 | I12: =[17]MVTMAI24!$AH$41 -> 0 | J12: =[17]MVTMAI24!$V$41 -> 1500000 | M12: =SUM(C12:K12) -> 1619000
A13: JUIN | D13: =[17]MVTJUIN24!$AF$41 -> 12000 | E13: =[17]MVTJUIN24!$AG$41 -> 0 | F13: =[17]MVTJUIN24!$AI$41 -> 100000 | G13: =[17]MVTJUIN24!$AA$41 -> 0 | I13: =[17]MVTJUIN24!$AH$41 -> 0 | J13: =[17]MVTJUIN24!$V$41 -> 360000 | M13: =SUM(C13:K13) -> 472000
A14: JUILLET | D14: =[17]MVTJUIL24!$AF$41 -> 42000 | E14: =[17]MVTJUIL24!$AG$41 -> 288500 | F14: =[17]MVTJUIL24!$AI$41 -> 100000 | G14: =[17]MVTJUIL24!$AA$41 -> 0 | I14: =[17]MVTJUIL24!$AH$41 -> 0 | J14: =[17]MVTJUIL24!$V$41 -> 1738500 | M14: =SUM(C14:K14) -> 2169000
A15: AOÛT | D15: =[17]MVTAOUT24!$AF$41 -> 6000 | E15: =[17]MVTAOUT24!$AG$41 -> 0 | F15: =[17]MVTAOUT24!$AI$41 -> 100000 | G15: =[17]MVTAOUT24!$AA$41 -> 0 | I15: =[17]MVTAOUT24!$AH$41 -> 0 | J15: =[17]MVTAOUT24!$V$41 -> 0 | M15: =SUM(C15:K15) -> 106000
A16: SEPTEMBRE | D16: =[17]MVTSEPT24!$AF$41 -> 6000 | E16: =[17]MVTSEPT24!$AG$41 -> 0 | F16: =[17]MVTSEPT24!$AI$41 -> 100000 | G16: =[17]MVTSEPT24!$AA$41 -> 0 | I16: =[17]MVTSEPT24!$AH$41 -> 0 | J16: =[17]MVTSEPT24!$V$41 -> 0 | M16: =SUM(C16:K16) -> 106000
A17: OCTOBRE | D17: =[17]MVTOCT24!$AF$41 -> 6000 | E17: =[17]MVTOCT24!$AG$41 -> 321500 | F17: =[17]MVTOCT24!$AI$41 -> 100000 | G17: =[17]MVTOCT24!$AA$41 -> 0 | I17: =[17]MVTOCT24!$AH$41 -> 0 | J17: =[17]MVTOCT24!$V$41 -> 100000 | M17: =SUM(C17:K17) -> 527500
A18: NOVEMBRE | D18: =[17]MVTNOV24!$AF$41 -> 6000 | E18: =[17]MVTNOV24!$AG$41 -> 50000 | F18: =[17]MVTNOV24!$AI$41 -> 106000 | G18: =[17]MVTNOV24!$AA$41 -> 0 | I18: =[17]MVTNOV24!$AH$41 -> 100000 | J18: =[17]MVTNOV24!$V$41 -> 1190000 | M18: =SUM(C18:K18) -> 1452000
A19: DÉCEMBRE | D19: =[17]MVTDEC24!$AF$41 -> 31000 | E19: =[17]MVTDEC24!$AG$41 -> 0 | F19: =[17]MVTDEC24!$AI$41 -> 100000 | G19: =[17]MVTDEC24!$AA$41 -> 0 | I19: =[17]MVTDEC24!$AH$41 -> 0 | J19: =[17]MVTDEC24!$V$41 -> 11817500 | M19: =SUM(C19:K19) -> 11948500
A22: TOTAL | B22: =SUM(B8:B21) -> 0 | C22: =SUM(C8:C21) -> 0 | D22: =SUM(D8:D21) -> #REF! | E22: =SUM(E8:E21) -> #REF! | F22: =SUM(F8:F21) -> #REF! | G22: =SUM(G8:G21) -> #REF! | H22: =SUM(H8:H21) -> 0 | I22: =SUM(I8:I21) -> #REF! | J22: =SUM(J7:J21) -> #REF! | K22: =SUM(K8:K21) -> 0 | L22: =SUM(L8:L21) -> 0 | M22: =SUM(M8:M21) -> #REF!

Sheet SYNTHESECOMPTE
A1: ASSOCIATION | B1: ASELBY
A2: ANNEE | B2: 2025
A3: SYNTHESE DES COMPTES
A4: NUMERO ORDRE | B4: RUBRIQUE | C4: REPORT A NOUVEAU | D4: ENTREES | E4: SORTIES | F4: SOLDE
A5: 1 | B5: FONDS DE CAISSE ET RECONDUCTION | C5: 30596797 | D5: =DETAILFICHECASSATION!L44 -> 5700000 | E5: =+'DETAIL PRETENCIRCULATION'!C46 -> 17320000 | F5: =C5+D5-E5 -> 18976797
A6: 2 | B6: FONDS DE ROULEMENT | C6: 2293228 | D6: =DETAILFPNDSROULT!C46 -> 416000 | E6: =DETAILFPNDSROULT!F46 -> 266000 | F6: =C6+D6-E6 -> 2443228
A7: 3 | B7: FRAIS EXCEPTIONNELS | C7: 462960 | D7: =DETAILFRAISEXCEPTIONNEL!C46 -> 416000 | E7: =DETAILFRAISEXCEPTIONNEL!F46 -> 200000 | F7: =C7+D7-E7 -> 678960
A8: 4 | B8: MUTUELLE\COMPLEMENT MUTUEL | C8: 1654762 | D8: =DETAILFONDSMUTUEL!E44 -> 1160000 | E8: =DETAILFONDSMUTUEL!H44 -> 1060000 | F8: =C8+D8-E8 -> 1754762
A9: 5 | B9: INSCRIPTION | C9: 830000 | D9: =DETAILINSCRIPTION!C46 -> 25000 | E9: =DETAILINSCRIPTION!F46 -> 0 | F9: =C9+D9-E9 -> 855000
A10: 6 | B10: PENALITES PAIEMENT ESPECES | C10: 940025 | D10: =DETAILPENALITES!C46 -> 104000 | E10: =DETAILPENALITES!H46 -> 0 | F10: =C10+D10-E10 -> 1044025
A11: 7 | B11: SANCTIONS | C11: 10750 | D11: =DETAILPENALITES!D46 -> 5000 | E11: =DETAILPENALITES!I46 -> 0 | F11: =C11+D11-E11 -> 15750
A12: 8 | B12: COLLATION | C12: 1962525 | D12: =DETAILCOLLATION!C46 -> 1664000 | E12: =DETAILCOLLATION!F46 -> 1270000 | F12: =C12+D12-E12 -> 2356525
A13: 9 | B13: INTERET BANCAIRE | C13: 135828 | E13: =DETAILAGIOS!B21 -> 32207 | F13: =C13+D13-E13 -> 103621
A14: 10 | B14: FOYER | C14: 371000 | D14: =DETAILFOYER!C46 -> 475000 | E14: =DETAILFOYER!F46 -> 6871000 | F14: =C14+D14-E14 -> -6025000
A15: 11 | B15: TERRAIN | C15: -15300000 | E15: =+DETAILAUTREDEPENSE!C31 -> 430000 | F15: =C15+D15-E15 -> -15730000
A16: 12 | B16: INTERET EPARGNE | C16: 1398000 | F16: =C16+D16-E16 -> 1398000
A17: 13 | B17: AIDES LAGWE NON REVERSEES | F17: =C17+D17-E17 -> 0
F18: =C18+D18-E18 -> 0
B20: TOTAL | C20: =SUM(C5:C19) -> 25355875 | D20: =SUM(D5:D19) -> 9965000 | E20: =SUM(E5:E19) -> 27449207 | F20: =SUM(F5:F19) -> 7871668
B24: DISPOSITION DES FONDS
C27: 2024 | D27: 2025
A28: 1 | B28: COMPTE CCA AU 30/12/2021 | C28: 0 | D28: =+'BILAN 2024'!D33 -> 0
A29: 2 | B29: COMPTE MC²(NON ACTUALISE) | C29: 640005
A30: 3 | B30: COMPTE AFRILAND | C30: 5265069
A31: 4 | B31: DETTE PREFINANCEMENT LA'AGWEU | C31: ='BILAN 2024'!C36 -> 744700
A32: 6 | B32: RESTE A RECUPERE AU CONSEIL | C32: ='BILAN 2024'!C38 -> 154000
A33: 7 | B33: FONDS EN CIRCULATION | C33: 20222684 | D33: =+'DETAIL PRETENCIRCULATION'!C46 -> 17320000
B34: CAISSE MBOGNING 60 000 DJOUKWE 90 000) | C34: 150000
B36: TOTAL | C36: =SUM(C28:C34) -> 27176458 | D36: =SUM(D28:D34) -> 17320000

Sheet DETAILFICHECASSATION
A1: ASSOCIATION | B1: ASELBY
A2: ANNEE | B2: 2025
A5: MATRICULE | B5: NOM ET PRENOM | C5: FONDS DE CAISSE | D5: RECONDUCTION | E5: REPARTITION INTERET | F5: EPARGNE | G5: REPARTITION PENALITE REMBOURSEMENT PRÊT | H5: REPARTITION COLLATION | I5: TOTAL A DISTRIBUER | J5: SANCTION | K5: COMPLEMENT MUTUELLE | L5: COMPLEMENT FONDS | M5: DETTE PRÊT FONDS | N5: TOTAL RETENU | O5: TOTAL A PERCEVOIR | P5: MONTANT PERCU | Q5: RECONDUCTION 2025 | R5: NOUVEAU FONDS | S5: DONS FOYER | T5: MONTANT PERCU EN ESPECES | U5: MONTANT PERCU CHEQUE | V5: INTERET
A6: AS201648 | B6: =VLOOKUP($A$6,[12]LISTADHERENT!$A$5:$K$43,3,0) -> ASELBY | C6: =VLOOKUP($A6,[13]MVTRESUME25!$A$6:$AL$45,3,0) -> 0 | D6: =VLOOKUP($A6,[13]MVTRESUME25!$A$6:$AL$45,4,0) -> 1023134 | E6: 82902 | F6: =VLOOKUP($A6,[13]MVTRESUME25!$A$6:$AL$45,12,0) -> 80000 | I6: =+D6+E6+F6+G6+H6 -> 1186036 | J6: =VLOOKUP($A6,[13]MVTRESUME25!$A$6:$AL$45,10,0) -> 0 | M6: =VLOOKUP($A6,[13]MVTDEC25!$A$6:$AL$45,19,0) -> 0 | N6: =J6+K6+L6+M6 -> 0 | O6: =I6-N6-S6 -> 1186036 | Q6: =O6-P6-S6 -> 1186036 | V6: 82902
A7: AS201601 | B7: =VLOOKUP(A7,[12]LISTADHERENT!$A$5:$K$43,3,0) -> BAKOP ACHILLE | C7: =VLOOKUP($A7,[13]MVTRESUME25!$A$6:$AL$45,3,0) -> 800000 | D7: =VLOOKUP($A7,[13]MVTRESUME25!$A$6:$AL$45,4,0) -> 18598 | E7: 68535 | F7: =VLOOKUP($A7,[13]MVTRESUME25!$A$6:$AL$45,12,0) -> 223000 | I7: =+D7+E7+F7+G7+H7 -> 310133 | J7: =VLOOKUP($A7,[13]MVTRESUME25!$A$6:$AL$45,10,0) -> 0 | K7: 30000 | L7: 100000 | M7: =VLOOKUP($A7,[13]MVTRESUME25!$A$6:$AL$45,23,0) -> 0 | N7: =J7+K7+L7+M7 -> 130000 | O7: =I7-N7 -> 180133 | P7: =T7 -> 80000 | Q7: =O7-P7-S7 -> 133 | R7: =C7+L7 -> 900000 | S7: 100000 | T7: 80000 | V7: 68535
A8: AS201602 | B8: =VLOOKUP(A8,[12]LISTADHERENT!$A$5:$K$43,3,0) -> BOUTCHOUANG WILLIAM | C8: =VLOOKUP($A8,[13]MVTRESUME25!$A$6:$AL$45,3,0) -> 800000 | D8: =VLOOKUP($A8,[13]MVTRESUME25!$A$6:$AL$45,4,0) -> 132669 | E8: 77823 | F8: =VLOOKUP($A8,[13]MVTRESUME25!$A$6:$AL$45,12,0) -> 228000 | I8: =+D8+E8+F8+G8+H8 -> 438492 | J8: =VLOOKUP($A8,[13]MVTRESUME25!$A$6:$AL$45,10,0) -> 0 | K8: 30000 | L8: 100000 | M8: =VLOOKUP($A8,[13]MVTRESUME25!$A$6:$AL$45,23,0) -> 0 | N8: =J8+K8+L8+M8 -> 130000 | O8: =I8-N8 -> 308492 | P8: =T8 -> 250000 | Q8: =O8-P8-S8 -> 58492 | R8: =C8+L8 -> 900000 | T8: 250000 | V8: 77823
A9: AS201604 | B9: =VLOOKUP(A9,[12]LISTADHERENT!$A$5:$K$43,3,0) -> DJOMO JEAN PAUL | C9: =VLOOKUP($A9,[13]MVTRESUME25!$A$6:$AL$45,3,0) -> 800000 | D9: =VLOOKUP($A9,[13]MVTRESUME25!$A$6:$AL$45,4,0) -> 6643 | E9: 67612 | F9: =VLOOKUP($A9,[13]MVTRESUME25!$A$6:$AL$45,12,0) -> 228000 | I9: =+D9+E9+F9+G9+H9 -> 302255 | J9: =VLOOKUP($A9,[13]MVTRESUME25!$A$6:$AL$45,10,0) -> 5000 | K9: 30000 | L9: 100000 | M9: =VLOOKUP($A9,[13]MVTRESUME25!$A$6:$AL$45,23,0) -> 0 | N9: =J9+K9+L9+M9 -> 135000 | O9: =I9-N9 -> 167255 | P9: =T9 -> 0 | Q9: =O9-P9-S9 -> 167255 | R9: =C9+L9 -> 900000 | V9: 67612
A10: AS201654 | B10: =VLOOKUP(A10,[12]LISTADHERENT!$A$5:$K$43,3,0) -> DJOMOU TCHAPDA | C10: =VLOOKUP($A10,[13]MVTRESUME25!$A$6:$AL$45,3,0) -> 800000 | D10: =VLOOKUP($A10,[13]MVTRESUME25!$A$6:$AL$45,4,0) -> 7246 | E10: 67876 | F10: =VLOOKUP($A10,[13]MVTRESUME25!$A$6:$AL$45,12,0) -> 235500 | I10: =+D10+E10+F10+G10+H10 -> 310622 | J10: =VLOOKUP($A10,[13]MVTRESUME25!$A$6:$AL$45,10,0) -> 0 | K10: 30000 | L10: 100000 | M10: =VLOOKUP($A10,[13]MVTRESUME25!$A$6:$AL$45,23,0) -> 0 | N10: =J10+K10+L10+M10 -> 130000 | O10: =I10-N10 -> 180622 | P10: =T10 -> 70000 | Q10: =O10-P10-S10 -> 10622 | R10: =C10+L10 -> 900000 | S10: 100000 | T10: 70000 | V10: 67876
A11: AS201605 | B11: =VLOOKUP(A11,[12]LISTADHERENT!$A$5:$K$43,3,0) -> DJOUKWE NANGUEN GUY BLAISE | C11: =VLOOKUP($A11,[13]MVTRESUME25!$A$6:$AL$45,3,0) -> 800000 | D11: =VLOOKUP($A11,[13]MVTRESUME25!$A$6:$AL$45,4,0) -> 6032 | E11: 68550 | F11: =VLOOKUP($A11,[13]MVTRESUME25!$A$6:$AL$45,12,0) -> 478375 | I11: =+D11+E11+F11+G11+H11 -> 552957 | J11: =VLOOKUP($A11,[13]MVTRESUME25!$A$6:$AL$45,10,0) -> 0 | K11: 30000 | L11: 100000 | M11: =VLOOKUP($A11,[13]MVTRESUME25!$A$6:$AL$45,23,0) -> 0 | N11: =J11+K11+L11+M11 -> 130000 | O11: =I11-N11 -> 422957 | P11: =T11 -> 400000 | Q11: =O11-P11-S11 -> -18043 | R11: =C11+L11 -> 900000 | S11: 41000 | T11: 400000 | V11: 68550
A12: AS201608 | B12: =VLOOKUP(A12,[12]LISTADHERENT!$A$5:$K$43,3,0) -> DJUOMBESSY ANTOINE | C12: =VLOOKUP($A12,[13]MVTRESUME25!$A$6:$AL$45,3,0) -> 800000 | D12: =VLOOKUP($A12,[13]MVTRESUME25!$A$6:$AL$45,4,0) -> 14486 | E12: 85054 | F12: =VLOOKUP($A12,[13]MVTRESUME25!$A$6:$AL$45,12,0) -> 1208500 | I12: =+D12+E12+F12+G12+H12 -> 1308040 | J12: =VLOOKUP($A12,[13]MVTRESUME25!$A$6:$AL$45,10,0) -> 0 | K12: 30000 | L12: 100000 | M12: =VLOOKUP($A12,[13]MVTRESUME25!$A$6:$AL$45,23,0) -> 0 | N12: =J12+K12+L12 -> 130000 | O12: =I12-N12 -> 1178040 | P12: 400000 | Q12: =O12-P12-S12 -> 678040 | R12: =C12+L12 -> 900000 | S12: 100000 | U12: 400000 | V12: 85054
A13: AS201651 | B13: =VLOOKUP(A13,[12]LISTADHERENT!$A$5:$K$43,3,0) -> DOMOU FABIEN | C13: =VLOOKUP($A13,[13]MVTRESUME25!$A$6:$AL$45,3,0) -> 800000 | D13: =VLOOKUP($A13,[13]MVTRESUME25!$A$6:$AL$45,4,0) -> 6365 | E13: 67590 | F13: =VLOOKUP($A13,[13]MVTRESUME25!$A$6:$AL$45,12,0) -> 228000 | I13: =+D13+E13+F13+G13+H13 -> 301955 | J13: =VLOOKUP($A13,[13]MVTRESUME25!$A$6:$AL$45,10,0) -> 0 | K13: 30000 | L13: 100000 | M13: =VLOOKUP($A13,[13]MVTRESUME25!$A$6:$AL$45,23,0) -> 0 | N13: =J13+K13+L13 -> 130000 | O13: =I13-N13 -> 171955 | P13: =+T13 -> 170000 | Q13: =O13-P13-S13 -> 1955 | R13: =C13+L13 -> 900000 | T13: 170000 | V13: 67590
A14: AS201609 | B14: =VLOOKUP(A14,[12]LISTADHERENT!$A$5:$K$43,3,0) -> DONHOU DAVID | C14: =VLOOKUP($A14,[13]MVTRESUME25!$A$6:$AL$45,3,0) -> 800000 | D14: =VLOOKUP($A14,[13]MVTRESUME25!$A$6:$AL$45,4,0) -> 702391 | E14: 123976 | F14: =VLOOKUP($A14,[13]MVTRESUME25!$A$6:$AL$45,12,0) -> 225000 | I14: =+D14+E14+F14+G14+H14 -> 1051367 | J14: =VLOOKUP($A14,[13]MVTRESUME25!$A$6:$AL$45,10,0) -> 0 | K14: 30000 | L14: 100000 | M14: =VLOOKUP($A14,[13]MVTRESUME25!$A$6:$AL$45,23,0) -> 0 | N14: =J14+K14+L14 -> 130000 | O14: =I14-N14 -> 921367 | P14: =+T14 -> 0 | Q14: =O14-P14-S14 -> 921367 | R14: =C14+L14 -> 900000 | V14: 123976
A15: AS201663 | B15: =VLOOKUP(A15,[12]LISTADHERENT!$A$5:$K$43,3,0) -> FAMPOU PAUL | C15: =VLOOKUP($A15,[13]MVTRESUME25!$A$6:$AL$45,3,0) -> 0 | D15: =VLOOKUP($A15,[13]MVTRESUME25!$A$6:$AL$45,4,0) -> 0 | E15: 3119 | F15: =VLOOKUP($A15,[13]MVTRESUME25!$A$6:$AL$45,12,0) -> 1027000 | I15: =+D15+E15+F15+G15+H15 -> 1030119 | J15: =VLOOKUP($A15,[13]MVTRESUME25!$A$6:$AL$45,10,0) -> 0 | K15: 30000 | L15: =100000+800000 -> 900000 | M15: =VLOOKUP($A15,[13]MVTRESUME25!$A$6:$AL$45,23,0) -> 0 | N15: =J15+K15+L15 -> 930000 | O15: =I15-N15 -> 100119 | P15: =+T15 -> 60000 | Q15: =O15-P15-S15 -> 40119 | R15: =C15+L15 -> 900000 | T15: 60000 | V15: 3119
