Workbook
Name BANQUE: #REF!
Name BANQUE: #REF!
Name BANQUE: #REF!
Name MODEPAID: [1]Feuil2!$A$1:$A$3
Name MODEPAID: [2]Feuil2!$A$1:$A$3
Name MODEVERSEMENT: #REF!
Name MODEVERSEMENT: #REF!
Name MODEVERSEMENT: #REF!
Name MODEVERSEMENTS: [3]MODEVERSEMENT!$A$1:$A$3
Name MODPAID: BILANFINAOUT2017!#REF!

Sheet BILAN 2016 (2)
A2: BILAN ALLANT DE LA PERIODE DU 01 DECEMBRE 2015 AU 30 NOVEMBRE 2016
A5: RUBRIQUE | B5: REPORT A NOUVEAU | C5: ENTREES | D5: SORTIES | E5: SOLDE
A7: EPARGNE\RELIQUAT2015 | B7: =[4]TRAVAUXINVENTAIRE!D54 -> 3525236 | C7: =[4]TRAVAUXINVENTAIRE!R54+C17 -> 6051809 | D7: =[4]EPARGNE!D17+[4]TRAVAUXINVENTAIRE!L54 -> 3142500 | E7: =B7+C7-D7 -> 6434545
A8: FONDS DE CAISSE | B8: =[4]TRAVAUXINVENTAIRE!C54 -> 14428521 | C8: =[4]TRAVAUXINVENTAIRE!M54 -> 1050000 | E8: =B8+C8-D8 -> 15478521
A9: FONDS DE ROULEMENT | C9: =[4]TRAVAUXINVENTAIRE!S54 -> 250500 | D9: =[4]TRAVAUXINVENTAIREDEC!B5 -> 0 | E9: =B9+C9-D9 -> 250500
A10: FRAIS EXCEPTIONNELS | C10: =[4]TRAVAUXINVENTAIRE!T54 -> 501000 | D10: =[4]TRAVAUXINVENTAIREDEC!B6 -> 1100000 | E10: =B10+C10-D10 -> -599000
A11: COLLATION | C11: =[4]TRAVAUXINVENTAIRE!U54 -> 1252500 | D11: =[4]TRAVAUXINVENTAIREDEC!B7 -> 1260000 | E11: =B11+C11-D11 -> -7500
A12: MUTUELLE\COMPLEMENT MUTUEL | C12: =[4]TRAVAUXINVENTAIRE!V54+[4]TRAVAUXINVENTAIRE!O54 -> 1954860 | D12: =[4]TRAVAUXINVENTAIREDEC!B8 -> 2595000 | E12: =B12+C12-D12 -> -640140
A14: FOYER
A15: RECOUVREMENT POUR LAGWEU GENERAL | C15: =320750+16500 -> 337250 | F15: 1711250
A16: AUTRES
A17: INTERET EMPRUNT | C17: =[4]TRAVAUXINVENTAIRE!G54 -> 2230668 | E17: =B17+C17-D17 -> 2230668
A19: EMPRUNT | D19: =[4]EMPRUNT!AP52 -> 0 | E19: =[4]EMPRUNT!AP52 -> 0
A21: RELIQUAT 2016 | C21: =[4]TRAVAUXINVENTAIRE!E54 -> 3212114
A24: COMPTE CCA | C24: 19683000 | D24: 18428363 | E24: =C24-D24 -> 1254637
A25: COMPTE AFRILAND | E25: 4369987
A26: COMPTE MC2 | C26: 614769 | E26: =C26-D26 -> 614769
A27: ASELBY CAISSE(NDJOMO ETIENNE) | C27: 353000 | E27: =C27-D27 -> 353000
A29: RETRAIT DISTRIBUTION EPARGNE | C29: 8000000 | E29: =C29-D29 -> 8000000
A31: SOUS TOTAL | E31: =SUM(E24:E29) -> 14592393
A33: MONTANT DISPONIBLE | E33: =E19+E31 -> 14592393

Sheet BILAN 2016
A2: BILAN ALLANT DE LA PERIODE DU 01 DECEMBRE 2016 AU 30 AOUT 2017
A5: RUBRIQUE | B5: REPORT A NOUVEAU | C5: ENTREES | D5: SORTIES | E5: SOLDE
A7: EPARGNE\RELIQUAT2016 | B7: =BILANFINAOUT2017!D56 -> #REF! | C7: =BILANFINAOUT2017!E56 -> 3963693
A8: FONDS DE CAISSE | B8: 14398519 | C8: =BILANFINAOUT2017!C56 -> 16310819
A9: FONDS DE ROULEMENT | B9: =BILANFINAOUT2017!F5 -> 250500 | C9: =BILANFINAOUT2017!F56 -> 182000
A10: FRAIS EXCEPTIONNELS | B10: =BILANFINAOUT2017!G5 -> -599000 | C10: =BILANFINAOUT2017!G56 -> 364000
A11: COLLATION | B11: =BILANFINAOUT2017!H5 -> -7500 | C11: =BILANFINAOUT2017!H56 -> 910000
A12: MUTUELLE\COMPLEMENT MUTUEL | B12: =BILANFINAOUT2017!I5 -> -640140 | C12: =BILANFINAOUT2017!I56 -> 2009927
A13: PENALITE VERSEMENT EN ESPECES | C13: =BILANFINAOUT2017!R56 -> 125000
A14: SANCTION | C14: =+BILANFINAOUT2017!J56 -> 0
A16: FOYER
A17: RECOUVREMENT POUR LAGWEU GENERAL
A18: AUTRES
A19: INTERET EMPRUNT
A21: EMPRUNT
A23: RELIQUAT 2016
A26: COMPTE CCA
A27: COMPTE AFRILAND
A28: COMPTE MC2
A29: ASELBY CAISSE(NDJOMO ETIENNE)
A31: RETRAIT DISTRIBUTION EPARGNE
A35: MONTANT DISPONIBLE | E35: =E21+E33 -> 0

Sheet BILANFINAOUT2017
A1: NOM | B1: ASELBY
A2: ANNEE | B2: 2016/2017
A3: BILAN MI PARCOURS
A4: MATRICULE | B4: NOM ET PRENOM | C4: FONDS DE CAISSE | D4: RELIQUAT 2016 | E4: EPARGNE | F4: FONDS DE ROULEMENT | G4: FRAIS EXCEPTIONNEL | H4: COLLATION | I4: MUTUELLE | J4: SANCTION | K4: INTERET PERCU | L4: MONTANT A PERCEVOIR | M4: PRÊT EN COURS | N4: INTERET PRORATA | O4: DATE REMBOURSEMENT | P4: OBSERVATION | Q4: MONTAN INTERET 2017 | R4: PENALITE VERSEMENT ESPECES
B5: REPORT 2015-2016 | F5: ='[5]BILAN 2016'!$E$9 -> 250500 | G5: ='[5]BILAN 2016'!$E$10 -> -599000 | H5: ='[5]BILAN 2016'!$E$11 -> -7500 | I5: ='[5]BILAN 2016'!$E$12 -> -640140
A6: AS201648 | B6: =VLOOKUP(A6,[3]LISTADHERENT!A$5:H$52,2,0) -> #N/A | C6: =[3]FONDSDECAISSE!O5 -> 0 | D6: =[3]TONT20000DEC2016!D5 -> 355097 | E6: 0 | I6: 0 | K6: =[3]TONT20000ANNUELLE!C5 -> 23675.873 | Q6: =[5]EMPRUNT!AU5 -> 0
A7: AS201601 | B7: =VLOOKUP(A7,[3]LISTADHERENT!A$5:H$52,2,0) -> BAKOP ACHILLE | C7: =[3]FONDSDECAISSE!O6 -> 420000 | D7: =[3]TONT20000DEC2016!D6 -> 51993 | E7: =[3]TONT20000ANNUELLE!J6 -> 30000 | F7: =[3]TONT20000ANNUELLE!K6 -> 5000 | G7: =[3]TONT20000ANNUELLE!L6 -> 10000 | H7: =[3]TONT20000ANNUELLE!M6 -> 25000 | I7: =[3]TONT20000ANNUELLE!N6 -> 50000 | K7: =[3]TONT20000ANNUELLE!C6 -> 31473.444 | M7: =[5]EMPRUNT!$AP6 -> 588000 | N7: =[5]EMPRUNT!$AS6 -> 60000 | O7: =[5]EMPRUNT!$AR6 -> 42948 | P7: =[5]EMPRUNT!AT6 -> ECHEC | Q7: =[5]EMPRUNT!AU6 -> 0 | R7: =[3]TONT20000ANNUELLE!$G6 -> 2000
A8: AS201602 | B8: =VLOOKUP(A8,[3]LISTADHERENT!A$5:H$51,2) -> BOUTCHOUANG WILLIAM | C8: =[3]FONDSDECAISSE!O7 -> 420000 | D8: =[3]TONT20000DEC2016!D7 -> 2720 | E8: =[3]TONT20000ANNUELLE!J7 -> 27000 | F8: =[3]TONT20000ANNUELLE!K7 -> 4500 | G8: =[3]TONT20000ANNUELLE!L7 -> 9000 | H8: =[3]TONT20000ANNUELLE!M7 -> 22500 | I8: =[3]TONT20000ANNUELLE!N7 -> 50000 | K8: =[3]TONT20000ANNUELLE!C7 -> 29249.87 | M8: =[5]EMPRUNT!$AP7 -> 784000 | N8: =[5]EMPRUNT!$AS7 -> 63090 | O8: =[5]EMPRUNT!$AR7 -> 43040 | Q8: =[5]EMPRUNT!AU7 -> 0 | R8: =[3]TONT20000ANNUELLE!$G7 -> 8000
A9: AS201603 | B9: =VLOOKUP(A9,[3]LISTADHERENT!A$5:H$51,2) -> CHINGUE FABRICE | C9: =[3]FONDSDECAISSE!O8 -> 420000 | D9: =[3]TONT20000DEC2016!D8 -> 5874 | E9: =[3]TONT20000ANNUELLE!J8 -> 27000 | F9: =[3]TONT20000ANNUELLE!K8 -> 4500 | G9: =[3]TONT20000ANNUELLE!L8 -> 9000 | H9: =[3]TONT20000ANNUELLE!M8 -> 22500 | I9: =[3]TONT20000ANNUELLE!N8 -> 50000 | K9: =[3]TONT20000ANNUELLE!C8 -> 29460.161 | M9: =[5]EMPRUNT!$AP8 -> 1293600 | N9: =[5]EMPRUNT!$AS8 -> 140140 | O9: =[5]EMPRUNT!$AR8 -> 42887 | P9: =[5]EMPRUNT!AT8 -> ECHEC | Q9: =[5]EMPRUNT!AU8 -> 0 | R9: =[3]TONT20000ANNUELLE!$G8 -> 7000
A10: AS201604 | B10: =VLOOKUP(A10,[3]LISTADHERENT!A$5:H$51,2) -> DJOMO JEAN PAUL | C10: =[3]FONDSDECAISSE!O9 -> 420000 | D10: =[3]TONT20000DEC2016!D9 -> 2570 | E10: =[3]TONT20000ANNUELLE!J9 -> 37500 | F10: =[3]TONT20000ANNUELLE!K9 -> 4500 | G10: =[3]TONT20000ANNUELLE!L9 -> 9000 | H10: =[3]TONT20000ANNUELLE!M9 -> 22500 | I10: =[3]TONT20000ANNUELLE!N9 -> 50000 | K10: =[3]TONT20000ANNUELLE!C9 -> 29704.875 | M10: =[5]EMPRUNT!$AP9 -> -3000 | N10: =[5]EMPRUNT!$AS9 -> 70000 | O10: =[5]EMPRUNT!$AR9 -> 43132 | Q10: =[5]EMPRUNT!AU9 -> 60000 | R10: =[3]TONT20000ANNUELLE!$G9 -> 1000
A11: AS201605 | B11: =VLOOKUP(A11,[3]LISTADHERENT!A$5:H$51,2) -> DJOUKWE NANGUEN GUY BLAISE | C11: =[3]FONDSDECAISSE!O10 -> 420000 | D11: =[3]TONT20000DEC2016!D10 -> 2697 | E11: =[3]TONT20000ANNUELLE!J10 -> 40000 | F11: =[3]TONT20000ANNUELLE!K10 -> 4500 | G11: =[3]TONT20000ANNUELLE!L10 -> 9000 | H11: =[3]TONT20000ANNUELLE!M10 -> 22500 | I11: =[3]TONT20000ANNUELLE!N10 -> 50000 | K11: =[3]TONT20000ANNUELLE!C10 -> 29661.677 | M11: =[5]EMPRUNT!$AP10 -> 70000 | N11: =[5]EMPRUNT!$AS10 -> 20080 | O11: =[5]EMPRUNT!$AR10 -> 42767 | P11: ECHEC | Q11: =[5]EMPRUNT!AU10 -> 0 | R11: =[3]TONT20000ANNUELLE!$G10 -> 7000
C12: =[3]FONDSDECAISSE!O11 -> 0 | D12: =[3]TONT20000DEC2016!D11 -> 0 | E12: =[3]TONT20000ANNUELLE!J11 -> 0 | G12: =[3]TONT20000ANNUELLE!L11 -> 0 | H12: =[3]TONT20000ANNUELLE!M11 -> 0 | I12: =[3]TONT20000ANNUELLE!N11 -> 0 | K12: =[3]TONT20000ANNUELLE!C11 -> 0 | R12: =[3]TONT20000ANNUELLE!$G11 -> 0
A13: AS201607 | B13: =VLOOKUP(A13,[3]LISTADHERENT!A$5:H$51,2) -> DJOUNKEP SAMUEL | C13: =[3]FONDSDECAISSE!O12 -> 420000 | D13: =[3]TONT20000DEC2016!D12 -> 635540 | E13: =[3]TONT20000ANNUELLE!J12 -> 227000 | F13: =[3]TONT20000ANNUELLE!K12 -> 4500 | G13: =[3]TONT20000ANNUELLE!L12 -> 9000 | H13: =[3]TONT20000ANNUELLE!M12 -> 22500 | I13: =[3]TONT20000ANNUELLE!N12 -> 50000 | K13: =[3]TONT20000ANNUELLE!C12 -> 71442.753 | M13: =[5]EMPRUNT!$AP11 -> 1120000 | N13: =[5]EMPRUNT!$AS11 -> 20000 | O13: =[5]EMPRUNT!$AR11 -> 43252 | Q13: =[5]EMPRUNT!AU11 -> 20000 | R13: =[3]TONT20000ANNUELLE!$G12 -> 0
A14: AS201608 | B14: =VLOOKUP(A14,[3]LISTADHERENT!A$5:H$51,2) -> DJUOMBESSY ANTOINE | C14: =[3]FONDSDECAISSE!O13 -> 420000 | D14: =[3]TONT20000DEC2016!D13 -> 2746 | E14: =[3]TONT20000ANNUELLE!J13 -> 27000 | F14: =[3]TONT20000ANNUELLE!K13 -> 4500 | G14: =[3]TONT20000ANNUELLE!L13 -> 9000 | H14: =[3]TONT20000ANNUELLE!M13 -> 22500 | I14: =[3]TONT20000ANNUELLE!N13 -> 50000 | K14: =[3]TONT20000ANNUELLE!C13 -> 29251.603 | M14: =[5]EMPRUNT!$AP12 -> 784000 | N14: =[5]EMPRUNT!$AS12 -> 14000 | O14: =[5]EMPRUNT!$AR12 -> 43252 | Q14: =[5]EMPRUNT!AU12 -> 14000 | R14: =[3]TONT20000ANNUELLE!$G13 -> 2000
A15: AS201609 | B15: =VLOOKUP(A15,[3]LISTADHERENT!A$5:H$51,2) -> DONHOU DAVID | C15: =[3]FONDSDECAISSE!O14 -> 420000 | D15: =[3]TONT20000DEC2016!D14 -> 53748 | E15: =[3]TONT20000ANNUELLE!J14 -> 27000 | F15: =[3]TONT20000ANNUELLE!K14 -> 4500 | G15: =[3]TONT20000ANNUELLE!L14 -> 9000 | H15: =[3]TONT20000ANNUELLE!M14 -> 22500 | I15: =[3]TONT20000ANNUELLE!N14 -> 50000 | K15: =[3]TONT20000ANNUELLE!C14 -> 32652.13 | M15: =[5]EMPRUNT!$AP13 -> 0 | N15: =[5]EMPRUNT!$AS13 -> 0 | Q15: =[5]EMPRUNT!AU13 -> 0 | R15: =[3]TONT20000ANNUELLE!$G14 -> 3000
A16: AS201610 | B16: =VLOOKUP(A16,[3]LISTADHERENT!A$5:H$51,2) -> FOTSO THOMAS | C16: =[3]FONDSDECAISSE!O15 -> 420000 | D16: =[3]TONT20000DEC2016!D15 -> 2522 | E16: =[3]TONT20000ANNUELLE!J15 -> 27000 | F16: =[3]TONT20000ANNUELLE!K15 -> 4500 | G16: =[3]TONT20000ANNUELLE!L15 -> 9000 | H16: =[3]TONT20000ANNUELLE!M15 -> 22500 | I16: =[3]TONT20000ANNUELLE!N15 -> 50000 | K16: =[3]TONT20000ANNUELLE!C15 -> 29236.668 | M16: =[5]EMPRUNT!$AP14 -> 967600 | N16: =[5]EMPRUNT!$AS14 -> 170170 | O16: =[5]EMPRUNT!$AR14 -> 43313 | P16: =[5]EMPRUNT!AT14 -> ECHEC | Q16: =[5]EMPRUNT!AU14 -> 0 | R16: =[3]TONT20000ANNUELLE!$G15 -> 7000
A17: AS201611 | B17: =VLOOKUP(A17,[3]LISTADHERENT!A$5:H$51,2) -> HENGUE PAUL OMER | C17: =[3]FONDSDECAISSE!O16 -> 420000 | D17: =[3]TONT20000DEC2016!D16 -> #REF! | E17: =[3]TONT20000ANNUELLE!J16 -> 93000 | F17: =[3]TONT20000ANNUELLE!K16 -> 5500 | G17: =[3]TONT20000ANNUELLE!L16 -> 11000 | H17: =[3]TONT20000ANNUELLE!M16 -> 27500 | I17: =[3]TONT20000ANNUELLE!N16 -> 50000 | K17: =[3]TONT20000ANNUELLE!C16 -> 33469.025 | M17: =[5]EMPRUNT!$AP15 -> 0 | N17: =[5]EMPRUNT!$AS15 -> 0 | O17: =[5]EMPRUNT!$AR15 -> 0 | Q17: =[5]EMPRUNT!AU15 -> 0 | R17: =[3]TONT20000ANNUELLE!$G16 -> 1000
A18: AS201612 | B18: =VLOOKUP(A18,[3]LISTADHERENT!A$5:H$51,2) -> HODIEP JULES | C18: =[3]FONDSDECAISSE!O17 -> 50000 | D18: =[3]TONT20000DEC2016!D17 -> 260 | E18: =[3]TONT20000ANNUELLE!J17 -> 0 | F18: =[3]TONT20000ANNUELLE!K17 -> 0 | G18: =[3]TONT20000ANNUELLE!L17 -> 0 | H18: =[3]TONT20000ANNUELLE!M17 -> 0 | I18: =[3]TONT20000ANNUELLE!N17 -> 14092 | K18: =[3]TONT20000ANNUELLE!C17 -> 3351.0545 | M18: =[5]EMPRUNT!$AP16 -> 0 | N18: =[5]EMPRUNT!$AS16 -> 0 | Q18: =[5]EMPRUNT!AU16 -> 0 | R18: =[3]TONT20000ANNUELLE!$G17 -> 0
A19: AS201613 | B19: =VLOOKUP(A19,[3]LISTADHERENT!A$5:H$51,2) -> HOTCHO BENJAMIN | C19: =[3]FONDSDECAISSE!O18 -> 420000 | D19: =[3]TONT20000DEC2016!D18 -> 112685 | E19: =[3]TONT20000ANNUELLE!J18 -> 27000 | F19: =[3]TONT20000ANNUELLE!K18 -> 4500 | G19: =[3]TONT20000ANNUELLE!L18 -> 9000 | H19: =[3]TONT20000ANNUELLE!M18 -> 22500 | I19: =[3]TONT20000ANNUELLE!N18 -> 50000 | K19: =[3]TONT20000ANNUELLE!C18 -> 36581.718 | M19: =[5]EMPRUNT!$AP17 -> 684000 | N19: =[5]EMPRUNT!$AS17 -> 14000 | O19: =[5]EMPRUNT!$AR17 -> 43252 | Q19: =[5]EMPRUNT!AU17 -> 14000 | R19: =[3]TONT20000ANNUELLE!$G18 -> 0
A20: AS201614 | B20: =VLOOKUP(A20,[3]LISTADHERENT!A$5:H$51,2) -> NKEHE DAVID | C20: =[3]FONDSDECAISSE!O19 -> 357000 | D20: =[3]TONT20000DEC2016!D19 -> 177 | E20: =[3]TONT20000ANNUELLE!J19 -> 24000 | F20: =[3]TONT20000ANNUELLE!K19 -> 4000 | G20: =[3]TONT20000ANNUELLE!L19 -> 8000 | H20: =[3]TONT20000ANNUELLE!M19 -> 20000 | I20: =[3]TONT20000ANNUELLE!N19 -> 21829 | K20: =[3]TONT20000ANNUELLE!C19 -> 24879.47 | M20: =[5]EMPRUNT!$AP18 -> 0 | N20: =[5]EMPRUNT!$AS18 -> 0 | Q20: =[5]EMPRUNT!AU18 -> 0 | R20: =[3]TONT20000ANNUELLE!$G19 -> 2000
A21: AS201615 | B21: =VLOOKUP(A21,[3]LISTADHERENT!A$5:H$51,2) -> KEPSEU FRANCIS | C21: =[3]FONDSDECAISSE!O20 -> 420000 | D21: =[3]TONT20000DEC2016!D20 -> 705425 | E21: =[3]TONT20000ANNUELLE!J20 -> 2054000 | F21: =[3]TONT20000ANNUELLE!K20 -> 4500 | G21: =[3]TONT20000ANNUELLE!L20 -> 9000 | H21: =[3]TONT20000ANNUELLE!M20 -> 22500 | I21: =[3]TONT20000ANNUELLE!N20 -> 50000 | K21: =[3]TONT20000ANNUELLE!C20 -> 160404.21 | M21: =[5]EMPRUNT!$AP19 -> 0 | N21: =[5]EMPRUNT!$AS19 -> 0 | Q21: =[5]EMPRUNT!AU19 -> 0 | R21: =[3]TONT20000ANNUELLE!$G20 -> 0
A22: AS201616 | B22: =VLOOKUP(A22,[3]LISTADHERENT!A$5:H$51,2) -> KOUAMOU EMMANUEL | C22: =[3]FONDSDECAISSE!O21 -> 420000 | D22: =[3]TONT20000DEC2016!D21 -> 2357 | E22: =[3]TONT20000ANNUELLE!J21 -> 27000 | F22: =[3]TONT20000ANNUELLE!K21 -> 4500 | G22: =[3]TONT20000ANNUELLE!L21 -> 9000 | H22: =[3]TONT20000ANNUELLE!M21 -> 22500 | I22: =[3]TONT20000ANNUELLE!N21 -> 50000 | K22: =[3]TONT20000ANNUELLE!C21 -> 29225.667 | M22: =[5]EMPRUNT!$AP20 -> 450000 | N22: =[5]EMPRUNT!$AS20 -> 270000 | O22: =[5]EMPRUNT!$AR20 -> 42917 | Q22: =[5]EMPRUNT!AU20 -> 150000 | R22: =[3]TONT20000ANNUELLE!$G21 -> 6000
A23: AS201617 | B23: =VLOOKUP(A23,[3]LISTADHERENT!A$5:H$51,2) -> KOUAMOU MOISE | C23: =[3]FONDSDECAISSE!O22 -> 420000 | D23: =[3]TONT20000DEC2016!D22 -> 3048 | E23: =[3]TONT20000ANNUELLE!J22 -> 27000 | F23: =[3]TONT20000ANNUELLE!K22 -> 4000 | G23: =[3]TONT20000ANNUELLE!L22 -> 8000 | H23: =[3]TONT20000ANNUELLE!M22 -> 20000 | I23: =[3]TONT20000ANNUELLE!N22 -> 50000 | K23: =[3]TONT20000ANNUELLE!C22 -> 29204.096 | M23: =[5]EMPRUNT!$AP21 -> 592000 | N23: =[5]EMPRUNT!$AS21 -> 25000 | O23: =[5]EMPRUNT!$AR21 -> 43160 | Q23: =[5]EMPRUNT!AU21 -> 15000 | R23: =[3]TONT20000ANNUELLE!$G22 -> 1000
A24: AS201618 | B24: =VLOOKUP(A24,[3]LISTADHERENT!A$5:H$51,2) -> KOUAMO VICTOR PEGUY | C24: =[3]FONDSDECAISSE!O23 -> 420000 | D24: =[3]TONT20000DEC2016!D23 -> 2686 | E24: =[3]TONT20000ANNUELLE!J23 -> 27000 | F24: =[3]TONT20000ANNUELLE!K23 -> 4500 | G24: =[3]TONT20000ANNUELLE!L23 -> 9000 | H24: =[3]TONT20000ANNUELLE!M23 -> 22500 | I24: =[3]TONT20000ANNUELLE!N23 -> 50000 | K24: =[3]TONT20000ANNUELLE!C23 -> 29247.603 | M24: =[5]EMPRUNT!$AP22 -> 980000 | N24: =[5]EMPRUNT!$AS22 -> 72000 | O24: =[5]EMPRUNT!$AR22 -> 43374 | Q24: =[5]EMPRUNT!AU22 -> 0 | R24: =[3]TONT20000ANNUELLE!$G23 -> 5000
A25: AS201619 | B25: =VLOOKUP(A25,[3]LISTADHERENT!A$5:H$51,2) -> KOUATCHO MESSACK | C25: =[3]FONDSDECAISSE!O24 -> 420000 | D25: =[3]TONT20000DEC2016!D24 -> 3818 | E25: =[3]TONT20000ANNUELLE!J24 -> 27000 | F25: =[3]TONT20000ANNUELLE!K24 -> 4500 | G25: =[3]TONT20000ANNUELLE!L24 -> 9000 | H25: =[3]TONT20000ANNUELLE!M24 -> 22500 | I25: =[3]TONT20000ANNUELLE!N24 -> 50000 | K25: =[3]TONT20000ANNUELLE!C24 -> 29323.078 | M25: =[5]EMPRUNT!$AP23 -> 1120000 | N25: =[5]EMPRUNT!$AS23 -> 40000 | O25: =[5]EMPRUNT!$AR23 -> 43191 | Q25: =[5]EMPRUNT!AU23 -> 40000 | R25: =[3]TONT20000ANNUELLE!$G24 -> 3000
A26: AS201620 | B26: =VLOOKUP(A26,[3]LISTADHERENT!A$5:H$51,2) -> LOWE JEAN | C26: =[3]FONDSDECAISSE!O25 -> 420000 | D26: =[3]TONT20000DEC2016!D25 -> 2652 | E26: =[3]TONT20000ANNUELLE!J25 -> 24000 | F26: =[3]TONT20000ANNUELLE!K25 -> 4000 | G26: =[3]TONT20000ANNUELLE!L25 -> 8000 | H26: =[3]TONT20000ANNUELLE!M25 -> 20000 | I26: =[3]TONT20000ANNUELLE!N25 -> 50000 | K26: =[3]TONT20000ANNUELLE!C25 -> 29195.648 | M26: =[5]EMPRUNT!$AP24 -> 154500 | N26: =[5]EMPRUNT!$AS24 -> 1600 | O26: =[5]EMPRUNT!$AR24 -> 42979 | P26: =[5]EMPRUNT!AT24 -> 0 | Q26: =[5]EMPRUNT!AU24 -> 1500 | R26: =[3]TONT20000ANNUELLE!$G25 -> 1000
A27: AS201621 | B27: =VLOOKUP(A27,[3]LISTADHERENT!A$5:H$51,2) -> LOWE JEAN | C27: =[3]FONDSDECAISSE!O26 -> 420000 | D27: =[3]TONT20000DEC2016!D26 -> 2741 | E27: =[3]TONT20000ANNUELLE!J26 -> 27000 | F27: =[3]TONT20000ANNUELLE!K26 -> 4500 | G27: =[3]TONT20000ANNUELLE!L26 -> 9000 | H27: =[3]TONT20000ANNUELLE!M26 -> 22500 | I27: =[3]TONT20000ANNUELLE!N26 -> 50000 | K27: =[3]TONT20000ANNUELLE!C26 -> 29251.27 | M27: =[5]EMPRUNT!$AP25 -> 0 | N27: =[5]EMPRUNT!$AS25 -> 140000 | O27: =[5]EMPRUNT!$AR25 -> 42917 | P27: =[5]EMPRUNT!AT25 -> 0 | Q27: =[5]EMPRUNT!AU25 -> 0 | R27: =[3]TONT20000ANNUELLE!$G26 -> 1000
A28: AS201622 | B28: =VLOOKUP(A28,[3]LISTADHERENT!A$5:H$51,2) -> NDJOMO ETIENNE | C28: =[3]FONDSDECAISSE!O27 -> 420000 | D28: =[3]TONT20000DEC2016!D27 -> 2818 | E28: =[3]TONT20000ANNUELLE!J27 -> 72000 | F28: =[3]TONT20000ANNUELLE!K27 -> 4500 | G28: =[3]TONT20000ANNUELLE!L27 -> 9000 | H28: =[3]TONT20000ANNUELLE!M27 -> 22500 | I28: =[3]TONT20000ANNUELLE!N27 -> 50000 | K28: =[3]TONT20000ANNUELLE!C27 -> 31031.261 | M28: =[5]EMPRUNT!$AP26 -> 672000 | N28: =[5]EMPRUNT!$AS26 -> 30000 | O28: =[5]EMPRUNT!$AR26 -> 43160 | Q28: =[5]EMPRUNT!AU26 -> 42000 | R28: =[3]TONT20000ANNUELLE!$G27 -> 1000
A29: AS201623 | B29: =VLOOKUP(A29,[3]LISTADHERENT!A$5:H$51,2) -> NDOMBOU JEAN CLAUDE | C29: =[3]FONDSDECAISSE!O28 -> 420000 | D29: =[3]TONT20000DEC2016!D28 -> 0 | E29: =[3]TONT20000ANNUELLE!J28 -> 3000 | F29: =[3]TONT20000ANNUELLE!K28 -> 500 | G29: =[3]TONT20000ANNUELLE!L28 -> 1000 | H29: =[3]TONT20000ANNUELLE!M28 -> 2500 | I29: =[3]TONT20000ANNUELLE!N28 -> 50000 | K29: =[3]TONT20000ANNUELLE!C28 -> 28003.601 | M29: =[5]EMPRUNT!$AP27 -> 0 | N29: =[5]EMPRUNT!$AS27 -> 0 | Q29: =[5]EMPRUNT!AU27 -> 0 | R29: =[3]TONT20000ANNUELLE!$G28 -> 0
A30: AS201624 | B30: =VLOOKUP(A30,[3]LISTADHERENT!A$5:H$51,2) -> NGONDIEP CLAUDE | C30: =[3]FONDSDECAISSE!O29 -> 420000 | D30: =[3]TONT20000DEC2016!D29 -> 3250 | E30: =[3]TONT20000ANNUELLE!J29 -> 36000 | F30: =[3]TONT20000ANNUELLE!K29 -> 4500 | G30: =[3]TONT20000ANNUELLE!L29 -> 9000 | H30: =[3]TONT20000ANNUELLE!M29 -> 22500 | I30: =[3]TONT20000ANNUELLE!N29 -> 50000 | K30: =[3]TONT20000ANNUELLE!C29 -> 29879.831 | M30: =[5]EMPRUNT!$AP28 -> 1020000 | N30: =[5]EMPRUNT!$AS28 -> 20020 | O30: =[5]EMPRUNT!$AR28 -> 43252 | Q30: =[5]EMPRUNT!AU28 -> 20000 | R30: =[3]TONT20000ANNUELLE!$G29 -> 1000
A31: AS201625 | B31: =VLOOKUP(A31,[3]LISTADHERENT!A$5:H$51,2) -> NGONGANG JEAN THEODORE | C31: =[3]FONDSDECAISSE!O30 -> 0 | D31: =[3]TONT20000DEC2016!D30 -> 106 | E31: =[3]TONT20000ANNUELLE!J30 -> 16193 | F31: =[3]TONT20000ANNUELLE!K30 -> 4000 | G31: =[3]TONT20000ANNUELLE!L30 -> 8000 | H31: =[3]TONT20000ANNUELLE!M30 -> 20000 | I31: =[3]TONT20000ANNUELLE!N30 -> 50000 | K31: =[3]TONT20000ANNUELLE!C30 -> 982.09061 | M31: =[5]EMPRUNT!$AP29 -> 0 | N31: =[5]EMPRUNT!$AS29 -> 0 | Q31: =[5]EMPRUNT!AU29 -> 0 | R31: =[3]TONT20000ANNUELLE!$G30 -> 3000
A32: AS201626 | B32: =VLOOKUP(A32,[3]LISTADHERENT!A$5:H$51,2) -> NGUIEMEGNI MATHIEU BLAISE | C32: =[3]FONDSDECAISSE!O31 -> 420000 | D32: =[3]TONT20000DEC2016!D31 -> 40133 | E32: =[3]TONT20000ANNUELLE!J31 -> 27000 | F32: =[3]TONT20000ANNUELLE!K31 -> 4500 | G32: =[3]TONT20000ANNUELLE!L31 -> 9000 | H32: =[3]TONT20000ANNUELLE!M31 -> 22500 | I32: =[3]TONT20000ANNUELLE!N31 -> 50000 | K32: =[3]TONT20000ANNUELLE!C31 -> 31746.159 | M32: =[5]EMPRUNT!$AP30 -> 0 | N32: =[5]EMPRUNT!$AS30 -> 0 | Q32: =[5]EMPRUNT!AU30 -> 0 | R32: =[3]TONT20000ANNUELLE!$G31 -> 2000
A33: AS201627 | B33: =VLOOKUP(A33,[3]LISTADHERENT!A$5:H$51,2) -> NJEPDJIO MBOUKAM DELUXE | C33: =[3]FONDSDECAISSE!O32 -> 420000 | D33: =[3]TONT20000DEC2016!D32 -> 2773 | E33: =[3]TONT20000ANNUELLE!J32 -> 32000 | F33: =[3]TONT20000ANNUELLE!K32 -> 4500 | G33: =[3]TONT20000ANNUELLE!L32 -> 9000 | H33: =[3]TONT20000ANNUELLE!M32 -> 22500 | I33: =[3]TONT20000ANNUELLE!N32 -> 50000 | K33: =[3]TONT20000ANNUELLE!C32 -> 29585.551 | M33: =[5]EMPRUNT!$AP31 -> 896000 | N33: =[5]EMPRUNT!$AS31 -> 24000 | O33: =[5]EMPRUNT!$AR31 -> 43221 | Q33: =[5]EMPRUNT!AU31 -> 24000 | R33: =[3]TONT20000ANNUELLE!$G32 -> 7000
A34: AS201628 | B34: =VLOOKUP(A34,[3]LISTADHERENT!A$5:H$51,2) -> NKAMGANG JUSTIN DEJOLIE | C34: =[3]FONDSDECAISSE!O33 -> 420000 | D34: =[3]TONT20000DEC2016!D33 -> 69808 | E34: =[3]TONT20000ANNUELLE!J33 -> 56000 | F34: =[3]TONT20000ANNUELLE!K33 -> 4500 | G34: =[3]TONT20000ANNUELLE!L33 -> 9000 | H34: =[3]TONT20000ANNUELLE!M33 -> 22500 | I34: =[3]TONT20000ANNUELLE!N33 -> 50000 | K34: =[3]TONT20000ANNUELLE!C33 -> 34923.936 | M34: =[5]EMPRUNT!$AP32 -> 1120000 | N34: =[5]EMPRUNT!$AS32 -> 90090 | O34: =[5]EMPRUNT!$AR32 -> 43040 | Q34: =[5]EMPRUNT!AU32 -> 0 | R34: =[3]TONT20000ANNUELLE!$G33 -> 7000
A35: AS201629 | B35: =VLOOKUP(A35,[3]LISTADHERENT!A$5:H$51,2) -> NKEPSEU DIEUDONNE | C35: =[3]FONDSDECAISSE!O34 -> 420000 | D35: =[3]TONT20000DEC2016!D34 -> 2772 | E35: =[3]TONT20000ANNUELLE!J34 -> 172000 | F35: =[3]TONT20000ANNUELLE!K34 -> 4500 | G35: =[3]TONT20000ANNUELLE!L34 -> 9000 | H35: =[3]TONT20000ANNUELLE!M34 -> 22500 | I35: =[3]TONT20000ANNUELLE!N34 -> 50000 | K35: =[3]TONT20000ANNUELLE!C34 -> 37701.035 | M35: =[5]EMPRUNT!$AP33 -> 532000 | N35: =[5]EMPRUNT!$AS33 -> 60100 | O35: =[5]EMPRUNT!$AR33 -> 43009 | Q35: =[5]EMPRUNT!AU33 -> 0 | R35: =[3]TONT20000ANNUELLE!$G34 -> 7000
C36: =[3]FONDSDECAISSE!O35 -> 0 | D36: =[3]TONT20000DEC2016!D35 -> 0 | E36: =[3]TONT20000ANNUELLE!J35 -> 0 | F36: =[3]TONT20000ANNUELLE!K35 -> 0 | G36: =[3]TONT20000ANNUELLE!L35 -> 0 | H36: =[3]TONT20000ANNUELLE!M35 -> 0 | I36: =[3]TONT20000ANNUELLE!N35 -> 0 | K36: =[3]TONT20000ANNUELLE!C35 -> 0 | Q36: =[5]EMPRUNT!AU34 -> 0 | R36: =[3]TONT20000ANNUELLE!$G35 -> 0
A37: AS201631 | B37: =VLOOKUP(A37,[3]LISTADHERENT!A$5:H$51,2) -> NTEPDIE TUEMAC MZ | C37: =[3]FONDSDECAISSE!O36 -> 0 | D37: =[3]TONT20000DEC2016!D36 -> #REF! | E37: =[3]TONT20000ANNUELLE!J36 -> 0 | F37: =[3]TONT20000ANNUELLE!K36 -> 0 | G37: =[3]TONT20000ANNUELLE!L36 -> 0 | H37: =[3]TONT20000ANNUELLE!M36 -> 0 | I37: =[3]TONT20000ANNUELLE!N36 -> 0 | K37: =[3]TONT20000ANNUELLE!C36 -> 0 | M37: =[5]EMPRUNT!$AP34 -> 0 | N37: =[5]EMPRUNT!$AS34 -> 0 | Q37: =[5]EMPRUNT!AU35 -> 0 | R37: =[3]TONT20000ANNUELLE!$G36 -> 0
C38: =[3]FONDSDECAISSE!O37 -> 0 | D38: =[3]TONT20000DEC2016!D37 -> 0 | E38: =[3]TONT20000ANNUELLE!J37 -> 0 | F38: =[3]TONT20000ANNUELLE!K37 -> 0 | G38: =[3]TONT20000ANNUELLE!L37 -> 0 | H38: =[3]TONT20000ANNUELLE!M37 -> 0 | I38: =[3]TONT20000ANNUELLE!N37 -> 0 | K38: =[3]TONT20000ANNUELLE!C37 -> 0 | M38: =[5]EMPRUNT!$AP35 -> 0 | N38: =[5]EMPRUNT!$AS35 -> 0 | Q38: =[5]EMPRUNT!AU36 -> 0 | R38: =[3]TONT20000ANNUELLE!$G37 -> 0
A39: AS201633 | B39: =VLOOKUP(A39,[3]LISTADHERENT!A$5:H$51,2) -> PATEGO NJOSSU GUSTAVE | C39: =[3]FONDSDECAISSE!O38 -> 420000 | D39: =[3]TONT20000DEC2016!D38 -> 2474 | E39: =[3]TONT20000ANNUELLE!J38 -> 27000 | F39: =[3]TONT20000ANNUELLE!K38 -> 4500 | G39: =[3]TONT20000ANNUELLE!L38 -> 9000 | H39: =[3]TONT20000ANNUELLE!M38 -> 22500 | I39: =[3]TONT20000ANNUELLE!N38 -> 50000 | K39: =[3]TONT20000ANNUELLE!C38 -> 29235.269 | M39: =[5]EMPRUNT!$AP35 -> 0 | N39: =[5]EMPRUNT!$AS35 -> 0 | R39: =[3]TONT20000ANNUELLE!$G38 -> 0
A40: AS201634 | B40: =VLOOKUP(A40,[3]LISTADHERENT!A$5:H$51,2) -> SEUNOU RICHELOT | C40: =[3]FONDSDECAISSE!O39 -> 420000 | D40: =[3]TONT20000DEC2016!D39 -> 6756 | E40: =[3]TONT20000ANNUELLE!J39 -> 27000 | F40: =[3]TONT20000ANNUELLE!K39 -> 4500 | G40: =[3]TONT20000ANNUELLE!L39 -> 9000 | H40: =[3]TONT20000ANNUELLE!M39 -> 22500 | I40: =[3]TONT20000ANNUELLE!N39 -> 50000 | K40: =[3]TONT20000ANNUELLE!C39 -> 29520.768 | M40: =[5]EMPRUNT!$AP36 -> 1120000 | N40: =[5]EMPRUNT!$AS36 -> 100100 | O40: =[5]EMPRUNT!$AR36 -> 43009 | Q40: =[5]EMPRUNT!AU36 -> 0 | R40: =[3]TONT20000ANNUELLE!$G39 -> 8000
...

Sheet BILANUPDATE
B1: SOLDE AU 30/11/2016 | C1: DEC 2016 | E1: JANV. | G1: FÉVR. | I1: MARS | K1: AVRIL | M1: MAI | O1: JUIN | Q1: JUILLET | S1: AOÛT | U1: TOTAL | W1: SOLDE | Y1: BILANINFORMATIQU
C2: ENTREE | D2: SORTIE | E2: ENTREE | F2: SORTIE | G2: ENTREE | H2: SORTIE | I2: ENTREE | J2: SORTIE | K2: ENTREE | L2: SORTIE | M2: ENTREE | N2: SORTIE | O2: ENTREE | P2: SORTIE | Q2: ENTREE | R2: SORTIE | S2: ENTREE | T2: SORTIE | U2: ENTREE | V2: SORTIE | W2: ENTREE | X2: SORTIE | Y2: ENTREE | Z2: SORTIE
A3: FONDS DE CAISSE | B3: ='BILAN 2016'!B8 -> 14398519 | C3: 1307000 | D3: 400000 | E3: 407000 | G3: 163000 | H3: 2000000 | I3: 604000 | J3: 1600000 | K3: 153000 | L3: 1500000 | M3: 164000 | N3: 4200000 | O3: 1156000 | P3: 3800000 | Q3: =141500+39000 -> 180500 | S3: 389000 | T3: 150000 | U3: =C3+E3+G3+I3+K3+M3+O3+Q3+S3 -> 4523500 | V3: =D3+F3+H3+J3+L3+N3+P3+R3+T3 -> 13650000 | W3: =B3+U3-V3 -> 5272019 | Y3: =BILANFINAOUT2017!C56+BILANFINAOUT2017!D56 -> #REF!
A4: EPARGNE | B4: =BILANFINAOUT2017!D56 -> #REF! | U4: =C4+E4+G4+I4+K4+M4+O4+Q4+S4 -> 0 | V4: =D4+F4+H4+J4+L4+N4+P4+R4+T4 -> 0 | W4: =B4+U4-V4 -> #REF! | Y4: =+BILANFINAOUT2017!E56 -> 3963693
A5: COLLATION | B5: ='BILAN 2016'!B11 -> -7500 | C5: 105000 | D5: 100000 | E5: 95000 | F5: 110000 | G5: 105000 | H5: 100000 | I5: 130350 | J5: 100000 | K5: 97500 | L5: 100000 | M5: 97500 | N5: 100000 | O5: 100000 | P5: 100000 | Q5: 97500 | R5: 100000 | S5: 115000 | T5: 100000 | U5: =C5+E5+G5+I5+K5+M5+O5+Q5+S5 -> 942850 | V5: =D5+F5+H5+J5+L5+N5+P5+R5+T5 -> 910000 | W5: =B5+U5-V5 -> 25350 | Y5: =BILANFINAOUT2017!H56 -> 910000
A6: FONDS DE ROULEMENT | B6: ='BILAN 2016'!B9 -> 250500 | C6: 21000 | D6: 87000 | E6: 19000 | F6: 84000 | G6: 21000 | H6: =200000+12000 -> 212000 | I6: 20000 | J6: 10000 | K6: 19500 | L6: 6000 | M6: 19500 | O6: 20000 | P6: =33000+15000 -> 48000 | Q6: 19500 | R6: 13000 | S6: 23000 | T6: 5000 | U6: =C6+E6+G6+I6+K6+M6+O6+Q6+S6 -> 182500 | V6: =D6+F6+H6+J6+L6+N6+P6+R6+T6 -> 465000 | W6: =B6+U6-V6 -> -32000 | Y6: =BILANFINAOUT2017!F56 -> 182000
A7: FRAIS EXCEPTIONNELLE | B7: ='BILAN 2016'!B10 -> -599000 | C7: 42000 | E7: 38000 | G7: 42000 | I7: 40000 | K7: 39000 | M7: 39000 | O7: 40000 | Q7: 39000 | R7: 345000 | S7: 46000 | U7: =C7+E7+G7+I7+K7+M7+O7+Q7+S7 -> 365000 | V7: =D7+F7+H7+J7+L7+N7+P7+R7+T7 -> 345000 | W7: =B7+U7-V7 -> -579000 | Y7: =BILANFINAOUT2017!G56 -> 364000
A8: MUTUELLE | B8: =+'BILAN 2016'!B12 -> -640140 | C8: =+[6]TRAVAUXINVENTAIRE!$O$54 -> 1930123 | F8: 200000 | I8: 50000 | N8: 100000 | R8: 640000 | U8: =C8+E8+G8+I8+K8+M8+O8+Q8+S8 -> 1980123 | V8: =D8+F8+H8+J8+L8+N8+P8+R8+T8 -> 940000 | W8: =B8+U8-V8 -> 399983 | Y8: =BILANFINAOUT2017!I56 -> 2009927
A9: INSCRIPTION | U9: =C9+E9+G9+I9+K9+M9+O9+Q9+S9 -> 0 | V9: =D9+F9+H9+J9+L9+N9+P9+R9+T9 -> 0 | W9: =B9+U9-V9 -> 0
A10: PENALITE | C10: 10000 | E10: 36000 | G10: 15000 | I10: 16000 | K10: 18000 | M10: 15000 | O10: 15000 | Q10: 15000 | S10: =31000+22000 -> 53000 | U10: =C10+E10+G10+I10+K10+M10+O10+Q10+S10 -> 193000 | V10: =D10+F10+H10+J10+L10+N10+P10+R10+T10 -> 0 | W10: =B10+U10-V10 -> 193000 | Y10: ='BILAN 2016'!C13 -> 125000
A11: REMBOURSEMENT | C11: 574400 | E11: 309000 | G11: =1969000+70000 -> 2039000 | I11: 1939000 | K11: 1600000 | M11: 4271800 | O11: 1094000 | Q11: =805000-39000 -> 766000 | S11: 511000 | U11: =C11+E11+G11+I11+K11+M11+O11+Q11+S11 -> 13104200 | V11: =D11+F11+H11+J11+L11+N11+P11+R11+T11 -> 0 | W11: =B11+U11-V11 -> 13104200 | Z11: =BILANFINAOUT2017!M56 -> 21149400
A12: FOYER | G12: =320375+31875 -> 352250 | I12: 100000 | K12: 99500 | U12: =C12+E12+G12+I12+K12+M12+O12+Q12+S12 -> 551750 | V12: =D12+F12+H12+J12+L12+N12+P12+R12+T12 -> 0 | W12: =B12+U12-V12 -> 551750
A13: ARGENT GARDE | O13: 300000 | U13: =C13+E13+G13+I13+K13+M13+O13+Q13+S13 -> 300000 | V13: =D13+F13+H13+J13+L13+N13+P13+R13+T13 -> 0 | W13: =B13+U13-V13 -> 300000
A15: TOTAL | B15: =SUM(B3:B14) -> #REF! | C15: =SUM(C3:C14) -> 3989523 | D15: =SUM(D3:D14) -> 587000 | E15: =SUM(E3:E14) -> 904000 | F15: =SUM(F3:F14) -> 394000 | G15: =SUM(G3:G14) -> 2737250 | H15: =SUM(H3:H14) -> 2312000 | I15: =SUM(I3:I14) -> 2899350 | ... W15: =SUM(W3:W14) -> #REF!

Sheet BILANUPDATEDPA
B1: SOLDE AU 30/11/2016 | C1: DEC 2016 | E1: JANV. | G1: FÉVR. | I1: MARS | K1: AVRIL | M1: MAI | O1: JUIN | Q1: JUILLET | S1: AOÛT | U1: TOTAL | W1: SOLDE | Y1: BILANDEJOLIE
C2: ENTREE | D2: SORTIE | E2: ENTREE | F2: SORTIE | G2: ENTREE | H2: SORTIE | I2: ENTREE | J2: SORTIE | K2: ENTREE | L2: SORTIE | M2: ENTREE | N2: SORTIE | O2: ENTREE | P2: SORTIE | Q2: ENTREE | R2: SORTIE | S2: ENTREE | T2: SORTIE | U2: ENTREE | V2: SORTIE | Y2: ENTREE | Z2: SORTIE
A3: FONDS DE CAISSE | B3: ='BILAN 2016'!B8 -> 14398519 | C3: =+[6]TRAVAUXINVENTAIRE!$M$54 -> 1050000 | D3: =[6]TONT20000DEC2016!$Q$56+[6]TONT20000DEC2016!$R$56 -> 412000 | F3: =[6]TONT20000JANV2017!$O$56+[6]TONT20000JANV2017!$P$56 -> 0 | H3: =[6]TONT20000FEV2017!$O$56+[6]TONT20000FEV2017!$P$56 -> 2120000 | J3: =[6]TONT20000MARS2017!$O$56+[6]TONT20000MARS2017!$P$56 -> 1680000 | L3: =[6]TONT20000AVRIL2017!$O$56+[6]TONT20000AVRIL2017!$P$56 -> 1565000 | N3: =[6]TONT20000MAI2017!$O$56+[6]TONT20000MAI2017!$P$56 -> 4326000 | P3: =[6]TONT20000JUIN2017!$O$56+[6]TONT20000JUIN2017!$P$56 -> 3880000 | R3: =[6]TONT20000JUIL2017!$O$56+[6]TONT20000JUIL2017!$P$56 -> 0 | T3: =[7]MVTAOUT2017!$M$53+[7]MVTAOUT2017!$N$53 -> 154500 | U3: =C3+E3+G3+I3+K3+M3+O3+Q3+S3 -> 1050000 | V3: =D3+F3+H3+J3+L3+N3+P3+R3+T3 -> 14137500 | W3: =+B3+U3 -> 15448519 | Y3: =BILANUPDATE!U3 -> 4523500
A4: EPARGNE/RELIQUAT | B4: =BILANFINAOUT2017!D56 -> #REF! | C4: =+[6]TONT20000DEC2016!$L$56 -> 1307000 | D4: =+BILANUPDATE!D4 -> 0 | E4: =[6]TONT20000JANV2017!$J$56 -> 407000 | F4: =+BILANUPDATE!F4 -> 0 | G4: =[6]TONT20000FEV2017!$J$56 -> 163000 | H4: =+BILANUPDATE!H4 -> 0 | I4: =[6]TONT20000MARS2017!$J$56 -> 604000 | J4: =+BILANUPDATE!J4 -> 0 | K4: =[6]TONT20000AVRIL2017!$J$56 -> 153000 | L4: =+BILANUPDATE!L4 -> 0 | M4: =[6]TONT20000MAI2017!$J$56 -> 164000 | N4: =+BILANUPDATE!N4 -> 0 | O4: =[6]TONT20000JUIN2017!$J$56 -> 1156000 | P4: =+BILANUPDATE!P4 -> 0 | Q4: =[6]TONT20000JUIL2017!$J$56 -> 141500 | R4: =+BILANUPDATE!R4 -> 0 | S4: =[7]MVTAOUT2017!$H$53 -> 359000 | T4: =+BILANUPDATE!T4 -> 0 | U4: =C4+E4+G4+I4+K4+M4+O4+Q4+S4 -> 4454500 | V4: =D4+F4+H4+J4+L4+N4+P4+R4+T4 -> 0 | W4: =+B4+U4 -> #REF!
A5: COLLATION | B5: ='BILAN 2016'!B11 -> -7500 | C5: =+[6]TONT20000DEC2016!$O$56 -> 105000 | D5: =+BILANUPDATE!D5 -> 100000 | E5: =[6]TONT20000JANV2017!$M$56 -> 95000 | F5: =+BILANUPDATE!F5 -> 110000 | G5: =[6]TONT20000FEV2017!$M$56 -> 105000 | H5: =+BILANUPDATE!H5 -> 100000 | I5: =[6]TONT20000MARS2017!$M$56 -> 130350 | J5: =+BILANUPDATE!J5 -> 100000 | K5: =[6]TONT20000AVRIL2017!$M$56 -> 97500 | L5: =+BILANUPDATE!L5 -> 100000 | M5: =[6]TONT20000MAI2017!$M$56 -> 97500 | N5: =+BILANUPDATE!N5 -> 100000 | O5: =[6]TONT20000JUIN2017!$M$56 -> 97500 | P5: =+BILANUPDATE!P5 -> 100000 | Q5: =[6]TONT20000JUIL2017!$M$56 -> 97500 | R5: =+BILANUPDATE!R5 -> 100000 | S5: =[7]MVTAOUT2017!$K$53 -> 115000 | T5: =+BILANUPDATE!T5 -> 100000 | U5: =C5+E5+G5+I5+K5+M5+O5+Q5+S5 -> 940350 | V5: =D5+F5+H5+J5+L5+N5+P5+R5+T5 -> 910000 | W5: =+B5+U5-V5 -> 22850 | Y5: =BILANUPDATE!U5 -> 942850
A6: FONDS DE ROULEMENT | B6: ='BILAN 2016'!B9 -> 250500 | C6: =+[6]TONT20000DEC2016!$M$56 -> 21000 | D6: =+BILANUPDATE!D6 -> 87000 | E6: =[6]TONT20000JANV2017!$K$56 -> 19000 | F6: =+BILANUPDATE!F6 -> 84000 | G6: =[6]TONT20000FEV2017!$K$56 -> 21000 | H6: =+BILANUPDATE!H6 -> 212000 | I6: =[6]TONT20000MARS2017!$K$56 -> 20000 | J6: =+BILANUPDATE!J6 -> 10000 | K6: =[6]TONT20000AVRIL2017!$K$56 -> 19500 | L6: =+BILANUPDATE!L6 -> 6000 | M6: =[6]TONT20000MAI2017!$K$56 -> 19500 | N6: =+BILANUPDATE!N6 -> 0 | O6: =[6]TONT20000JUIN2017!$K$56 -> 19500 | P6: =+BILANUPDATE!P6 -> 48000 | Q6: =[6]TONT20000JUIL2017!$K$56 -> 19500 | R6: =+BILANUPDATE!R6 -> 13000 | S6: =[7]MVTAOUT2017!$I$53 -> 23000 | T6: =+BILANUPDATE!T6 -> 5000 | U6: =C6+E6+G6+I6+K6+M6+O6+Q6+S6 -> 182000 | V6: =D6+F6+H6+J6+L6+N6+P6+R6+T6 -> 465000 | W6: =+B6+U6-V6 -> -32500 | Y6: =BILANUPDATE!U6 -> 182500
A7: FRAIS EXCEPTIONNELLE | B7: ='BILAN 2016'!B10 -> -599000 | C7: =+[6]TONT20000DEC2016!$N$56 -> 42000 | D7: =+BILANUPDATE!D7 -> 0 | E7: =[6]TONT20000JANV2017!$L$56 -> 38000 | F7: =+BILANUPDATE!F7 -> 0 | G7: =[6]TONT20000FEV2017!$L$56 -> 42000 | H7: =+BILANUPDATE!H7 -> 0 | I7: =[6]TONT20000MARS2017!$L$56 -> 40000 | J7: =+BILANUPDATE!J7 -> 0 | K7: =[6]TONT20000AVRIL2017!$L$56 -> 39000 | L7: =+BILANUPDATE!L7 -> 0 | M7: =[6]TONT20000MAI2017!$L$56 -> 39000 | N7: =+BILANUPDATE!N7 -> 0 | O7: =[6]TONT20000JUIN2017!$L$56 -> 39000 | P7: =+BILANUPDATE!P7 -> 0 | Q7: =[6]TONT20000JUIL2017!$L$56 -> 39000 | R7: =+BILANUPDATE!R7 -> 345000 | S7: =[7]MVTAOUT2017!$J$53 -> 46000 | T7: =+BILANUPDATE!T7 -> 0 | U7: =C7+E7+G7+I7+K7+M7+O7+Q7+S7 -> 364000 | V7: =D7+F7+H7+J7+L7+N7+P7+R7+T7 -> 345000 | W7: =+B7+U7-V7 -> -580000 | Y7: =BILANUPDATE!U7 -> 365000
A8: MUTUELLE | B8: =+'BILAN 2016'!B12 -> -640140 | C8: =+[6]TRAVAUXINVENTAIRE!$O$54 -> 1930123 | D8: =+BILANUPDATE!D8 -> 0 | E8: =[6]TONT20000JANV2017!$N$56 -> 0 | F8: =+BILANUPDATE!F8 -> 200000 | G8: =[6]TONT20000FEV2017!$N$56 -> 0 | H8: =+BILANUPDATE!H8 -> 0 | I8: =[6]TONT20000MARS2017!$N$56 -> 50000 | J8: =+BILANUPDATE!J8 -> 0 | K8: =[6]TONT20000AVRIL2017!$N$56 -> 0 | L8: =+BILANUPDATE!L8 -> 0 | M8: =[6]TONT20000MAI2017!$N$56 -> 0 | N8: =+BILANUPDATE!N8 -> 100000 | O8: =[6]TONT20000JUIN2017!$N$56 -> 0 | P8: =+BILANUPDATE!P8 -> 0 | Q8: =[6]TONT20000JUIL2017!$N$56 -> 0 | R8: =+BILANUPDATE!R8 -> 640000 | S8: =[7]MVTAOUT2017!$L$53 -> 30000 | T8: =+BILANUPDATE!T8 -> 0 | U8: =C8+E8+G8+I8+K8+M8+O8+Q8+S8 -> 2010123 | V8: =D8+F8+H8+J8+L8+N8+P8+R8+T8 -> 940000 | W8: =+B8+U8-V8 -> 429983 | Y8: =BILANUPDATE!U8 -> 1980123
A9: INSCRIPTION | D9: =+BILANUPDATE!D9 -> 0 | F9: =+BILANUPDATE!F9 -> 0 | H9: =+BILANUPDATE!H9 -> 0 | J9: =+BILANUPDATE!J9 -> 0 | L9: =+BILANUPDATE!L9 -> 0 | N9: =+BILANUPDATE!N9 -> 0 | P9: =+BILANUPDATE!P9 -> 0 | R9: =+BILANUPDATE!R9 -> 0 | T9: =+BILANUPDATE!T9 -> 0 | U9: =C9+E9+G9+I9+K9+M9+O9+Q9+S9 -> 0 | V9: =D9+F9+H9+J9+L9+N9+P9+R9+T9 -> 0 | W9: =+B9+U9-V9 -> 0
A10: PENALITE | C10: =+BILANUPDATE!C10 -> 10000 | D10: =+BILANUPDATE!D10 -> 0 | E10: =+BILANUPDATE!E10 -> 36000 | F10: =+BILANUPDATE!F10 -> 0 | G10: =+BILANUPDATE!G10 -> 15000 | H10: =+BILANUPDATE!H10 -> 0 | I10: =+BILANUPDATE!I10 -> 16000 | J10: =+BILANUPDATE!J10 -> 0 | ... T10: =+BILANUPDATE!T10 -> 0 | U10: =C10+E10+G10+I10+K10+M10+O10+Q10+S10 -> 193000 | V10: =D10+F10+H10+J10+L10+N10+P10+R10+T10 -> 0 | W10: =+B10+U10-V10 -> 193000 | Y10: =BILANUPDATE!U10 -> 193000
A11: PENALITE VESEMENT ESPECE | C11: =+[6]TONT20000DEC2016!$I$56 -> 10000 | D11: =+BILANUPDATE!D11 -> 0 | E11: =[6]TONT20000JANV2017!$G$56 -> 36000 | F11: =+BILANUPDATE!F11 -> 0 | G11: =[6]TONT20000FEV2017!$G$56 -> 14000 | H11: =+BILANUPDATE!H11 -> 0 | I11: =[6]TONT20000MARS2017!$G$56 -> 16000 | J11: =+BILANUPDATE!J11 -> 0 | K11: =[6]TONT20000AVRIL2017!$G$56 -> 18000 | L11: =+BILANUPDATE!L11 -> 0 | M11: =[6]TONT20000MAI2017!$G$56 -> 15000 | N11: =+BILANUPDATE!N11 -> 0 | O11: =[6]TONT20000JUIN2017!$G$56 -> 15000 | P11: =+BILANUPDATE!P11 -> 0 | Q11: =[6]TONT20000JUIL2017!$G$56 -> 15000 | R11: =+BILANUPDATE!R11 -> 0 | S11: =[8]TONTAOUT!$F$52 -> 0 | T11: =+BILANUPDATE!T11 -> 0 | U11: =C11+E11+G11+I11+K11+M11+O11+Q11+S11 -> 139000 | V11: =D11+F11+H11+J11+L11+N11+P11+R11+T11 -> 0 | W11: =+B11+U11-V11 -> 139000
A12: REMBOURSEMENT | C12: =+[6]TONT20000DEC2016!$S$56 -> 494400 | D12: =+BILANUPDATE!D12 -> 0 | E12: =+[6]TONT20000JANV2017!$Q$56 -> 309000 | F12: =+BILANUPDATE!F12 -> 0 | G12: =+[6]TONT20000FEV2017!$Q$56 -> 2039000 | H12: =+BILANUPDATE!H12 -> 0 | I12: =+[6]TONT20000MARS2017!$Q$56 -> 1939000 | J12: =+BILANUPDATE!J12 -> 0 | K12: =+[6]TONT20000AVRIL2017!$Q$56 -> 1300000 | L12: =+BILANUPDATE!L12 -> 0 | M12: =+[6]TONT20000MAI2017!$Q$56 -> 4271800 | N12: =+BILANUPDATE!N12 -> 0 | O12: =+[6]TONT20000JUIN2017!$Q$56 -> 1094000 | P12: =+BILANUPDATE!P12 -> 0 | Q12: =+[6]TONT20000JUIL2017!$Q$56 -> 805000 | R12: =+BILANUPDATE!R12 -> 0 | S12: =[7]MVTAOUT2017!$O$53 -> 391000 | T12: =+BILANUPDATE!T12 -> 0 | U12: =C12+E12+G12+I12+K12+M12+O12+Q12+S12 -> 12643200 | W12: =+B12+U12-V12 -> 12643200 | Y12: =BILANUPDATE!U11 -> 13104200
A13: FOYER | U13: =C13+E13+G13+I13+K13+M13+O13+Q13+S13 -> 0 | V13: =D13+F13+H13+J13+L13+N13+P13+R13+T13 -> 0 | W13: =+B13+U13-V13 -> 0 | Y13: =BILANUPDATE!U12 -> 551750
A14: ARGENT GARDE | U14: =C14+E14+G14+I14+K14+M14+O14+Q14+S14 -> 0 | V14: =D14+F14+H14+J14+L14+N14+P14+R14+T14 -> 0 | W14: =+B14+U14-V14 -> 0 | Y14: =BILANUPDATE!U13 -> 300000
A16: TOTAL | B16: =SUM(B3:B15) -> #REF! | C16: =SUM(C3:C15) -> 4969523 | D16: =SUM(D3:D15) -> 599000 | E16: =SUM(E3:E15) -> 940000 | F16: =SUM(F3:F15) -> 394000 | G16: =SUM(G3:G15) -> 2399000 | H16: =SUM(H3:H15) -> 2432000 | I16: =SUM(I3:I15) -> 2815350 | ... W16: =SUM(W3:W15) -> #REF!

Sheet Feuil1
A1: MOIS | B1: FONDS DE CAISSE | D1: EPARGNE | F1: COLLATION | H1: FONDS DE ROULEMENT | J1: FRAIS EXCEPTIONNELLE | L1: MUTUELLE | N1: INSCRIPTION | P1: PENALITE | R1: REMBOURSEMENT | T1: FOYER | V1: ARGENT GARDE | X1: TOTAL
B2: ENTREE | C2: SORTIE | D2: ENTREE | E2: SORTIE | F2: ENTREE | G2: SORTIE | H2: ENTREE | I2: SORTIE | J2: ENTREE | K2: SORTIE | L2: ENTREE | M2: SORTIE | N2: ENTREE | O2: SORTIE | P2: ENTREE | Q2: SORTIE | R2: ENTREE | S2: SORTIE | T2: ENTREE | U2: SORTIE | V2: ENTREE | W2: SORTIE | X2: ENTREE | Y2: SORTIE
A3: REPORT A NOUVEAU NOV 2016 | B3: =+BILANUPDATE!B3 -> 14398519 | D3: =+BILANUPDATE!B4 -> #REF! | F3: =+BILANUPDATE!B5 -> -7500 | H3: =+BILANUPDATE!B6 -> 250500 | J3: =+BILANUPDATE!B7 -> -599000 | L3: =+BILANUPDATE!B8 -> -640140 | X3: =B3+D3+F3+H3+J3+L3+N3+P3+R3+T3+V3 -> #REF! | Y3: =C3+E3+G3+I3+K3+M3+O3+Q3+S3+U3+W3 -> 0
A4: JANVIER 2017
A5: FEVRIER
A6: MARS
A7: AVRIL
A8: MAI
A9: JUIN
A10: JUILLET
A11: AOUT

Sheet Feuil2
A1: SITUATION GLOBALE DE TRESORERIE AU 31 AOUT 2017
A3: LIBELLE BANQUE | B3: SOLDE
A5: CCA | B5: 4477474
A6: AFRILAND FIRST BANK | B6: 4817411
A7: MC2 | B7: 630006
A9: S/TOTAL | B9: =SUM(B5:B8) -> 9924891
A11: PRÊT EN CIRCULATION | B11: =+[4]EMPRUNT!$C$52 -> 0
A13: MASSE MONETAIRE | B13: =B9+B11 -> 9924891
A16: LIBELLE | B16: REPORT | C16: ENTREE | D16: SORTIE | E16: MONTANT
A17: FONDS DE CAISSE/EPARGNE/RELIQUAT | B17: 17924326 | C17: 5087693 | D17: =+B11 -> 0 | E17: =+B17+C17-D17 -> 23012019
A18: COLLATION | B18: =+BILANUPDATEDPA!B5 -> -7500 | C18: =+BILANUPDATE!U5 -> 942850 | D18: =+BILANUPDATE!V5 -> 910000 | E18: =+B18+C18-D18 -> 25350
A19: FONDS DE ROULEMENT | B19: =+BILANUPDATEDPA!B6 -> 250500 | C19: =+BILANUPDATE!U6 -> 182500 | D19: =+BILANUPDATE!V6 -> 465000 | E19: =+B19+C19-D19 -> -32000
A20: FRAIS EXCEPTIONNELLE | B20: =+BILANUPDATEDPA!B7 -> -599000 | C20: =+BILANUPDATE!U7 -> 365000 | D20: =+BILANUPDATE!V7 -> 345000 | E20: =+B20+C20-D20 -> -579000
A21: MUTUELLE | B21: =+BILANUPDATEDPA!B8 -> -640140 | C21: =+BILANUPDATE!U8 -> 1980123 | D21: =+BILANUPDATE!V8 -> 940000 | E21: =+B21+C21-D21 -> 399983
A22: INSCRIPTION | B22: =+BILANUPDATEDPA!B9 -> 0 | C22: =+BILANUPDATE!U9 -> 0 | D22: =+BILANUPDATE!V9 -> 0 | E22: =+B22+C22-D22 -> 0
A23: PENALITE | B23: =+BILANUPDATEDPA!B10 -> 0 | C23: =+BILANUPDATE!U10 -> 193000 | D23: =+BILANUPDATE!V10 -> 0 | E23: =+B23+C23-D23 -> 193000
A24: FOYER | B24: =+BILANUPDATEDPA!B11 -> 0 | C24: =+BILANUPDATE!W12 -> 551750 | D24: =+BILANUPDATE!V11 -> 0 | E24: =+B24+C24-D24 -> 551750
A25: ARGENT GARDE | B25: =+BILANUPDATEDPA!B12 -> 0 | C25: =+BILANUPDATE!W13 -> 300000 | D25: =+BILANUPDATE!V12 -> 0 | E25: =+B25+C25-D25 -> 300000
A27: TOTAL | B27: =SUM(B17:B26) -> 16928186 | C27: =SUM(C17:C26) -> 9602916 | D27: =SUM(D17:D26) -> 2660000 | E27: =+B27+C27-D27 -> 23871102

Sheet Feuil2 (2)
A2: SITUATION GLOBALE DE TRESORERIE AU 31 AOUT 2017
A4: LIBELLE BANQUE | B4: SOLDE
A6: CCA | B6: 4477474
A7: AFRILAND FIRST BANK | B7: 4817411
A8: MC2 | B8: 630005
B10: =SUM(B6:B9) -> 9924890
A12: PRÊT EN CIRCULATION | B12: =+[4]EMPRUNT!$C$52 -> 0
A14: MASSE MONETAIRE | B14: =B10+B12 -> 9924890
A18: LIBELLE | B18: MONTANT
A19: FONDS DE CAISSE | B19: =+[9]BILANUPDATEDPA!W3 -> 15448519
A20: EPARGNE | B20: =+[9]BILANUPDATEDPA!W4 -> 7578500
A21: COLLATION | B21: =+[9]BILANUPDATE!W5 -> 25350
A22: FONDS DE ROULEMENT | B22: =+[9]BILANUPDATE!W6 -> -32000
A23: FRAIS EXCEPTIONNELLE | B23: =+[9]BILANUPDATE!W7 -> -579000
A24: MUTUELLE | B24: =+[9]BILANUPDATE!W8 -> 399983
A25: INSCRIPTION | B25: =+[9]BILANUPDATE!W9 -> 0
A26: PENALITE | B26: =+[9]BILANUPDATE!W10 -> 193000
A27: FOYER | B27: =+[9]BILANUPDATE!W12 -> 551750
A28: ARGENT GARDE | B28: =+[9]BILANUPDATE!W13 -> 300000
A30: TOTAL | B30: =SUM(B19:B29) -> 23886102
A32: DIFFERENCE | B32: =B30-B14 -> 13961212
