Workbook
Name BANQUE: #REF!
Name BANQUE: #REF!
Name BANQUE: #REF!
Name BANQUE: #REF!
Name BANQUE: #REF!
Name BANQUE: #REF!
Name BANQUE: #REF!
Name BANQUE: #REF!
Name BANQUE: #REF!
Name BANQUE: #REF!
Name BANQUE: #REF!
Name BANQUE: #REF!
Name BANQUE: #REF!
Name BANQUE: #REF!
Name BANQUE: #REF!
Name MODEET30000: [1]MODEVERSEMENT!$A$1:$A$3
Name MODEPAID: [2]Feuil2!$A$1:$A$3
Name MODEPAID: [2]Feuil2!$A$1:$A$3
Name MODEPAID: [2]Feuil2!$A$1:$A$3
Name MODEPAID: [3]Feuil2!$A$1:$A$3
Name MODEPAID: [4]Feuil2!$A$1:$A$3
Name MODEPAID30000: DETAILFICHECASSATION!#REF!
Name MODEPAIDOK: [5]MODEVERSEMENT!$A$1:$A$4
Name MODEPAIDOK: [5]MODEVERSEMENT!$A$1:$A$4
Name MODEPAIDS: [1]MODEVERSEMENT!$A$1:$A$3
Name MODET25000: [6]MODEVERSEMENT!$A$1:$A$3
Name MODET3000: [1]MODEVERSEMENT!$A$1:$A$3
Name MODET30000: DETAILFICHECASSATION!#REF!
Name MODEVERSEMENT: #REF!
Name MODEVERSEMENT: #REF!
Name MODEVERSEMENT: #REF!
Name MODEVERSEMENT: #REF!
Name MODEVERSEMENT: #REF!
Name MODEVERSEMENT: #REF!
Name MODEVERSEMENT: #REF!
Name MODEVERSEMENT: #REF!
Name MODEVERSEMENT: #REF!
Name MODEVERSEMENT: #REF!
Name MODEVERSEMENT: #REF!
Name MODEVERSEMENT: #REF!
Name MODEVERSEMENT: #REF!
Name MODEVERSEMENT: #REF!
Name MODEVERSEMENT: #REF!
Name MODEVERSEMENTS: [7]MODEVERSEMENT!$A$1:$A$3
Name MODPAID: DETAILFICHECASSATION!#REF!
Name VALMODEPAID: [8]MODEPAID!$A$1:$A$3

Sheet BILAN 2016
A2: BILAN ALLANT DE LA PERIODE DU 01 DECEMBRE 2015 AU 30 NOVEMBRE 2016
A5: RUBRIQUE | B5: REPORT A NOUVEAU | C5: ENTREES | D5: SORTIES | E5: SOLDE
A7: EPARGNE\RELIQUAT2015 | B7: 29756024 | C7: =[9]TRAVAUXINVENTAIRE!R54+C20+1050000+2230668 -> 7101809 | E7: =B7+C7-D7 -> 36857833
A8: FONDS DE CAISSE | C8: 28382451 | D8: 39386431 | E8: =B8+C8-D8 -> -11003980
A9: FONDS DE ROULEMENT | B9: 3031178 | C9: =[9]TRAVAUXINVENTAIRE!S54 -> 250500 | D9: ='[10]BILAN 2016'!$D$9 -> 224500 | E9: =B9+C9-D9 -> 3057178
A10: FRAIS EXCEPTIONNELS | B10: 1267460 | C10: =[9]TRAVAUXINVENTAIRE!T54 -> 501000 | D10: =[9]TRAVAUXINVENTAIREDEC!B6 -> 1100000 | E10: =B10+C10-D10 -> 668460
A11: COLLATION | B11: 940125 | C11: =[9]TRAVAUXINVENTAIRE!U54 -> 1252500 | D11: =[9]TRAVAUXINVENTAIREDEC!B7 -> 1260000 | E11: =B11+C11-D11 -> 932625
A12: MUTUELLE\COMPLEMENT MUTUEL | B12: =-101500 -> -101500 | C12: =[9]TRAVAUXINVENTAIRE!V54+[9]TRAVAUXINVENTAIRE!O54 -> 1954860 | D12: =[9]TRAVAUXINVENTAIREDEC!B8 -> 2595000 | E12: =B12+C12-D12 -> -741640
A13: INSCRIPTION | B13: 530000 | E13: =B13+C13-D13 -> 530000
A14: FONDS GELE | B14: 54508 | E14: =B14+C14-D14 -> 54508
A15: CHAISE | B15: -164500 | E15: =B15+C15-D15 -> -164500
A16: TENUE | B16: -75000 | E16: =B16+C16-D16 -> -75000
A17: FOYER | E17: =B17+C17-D17 -> 0
A18: RECOUVREMENT POUR LAGWEU GENERAL | C18: =320750+16500 -> 337250 | E18: =B18+C18-D18 -> 337250 | F18: 1711250
A19: AUTRES | E19: =B19+C19-D19 -> 0
A20: INTERET EMPRUNT | E20: =B20+C20-D20 -> 0
A22: EMPRUNT
A24: RELIQUAT 2016
A27: COMPTE CCA
A28: COMPTE AFRILAND
A29: INTERET BQUE AFRILAND | B29: 1779594 | E29: =B29+C29-D29 -> 1779594
A30: COMPTE MC2
A31: ASELBY CAISSE(NDJOMO ETIENNE)
A33: RETRAIT DISTRIBUTION EPARGNE
A35: SOUS TOTAL
A37: MONTANT DISPONIBLE | B37: =SUM(B7:B36) -> 37017889 | C37: =SUM(C7:C36) -> 39780370 | D37: =SUM(D7:D36) -> 44565931 | E37: =B37+C37-D37 -> 32232328

Sheet BILAN 2017
A2: BILAN ALLANT DE LA PERIODE DU 01 DECEMBRE 2016 AU 30 AOUT 2017
A5: RUBRIQUE | B5: REPORT A NOUVEAU | C5: ENTREES | D5: SORTIES | E5: SOLDE
A7: EPARGNE\RELIQUAT2016 | B7: ='BILAN 2016'!E7 -> 36857833 | C7: =[11]BILANFINAOUT2017!E56 -> 3963693 | D7: 13500000 | E7: =B7+C7-D7 -> 27321526
A8: FONDS DE CAISSE | B8: ='BILAN 2016'!E8 -> -11003980 | C8: =[11]BILANFINAOUT2017!C56 -> 16310819 | E8: =B8+C8-D8 -> 5306839
A9: FONDS DE ROULEMENT | B9: ='BILAN 2016'!E9 -> 3057178 | C9: =[11]BILANFINAOUT2017!F56 -> 182000 | D9: =89000+84000+12000+10000+6000+48000+13000+5000 -> 267000 | E9: =B9+C9-D9 -> 2972178
A10: FRAIS EXCEPTIONNELS | B10: ='BILAN 2016'!E10 -> 668460 | C10: =[11]BILANFINAOUT2017!G56 -> 364000 | D10: =200000+345000 -> 545000 | E10: =B10+C10-D10 -> 487460
A11: COLLATION | B11: ='BILAN 2016'!E11 -> 932625 | C11: =[11]BILANFINAOUT2017!H56 -> 910000 | D11: =100000+110000+100000+100000+100000+100000+100000+100000+100000 -> 910000 | E11: =B11+C11-D11 -> 932625
A12: MUTUELLE\COMPLEMENT MUTUEL | B12: ='BILAN 2016'!E12 -> -741640 | C12: =[11]BILANFINAOUT2017!I56 -> 2009927 | D12: =200000+100000+640000 -> 940000 | E12: =B12+C12-D12 -> 328287
A13: PENALITE VERSEMENT EN ESPECES | C13: =[11]BILANFINAOUT2017!R56 -> 125000 | E13: =B13+C13-D13 -> 125000
A14: SANCTION | C14: =+[11]BILANFINAOUT2017!J56 -> 0
A15: INSCRIPTION | B15: ='BILAN 2016'!E13 -> 530000 | E15: =B15+C15-D15 -> 530000
A16: FONDS GELE | B16: ='BILAN 2016'!E14 -> 54508 | E16: =B16+C16-D16 -> 54508
A17: CHAISE | B17: ='BILAN 2016'!E15 -> -164500 | E17: =B17+C17-D17 -> -164500
A18: TENUE | B18: ='BILAN 2016'!E16 -> -75000 | E18: =B18+C18-D18 -> -75000
E19: =B19+C19-D19 -> 0
A20: FOYER | E20: =B20+C20-D20 -> 0
A21: RECOUVREMENT POUR LAGWEU GENERAL | B21: ='BILAN 2016'!E18 -> 337250 | E21: =B21+C21-D21 -> 337250
A22: AUTRES
A23: INTERET EMPRUNT
A25: EMPRUNT | E25: =B25+C25-D25 -> 0
A27: RELIQUAT 2016
A29: INTERET BQUE AFRILAND | B29: 1779594 | E29: =B29+C29-D29 -> 1779594
A30: COMPTE CCA
A31: COMPTE AFRILAND
A32: COMPTE MC2
A33: ASELBY CAISSE(NDJOMO ETIENNE)
A35: RETRAIT DISTRIBUTION EPARGNE
A39: MONTANT DISPONIBLE | B39: =SUM(B7:B38) -> 32232328 | C39: =SUM(C7:C38) -> 23865439 | D39: =SUM(D7:D38) -> 16162000 | E39: =B39+C39-D39 -> 39935767

Sheet BILAN 2022
B1: ASELBY
B2: ANNEE | C2: 2022
B3: SYNTHESE DES COMPTES
A6: NUMERO ORDRE | B6: RUBRIQUE | C6: REPORT A NOUVEAU | D6: ENTREES | E6: SORTIES | F6: SOLDE
A8: 1 | B8: FONDS DE CAISSE ET RELIQUAT | C8: 21791466 | E8: 500000 | F8: 21291466
A9: 2 | B9: FONDS DE ROULEMENT | C9: 2074728 | D9: 156000 | E9: 234500 | F9: 1996228
A10: 3 | B10: FRAIS EXCEPTIONNELS | C10: 1191460 | D10: 312000 | E10: 0 | F10: 1503460
A11: 4 | B11: MUTUELLE\COMPLEMENT MUTUEL | C11: 94762 | D11: 520000 | E11: 0 | F11: =C11+D11 -> 614762
A12: 5 | B12: INSCRIPTION | C12: 680000 | D12: 0 | E12: 0 | F12: 680000
A13: 6 | B13: PENALITES | C13: 1122025 | D13: 96000 | E13: 450000 | F13: 768025
A14: 7 | B14: COLLATION | C14: 1310525 | D14: 780000 | E14: 770000 | F14: 1320525
A15: 8 | B15: TONTINE DE PRESENCE | C15: 94000 | F15: 94000
A16: 9 | B16: RECOUVREMENT POUR LA'AGWEU | F16: 0
A17: 10 | B17: FOYER | C17: 527000 | D17: 1836000 | E17: 1820000 | F17: 543000
A18: 11 | B18: CHAISES | C18: 164500 | E18: 164500 | F18: 0
A19: 12 | B19: DIVERS | C19: 619900 | E19: 619900 | F19: 0
A20: 13 | B20: TENUES | C20: 75000 | E20: 75000 | F20: 0
A21: 14 | B21: FONDS GELES | C21: 54508 | E21: 54508 | F21: 0
A22: 15 | B22: INTERETS ET AUTRES | C22: 2858226 | D22: 3748108 | F22: 6606334
B23: INTERET TONTINE 100 | D23: 28000 | F23: 28000
B25: TOTAL | C25: 32658100 | D25: =SUM(D9:D23) -> 7476108 | E25: 4688408 | F25: =SUM(F8:F23) -> 35445800 | H25: 479000
B27: DISPOSITION DES FONDS
C30: 2021 | D30: 2022
A31: 1 | B31: COMPTE CCA AU 30/12/2022 | C31: 7304779 | D31: 4337431
A32: 2 | B32: COMPTE MC²(NON ACTUALISE) | C32: 630005 | D32: 630005
A33: 3 | B33: COMPTE AFRILAND | C33: 1423702 | D33: 1423702
A34: 4 | B34: DETTE PREFINANCEMENT LA'AGWEU | C34: 744700 | D34: 744700
A35: 5 | B35: DETTE MR KOUATCHO | C35: 275000 | D35: 0
A36: 6 | B36: RESTE A RECUPERE AU CONSEIL | C36: 154000 | D36: 154000
A37: 7 | B37: FONDS EN CIRCULATION | C37: 20515659 | D37: 18658500
A38: 8 | B38: DETTES TONTINES | C38: 1233618 | D38: 656618
B40: TOTAL | C40: 32281463 | D40: 26604956

Sheet BILAN 2024
B1: ASELBY
B2: ANNEE | C2: 2024
B3: SYNTHESE DES COMPTES
A6: NUMERO ORDRE | B6: RUBRIQUE | C6: REPORT A NOUVEAU | D6: ENTREES | E6: SORTIES | F6: SOLDE
A8: ='BILAN 2024'!A8 -> 1 | B8: ='BILAN 2024'!B8 -> FONDS DE CAISSE ET RECONDUCTION | C8: =SYNTHESECOMPTE!C5 -> 23877869 | D8: =800000*6+100000*24 -> 7200000 | E8: =7077869-6896797 -> 181072 | F8: =C8+D8-E8 -> 30896797
A9: ='BILAN 2024'!A9 -> 2 | B9: ='BILAN 2024'!B9 -> FONDS DE ROULEMENT | C9: =SYNTHESECOMPTE!C6 -> 2160228 | D9: ='BILAN 2024'!D9 -> 384000 | E9: ='BILAN 2024'!E9 -> 251000 | F9: =C9+D9-E9 -> 2293228
A10: ='BILAN 2024'!A10 -> 3 | B10: ='BILAN 2024'!B10 -> FRAIS EXCEPTIONNELS | C10: =SYNTHESECOMPTE!C7 -> 1038460 | D10: ='BILAN 2024'!D10 -> 384000 | E10: ='BILAN 2024'!E10 -> 0 | F10: =C10+D10-E10 -> 1422460
A11: ='BILAN 2024'!A11 -> 4 | B11: ='BILAN 2024'!B11 -> MUTUELLE\COMPLEMENT MUTUEL | C11: =SYNTHESECOMPTE!C8 -> 814762 | D11: ='BILAN 2024'!D11 -> 240000 | E11: ='BILAN 2024'!E11 -> 200000 | F11: =C11+D11-E11 -> 854762
A12: ='BILAN 2024'!A12 -> 5 | B12: ='BILAN 2024'!B12 -> INSCRIPTION | C12: =SYNTHESECOMPTE!C9 -> 755000 | D12: ='BILAN 2024'!D12 -> 75000 | E12: ='BILAN 2024'!E12 -> 0 | F12: =C12+D12-E12 -> 830000
A13: ='BILAN 2024'!A13 -> 6 | B13: ='BILAN 2024'!B13 -> PENALITES PAIEMENT ESPECES | C13: =SYNTHESECOMPTE!C10 -> 847025 | D13: ='BILAN 2024'!D13 -> 93000 | E13: ='BILAN 2024'!E13 -> 0 | F13: =C13+D13-E13 -> 940025
A14: ='BILAN 2024'!A14 -> 7 | B14: SANCTION | C14: =SYNTHESECOMPTE!C11 -> 7000 | D14: ='BILAN 2024'!D14 -> 3750 | E14: ='BILAN 2024'!E14 -> 0 | F14: =C14+D14-E14 -> 10750
A15: ='BILAN 2024'!A15 -> 8 | B15: ='BILAN 2024'!B15 -> COLLATION | C15: =SYNTHESECOMPTE!C12 -> 1632525 | D15: ='BILAN 2024'!D15 -> 1536000 | E15: ='BILAN 2024'!E15 -> 1200000 | F15: =C15+D15-E15 -> 1968525
A16: ='BILAN 2024'!A16 -> 9 | B16: INTERET COMPTE AFRILAND | C16: =SYNTHESECOMPTE!C13 -> 124127 | D16: 11701 | F16: =C16+D16-E16 -> 135828
A17: ='BILAN 2024'!A17 -> 10 | B17: ='[12]BILAN 2024'!B18 -> FOYER | C17: =SYNTHESECOMPTE!C14 -> 1010525 | D17: ='BILAN 2024'!D18 -> 0 | E17: ='BILAN 2024'!E18 -> 0 | F17: =C17+D17-E17 -> 1010525
A18: ='BILAN 2024'!A18 -> 11 | B18: ='[12]BILAN 2024'!B23 -> INTERETS ET AUTRES | C18: =SYNTHESECOMPTE!C15 -> 101230 | D18: ='BILAN 2024'!D23 -> 0 | E18: ='BILAN 2024'!E23 -> 0 | F18: =C18+D18-E18 -> 101230
A19: 12 | B19: TERRAIN | C19: =SYNTHESECOMPTE!C16 -> -6000000 | E19: 9300000 | F19: =C19+D19-E19 -> -15300000
B27: TOTAL | C27: =SUM(C8:C26) -> 26368751 | D27: =SUM(D8:D26) -> 0
B29: DISPOSITION DES FONDS
C32: 2023 | D32: 2024
A33: 1 | B33: COMPTE CCA AU 30/12/2022 | C33: 4337431
A34: 2 | B34: COMPTE MC²(NON ACTUALISE) | C34: 630005 | D34: =C34+10000 -> 640005
A35: 3 | B35: COMPTE AFRILAND | C35: 1423702 | D35: 5265069
A36: 4 | B36: DETTE PREFINANCEMENT LA'AGWEU | C36: 744700
A37: 5 | B37: DETTE MR KOUATCHO | C37: 0
A38: 6 | B38: RESTE A RECUPERE AU CONSEIL | C38: 154000
A39: 7 | B39: FONDS EN CIRCULATION | C39: 18658500 | D39: ='DETAIL PRETENCIRCULATION'!C42+'DETAIL PRETENCIRCULATION'!C52 -> #N/A
A40: 8 | B40: DETTES TONTINES | C40: 656618
B42: TOTAL | C42: =SUM(C33:C41) -> 26604956 | D42: =SUM(D33:D41) -> #N/A

Sheet ENTREE
D2: ENTREE DES DIFFERENTES RUBRIQUES
A3: ANNEE | E3: 2024
A6: MOIS | B6: FONDS DE CAISSE | C6: RELIQUAT | D6: INTERET | E6: EPARGNE | F6: FONDS DE ROULEMENT | G6: FRAIS EXCEPTIONNEL | H6: COLLATION | I6: PENALITE VST ESPECES | J6: INSCRIPTION | K6: MUTUELLE | L6: REMBOURSEMENT | M6: SANCTION | N6: FOYER | O6: INTERET TONTINE | P6: TOTAL
A7: REPORT | B7: =[13]MVTRESUME24!#REF! -> #REF! | C7: =[13]MVTRESUME24!#REF! -> #REF! | D7: =[13]MVTDEC23!$T$41 -> 1168000
A8: JANVIER | D8: =#REF! -> #REF! | E8: =#REF! -> #REF! | F8: =#REF! -> #REF! | G8: =#REF! -> #REF! | H8: =#REF! -> #REF! | I8: =#REF! -> #REF! | J8: =#REF! -> #REF! | K8: =#REF! -> #REF! | ... N8: =#REF! -> #REF! | P8: =SUM(B8:O8) -> #REF!
A9: FÉVRIER | D9: =[13]MVTFEV24!$T$41 -> 26000 | E9: =[13]MVTFEV24!$L$41 -> 720000 | F9: =[13]MVTFEV24!$M$41 -> 32000 | G9: =[13]MVTFEV24!$N$41 -> 32000 | H9: =[13]MVTFEV24!$O$41 -> 128000 | I9: =[13]MVTFEV24!$P$41 -> 9000 | J9: =[13]MVTFEV24!$Q$41 -> 0 | K9: =[13]MVTFEV24!$R$41 -> 0 | L9: =[13]MVTFEV24!$V$41 -> 1000000 | M9: =[13]MVTFEV24!$J$41 -> 0 | N9: =[13]MVTFEV24!$AE$41 -> 0 | P9: =SUM(B9:O9) -> 1947000
A10: MARS | D10: =[13]MVTMARS24!$T$41 -> 92500 | E10: =[13]MVTMARS24!$L$41 -> 759000 | F10: =[13]MVTMARS24!$M$41 -> 32000 | G10: =[13]MVTMARS24!$N$41 -> 32000 | H10: =[13]MVTMARS24!$O$41 -> 128000 | I10: =[13]MVTMARS24!$P$41 -> 6000 | J10: =[13]MVTMARS24!$Q$41 -> 0 | K10: =[13]MVTMARS24!$R$41 -> 0 | L10: =[13]MVTMARS24!$V$41 -> 750000 | M10: =[13]MVTMARS24!$J$41 -> 0 | N10: =[13]MVTMARS24!$AE$41 -> 0 | P10: =SUM(B10:O10) -> 1799500
A11: AVRIL | D11: =[13]MVTAVRIL24!$T$41 -> 0 | E11: =[13]MVTAVRIL24!$L$41 -> 778500 | F11: =[13]MVTAVRIL24!$M$41 -> 32000 | G11: =[13]MVTAVRIL24!$N$41 -> 32000 | H11: =[13]MVTAVRIL24!$O$41 -> 128000 | I11: =[13]MVTAVRIL24!$P$41 -> 12000 | J11: =[13]MVTAVRIL24!$Q$41 -> 0 | K11: =[13]MVTAVRIL24!$R$41 -> 0 | L11: =[13]MVTAVRIL24!$V$41 -> 0 | M11: =[13]MVTAVRIL24!$J$41 -> 0 | N11: =[13]MVTAVRIL24!$AE$41 -> 0 | P11: =SUM(B11:O11) -> 982500
A12: MAI | D12: =[13]MVTMAI24!$T$41 -> 84000 | E12: =[13]MVTMAI24!$L$41 -> 725000 | F12: =[13]MVTMAI24!$M$41 -> 32000 | G12: =[13]MVTMAI24!$N$41 -> 32000 | H12: =[13]MVTMAI24!$O$41 -> 128000 | I12: =[13]MVTMAI24!$P$41 -> 9000 | J12: =[13]MVTMAI24!$Q$41 -> 0 | K12: =[13]MVTMAI24!$R$41 -> 0 | L12: =[13]MVTMAI24!$V$41 -> 1500000 | M12: =[13]MVTMAI24!$J$41 -> 0 | N12: =[13]MVTMAI24!$AE$41 -> 0 | P12: =SUM(B12:O12) -> 2510000
A13: JUIN | D13: =[13]MVTJUIN24!$T$41 -> 110000 | E13: =[13]MVTJUIN24!$L$41 -> 724500 | F13: =[13]MVTJUIN24!$M$41 -> 32000 | G13: =[13]MVTJUIN24!$N$41 -> 32000 | H13: =[13]MVTJUIN24!$O$41 -> 128000 | I13: =[13]MVTJUIN24!$P$41 -> 6000 | J13: =[13]MVTJUIN24!$Q$41 -> 0 | K13: =[13]MVTJUIN24!$R$41 -> 0 | L13: =[13]MVTJUIN24!$V$41 -> 360000 | M13: =[13]MVTJUIN24!$J$41 -> 0 | N13: =[13]MVTJUIN24!$AE$41 -> 0 | P13: =SUM(B13:O13) -> 1392500
A14: JUILLET | D14: =[13]MVTJUIL24!$T$41 -> 128400 | E14: =[13]MVTJUIL24!$L$41 -> 1698100 | F14: =[13]MVTJUIL24!$M$41 -> 32000 | G14: =[13]MVTJUIL24!$N$41 -> 32000 | H14: =[13]MVTJUIL24!$O$41 -> 128000 | I14: =[13]MVTJUIL24!$P$41 -> 12000 | J14: =[13]MVTJUIL24!$Q$41 -> 0 | K14: =[13]MVTJUIL24!$R$41 -> 0 | L14: =[13]MVTJUIL24!$V$41 -> 1738500 | M14: =[13]MVTJUIL24!$J$41 -> 0 | N14: =[13]MVTJUIL24!$AE$41 -> 0 | P14: =SUM(B14:O14) -> 3769000
A15: AOÛT | D15: =[13]MVTAOUT24!$T$41 -> 20000 | E15: =[13]MVTAOUT24!$L$41 -> 658500 | F15: =[13]MVTAOUT24!$M$41 -> 31000 | G15: =[13]MVTAOUT24!$N$41 -> 31000 | H15: =[13]MVTAOUT24!$O$41 -> 124000 | I15: =[13]MVTAOUT24!$P$41 -> 3000 | J15: =[13]MVTAOUT24!$Q$41 -> 0 | K15: =[13]MVTAOUT24!$R$41 -> 0 | L15: =[13]MVTAOUT24!$V$41 -> 0 | M15: =[13]MVTAOUT24!$J$41 -> 0 | N15: =[13]MVTAOUT24!$AE$41 -> 0 | P15: =SUM(B15:O15) -> 867500
A16: SEPTEMBRE | D16: =[13]MVTSEPT24!$T$41 -> 20000 | E16: =[13]MVTSEPT24!$L$41 -> 1585250 | F16: =[13]MVTSEPT24!$M$41 -> 33000 | G16: =[13]MVTSEPT24!$N$41 -> 33000 | H16: =[13]MVTSEPT24!$O$41 -> 132000 | I16: =[13]MVTSEPT24!$P$41 -> 18000 | J16: =[13]MVTSEPT24!$Q$41 -> 0 | K16: =[13]MVTSEPT24!$R$41 -> 120000 | L16: =[13]MVTSEPT24!$V$41 -> 0 | M16: =[13]MVTSEPT24!$J$41 -> 0 | N16: =[13]MVTSEPT24!$AE$41 -> 380000 | P16: =SUM(B16:O16) -> 2321250
A17: OCTOBRE | D17: =[13]MVTOCT24!$T$41 -> 0 | E17: =[13]MVTOCT24!$L$41 -> 734000 | F17: =[13]MVTOCT24!$M$41 -> 32000 | G17: =[13]MVTOCT24!$N$41 -> 32000 | H17: =[13]MVTOCT24!$O$41 -> 128000 | I17: =[13]MVTOCT24!$P$41 -> 6000 | J17: =[13]MVTOCT24!$Q$41 -> 0 | K17: =[13]MVTOCT24!$R$41 -> 0 | L17: =[13]MVTOCT24!$V$41 -> 100000 | M17: =[13]MVTOCT24!$J$41 -> 0 | N17: =[13]MVTOCT24!$AE$41 -> 20000 | P17: =SUM(B17:O17) -> 1052000
A18: NOVEMBRE | D18: =[13]MVTNOV24!$T$41 -> 10000 | E18: =[13]MVTNOV24!$L$41 -> 678500 | F18: =[13]MVTNOV24!$M$41 -> 32000 | G18: =[13]MVTNOV24!$N$41 -> 32000 | H18: =[13]MVTNOV24!$O$41 -> 128000 | I18: =[13]MVTNOV24!$P$41 -> 15000 | J18: =[13]MVTNOV24!$Q$41 -> 0 | K18: =[13]MVTNOV24!$R$41 -> 0 | L18: =[13]MVTNOV24!$V$41 -> 1190000 | M18: =[13]MVTNOV24!$J$41 -> 0 | N18: =[13]MVTNOV24!$AE$41 -> 0 | P18: =SUM(B18:O18) -> 2085500
A19: DÉCEMBRE | D19: =[13]MVTDEC24!$T$41 -> #N/A | E19: =[13]MVTDEC24!$L$41 -> #N/A | F19: =[13]MVTDEC24!$M$41 -> #N/A | G19: =[13]MVTDEC24!$N$41 -> #N/A | H19: =[13]MVTDEC24!$O$41 -> #N/A | I19: =[13]MVTDEC24!$P$41 -> #N/A | J19: =[13]MVTDEC24!$Q$41 -> #N/A | K19: =[13]MVTDEC24!$R$41 -> #N/A | L19: =[13]MVTDEC24!$V$41 -> #N/A | M19: =[13]MVTDEC24!$J$41 -> #N/A | N19: =[13]MVTDEC24!$AE$41 -> #N/A | O19: =[14]TONTRESUME23!$S$6+[15]TONTRESUME23!$S$6 -> 63707.983 | P19: =SUM(B19:O19) -> #N/A
A21: TOTAL | B21: =SUM(B8:B20) -> 0 | C21: =SUM(C8:C20) -> 0 | D21: =SUM(D7:D20) -> #REF! | E21: =SUM(E8:E20) -> #REF! | F21: =SUM(F8:F20) -> #REF! | G21: =SUM(G8:G20) -> #REF! | H21: =SUM(H8:H20) -> #REF! | I21: =SUM(I8:I20) -> #REF! | J21: =SUM(J8:J20) -> #REF! | K21: =SUM(K8:K20) -> #REF! | L21: =SUM(L8:L20) -> #REF! | ... P21: =SUM(P8:P20) -> #REF!

Sheet SORTIE
C2: SORTIE DES DIFFERENTES RUBRIQUES
A3: ANNEE | B3: 2023-2024
A6: MOIS | B6: FONDS DE CAISSE | C6: EPARGNE | D6: FONDS DE ROULEMENT | E6: FRAIS EXCEPTIONNEL | F6: COLLATION | G6: PENALITE VST ESPECES | H6: INSCRIPTION | I6: MUTUELLE | J6: PRÊT | K6: PENALITE | L6: FOYER | M6: TOTAL
A7: REPORT | J7: =[13]MVTDEC23!$S$41 -> 15088500
A8: JANVIER | D8: =#REF! -> #REF! | E8: =#REF! -> #REF! | F8: =#REF! -> #REF! | G8: =#REF! -> #REF! | I8: =#REF! -> #REF! | J8: =#REF! -> #REF! | M8: =SUM(C8:K8) -> #REF!
A9: FÉVRIER | D9: =[13]MVTFEV24!$AF$41 -> 27000 | E9: =[13]MVTFEV24!$AG$41 -> 0 | F9: =[13]MVTFEV24!$AI$41 -> 100000 | G9: =[13]MVTFEV24!$AA$41 -> 0 | I9: =[13]MVTFEV24!$AH$41 -> 100000 | J9: =[13]MVTFEV24!$V$41 -> 1000000 | M9: =SUM(C9:K9) -> 1227000
A10: MARS | D10: =[13]MVTMARS24!$AF$41 -> 48000 | E10: =[13]MVTMARS24!$AG$41 -> 0 | F10: =[13]MVTMARS24!$AI$41 -> 100000 | G10: =[13]MVTMARS24!$AA$41 -> 0 | I10: =[13]MVTMARS24!$AH$41 -> 0 | J10: =[13]MVTMARS24!$V$41 -> 750000 | M10: =SUM(C10:K10) -> 898000
A11: AVRIL | D11: =[13]MVTAVRIL24!$AF$41 -> 21000 | E11: =[13]MVTAVRIL24!$AG$41 -> 100000 | F11: =[13]MVTAVRIL24!$AI$41 -> 100000 | G11: =[13]MVTAVRIL24!$AA$41 -> 0 | I11: =[13]MVTAVRIL24!$AH$41 -> 0 | J11: =[13]MVTAVRIL24!$V$41 -> 0 | M11: =SUM(C11:K11) -> 221000
A12: MAI | D12: =[13]MVTMAI24!$AF$41 -> 19000 | E12: =[13]MVTMAI24!$AG$41 -> 0 | F12: =[13]MVTMAI24!$AI$41 -> 100000 | G12: =[13]MVTMAI24!$AA$41 -> 0 | I12: =[13]MVTMAI24!$AH$41 -> 0 | J12: =[13]MVTMAI24!$V$41 -> 1500000 | M12: =SUM(C12:K12) -> 1619000
A13: JUIN | D13: =[13]MVTJUIN24!$AF$41 -> 12000 | E13: =[13]MVTJUIN24!$AG$41 -> 0 | F13: =[13]MVTJUIN24!$AI$41 -> 100000 | G13: =[13]MVTJUIN24!$AA$41 -> 0 | I13: =[13]MVTJUIN24!$AH$41 -> 0 | J13: =[13]MVTJUIN24!$V$41 -> 360000 | M13: =SUM(C13:K13) -> 472000
A14: JUILLET | D14: =[13]MVTJUIL24!$AF$41 -> 42000 | E14: =[13]MVTJUIL24!$AG$41 -> 288500 | F14: =[13]MVTJUIL24!$AI$41 -> 100000 | G14: =[13]MVTJUIL24!$AA$41 -> 0 | I14: =[13]MVTJUIL24!$AH$41 -> 0 | J14: =[13]MVTJUIL24!$V$41 -> 1738500 | M14: =SUM(C14:K14) -> 2169000
A15: AOÛT | D15: =[13]MVTAOUT24!$AF$41 -> 6000 | E15: =[13]MVTAOUT24!$AG$41 -> 0 | F15: =[13]MVTAOUT24!$AI$41 -> 100000 | G15: =[13]MVTAOUT24!$AA$41 -> 0 | I15: =[13]MVTAOUT24!$AH$41 -> 0 | J15: =[13]MVTAOUT24!$V$41 -> 0 | M15: =SUM(C15:K15) -> 106000
A16: SEPTEMBRE | D16: =[13]MVTSEPT24!$AF$41 -> 6000 | E16: =[13]MVTSEPT24!$AG$41 -> 0 | F16: =[13]MVTSEPT24!$AI$41 -> 100000 | G16: =[13]MVTSEPT24!$AA$41 -> 0 | I16: =[13]MVTSEPT24!$AH$41 -> 0 | J16: =[13]MVTSEPT24!$V$41 -> 0 | M16: =SUM(C16:K16) -> 106000
A17: OCTOBRE | D17: =[13]MVTOCT24!$AF$41 -> 6000 | E17: =[13]MVTOCT24!$AG$41 -> 321500 | F17: =[13]MVTOCT24!$AI$41 -> 100000 | G17: =[13]MVTOCT24!$AA$41 -> 0 | I17: =[13]MVTOCT24!$AH$41 -> 0 | J17: =[13]MVTOCT24!$V$41 -> 100000 | M17: =SUM(C17:K17) -> 527500
A18: NOVEMBRE | D18: =[13]MVTNOV24!$AF$41 -> 6000 | E18: =[13]MVTNOV24!$AG$41 -> 50000 | F18: =[13]MVTNOV24!$AI$41 -> 106000 | G18: =[13]MVTNOV24!$AA$41 -> 0 | I18: =[13]MVTNOV24!$AH$41 -> 100000 | J18: =[13]MVTNOV24!$V$41 -> 1190000 | M18: =SUM(C18:K18) -> 1452000
A19: DÉCEMBRE | D19: =[13]MVTDEC24!$AF$41 -> #N/A | E19: =[13]MVTDEC24!$AG$41 -> #N/A | F19: =[13]MVTDEC24!$AI$41 -> #N/A | G19: =[13]MVTDEC24!$AA$41 -> 0 | I19: =[13]MVTDEC24!$AH$41 -> #N/A | J19: =[13]MVTDEC24!$V$41 -> #N/A | M19: =SUM(C19:K19) -> #N/A
A22: TOTAL | B22: =SUM(B8:B21) -> 0 | C22: =SUM(C8:C21) -> 0 | D22: =SUM(D8:D21) -> #REF! | E22: =SUM(E8:E21) -> #REF! | F22: =SUM(F8:F21) -> #REF! | G22: =SUM(G8:G21) -> #REF! | H22: =SUM(H8:H21) -> 0 | I22: =SUM(I8:I21) -> #REF! | J22: =SUM(J7:J21) -> #REF! | K22: =SUM(K8:K21) -> 0 | L22: =SUM(L8:L21) -> 0 | M22: =SUM(M8:M21) -> #REF!

Sheet SYNTHESECOMPTE
A1: ASSOCIATION | B1: ASELBY
A2: ANNEE | B2: 2024
A3: SYNTHESE DES COMPTES
A4: NUMERO ORDRE | B4: RUBRIQUE | C4: REPORT A NOUVEAU | D4: ENTREES | E4: SORTIES | F4: SOLDE
A5: ='BILAN 2024'!A8 -> 1 | B5: ='BILAN 2024'!B8 -> FONDS DE CAISSE ET RECONDUCTION | C5: 23877869 | D5: =800000*6+100000*24 -> 7200000 | E5: =7077869-6896797 -> 181072 | F5: =C5+D5-E5 -> 30896797
A6: ='BILAN 2024'!A9 -> 2 | B6: ='BILAN 2024'!B9 -> FONDS DE ROULEMENT | C6: 2160228 | D6: ='BILAN 2024'!D9 -> 384000 | E6: ='BILAN 2024'!E9 -> 251000 | F6: =C6+D6-E6 -> 2293228
A7: ='BILAN 2024'!A10 -> 3 | B7: ='BILAN 2024'!B10 -> FRAIS EXCEPTIONNELS | C7: 1038460 | D7: ='BILAN 2024'!D10 -> 384000 | E7: ='BILAN 2024'!E10 -> 0 | F7: =C7+D7-E7 -> 1422460
A8: ='BILAN 2024'!A11 -> 4 | B8: ='BILAN 2024'!B11 -> MUTUELLE\COMPLEMENT MUTUEL | C8: 814762 | D8: ='BILAN 2024'!D11 -> 240000 | E8: ='BILAN 2024'!E11 -> 200000 | F8: =C8+D8-E8 -> 854762
A9: ='BILAN 2024'!A12 -> 5 | B9: ='BILAN 2024'!B12 -> INSCRIPTION | C9: 755000 | D9: ='BILAN 2024'!D12 -> 75000 | E9: ='BILAN 2024'!E12 -> 0 | F9: =C9+D9-E9 -> 830000
A10: ='BILAN 2024'!A13 -> 6 | B10: ='BILAN 2024'!B13 -> PENALITES PAIEMENT ESPECES | C10: 847025 | D10: ='BILAN 2024'!D13 -> 93000 | E10: ='BILAN 2024'!E13 -> 0 | F10: =C10+D10-E10 -> 940025
A11: ='BILAN 2024'!A14 -> 7 | B11: SANCTION | C11: 7000 | D11: ='BILAN 2024'!D14 -> 3750 | E11: ='BILAN 2024'!E14 -> 0 | F11: =C11+D11-E11 -> 10750
A12: ='BILAN 2024'!A15 -> 8 | B12: ='BILAN 2024'!B15 -> COLLATION | C12: 1632525 | D12: ='BILAN 2024'!D15 -> 1536000 | E12: ='BILAN 2024'!E15 -> 1200000 | F12: =C12+D12-E12 -> 1968525
A13: ='BILAN 2024'!A16 -> 9 | B13: INTERET COMPTE AFRILAND | C13: 124127 | D13: 11701 | F13: =C13+D13-E13 -> 135828
A14: ='BILAN 2024'!A17 -> 10 | B14: ='BILAN 2024'!B18 -> INTERETS ET AUTRES | C14: 1010525 | D14: ='BILAN 2024'!D18 -> 0 | E14: ='BILAN 2024'!E18 -> 0 | F14: =C14+D14-E14 -> 1010525
A15: ='BILAN 2024'!A18 -> 11 | B15: ='BILAN 2024'!B23 -> 0 | C15: 101230 | D15: ='BILAN 2024'!D23 -> 0 | E15: ='BILAN 2024'!E23 -> 0 | F15: =C15+D15-E15 -> 101230
A16: 12 | B16: TERRAIN | C16: -6000000 | E16: 9300000 | F16: =C16+D16-E16 -> -15300000
B17: INTERET EPARGNE | D17: 201500 | F17: =C17+D17-E17 -> 201500
B18: FOYER | C18: 1033000 | D18: =+DETAILFOYER!C43 -> 771700 | E18: =DETAILFOYER!F43 -> 1150000 | F18: =C18+D18-E18 -> 654700
B20: TOTAL | C20: =+C5+C6+C7+C8+C9+C10+C11+C12+C13+C14+C15+C16 -> 26368751 | D20: =SUM(D5:D18) -> 0 | E20: =+E5+E6+E7+E8+E9+E10+E11+E12+E13+E14+E15+E16+E17 -> 0
B24: DISPOSITION DES FONDS
C27: 2023 | D27: 2024
A28: 1 | B28: COMPTE CCA AU 30/12/2022 | C28: ='BILAN 2024'!C33 -> 4337431 | D28: =+'BILAN 2024'!D33 -> 0
A29: 2 | B29: COMPTE MC²(NON ACTUALISE) | C29: ='BILAN 2024'!C34 -> 630005 | D29: =+'BILAN 2024'!D34 -> 640005
A30: 3 | B30: COMPTE AFRILAND | C30: ='BILAN 2024'!C35 -> 1423702 | D30: =+'BILAN 2024'!D35 -> 5265069
A31: 4 | B31: DETTE PREFINANCEMENT LA'AGWEU | C31: ='BILAN 2024'!C36 -> 744700 | D31: =C31 -> 744700
A32: 5 | B32: DETTE MR KOUATCHO | C32: ='BILAN 2024'!C37 -> 0 | D32: =+'BILAN 2024'!D37 -> 0
A33: 6 | B33: RESTE A RECUPERE AU CONSEIL | C33: ='BILAN 2024'!C38 -> 154000 | D33: =C33 -> 154000
A34: 7 | B34: FONDS EN CIRCULATION | C34: ='BILAN 2024'!C39 -> 18658500 | D34: =+'BILAN 2024'!D39 -> #N/A
A35: 8 | B35: DETTES TONTINES | C35: ='BILAN 2024'!C40 -> 656618 | D35: =+'BILAN 2024'!D40 -> 0
B36: CAISSE?BOGNING 60 000 DJOUKWE 90 000) | D36: 150000
B38: TOTAL | C38: =SUM(C28:C36) -> 26604956 | D38: =SUM(D28:D36) -> #N/A

Sheet DETAILFICHECASSATION
A1: ASSOCIATION | B1: ASELBY
A2: ANNEE | B2: 2023/2024
A5: MATRICULE | B5: NOM ET PRENOM | C5: FONDS DE CAISSE | D5: RECONDUCTION | E5: REPARTITION INTERET | F5: EPARGNE | G5: REPARTITION PENALITE REMBOURSEMENT PRÊT | H5: REPARTITION COLLATION | I5: TOTAL | J5: SANCTION | K5: COMPLEMENT MUTUELLE | L5: COMPLEMENT FONDS | M5: DETTE PRÊT FONDS | N5: TOTAL RETENU | O5: TOTAL A PERCEVOIR | P5: MONTANT PERCU | Q5: RECONDUCTION 2024 | R5: NOUVEAU FONDS | S5: FOYER
A6: AS201648 | B6: =VLOOKUP(A6,[16]LISTADHERENT!A$5:H$60,3,0) -> ASELBY | C6: =VLOOKUP($A6,[13]MVTRESUME24!$A$7:$Q$41,3,0) -> 0 | D6: =VLOOKUP($A6,[13]MVTRESUME24!$A$7:$Q$41,4,0) -> 886523.26 | E6: =VLOOKUP($A6,[13]MVTRESUME24!$A$7:$Q$41,8,0) -> 74148.369 | F6: =VLOOKUP($A6,[13]MVTRESUME24!$A$7:$Q$41,12,0) -> 62000 | I6: =D6+E6+F6+G6+H6 -> 1022671.6 | J6: =VLOOKUP($A6,[13]MVTRESUME24!$A$7:$Q$41,10,0) -> 0 | N6: =J6+K6+L6+M6 -> 0 | O6: =I6-N6 -> 1022671.6 | Q6: 1023134
A7: AS201601 | B7: =VLOOKUP(A7,[16]LISTADHERENT!A$5:H$60,3,0) -> BAKOP ACHILLE | C7: =VLOOKUP($A7,[13]MVTRESUME24!$A$7:$Q$41,3,0) -> 0 | D7: =VLOOKUP($A7,[13]MVTRESUME24!$A$7:$Q$41,4,0) -> 1356964 | E7: =VLOOKUP($A7,[13]MVTRESUME24!$A$7:$Q$41,8,0) -> 17268.352 | F7: =VLOOKUP($A7,[13]MVTRESUME24!$A$7:$Q$41,12,0) -> 236000 | I7: =D7+E7+F7+G7+H7 -> 1610232.4 | J7: =VLOOKUP($A7,[13]MVTRESUME24!$A$7:$Q$41,10,0) -> 0 | K7: 20000 | L7: 100000 | N7: =J7+K7+L7+M7 -> 120000 | O7: =I7-N7 -> 1490232.4 | P7: =700000+93000 -> 793000 | Q7: 18598 | R7: 800000
A8: AS201602 | B8: =VLOOKUP(A8,[16]LISTADHERENT!A$5:H$60,3,0) -> BOUTCHOUANG WILLIAM | C8: =VLOOKUP($A8,[13]MVTRESUME24!$A$7:$Q$41,3,0) -> 700000 | D8: =VLOOKUP($A8,[13]MVTRESUME24!$A$7:$Q$41,4,0) -> 33.126263 | E8: =VLOOKUP($A8,[13]MVTRESUME24!$A$7:$Q$41,8,0) -> 61331.963 | F8: =VLOOKUP($A8,[13]MVTRESUME24!$A$7:$Q$41,12,0) -> 225000 | I8: =D8+E8+F8+G8+H8 -> 286365.09 | J8: =VLOOKUP($A8,[13]MVTRESUME24!$A$7:$Q$41,10,0) -> 0 | K8: 20000 | L8: 100000 | N8: =J8+K8+L8+M8 -> 120000 | O8: =I8-N8 -> 166365.09 | P8: 34625 | Q8: 132669 | R8: =C8+L8 -> 800000
A9: AS201604 | B9: =VLOOKUP(A9,[16]LISTADHERENT!A$5:H$60,3,0) -> DJOMO JEAN PAUL | C9: =VLOOKUP($A9,[13]MVTRESUME24!$A$7:$Q$41,3,0) -> 700000 | D9: =VLOOKUP($A9,[13]MVTRESUME24!$A$7:$Q$41,4,0) -> 53357.826 | E9: =VLOOKUP($A9,[13]MVTRESUME24!$A$7:$Q$41,8,0) -> 65782.523 | F9: =VLOOKUP($A9,[13]MVTRESUME24!$A$7:$Q$41,12,0) -> 220500 | I9: =D9+E9+F9+G9+H9 -> 339640.35 | J9: =VLOOKUP($A9,[13]MVTRESUME24!$A$7:$Q$41,10,0) -> 0 | K9: 20000 | L9: 100000 | N9: =J9+K9+L9+M9 -> 120000 | O9: =I9-N9 -> 219640.35 | P9: 214000 | Q9: 6643 | R9: =C9+L9 -> 800000
A10: AS201654 | B10: =VLOOKUP(A10,[16]LISTADHERENT!A$5:H$60,3,0) -> DJOMOU TCHAPDA | C10: =VLOOKUP($A10,[13]MVTRESUME24!$A$7:$Q$41,3,0) -> 700000 | D10: =VLOOKUP($A10,[13]MVTRESUME24!$A$7:$Q$41,4,0) -> 294.6793 | E10: =VLOOKUP($A10,[13]MVTRESUME24!$A$7:$Q$41,8,0) -> 61289.029 | F10: =VLOOKUP($A10,[13]MVTRESUME24!$A$7:$Q$41,12,0) -> 221500 | I10: =D10+E10+F10+G10+H10 -> 283083.71 | J10: =VLOOKUP($A10,[13]MVTRESUME24!$A$7:$Q$41,10,0) -> 0 | K10: 20000 | L10: 100000 | N10: =J10+K10+L10+M10 -> 120000 | O10: =I10-N10 -> 163083.71 | P10: =154825+1943 -> 156768 | Q10: 7246 | R10: =C10+L10 -> 800000
A11: AS201605 | B11: =VLOOKUP(A11,[16]LISTADHERENT!A$5:H$60,3,0) -> DJOUKWE NANGUEN GUY BLAISE | C11: =VLOOKUP($A11,[13]MVTRESUME24!$A$7:$Q$41,3,0) -> 700000 | D11: =VLOOKUP($A11,[13]MVTRESUME24!$A$7:$Q$41,4,0) -> 2196.7679 | E11: =VLOOKUP($A11,[13]MVTRESUME24!$A$7:$Q$41,8,0) -> 61907.328 | F11: =VLOOKUP($A11,[13]MVTRESUME24!$A$7:$Q$41,12,0) -> 251000 | I11: =D11+E11+F11+G11+H11 -> 315104.1 | J11: =VLOOKUP($A11,[13]MVTRESUME24!$A$7:$Q$41,10,0) -> 0 | K11: 20000 | L11: 100000 | N11: =J11+K11+L11+M11 -> 120000 | O11: =I11-N11 -> 195104.1 | P11: =90000+100000 -> 190000 | Q11: 6032 | R11: =C11+L11 -> 800000
A12: AS201608 | B12: =VLOOKUP(A12,[16]LISTADHERENT!A$5:H$60,3,0) -> DJUOMBESSY ANTOINE | C12: =VLOOKUP($A12,[13]MVTRESUME24!$A$7:$Q$41,3,0) -> 700000 | D12: =VLOOKUP($A12,[13]MVTRESUME24!$A$7:$Q$41,4,0) -> 14513.277 | E12: =VLOOKUP($A12,[13]MVTRESUME24!$A$7:$Q$41,8,0) -> 63433.589 | F12: =VLOOKUP($A12,[13]MVTRESUME24!$A$7:$Q$41,12,0) -> 295600 | I12: =D12+E12+F12+G12+H12 -> 373546.87 | J12: =VLOOKUP($A12,[13]MVTRESUME24!$A$7:$Q$41,10,0) -> 0 | K12: 20000 | L12: 100000 | N12: =J12+K12+L12+M12 -> 120000 | O12: =I12-N12 -> 253546.87 | P12: 240000 | Q12: 14486 | R12: =C12+L12 -> 800000
A13: AS201651 | B13: =VLOOKUP(A13,[16]LISTADHERENT!A$5:H$60,3,0) -> DOMOU FABIEN | C13: =VLOOKUP($A13,[13]MVTRESUME24!$A$7:$Q$41,3,0) -> 700000 | D13: =VLOOKUP($A13,[13]MVTRESUME24!$A$7:$Q$41,4,0) -> 41.235806 | E13: =VLOOKUP($A13,[13]MVTRESUME24!$A$7:$Q$41,8,0) -> 61395.795 | F13: =VLOOKUP($A13,[13]MVTRESUME24!$A$7:$Q$41,12,0) -> 228000 | I13: =D13+E13+F13+G13+H13 -> 289437.03 | J13: =VLOOKUP($A13,[13]MVTRESUME24!$A$7:$Q$41,10,0) -> 0 | K13: 20000 | L13: 100000 | N13: =J13+K13+L13+M13 -> 120000 | O13: =I13-N13 -> 169437.03 | P13: 164000 | Q13: 6365 | R13: =C13+L13 -> 800000
A14: AS201609 | B14: =VLOOKUP(A14,[16]LISTADHERENT!A$5:H$60,3,0) -> DONHOU DAVID | C14: =VLOOKUP($A14,[13]MVTRESUME24!$A$7:$Q$41,3,0) -> 700000 | D14: =VLOOKUP($A14,[13]MVTRESUME24!$A$7:$Q$41,4,0) -> 518031.29 | E14: =VLOOKUP($A14,[13]MVTRESUME24!$A$7:$Q$41,8,0) -> 104720.23 | F14: =VLOOKUP($A14,[13]MVTRESUME24!$A$7:$Q$41,12,0) -> 228000 | I14: =D14+E14+F14+G14+H14 -> 850751.52 | J14: =VLOOKUP($A14,[13]MVTRESUME24!$A$7:$Q$41,10,0) -> 0 | K14: 20000 | L14: 100000 | N14: =J14+K14+L14+M14 -> 120000 | O14: =I14-N14 -> 730751.52 | P14: 30000 | Q14: 702391 | R14: =C14+L14 -> 800000
A15: AS201611 | B15: =VLOOKUP(A15,[16]LISTADHERENT!A$5:H$60,3,0) -> HENGUE PAUL OMER | C15: =VLOOKUP($A15,[13]MVTRESUME24!$A$7:$Q$41,3,0) -> 700000 | D15: =VLOOKUP($A15,[13]MVTRESUME24!$A$7:$Q$41,4,0) -> 57899.604 | E15: =VLOOKUP($A15,[13]MVTRESUME24!$A$7:$Q$41,8,0) -> 66235.04 | F15: =VLOOKUP($A15,[13]MVTRESUME24!$A$7:$Q$41,12,0) -> 228000 | I15: =D15+E15+F15+G15+H15 -> 352134.64 | J15: =VLOOKUP($A15,[13]MVTRESUME24!$A$7:$Q$41,10,0) -> 0 | K15: 20000 | L15: 100000 | N15: =J15+K15+L15+M15 -> 120000 | O15: =I15-N15 -> 232134.64 | P15: =80000+60000+86000 -> 226000 | Q15: 7143 | R15: =C15+L15 -> 800000
A16: AS201613 | B16: =VLOOKUP(A16,[16]LISTADHERENT!A$5:H$60,3,0) -> HOTCHO BENJAMIN | C16: =VLOOKUP($A16,[13]MVTRESUME24!$A$7:$Q$41,3,0) -> 700000 | D16: =VLOOKUP($A16,[13]MVTRESUME24!$A$7:$Q$41,4,0) -> 29661.208 | E16: =VLOOKUP($A16,[13]MVTRESUME24!$A$7:$Q$41,8,0) -> 68725.529 | F16: =VLOOKUP($A16,[13]MVTRESUME24!$A$7:$Q$41,12,0) -> 587000 | I16: =D16+E16+F16+G16+H16 -> 685386.74 | J16: =VLOOKUP($A16,[13]MVTRESUME24!$A$7:$Q$41,10,0) -> 0 | K16: 20000 | L16: 100000 | N16: =J16+K16+L16+M16 -> 120000 | O16: =I16-N16 -> 565386.74 | P16: =40000+20000 -> 60000 | Q16: 6301 | R16: =C16+L16 -> 800000
A17: AS201617 | B17: =VLOOKUP(A17,[16]LISTADHERENT!A$5:H$60,3,0) -> KOUAMOU MOISE | C17: =VLOOKUP($A17,[13]MVTRESUME24!$A$7:$Q$41,3,0) -> 700000 | D17: =VLOOKUP($A17,[13]MVTRESUME24!$A$7:$Q$41,4,0) -> 9267.5052 | E17: =VLOOKUP($A17,[13]MVTRESUME24!$A$7:$Q$41,8,0) -> 62143.618 | F17: =VLOOKUP($A17,[13]MVTRESUME24!$A$7:$Q$41,12,0) -> 224000 | I17: =D17+E17+F17+G17+H17 -> 295411.12 | J17: =VLOOKUP($A17,[13]MVTRESUME24!$A$7:$Q$41,10,0) -> 0 | K17: 20000 | L17: 100000 | N17: =J17+K17+L17+M17 -> 120000 | O17: =I17-N17 -> 175411.12 | P17: 170000 | Q17: 6353 | R17: =C17+L17 -> 800000
A18: AS201619 | B18: =VLOOKUP(A18,[16]LISTADHERENT!A$5:H$60,3,0) -> KOUATCHO MESSACK | C18: =VLOOKUP($A18,[13]MVTRESUME24!$A$7:$Q$41,3,0) -> 700000 | D18: =VLOOKUP($A18,[13]MVTRESUME24!$A$7:$Q$41,4,0) -> 24428.628 | E18: =VLOOKUP($A18,[13]MVTRESUME24!$A$7:$Q$41,8,0) -> 64564.757 | F18: =VLOOKUP($A18,[13]MVTRESUME24!$A$7:$Q$41,12,0) -> 320000 | I18: =D18+E18+F18+G18+H18 -> 408993.39 | J18: =VLOOKUP($A18,[13]MVTRESUME24!$A$7:$Q$41,10,0) -> 0 | K18: 20000 | L18: 100000 | N18: =J18+K18+L18+M18 -> 120000 | O18: =I18-N18 -> 288993.39 | Q18: 9944 | R18: =C18+L18 -> 800000
A19: AS201620 | B19: =VLOOKUP(A19,[16]LISTADHERENT!A$5:H$60,3,0) -> LOWE JEAN | C19: =VLOOKUP($A19,[13]MVTRESUME24!$A$7:$Q$41,3,0) -> 0 | D19: 676217 | E19: =VLOOKUP($A19,[13]MVTRESUME24!$A$7:$Q$41,8,0) -> 0 | F19: =VLOOKUP($A19,[13]MVTRESUME24!$A$7:$Q$41,12,0) -> 0 | I19: =D19+E19+F19+G19+H19 -> 676217 | J19: =VLOOKUP($A19,[13]MVTRESUME24!$A$7:$Q$41,10,0) -> 0 | N19: =J19+K19+L19+M19 -> 0 | O19: =I19-N19 -> 676217 | Q19: 676217 | R19: =C19+L19 -> 0 | T19: 676217
A20: AS201661 | B20: =VLOOKUP(A20,[16]LISTADHERENT!A$5:H$60,3,0) -> MASSEUNGOUE DAGOBERT | C20: =VLOOKUP($A20,[13]MVTRESUME24!$A$7:$Q$41,3,0) -> 0 | D20: =VLOOKUP($A20,[13]MVTRESUME24!$A$7:$Q$41,4,0) -> 0 | E20: =VLOOKUP($A20,[13]MVTRESUME24!$A$7:$Q$41,8,0) -> 0 | F20: =VLOOKUP($A20,[13]MVTRESUME24!$A$7:$Q$41,12,0) -> 525500 | I20: =D20+E20+F20+G20+H20 -> 525500 | J20: =VLOOKUP($A20,[13]MVTRESUME24!$A$7:$Q$41,10,0) -> 0 | K20: 120000 | N20: =J20+K20+L20+M20 -> 120000 | O20: =I20-N20 -> 405500 | P20: =190000+16875 -> 206875 | Q20: 198625 | R20: =C20+L20 -> 0 | S20: =Q20-R20 -> 198625 | T20: 198625
A21: AS201649 | B21: =VLOOKUP(A21,[16]LISTADHERENT!A$5:H$60,3,0) -> MBOGNING TUGMA GUY | C21: =VLOOKUP($A21,[13]MVTRESUME24!$A$7:$Q$41,3,0) -> 700000 | D21: =VLOOKUP($A21,[13]MVTRESUME24!$A$7:$Q$41,4,0) -> 31709.397 | E21: =VLOOKUP($A21,[13]MVTRESUME24!$A$7:$Q$41,8,0) -> 64019.635 | F21: =VLOOKUP($A21,[13]MVTRESUME24!$A$7:$Q$41,12,0) -> 226500 | I21: =D21+E21+F21+G21+H21 -> 322229.03 | J21: =VLOOKUP($A21,[13]MVTRESUME24!$A$7:$Q$41,10,0) -> 0 | K21: 20000 | L21: 100000 | N21: =J21+K21+L21+M21 -> 120000 | O21: =I21-N21 -> 202229.03 | P21: =120000+66700+8000 -> 194700 | Q21: 8501 | R21: =C21+L21 -> 800000 | S21: 66700
A22: AS201639 | B22: =VLOOKUP(A22,[16]LISTADHERENT!A$5:H$60,3,0) -> NANGUEN MARTIN | C22: =VLOOKUP($A22,[13]MVTRESUME24!$A$7:$Q$41,3,0) -> 700000 | D22: =VLOOKUP($A22,[13]MVTRESUME24!$A$7:$Q$41,4,0) -> 1150.3621 | E22: =VLOOKUP($A22,[13]MVTRESUME24!$A$7:$Q$41,8,0) -> 61488.561 | F22: =VLOOKUP($A22,[13]MVTRESUME24!$A$7:$Q$41,12,0) -> 228000 | I22: =D22+E22+F22+G22+H22 -> 290638.92 | J22: =VLOOKUP($A22,[13]MVTRESUME24!$A$7:$Q$41,10,0) -> 0 | K22: 20000 | L22: 100000 | N22: =J22+K22+L22+M22 -> 120000 | O22: =I22-N22 -> 170638.92 | P22: =75000+40000+48750 -> 163750 | Q22: 7819 | R22: =C22+L22 -> 800000
A23: AS201621 | B23: =VLOOKUP(A23,[16]LISTADHERENT!A$5:H$60,3,0) -> NANKAM APPOLINAIRE | C23: =VLOOKUP($A23,[13]MVTRESUME24!$A$7:$Q$41,3,0) -> 700000 | D23: =VLOOKUP($A23,[13]MVTRESUME24!$A$7:$Q$41,4,0) -> 100402.23 | E23: =VLOOKUP($A23,[13]MVTRESUME24!$A$7:$Q$41,8,0) -> 69789.939 | F23: =VLOOKUP($A23,[13]MVTRESUME24!$A$7:$Q$41,12,0) -> 228000 | I23: =D23+E23+F23+G23+H23 -> 398192.17 | J23: =VLOOKUP($A23,[13]MVTRESUME24!$A$7:$Q$41,10,0) -> 0 | K23: 20000 | L23: 100000 | N23: =J23+K23+L23+M23 -> 120000 | O23: =I23-N23 -> 278192.17 | P23: 30000 | Q23: 249258 | R23: =C23+L23 -> 800000
A24: AS201622 | B24: =VLOOKUP(A24,[16]LISTADHERENT!A$5:H$60,3,0) -> NDJOMO ETIENNE | C24: =VLOOKUP($A24,[13]MVTRESUME24!$A$7:$Q$41,3,0) -> 700000 | D24: =VLOOKUP($A24,[13]MVTRESUME24!$A$7:$Q$41,4,0) -> 224970.62 | E24: =VLOOKUP($A24,[13]MVTRESUME24!$A$7:$Q$41,8,0) -> 81969.599 | F24: =VLOOKUP($A24,[13]MVTRESUME24!$A$7:$Q$41,12,0) -> 368000 | I24: =D24+E24+F24+G24+H24 -> 674940.22 | J24: =VLOOKUP($A24,[13]MVTRESUME24!$A$7:$Q$41,10,0) -> 0 | K24: 20000 | L24: 100000 | N24: =J24+K24+L24+M24 -> 120000 | O24: =I24-N24 -> 554940.22 | P24: 300000 | Q24: 256158 | R24: =C24+L24 -> 800000
A25: AS201624 | B25: =VLOOKUP(A25,[16]LISTADHERENT!A$5:H$60,3,0) -> NGONDIEP CLAUDE | C25: =VLOOKUP($A25,[13]MVTRESUME24!$A$7:$Q$41,3,0) -> 700000 | D25: =VLOOKUP($A25,[13]MVTRESUME24!$A$7:$Q$41,4,0) -> 57632.732 | E25: =VLOOKUP($A25,[13]MVTRESUME24!$A$7:$Q$41,8,0) -> 68236.402 | F25: =VLOOKUP($A25,[13]MVTRESUME24!$A$7:$Q$41,12,0) -> 393000 | I25: =D25+E25+F25+G25+H25 -> 518869.13 | J25: =VLOOKUP($A25,[13]MVTRESUME24!$A$7:$Q$41,10,0) -> 0 | K25: 20000 | L25: 100000 | N25: =J25+K25+L25+M25 -> 120000 | O25: =I25-N25 -> 398869.13 | Q25: 353356 | R25: =C25+L25 -> 800000
A26: AS201626 | B26: =VLOOKUP(A26,[16]LISTADHERENT!A$5:H$60,3,0) -> NGUIEMEGNI MATHIEU BLAISE | C26: =VLOOKUP($A26,[13]MVTRESUME24!$A$7:$Q$41,3,0) -> 700000 | D26: =VLOOKUP($A26,[13]MVTRESUME24!$A$7:$Q$41,4,0) -> 20382.784 | E26: =VLOOKUP($A26,[13]MVTRESUME24!$A$7:$Q$41,8,0) -> 63080.198 | F26: =VLOOKUP($A26,[13]MVTRESUME24!$A$7:$Q$41,12,0) -> 220500 | I26: =D26+E26+F26+G26+H26 -> 303962.98 | J26: =VLOOKUP($A26,[13]MVTRESUME24!$A$7:$Q$41,10,0) -> 0 | K26: 20000 | L26: 100000 | N26: =J26+K26+L26+M26 -> 120000 | O26: =I26-N26 -> 183962.98 | P26: =75000+55625+45120 -> 175745 | Q26: 9175 | R26: =C26+L26 -> 800000
A27: AS201628 | B27: =VLOOKUP(A27,[16]LISTADHERENT!A$5:H$60,3,0) -> NKAMGANG JUSTIN DEJOLIE | C27: =VLOOKUP($A27,[13]MVTRESUME24!$A$7:$Q$41,3,0) -> 700000 | D27: =VLOOKUP($A27,[13]MVTRESUME24!$A$7:$Q$41,4,0) -> 19031.485 | E27: =VLOOKUP($A27,[13]MVTRESUME24!$A$7:$Q$41,8,0) -> 62995.892 | F27: =VLOOKUP($A27,[13]MVTRESUME24!$A$7:$Q$41,12,0) -> 229500 | I27: =D27+E27+F27+G27+H27 -> 311527.38 | J27: =VLOOKUP($A27,[13]MVTRESUME24!$A$7:$Q$41,10,0) -> 0 | K27: 20000 | L27: 100000 | N27: =J27+K27+L27+M27 -> 120000 | O27: =I27-N27 -> 191527.38 | P27: 185000 | Q27: 10531 | R27: =C27+L27 -> 800000
A28: AS201656 | B28: =VLOOKUP(A28,[16]LISTADHERENT!A$5:H$60,3,0) -> NOUBE ETIENNE | C28: =VLOOKUP($A28,[13]MVTRESUME24!$A$7:$Q$41,3,0) -> 0 | D28: =VLOOKUP($A28,[13]MVTRESUME24!$A$7:$Q$41,4,0) -> 1332038 | E28: =VLOOKUP($A28,[13]MVTRESUME24!$A$7:$Q$41,8,0) -> 16720.148 | F28: =VLOOKUP($A28,[13]MVTRESUME24!$A$7:$Q$41,12,0) -> 228000 | I28: =D28+E28+F28+G28+H28 -> 1576758.1 | J28: =VLOOKUP($A28,[13]MVTRESUME24!$A$7:$Q$41,10,0) -> 0 | K28: 20000 | L28: =144000-10019 -> 133981 | N28: =J28+K28+L28+M28 -> 153981 | O28: =I28-N28 -> 1422777.1 | P28: 100000 | Q28: -17159 | R28: 800000 | S28: =Q28+R28 -> 782841
A29: AS201633 | B29: =VLOOKUP(A29,[16]LISTADHERENT!A$5:H$60,3,0) -> PATEGO NJOSSU GUSTAVE | C29: =VLOOKUP($A29,[13]MVTRESUME24!$A$7:$Q$41,3,0) -> 700000 | D29: =VLOOKUP($A29,[13]MVTRESUME24!$A$7:$Q$41,4,0) -> 43697.666 | E29: =VLOOKUP($A29,[13]MVTRESUME24!$A$7:$Q$41,8,0) -> 65157.656 | F29: =VLOOKUP($A29,[13]MVTRESUME24!$A$7:$Q$41,12,0) -> 255000 | I29: =D29+E29+F29+G29+H29 -> 363855.32 | J29: =VLOOKUP($A29,[13]MVTRESUME24!$A$7:$Q$41,10,0) -> 0 | K29: 20000 | L29: 100000 | N29: =J29+K29+L29+M29 -> 120000 | O29: =I29-N29 -> 243855.32 | P29: 11500 | Q29: 133342 | R29: =C29+L29 -> 800000
A30: AS201657 | B30: =VLOOKUP(A30,[16]LISTADHERENT!A$5:H$60,3,0) -> SEUMO POLYCARPE | C30: =VLOOKUP($A30,[13]MVTRESUME24!$A$7:$Q$41,3,0) -> 0 | D30: =VLOOKUP($A30,[13]MVTRESUME24!$A$7:$Q$41,4,0) -> 245500 | E30: =VLOOKUP($A30,[13]MVTRESUME24!$A$7:$Q$41,8,0) -> 17373.219 | F30: =VLOOKUP($A30,[13]MVTRESUME24!$A$7:$Q$41,12,0) -> 685500 | I30: =D30+E30+F30+G30+H30 -> 948373.22 | J30: =VLOOKUP($A30,[13]MVTRESUME24!$A$7:$Q$41,10,0) -> 0 | K30: 20000 | L30: 800000 | N30: =J30+K30+L30+M30 -> 820000 | O30: =I30-N30 -> 128373.22 | P30: =115000+37500 -> 152500 | Q30: -9977 | R30: =C30+L30 -> 800000 | S30: 115000
A31: AS201653 | B31: =VLOOKUP(A31,[16]LISTADHERENT!A$5:H$60,3,0) -> SIME BRICE | C31: =VLOOKUP($A31,[13]MVTRESUME24!$A$7:$Q$41,3,0) -> 700000 | D31: =VLOOKUP($A31,[13]MVTRESUME24!$A$7:$Q$41,4,0) -> 104364.15 | E31: =VLOOKUP($A31,[13]MVTRESUME24!$A$7:$Q$41,8,0) -> 70150.658 | F31: =VLOOKUP($A31,[13]MVTRESUME24!$A$7:$Q$41,12,0) -> 231000 | I31: =D31+E31+F31+G31+H31 -> 405514.81 | J31: =VLOOKUP($A31,[13]MVTRESUME24!$A$7:$Q$41,10,0) -> 0 | K31: 20000 | L31: 100000 | N31: =J31+K31+L31+M31 -> 120000 | O31: =I31-N31 -> 285514.81 | P31: =150000+8000+49480 -> 207480 | Q31: 79106 | R31: =C31+L31 -> 800000
A32: AS201638 | B32: =VLOOKUP(A32,[16]LISTADHERENT!A$5:H$60,3,0) -> SIMO PIERRE | C32: =VLOOKUP($A32,[13]MVTRESUME24!$A$7:$Q$41,3,0) -> 700000 | D32: =VLOOKUP($A32,[13]MVTRESUME24!$A$7:$Q$41,4,0) -> 686.61218 | E32: =VLOOKUP($A32,[13]MVTRESUME24!$A$7:$Q$41,8,0) -> 61449.774 | F32: =VLOOKUP($A32,[13]MVTRESUME24!$A$7:$Q$41,12,0) -> 228000 | I32: =D32+E32+F32+G32+H32 -> 290136.39 | J32: =VLOOKUP($A32,[13]MVTRESUME24!$A$7:$Q$41,10,0) -> 0 | K32: 20000 | L32: 100000 | N32: =J32+K32+L32+M32 -> 120000 | O32: =I32-N32 -> 170136.39 | P32: 24375 | Q32: 46691 | R32: =C32+L32 -> 800000
A33: AS201641 | B33: =VLOOKUP(A33,[16]LISTADHERENT!A$5:H$60,3,0) -> TCHOUAMOU MATHIEU | C33: =VLOOKUP($A33,[13]MVTRESUME24!$A$7:$Q$41,3,0) -> 700000 | D33: =VLOOKUP($A33,[13]MVTRESUME24!$A$7:$Q$41,4,0) -> 975.80621 | E33: =VLOOKUP($A33,[13]MVTRESUME24!$A$7:$Q$41,8,0) -> 71255.948 | F33: =VLOOKUP($A33,[13]MVTRESUME24!$A$7:$Q$41,12,0) -> 1228000 | I33: =D33+E33+F33+G33+H33 -> 1300231.8 | J33: =VLOOKUP($A33,[13]MVTRESUME24!$A$7:$Q$41,10,0) -> 0 | K33: 20000 | L33: 100000 | N33: =J33+K33+L33+M33 -> 120000 | O33: =I33-N33 -> 1180231.8 | P33: =1175000+30000 -> 1205000 | Q33: 6050 | R33: =C33+L33 -> 800000
A34: AS201660 | B34: =VLOOKUP(A34,[16]LISTADHERENT!A$5:H$60,3,0) -> TCHOUATEU AUGUSTIN | C34: =VLOOKUP($A34,[13]MVTRESUME24!$A$7:$Q$41,3,0) -> 0 | D34: =VLOOKUP($A34,[13]MVTRESUME24!$A$7:$Q$41,4,0) -> 0 | E34: =VLOOKUP($A34,[13]MVTRESUME24!$A$7:$Q$41,8,0) -> 4718.6606 | F34: =VLOOKUP($A34,[13]MVTRESUME24!$A$7:$Q$41,12,0) -> 972000 | I34: =D34+E34+F34+G34+H34 -> 976718.66 | J34: =VLOOKUP($A34,[13]MVTRESUME24!$A$7:$Q$41,10,0) -> 0 | L34: 800000 | N34: =J34+K34+L34+M34 -> 800000 | O34: =I34-N34 -> 176718.66 | P34: 150000 | Q34: -3392 | R34: =C34+L34 -> 800000 | S34: 55000
A35: AS201643 | B35: =VLOOKUP(A35,[16]LISTADHERENT!A$5:H$60,3,0) -> TCHOUTOU NANA CLAUDE | C35: =VLOOKUP($A35,[13]MVTRESUME24!$A$7:$Q$41,3,0) -> 0 | D35: =VLOOKUP($A35,[13]MVTRESUME24!$A$7:$Q$41,4,0)+76000 -> 179000 | E35: =VLOOKUP($A35,[13]MVTRESUME24!$A$7:$Q$41,8,0) -> 0 | F35: =VLOOKUP($A35,[13]MVTRESUME24!$A$7:$Q$41,12,0) -> 528750 | I35: =D35+E35+F35+G35+H35 -> 707750 | J35: =VLOOKUP($A35,[13]MVTRESUME24!$A$7:$Q$41,10,0) -> 0 | K35: 120000 | N35: =J35+K35+L35+M35 -> 120000 | O35: =I35-N35 -> 587750 | P35: =100000 -> 100000 | Q35: 487750 | T35: 487750
A36: AS201658 | B36: =VLOOKUP(A36,[16]LISTADHERENT!A$5:H$60,3,0) -> YANTCHOU GERVAIS | C36: =VLOOKUP($A36,[13]MVTRESUME24!$A$7:$Q$41,3,0) -> 0 | D36: =VLOOKUP($A36,[13]MVTRESUME24!$A$7:$Q$41,4,0) -> 1396048 | E36: =VLOOKUP($A36,[13]MVTRESUME24!$A$7:$Q$41,8,0) -> 62683.369 | F36: =VLOOKUP($A36,[13]MVTRESUME24!$A$7:$Q$41,12,0) -> 338000 | I36: =D36+E36+F36+G36+H36 -> 1796731.4 | J36: =VLOOKUP($A36,[13]MVTRESUME24!$A$7:$Q$41,10,0) -> 0 | K36: 20000 | L36: 100000 | N36: =J36+K36+L36+M36 -> 120000 | O36: =I36-N36 -> 1676731.4 | P36: 50000 | Q36: -32497 | R36: 800000
A37: AS201646 | B37: =VLOOKUP(A37,[16]LISTADHERENT!A$5:H$60,3,0) -> YEPMOU JEAN JACQUES | C37: =VLOOKUP($A37,[13]MVTRESUME24!$A$7:$Q$41,3,0) -> 700000 | D37: =VLOOKUP($A37,[13]MVTRESUME24!$A$7:$Q$41,4,0) -> 1003326.8 | E37: =VLOOKUP($A37,[13]MVTRESUME24!$A$7:$Q$41,8,0) -> 145310.11 | F37: =VLOOKUP($A37,[13]MVTRESUME24!$A$7:$Q$41,12,0) -> 228000 | I37: =D37+E37+F37+G37+H37 -> 1376637 | J37: =VLOOKUP($A37,[13]MVTRESUME24!$A$7:$Q$41,10,0) -> 0 | K37: 20000 | L37: 100000 | N37: =J37+K37+L37+M37 -> 120000 | O37: =I37-N37 -> 1256637 | P37: 516250 | Q37: 739643 | R37: =C37+L37 -> 800000
A38: AS201659 | B38: =VLOOKUP(A38,[16]LISTADHERENT!A$5:H$60,3,0) -> YIALA ALAIN OSCAR | C38: =VLOOKUP($A38,[13]MVTRESUME24!$A$7:$Q$41,3,0) -> 0 | D38: =VLOOKUP($A38,[13]MVTRESUME24!$A$7:$Q$41,4,0) -> 0 | E38: =VLOOKUP($A38,[13]MVTRESUME24!$A$7:$Q$41,8,0) -> 4571.02 | F38: =VLOOKUP($A38,[13]MVTRESUME24!$A$7:$Q$41,12,0) -> 928000 | I38: =D38+E38+F38+G38+H38 -> 932571.02 | J38: =VLOOKUP($A38,[13]MVTRESUME24!$A$7:$Q$41,10,0) -> 0 | L38: 800000 | N38: =J38+K38+L38+M38 -> 800000 | O38: =I38-N38 -> 132571.02 | P38: 114000 | Q38: 241 | R38: =C38+L38 -> 800000
A39: AS201647 | B39: =VLOOKUP(A39,[16]LISTADHERENT!A$5:H$60,3,0) -> YOUMBI EMMANUEL | C39: =VLOOKUP($A39,[13]MVTRESUME24!$A$7:$Q$41,3,0) -> 700000 | D39: =VLOOKUP($A39,[13]MVTRESUME24!$A$7:$Q$41,4,0) -> 1157835 | E39: =VLOOKUP($A39,[13]MVTRESUME24!$A$7:$Q$41,8,0) -> 158233.09 | F39: =VLOOKUP($A39,[13]MVTRESUME24!$A$7:$Q$41,12,0) -> 228000 | I39: =D39+E39+F39+G39+H39 -> 1544068.1 | J39: =VLOOKUP($A39,[13]MVTRESUME24!$A$7:$Q$41,10,0) -> 0 | K39: 20000 | L39: 100000 | N39: =J39+K39+L39+M39 -> 120000 | O39: =I39-N39 -> 1424068.1 | P39: 30000 | Q39: 1296586 | R39: =C39+L39 -> 800000
A40: AS201604 | B40: SIMO FONGANG ERIC | Q40: 153468 | T40: 153468
A42: TOTAL | C42: =SUM(C6:C39) -> 16800000 | D42: =SUM(D6:D39) -> 9548181.1 | E42: =SUM(E6:E39) -> 1982150 | F42: =SUM(F6:F39) -> 11823850 | G42: =SUM(G6:G39) -> 0 | H42: =SUM(H6:H39) -> 0 | I42: =SUM(I6:I39) -> 23354181 | J42: =SUM(J6:J39) -> 0 | ... P42: =SUM(P6:P39) -> 6195568 | Q42: =SUM(Q6:Q40) -> 6596797 | R42: =SUM(R6:R40) -> 24000000
B44: FONGANG ERIC | R44: =DETAILLISTEROUGE!F10 -> 153468
...

Sheet DISPOFONDS
A1: ASSOCIATION | B1: ASELBY
A2: ANNEE | B2: 2024
A4: DISPOSITION DES FONDS
A6: NUMERO ORDRE | B6: RUBRIQUE | C6: 2022 | D6: 2023
C7: MONTANT | D7: MONTANT
A8: ='BILAN 2024'!A33 -> 1 | B8: ='BILAN 2024'!B33 -> COMPTE CCA AU 30/12/2022 | C8: ='BILAN 2024'!C33 -> 4337431 | D8: ='BILAN 2024'!D33 -> 0
A9: ='BILAN 2024'!A34 -> 2 | B9: ='BILAN 2024'!B34 -> COMPTE MC²(NON ACTUALISE) | C9: ='BILAN 2024'!C34 -> 630005 | D9: ='BILAN 2024'!D34 -> 640005
A10: ='BILAN 2024'!A35 -> 3 | B10: ='BILAN 2024'!B35 -> COMPTE AFRILAND | C10: ='BILAN 2024'!C35 -> 1423702 | D10: ='BILAN 2024'!D35 -> 5265069
A11: ='BILAN 2024'!A36 -> 4 | B11: ='BILAN 2024'!B36 -> DETTE PREFINANCEMENT LA'AGWEU | C11: ='BILAN 2024'!C36 -> 744700 | D11: ='BILAN 2024'!D36 -> 0
A12: ='BILAN 2024'!A37 -> 5 | B12: ='BILAN 2024'!B37 -> DETTE MR KOUATCHO | C12: ='BILAN 2024'!C37 -> 0 | D12: ='BILAN 2024'!D37 -> 0
A13: ='BILAN 2024'!A38 -> 6 | B13: ='BILAN 2024'!B38 -> RESTE A RECUPERE AU CONSEIL | C13: ='BILAN 2024'!C38 -> 154000 | D13: ='BILAN 2024'!D38 -> 0
A14: ='BILAN 2024'!A39 -> 7 | B14: ='BILAN 2024'!B39 -> FONDS EN CIRCULATION | C14: ='BILAN 2024'!C39 -> 18658500 | D14: ='BILAN 2024'!D39 -> #N/A
A15: ='BILAN 2024'!A40 -> 8 | B15: ='BILAN 2024'!B40 -> DETTES TONTINES | C15: ='BILAN 2024'!C40 -> 656618 | D15: ='BILAN 2024'!D40 -> 0
B17: TOTAL | C17: =SUM(C8:C16) -> 26604956 | D17: =SUM(D8:D16) -> #N/A

Sheet DETAILFPNDSROULT
A1: ASSOCIATION | B1: ASELBY
A2: ANNEE | B2: 2024
A4: FONDS DE ROULEMENT
A6: MATRICULE | B6: NOM ET PRENOM | C6: ENTREE | D6: SORTIE
C7: MONTANT | D7: DATE | E7: LIBELLE | F7: MONTANT
A8: AS201648 | B8: =VLOOKUP(A8,[16]LISTADHERENT!A$5:H$60,3,0) -> ASELBY | C8: =VLOOKUP(A8,[13]MVTRESUME24!$A$7:$Q$41,13,0) -> 0 | D8: 45292 | E8: ACHAT FOURNITURE | F8: =+[19]HISTOJANV24!$BQ$6 -> 8500
A9: AS201601 | B9: =VLOOKUP(A9,[16]LISTADHERENT!A$5:H$60,3,0) -> BAKOP ACHILLE | C9: =VLOOKUP(A9,[13]MVTRESUME24!$A$7:$Q$41,13,0) -> 12000 | D9: 45292 | E9: OUVERTURE DE COMPTE | F9: =[19]HISTOJANV24!$BQ$9 -> 18500
A10: AS201602 | B10: =VLOOKUP(A10,[16]LISTADHERENT!A$5:H$60,3,0) -> BOUTCHOUANG WILLIAM | C10: =VLOOKUP(A10,[13]MVTRESUME24!$A$7:$Q$41,13,0) -> 12000 | D10: 45292 | E10: FRAIS DOSSIER TECHNIQUE | F10: =[19]HISTOJANV24!$BQ$14 -> 0
A11: AS201604 | B11: =VLOOKUP(A11,[16]LISTADHERENT!A$5:H$60,3,0) -> DJOMO JEAN PAUL | C11: =VLOOKUP(A11,[13]MVTRESUME24!$A$7:$Q$41,13,0) -> 12000 | D11: 45323 | E11: ACHAT FOURNITURE | F11: =[19]HISTOFEV24!$BQ$6 -> 3000
A12: AS201654 | B12: =VLOOKUP(A12,[16]LISTADHERENT!A$5:H$60,3,0) -> DJOMOU TCHAPDA | C12: =VLOOKUP(A12,[13]MVTRESUME24!$A$7:$Q$41,13,0) -> 12000 | D12: 45323 | E12: COMMISSION | F12: =[19]HISTOFEV24!$BQ$8 -> 12000
A13: AS201605 | B13: =VLOOKUP(A13,[16]LISTADHERENT!A$5:H$60,3,0) -> DJOUKWE NANGUEN GUY BLAISE | C13: =VLOOKUP(A13,[13]MVTRESUME24!$A$7:$Q$41,13,0) -> 12000 | D13: 45323 | E13: TAXI BANQUE JANV/FEV | F13: =[19]HISTOFEV24!$BQ$13 -> 12000
A14: AS201608 | B14: =VLOOKUP(A14,[16]LISTADHERENT!A$5:H$60,3,0) -> DJUOMBESSY ANTOINE | C14: =VLOOKUP(A14,[13]MVTRESUME24!$A$7:$Q$41,13,0) -> 12000 | D14: 45353 | E14: PRODUCTION RAPPORT | F14: =[19]HISTOMARS24!$BQ$11 -> 30000
A15: AS201651 | B15: =VLOOKUP(A15,[16]LISTADHERENT!A$5:H$60,3,0) -> DOMOU FABIEN | C15: =VLOOKUP(A15,[13]MVTRESUME24!$A$7:$Q$41,13,0) -> 12000 | D15: 45354 | E15: TAXI BANQUE | F15: =[19]HISTOMARS24!$BQ$13 -> 18000
A16: AS201609 | B16: =VLOOKUP(A16,[16]LISTADHERENT!A$5:H$60,3,0) -> DONHOU DAVID | C16: =VLOOKUP(A16,[13]MVTRESUME24!$A$7:$Q$41,13,0) -> 12000 | D16: 45385 | E16: TAXI BANQUE | F16: =[19]HISTOAVRIL24!$BQ$13 -> 6000
A17: AS201611 | B17: =VLOOKUP(A17,[16]LISTADHERENT!A$5:H$60,3,0) -> HENGUE PAUL OMER | C17: =VLOOKUP(A17,[13]MVTRESUME24!$A$7:$Q$41,13,0) -> 12000 | D17: 45386 | E17: COMMISSION | F17: =[19]HISTOAVRIL24!$BQ$8 -> 15000
A18: AS201613 | B18: =VLOOKUP(A18,[16]LISTADHERENT!A$5:H$60,3,0) -> HOTCHO BENJAMIN | C18: =VLOOKUP(A18,[13]MVTRESUME24!$A$7:$Q$41,13,0) -> 12000 | D18: 45416 | E18: TAXI BANQUE | F18: =[19]HISTOMAI24!$BQ$13 -> 6000
A19: AS201617 | B19: =VLOOKUP(A19,[16]LISTADHERENT!A$5:H$60,3,0) -> KOUAMOU MOISE | C19: =VLOOKUP(A19,[13]MVTRESUME24!$A$7:$Q$41,13,0) -> 12000 | D19: 45417 | E19: COMMISSION FERMETURE BANQUE | F19: =[19]HISTOMAI24!$BQ$8 -> 13000
A20: AS201619 | B20: =VLOOKUP(A20,[16]LISTADHERENT!A$5:H$60,3,0) -> KOUATCHO MESSACK | C20: =VLOOKUP(A20,[13]MVTRESUME24!$A$7:$Q$41,13,0) -> 12000 | D20: 45449 | E20: COMMISSION | F20: =+[19]HISTOJUIN24!$BQ$13 -> 12000
A21: AS201620 | B21: =VLOOKUP(A21,[16]LISTADHERENT!A$5:H$60,3,0) -> LOWE JEAN | C21: =VLOOKUP(A21,[13]MVTRESUME24!$A$7:$Q$41,13,0) -> 0 | D21: 45477 | E21: TAXI BANQUE | F21: =+[19]HISTOJUIL24!$BQ$13 -> 6000
A22: AS201661 | B22: =VLOOKUP(A22,[16]LISTADHERENT!A$5:H$60,3,0) -> MASSEUNGOUE DAGOBERT | C22: =VLOOKUP(A22,[13]MVTRESUME24!$A$7:$Q$41,13,0) -> 12000 | D22: 45477 | E22: COMMISSION | F22: =+[19]HISTOJUIL24!$BQ$8 -> 36000
A23: AS201649 | B23: =VLOOKUP(A23,[16]LISTADHERENT!A$5:H$60,3,0) -> MBOGNING TUGMA GUY | C23: =VLOOKUP(A23,[13]MVTRESUME24!$A$7:$Q$41,13,0) -> 12000 | D23: 45508 | E23: TAXI BANQUE | F23: =+[19]HISTOAOUT24!$BQ$13 -> 6000
A24: AS201639 | B24: =VLOOKUP(A24,[16]LISTADHERENT!A$5:H$60,3,0) -> NANGUEN MARTIN | C24: =VLOOKUP(A24,[13]MVTRESUME24!$A$7:$Q$41,13,0) -> 12000 | D24: 45540 | E24: TAXI BANQUE | F24: =+[19]HISTOSEPT24!$BQ$13 -> 6000
A25: AS201621 | B25: =VLOOKUP(A25,[16]LISTADHERENT!A$5:H$60,3,0) -> NANKAM APPOLINAIRE | C25: =VLOOKUP(A25,[13]MVTRESUME24!$A$7:$Q$41,13,0) -> 12000 | D25: 45570 | E25: TAXI BANQUE | F25: =[19]HISTOOCT24!$BQ$13 -> 6000
A26: AS201622 | B26: =VLOOKUP(A26,[16]LISTADHERENT!A$5:H$60,3,0) -> NDJOMO ETIENNE | C26: =VLOOKUP(A26,[13]MVTRESUME24!$A$7:$Q$41,13,0) -> 12000 | D26: 45601 | E26: TAXI BANQUE | F26: =+[19]HISTONOV24!$BQ$13 -> 6000
A27: AS201624 | B27: =VLOOKUP(A27,[16]LISTADHERENT!A$5:H$60,3,0) -> NGONDIEP CLAUDE | C27: =VLOOKUP(A27,[13]MVTRESUME24!$A$7:$Q$41,13,0) -> 12000 | D27: 45631 | E27: COMMISSION | F27: =+[19]HISTODEC24!$BQ$8 -> 25000
A28: AS201626 | B28: =VLOOKUP(A28,[16]LISTADHERENT!A$5:H$60,3,0) -> NGUIEMEGNI MATHIEU BLAISE | C28: =VLOOKUP(A28,[13]MVTRESUME24!$A$7:$Q$41,13,0) -> 12000 | D28: 45631 | F28: =[19]HISTODEC24!$BQ$13 -> 6000
A29: AS201628 | B29: =VLOOKUP(A29,[16]LISTADHERENT!A$5:H$60,3,0) -> NKAMGANG JUSTIN DEJOLIE | C29: =VLOOKUP(A29,[13]MVTRESUME24!$A$7:$Q$41,13,0) -> 12000
A30: AS201656 | B30: =VLOOKUP(A30,[16]LISTADHERENT!A$5:H$60,3,0) -> NOUBE ETIENNE | C30: =VLOOKUP(A30,[13]MVTRESUME24!$A$7:$Q$41,13,0) -> 12000
A31: AS201633 | B31: =VLOOKUP(A31,[16]LISTADHERENT!A$5:H$60,3,0) -> PATEGO NJOSSU GUSTAVE | C31: =VLOOKUP(A31,[13]MVTRESUME24!$A$7:$Q$41,13,0) -> 12000
A32: AS201657 | B32: =VLOOKUP(A32,[16]LISTADHERENT!A$5:H$60,3,0) -> SEUMO POLYCARPE | C32: =VLOOKUP(A32,[13]MVTRESUME24!$A$7:$Q$41,13,0) -> 12000
A33: AS201653 | B33: =VLOOKUP(A33,[16]LISTADHERENT!A$5:H$60,3,0) -> SIME BRICE | C33: =VLOOKUP(A33,[13]MVTRESUME24!$A$7:$Q$41,13,0) -> 12000
A34: AS201638 | B34: =VLOOKUP(A34,[16]LISTADHERENT!A$5:H$60,3,0) -> SIMO PIERRE | C34: =VLOOKUP(A34,[13]MVTRESUME24!$A$7:$Q$41,13,0) -> 12000
A35: AS201641 | B35: =VLOOKUP(A35,[16]LISTADHERENT!A$5:H$60,3,0) -> TCHOUAMOU MATHIEU | C35: =VLOOKUP(A35,[13]MVTRESUME24!$A$7:$Q$41,13,0) -> 12000
A36: AS201660 | B36: =VLOOKUP(A36,[16]LISTADHERENT!A$5:H$60,3,0) -> TCHOUATEU AUGUSTIN | C36: =VLOOKUP(A36,[13]MVTRESUME24!$A$7:$Q$41,13,0) -> 12000
A37: AS201643 | B37: =VLOOKUP(A37,[16]LISTADHERENT!A$5:H$60,3,0) -> TCHOUTOU NANA CLAUDE | C37: =VLOOKUP(A37,[13]MVTRESUME24!$A$7:$Q$41,13,0) -> 12000
A38: AS201658 | B38: =VLOOKUP(A38,[16]LISTADHERENT!A$5:H$60,3,0) -> YANTCHOU GERVAIS | C38: =VLOOKUP(A38,[13]MVTRESUME24!$A$7:$Q$41,13,0) -> 12000
A39: AS201646 | B39: =VLOOKUP(A39,[16]LISTADHERENT!A$5:H$60,3,0) -> YEPMOU JEAN JACQUES | C39: =VLOOKUP(A39,[13]MVTRESUME24!$A$7:$Q$41,13,0) -> 12000
A40: AS201659 | B40: =VLOOKUP(A40,[16]LISTADHERENT!A$5:H$60,3,0) -> YIALA ALAIN OSCAR | C40: =VLOOKUP(A40,[13]MVTRESUME24!$A$7:$Q$41,13,0) -> 12000
A41: AS201647 | B41: =VLOOKUP(A41,[16]LISTADHERENT!A$5:H$60,3,0) -> YOUMBI EMMANUEL | C41: =VLOOKUP(A41,[13]MVTRESUME24!$A$7:$Q$41,13,0) -> 12000
A43: TOTAL | C43: =SUM(C8:C42) -> 384000 | E43: =SUM(E6:E42) -> 0 | F43: =SUM(F6:F42) -> 251000

Sheet DETAILFRAISEXCEPTIONNEL
A1: ASSOCIATION | B1: ASELBY
A2: ANNEE | B2: 2024
A4: FRAIS EXCEPTIONNELLE
A6: MATRICULE | B6: NOM ET PRENOM | C6: ENTREE | D6: SORTIE
C7: MONTANT | D7: DATE | E7: LIBELLE | F7: MONTANT
A8: AS201648 | B8: =VLOOKUP(A8,[16]LISTADHERENT!A$5:H$60,3,0) -> ASELBY | C8: =VLOOKUP(A8,[13]MVTRESUME24!$A$7:$Q$51,14,0) -> 0 | D8: 45292 | E8: GRATIFICATION 2023 | F8: =+[19]HISTOJANV24!$BQ$24 -> 200000
A9: AS201601 | B9: =VLOOKUP(A9,[16]LISTADHERENT!A$5:H$60,3,0) -> BAKOP ACHILLE | C9: =VLOOKUP(A9,[13]MVTRESUME24!$A$7:$Q$41,14,0) -> 12000 | D9: 45292 | E9: DOSSIER TECHNIQUE | F9: =[19]HISTOJANV24!$BQ$25 -> 0
A10: AS201602 | B10: =VLOOKUP(A10,[16]LISTADHERENT!A$5:H$60,3,0) -> BOUTCHOUANG WILLIAM | C10: =VLOOKUP(A10,[13]MVTRESUME24!$A$7:$Q$41,14,0) -> 12000 | D10: 45384 | E10: INSTALLATION CHEF LA'AGWE | F10: =[19]HISTOAVRIL24!$BQ$25 -> 100000
A11: AS201604 | B11: =VLOOKUP(A11,[16]LISTADHERENT!A$5:H$60,3,0) -> DJOMO JEAN PAUL | C11: =VLOOKUP(A11,[13]MVTRESUME24!$A$7:$Q$41,14,0) -> 12000 | D11: 45475 | E11: REMBOURSEMENT DETTE HOTCHO NUIT DES ELITES | F11: =+[19]HISTOJUIL24!$BQ$27 -> 238500
A12: AS201654 | B12: =VLOOKUP(A12,[16]LISTADHERENT!A$5:H$60,3,0) -> DJOMOU TCHAPDA | C12: =VLOOKUP(A12,[13]MVTRESUME24!$A$7:$Q$41,14,0) -> 12000 | D12: 45475 | E12: ASCOBA 2023 | F12: =[19]HISTOJUIL24!$BQ$25 -> 50000
A13: AS201605 | B13: =VLOOKUP(A13,[16]LISTADHERENT!A$5:H$60,3,0) -> DJOUKWE NANGUEN GUY BLAISE | C13: =VLOOKUP(A13,[13]MVTRESUME24!$A$7:$Q$41,14,0) -> 12000 | D13: 45567 | E13: REMBOURSEMENT DETTE NGONDIEP PLAQUETTE | F13: =[19]HISTOOCT24!$BQ$26 -> 321500
A14: AS201608 | B14: =VLOOKUP(A14,[16]LISTADHERENT!A$5:H$60,3,0) -> DJUOMBESSY ANTOINE | C14: =VLOOKUP(A14,[13]MVTRESUME24!$A$7:$Q$41,14,0) -> 12000 | D14: 45598 | E14: ASCOBA 2024 | F14: =[19]HISTOJUIL24!$BQ$25 -> 50000
A15: AS201651 | B15: =VLOOKUP(A15,[16]LISTADHERENT!A$5:H$60,3,0) -> DOMOU FABIEN | C15: =VLOOKUP(A15,[13]MVTRESUME24!$A$7:$Q$41,14,0) -> 12000
A16: AS201609 | B16: =VLOOKUP(A16,[16]LISTADHERENT!A$5:H$60,3,0) -> DONHOU DAVID | C16: =VLOOKUP(A16,[13]MVTRESUME24!$A$7:$Q$41,14,0) -> 12000
A17: AS201611 | B17: =VLOOKUP(A17,[16]LISTADHERENT!A$5:H$60,3,0) -> HENGUE PAUL OMER | C17: =VLOOKUP(A17,[13]MVTRESUME24!$A$7:$Q$41,14,0) -> 12000
A18: AS201613 | B18: =VLOOKUP(A18,[16]LISTADHERENT!A$5:H$60,3,0) -> HOTCHO BENJAMIN | C18: =VLOOKUP(A18,[13]MVTRESUME24!$A$7:$Q$41,14,0) -> 12000
A19: AS201617 | B19: =VLOOKUP(A19,[16]LISTADHERENT!A$5:H$60,3,0) -> KOUAMOU MOISE | C19: =VLOOKUP(A19,[13]MVTRESUME24!$A$7:$Q$41,14,0) -> 12000
A20: AS201619 | B20: =VLOOKUP(A20,[16]LISTADHERENT!A$5:H$60,3,0) -> KOUATCHO MESSACK | C20: =VLOOKUP(A20,[13]MVTRESUME24!$A$7:$Q$41,14,0) -> 12000
A21: AS201620 | B21: =VLOOKUP(A21,[16]LISTADHERENT!A$5:H$60,3,0) -> LOWE JEAN | C21: =VLOOKUP(A21,[13]MVTRESUME24!$A$7:$Q$41,14,0) -> 0
A22: AS201661 | B22: =VLOOKUP(A22,[16]LISTADHERENT!A$5:H$60,3,0) -> MASSEUNGOUE DAGOBERT | C22: =VLOOKUP(A22,[13]MVTRESUME24!$A$7:$Q$41,14,0) -> 12000
A23: AS201649 | B23: =VLOOKUP(A23,[16]LISTADHERENT!A$5:H$60,3,0) -> MBOGNING TUGMA GUY | C23: =VLOOKUP(A23,[13]MVTRESUME24!$A$7:$Q$41,14,0) -> 12000
A24: AS201639 | B24: =VLOOKUP(A24,[16]LISTADHERENT!A$5:H$60,3,0) -> NANGUEN MARTIN | C24: =VLOOKUP(A24,[13]MVTRESUME24!$A$7:$Q$41,14,0) -> 12000
A25: AS201621 | B25: =VLOOKUP(A25,[16]LISTADHERENT!A$5:H$60,3,0) -> NANKAM APPOLINAIRE | C25: =VLOOKUP(A25,[13]MVTRESUME24!$A$7:$Q$41,14,0) -> 12000
A26: AS201622 | B26: =VLOOKUP(A26,[16]LISTADHERENT!A$5:H$60,3,0) -> NDJOMO ETIENNE | C26: =VLOOKUP(A26,[13]MVTRESUME24!$A$7:$Q$41,14,0) -> 12000
... A41: AS201647 | B41: =VLOOKUP(A41,[16]LISTADHERENT!A$5:H$60,3,0) -> YOUMBI EMMANUEL | C41: =VLOOKUP(A41,[13]MVTRESUME24!$A$7:$Q$41,14,0) -> 12000
C43: =SUM(C8:C41) -> 384000 | E43: =SUM(E8:E41) -> 0 | F43: =SUM(F8:F41) -> 960000

Sheet DETAILCOLLATION
A1: ASSOCIATION | B1: ASELBY
A2: ANNEE | B2: 2024
A4: COLLATION
A6: MATRICULE | B6: NOM ET PRENOM | C6: ENTREE | D6: SORTIE
C7: MONTANT | D7: DATE | E7: LIBELLE | F7: MONTANT
A8: AS201648 | B8: =VLOOKUP(A8,[16]LISTADHERENT!A$5:H$60,3,0) -> ASELBY | C8: =VLOOKUP(A8,[13]MVTRESUME24!$A$7:$Q$51,15,0) -> 0 | D8: 45292 | E8: HOTCHO BENJAMIN | F8: =+[19]HISTOJANV24!$BQ$36 -> 100000
A9: AS201601 | B9: =VLOOKUP(A9,[16]LISTADHERENT!A$5:H$60,3,0) -> BAKOP ACHILLE | C9: =VLOOKUP(A9,[13]MVTRESUME24!$A$7:$Q$51,15,0) -> 48000 | D9: 45323 | E9: KOUAMO MOISE | F9: =+[19]HISTOFEV24!$BQ$36 -> 100000
A10: AS201602 | B10: =VLOOKUP(A10,[16]LISTADHERENT!A$5:H$60,3,0) -> BOUTCHOUANG WILLIAM | C10: =VLOOKUP(A10,[13]MVTRESUME24!$A$7:$Q$51,15,0) -> 48000 | D10: 45352 | E10: NGONDIEP CLAUDE | F10: =+[19]HISTOMARS24!$BQ$36 -> 100000
A11: AS201604 | B11: =VLOOKUP(A11,[16]LISTADHERENT!A$5:H$60,3,0) -> DJOMO JEAN PAUL | C11: =VLOOKUP(A11,[13]MVTRESUME24!$A$7:$Q$51,15,0) -> 48000 | D11: 45383 | E11: YOUMBI EMMANUEL | F11: 100000
A12: AS201654 | B12: =VLOOKUP(A12,[16]LISTADHERENT!A$5:H$60,3,0) -> DJOMOU TCHAPDA | C12: =VLOOKUP(A12,[13]MVTRESUME24!$A$7:$Q$51,15,0) -> 48000 | D12: 45413 | E12: FOYER | F12: 100000
A13: AS201605 | B13: =VLOOKUP(A13,[16]LISTADHERENT!A$5:H$60,3,0) -> DJOUKWE NANGUEN GUY BLAISE | C13: =VLOOKUP(A13,[13]MVTRESUME24!$A$7:$Q$51,15,0) -> 48000 | D13: 45444 | E13: NDJOMO ETIENNE | F13: 100000
A14: AS201608 | B14: =VLOOKUP(A14,[16]LISTADHERENT!A$5:H$60,3,0) -> DJUOMBESSY ANTOINE | C14: =VLOOKUP(A14,[13]MVTRESUME24!$A$7:$Q$51,15,0) -> 48000 | D14: 45474 | E14: YEPMO JEAN JACQUES | F14: 100000
A15: AS201651 | B15: =VLOOKUP(A15,[16]LISTADHERENT!A$5:H$60,3,0) -> DOMOU FABIEN | C15: =VLOOKUP(A15,[13]MVTRESUME24!$A$7:$Q$51,15,0) -> 48000 | D15: 45505 | E15: NOUBE ETIENNE | F15: 100000
A16: AS201609 | B16: =VLOOKUP(A16,[16]LISTADHERENT!A$5:H$60,3,0) -> DONHOU DAVID | C16: =VLOOKUP(A16,[13]MVTRESUME24!$A$7:$Q$51,15,0) -> 48000 | D16: 45536 | E16: YANTCHOU HERVE | F16: 100000
A17: AS201611 | B17: =VLOOKUP(A17,[16]LISTADHERENT!A$5:H$60,3,0) -> HENGUE PAUL OMER | C17: =VLOOKUP(A17,[13]MVTRESUME24!$A$7:$Q$51,15,0) -> 48000 | D17: 45566 | E17: FOYER | F17: 100000
A18: AS201613 | B18: =VLOOKUP(A18,[16]LISTADHERENT!A$5:H$60,3,0) -> HOTCHO BENJAMIN | C18: =VLOOKUP(A18,[13]MVTRESUME24!$A$7:$Q$51,15,0) -> 48000 | D18: 45597 | E18: FOYER | F18: 100000
A19: AS201617 | B19: =VLOOKUP(A19,[16]LISTADHERENT!A$5:H$60,3,0) -> KOUAMOU MOISE | C19: =VLOOKUP(A19,[13]MVTRESUME24!$A$7:$Q$51,15,0) -> 48000 | D19: 45627 | E19: SEUMO POLYCARPE | F19: 100000
A20: AS201619 | B20: =VLOOKUP(A20,[16]LISTADHERENT!A$5:H$60,3,0) -> KOUATCHO MESSACK | C20: =VLOOKUP(A20,[13]MVTRESUME24!$A$7:$Q$51,15,0) -> 48000
A21: AS201620 | B21: =VLOOKUP(A21,[16]LISTADHERENT!A$5:H$60,3,0) -> LOWE JEAN | C21: =VLOOKUP(A21,[13]MVTRESUME24!$A$7:$Q$51,15,0) -> 0
A22: AS201661 | B22: =VLOOKUP(A22,[16]LISTADHERENT!A$5:H$60,3,0) -> MASSEUNGOUE DAGOBERT | C22: =VLOOKUP(A22,[13]MVTRESUME24!$A$7:$Q$51,15,0) -> 48000
A23: AS201649 | B23: =VLOOKUP(A23,[16]LISTADHERENT!A$5:H$60,3,0) -> MBOGNING TUGMA GUY | C23: =VLOOKUP(A23,[13]MVTRESUME24!$A$7:$Q$51,15,0) -> 48000
A24: AS201639 | B24: =VLOOKUP(A24,[16]LISTADHERENT!A$5:H$60,3,0) -> NANGUEN MARTIN | C24: =VLOOKUP(A24,[13]MVTRESUME24!$A$7:$Q$51,15,0) -> 48000
A25: AS201621 | B25: =VLOOKUP(A25,[16]LISTADHERENT!A$5:H$60,3,0) -> NANKAM APPOLINAIRE | C25: =VLOOKUP(A25,[13]MVTRESUME24!$A$7:$Q$51,15,0) -> 48000
