Workbook
Name MODEPAID: MODEPAID!$A$1:$A$3
Name MODEPAID: #REF!
Name MODEPAID: #REF!
Name MODEPAID: #REF!
Name MODEPAID: #REF!
Name MODEPAID: #REF!
Name MODEPAID: #REF!
Name MODEPAID: #REF!
Name MODEPAID: #REF!
Name MODEPAID: #REF!
Name MODEPAID: #REF!
Name MODEPAID: #REF!
Name MODEPAID: #REF!
Name MODEPAID: #REF!
Name MODEPAID: #REF!
Name MODEPAID: #REF!
Name MODEPAID: #REF!
Name VALMODEPAID: MODEPAID!$A$1:$A$3

Sheet Feuil1
B1: INTERET VENTE | C1: MISE A PRIX | D1: INTERET MISE EN VENTE | E1: INTERET PETIT LOT | F1: INT CUMUL MISE EN VENTE | G1: INTERET NON REMB | H1: PETIT LOT + INTERET
A2: 42979 | B2: =#REF! -> #REF! | C2: 200000 | D2: =B2-C2 -> #REF! | E2: =#REF! -> #REF! | H2: =#REF! -> #REF! | I2: OK
A3: 43009 | B3: =+#REF! -> #REF! | C3: 200000 | D3: =B3-C3 -> #REF! | E3: =+#REF! -> #REF! | F3: =D2+E2+D3 -> #REF! | H3: =#REF! -> #REF! | I3: OK
A4: 43040 | B4: =+#REF! -> #REF! | C4: 200000 | D4: =B4-C4 -> #REF! | E4: =+#REF! -> #REF! | F4: =F3+D4+E3 -> #REF! | H4: =#REF! -> #REF! | I4: OK
A5: 43070 | B5: =#REF! -> #REF! | C5: 200000 | D5: =B5-C5 -> #REF! | E5: =+#REF! -> #REF! | F5: =F4+D5+E4 -> #REF! | G5: 200000 | H5: =#REF! -> #REF! | I5: NOK
A6: 43101 | B6: =+#REF! -> #REF! | C6: 200000 | D6: =B6-C6 -> #REF! | E6: =+#REF! -> #REF! | F6: =F5+D6+E5 -> #REF! | H6: =#REF! -> #REF!
A7: 43132 | B7: =+#REF! -> #REF! | C7: 200000 | D7: =B7-C7 -> #REF! | E7: =+#REF! -> #REF! | F7: =F6+D7+E6 -> #REF! | G7: 200000 | H7: =#REF! -> #REF!
A8: 43160 | B8: =+#REF! -> #REF! | C8: 200000 | D8: =B8-C8 -> #REF! | E8: =+#REF! -> #REF! | F8: =F7+D8+E7 -> #REF! | H8: =#REF! -> #REF!
A9: 43191 | B9: =+#REF! -> #REF! | C9: 200000 | D9: =B9-C9 -> #REF! | E9: =+#REF! -> #REF! | F9: =F8+D9+E8 -> #REF! | H9: =#REF! -> #REF!
A10: 43221 | B10: =+#REF! -> #REF! | C10: 200000 | D10: =B10-C10 -> #REF! | E10: =+#REF! -> #REF! | F10: =F9+D10+E9 -> #REF! | H10: =#REF! -> #REF!
A11: 43252 | B11: =+#REF! -> #REF! | C11: 200000 | D11: =B11-C11 -> #REF! | E11: =+#REF! -> #REF! | F11: =F10+D11+E10 -> #REF! | H11: =#REF! -> #REF!
A12: 43282 | B12: =+#REF! -> #REF! | C12: 100000 | D12: =B12-C12 -> #REF! | E12: =+#REF! -> #REF! | F12: =F11+D12+E11 -> #REF! | H12: =#REF! -> #REF!
A13: 43313 | B13: 200000 | C13: 200000 | D13: 0 | E13: 0 | F13: =F12+D13+E12 -> #REF! | H13: =#REF! -> #REF!
B14: =SUM(B2:B13) -> #REF! | C14: =SUM(C2:C13) -> 2300000
C15: =+B14-C14 -> #REF! | D15: =SUM(D2:D14) -> #REF! | E15: =SUM(E2:E14) -> #REF! | H15: 1145500 | I15: 2300000
H16: 12000
B17: NGONDIEP | D17: 101000 | H17: =+H15+H16 -> 1157500
B18: NANGUEN | D18: 96000 | H18: 200000
B19: FOTSO THOMAS | D19: 206000 | H19: 269000
H20: =+H17+H18+H19 -> 1626500
H21: =D15+E15-H20 -> #REF!
D22: =SUM(D17:D21) -> 403000

Sheet MODEPAID
A1: BANQUE
A2: ESPECES
A3: ECHEC

Sheet TONTNOV
A1: ASSOCIATION | B1: ASELBY
A2: ANNEE | B2: 2019/2020
A3: TONTINE | B3: 100000
C4: 43793
A5: MATRICULE | B5: NOM ET PRENOM | C5: MONTANT TONTINE | D5: PENALITE | E5: MODE VERSEMENT TONTINE | F5: REPORT ECHEC PETIT LOT | G5: MODE VERSEMENT VENTE PETIT LOT | H5: VENTE PETIT LOT | I5: INTERET PETIT LOT | J5: MODE VERSEMENT VENTE PETIT LOT | K5: NUMERO CHEQUE | L5: REMBOURSEMENT | M5: MODE VERSEMENT REMBOURSEMENT | N5: MODE VERSEMENT TONTINE PRINCIPAL | O5: NUMERO CHEQUE | P5: MONTANT TONTINE LOT PRINCIPAL | Q5: INTERET LOT PRINCIPAL | R5: DATE VENTE
A6: AS201608 | B6: =VLOOKUP(A6,[1]LISTADHERENT!A$5:H$60,3,0) -> DJUOMBESSY ANTOINE | C6: =IF(E6="ECHEC",0,IF(E6="",0,100000)) -> 100000 | D6: =IF(E6="ESPECES",0,0) -> 0 | E6: BANQUE | P6: =IF(Q6=0,0,($C$38-Q6)) -> 0
A7: AS201613 | B7: =VLOOKUP(A7,[1]LISTADHERENT!A$5:H$60,3,0) -> HOTCHO BENJAMIN | C7: =IF(E7="ECHEC",0,IF(E7="",0,100000)) -> 100000 | D7: =IF(E7="ESPECES",0,0) -> 0 | E7: BANQUE | P7: =IF(Q7=0,0,($C$38-Q7)) -> 0
A8: AS201619 | B8: =VLOOKUP(A8,[1]LISTADHERENT!A$5:H$60,3,0) -> KOUATCHO MESSACK | C8: =IF(E8="ECHEC",0,IF(E8="",0,100000)) -> 100000 | D8: =IF(E8="ESPECES",0,0) -> 0 | E8: BANQUE | H8: =100000+50000 -> 150000 | I8: =2500+1000 -> 3500 | J8: ESPECES | P8: =IF(Q8=0,0,($C$38-Q8)) -> 0
A9: AS201617 | B9: =VLOOKUP(A9,[1]LISTADHERENT!A$5:H$60,3,0) -> KOUAMOU MOISE | C9: =IF(E9="ECHEC",0,IF(E9="",0,100000)) -> 100000 | D9: =IF(E9="ESPECES",0,0) -> 0 | E9: BANQUE | P9: =IF(Q9=0,0,($C$38-Q9)) -> 0
A10: AS201649 | B10: =VLOOKUP(A10,[1]LISTADHERENT!A$5:H$60,3,0) -> MBOGNING TUGMA GUY | C10: =IF(E10="ECHEC",0,IF(E10="",0,100000)) -> 100000 | D10: =IF(E10="ESPECES",0,0) -> 0 | E10: BANQUE | H10: =100000+100000 -> 200000 | I10: =2500+5500 -> 8000 | J10: BANQUE | P10: =IF(Q10=0,0,($C$38-Q10)) -> 0
A11: AS201649 | B11: =VLOOKUP(A11,[1]LISTADHERENT!A$5:H$60,3,0) -> MBOGNING TUGMA GUY | C11: =IF(E11="ECHEC",0,IF(E11="",0,100000)) -> 100000 | D11: =IF(E11="ESPECES",0,0) -> 0 | E11: BANQUE | P11: =IF(Q11=0,0,($C$38-Q11)) -> 0
A12: AS201639 | B12: =VLOOKUP(A12,[1]LISTADHERENT!A$5:H$60,3,0) -> NANGUEN MARTIN | C12: =IF(E12="ECHEC",0,IF(E12="",0,100000)) -> 100000 | D12: =IF(E12="ESPECES",0,0) -> 0 | E12: BANQUE | P12: =IF(Q12=0,0,($C$38-Q12)) -> 0
A13: AS201622 | B13: =VLOOKUP(A13,[1]LISTADHERENT!A$5:H$60,3,0) -> NDJOMO ETIENNE | C13: =IF(E13="ECHEC",0,IF(E13="",0,100000)) -> 100000 | D13: =IF(E13="ESPECES",0,0) -> 0 | E13: BANQUE | P13: =IF(Q13=0,0,($C$38-Q13)) -> 0
A14: AS201624 | B14: =VLOOKUP(A14,[1]LISTADHERENT!A$5:H$60,3,0) -> NGONDIEP CLAUDE | C14: =IF(E14="ECHEC",0,IF(E14="",0,100000)) -> 100000 | D14: =IF(E14="ESPECES",0,0) -> 0 | E14: BANQUE | P14: =IF(Q14=0,0,($C$38-Q14)) -> 0
A15: AS201614 | B15: =VLOOKUP(A15,[1]LISTADHERENT!A$5:H$60,3,0) -> NKEHE DAVID | C15: =IF(E15="ECHEC",0,IF(E15="",0,100000)) -> 100000 | D15: =IF(E15="ESPECES",0,0) -> 0 | E15: ESPECES | N15: BANQUE | P15: =IF(Q15=0,0,($C$38-Q15)) -> 1350000 | Q15: 150000 | R15: 43793
A16: AS201629 | B16: =VLOOKUP(A16,[1]LISTADHERENT!A$5:H$60,3,0) -> NKEPSEU DIEUDONNE | C16: =IF(E16="ECHEC",0,IF(E16="",0,100000)) -> 100000 | D16: =IF(E16="ESPECES",0,0) -> 0 | E16: BANQUE | P16: =IF(Q16=0,0,($C$38-Q16)) -> 0
A17: AS201636 | B17: =VLOOKUP(A17,[1]LISTADHERENT!A$5:H$60,3,0) -> SIMO FONGANG ERIC | C17: =IF(E17="ECHEC",0,IF(E17="",0,100000)) -> 100000 | D17: =IF(E17="ESPECES",0,0) -> 0 | E17: BANQUE | P17: =IF(Q17=0,0,($C$38-Q17)) -> 0
A18: AS201636 | B18: =VLOOKUP(A18,[1]LISTADHERENT!A$5:H$60,3,0) -> SIMO FONGANG ERIC | C18: =IF(E18="ECHEC",0,IF(E18="",0,100000)) -> 100000 | D18: =IF(E18="ESPECES",0,0) -> 0 | E18: BANQUE | P18: =IF(Q18=0,0,($C$38-Q18)) -> 0
A19: AS201637 | B19: =VLOOKUP(A19,[1]LISTADHERENT!A$5:H$60,3,0) -> SIME MATHIEU | C19: =IF(E19="ECHEC",0,IF(E19="",0,100000)) -> 100000 | D19: =IF(E19="ESPECES",0,0) -> 0 | E19: BANQUE | P19: =IF(Q19=0,0,($C$38-Q19)) -> 0
A20: AS201637 | B20: =VLOOKUP(A20,[1]LISTADHERENT!A$5:H$60,3,0) -> SIME MATHIEU | C20: =IF(E20="ECHEC",0,IF(E20="",0,100000)) -> 100000 | D20: =IF(E20="ESPECES",0,0) -> 0 | E20: BANQUE | P20: =IF(Q20=0,0,($C$38-Q20)) -> 0
A21: AS201641 | B21: =VLOOKUP(A21,[1]LISTADHERENT!A$5:H$60,3,0) -> TCHOUAMOU MATHIEU | C21: =IF(E21="ECHEC",0,IF(E21="",0,100000)) -> 100000 | D21: =IF(E21="ESPECES",0,0) -> 0 | E21: BANQUE | P21: =IF(Q21=0,0,($C$38-Q21)) -> 0
A22: AS201644 | B22: =VLOOKUP(A22,[1]LISTADHERENT!A$5:H$60,3,0) -> TIEYAM ERNEST | C22: =IF(E22="ECHEC",0,IF(E22="",0,100000)) -> 100000 | D22: =IF(E22="ESPECES",0,0) -> 0 | E22: BANQUE | H22: =100000+100000 -> 200000 | I22: =4000+9000 -> 13000 | J22: BANQUE | P22: =IF(Q22=0,0,($C$38-Q22)) -> 0
A23: AS201647 | B23: =VLOOKUP(A23,[1]LISTADHERENT!A$5:H$60,3,0) -> YOUMBI EMMANUEL | C23: =IF(E23="ECHEC",0,IF(E23="",0,100000)) -> 100000 | D23: =IF(E23="ESPECES",0,0) -> 0 | E23: BANQUE | P23: =IF(Q23=0,0,($C$38-Q23)) -> 0
A25: TOTAL | C25: =SUM(C6:C24) -> 1800000 | D25: =SUM(D6:D24) -> 0 | F25: =SUM(F6:F24) -> 0 | H25: =SUM(H6:H24) -> 550000 | I25: =SUM(I6:I24) -> 24500 | L25: =SUM(L6:L24) -> 0 | P25: =SUM(P6:P24) -> 1350000 | Q25: =SUM(Q6:Q24) -> 150000
C27: TONTINE | D27: REMBOURSEMENT PETIT LOT | E27: VENTE PETIT LOT | F27: VENTE LOT PRINCIPAL | G27: SOLDE EN CAISSE | M27: TONTINE + REMB + INTERET VENTE | N27: =C32+D32+Q25 -> 1950000
M28: VENDUE | N28: =IF(N27>=2800000,1500000*2,1500000) -> 1500000
B29: ESPECES | C29: =SUMIFS(C6:C24,E6:E24,"ESPECES") -> 100000 | D29: =SUMIFS(L6:L24,M6:M24,"ESPECES")+SUMIFS(F6:F24,G6:G24,"ESPECES") -> 0 | E29: =SUMIFS(H6:H24,J6:J24,"ESPECES") -> 150000 | F29: =SUMIFS(P6:P24,N6:N24,"ESPECES") -> 0 | G29: =C29+D29-E29-F29 -> -50000
B30: BANQUE | C30: =SUMIFS(C6:C24,E6:E24,"BANQUE") -> 1700000 | D30: =SUMIFS(L6:L24,M6:M24,"BANQUE")+SUMIFS(F6:F24,G6:G24,"BANQUE") -> 0 | E30: =SUMIFS(H6:H24,J6:J24,"BANQUE") -> 400000 | F30: =SUMIFS(P6:P24,N6:N24,"BANQUE") -> 1350000 | G30: =C30+D30-E30-F30 -> -50000 | M30: PETIT LOT | N30: =N27-N28 -> 450000
B32: TOTAL | C32: =C29+C30 -> 1800000 | D32: =D29+D30 -> 0 | E32: =E29+E30 -> 550000 | F32: =F29+F30 -> 1350000 | G32: =G29+G30 -> -100000 | M32: RELIQUAT | N32: =N30-H25 -> -100000 | O32: =N32 -> -100000 | P32: CUMUL
M34: ECHEC TONTINE | N34: =COUNTIFS(E6:E24,"ECHEC")*100000 -> 0 | O34: =N34 -> 0 | P34: CUMUL
B35: INTERET LOT PRINCIPAL | C35: =Q25 -> 150000 | M35: ECHEC REMBOURSEMENT | N35: =SUMIFS(F6:F24,G6:G24,"ECHEC") -> 0 | P35: CUMUL
B36: INTERET PETIT LOT | C36: =+I25 -> 24500
B38: MONTANT TONTINE | C38: 1500000
B39: MONTANT PETIT LOT A VENDRE | C39: =H25 -> 550000

Sheet TONTDEC
A1: ASSOCIATION | B1: ASELBY
A2: ANNEE | B2: 2019/2020
A3: TONTINE | B3: 100000
C4: 43814
A5: MATRICULE | B5: NOM ET PRENOM | C5: MONTANT TONTINE | D5: PENALITE | E5: MODE VERSEMENT TONTINE | F5: REPORT ECHEC PETIT LOT | G5: MODE VERSEMENT VENTE PETIT LOT | H5: VENTE PETIT LOT | I5: INTERET PETIT LOT | J5: MODE VERSEMENT VENTE PETIT LOT | K5: NUMERO CHEQUE | L5: REMBOURSEMENT | M5: MODE VERSEMENT REMBOURSEMENT | N5: MODE VERSEMENT TONTINE PRINCIPAL | O5: NUMERO CHEQUE | P5: MONTANT TONTINE LOT PRINCIPAL | Q5: INTERET LOT PRINCIPAL | R5: DATE VENTE
A6: AS201608 | B6: =VLOOKUP(A6,[1]LISTADHERENT!A$5:H$60,3,0) -> DJUOMBESSY ANTOINE | C6: =IF(E6="ECHEC",0,IF(E6="",0,100000)) -> 100000 | D6: =IF(E6="ESPECES",0,0) -> 0 | E6: BANQUE | F6: =TONTNOV!F6 -> 0 | L6: =TONTNOV!H6+TONTNOV!I6 -> 0 | P6: =IF(Q6=0,0,($C$38-Q6)) -> 0
A7: AS201613 | B7: =VLOOKUP(A7,[1]LISTADHERENT!A$5:H$60,3,0) -> HOTCHO BENJAMIN | C7: =IF(E7="ECHEC",0,IF(E7="",0,100000)) -> 100000 | D7: =IF(E7="ESPECES",0,0) -> 0 | E7: BANQUE | F7: =TONTNOV!F7 -> 0 | L7: =TONTNOV!H7+TONTNOV!I7 -> 0 | P7: =IF(Q7=0,0,($C$38-Q7)) -> 0
A8: AS201619 | B8: =VLOOKUP(A8,[1]LISTADHERENT!A$5:H$60,3,0) -> KOUATCHO MESSACK | C8: =IF(E8="ECHEC",0,IF(E8="",0,100000)) -> 100000 | D8: =IF(E8="ESPECES",0,0) -> 0 | E8: BANQUE | F8: =TONTNOV!F8 -> 0 | L8: =TONTNOV!H8+TONTNOV!I8 -> 153500 | M8: BANQUE | P8: =IF(Q8=0,0,($C$38-Q8)) -> 1250000 | Q8: 250000 | R8: 43814
A9: AS201617 | B9: =VLOOKUP(A9,[1]LISTADHERENT!A$5:H$60,3,0) -> KOUAMOU MOISE | C9: =IF(E9="ECHEC",0,IF(E9="",0,100000)) -> 100000 | D9: =IF(E9="ESPECES",0,0) -> 0 | E9: BANQUE | F9: =TONTNOV!F9 -> 0 | L9: =TONTNOV!H9+TONTNOV!I9 -> 0 | P9: =IF(Q9=0,0,($C$38-Q9)) -> 0
A10: AS201649 | B10: =VLOOKUP(A10,[1]LISTADHERENT!A$5:H$60,3,0) -> MBOGNING TUGMA GUY | C10: =IF(E10="ECHEC",0,IF(E10="",0,100000)) -> 100000 | D10: =IF(E10="ESPECES",0,0) -> 0 | E10: BANQUE | F10: =TONTNOV!F10 -> 0 | L10: =TONTNOV!H10+TONTNOV!I10 -> 208000 | M10: BANQUE | P10: =IF(Q10=0,0,($C$38-Q10)) -> 0
A11: AS201649 | B11: =VLOOKUP(A11,[1]LISTADHERENT!A$5:H$60,3,0) -> MBOGNING TUGMA GUY | C11: =IF(E11="ECHEC",0,IF(E11="",0,100000)) -> 100000 | D11: =IF(E11="ESPECES",0,0) -> 0 | E11: BANQUE | F11: =TONTNOV!F11 -> 0 | L11: =TONTNOV!H11+TONTNOV!I11 -> 0 | P11: =IF(Q11=0,0,($C$38-Q11)) -> 0
A12: AS201639 | B12: =VLOOKUP(A12,[1]LISTADHERENT!A$5:H$60,3,0) -> NANGUEN MARTIN | C12: =IF(E12="ECHEC",0,IF(E12="",0,100000)) -> 100000 | D12: =IF(E12="ESPECES",0,0) -> 0 | E12: BANQUE | F12: =TONTNOV!F12 -> 0 | L12: =TONTNOV!H12+TONTNOV!I12 -> 0 | P12: =IF(Q12=0,0,($C$38-Q12)) -> 0
A13: AS201622 | B13: =VLOOKUP(A13,[1]LISTADHERENT!A$5:H$60,3,0) -> NDJOMO ETIENNE | C13: =IF(E13="ECHEC",0,IF(E13="",0,100000)) -> 100000 | D13: =IF(E13="ESPECES",0,0) -> 0 | E13: BANQUE | F13: =TONTNOV!F13 -> 0 | L13: =TONTNOV!H13+TONTNOV!I13 -> 0 | P13: =IF(Q13=0,0,($C$38-Q13)) -> 0
A14: AS201624 | B14: =VLOOKUP(A14,[1]LISTADHERENT!A$5:H$60,3,0) -> NGONDIEP CLAUDE | C14: =IF(E14="ECHEC",0,IF(E14="",0,100000)) -> 100000 | D14: =IF(E14="ESPECES",0,0) -> 0 | E14: BANQUE | F14: =TONTNOV!F14 -> 0 | L14: =TONTNOV!H14+TONTNOV!I14 -> 0 | P14: =IF(Q14=0,0,($C$38-Q14)) -> 0
A15: AS201614 | B15: =VLOOKUP(A15,[1]LISTADHERENT!A$5:H$60,3,0) -> NKEHE DAVID | C15: =IF(E15="ECHEC",0,IF(E15="",0,100000)) -> 100000 | D15: =IF(E15="ESPECES",0,0) -> 0 | E15: BANQUE | F15: =TONTNOV!F15 -> 0 | L15: =TONTNOV!H15+TONTNOV!I15 -> 0 | P15: =IF(Q15=0,0,($C$38-Q15)) -> 0
A16: AS201629 | B16: =VLOOKUP(A16,[1]LISTADHERENT!A$5:H$60,3,0) -> NKEPSEU DIEUDONNE | C16: =IF(E16="ECHEC",0,IF(E16="",0,100000)) -> 100000 | D16: =IF(E16="ESPECES",0,0) -> 0 | E16: ESPECES | F16: =TONTNOV!F16 -> 0 | L16: =TONTNOV!H16+TONTNOV!I16 -> 0 | P16: =IF(Q16=0,0,($C$38-Q16)) -> 0
A17: AS201636 | B17: =VLOOKUP(A17,[1]LISTADHERENT!A$5:H$60,3,0) -> SIMO FONGANG ERIC | C17: =IF(E17="ECHEC",0,IF(E17="",0,100000)) -> 100000 | D17: =IF(E17="ESPECES",0,0) -> 0 | E17: ESPECES | F17: =TONTNOV!F17 -> 0 | L17: =TONTNOV!H17+TONTNOV!I17 -> 0 | P17: =IF(Q17=0,0,($C$38-Q17)) -> 1255000 | Q17: 245000 | R17: 43814
A18: AS201636 | B18: =VLOOKUP(A18,[1]LISTADHERENT!A$5:H$60,3,0) -> SIMO FONGANG ERIC | C18: =IF(E18="ECHEC",0,IF(E18="",0,100000)) -> 100000 | D18: =IF(E18="ESPECES",0,0) -> 0 | E18: ESPECES | F18: =TONTNOV!F18 -> 0 | L18: =TONTNOV!H18+TONTNOV!I18 -> 0 | N18: BANQUE | P18: =IF(Q18=0,0,($C$38-Q18)) -> 0
A19: AS201637 | B19: =VLOOKUP(A19,[1]LISTADHERENT!A$5:H$60,3,0) -> SIME MATHIEU | C19: =IF(E19="ECHEC",0,IF(E19="",0,100000)) -> 100000 | D19: =IF(E19="ESPECES",0,0) -> 0 | E19: BANQUE | F19: =TONTNOV!F19 -> 0 | L19: =TONTNOV!H19+TONTNOV!I19 -> 0 | P19: =IF(Q19=0,0,($C$38-Q19)) -> 0
A20: AS201637 | B20: =VLOOKUP(A20,[1]LISTADHERENT!A$5:H$60,3,0) -> SIME MATHIEU | C20: =IF(E20="ECHEC",0,IF(E20="",0,100000)) -> 100000 | D20: =IF(E20="ESPECES",0,0) -> 0 | E20: BANQUE | F20: =TONTNOV!F20 -> 0 | L20: =TONTNOV!H20+TONTNOV!I20 -> 0 | P20: =IF(Q20=0,0,($C$38-Q20)) -> 0
A21: AS201641 | B21: =VLOOKUP(A21,[1]LISTADHERENT!A$5:H$60,3,0) -> TCHOUAMOU MATHIEU | C21: =IF(E21="ECHEC",0,IF(E21="",0,100000)) -> 100000 | D21: =IF(E21="ESPECES",0,0) -> 0 | E21: BANQUE | F21: =TONTNOV!F21 -> 0 | L21: =TONTNOV!H21+TONTNOV!I21 -> 0 | P21: =IF(Q21=0,0,($C$38-Q21)) -> 0
A22: AS201644 | B22: =VLOOKUP(A22,[1]LISTADHERENT!A$5:H$60,3,0) -> TIEYAM ERNEST | C22: =IF(E22="ECHEC",0,IF(E22="",0,100000)) -> 100000 | D22: =IF(E22="ESPECES",0,0) -> 0 | E22: BANQUE | F22: =TONTNOV!F22 -> 0 | L22: =TONTNOV!H22+TONTNOV!I22 -> 213000 | M22: ESPECES | P22: =IF(Q22=0,0,($C$38-Q22)) -> 0
A23: AS201647 | B23: =VLOOKUP(A23,[1]LISTADHERENT!A$5:H$60,3,0) -> YOUMBI EMMANUEL | C23: =IF(E23="ECHEC",0,IF(E23="",0,100000)) -> 100000 | D23: =IF(E23="ESPECES",0,0) -> 0 | E23: BANQUE | F23: =TONTNOV!F23 -> 0 | L23: =TONTNOV!H23+TONTNOV!I23 -> 0 | P23: =IF(Q23=0,0,($C$38-Q23)) -> 0
A25: TOTAL | C25: =SUM(C6:C24) -> 1800000 | D25: =SUM(D6:D24) -> 0 | F25: =SUM(F6:F24) -> 0 | H25: =SUM(H6:H24) -> 0 | I25: =SUM(I6:I24) -> 0 | L25: =SUM(L6:L24) -> 574500 | P25: =SUM(P6:P24) -> 2505000 | Q25: =SUM(Q6:Q24) -> 495000
C27: TONTINE | D27: REMBOURSEMENT PETIT LOT | E27: VENTE PETIT LOT | F27: VENTE LOT PRINCIPAL | G27: SOLDE EN CAISSE | M27: TONTINE + REMB + INTERET VENTE | N27: =C32+D32+Q25 -> 2869500
M28: VENDUE | N28: =IF(N27>=2800000,1500000*2,1500000) -> 3000000
B29: ESPECES | C29: =SUMIFS(C6:C24,E6:E24,"ESPECES") -> 300000 | D29: =SUMIFS(L6:L24,M6:M24,"ESPECES")+SUMIFS(F6:F24,G6:G24,"ESPECES") -> 213000 | E29: =SUMIFS(H6:H24,J6:J24,"ESPECES") -> 0 | F29: =SUMIFS(P6:P24,N6:N24,"ESPECES") -> 0 | G29: =C29+D29-E29-F29 -> 513000
B30: BANQUE | C30: =SUMIFS(C6:C24,E6:E24,"BANQUE") -> 1500000 | D30: =SUMIFS(L6:L24,M6:M24,"BANQUE")+SUMIFS(F6:F24,G6:G24,"BANQUE") -> 361500 | E30: =SUMIFS(H6:H24,J6:J24,"BANQUE") -> 0 | F30: =SUMIFS(P6:P24,N6:N24,"BANQUE") -> 0 | G30: =C30+D30-E30-F30 -> 1861500 | M30: PETIT LOT | N30: =N27-N28 -> -130500
B32: TOTAL | C32: =C29+C30 -> 1800000 | D32: =D29+D30 -> 574500 | E32: =E29+E30 -> 0 | F32: =F29+F30 -> 0 | G32: =G29+G30 -> 2374500 | M32: RELIQUAT | N32: =N30-H25 -> -130500 | O32: =N32+TONTNOV!O32 -> -230500 | P32: CUMUL
M34: ECHEC TONTINE | N34: =COUNTIFS(E6:E24,"ECHEC")*100000 -> 0 | O34: =N34+TONTNOV!O34 -> 0 | P34: CUMUL
B35: INTERET LOT PRINCIPAL | C35: =Q25 -> 495000 | M35: ECHEC REMBOURSEMENT | N35: =SUMIFS(F6:F24,G6:G24,"ECHEC") -> 0 | P35: CUMUL
B36: INTERET PETIT LOT | C36: =+I25 -> 0
B38: MONTANT TONTINE | C38: 1500000
B39: MONTANT PETIT LOT A VENDRE | C39: =H25 -> 0

Sheet TONTJANV
A1: ASSOCIATION | B1: ASELBY
A2: ANNEE | B2: 2019/2020
A3: TONTINE | B3: 100000
C4: 43848
A5: MATRICULE | B5: NOM ET PRENOM | C5: MONTANT TONTINE | D5: PENALITE | E5: MODE VERSEMENT TONTINE | F5: REPORT ECHEC PETIT LOT | G5: MODE VERSEMENT VENTE PETIT LOT | H5: VENTE PETIT LOT | I5: INTERET PETIT LOT | J5: MODE VERSEMENT VENTE PETIT LOT | K5: NUMERO CHEQUE | L5: REMBOURSEMENT | M5: MODE VERSEMENT REMBOURSEMENT | N5: MODE VERSEMENT TONTINE PRINCIPAL | O5: NUMERO CHEQUE | P5: MONTANT TONTINE LOT PRINCIPAL | Q5: INTERET LOT PRINCIPAL | R5: DATE VENTE
A6: AS201608 | B6: =VLOOKUP(A6,[1]LISTADHERENT!A$5:H$60,3,0) -> DJUOMBESSY ANTOINE | C6: =IF(E6="ECHEC",0,IF(E6="",0,100000)) -> 100000 | D6: =IF(E6="ESPECES",0,0) -> 0 | E6: BANQUE | F6: =TONTDEC!F6 -> 0 | L6: =TONTDEC!H6+TONTDEC!I6 -> 0 | P6: =IF(Q6=0,0,($C$38-Q6)) -> 0
A7: AS201613 | B7: =VLOOKUP(A7,[1]LISTADHERENT!A$5:H$60,3,0) -> HOTCHO BENJAMIN | C7: =IF(E7="ECHEC",0,IF(E7="",0,100000)) -> 100000 | D7: =IF(E7="ESPECES",0,0) -> 0 | E7: BANQUE | F7: =TONTDEC!F7 -> 0 | L7: =TONTDEC!H7+TONTDEC!I7 -> 0 | P7: =IF(Q7=0,0,($C$38-Q7)) -> 0
A8: AS201619 | B8: =VLOOKUP(A8,[1]LISTADHERENT!A$5:H$60,3,0) -> KOUATCHO MESSACK | C8: =IF(E8="ECHEC",0,IF(E8="",0,100000)) -> 100000 | D8: =IF(E8="ESPECES",0,0) -> 0 | E8: BANQUE | F8: =TONTDEC!F8 -> 0 | H8: 100000 | I8: 4000 | J8: ESPECES | L8: =TONTDEC!H8+TONTDEC!I8 -> 0 | P8: =IF(Q8=0,0,($C$38-Q8)) -> 0
A9: AS201617 | B9: =VLOOKUP(A9,[1]LISTADHERENT!A$5:H$60,3,0) -> KOUAMOU MOISE | C9: =IF(E9="ECHEC",0,IF(E9="",0,100000)) -> 100000 | D9: =IF(E9="ESPECES",0,0) -> 0 | E9: BANQUE | F9: =TONTDEC!F9 -> 0 | L9: =TONTDEC!H9+TONTDEC!I9 -> 0 | P9: =IF(Q9=0,0,($C$38-Q9)) -> 0
A10: AS201649 | B10: =VLOOKUP(A10,[1]LISTADHERENT!A$5:H$60,3,0) -> MBOGNING TUGMA GUY | C10: =IF(E10="ECHEC",0,IF(E10="",0,100000)) -> 100000 | D10: =IF(E10="ESPECES",0,0) -> 0 | E10: BANQUE | F10: =TONTDEC!F10 -> 0 | L10: =TONTDEC!H10+TONTDEC!I10 -> 0 | P10: =IF(Q10=0,0,($C$38-Q10)) -> 1270000 | Q10: 230000
A11: AS201649 | B11: =VLOOKUP(A11,[1]LISTADHERENT!A$5:H$60,3,0) -> MBOGNING TUGMA GUY | C11: =IF(E11="ECHEC",0,IF(E11="",0,100000)) -> 100000 | D11: =IF(E11="ESPECES",0,0) -> 0 | E11: BANQUE | F11: =TONTDEC!F11 -> 0 | L11: =TONTDEC!H11+TONTDEC!I11 -> 0 | P11: =IF(Q11=0,0,($C$38-Q11)) -> 0
A12: AS201639 | B12: =VLOOKUP(A12,[1]LISTADHERENT!A$5:H$60,3,0) -> NANGUEN MARTIN | C12: =IF(E12="ECHEC",0,IF(E12="",0,100000)) -> 100000 | D12: =IF(E12="ESPECES",0,0) -> 0 | E12: BANQUE | F12: =TONTDEC!F12 -> 0 | L12: =TONTDEC!H12+TONTDEC!I12 -> 0 | P12: =IF(Q12=0,0,($C$38-Q12)) -> 0
A13: AS201622 | B13: =VLOOKUP(A13,[1]LISTADHERENT!A$5:H$60,3,0) -> NDJOMO ETIENNE | C13: =IF(E13="ECHEC",0,IF(E13="",0,100000)) -> 100000 | D13: =IF(E13="ESPECES",0,0) -> 0 | E13: BANQUE | F13: =TONTDEC!F13 -> 0 | L13: =TONTDEC!H13+TONTDEC!I13 -> 0 | P13: =IF(Q13=0,0,($C$38-Q13)) -> 0
A14: AS201624 | B14: =VLOOKUP(A14,[1]LISTADHERENT!A$5:H$60,3,0) -> NGONDIEP CLAUDE | C14: =IF(E14="ECHEC",0,IF(E14="",0,100000)) -> 100000 | D14: =IF(E14="ESPECES",0,0) -> 0 | E14: BANQUE | F14: =TONTDEC!F14 -> 0 | H14: 99500 | I14: 4000 | J14: ESPECES | L14: =TONTDEC!H14+TONTDEC!I14 -> 0 | P14: =IF(Q14=0,0,($C$38-Q14)) -> 0
A15: AS201614 | B15: =VLOOKUP(A15,[1]LISTADHERENT!A$5:H$60,3,0) -> NKEHE DAVID | C15: =IF(E15="ECHEC",0,IF(E15="",0,100000)) -> 100000 | D15: =IF(E15="ESPECES",0,0) -> 0 | E15: BANQUE | F15: =TONTDEC!F15 -> 0 | H15: 100000 | I15: 6000 | J15: ESPECES | L15: =TONTDEC!H15+TONTDEC!I15 -> 0 | P15: =IF(Q15=0,0,($C$38-Q15)) -> 0
A16: AS201629 | B16: =VLOOKUP(A16,[1]LISTADHERENT!A$5:H$60,3,0) -> NKEPSEU DIEUDONNE | C16: =IF(E16="ECHEC",0,IF(E16="",0,100000)) -> 100000 | D16: =IF(E16="ESPECES",0,0) -> 0 | E16: BANQUE | F16: =TONTDEC!F16 -> 0 | L16: =TONTDEC!H16+TONTDEC!I16 -> 0 | P16: =IF(Q16=0,0,($C$38-Q16)) -> 0
A17: AS201636 | B17: =VLOOKUP(A17,[1]LISTADHERENT!A$5:H$60,3,0) -> SIMO FONGANG ERIC | C17: =IF(E17="ECHEC",0,IF(E17="",0,100000)) -> 100000 | D17: =IF(E17="ESPECES",0,0) -> 0 | E17: BANQUE | F17: =TONTDEC!F17 -> 0 | L17: =TONTDEC!H17+TONTDEC!I17 -> 0 | P17: =IF(Q17=0,0,($C$38-Q17)) -> 0
A18: AS201636 | B18: =VLOOKUP(A18,[1]LISTADHERENT!A$5:H$60,3,0) -> SIMO FONGANG ERIC | C18: =IF(E18="ECHEC",0,IF(E18="",0,100000)) -> 100000 | D18: =IF(E18="ESPECES",0,0) -> 0 | E18: BANQUE | F18: =TONTDEC!F18 -> 0 | L18: =TONTDEC!H18+TONTDEC!I18 -> 0 | P18: =IF(Q18=0,0,($C$38-Q18)) -> 0
A19: AS201637 | B19: =VLOOKUP(A19,[1]LISTADHERENT!A$5:H$60,3,0) -> SIME MATHIEU | C19: =IF(E19="ECHEC",0,IF(E19="",0,100000)) -> 100000 | D19: =IF(E19="ESPECES",0,0) -> 0 | E19: BANQUE | F19: =TONTDEC!F19 -> 0 | L19: =TONTDEC!H19+TONTDEC!I19 -> 0 | P19: =IF(Q19=0,0,($C$38-Q19)) -> 0
A20: AS201637 | B20: =VLOOKUP(A20,[1]LISTADHERENT!A$5:H$60,3,0) -> SIME MATHIEU | C20: =IF(E20="ECHEC",0,IF(E20="",0,100000)) -> 100000 | D20: =IF(E20="ESPECES",0,0) -> 0 | E20: BANQUE | F20: =TONTDEC!F20 -> 0 | L20: =TONTDEC!H20+TONTDEC!I20 -> 0 | P20: =IF(Q20=0,0,($C$38-Q20)) -> 0
A21: AS201641 | B21: =VLOOKUP(A21,[1]LISTADHERENT!A$5:H$60,3,0) -> TCHOUAMOU MATHIEU | C21: =IF(E21="ECHEC",0,IF(E21="",0,100000)) -> 100000 | D21: =IF(E21="ESPECES",0,0) -> 0 | E21: BANQUE | F21: =TONTDEC!F21 -> 0 | L21: =TONTDEC!H21+TONTDEC!I21 -> 0 | P21: =IF(Q21=0,0,($C$38-Q21)) -> 0
A22: AS201644 | B22: =VLOOKUP(A22,[1]LISTADHERENT!A$5:H$60,3,0) -> TIEYAM ERNEST | C22: =IF(E22="ECHEC",0,IF(E22="",0,100000)) -> 100000 | D22: =IF(E22="ESPECES",0,0) -> 0 | E22: BANQUE | F22: =TONTDEC!F22 -> 0 | H22: 200000 | I22: 10000 | J22: ESPECES | L22: =TONTDEC!H22+TONTDEC!I22 -> 0 | P22: =IF(Q22=0,0,($C$38-Q22)) -> 0
A23: AS201647 | B23: =VLOOKUP(A23,[1]LISTADHERENT!A$5:H$60,3,0) -> YOUMBI EMMANUEL | C23: =IF(E23="ECHEC",0,IF(E23="",0,100000)) -> 100000 | D23: =IF(E23="ESPECES",0,0) -> 0 | E23: BANQUE | F23: =TONTDEC!F23 -> 0 | L23: =TONTDEC!H23+TONTDEC!I23 -> 0 | P23: =IF(Q23=0,0,($C$38-Q23)) -> 0
A25: TOTAL | C25: =SUM(C6:C24) -> 1800000 | D25: =SUM(D6:D24) -> 0 | F25: =SUM(F6:F24) -> 0 | H25: =SUM(H6:H24) -> 499500 | I25: =SUM(I6:I24) -> 24000 | L25: =SUM(L6:L24) -> 0 | P25: =SUM(P6:P24) -> 1270000 | Q25: =SUM(Q6:Q24) -> 230000
C27: TONTINE | D27: REMBOURSEMENT PETIT LOT | E27: VENTE PETIT LOT | F27: VENTE LOT PRINCIPAL | G27: SOLDE EN CAISSE | M27: TONTINE + REMB + INTERET VENTE | N27: =C32+D32+Q25 -> 2030000
M28: VENDUE | N28: =IF(N27>=2800000,1500000*2,1500000) -> 1500000
B29: ESPECES | C29: =SUMIFS(C6:C24,E6:E24,"ESPECES") -> 0 | D29: =SUMIFS(L6:L24,M6:M24,"ESPECES")+SUMIFS(F6:F24,G6:G24,"ESPECES") -> 0 | E29: =SUMIFS(H6:H24,J6:J24,"ESPECES") -> 499500 | F29: =SUMIFS(P6:P24,N6:N24,"ESPECES") -> 0 | G29: =C29+D29-E29-F29 -> -499500
B30: BANQUE | C30: =SUMIFS(C6:C24,E6:E24,"BANQUE") -> 1800000 | D30: =SUMIFS(L6:L24,M6:M24,"BANQUE")+SUMIFS(F6:F24,G6:G24,"BANQUE") -> 0 | E30: =SUMIFS(H6:H24,J6:J24,"BANQUE") -> 0 | F30: =SUMIFS(P6:P24,N6:N24,"BANQUE") -> 0 | G30: =C30+D30-E30-F30 -> 1800000 | M30: PETIT LOT | N30: =N27-N28 -> 530000
B32: TOTAL | C32: =C29+C30 -> 1800000 | D32: =D29+D30 -> 0 | E32: =E29+E30 -> 499500 | F32: =F29+F30 -> 0 | G32: =G29+G30 -> 1300500 | M32: RELIQUAT | N32: =N30-H25 -> 30500 | O32: =N32+TONTDEC!O32 -> -200000 | P32: CUMUL
M34: ECHEC TONTINE | N34: =COUNTIFS(E6:E24,"ECHEC")*100000 -> 0 | O34: =N34+TONTDEC!O34 -> 0 | P34: CUMUL
B35: INTERET LOT PRINCIPAL | C35: =Q25 -> 230000 | M35: ECHEC REMBOURSEMENT | N35: =SUMIFS(F6:F24,G6:G24,"ECHEC") -> 0 | P35: CUMUL
B36: INTERET PETIT LOT | C36: =+I25 -> 24000
B38: MONTANT TONTINE | C38: 1500000
B39: MONTANT PETIT LOT A VENDRE | C39: =H25 -> 499500

Sheet TONTFEV
A1: ASSOCIATION | B1: ASELBY
A2: ANNEE | B2: 2019/2020
A3: TONTINE | B3: 100000
C4: 43877
A5: MATRICULE | B5: NOM ET PRENOM | C5: MONTANT TONTINE | D5: PENALITE | E5: MODE VERSEMENT TONTINE | F5: REPORT ECHEC PETIT LOT | G5: MODE VERSEMENT VENTE PETIT LOT | H5: VENTE PETIT LOT | I5: INTERET PETIT LOT | J5: MODE VERSEMENT VENTE PETIT LOT | K5: NUMERO CHEQUE | L5: REMBOURSEMENT | M5: MODE VERSEMENT REMBOURSEMENT | N5: MODE VERSEMENT TONTINE PRINCIPAL | O5: NUMERO CHEQUE | P5: MONTANT TONTINE LOT PRINCIPAL | Q5: INTERET LOT PRINCIPAL | R5: DATE VENTE
A6: AS201608 | B6: =VLOOKUP(A6,[1]LISTADHERENT!A$5:H$60,3,0) -> DJUOMBESSY ANTOINE | C6: =IF(E6="ECHEC",0,IF(E6="",0,100000)) -> 100000 | D6: =IF(E6="ESPECES",0,0) -> 0 | E6: BANQUE | F6: =TONTJANV!F6 -> 0 | L6: =TONTJANV!H6+TONTJANV!I6 -> 0 | P6: =IF(Q6=0,0,($C$38-Q6)) -> 0
A7: AS201613 | B7: =VLOOKUP(A7,[1]LISTADHERENT!A$5:H$60,3,0) -> HOTCHO BENJAMIN | C7: =IF(E7="ECHEC",0,IF(E7="",0,100000)) -> 100000 | D7: =IF(E7="ESPECES",0,0) -> 0 | E7: BANQUE | F7: =TONTJANV!F7 -> 0 | L7: =TONTJANV!H7+TONTJANV!I7 -> 0 | P7: =IF(Q7=0,0,($C$38-Q7)) -> 0
A8: AS201619 | B8: =VLOOKUP(A8,[1]LISTADHERENT!A$5:H$60,3,0) -> KOUATCHO MESSACK | C8: =IF(E8="ECHEC",0,IF(E8="",0,100000)) -> 100000 | D8: =IF(E8="ESPECES",0,0) -> 0 | E8: BANQUE | F8: =TONTJANV!F8 -> 0 | H8: 100000 | I8: 3000 | J8: BANQUE | L8: =TONTJANV!H8+TONTJANV!I8 -> 104000 | M8: ESPECES | P8: =IF(Q8=0,0,($C$38-Q8)) -> 0
A9: AS201617 | B9: =VLOOKUP(A9,[1]LISTADHERENT!A$5:H$60,3,0) -> KOUAMOU MOISE | C9: =IF(E9="ECHEC",0,IF(E9="",0,100000)) -> 100000 | D9: =IF(E9="ESPECES",0,0) -> 0 | E9: BANQUE | F9: =TONTJANV!F9 -> 0 | L9: =TONTJANV!H9+TONTJANV!I9 -> 0 | P9: =IF(Q9=0,0,($C$38-Q9)) -> 0
A10: AS201649 | B10: =VLOOKUP(A10,[1]LISTADHERENT!A$5:H$60,3,0) -> MBOGNING TUGMA GUY | C10: =IF(E10="ECHEC",0,IF(E10="",0,100000)) -> 100000 | D10: =IF(E10="ESPECES",0,0) -> 0 | E10: BANQUE | F10: =TONTJANV!F10 -> 0 | H10: 200000 | I10: 5000 | J10: ESPECES | L10: =TONTJANV!H10+TONTJANV!I10 -> 0 | P10: =IF(Q10=0,0,($C$38-Q10)) -> 0
A11: AS201649 | B11: =VLOOKUP(A11,[1]LISTADHERENT!A$5:H$60,3,0) -> MBOGNING TUGMA GUY | C11: =IF(E11="ECHEC",0,IF(E11="",0,100000)) -> 100000 | D11: =IF(E11="ESPECES",0,0) -> 0 | E11: BANQUE | F11: =TONTJANV!F11 -> 0 | L11: =TONTJANV!H11+TONTJANV!I11 -> 0 | P11: =IF(Q11=0,0,($C$38-Q11)) -> 0
A12: AS201639 | B12: =VLOOKUP(A12,[1]LISTADHERENT!A$5:H$60,3,0) -> NANGUEN MARTIN | C12: =IF(E12="ECHEC",0,IF(E12="",0,100000)) -> 100000 | D12: =IF(E12="ESPECES",0,0) -> 0 | E12: BANQUE | F12: =TONTJANV!F12 -> 0 | L12: =TONTJANV!H12+TONTJANV!I12 -> 0 | P12: =IF(Q12=0,0,($C$38-Q12)) -> 0
A13: AS201622 | B13: =VLOOKUP(A13,[1]LISTADHERENT!A$5:H$60,3,0) -> NDJOMO ETIENNE | C13: =IF(E13="ECHEC",0,IF(E13="",0,100000)) -> 100000 | D13: =IF(E13="ESPECES",0,0) -> 0 | E13: BANQUE | F13: =TONTJANV!F13 -> 0 | H13: 100000 | I13: 3000 | J13: BANQUE | L13: =TONTJANV!H13+TONTJANV!I13 -> 0 | P13: =IF(Q13=0,0,($C$38-Q13)) -> 0
A14: AS201624 | B14: =VLOOKUP(A14,[1]LISTADHERENT!A$5:H$60,3,0) -> NGONDIEP CLAUDE | C14: =IF(E14="ECHEC",0,IF(E14="",0,100000)) -> 100000 | D14: =IF(E14="ESPECES",0,0) -> 0 | E14: BANQUE | F14: =TONTJANV!F14 -> 0 | L14: =TONTJANV!H14+TONTJANV!I14 -> 103500 | M14: ESPECES | P14: =IF(Q14=0,0,($C$38-Q14)) -> 0
A15: AS201614 | B15: =VLOOKUP(A15,[1]LISTADHERENT!A$5:H$60,3,0) -> NKEHE DAVID | C15: =IF(E15="ECHEC",0,IF(E15="",0,100000)) -> 100000 | D15: =IF(E15="ESPECES",0,0) -> 0 | E15: ESPECES | F15: =TONTJANV!F15 -> 0 | H15: 213500 | I15: 4000 | J15: ESPECES | L15: =TONTJANV!H15+TONTJANV!I15 -> 106000 | M15: ESPECES | P15: =IF(Q15=0,0,($C$38-Q15)) -> 0
A16: AS201629 | B16: =VLOOKUP(A16,[1]LISTADHERENT!A$5:H$60,3,0) -> NKEPSEU DIEUDONNE | C16: =IF(E16="ECHEC",0,IF(E16="",0,100000)) -> 100000 | D16: =IF(E16="ESPECES",0,0) -> 0 | E16: BANQUE | F16: =TONTJANV!F16 -> 0 | H16: 100000 | I16: 2000 | J16: BANQUE | L16: =TONTJANV!H16+TONTJANV!I16 -> 0 | N16: BANQUE | P16: =IF(Q16=0,0,($C$38-Q16)) -> 1400000 | Q16: 100000
A17: AS201636 | B17: =VLOOKUP(A17,[1]LISTADHERENT!A$5:H$60,3,0) -> SIMO FONGANG ERIC | C17: =IF(E17="ECHEC",0,IF(E17="",0,100000)) -> 100000 | D17: =IF(E17="ESPECES",0,0) -> 0 | E17: BANQUE | F17: =TONTJANV!F17 -> 0 | L17: =TONTJANV!H17+TONTJANV!I17 -> 0 | P17: =IF(Q17=0,0,($C$38-Q17)) -> 0
A18: AS201636 | B18: =VLOOKUP(A18,[1]LISTADHERENT!A$5:H$60,3,0) -> SIMO FONGANG ERIC | C18: =IF(E18="ECHEC",0,IF(E18="",0,100000)) -> 100000 | D18: =IF(E18="ESPECES",0,0) -> 0 | E18: BANQUE | F18: =TONTJANV!F18 -> 0 | L18: =TONTJANV!H18+TONTJANV!I18 -> 0 | P18: =IF(Q18=0,0,($C$38-Q18)) -> 0
A19: AS201637 | B19: =VLOOKUP(A19,[1]LISTADHERENT!A$5:H$60,3,0) -> SIME MATHIEU | C19: =IF(E19="ECHEC",0,IF(E19="",0,100000)) -> 100000 | D19: =IF(E19="ESPECES",0,0) -> 0 | E19: BANQUE | F19: =TONTJANV!F19 -> 0 | L19: =TONTJANV!H19+TONTJANV!I19 -> 0 | P19: =IF(Q19=0,0,($C$38-Q19)) -> 0
A20: AS201637 | B20: =VLOOKUP(A20,[1]LISTADHERENT!A$5:H$60,3,0) -> SIME MATHIEU | C20: =IF(E20="ECHEC",0,IF(E20="",0,100000)) -> 100000 | D20: =IF(E20="ESPECES",0,0) -> 0 | E20: BANQUE | F20: =TONTJANV!F20 -> 0 | L20: =TONTJANV!H20+TONTJANV!I20 -> 0 | P20: =IF(Q20=0,0,($C$38-Q20)) -> 0
A21: AS201641 | B21: =VLOOKUP(A21,[1]LISTADHERENT!A$5:H$60,3,0) -> TCHOUAMOU MATHIEU | C21: =IF(E21="ECHEC",0,IF(E21="",0,100000)) -> 100000 | D21: =IF(E21="ESPECES",0,0) -> 0 | E21: BANQUE | F21: =TONTJANV!F21 -> 0 | L21: =TONTJANV!H21+TONTJANV!I21 -> 0 | P21: =IF(Q21=0,0,($C$38-Q21)) -> 0
A22: AS201644 | B22: =VLOOKUP(A22,[1]LISTADHERENT!A$5:H$60,3,0) -> TIEYAM ERNEST | C22: =IF(E22="ECHEC",0,IF(E22="",0,100000)) -> 100000 | D22: =IF(E22="ESPECES",0,0) -> 0 | E22: BANQUE | F22: 230000 | G22: ECHEC | L22: =TONTJANV!H22+TONTJANV!I22 -> 210000 | M22: ECHEC | P22: =IF(Q22=0,0,($C$38-Q22)) -> 0
A23: AS201647 | B23: =VLOOKUP(A23,[1]LISTADHERENT!A$5:H$60,3,0) -> YOUMBI EMMANUEL | C23: =IF(E23="ECHEC",0,IF(E23="",0,100000)) -> 100000 | D23: =IF(E23="ESPECES",0,0) -> 0 | E23: BANQUE | L23: =TONTJANV!H23+TONTJANV!I23 -> 0 | P23: =IF(Q23=0,0,($C$38-Q23)) -> 0
A25: TOTAL | C25: =SUM(C6:C24) -> 1800000 | D25: =SUM(D6:D24) -> 0 | F25: =SUM(F6:F24) -> 230000 | H25: =SUM(H6:H24) -> 713500 | I25: =SUM(I6:I24) -> 17000 | L25: =SUM(L6:L24) -> 523500 | P25: =SUM(P6:P24) -> 1400000 | Q25: =SUM(Q6:Q24) -> 100000
C27: TONTINE | D27: REMBOURSEMENT PETIT LOT | E27: VENTE PETIT LOT | F27: VENTE LOT PRINCIPAL | G27: SOLDE EN CAISSE | M27: TONTINE + REMB + INTERET VENTE | N27: =C32+D32+Q25 -> 2213500
M28: VENDUE | N28: =IF(N27>=2800000,1500000*2,1500000) -> 1500000
B29: ESPECES | C29: =SUMIFS(C6:C24,E6:E24,"ESPECES") -> 100000 | D29: =SUMIFS(L6:L24,M6:M24,"ESPECES")+SUMIFS(F6:F24,G6:G24,"ESPECES") -> 313500 | E29: =SUMIFS(H6:H24,J6:J24,"ESPECES") -> 413500 | F29: =SUMIFS(P6:P24,N6:N24,"ESPECES") -> 0 | G29: =C29+D29-E29-F29 -> 0
B30: BANQUE | C30: =SUMIFS(C6:C24,E6:E24,"BANQUE") -> 1700000 | D30: =SUMIFS(L6:L24,M6:M24,"BANQUE")+SUMIFS(F6:F24,G6:G24,"BANQUE") -> 0 | E30: =SUMIFS(H6:H24,J6:J24,"BANQUE") -> 300000 | F30: =SUMIFS(P6:P24,N6:N24,"BANQUE") -> 1400000 | G30: =C30+D30-E30-F30 -> 0 | M30: PETIT LOT | N30: =N27-N28 -> 713500
B32: TOTAL | C32: =C29+C30 -> 1800000 | D32: =D29+D30 -> 313500 | E32: =E29+E30 -> 713500 | F32: =F29+F30 -> 1400000 | G32: =G29+G30 -> 0 | M32: RELIQUAT | N32: =N30-H25 -> 0 | O32: =N32+TONTJANV!O32 -> -200000 | P32: CUMUL
M34: ECHEC TONTINE | N34: =COUNTIFS(E6:E24,"ECHEC")*100000 -> 0 | O34: =N34+TONTJANV!O34 -> 0 | P34: CUMUL
B35: INTERET LOT PRINCIPAL | C35: =Q25 -> 100000 | M35: ECHEC REMBOURSEMENT | N35: =SUMIFS(F6:F24,G6:G24,"ECHEC") -> 230000 | P35: CUMUL
B36: INTERET PETIT LOT | C36: =+I25 -> 17000
B38: MONTANT TONTINE | C38: 1500000
B39: MONTANT PETIT LOT A VENDRE | C39: =H25 -> 713500

Sheet TONTMARS
A1: ASSOCIATION | B1: ASELBY
A2: ANNEE | B2: 2019/2020
A3: TONTINE | B3: 100000
C4: 43905
A5: MATRICULE | B5: NOM ET PRENOM | C5: MONTANT TONTINE | D5: PENALITE | E5: MODE VERSEMENT TONTINE | F5: REPORT ECHEC PETIT LOT | G5: MODE VERSEMENT VENTE PETIT LOT | H5: VENTE PETIT LOT | I5: INTERET PETIT LOT | J5: MODE VERSEMENT VENTE PETIT LOT | K5: NUMERO CHEQUE | L5: REMBOURSEMENT | M5: MODE VERSEMENT REMBOURSEMENT | N5: MODE VERSEMENT TONTINE PRINCIPAL | O5: NUMERO CHEQUE | P5: MONTANT TONTINE LOT PRINCIPAL | Q5: INTERET LOT PRINCIPAL | R5: DATE VENTE
A6: AS201608 | B6: =VLOOKUP(A6,[1]LISTADHERENT!A$5:H$60,3,0) -> DJUOMBESSY ANTOINE | C6: =IF(E6="ECHEC",0,IF(E6="",0,100000)) -> 100000 | D6: =IF(E6="ESPECES",0,0) -> 0 | E6: BANQUE | F6: =TONTFEV!F6 -> 0 | L6: =TONTFEV!H6+TONTFEV!I6 -> 0 | P6: =IF(Q6=0,0,($C$38-Q6)) -> 0
A7: AS201613 | B7: =VLOOKUP(A7,[1]LISTADHERENT!A$5:H$60,3,0) -> HOTCHO BENJAMIN | C7: =IF(E7="ECHEC",0,IF(E7="",0,100000)) -> 100000 | D7: =IF(E7="ESPECES",0,0) -> 0 | E7: BANQUE | F7: =TONTFEV!F7 -> 0 | L7: =TONTFEV!H7+TONTFEV!I7 -> 0 | P7: =IF(Q7=0,0,($C$38-Q7)) -> 0
A8: AS201619 | B8: =VLOOKUP(A8,[1]LISTADHERENT!A$5:H$60,3,0) -> KOUATCHO MESSACK | C8: =IF(E8="ECHEC",0,IF(E8="",0,100000)) -> 100000 | D8: =IF(E8="ESPECES",0,0) -> 0 | E8: BANQUE | F8: =TONTFEV!F8 -> 0 | H8: 200000 | I8: 2500 | J8: BANQUE | L8: =TONTFEV!H8+TONTFEV!I8 -> 103000 | M8: BANQUE | P8: =IF(Q8=0,0,($C$38-Q8)) -> 0
A9: AS201617 | B9: =VLOOKUP(A9,[1]LISTADHERENT!A$5:H$60,3,0) -> KOUAMOU MOISE | C9: =IF(E9="ECHEC",0,IF(E9="",0,100000)) -> 100000 | D9: =IF(E9="ESPECES",0,0) -> 0 | E9: BANQUE | F9: =TONTFEV!F9 -> 0 | L9: =TONTFEV!H9+TONTFEV!I9 -> 0 | P9: =IF(Q9=0,0,($C$38-Q9)) -> 1365000 | Q9: 135000
A10: AS201649 | B10: =VLOOKUP(A10,[1]LISTADHERENT!A$5:H$60,3,0) -> MBOGNING TUGMA GUY | C10: =IF(E10="ECHEC",0,IF(E10="",0,100000)) -> 100000 | D10: =IF(E10="ESPECES",0,0) -> 0 | E10: BANQUE | F10: =TONTFEV!F10 -> 0 | H10: 100000 | I10: 1000 | J10: BANQUE | L10: =TONTFEV!H10+TONTFEV!I10 -> 205000 | M10: BANQUE | P10: =IF(Q10=0,0,($C$38-Q10)) -> 0
A11: AS201649 | B11: =VLOOKUP(A11,[1]LISTADHERENT!A$5:H$60,3,0) -> MBOGNING TUGMA GUY | C11: =IF(E11="ECHEC",0,IF(E11="",0,100000)) -> 100000 | D11: =IF(E11="ESPECES",0,0) -> 0 | E11: BANQUE | F11: =TONTFEV!F11 -> 0 | L11: =TONTFEV!H11+TONTFEV!I11 -> 0 | P11: =IF(Q11=0,0,($C$38-Q11)) -> 0
A12: AS201639 | B12: =VLOOKUP(A12,[1]LISTADHERENT!A$5:H$60,3,0) -> NANGUEN MARTIN | C12: =IF(E12="ECHEC",0,IF(E12="",0,100000)) -> 100000 | D12: =IF(E12="ESPECES",0,0) -> 0 | E12: BANQUE | F12: =TONTFEV!F12 -> 0 | L12: =TONTFEV!H12+TONTFEV!I12 -> 0 | P12: =IF(Q12=0,0,($C$38-Q12)) -> 0
A13: AS201622 | B13: =VLOOKUP(A13,[1]LISTADHERENT!A$5:H$60,3,0) -> NDJOMO ETIENNE | C13: =IF(E13="ECHEC",0,IF(E13="",0,100000)) -> 100000 | D13: =IF(E13="ESPECES",0,0) -> 0 | E13: BANQUE | F13: =TONTFEV!F13 -> 0 | H13: 100000 | I13: 1500 | J13: BANQUE | L13: =TONTFEV!H13+TONTFEV!I13 -> 103000 | M13: BANQUE | P13: =IF(Q13=0,0,($C$38-Q13)) -> 0
A14: AS201624 | B14: =VLOOKUP(A14,[1]LISTADHERENT!A$5:H$60,3,0) -> NGONDIEP CLAUDE | C14: =IF(E14="ECHEC",0,IF(E14="",0,100000)) -> 100000 | D14: =IF(E14="ESPECES",0,0) -> 0 | E14: BANQUE | F14: =TONTFEV!F14 -> 0 | L14: =TONTFEV!H14+TONTFEV!I14 -> 0 | P14: =IF(Q14=0,0,($C$38-Q14)) -> 0
A15: AS201614 | B15: =VLOOKUP(A15,[1]LISTADHERENT!A$5:H$60,3,0) -> NKEHE DAVID | C15: =IF(E15="ECHEC",0,IF(E15="",0,100000)) -> 100000 | D15: =IF(E15="ESPECES",0,0) -> 0 | E15: BANQUE | F15: 225500 | G15: ECHEC | H15: 217500 | I15: 8000 | J15: ECHEC | L15: =TONTFEV!H15+TONTFEV!I15 -> 217500 | M15: ECHEC | P15: =IF(Q15=0,0,($C$38-Q15)) -> 0
A16: AS201629 | B16: =VLOOKUP(A16,[1]LISTADHERENT!A$5:H$60,3,0) -> NKEPSEU DIEUDONNE | C16: =IF(E16="ECHEC",0,IF(E16="",0,100000)) -> 100000 | D16: =IF(E16="ESPECES",0,0) -> 0 | E16: BANQUE | F16: =TONTFEV!F16 -> 0 | H16: 200000 | I16: 3000 | J16: BANQUE | L16: =TONTFEV!H16+TONTFEV!I16 -> 102000 | M16: BANQUE | P16: =IF(Q16=0,0,($C$38-Q16)) -> 0
A17: AS201636 | B17: =VLOOKUP(A17,[1]LISTADHERENT!A$5:H$60,3,0) -> SIMO FONGANG ERIC | C17: =IF(E17="ECHEC",0,IF(E17="",0,100000)) -> 100000 | D17: =IF(E17="ESPECES",0,0) -> 0 | E17: ESPECES | F17: =TONTFEV!F17 -> 0 | H17: 200000 | I17: 2500 | J17: BANQUE | L17: =TONTFEV!H17+TONTFEV!I17 -> 0 | P17: =IF(Q17=0,0,($C$38-Q17)) -> 0
A18: AS201636 | B18: =VLOOKUP(A18,[1]LISTADHERENT!A$5:H$60,3,0) -> SIMO FONGANG ERIC | C18: =IF(E18="ECHEC",0,IF(E18="",0,100000)) -> 100000 | D18: =IF(E18="ESPECES",0,0) -> 0 | E18: ESPECES | F18: =TONTFEV!F18 -> 0 | L18: =TONTFEV!H18+TONTFEV!I18 -> 0 | P18: =IF(Q18=0,0,($C$38-Q18)) -> 0
A19: AS201637 | B19: =VLOOKUP(A19,[1]LISTADHERENT!A$5:H$60,3,0) -> SIME MATHIEU | C19: =IF(E19="ECHEC",0,IF(E19="",0,100000)) -> 100000 | D19: =IF(E19="ESPECES",0,0) -> 0 | E19: BANQUE | F19: =TONTFEV!F19 -> 0 | L19: =TONTFEV!H19+TONTFEV!I19 -> 0 | P19: =IF(Q19=0,0,($C$38-Q19)) -> 0
A20: AS201637 | B20: =VLOOKUP(A20,[1]LISTADHERENT!A$5:H$60,3,0) -> SIME MATHIEU | C20: =IF(E20="ECHEC",0,IF(E20="",0,100000)) -> 100000 | D20: =IF(E20="ESPECES",0,0) -> 0 | E20: BANQUE | F20: =TONTFEV!F20 -> 0 | L20: =TONTFEV!H20+TONTFEV!I20 -> 0 | P20: =IF(Q20=0,0,($C$38-Q20)) -> 0
A21: AS201641 | B21: =VLOOKUP(A21,[1]LISTADHERENT!A$5:H$60,3,0) -> TCHOUAMOU MATHIEU | C21: =IF(E21="ECHEC",0,IF(E21="",0,100000)) -> 100000 | D21: =IF(E21="ESPECES",0,0) -> 0 | E21: BANQUE | F21: =TONTFEV!F21 -> 0 | H21: 200000 | I21: 2000 | J21: BANQUE | L21: =TONTFEV!H21+TONTFEV!I21 -> 0 | P21: =IF(Q21=0,0,($C$38-Q21)) -> 0
A22: AS201644 | B22: =VLOOKUP(A22,[1]LISTADHERENT!A$5:H$60,3,0) -> TIEYAM ERNEST | C22: =IF(E22="ECHEC",0,IF(E22="",0,100000)) -> 100000 | D22: =IF(E22="ESPECES",0,0) -> 0 | E22: BANQUE | F22: =TONTFEV!F22 -> 230000 | G22: ESPECES | H22: 200000 | I22: 2000 | J22: BANQUE | L22: =TONTFEV!H22+TONTFEV!I22 -> 0 | M22: BANQUE | P22: =IF(Q22=0,0,($C$38-Q22)) -> 0
A23: AS201647 | B23: =VLOOKUP(A23,[1]LISTADHERENT!A$5:H$60,3,0) -> YOUMBI EMMANUEL | C23: =IF(E23="ECHEC",0,IF(E23="",0,100000)) -> 100000 | D23: =IF(E23="ESPECES",0,0) -> 0 | E23: BANQUE | F23: =TONTFEV!F23 -> 0 | L23: =TONTFEV!H23+TONTFEV!I23 -> 0 | P23: =IF(Q23=0,0,($C$38-Q23)) -> 0
A25: TOTAL | C25: =SUM(C6:C24) -> 1800000 | D25: =SUM(D6:D24) -> 0 | F25: =SUM(F6:F24) -> 455500 | H25: =SUM(H6:H24) -> 1417500 | I25: =SUM(I6:I24) -> 22500 | L25: =SUM(L6:L24) -> 730500 | P25: =SUM(P6:P24) -> 1365000 | Q25: =SUM(Q6:Q24) -> 135000
C27: TONTINE | D27: REMBOURSEMENT PETIT LOT | E27: VENTE PETIT LOT | F27: VENTE LOT PRINCIPAL | G27: SOLDE EN CAISSE | M27: TONTINE + REMB + INTERET VENTE | N27: =C32+D32+Q25 -> 2678000
M28: VENDUE | N28: =IF(N27>=2800000,1500000*2,1500000) -> 1500000
B29: ESPECES | C29: =SUMIFS(C6:C24,E6:E24,"ESPECES") -> 200000 | D29: =SUMIFS(L6:L24,M6:M24,"ESPECES")+SUMIFS(F6:F24,G6:G24,"ESPECES") -> 230000 | E29: =SUMIFS(H6:H24,J6:J24,"ESPECES") -> 0 | F29: =SUMIFS(P6:P24,N6:N24,"ESPECES") -> 0 | G29: =C29+D29-E29-F29 -> 430000
B30: BANQUE | C30: =SUMIFS(C6:C24,E6:E24,"BANQUE") -> 1600000 | D30: =SUMIFS(L6:L24,M6:M24,"BANQUE")+SUMIFS(F6:F24,G6:G24,"BANQUE") -> 513000 | E30: =SUMIFS(H6:H24,J6:J24,"BANQUE") -> 1200000 | F30: =SUMIFS(P6:P24,N6:N24,"BANQUE") -> 0 | G30: =C30+D30-E30-F30 -> 913000 | M30: PETIT LOT | N30: =N27-N28 -> 1178000
B32: TOTAL | C32: =C29+C30 -> 1800000 | D32: =D29+D30 -> 743000 | E32: =E29+E30 -> 1200000 | F32: =F29+F30 -> 0 | G32: =G29+G30 -> 1343000 | M32: RELIQUAT | N32: =N30-H25 -> -239500 | O32: =N32+TONTFEV!O32 -> -439500 | P32: CUMUL
M34: ECHEC TONTINE | N34: =COUNTIFS(E6:E24,"ECHEC")*100000 -> 0 | O34: =N34+TONTFEV!O34 -> 0 | P34: CUMUL
B35: INTERET LOT PRINCIPAL | C35: =Q25 -> 135000 | M35: ECHEC REMBOURSEMENT | N35: =SUMIFS(F6:F24,G6:G24,"ECHEC") -> 225500 | P35: CUMUL
B36: INTERET PETIT LOT | C36: =+I25 -> 22500
B38: MONTANT TONTINE | C38: 1500000
B39: MONTANT PETIT LOT A VENDRE | C39: =H25 -> 1417500

Sheet TONTAVRIL
A1: ASSOCIATION | B1: ASELBY
A2: ANNEE | B2: 2019/2020
A3: TONTINE | B3: 100000
C4: 43940
A5: MATRICULE | B5: NOM ET PRENOM | C5: MONTANT TONTINE | D5: PENALITE | E5: MODE VERSEMENT TONTINE | F5: REPORT ECHEC PETIT LOT | G5: MODE VERSEMENT VENTE PETIT LOT | H5: VENTE PETIT LOT | I5: INTERET PETIT LOT | J5: MODE VERSEMENT VENTE PETIT LOT | K5: NUMERO CHEQUE | L5: REMBOURSEMENT | M5: MODE VERSEMENT REMBOURSEMENT | N5: MODE VERSEMENT TONTINE PRINCIPAL | O5: NUMERO CHEQUE | P5: MONTANT TONTINE LOT PRINCIPAL | Q5: INTERET LOT PRINCIPAL | R5: DATE VENTE
A6: AS201608 | B6: =VLOOKUP(A6,[1]LISTADHERENT!A$5:H$60,3,0) -> DJUOMBESSY ANTOINE | C6: =IF(E6="ECHEC",0,IF(E6="",0,100000)) -> 100000 | D6: =IF(E6="ESPECES",0,0) -> 0 | E6: BANQUE | F6: =TONTMARS!F6 -> 0 | L6: =TONTMARS!H6+TONTMARS!I6 -> 0 | P6: =IF(Q6=0,0,($C$38-Q6)) -> 0
A7: AS201613 | B7: =VLOOKUP(A7,[1]LISTADHERENT!A$5:H$60,3,0) -> HOTCHO BENJAMIN | C7: =IF(E7="ECHEC",0,IF(E7="",0,100000)) -> 100000 | D7: =IF(E7="ESPECES",0,0) -> 0 | E7: BANQUE | F7: =TONTMARS!F7 -> 0 | L7: =TONTMARS!H7+TONTMARS!I7 -> 0 | N7: BANQUE | P7: =IF(Q7=0,0,($C$38-Q7)) -> 1400000 | Q7: 100000
A8: AS201619 | B8: =VLOOKUP(A8,[1]LISTADHERENT!A$5:H$60,3,0) -> KOUATCHO MESSACK | C8: =IF(E8="ECHEC",0,IF(E8="",0,100000)) -> 100000 | D8: =IF(E8="ESPECES",0,0) -> 0 | E8: BANQUE | F8: =TONTMARS!F8 -> 0 | L8: =TONTMARS!H8+TONTMARS!I8 -> 202500 | M8: BANQUE | P8: =IF(Q8=0,0,($C$38-Q8)) -> 0
A9: AS201617 | B9: =VLOOKUP(A9,[1]LISTADHERENT!A$5:H$60,3,0) -> KOUAMOU MOISE | C9: =IF(E9="ECHEC",0,IF(E9="",0,100000)) -> 100000 | D9: =IF(E9="ESPECES",0,0) -> 0 | E9: BANQUE | F9: =TONTMARS!F9 -> 0 | L9: =TONTMARS!H9+TONTMARS!I9 -> 0 | P9: =IF(Q9=0,0,($C$38-Q9)) -> 0
A10: AS201649 | B10: =VLOOKUP(A10,[1]LISTADHERENT!A$5:H$60,3,0) -> MBOGNING TUGMA GUY | C10: =IF(E10="ECHEC",0,IF(E10="",0,100000)) -> 100000 | D10: =IF(E10="ESPECES",0,0) -> 0 | E10: BANQUE | F10: =TONTMARS!F10 -> 0 | L10: =TONTMARS!H10+TONTMARS!I10 -> 101000 | M10: BANQUE | P10: =IF(Q10=0,0,($C$38-Q10)) -> 0
A11: AS201649 | B11: =VLOOKUP(A11,[1]LISTADHERENT!A$5:H$60,3,0) -> MBOGNING TUGMA GUY | C11: =IF(E11="ECHEC",0,IF(E11="",0,100000)) -> 100000 | D11: =IF(E11="ESPECES",0,0) -> 0 | E11: BANQUE | F11: =TONTMARS!F11 -> 0 | L11: =TONTMARS!H11+TONTMARS!I11 -> 0 | P11: =IF(Q11=0,0,($C$38-Q11)) -> 0
A12: AS201639 | B12: =VLOOKUP(A12,[1]LISTADHERENT!A$5:H$60,3,0) -> NANGUEN MARTIN | C12: =IF(E12="ECHEC",0,IF(E12="",0,100000)) -> 100000 | D12: =IF(E12="ESPECES",0,0) -> 0 | E12: BANQUE | F12: =TONTMARS!F12 -> 0 | L12: =TONTMARS!H12+TONTMARS!I12 -> 0 | P12: =IF(Q12=0,0,($C$38-Q12)) -> 0
A13: AS201622 | B13: =VLOOKUP(A13,[1]LISTADHERENT!A$5:H$60,3,0) -> NDJOMO ETIENNE | C13: =IF(E13="ECHEC",0,IF(E13="",0,100000)) -> 100000 | D13: =IF(E13="ESPECES",0,0) -> 0 | E13: BANQUE | F13: =TONTMARS!F13 -> 0 | L13: =TONTMARS!H13+TONTMARS!I13 -> 101500 | M13: BANQUE | N13: BANQUE | P13: =IF(Q13=0,0,($C$38-Q13)) -> 1400000 | Q13: 100000
A14: AS201624 | B14: =VLOOKUP(A14,[1]LISTADHERENT!A$5:H$60,3,0) -> NGONDIEP CLAUDE | C14: =IF(E14="ECHEC",0,IF(E14="",0,100000)) -> 100000 | D14: =IF(E14="ESPECES",0,0) -> 0 | E14: BANQUE | F14: =TONTMARS!F14 -> 0 | L14: =TONTMARS!H14+TONTMARS!I14 -> 0 | P14: =IF(Q14=0,0,($C$38-Q14)) -> 0
A15: AS201614 | B15: =VLOOKUP(A15,[1]LISTADHERENT!A$5:H$60,3,0) -> NKEHE DAVID | C15: =IF(E15="ECHEC",0,IF(E15="",0,100000)) -> 100000 | D15: =IF(E15="ESPECES",0,0) -> 0 | E15: BANQUE | F15: =TONTMARS!F15 -> 225500 | G15: ECHEC | L15: =TONTMARS!H15+TONTMARS!I15 -> 225500 | P15: =IF(Q15=0,0,($C$38-Q15)) -> 0
A16: AS201629 | B16: =VLOOKUP(A16,[1]LISTADHERENT!A$5:H$60,3,0) -> NKEPSEU DIEUDONNE | C16: =IF(E16="ECHEC",0,IF(E16="",0,100000)) -> 100000 | D16: =IF(E16="ESPECES",0,0) -> 0 | E16: BANQUE | F16: =TONTMARS!F16 -> 0 | L16: =TONTMARS!H16+TONTMARS!I16 -> 203000 | M16: BANQUE | P16: =IF(Q16=0,0,($C$38-Q16)) -> 0
A17: AS201636 | B17: =VLOOKUP(A17,[1]LISTADHERENT!A$5:H$60,3,0) -> SIMO FONGANG ERIC | C17: =IF(E17="ECHEC",0,IF(E17="",0,100000)) -> 100000 | D17: =IF(E17="ESPECES",0,0) -> 0 | E17: ESPECES | F17: =TONTMARS!F17 -> 0 | L17: =TONTMARS!H17+TONTMARS!I17-22000 -> 180500 | M17: ESPECES | P17: =IF(Q17=0,0,($C$38-Q17)) -> 0
A18: AS201636 | B18: =VLOOKUP(A18,[1]LISTADHERENT!A$5:H$60,3,0) -> SIMO FONGANG ERIC | C18: =IF(E18="ECHEC",0,IF(E18="",0,100000)) -> 100000 | D18: =IF(E18="ESPECES",0,0) -> 0 | E18: ESPECES | F18: =TONTMARS!F18 -> 0 | L18: =TONTMARS!H18+TONTMARS!I18 -> 0 | P18: =IF(Q18=0,0,($C$38-Q18)) -> 0
A19: AS201637 | B19: =VLOOKUP(A19,[1]LISTADHERENT!A$5:H$60,3,0) -> SIME MATHIEU | C19: =IF(E19="ECHEC",0,IF(E19="",0,100000)) -> 100000 | D19: =IF(E19="ESPECES",0,0) -> 0 | E19: BANQUE | F19: =TONTMARS!F19 -> 0 | L19: =TONTMARS!H19+TONTMARS!I19 -> 0 | P19: =IF(Q19=0,0,($C$38-Q19)) -> 0
A20: AS201637 | B20: =VLOOKUP(A20,[1]LISTADHERENT!A$5:H$60,3,0) -> SIME MATHIEU | C20: =IF(E20="ECHEC",0,IF(E20="",0,100000)) -> 100000 | D20: =IF(E20="ESPECES",0,0) -> 0 | E20: BANQUE | F20: =TONTMARS!F20 -> 0 | L20: =TONTMARS!H20+TONTMARS!I20 -> 0 | P20: =IF(Q20=0,0,($C$38-Q20)) -> 0
A21: AS201641 | B21: =VLOOKUP(A21,[1]LISTADHERENT!A$5:H$60,3,0) -> TCHOUAMOU MATHIEU | C21: =IF(E21="ECHEC",0,IF(E21="",0,100000)) -> 100000 | D21: =IF(E21="ESPECES",0,0) -> 0 | E21: BANQUE | F21: =TONTMARS!F21 -> 0 | L21: =TONTMARS!H21+TONTMARS!I21 -> 202000 | M21: BANQUE | P21: =IF(Q21=0,0,($C$38-Q21)) -> 0
A22: AS201644 | B22: =VLOOKUP(A22,[1]LISTADHERENT!A$5:H$60,3,0) -> TIEYAM ERNEST | C22: =IF(E22="ECHEC",0,IF(E22="",0,100000)) -> 100000 | D22: =IF(E22="ESPECES",0,0) -> 0 | E22: BANQUE | F22: 210000 | G22: ECHEC | L22: =TONTMARS!H22+TONTMARS!I22 -> 202000 | P22: =IF(Q22=0,0,($C$38-Q22)) -> 0
A23: AS201647 | B23: =VLOOKUP(A23,[1]LISTADHERENT!A$5:H$60,3,0) -> YOUMBI EMMANUEL | C23: =IF(E23="ECHEC",0,IF(E23="",0,100000)) -> 100000 | D23: =IF(E23="ESPECES",0,0) -> 0 | E23: BANQUE | F23: 0 | L23: =TONTFEV!H23+TONTFEV!I23 -> 0 | P23: =IF(Q23=0,0,($C$38-Q23)) -> 0
A25: TOTAL | C25: =SUM(C6:C24) -> 1800000 | D25: =SUM(D6:D24) -> 0 | F25: =SUM(F6:F24) -> 435500 | H25: =SUM(H6:H24) -> 0 | I25: =SUM(I6:I24) -> 0 | L25: =SUM(L6:L24) -> 1418000 | P25: =SUM(P6:P24) -> 2800000 | Q25: =SUM(Q6:Q24) -> 200000
C27: TONTINE | D27: REMBOURSEMENT PETIT LOT | E27: VENTE PETIT LOT | F27: VENTE LOT PRINCIPAL | G27: SOLDE EN CAISSE | M27: TONTINE + REMB + INTERET VENTE | N27: =C32+D32+Q25 -> 2990500
M28: VENDUE | N28: =IF(N27>=2800000,1500000*2,1500000) -> 3000000
B29: ESPECES | C29: =SUMIFS(C6:C24,E6:E24,"ESPECES") -> 200000 | D29: =SUMIFS(L6:L24,M6:M24,"ESPECES")+SUMIFS(F6:F24,G6:G24,"ESPECES") -> 180500 | E29: =SUMIFS(H6:H24,J6:J24,"ESPECES") -> 0 | F29: =SUMIFS(P6:P24,N6:N24,"ESPECES") -> 0 | G29: =C29+D29-E29-F29 -> 380500
B30: BANQUE | C30: =SUMIFS(C6:C24,E6:E24,"BANQUE") -> 1600000 | D30: =SUMIFS(L6:L24,M6:M24,"BANQUE")+SUMIFS(F6:F24,G6:G24,"BANQUE") -> 810000 | E30: =SUMIFS(H6:H24,J6:J24,"BANQUE") -> 0 | F30: =SUMIFS(P6:P24,N6:N24,"BANQUE") -> 2800000 | G30: =C30+D30-E30-F30 -> -390000 | M30: PETIT LOT | N30: =N27-N28 -> -9500
B32: TOTAL | C32: =C29+C30 -> 1800000 | D32: =D29+D30 -> 990500 | E32: =E29+E30 -> 0 | F32: =F29+F30 -> 2800000 | G32: =G29+G30 -> -9500 | M32: RELIQUAT | N32: =N30-H25 -> -9500 | O32: =N32+TONTMARS!O32 -> -449000 | P32: CUMUL
M34: ECHEC TONTINE | N34: =COUNTIFS(E6:E24,"ECHEC")*100000 -> 0 | O34: =N34+TONTMARS!O34 -> 0 | P34: CUMUL
B35: INTERET LOT PRINCIPAL | C35: =Q25 -> 200000 | M35: ECHEC REMBOURSEMENT | N35: =SUMIFS(F6:F24,G6:G24,"ECHEC") -> 435500 | P35: CUMUL
B36: INTERET PETIT LOT | C36: =+I25 -> 0
B38: MONTANT TONTINE | C38: 1500000
B39: MONTANT PETIT LOT A VENDRE | C39: =H25 -> 0

Sheet TONTMAI
A1: ASSOCIATION | B1: ASELBY
A2: ANNEE | B2: 2019/2020
A3: TONTINE | B3: 100000
C4: 43968
A5: MATRICULE | B5: NOM ET PRENOM | C5: MONTANT TONTINE | D5: PENALITE | E5: MODE VERSEMENT TONTINE | F5: REPORT ECHEC PETIT LOT | G5: MODE VERSEMENT VENTE PETIT LOT | H5: VENTE PETIT LOT | I5: INTERET PETIT LOT | J5: MODE VERSEMENT VENTE PETIT LOT | K5: NUMERO CHEQUE | L5: REMBOURSEMENT | M5: MODE VERSEMENT REMBOURSEMENT | N5: MODE VERSEMENT TONTINE PRINCIPAL | O5: NUMERO CHEQUE | P5: MONTANT TONTINE LOT PRINCIPAL | Q5: INTERET LOT PRINCIPAL | R5: DATE VENTE
A6: AS201608 | B6: =VLOOKUP(A6,[1]LISTADHERENT!A$5:H$60,3,0) -> DJUOMBESSY ANTOINE | C6: =IF(E6="ECHEC",0,IF(E6="",0,100000)) -> 100000 | D6: =IF(E6="ESPECES",0,0) -> 0 | E6: BANQUE | F6: =TONTAVRIL!F6 -> 0 | L6: =TONTAVRIL!H6+TONTAVRIL!I6 -> 0 | P6: =IF(Q6=0,0,($C$38-Q6)) -> 0
A7: AS201613 | B7: =VLOOKUP(A7,[1]LISTADHERENT!A$5:H$60,3,0) -> HOTCHO BENJAMIN | C7: =IF(E7="ECHEC",0,IF(E7="",0,100000)) -> 100000 | D7: =IF(E7="ESPECES",0,0) -> 0 | E7: BANQUE | F7: =TONTAVRIL!F7 -> 0 | L7: =TONTAVRIL!H7+TONTAVRIL!I7 -> 0 | P7: =IF(Q7=0,0,($C$38-Q7)) -> 0
A8: AS201619 | B8: =VLOOKUP(A8,[1]LISTADHERENT!A$5:H$60,3,0) -> KOUATCHO MESSACK | C8: =IF(E8="ECHEC",0,IF(E8="",0,100000)) -> 100000 | D8: =IF(E8="ESPECES",0,0) -> 0 | E8: BANQUE | F8: =TONTAVRIL!F8 -> 0 | H8: 200000 | I8: 10000 | L8: =TONTAVRIL!H8+TONTAVRIL!I8 -> 0 | P8: =IF(Q8=0,0,($C$38-Q8)) -> 0
A9: AS201617 | B9: =VLOOKUP(A9,[1]LISTADHERENT!A$5:H$60,3,0) -> KOUAMOU MOISE | C9: =IF(E9="ECHEC",0,IF(E9="",0,100000)) -> 100000 | D9: =IF(E9="ESPECES",0,0) -> 0 | E9: BANQUE | F9: =TONTAVRIL!F9 -> 0 | L9: =TONTAVRIL!H9+TONTAVRIL!I9 -> 0 | P9: =IF(Q9=0,0,($C$38-Q9)) -> 0
A10: AS201649 | B10: =VLOOKUP(A10,[1]LISTADHERENT!A$5:H$60,3,0) -> MBOGNING TUGMA GUY | C10: =IF(E10="ECHEC",0,IF(E10="",0,100000)) -> 100000 | D10: =IF(E10="ESPECES",0,0) -> 0 | E10: BANQUE | F10: =TONTAVRIL!F10 -> 0 | L10: =TONTAVRIL!H10+TONTAVRIL!I10 -> 0 | P10: =IF(Q10=0,0,($C$38-Q10)) -> 0
A11: AS201649 | B11: =VLOOKUP(A11,[1]LISTADHERENT!A$5:H$60,3,0) -> MBOGNING TUGMA GUY | C11: =IF(E11="ECHEC",0,IF(E11="",0,100000)) -> 100000 | D11: =IF(E11="ESPECES",0,0) -> 0 | E11: BANQUE | F11: =TONTAVRIL!F11 -> 0 | L11: =TONTAVRIL!H11+TONTAVRIL!I11 -> 0 | P11: =IF(Q11=0,0,($C$38-Q11)) -> 0
A12: AS201639 | B12: =VLOOKUP(A12,[1]LISTADHERENT!A$5:H$60,3,0) -> NANGUEN MARTIN | C12: =IF(E12="ECHEC",0,IF(E12="",0,100000)) -> 100000 | D12: =IF(E12="ESPECES",0,0) -> 0 | E12: BANQUE | F12: =TONTAVRIL!F12 -> 0 | L12: =TONTAVRIL!H12+TONTAVRIL!I12 -> 0 | P12: =IF(Q12=0,0,($C$38-Q12)) -> 0
A13: AS201622 | B13: =VLOOKUP(A13,[1]LISTADHERENT!A$5:H$60,3,0) -> NDJOMO ETIENNE | C13: =IF(E13="ECHEC",0,IF(E13="",0,100000)) -> 100000 | D13: =IF(E13="ESPECES",0,0) -> 0 | E13: BANQUE | F13: =TONTAVRIL!F13 -> 0 | H13: 126000 | I13: 1000 | L13: =TONTAVRIL!H13+TONTAVRIL!I13 -> 0 | P13: =IF(Q13=0,0,($C$38-Q13)) -> 0
A14: AS201624 | B14: =VLOOKUP(A14,[1]LISTADHERENT!A$5:H$60,3,0) -> NGONDIEP CLAUDE | C14: =IF(E14="ECHEC",0,IF(E14="",0,100000)) -> 100000 | D14: =IF(E14="ESPECES",0,0) -> 0 | E14: BANQUE | F14: =TONTAVRIL!F14 -> 0 | L14: =TONTAVRIL!H14+TONTAVRIL!I14 -> 0 | P14: =IF(Q14=0,0,($C$38-Q14)) -> 1370000 | Q14: 130000
A15: AS201614 | B15: =VLOOKUP(A15,[1]LISTADHERENT!A$5:H$60,3,0) -> NKEHE DAVID | C15: =IF(E15="ECHEC",0,IF(E15="",0,100000)) -> 100000 | D15: =IF(E15="ESPECES",0,0) -> 0 | E15: ESPECES | F15: =TONTAVRIL!F15 -> 225500 | G15: ECHEC | L15: =TONTAVRIL!H15+TONTAVRIL!I15 -> 0 | M15: ECHEC | P15: =IF(Q15=0,0,($C$38-Q15)) -> 0
A16: AS201629 | B16: =VLOOKUP(A16,[1]LISTADHERENT!A$5:H$60,3,0) -> NKEPSEU DIEUDONNE | C16: =IF(E16="ECHEC",0,IF(E16="",0,100000)) -> 100000 | D16: =IF(E16="ESPECES",0,0) -> 0 | E16: BANQUE | F16: =TONTAVRIL!F16 -> 0 | L16: =TONTAVRIL!H16+TONTAVRIL!I16 -> 0 | P16: =IF(Q16=0,0,($C$38-Q16)) -> 0
A17: AS201636 | B17: =VLOOKUP(A17,[1]LISTADHERENT!A$5:H$60,3,0) -> SIMO FONGANG ERIC | C17: =IF(E17="ECHEC",0,IF(E17="",0,100000)) -> 100000 | D17: =IF(E17="ESPECES",0,0) -> 0 | E17: ESPECES | F17: =TONTAVRIL!F17 -> 0 | H17: 200000 | I17: 11000 | L17: =TONTAVRIL!H17+TONTAVRIL!I17 -> 0 | P17: =IF(Q17=0,0,($C$38-Q17)) -> 0
A18: AS201636 | B18: =VLOOKUP(A18,[1]LISTADHERENT!A$5:H$60,3,0) -> SIMO FONGANG ERIC | C18: =IF(E18="ECHEC",0,IF(E18="",0,100000)) -> 100000 | D18: =IF(E18="ESPECES",0,0) -> 0 | E18: ESPECES | F18: =TONTAVRIL!F18 -> 0 | L18: =TONTAVRIL!H18+TONTAVRIL!I18 -> 0 | P18: =IF(Q18=0,0,($C$38-Q18)) -> 0
A19: AS201637 | B19: =VLOOKUP(A19,[1]LISTADHERENT!A$5:H$60,3,0) -> SIME MATHIEU | C19: =IF(E19="ECHEC",0,IF(E19="",0,100000)) -> 100000 | D19: =IF(E19="ESPECES",0,0) -> 0 | E19: BANQUE | F19: =TONTAVRIL!F19 -> 0 | L19: =TONTAVRIL!H19+TONTAVRIL!I19 -> 0 | P19: =IF(Q19=0,0,($C$38-Q19)) -> 0
A20: AS201637 | B20: =VLOOKUP(A20,[1]LISTADHERENT!A$5:H$60,3,0) -> SIME MATHIEU | C20: =IF(E20="ECHEC",0,IF(E20="",0,100000)) -> 100000 | D20: =IF(E20="ESPECES",0,0) -> 0 | E20: BANQUE | F20: =TONTAVRIL!F20 -> 0 | L20: =TONTAVRIL!H20+TONTAVRIL!I20 -> 0 | P20: =IF(Q20=0,0,($C$38-Q20)) -> 0
A21: AS201641 | B21: =VLOOKUP(A21,[1]LISTADHERENT!A$5:H$60,3,0) -> TCHOUAMOU MATHIEU | C21: =IF(E21="ECHEC",0,IF(E21="",0,100000)) -> 100000 | D21: =IF(E21="ESPECES",0,0) -> 0 | E21: BANQUE | F21: =TONTAVRIL!F21 -> 0 | L21: =TONTAVRIL!H21+TONTAVRIL!I21 -> 0 | P21: =IF(Q21=0,0,($C$38-Q21)) -> 0
A22: AS201644 | B22: =VLOOKUP(A22,[1]LISTADHERENT!A$5:H$60,3,0) -> TIEYAM ERNEST | C22: =IF(E22="ECHEC",0,IF(E22="",0,100000)) -> 100000 | D22: =IF(E22="ESPECES",0,0) -> 0 | E22: BANQUE | F22: =TONTAVRIL!F22 -> 210000 | G22: ESPECES | H22: 100000 | I22: 6000 | L22: =TONTAVRIL!H22+TONTAVRIL!I22 -> 0 | M22: ESPECES | P22: =IF(Q22=0,0,($C$38-Q22)) -> 0
A23: AS201647 | B23: =VLOOKUP(A23,[1]LISTADHERENT!A$5:H$60,3,0) -> YOUMBI EMMANUEL | C23: =IF(E23="ECHEC",0,IF(E23="",0,100000)) -> 100000 | D23: =IF(E23="ESPECES",0,0) -> 0 | E23: BANQUE | F23: =TONTAVRIL!F23 -> 0 | L23: =TONTAVRIL!H23+TONTAVRIL!I23 -> 0 | P23: =IF(Q23=0,0,($C$38-Q23)) -> 0
A25: TOTAL | C25: =SUM(C6:C24) -> 1800000 | D25: =SUM(D6:D24) -> 0 | F25: =SUM(F6:F24) -> 435500 | H25: =SUM(H6:H24) -> 626000 | I25: =SUM(I6:I24) -> 28000 | L25: =SUM(L6:L24) -> 0 | P25: =SUM(P6:P24) -> 1370000 | Q25: =SUM(Q6:Q24) -> 130000
C27: TONTINE | D27: REMBOURSEMENT PETIT LOT | E27: VENTE PETIT LOT | F27: VENTE LOT PRINCIPAL | G27: SOLDE EN CAISSE | M27: TONTINE + REMB + INTERET VENTE | N27: =C32+D32+Q25 -> 2140000
M28: VENDUE | N28: =IF(N27>=2800000,1500000*2,1500000) -> 1500000
B29: ESPECES | C29: =SUMIFS(C6:C24,E6:E24,"ESPECES") -> 300000 | D29: =SUMIFS(L6:L24,M6:M24,"ESPECES")+SUMIFS(F6:F24,G6:G24,"ESPECES") -> 210000 | E29: =SUMIFS(H6:H24,J6:J24,"ESPECES") -> 0 | F29: =SUMIFS(P6:P24,N6:N24,"ESPECES") -> 0 | G29: =C29+D29-E29-F29 -> 510000
B30: BANQUE | C30: =SUMIFS(C6:C24,E6:E24,"BANQUE") -> 1500000 | D30: =SUMIFS(L6:L24,M6:M24,"BANQUE")+SUMIFS(F6:F24,G6:G24,"BANQUE") -> 0 | E30: =SUMIFS(H6:H24,J6:J24,"BANQUE") -> 0 | F30: =SUMIFS(P6:P24,N6:N24,"BANQUE") -> 0 | G30: =C30+D30-E30-F30 -> 1500000 | M30: PETIT LOT | N30: =N27-N28 -> 640000
B32: TOTAL | C32: =C29+C30 -> 1800000 | D32: =D29+D30 -> 210000 | E32: =E29+E30 -> 0 | F32: =F29+F30 -> 0 | G32: =G29+G30 -> 2010000 | M32: RELIQUAT | N32: =N30-H25 -> 14000 | O32: =N32+TONTAVRIL!O32 -> -435000 | P32: CUMUL
M34: ECHEC TONTINE | N34: =COUNTIFS(E6:E24,"ECHEC")*100000 -> 0 | O34: =N34+TONTAVRIL!O34 -> 0 | P34: CUMUL
B35: INTERET LOT PRINCIPAL | C35: =Q25 -> 130000 | M35: ECHEC REMBOURSEMENT | N35: =SUMIFS(F6:F24,G6:G24,"ECHEC") -> 225500 | P35: CUMUL
B36: INTERET PETIT LOT | C36: =+I25 -> 28000
B38: MONTANT TONTINE | C38: 1500000
B39: MONTANT PETIT LOT A VENDRE | C39: =H25 -> 626000

Sheet TONTJUIN
A1: ASSOCIATION | B1: ASELBY
A2: ANNEE | B2: 2019/2020
A3: TONTINE | B3: 100000
C4: 44003
A5: MATRICULE | B5: NOM ET PRENOM | C5: MONTANT TONTINE | D5: PENALITE | E5: MODE VERSEMENT TONTINE | F5: REPORT ECHEC PETIT LOT | G5: MODE VERSEMENT VENTE PETIT LOT | H5: VENTE PETIT LOT | I5: INTERET PETIT LOT | J5: MODE VERSEMENT VENTE PETIT LOT | K5: NUMERO CHEQUE | L5: REMBOURSEMENT | M5: MODE VERSEMENT REMBOURSEMENT | N5: MODE VERSEMENT TONTINE PRINCIPAL | O5: NUMERO CHEQUE | P5: MONTANT TONTINE LOT PRINCIPAL | Q5: INTERET LOT PRINCIPAL | R5: DATE VENTE
A6: AS201608 | B6: =VLOOKUP(A6,[1]LISTADHERENT!A$5:H$60,3,0) -> DJUOMBESSY ANTOINE | C6: =IF(E6="ECHEC",0,IF(E6="",0,100000)) -> 100000 | D6: =IF(E6="ESPECES",0,0) -> 0 | E6: BANQUE | F6: =TONTMAI!F6 -> 0 | L6: =TONTMAI!H6+TONTMAI!I6 -> 0 | P6: =IF(Q6=0,0,($C$38-Q6)) -> 0
A7: AS201613 | B7: =VLOOKUP(A7,[1]LISTADHERENT!A$5:H$60,3,0) -> HOTCHO BENJAMIN | C7: =IF(E7="ECHEC",0,IF(E7="",0,100000)) -> 100000 | D7: =IF(E7="ESPECES",0,0) -> 0 | E7: BANQUE | F7: =TONTMAI!F7 -> 0 | L7: =TONTMAI!H7+TONTMAI!I7 -> 0 | P7: =IF(Q7=0,0,($C$38-Q7)) -> 0
A8: AS201619 | B8: =VLOOKUP(A8,[1]LISTADHERENT!A$5:H$60,3,0) -> KOUATCHO MESSACK | C8: =IF(E8="ECHEC",0,IF(E8="",0,100000)) -> 100000 | D8: =IF(E8="ESPECES",0,0) -> 0 | E8: BANQUE | F8: =TONTMAI!F8 -> 0 | H8: 200000 | I8: 2000 | J8: BANQUE | L8: =TONTMAI!H8+TONTMAI!I8 -> 210000 | M8: BANQUE | P8: =IF(Q8=0,0,($C$38-Q8)) -> 0
A9: AS201617 | B9: =VLOOKUP(A9,[1]LISTADHERENT!A$5:H$60,3,0) -> KOUAMOU MOISE | C9: =IF(E9="ECHEC",0,IF(E9="",0,100000)) -> 100000 | D9: =IF(E9="ESPECES",0,0) -> 0 | E9: BANQUE | F9: =TONTMAI!F9 -> 0 | L9: =TONTMAI!H9+TONTMAI!I9 -> 0 | P9: =IF(Q9=0,0,($C$38-Q9)) -> 0
A10: AS201649 | B10: =VLOOKUP(A10,[1]LISTADHERENT!A$5:H$60,3,0) -> MBOGNING TUGMA GUY | C10: =IF(E10="ECHEC",0,IF(E10="",0,100000)) -> 100000 | D10: =IF(E10="ESPECES",0,0) -> 0 | E10: BANQUE | F10: =TONTMAI!F10 -> 0 | H10: 100000 | I10: 1000 | J10: ESPECES | L10: =TONTMAI!H10+TONTMAI!I10 -> 0 | P10: =IF(Q10=0,0,($C$38-Q10)) -> 0
A11: AS201649 | B11: =VLOOKUP(A11,[1]LISTADHERENT!A$5:H$60,3,0) -> MBOGNING TUGMA GUY | C11: =IF(E11="ECHEC",0,IF(E11="",0,100000)) -> 100000 | D11: =IF(E11="ESPECES",0,0) -> 0 | E11: BANQUE | F11: =TONTMAI!F11 -> 0 | L11: =TONTMAI!H11+TONTMAI!I11 -> 0 | P11: =IF(Q11=0,0,($C$38-Q11)) -> 0
A12: AS201639 | B12: =VLOOKUP(A12,[1]LISTADHERENT!A$5:H$60,3,0) -> NANGUEN MARTIN | C12: =IF(E12="ECHEC",0,IF(E12="",0,100000)) -> 100000 | D12: =IF(E12="ESPECES",0,0) -> 0 | E12: BANQUE | F12: =TONTMAI!F12 -> 0 | L12: =TONTMAI!H12+TONTMAI!I12 -> 0 | P12: =IF(Q12=0,0,($C$38-Q12)) -> 0
A13: AS201622 | B13: =VLOOKUP(A13,[1]LISTADHERENT!A$5:H$60,3,0) -> NDJOMO ETIENNE | C13: =IF(E13="ECHEC",0,IF(E13="",0,100000)) -> 100000 | D13: =IF(E13="ESPECES",0,0) -> 0 | E13: BANQUE | F13: =TONTMAI!F13 -> 0 | H13: 200000 | I13: 2000 | J13: BANQUE | L13: =TONTMAI!H13+TONTMAI!I13 -> 127000 | M13: ESPECES | P13: =IF(Q13=0,0,($C$38-Q13)) -> 0
A14: AS201624 | B14: =VLOOKUP(A14,[1]LISTADHERENT!A$5:H$60,3,0) -> NGONDIEP CLAUDE | C14: =IF(E14="ECHEC",0,IF(E14="",0,100000)) -> 100000 | D14: =IF(E14="ESPECES",0,0) -> 0 | E14: BANQUE | F14: =TONTMAI!F14 -> 0 | L14: =TONTMAI!H14+TONTMAI!I14 -> 0 | P14: =IF(Q14=0,0,($C$38-Q14)) -> 0
A15: AS201614 | B15: =VLOOKUP(A15,[1]LISTADHERENT!A$5:H$60,3,0) -> NKEHE DAVID | C15: =IF(E15="ECHEC",0,IF(E15="",0,100000)) -> 0 | D15: =IF(E15="ESPECES",0,0) -> 0 | E15: ECHEC | F15: =TONTMAI!F15 -> 225500 | G15: ECHEC | L15: =TONTMAI!H15+TONTMAI!I15 -> 0 | M15: ECHEC | P15: =IF(Q15=0,0,($C$38-Q15)) -> 0
A16: AS201629 | B16: =VLOOKUP(A16,[1]LISTADHERENT!A$5:H$60,3,0) -> NKEPSEU DIEUDONNE | C16: =IF(E16="ECHEC",0,IF(E16="",0,100000)) -> 100000 | D16: =IF(E16="ESPECES",0,0) -> 0 | E16: BANQUE | F16: =TONTMAI!F16 -> 0 | L16: =TONTMAI!H16+TONTMAI!I16 -> 0 | P16: =IF(Q16=0,0,($C$38-Q16)) -> 0
A17: AS201636 | B17: =VLOOKUP(A17,[1]LISTADHERENT!A$5:H$60,3,0) -> SIMO FONGANG ERIC | C17: =IF(E17="ECHEC",0,IF(E17="",0,100000)) -> 100000 | D17: =IF(E17="ESPECES",0,0) -> 0 | E17: ESPECES | F17: 233000 | G17: ECHEC | L17: =TONTMAI!H17+TONTMAI!I17+22000 -> 233000 | M17: ECHEC | P17: =IF(Q17=0,0,($C$38-Q17)) -> 0
A18: AS201636 | B18: =VLOOKUP(A18,[1]LISTADHERENT!A$5:H$60,3,0) -> SIMO FONGANG ERIC | C18: =IF(E18="ECHEC",0,IF(E18="",0,100000)) -> 100000 | D18: =IF(E18="ESPECES",0,0) -> 0 | E18: ESPECES | F18: =TONTMAI!F18 -> 0 | L18: =TONTMAI!H18+TONTMAI!I18 -> 0 | P18: =IF(Q18=0,0,($C$38-Q18)) -> 0
A19: AS201637 | B19: =VLOOKUP(A19,[1]LISTADHERENT!A$5:H$60,3,0) -> SIME MATHIEU | C19: =IF(E19="ECHEC",0,IF(E19="",0,100000)) -> 100000 | D19: =IF(E19="ESPECES",0,0) -> 0 | E19: BANQUE | F19: =TONTMAI!F19 -> 0 | L19: =TONTMAI!H19+TONTMAI!I19 -> 0 | P19: =IF(Q19=0,0,($C$38-Q19)) -> 0
A20: AS201637 | B20: =VLOOKUP(A20,[1]LISTADHERENT!A$5:H$60,3,0) -> SIME MATHIEU | C20: =IF(E20="ECHEC",0,IF(E20="",0,100000)) -> 100000 | D20: =IF(E20="ESPECES",0,0) -> 0 | E20: BANQUE | F20: =TONTMAI!F20 -> 0 | L20: =TONTMAI!H20+TONTMAI!I20 -> 0 | P20: =IF(Q20=0,0,($C$38-Q20)) -> 0
